Workbook
Name Ccy: WACC!$E$1
Name circ: [1]Cover!$K$6
Name Circ: Cover!$K$6
Name Conv: WACC!$AP$24
Name Date: WACC!$H$1
Name Days: #REF!
Name Days: 'Working Capital'!$H$30
Name Fil: WACC!$AQ$27
Name GVKey: ""
Name img_1675017080: SHAK_10K!#REF!
Name IQ_CH: 110000
Name IQ_CQ: 5000
Name IQ_CY: 10000
Name IQ_DAILY: 500000
Name IQ_FH: 100000
Name IQ_FQ: 500
Name IQ_FY: 1000
Name IQ_LTM: 2000
Name IQ_MONTH: 15000
Name IQ_NTM: 6000
Name IQ_WEEK: 50000
Name IQ_YTD: 3000
Name List: 'Input Tab'!$AD$15:$AD$19
Name SPSet: "current"
Name SPWS_WBID: "D37EBD5C-BA90-4B94-B2F1-78539D014FA9"

Sheet _CIQHiddenCacheSheet
A1: 26 | B1: AwABTAVMT0NBTAFI/////wFQuQAAACNDSVEuS1IuSVFfRlhfUkFURS5ERUMyMDEzLjgvMjUvMjAxNwEAAADIS5MGAgAAAAsxMDU3LjEwOTA5MQCqPkp9LevVCPiMZn0t69UIMENJUS5ORExTLklRX1BSRUZfRVFVSVRZLjUwMC4yMDE4LTA3LTEwLkxGUi4uVVNELgEAAAD5n3sAAwAAAAAAFPwQcS/r1Qh2NzSKL+vVCCRDSVEuQ01HLklRX01BUktFVENBUC4yMDE4LTA3LTEwLlVTRC4BAAAATmcAAAIAAAALMTI2MjQuMDE5MzIBBgAAAAUAAAABMQEAAAAKMTg4NDk2MzMzMAMAAAADMTYwAgAAAAYxMDAwNTQEAAAAATAHAAAACTcvMTAvMjAxOBT8EHEv69UIdjc0ii/r1QgjQ0lRLktSLklRX0ZYX1JBVEUuU0VQMjAxNS44LzI1LzIwMTcBAAAAyEuTBgIAAAALMTE4NS4yNDA5MDkAqj5KfS3r1QgHZmZ9LevVCCtDSVEuTllTRTpTSEFLLklRX0VCVC4uMjAxOC0wNy0xMC5MRlIuLlVTRC5IAQAAAJ0Tpg0CAAAABjE2MC45NQEIAAAABQAAAAExAQAAAAoxODg3MjkwNTQxAwAAAAMxNjACAAAAAzEzOQQAAAABMAcAAAAJNy8xMC8yMDE4CAAAAAkzLzI4LzIwMTgJAAAAATBOt2twL+vVCFRmdLcv69UII0NJUS5LUi5JUV9GWF9SQVRFLk5PVjIwMTUuOC8yNS8yMDE3AQAAAMhLkwYCAAAACzExNTIuOTM4MDk1AKo+Sn0t69UIB2ZmfS3r1QgwQ0lRLlpPRVMuSVFfUFJFRl9FUVVJVFkuNTAwLjIwMTgtMDctMTAuTEZSLi5V | C1: U0QuAQAAANTGTwIDAAAAAAAU/BBxL+vVCG5eNIov69UIMUNJUS5IQUJULklRX1BSRUZfRVFVSVRZLjUwMC4yMDE4LTA3LTEwLkxGUi4uVVNELkgBAAAAI9YREAMAAAAAAIIe/FQv69UIVoU0ii/r1QgmQ0lRLk5ZU0U6TUNELklRX0NPTVBBTllfVElDS0VSX05PX0VYQ0gBAAAA4CACAAMAAAADTUNEAKFSM1Qv69UIghA0ii/r1QgtQ0lRQVZHLk5ETFMuSVFfRUZGRUNUX1RBWF9SQVRFLjk5Ni4yMDE4LTA3LTEwAQAAAPmfewACAAAABzQwLjA0NjEAgh78VC/r1QhuXjSKL+vVCB1DSVEuTllTRTpTSEFLLklRX1FVSUNLX0NPTVAuNgEAAACdE6YNAwAAAAhOWVNFOk1DRABOt2twL+vVCIIQNIov69UIL0NJUS5DTUcuSVFfVE9UQUxfREVCVC41MDAuMjAxOC0wNy0xMC5MRlIuLlVTRC5IAQAAAE5nAAACAAAAATABCAAAAAUAAAABMQEAAAAKMTg4NDk2MzMzMAMAAAADMTYwAgAAAAQ0MTczBAAAAAEwBwAAAAk3LzEwLzIwMTgIAAAACTMvMzEvMjAxOAkAAAABMIIe/FQv69UIUqw0ii/r1QgmQ0lRLktSLklRX0ZYX1JBVEVfRkMuU0VQMjAxOS44LzI0LzIwMTcBAAAAxDGUBgIAAAAKMTExNS41NzgzOQCqPkp9LevVCAE/Zn0t69UIKkNJUS5OWVNFOlNIQUsuSVFfRUJULi4yMDE4LTA3LTEwLkxGUi4uVVNELgEAAACdE6YNAgAAAAYxNjAuOTUBCAAAAAUAAAABMQEAAAAKMTg4NzI5MDU0MQMAAAADMTYwAgAAAAMxMzkE | D1: AAAAATAHAAAACTcvMTAvMjAxOAgAAAAJMy8yOC8yMDE4CQAAAAEwFPwQcS/r1QhUZnS3L+vVCCZDSVEuS1IuSVFfRlhfUkFURV9GQy5NQVkyMDIwLjgvMjQvMjAxNwEAAADEMZQGAgAAAAoxMTMyLjExMzQyAKo+Sn0t69UIAT9mfS3r1QgvQ0lRLk1DRC5JUV9UT1RBTF9ERUJULjUwMC4yMDE4LTA3LTEwLkxGUi4uVVNELkgBAAAA4CACAAIAAAAFMzA4ODgBCAAAAAUAAAABMQEAAAAKMTg4NzY2NTU5NgMAAAADMTYwAgAAAAQ0MTczBAAAAAEwBwAAAAk3LzEwLzIwMTgIAAAACTMvMzEvMjAxOAkAAAABMIIe/FQv69UIVEQkiy/r1Qg+Q0lRUkFOR0UuTllTRTpTSEFLLklRX0ZJWEVEX0lOQ09NRV9MSVNULjEuNTAwLi4uLi5GSVhFRCBJTkNPTUUDAAAAnROmDQAAAABOt2twL+vVCGw/dLcv69UIF0NJUS5NQ0QuSVFfQ09NUEFOWV9OQU1FAQAAAOAgAgADAAAAFk1jRG9uYWxkJ3MgQ29ycG9yYXRpb24Agh78VC/r1Qh2NzSKL+vVCBhDSVEuTkRMUy5JUV9DT01QQU5ZX05BTUUBAAAA+Z97AAMAAAARTm9vZGxlcyAmIENvbXBhbnkAgh78VC/r1QhuXjSKL+vVCCZDSVEuS1IuSVFfRlhfUkFURV9GQy5BUFIyMDIwLjgvMjQvMjAxNwEAAADEMZQGAgAAAAoxMTI4Ljg0NjM5AKo+Sn0t69UIAT9mfS3r1QgmQ0lRLkhBQlQuSVFfTUFSS0VUQ0FQLjIwMTgtMDctMTAuVVNELkgBAAAAI9YREAIAAAAKMjE1LjI5NTUyOAEG | E1: AAAABQAAAAExAQAAAAoxODg2NDUxNTgyAwAAAAMxNjACAAAABjEwMDA1NAQAAAABMAcAAAAJNy8xMC8yMDE4gh78VC/r1QhWhTSKL+vVCDFDSVEuWk9FUy5JUV9QUkVGX0VRVUlUWS41MDAuMjAxOC0wNy0xMC5MRlIuLlVTRC5IAQAAANTGTwIDAAAAAACCHvxUL+vVCFaFNIov69UII0NJUS5LUi5JUV9GWF9SQVRFLkRFQzIwMTUuOC8yNS8yMDE3AQAAAMhLkwYCAAAACzExNzIuMjEzMDQzAKo+Sn0t69UI+IxmfS3r1QgrQ0lRLk5ZU0U6U0hBSy5JUV9NQVJLRVRDQVAuMjAxOC0wNy0xMC5VU0QuSAEAAACdE6YNAgAAAAsxNzcxLjU5MTI3NgEGAAAABQAAAAExAQAAAAoxODg3MjkwMTI1AwAAAAMxNjACAAAABjEwMDA1NAQAAAABMAcAAAAJNy8xMC8yMDE4TrdrcC/r1QhUZnS3L+vVCBxDSVEuTllTRTpTSEFLLklRX1FVSUNLX0NPTVAuAQAAAJ0Tpg0DAAAACU5ZU0U6Wk9FUwAU/BBxL+vVCBT8EHEv69UII0NJUS5LUi5JUV9GWF9SQVRFLkpVTDIwMTMuOC8yNS8yMDE3AQAAAMhLkwYCAAAACzExMjYuNTc4MjYxAKo+Sn0t69UI+IxmfS3r1QgsQ0lRQVZHLk1DRC5JUV9FRkZFQ1RfVEFYX1JBVEUuOTk2LjIwMTgtMDctMTABAAAA4CACAAIAAAAIMzMuODkzODgAgh78VC/r1QhuXjSKL+vVCC9DSVEuTllTRTpTSEFLLklRX1BFUklPRERBVEUuMTAwMC4yMDE4LTA3LTEwLkxGUgEAAACdE6YNBQAAAAoyMDE3LTEy | F1: LTI3AE63a3Av69UIVGZ0ty/r1QgjQ0lRLktSLklRX0ZYX1JBVEUuTUFZMjAxMy44LzI1LzIwMTcBAAAAyEuTBgIAAAALMTExMC40OTU2NTIAvhdKfS3r1Qj4jGZ9LevVCCNDSVEuS1IuSVFfRlhfUkFURS5KVU4yMDEzLjgvMjUvMjAxNwEAAADIS5MGAgAAAAcxMTM0LjU0AKo+Sn0t69UI+IxmfS3r1QgjQ0lRLktSLklRX0ZYX1JBVEUuSkFOMjAxNS44LzI1LzIwMTcBAAAAyEuTBgIAAAALMTA4OS42NDA5MDkAqj5KfS3r1QgHZmZ9LevVCCZDSVEuS1IuSVFfRlhfUkFURV9GQy5KQU4yMDE5LjgvMjQvMjAxNwEAAADEMZQGAgAAAAoxMTAxLjYwMjY3AKo+Sn0t69UIAT9mfS3r1QguQ0lRLk5ZU0U6U0hBSy5JUV9JTkNfVEFYLi4yMDE4LTA3LTEwLkxGUi4uVVNELgEAAACdE6YNAgAAAAcxNTAuOTQ5AQgAAAAFAAAAATEBAAAACjE4ODcyOTA1NDEDAAAAAzE2MAIAAAACNzUEAAAAATAHAAAACTcvMTAvMjAxOAgAAAAJMy8yOC8yMDE4CQAAAAEwFPwQcS/r1QhUZnS3L+vVCDBDSVEuQ01HLklRX1BSRUZfRVFVSVRZLjUwMC4yMDE4LTA3LTEwLkxGUi4uVVNELkgBAAAATmcAAAMAAAAAAIIe/FQv69UIUqw0ii/r1QgjQ0lRLktSLklRX0ZYX1JBVEUuU0VQMjAxMy44LzI1LzIwMTcBAAAAyEuTBgIAAAAKMTA4Ni42NzYxOQC+F0p9LevVCPiMZn0t69UIOUNJUS5OWVNFOlNIQUsuSVFfU1BfSVNTVUVSX1JBVElORy4y | G1: MDE4LTA3LTEwLkxUX0xDLlJBVElORwEAAACdE6YNAwAAAAAATrdrcC/r1QhUZnS3L+vVCB1DSVEuTllTRTpTSEFLLklRX1FVSUNLX0NPTVAuNAEAAACdE6YNAwAAAA1OYXNkYXFHTTpIQUJUAE63a3Av69UIghA0ii/r1QgdQ0lRLk5ZU0U6U0hBSy5JUV9RVUlDS19DT01QLjIBAAAAnROmDQMAAAAITllTRTpDTUcATrdrcC/r1QiCEDSKL+vVCCVDSVFQQy5eU1BYLklRX0xBU1RTQUxFUFJJQ0UuLTFZLjQwMTc4AQAAAJu4KAACAAAAEDIzLjQ1MzgxNzQxOTA1ODQATrdrcC/r1Qg8tHS3L+vVCC9DSVEuWk9FUy5JUV9UT1RBTF9ERUJULjUwMC4yMDE4LTA3LTEwLkxGUi4uVVNELgEAAADUxk8CAgAAAAY0Ny42MzQBCAAAAAUAAAABMQEAAAAKMTg5MDY1MzA5OAMAAAADMTYwAgAAAAQ0MTczBAAAAAEwBwAAAAk3LzEwLzIwMTgIAAAACTQvMTYvMjAxOAkAAAABMBT8EHEv69UIdjc0ii/r1QgdQ0lRLi5JUV9SQVRFX0xFVkVMLjIwMTgtMDctMTAFAAAAAAAAAAgAAAAUKEludmFsaWQgSWRlbnRpZmllcikU/BBxL+vVCIIQNIov69UIJkNJUS5LUi5JUV9GWF9SQVRFX0ZDLkFQUjIwMTkuOC8yNC8yMDE3AQAAAMQxlAYCAAAACjExMTEuMzM4NTYAqj5KfS3r1QgBP2Z9LevVCCZDSVEuS1IuSVFfRlhfUkFURV9GQy5KVU4yMDIwLjgvMjQvMjAxNwEAAADEMZQGAgAAAAoxMTMyLjIyNjQ0AKo+Sn0t69UIAT9mfS3r1Qge | H1: Q0lRLkNNRy5JUV9CRVRBXzVZUi4yMDE4LTA3LTEwAQAAAE5nAAACAAAAETAuNDEzMzAxODc0MzM1OTYxAIIe/FQv69UIdjc0ii/r1QglQ0lRUEMuXlNQWC5JUV9MQVNUU0FMRVBSSUNFLi0xWS4zOTgxMwEAAACbuCgAAgAAABEtMzguNDg1MjU2MzYwNzMzOQBOt2twL+vVCDy0dLcv69UILkNJUS5OWVNFOlNIQUsuSVFfUEVSSU9EREFURS41MDAuMjAxOC0wNy0xMC5MRlIBAAAAnROmDQUAAAAKMjAxOC0wMy0yOABOt2twL+vVCFRmdLcv69UIL0NJUS5XRU4uSVFfVE9UQUxfREVCVC41MDAuMjAxOC0wNy0xMC5MRlIuLlVTRC5IAQAAAAVcAAACAAAACDI4MDguMDIxAQgAAAAFAAAAATEBAAAACjE4ODgwNTUxODADAAAAAzE2MAIAAAAENDE3MwQAAAABMAcAAAAJNy8xMC8yMDE4CAAAAAg0LzEvMjAxOAkAAAABMIIe/FQv69UIVoU0ii/r1QgcQ0lRLklRVDM2MTgzODM5LklRX1JBVEVfTkFNRQEAAAAdHygCAwAAADJVbml0ZWQgU3RhdGVzIFRyZWFzdXJ5IENvbnN0YW50IE1hdHVyaXR5IC0gMTAgWWVhcgBOt2twL+vVCFRmdLcv69UIJUNJUVBDLl5TUFguSVFfTEFTVFNBTEVQUklDRS4tMVkuNDMxMDABAAAAm7goAAIAAAAQMTkuNDIwMTY1MjU4NzMxOQBOt2twL+vVCFCNdLcv69UIJkNJUS5LUi5JUV9GWF9SQVRFX0ZDLk1BUjIwMTkuOC8yNC8yMDE3AQAAAMQxlAYCAAAACTExMDguMjMwOQCqPkp9LevVCAE/ | I1: Zn0t69UIJUNJUS5DTUcuSVFfTUFSS0VUQ0FQLjIwMTgtMDctMTAuVVNELkgBAAAATmcAAAIAAAALMTI2MjQuMDE5MzIBBgAAAAUAAAABMQEAAAAKMTg4NDk2MzMzMAMAAAADMTYwAgAAAAYxMDAwNTQEAAAAATAHAAAACTcvMTAvMjAxOIIe/FQv69UIVoU0ii/r1QgjQ0lRLktSLklRX0ZYX1JBVEUuSkFOMjAxMy44LzI1LzIwMTcBAAAAyEuTBgIAAAALMTA2NS45ODY5NTcAvhdKfS3r1Qj4jGZ9LevVCCBDSVEuTllTRTpTSEFLLklRX0lORFVTVFJZX1NFQ1RPUgEAAACdE6YNAwAAABZDb25zdW1lciBEaXNjcmV0aW9uYXJ5AE63a3Av69UIVGZ0ty/r1QgRQ0lRLi5JUV9SQVRFX05BTUUFAAAAAAAAAAgAAAAUKEludmFsaWQgSWRlbnRpZmllcikU/BBxL+vVCIIQNIov69UIL0NJUS5XRU4uSVFfUFJFRl9FUVVJVFkuNTAwLjIwMTgtMDctMTAuTEZSLi5VU0QuAQAAAAVcAAADAAAAAAAU/BBxL+vVCG5eNIov69UILENJUS5OWVNFOlNIQUsuSVFfUEVSSU9EREFURS4xMDAwLjIwMTgtMDctMTAuAQAAAJ0Tpg0FAAAACjIwMTctMTItMjcAFPwQcS/r1QhsP3S3L+vVCCVDSVEuTUNELklRX01BUktFVENBUC4yMDE4LTA3LTEwLlVTRC5IAQAAAOAgAgACAAAADTEyNjExNS4xOTM2NjcBBgAAAAUAAAABMQEAAAAKMTg4NzY2NTU5NgMAAAADMTYwAgAAAAYxMDAwNTQEAAAAATAHAAAACTcvMTAvMjAxOIIe/FQv69UIVEQk | J1: iy/r1QhCQ0lRLlVTRC5JUV9GVUxMX0NVUlZFX0FOTlVBTC5DT05TVU1FUkRJU0NSRVRJT05BUlkuMC41WS4yMDE4LTA3LTEwAQAAAAAAAAACAAAACTAuMDM4MjYyOQCVeTNUL+vVCFaFNIov69UII0NJUS5LUi5JUV9GWF9SQVRFLk1BWTIwMTUuOC8yNS8yMDE3AQAAAMhLkwYCAAAACzEwODkuMjgwOTUyAKo+Sn0t69UIB2ZmfS3r1QguQ0lRLk1DRC5JUV9UT1RBTF9ERUJULjUwMC4yMDE4LTA3LTEwLkxGUi4uVVNELgEAAADgIAIAAgAAAAUzMDg4OAEIAAAABQAAAAExAQAAAAoxODg3NjY1NTk2AwAAAAMxNjACAAAABDQxNzMEAAAAATAHAAAACTcvMTAvMjAxOAgAAAAJMy8zMS8yMDE4CQAAAAEwBOAdiy/r1QgE4B2LL+vVCCRDSVEuTllTRTpTSEFLLklRX0JFVEFfNVlSLjIwMTgtMDctMTABAAAAnROmDQIAAAAQMS4zNDc2NDIyNjAzNTM5NABOt2twL+vVCFRmdLcv69UIJkNJUS5LUi5JUV9GWF9SQVRFX0ZDLkZFQjIwMTkuOC8yNC8yMDE3AQAAAMQxlAYCAAAACjExMDUuMDkwNjIAqj5KfS3r1QgBP2Z9LevVCCNDSVEuS1IuSVFfRlhfUkFURS5KVUwyMDE2LjgvMjUvMjAxNwEAAADIS5MGAgAAAAsxMTQ0LjMzMzMzMwCqPkp9LevVCAdmZn0t69UIH0NJUS5LUi5JUV9GWF9SQVRFX0ZDLi44LzI0LzIwMTcBAAAARJe+BgMAAAAAAKo+Sn0t69UIqj5KfS3r1QgXQ0lRLkNNRy5JUV9DT01QQU5ZX05BTUUBAAAA | K1: TmcAAAMAAAAcQ2hpcG90bGUgTWV4aWNhbiBHcmlsbCwgSW5jLgCCHvxUL+vVCG5eNIov69UIJkNJUS5LUi5JUV9GWF9SQVRFX0ZDLkpVTjIwMTkuOC8yNC8yMDE3AQAAAMQxlAYCAAAACjExMTUuMTY0NjcAqj5KfS3r1QgBP2Z9LevVCCpDSVEuTkFTREFRR1M6V0VOLklRX0NPTVBBTllfVElDS0VSX05PX0VYQ0gBAAAABVwAAAMAAAADV0VOAKFSM1Qv69UIghA0ii/r1QgmQ0lRLktSLklRX0ZYX1JBVEVfRkMuRkVCMjAyMC44LzI0LzIwMTcBAAAAxDGUBgIAAAAKMTExMS4xODA4MwCqPkp9LevVCAE/Zn0t69UII0NJUS5LUi5JUV9GWF9SQVRFLk1BWTIwMTcuOC8yNS8yMDE3AQAAAMhLkwYCAAAACzExMjYuMzA4Njk2AKo+Sn0t69UIB2ZmfS3r1QgjQ0lRLktSLklRX0ZYX1JBVEUuSlVMMjAxNy44LzI1LzIwMTcBAAAAyEuTBgIAAAALMTEzMy45MzgwOTUAqj5KfS3r1QgBP2Z9LevVCDBDSVEuSEFCVC5JUV9UT1RBTF9ERUJULjUwMC4yMDE4LTA3LTEwLkxGUi4uVVNELkgBAAAAI9YREAIAAAAGMTcuMjIxAQgAAAAFAAAAATEBAAAACjE4ODY0NTE1ODIDAAAAAzE2MAIAAAAENDE3MwQAAAABMAcAAAAJNy8xMC8yMDE4CAAAAAkzLzI3LzIwMTgJAAAAATCCHvxUL+vVCFaFNIov69UII0NJUS5LUi5JUV9GWF9SQVRFLkpVTDIwMTQuOC8yNS8yMDE3AQAAAMhLkwYCAAAACzEwMTkuOTM0NzgzAKo+Sn0t69UI+Ixm | L1: fS3r1QgvQ0lRLkhBQlQuSVFfVE9UQUxfREVCVC41MDAuMjAxOC0wNy0xMC5MRlIuLlVTRC4BAAAAI9YREAIAAAAGMTcuMjIxAQgAAAAFAAAAATEBAAAACjE4ODY0NTE1ODIDAAAAAzE2MAIAAAAENDE3MwQAAAABMAcAAAAJNy8xMC8yMDE4CAAAAAkzLzI3LzIwMTgJAAAAATAU/BBxL+vVCHY3NIov69UII0NJUS5LUi5JUV9GWF9SQVRFLk1BUjIwMTUuOC8yNS8yMDE3AQAAAMhLkwYCAAAACzExMTIuNTY4MTgyAKo+Sn0t69UIB2ZmfS3r1QgjQ0lRLktSLklRX0ZYX1JBVEUuTUFZMjAxNi44LzI1LzIwMTcBAAAAyEuTBgIAAAALMTE2OC40NTkwOTEAqj5KfS3r1QgHZmZ9LevVCCtDSVEuTllTRTpTSEFLLklRX1BFUklPRERBVEUuNTAwLjIwMTgtMDctMTAuAQAAAJ0Tpg0FAAAACjIwMTgtMDMtMjgAFPwQcS/r1QhUZnS3L+vVCDBDSVEuTUNELklRX1BSRUZfRVFVSVRZLjUwMC4yMDE4LTA3LTEwLkxGUi4uVVNELkgBAAAA4CACAAMAAAAAAIIe/FQv69UIVEQkiy/r1QgsQ0lRLlVTRC5JUV9GVUxMX0NVUlZFX0FOTlVBTC4uLjVZLjIwMTgtMDctMTABAAAAAAAAAAIAAAAJMC4wMzg3OTU3AKFSM1Qv69UIghA0ii/r1QgjQ0lRLktSLklRX0ZYX1JBVEUuQVVHMjAxNS44LzI1LzIwMTcBAAAAyEuTBgIAAAALMTE3OS42MzMzMzMAqj5KfS3r1QgHZmZ9LevVCCNDSVEuS1IuSVFfRlhfUkFURS5KVUwyMDE1LjgvMjUv | M1: MjAxNwEAAADIS5MGAgAAAAsxMTQzLjAxNzM5MQCqPkp9LevVCAdmZn0t69UII0NJUS5LUi5JUV9GWF9SQVRFLkZFQjIwMTMuOC8yNS8yMDE3AQAAAMhLkwYCAAAACDEwODcuMDk1AL4XSn0t69UI+IxmfS3r1QgtQ0lRQVZHLkhBQlQuSVFfRUZGRUNUX1RBWF9SQVRFLjk5Ni4yMDE4LTA3LTEwAQAAACPWERACAAAACTM4Ljk0Njg3NQCCHvxUL+vVCHY3NIov69UIMENJUS5IQUJULklRX1BSRUZfRVFVSVRZLjUwMC4yMDE4LTA3LTEwLkxGUi4uVVNELgEAAAAj1hEQAwAAAAAAFPwQcS/r1QhuXjSKL+vVCBhDSVEuXlNQWC5JUV9DT01QQU5ZX05BTUUBAAAAm7goAAMAAAAHUyZQIDUwMABOt2twL+vVCIIQNIov69UIL0NJUS5NQ0QuSVFfUFJFRl9FUVVJVFkuNTAwLjIwMTgtMDctMTAuTEZSLi5VU0QuAQAAAOAgAgADAAAAAAAE4B2LL+vVCATgHYsv69UIGENJUS5IQUJULklRX0NPTVBBTllfTkFNRQEAAAAj1hEQAwAAABtUaGUgSGFiaXQgUmVzdGF1cmFudHMsIEluYy4Agh78VC/r1QhuXjSKL+vVCCNDSVEuS1IuSVFfRlhfUkFURS5BVUcyMDE0LjgvMjUvMjAxNwEAAADIS5MGAgAAAAsxMDI1LjQ5MDQ3NgCqPkp9LevVCPiMZn0t69UIGENJUS5aT0VTLklRX0NPTVBBTllfTkFNRQEAAADUxk8CAwAAABNab2UncyBLaXRjaGVuLCBJbmMuAIIe/FQv69UIdjc0ii/r1QglQ0lRUEMuXlNQWC5JUV9MQVNUU0FMRVBS | N1: SUNFLi0xWS40MTYzOQEAAACbuCgAAgAAABAyOS42MDExODUwNzE2NTkxAE63a3Av69UIUI10ty/r1QgjQ0lRLktSLklRX0ZYX1JBVEUuT0NUMjAxMy44LzI1LzIwMTcBAAAAyEuTBgIAAAALMTA2Ny41MTczOTEAqj5KfS3r1Qj4jGZ9LevVCCZDSVEuS1IuSVFfRlhfUkFURV9GQy5KQU4yMDIwLjgvMjQvMjAxNwEAAADEMZQGAgAAAAkxMTA4LjQ3ODMAqj5KfS3r1QgBP2Z9LevVCCNDSVEuS1IuSVFfRlhfUkFURS5BUFIyMDE2LjgvMjUvMjAxNwEAAADIS5MGAgAAAAsxMTQ3LjU5MDQ3NgCqPkp9LevVCAdmZn0t69UILENJUUFWRy5XRU4uSVFfRUZGRUNUX1RBWF9SQVRFLjk5Ni4yMDE4LTA3LTEwAQAAAAVcAAACAAAACTM1LjE4MTUyNQCCHvxUL+vVCG5eNIov69UII0NJUS5LUi5JUV9GWF9SQVRFLk9DVDIwMTYuOC8yNS8yMDE3AQAAAMhLkwYCAAAACzExMjMuNjg1NzE0AKo+Sn0t69UIB2ZmfS3r1QgmQ0lRLktSLklRX0ZYX1JBVEVfRkMuQVVHMjAxOS44LzI0LzIwMTcBAAAAxDGUBgIAAAAKMTExNi44Mjc2OQCqPkp9LevVCAE/Zn0t69UII0NJUS5LUi5JUV9GWF9SQVRFLkZFQjIwMTQuOC8yNS8yMDE3AQAAAMhLkwYCAAAABjEwNzEuNACqPkp9LevVCPiMZn0t69UIJkNJUS5LUi5JUV9GWF9SQVRFX0ZDLk5PVjIwMTguOC8yNC8yMDE3AQAAAMQxlAYCAAAACjEwOTMuMTE1NDQAqj5KfS3r1QgBP2Z9LevV | O1: CCVDSVEuTkRMUy5JUV9NQVJLRVRDQVAuMjAxOC0wNy0xMC5VU0QuAQAAAPmfewACAAAACjQ4OS44MTA0MjYBBgAAAAUAAAABMQEAAAAKMTg4ODc0NzA4MwMAAAADMTYwAgAAAAYxMDAwNTQEAAAAATAHAAAACTcvMTAvMjAxOBT8EHEv69UIdjc0ii/r1QgdQ0lRLk5ZU0U6U0hBSy5JUV9RVUlDS19DT01QLjUBAAAAnROmDQMAAAAMTmFzZGFxR1M6V0VOAE63a3Av69UIghA0ii/r1QgmQ0lRLktSLklRX0ZYX1JBVEVfRkMuT0NUMjAxOS44LzI0LzIwMTcBAAAAxDGUBgIAAAAKMTExMC4yMjYxNACqPkp9LevVCAE/Zn0t69UII0NJUS5LUi5JUV9GWF9SQVRFLkFQUjIwMTcuOC8yNS8yMDE3AQAAAMhLkwYCAAAACDExMzIuNzI1AKo+Sn0t69UIB2ZmfS3r1QgdQ0lRLk5ZU0U6U0hBSy5JUV9RVUlDS19DT01QLjMBAAAAnROmDQMAAAANTmFzZGFxR1M6TkRMUwBOt2twL+vVCIIQNIov69UIJkNJUS5ORExTLklRX01BUktFVENBUC4yMDE4LTA3LTEwLlVTRC5IAQAAAPmfewACAAAACjQ4OS44MTA0MjYBBgAAAAUAAAABMQEAAAAKMTg4ODc0NzA4MwMAAAADMTYwAgAAAAYxMDAwNTQEAAAAATAHAAAACTcvMTAvMjAxOIIe/FQv69UIVoU0ii/r1QgjQ0lRLktSLklRX0ZYX1JBVEUuU0VQMjAxNC44LzI1LzIwMTcBAAAAyEuTBgIAAAALMTAzMS4xMDQ1NDUAvhdKfS3r1Qj4jGZ9LevVCCNDSVEuS1IuSVFfRlhfUkFURS5O | P1: T1YyMDE0LjgvMjUvMjAxNwEAAADIS5MGAgAAAAkxMDk1LjQ0MDUAqj5KfS3r1Qj4jGZ9LevVCCNDSVEuS1IuSVFfRlhfUkFURS5ERUMyMDE2LjgvMjUvMjAxNwEAAADIS5MGAgAAAAsxMTgyLjA1NDU0NQCqPkp9LevVCAdmZn0t69UIHUNJUS5OWVNFOlNIQUsuSVFfQ09NUEFOWV9OQU1FAQAAAJ0Tpg0DAAAAEFNoYWtlIFNoYWNrIEluYy4AYicwGi3r1Qj9vj1SL+vVCB5DSVEuTUNELklRX0JFVEFfNVlSLjIwMTgtMDctMTABAAAA4CACAAIAAAARMC42ODE0MzUwMDM5OTcxOTkAgh78VC/r1QhuXjSKL+vVCCNDSVEuS1IuSVFfRlhfUkFURS5KVU4yMDE2LjgvMjUvMjAxNwEAAADIS5MGAgAAAAsxMTcxLjM3MjcyNwCqPkp9LevVCAdmZn0t69UII0NJUS5LUi5JUV9GWF9SQVRFLkFVRzIwMTMuOC8yNS8yMDE3AQAAAMhLkwYCAAAACzExMTYuOTU0NTQ1AKo+Sn0t69UI+IxmfS3r1QgiQ0lRLk5ZU0U6U0hBSy5JUV9DT01QQU5ZX05BTUVfTE9ORwEAAACdE6YNAwAAABxTaGFrZSBTaGFjayBJbmMuIChOWVNFOlNIQUspAE63a3Av69UIe+kzii/r1QglQ0lRLkhBQlQuSVFfTUFSS0VUQ0FQLjIwMTgtMDctMTAuVVNELgEAAAAj1hEQAgAAAAoyMTUuMjk1NTI4AQYAAAAFAAAAATEBAAAACjE4ODY0NTE1ODIDAAAAAzE2MAIAAAAGMTAwMDU0BAAAAAEwBwAAAAk3LzEwLzIwMTgU/BBxL+vVCG5eNIov69UII0NJUS5L | Q1: Ui5JUV9GWF9SQVRFLk1BUjIwMTMuOC8yNS8yMDE3AQAAAMhLkwYCAAAACzExMDEuNjA0NzYyAKo+Sn0t69UI+IxmfS3r1QgjQ0lRLktSLklRX0ZYX1JBVEUuU0VQMjAxNi44LzI1LzIwMTcBAAAAyEuTBgIAAAALMTEwNy45OTA5MDkAqj5KfS3r1QgHZmZ9LevVCCNDSVEuS1IuSVFfRlhfUkFURS5OT1YyMDE2LjgvMjUvMjAxNwEAAADIS5MGAgAAAAcxMTYxLjM1AKo+Sn0t69UIB2ZmfS3r1QgjQ0lRLktSLklRX0ZYX1JBVEUuREVDMjAxNC44LzI1LzIwMTcBAAAAyEuTBgIAAAALMTEwMy45OTU2NTIAqj5KfS3r1Qj4jGZ9LevVCCNDSVEuS1IuSVFfRlhfUkFURS5KVU4yMDE3LjgvMjUvMjAxNwEAAADIS5MGAgAAAAsxMTI5LjYyMjcyNwCqPkp9LevVCAdmZn0t69UIMENJUS5XRU4uSVFfUFJFRl9FUVVJVFkuNTAwLjIwMTgtMDctMTAuTEZSLi5VU0QuSAEAAAAFXAAAAwAAAAAAgh78VC/r1QhWhTSKL+vVCCZDSVEuS1IuSVFfRlhfUkFURV9GQy5ERUMyMDE4LjgvMjQvMjAxNwEAAADEMZQGAgAAAAoxMDk1Ljg4MzE0AKo+Sn0t69UIB2ZmfS3r1QgjQ0lRLktSLklRX0ZYX1JBVEUuSlVOMjAxNC44LzI1LzIwMTcBAAAAyEuTBgIAAAALMTAxOS43OTUyMzgAqj5KfS3r1Qj4jGZ9LevVCC9DSVEuQ01HLklRX1BSRUZfRVFVSVRZLjUwMC4yMDE4LTA3LTEwLkxGUi4uVVNELgEAAABOZwAAAwAAAAAAFPwQcS/r1Qh2 | R1: NzSKL+vVCCpDSVEuTllTRTpTSEFLLklRX01BUktFVENBUC4yMDE4LTA3LTEwLlVTRC4BAAAAnROmDQIAAAALMTc3MS41OTEyNzYBBgAAAAUAAAABMQEAAAAKMTg4NzI5MDEyNQMAAAADMTYwAgAAAAYxMDAwNTQEAAAAATAHAAAACTcvMTAvMjAxOBT8EHEv69UIVGZ0ty/r1QgmQ0lRLktSLklRX0ZYX1JBVEVfRkMuSlVMMjAxOS44LzI0LzIwMTcBAAAAxDGUBgIAAAAKMTExNi45MzU1OQCqPkp9LevVCAE/Zn0t69UII0NJUS5LUi5JUV9GWF9SQVRFLkpVTjIwMTUuOC8yNS8yMDE3AQAAAMhLkwYCAAAACzExMTIuMTk1NDU1AKo+Sn0t69UI+IxmfS3r1QgoQ0lRLklRVDM2MTgzODM5LklRX1JBVEVfTEVWRUwuMjAxOC0wNy0xMAEAAAAdHygCAgAAAAQyLjg3AE63a3Av69UIVoU0ii/r1QglQ0lRUEMuXlNQWC5JUV9MQVNUU0FMRVBSSUNFLi0xWS40MjAwNAEAAACbuCgAAgAAABAxMS4zOTA5NzY1NTI5MjQ2AE63a3Av69UIUI10ty/r1QgdQ0lRLk5ZU0U6U0hBSy5JUV9RVUlDS19DT01QLjEBAAAAnROmDQMAAAAJTllTRTpaT0VTAE63a3Av69UIghA0ii/r1QgvQ0lRUkFOR0UuTllTRTpTSEFLLklRX0JPTkRfTElTVC4xLjUwMC4uLi4uQk9ORFMDAAAAnROmDQAAAABOt2twL+vVCGw/dLcv69UIJUNJUVBDLl5TUFguSVFfTEFTVFNBTEVQUklDRS4tMVkuNDEyNzQBAAAAm7goAAIAAAAQMTMuNDA1MDk5MzU1NDA2 | S1: OABOt2twL+vVCFCNdLcv69UIHkNJUS4zNjAyLklRX0VWX09WRVJfTFRNX0VCSVREQQUAAAAAAAAACAAAABQoSW52YWxpZCBJZGVudGlmaWVyKU63a3Av69UIYwV6cC/r1QgwQ0lRLlpPRVMuSVFfVE9UQUxfREVCVC41MDAuMjAxOC0wNy0xMC5MRlIuLlVTRC5IAQAAANTGTwICAAAABjQ3LjYzNAEIAAAABQAAAAExAQAAAAoxODkwNjUzMDk4AwAAAAMxNjACAAAABDQxNzMEAAAAATAHAAAACTcvMTAvMjAxOAgAAAAJNC8xNi8yMDE4CQAAAAEwgh78VC/r1QhSrDSKL+vVCCVDSVFQQy5eU1BYLklRX0xBU1RTQUxFUFJJQ0UuLTFZLjQwOTA4AQAAAJu4KAACAAAAFC0wLjAwMjQ3OTQ1MDgwNzg3OTc5AE63a3Av69UIPLR0ty/r1QgXQ0lRLldFTi5JUV9DT01QQU5ZX05BTUUBAAAABVwAAAMAAAATVGhlIFdlbmR5J3MgQ29tcGFueQCCHvxUL+vVCG5eNIov69UIJkNJUS5LUi5JUV9GWF9SQVRFX0ZDLk1BWTIwMTkuOC8yNC8yMDE3AQAAAMQxlAYCAAAACjExMTMuNTQ0NzgAqj5KfS3r1QgBP2Z9LevVCB5DSVEuV0VOLklRX0JFVEFfNVlSLjIwMTgtMDctMTABAAAABVwAAAIAAAARMC41NjA1NzAxMzUxNjI1OTQAgh78VC/r1QhuXjSKL+vVCCVDSVEuV0VOLklRX01BUktFVENBUC4yMDE4LTA3LTEwLlVTRC5IAQAAAAVcAAACAAAACjQxODguNjI3NTEBBgAAAAUAAAABMQEAAAAKMTg4ODA1NTE4MAMAAAADMTYwAgAA | T1: AAYxMDAwNTQEAAAAATAHAAAACTcvMTAvMjAxOIIe/FQv69UIVoU0ii/r1QgmQ0lRLktSLklRX0ZYX1JBVEVfRkMuU0VQMjAxOC44LzI0LzIwMTcBAAAAxDGUBgIAAAAKMTA5NC4wNDczOQCqPkp9LevVCAdmZn0t69UIM0NJUS5OWVNFOlNIQUsuSVFfUFJFRl9FUVVJVFkuLjIwMTgtMDctMTAuTEZSLi5VU0QuSAEAAACdE6YNAwAAAAAATrdrcC/r1QhUZnS3L+vVCCNDSVEuS1IuSVFfRlhfUkFURS5BUFIyMDEzLjgvMjUvMjAxNwEAAADIS5MGAgAAAAsxMTIxLjgzMTgxOACqPkp9LevVCPiMZn0t69UIJUNJUVBDLl5TUFguSVFfTEFTVFNBTEVQUklDRS4tMVkuNDIzNjkBAAAAm7goAAIAAAASLTAuNzI2ODY4NjYzMTIxMzI2AE63a3Av69UIUI10ty/r1QgvQ0lRLk5ZU0U6U0hBSy5JUV9JTkNfVEFYLi4yMDE4LTA3LTEwLkxGUi4uVVNELkgBAAAAnROmDQIAAAAHMTUwLjk0OQEIAAAABQAAAAExAQAAAAoxODg3MjkwNTQxAwAAAAMxNjACAAAAAjc1BAAAAAEwBwAAAAk3LzEwLzIwMTgIAAAACTMvMjgvMjAxOAkAAAABME63a3Av69UIVGZ0ty/r1QgfQ0lRLlpPRVMuSVFfQkVUQV81WVIuMjAxOC0wNy0xMAEAAADUxk8CAgAAABEwLjE0Nzk3NDYyODU4Nzg0NgCCHvxUL+vVCG5eNIov69UII0NJUS5LUi5JUV9GWF9SQVRFLk1BUjIwMTcuOC8yNS8yMDE3AQAAAMhLkwYCAAAACzExMzUuMTA4Njk2AKo+Sn0t69UI | U1: B2ZmfS3r1QgjQ0lRLktSLklRX0ZYX1JBVEUuSkFOMjAxNC44LzI1LzIwMTcBAAAAyEuTBgIAAAAKMTA2NS43NjA4NwCqPkp9LevVCPiMZn0t69UIJkNJUS5LUi5JUV9GWF9SQVRFX0ZDLkpVTDIwMjAuOC8yNC8yMDE3AQAAAMQxlAYCAAAACjExMjEuNTM2NzcAqj5KfS3r1QgBP2Z9LevVCCNDSVEuS1IuSVFfRlhfUkFURS5NQVkyMDE0LjgvMjUvMjAxNwEAAADIS5MGAgAAAAsxMDI1Ljk5MDkwOQCqPkp9LevVCPiMZn0t69UIJkNJUS5aT0VTLklRX01BUktFVENBUC4yMDE4LTA3LTEwLlVTRC5IAQAAANTGTwICAAAACjE5NS42NDAxNTYBBgAAAAUAAAABMQEAAAAKMTg5MDY1MzA5OAMAAAADMTYwAgAAAAYxMDAwNTQEAAAAATAHAAAACTcvMTAvMjAxOIIe/FQv69UIUqw0ii/r1QgwQ0lRLk5ETFMuSVFfVE9UQUxfREVCVC41MDAuMjAxOC0wNy0xMC5MRlIuLlVTRC5IAQAAAPmfewACAAAABjYyLjg3MQEIAAAABQAAAAExAQAAAAoxODg4NzQ3MDgzAwAAAAMxNjACAAAABDQxNzMEAAAAATAHAAAACTcvMTAvMjAxOAgAAAAINC8zLzIwMTgJAAAAATCCHvxUL+vVCFaFNIov69UIJUNJUS5aT0VTLklRX01BUktFVENBUC4yMDE4LTA3LTEwLlVTRC4BAAAA1MZPAgIAAAAKMTk1LjY0MDE1NgEGAAAABQAAAAExAQAAAAoxODkwNjUzMDk4AwAAAAMxNjACAAAABjEwMDA1NAQAAAABMAcAAAAJNy8xMC8yMDE4FPwQcS/r | V1: 1Qh2NzSKL+vVCCZDSVEuS1IuSVFfRlhfUkFURV9GQy5NQVIyMDIwLjgvMjQvMjAxNwEAAADEMZQGAgAAAAoxMTE1Ljc0MjYzAKo+Sn0t69UIAT9mfS3r1QgmQ0lRLktSLklRX0ZYX1JBVEVfRkMuT0NUMjAxOC44LzI0LzIwMTcBAAAAxDGUBgIAAAAKMTA5MS40MTU3MwCqPkp9LevVCAdmZn0t69UIJkNJUS5LUi5JUV9GWF9SQVRFX0ZDLkFVRzIwMTguOC8yNC8yMDE3AQAAAMQxlAYCAAAACjEwOTIuMDM5MjMAqj5KfS3r1QgBP2Z9LevVCCNDSVEuS1IuSVFfRlhfUkFURS5NQVIyMDE2LjgvMjUvMjAxNwEAAADIS5MGAgAAAAsxMTkwLjUxNzM5MQCqPkp9LevVCAdmZn0t69UIJkNJUS5LUi5JUV9GWF9SQVRFX0ZDLk5PVjIwMTkuOC8yNC8yMDE3AQAAAMQxlAYCAAAACjExMDguOTEzNDEAqj5KfS3r1QgBP2Z9LevVCCNDSVEuS1IuSVFfRlhfUkFURS5OT1YyMDEzLjgvMjUvMjAxNwEAAADIS5MGAgAAAAsxMDYyLjcwOTUyNACqPkp9LevVCPiMZn0t69UII0NJUS5LUi5JUV9GWF9SQVRFLkpBTjIwMTYuOC8yNS8yMDE3AQAAAMhLkwYCAAAACzEyMDAuMzQyODU3AKo+Sn0t69UIB2ZmfS3r1QgjQ0lRLktSLklRX0ZYX1JBVEUuQVVHMjAxNi44LzI1LzIwMTcBAAAAyEuTBgIAAAALMTExMS4xMDg2OTYAqj5KfS3r1QgHZmZ9LevVCCxDSVFBVkcuQ01HLklRX0VGRkVDVF9UQVhfUkFURS45OTYuMjAxOC0wNy0xMAEA | W1: AABOZwAAAgAAAAgzOC4yOTUzNgCCHvxUL+vVCG5eNIov69UII0NJUS5LUi5JUV9GWF9SQVRFLkFQUjIwMTQuOC8yNS8yMDE3AQAAAMhLkwYCAAAACzEwNDQuNTU4MTgyAKo+Sn0t69UI+IxmfS3r1QgjQ0lRLktSLklRX0ZYX1JBVEUuT0NUMjAxNC44LzI1LzIwMTcBAAAAyEuTBgIAAAALMTA2MC42ODY5NTcAqj5KfS3r1Qj4jGZ9LevVCCVDSVFQQy5eU1BYLklRX0xBU1RTQUxFUFJJQ0UuLTFZLjQwNTQzAQAAAJu4KAACAAAADzEyLjc4MjA3OTAzNDM4OABOt2twL+vVCDy0dLcv69UII0NJUS5LUi5JUV9GWF9SQVRFLk1BUjIwMTQuOC8yNS8yMDE3AQAAAMhLkwYCAAAACzEwNzAuNzM4MDk1AKo+Sn0t69UI+IxmfS3r1QgfQ0lRLkhBQlQuSVFfQkVUQV81WVIuMjAxOC0wNy0xMAEAAAAj1hEQAgAAABEwLjUyMzI4OTkwNzM4MjQ5NgCCHvxUL+vVCG5eNIov69UII0NJUS5LUi5JUV9GWF9SQVRFLkpBTjIwMTcuOC8yNS8yMDE3AQAAAMhLkwYCAAAACzExODYuMDI3MjczAKo+Sn0t69UIB2ZmfS3r1QgcQ0lRLktSLklRX0ZYX1JBVEUuLjgvMjUvMjAxNwEAAABEl74GAwAAAAAAqj5KfS3r1QiqPkp9LevVCCNDSVEuS1IuSVFfRlhfUkFURS5GRUIyMDE2LjgvMjUvMjAxNwEAAADIS5MGAgAAAAsxMjE0LjgzODA5NQCqPkp9LevVCAdmZn0t69UIMkNJUS5OWVNFOlNIQUsuSVFfUFJFRl9FUVVJVFkuLjIwMTgtMDct | X1: MTAuTEZSLi5VU0QuAQAAAJ0Tpg0DAAAAAAAU/BBxL+vVCFRmdLcv69UIJENJUS5XRU4uSVFfTUFSS0VUQ0FQLjIwMTgtMDctMTAuVVNELgEAAAAFXAAAAgAAAAo0MTg4LjYyNzUxAQYAAAAFAAAAATEBAAAACjE4ODgwNTUxODADAAAAAzE2MAIAAAAGMTAwMDU0BAAAAAEwBwAAAAk3LzEwLzIwMTgU/BBxL+vVCG5eNIov69UILkNJUS5XRU4uSVFfVE9UQUxfREVCVC41MDAuMjAxOC0wNy0xMC5MRlIuLlVTRC4BAAAABVwAAAIAAAAIMjgwOC4wMjEBCAAAAAUAAAABMQEAAAAKMTg4ODA1NTE4MAMAAAADMTYwAgAAAAQ0MTczBAAAAAEwBwAAAAk3LzEwLzIwMTgIAAAACDQvMS8yMDE4CQAAAAEwFPwQcS/r1QhuXjSKL+vVCB9DSVEuTkRMUy5JUV9CRVRBXzVZUi4yMDE4LTA3LTEwAQAAAPmfewACAAAAES0wLjYyNzcyNzE0MTM4Nzg4AIIe/FQv69UIbl40ii/r1QgmQ0lRLk5ZU0U6Q01HLklRX0NPTVBBTllfVElDS0VSX05PX0VYQ0gBAAAATmcAAAMAAAADQ01HAKFSM1Qv69UIghA0ii/r1QglQ0lRUEMuXlNQWC5JUV9MQVNUU0FMRVBSSUNFLi0xWS40MjczNQEAAACbuCgAAgAAABA5LjUzNTAyMTQ4NzU1ODU3AE63a3Av69UIUI10ty/r1QgjQ0lRLktSLklRX0ZYX1JBVEUuQVBSMjAxNS44LzI1LzIwMTcBAAAAyEuTBgIAAAALMTA4OC42NjM2MzYAqj5KfS3r1QgHZmZ9LevVCCNDSVEuS1IuSVFfRlhfUkFURS5P | Y1: Q1QyMDE1LjgvMjUvMjAxNwEAAADIS5MGAgAAAAsxMTQ5LjIxODE4MgCqPkp9LevVCPiMZn0t69UIMUNJUS5ORExTLklRX1BSRUZfRVFVSVRZLjUwMC4yMDE4LTA3LTEwLkxGUi4uVVNELkgBAAAA+Z97AAMAAAAAAIIe/FQv69UIVoU0ii/r1QgjQ0lRLktSLklRX0ZYX1JBVEUuRkVCMjAxNy44LzI1LzIwMTcBAAAAyEuTBgIAAAAGMTE0NC42AKo+Sn0t69UIB2ZmfS3r1QgmQ0lRLktSLklRX0ZYX1JBVEVfRkMuREVDMjAxOS44LzI0LzIwMTcBAAAAxDGUBgIAAAAKMTEwOC42Nzg2OQCqPkp9LevVCAE/Zn0t69UIJ0NJUS5OWVNFOlpPRVMuSVFfQ09NUEFOWV9USUNLRVJfTk9fRVhDSAEAAADUxk8CAwAAAARaT0VTAKFSM1Qv69UIghA0ii/r1QgrQ0lRLk5BU0RBUUdTOk5ETFMuSVFfQ09NUEFOWV9USUNLRVJfTk9fRVhDSAEAAAD5n3sAAwAAAARORExTAKFSM1Qv69UIghA0ii/r1QgjQ0lRLktSLklRX0ZYX1JBVEUuRkVCMjAxNS44LzI1LzIwMTcBAAAAyEuTBgIAAAAHMTEwMC42NgCqPkp9LevVCAdmZn0t69UIL0NJUS5ORExTLklRX1RPVEFMX0RFQlQuNTAwLjIwMTgtMDctMTAuTEZSLi5VU0QuAQAAAPmfewACAAAABjYyLjg3MQEIAAAABQAAAAExAQAAAAoxODg4NzQ3MDgzAwAAAAMxNjACAAAABDQxNzMEAAAAATAHAAAACTcvMTAvMjAxOAgAAAAINC8zLzIwMTgJAAAAATAU/BBxL+vVCG5eNIov69UIJENJ | Z1: US5NQ0QuSVFfTUFSS0VUQ0FQLjIwMTgtMDctMTAuVVNELgEAAADgIAIAAgAAAA0xMjYxMTUuMTkzNjY3AQYAAAAFAAAAATEBAAAACjE4ODc2NjU1OTYDAAAAAzE2MAIAAAAGMTAwMDU0BAAAAAEwBwAAAAk3LzEwLzIwMTgE4B2LL+vVCATgHYsv69UILkNJUS5DTUcuSVFfVE9UQUxfREVCVC41MDAuMjAxOC0wNy0xMC5MRlIuLlVTRC4BAAAATmcAAAIAAAABMAEIAAAABQAAAAExAQAAAAoxODg0OTYzMzMwAwAAAAMxNjACAAAABDQxNzMEAAAAATAHAAAACTcvMTAvMjAxOAgAAAAJMy8zMS8yMDE4CQAAAAEwFPwQcS/r1Qh2NzSKL+vVCC1DSVFBVkcuWk9FUy5JUV9FRkZFQ1RfVEFYX1JBVEUuOTk2LjIwMTgtMDctMTABAAAA1MZPAgIAAAAIMzcuNTMwMjUAgh78VC/r1QhuXjSKL+vVCCtDSVEuTkFTREFRR006SEFCVC5JUV9DT01QQU5ZX1RJQ0tFUl9OT19FWENIAQAAACPWERADAAAABEhBQlQAoVIzVC/r1QiCEDSKL+vVCA==

Sheet Cover
B2: Shake Shack - 3 Statement Model with DCF
D6: Company name: | F6: Shake Shack | I6: Circ switch: | K6: 1
D7: Ticker: | F7: SHAK
D9: Latest update: | F9: =TODAY() -> 45835 | I9: Enterprise value: | K9: =+DCF!J47 -> 0
D10: Created by: | F10: Wall Street Training | I10: Equity value: | K10: =+DCF!J51 -> 0
I11: Target price per share: | K11: =+DCF!J55 -> 0
I12: Share price: | K12: 43.2
K13: (units in USD '000 except per share number)
C29: © 2021 Wall Street Training Asia Inc.
C30: No portion of this report may be reproduced, reused, or otherwise distributed in any form without prior written consent.
C31: For more information, please visit/contatct Wall Street Training Asia Inc. through www.wallstreettraining.co.kr
C33: © 2021 (주)월스트릿트레이닝아시아.
C34: 이 파일은 대한민국 및 미국 저작권법의 보호를 받는 저작물 입니다.
C35: 파일의 원 저자로부터 서면에 의한 허락없이 이 파일의 일부나 전체를 어떠한 형태로도 가공/배포할 수 없습니다.
C36: 이를 위반시에는 형사/민사상의 법적 책임을 질수 있으며, 특별한 문의가 있는경우 www.wallstreettraining.co.kr에 있는 정보로 연락주시기 바랍니다.

Sheet Operations
B2: Shake Shack, Inc (SHAK)
B3: Operations Analysis & Assumptions
B4: (units in USD '000)
H7: Historical Year Ending December 31, | K7: Projected year Ending December 31,
F8: 2013 | G8: =F8+1 -> 2014 | H8: =G8+1 -> 2015 | I8: =H8+1 -> 2016 | J8: =I8+1 -> 2017 | K8: =J8+1 -> 2018 | L8: =K8+1 -> 2019 | M8: =L8+1 -> 2020 | N8: =M8+1 -> 2021 | ... T8: =S8+1 -> 2027
A10: x | B10: Store
B11: Store Count (stores)
C12: Domestic Company Operated | F12: 21 | G12: 31 | H12: 44 | I12: 64 | J12: 90 | K12: =J12+K19 -> 123 | L12: =K12+L19 -> 163 | M12: =L12+M19 -> 200 | N12: =M12+N19 -> 225 | O12: =N12+O19 -> 250 | P12: =O12+P19+P23 -> 270 | Q12: =P12+Q19+Q23 -> 290 | R12: =Q12+R19+R23 -> 305 | S12: =R12+S19+S23 -> 315 | T12: =S12+T19+T23 -> 320
C13: Domestic Licensed | F13: 4 | G13: 5 | H13: 5 | I13: 7 | J13: 10 | K13: =J13+K20 -> 13 | L13: =K13+L20 -> 16 | M13: =L13+M20 -> 19 | N13: =M13+N20 -> 22 | O13: =N13+O20 -> 24 | P13: =O13+P20 -> 26 | Q13: =P13+Q20 -> 28 | R13: =Q13+R20 -> 29 | ... T13: =S13+T20 -> 31
C14: International Licensed | F14: 15 | G14: 27 | H14: 35 | I14: 43 | J14: 59 | K14: =J14+K21 -> 73 | L14: =K14+L21 -> 93 | M14: =L14+M21 -> 120 | N14: =M14+N21 -> 145 | O14: =N14+O21 -> 165 | P14: =O14+P21 -> 180 | Q14: =P14+Q21 -> 195 | R14: =Q14+R21 -> 210 | ... T14: =S14+T21 -> 230
B15: Total Stores | F15: =SUM(F12:F14) -> 40 | G15: =SUM(G12:G14) -> 63 | H15: =SUM(H12:H14) -> 84 | I15: =SUM(I12:I14) -> 114 | J15: =SUM(J12:J14) -> 159 | K15: =SUM(K12:K14) -> 209 | L15: =SUM(L12:L14) -> 272 | M15: =SUM(M12:M14) -> 339 | ... T15: =SUM(T12:T14) -> 581
C16: Comp Store Base | F16: 8 | G16: 13 | H16: 21 | I16: 29 | J16: 43 | K16: 64 | L16: 90 | M16: 123 | N16: 163 | O16: 200 | P16: =N12 -> 225 | Q16: =O12 -> 250 | R16: =P12 -> 270 | S16: =Q12 -> 290 | T16: =R12 -> 305
B18: New Store Openings (net)
C19: Domestic Company Operated | G19: =G12-F12 -> 10 | H19: =H12-G12 -> 13 | I19: =I12-H12 -> 20 | J19: =J12-I12 -> 26 | K19: 33 | L19: 40 | M19: 37 | N19: 25 | O19: 25 | P19: 20 | Q19: 20 | R19: 15 | S19: 10 | T19: 5
C20: Domestic Licensed | G20: =G13-F13 -> 1 | H20: =H13-G13 -> 0 | I20: =I13-H13 -> 2 | J20: =J13-I13 -> 3 | K20: 3 | L20: 3 | M20: 3 | N20: 3 | O20: 2 | P20: 2 | Q20: 2 | R20: 1 | S20: 1 | T20: 1
C21: International Licensed | G21: =G14-F14 -> 12 | H21: =H14-G14 -> 8 | I21: =I14-H14 -> 8 | J21: =J14-I14 -> 16 | K21: 14 | L21: 20 | M21: 27 | N21: 25 | O21: 20 | P21: 15 | Q21: 15 | R21: 15 | S21: 10 | T21: 10
B23: Closures (implied) | G23: 0 | H23: =H16-F12 -> 0 | I23: =I16-G12 -> -2 | J23: =J16-H12 -> -1 | K23: 0 | L23: 0 | M23: 0 | N23: 0 | O23: 0 | P23: 0 | Q23: 0 | R23: 0 | S23: 0 | T23: 0
B24: New Domestic Company Store Openings (gross) | G24: =G19+ABS(G23) -> 10 | H24: =H19+ABS(H23) -> 13 | I24: =I19+ABS(I23) -> 22 | J24: =J19+ABS(J23) -> 27 | K24: =K19+ABS(K23) -> 33 | L24: =L19+ABS(L23) -> 40 | M24: =M19+ABS(M23) -> 37 | N24: =N19+ABS(N23) -> 25 | O24: =O19+ABS(O23) -> 25 | P24: =+P19-P23 -> 20 | Q24: =+Q19-Q23 -> 20 | R24: =+R19-R23 -> 15 | S24: =+S19-S23 -> 10 | T24: =+T19-T23 -> 5
A26: x | B26: Revenue
B27: System-wide Revenue | F27: 139903 | G27: 217442 | H27: 295257 | I27: 402791 | J27: 532137 | K27: =K42/2*(J15+K15) -> 675451.2 | L27: =L42/2*(K15+L15) -> 854531.99 | M27: =M42/2*(L15+M15) -> 1063939.5 | N27: =N42/2*(M15+N15) -> 1269105.6 | O27: =O42/2*(N15+O15) -> 1439397.4 | P27: =P28+P31 -> 0 | Q27: =Q28+Q31 -> 0 | R27: =R28+R31 -> 0 | S27: =S28+S31 -> 0 | T27: =T28+T31 -> 0
B28: Licensed Location Revenue | F28: 61316 | G28: 105400 | H28: 112038 | I28: 143441 | J28: 185749 | K28: =K41/2*(J13+J14+K13+K14) -> 234683.72 | L28: =L41/2*(K13+K14+L13+L14) -> 292294.78 | M28: =M41/2*(L13+L14+M13+M14) -> 371739.01 | N28: =N41/2*(M13+M14+N13+N14) -> 458677.97 | O28: =O41/2*(N13+N14+O13+O14) -> 533625.35 | P28: =P41*(SUM(P13:P14)+SUM(O13:O14))/2 -> 0 | Q28: =Q41*(SUM(Q13:Q14)+SUM(P13:P14))/2 -> 0 | R28: =R41*(SUM(R13:R14)+SUM(Q13:Q14))/2 -> 0 | S28: =S41*(SUM(S13:S14)+SUM(R13:R14))/2 -> 0 | T28: =T41*(SUM(T13:T14)+SUM(S13:S14))/2 -> 0
B30: Corporate Revenue | F30: =+F31+F32 -> 82456 | G30: =+G31+G32 -> 118530 | H30: =+H31+H32 -> 190592 | I30: =+I31+I32 -> 268475 | J30: =+J31+J32 -> 358810 | K30: =K31+K32 -> 456021.93 | L30: =L31+L32 -> 581236.37 | M30: =M31+M32 -> 716363.54 | N30: =N31+N32 -> 840241.65 | O30: =O31+O32 -> 940457.65 | P30: =SUM(P31:P32) -> 0 | Q30: =SUM(Q31:Q32) -> 0 | R30: =SUM(R31:R32) -> 0 | S30: =SUM(S31:S32) -> 0 | T30: =SUM(T31:T32) -> 0
B31: Company Operated Stores Revenue | F31: 78587 | G31: 112042 | H31: 183219 | I31: 259350 | J31: 346388 | K31: =K40/2*(J12+K12) -> 440767.48 | L31: =L40/2*(K12+L12) -> 562237.21 | M31: =M40/2*(L12+M12) -> 692200.5 | N31: =N40/2*(M12+N12) -> 810427.58 | O31: =O40/2*(N12+O12) -> 905772.01 | P31: =P40*AVERAGE(O12:P12) -> 0 | Q31: =Q40*AVERAGE(P12:Q12) -> 0 | R31: =R40*AVERAGE(Q12:R12) -> 0 | S31: =S40*AVERAGE(R12:S12) -> 0 | T31: =T40*AVERAGE(S12:T12) -> 0
B32: Licensing Revenue | F32: 3869 | G32: 6488 | H32: 7373 | I32: 9125 | J32: 12422 | K32: =K28*K33 -> 15254.442 | L32: =L28*L33 -> 18999.161 | M32: =M28*M33 -> 24163.035 | N32: =N28*N33 -> 29814.068 | O32: =O28*O33 -> 34685.648 | P32: =P33*P28 -> 0 | Q32: =Q33*Q28 -> 0 | R32: =R33*R28 -> 0 | S32: =S33*S28 -> 0 | T32: =T33*T28 -> 0
C33: Royalty Rate | F33: =F32/F28 -> 0.063099354 | G33: =G32/G28 -> 0.061555977 | H33: =H32/H28 -> 0.065808029 | I33: =I32/I28 -> 0.063615005 | J33: =J32/J28 -> 0.066875192 | K33: 0.065 | L33: 0.065 | M33: 0.065 | N33: 0.065 | O33: 0.065 | P33: 0.065 | Q33: 0.065 | R33: 0.065 | S33: 0.065 | T33: 0.065
B35: Avg Unit Volume (Reported)
C36: Domestic Company Operated | F36: 5017 | G36: 4611 | H36: 4976 | I36: 4981 | J36: 4598
C37: International Licensed | F37: 6077 | G37: 4588 | H37: 3413 | I37: 3334 | J37: 3176
B39: Avg Unit Volume (Implied)
C40: Domestic Company Operated | G40: =G31/(F12+G12)*2 -> 4309.3077 | H40: =H31/(G12+H12)*2 -> 4885.84 | I40: =I31/(H12+I12)*2 -> 4802.7778 | J40: =J31/(I12+J12)*2 -> 4498.5455 | K40: =J40*(1+K45) -> 4138.6618 | L40: =K40*(1+L45) -> 3931.7287 | M40: =L40*(1+M45) -> 3813.7769 | N40: =M40*(1+N45) -> 3813.7769 | O40: =N40*(1+O45) -> 3813.7769
C41: Licensed (total) | G41: =G28/(F13+F14+G13+G14)*2 -> 4133.3333 | H41: =H28/(G13+G14+H13+H14)*2 -> 3112.1667 | I41: =I28/(H13+H14+I13+I14)*2 -> 3187.5778 | J41: =J28/(I13+I14+J13+J14)*2 -> 3121.8319 | K41: =J41*(1+K46) -> 3028.177 | L41: =K41*(1+L46) -> 2997.8952 | M41: =L41*(1+M46) -> 2997.8952 | N41: =M41*(1+N46) -> 2997.8952 | O41: =N41*(1+O46) -> 2997.8952
C42: Systemwide | G42: =G27/(F15+G15)*2 -> 4222.1748 | H42: =H27/(G15+H15)*2 -> 4017.102 | I42: =I27/(H15+I15)*2 -> 4068.596 | J42: =J27/(I15+J15)*2 -> 3898.4396 | K42: =J42*(1+K47) -> 3670.9304 | L42: =K42*(1+L47) -> 3553.1476 | M42: =L42*(1+M47) -> 3482.617 | N42: =M42*(1+N47) -> 3472.245 | O42: =N42*(1+O47) -> 3464.2536
B44: Avg Unit Volume (% yoy)
C45: Domestic Company Operated | H45: =(H40-G40)/G40 -> 0.13378769 | I45: =(I40-H40)/H40 -> -0.017000602 | J45: =(J40-I40)/I40 -> -0.063345076 | K45: -0.08 | L45: -0.05 | M45: -0.03 | N45: 0 | O45: 0 | P45: 0 | Q45: 0 | R45: 0 | S45: 0 | T45: 0
C46: Licensed (total) | H46: =(H41-G41)/G41 -> -0.24705645 | I46: =(I41-H41)/H41 -> 0.024231064 | J46: =(J41-I41)/I41 -> -0.020625644 | K46: -0.03 | L46: -0.01 | M46: 0 | N46: 0 | O46: 0 | P46: 0 | Q46: 0 | R46: 0 | S46: 0 | T46: 0 | U46: << add f/x conversion
C47: Systemwide | H47: =(H42-G42)/G42 -> -0.0485704 | I47: =(I42-H42)/H42 -> 0.012818673 | J47: =(J42-I42)/I42 -> -0.041821897 | K47: -0.058359025 | L47: -0.032085288 | M47: -0.019850154 | N47: -0.0029782301 | O47: -0.0023015233 | P47: =P42/O42-1 -> -1 | Q47: =Q42/P42-1 -> #DIV/0! | R47: =R42/Q42-1 -> #DIV/0! | S47: =S42/R42-1 -> #DIV/0! | T47: =T42/S42-1 -> #DIV/0!
B49: Same Shack Sales (% yoy) - Actual | G49: 0.041 | H49: 0.133 | I49: =(1+3.1%)*(1+1.1%)-1 -> 0.042341 | J49: =(1-3.2%)*(1+2%)-1 -> -0.01264
B51: Company Operated Stores Revenue
C52: Existing Shack Sales (Respt. Yr) | F52: =55600+2300 -> 57900 | G52: =F31+2300 -> 80887 | H52: =G31+10100 -> 122142 | I52: =H31+5200 -> 188419 | J52: =I31-2300 -> 257050
C53: New Shack Contribution (Respt. Yr) | F53: =F31-F52 -> 20687 | G53: =G31-G52 -> 31155 | H53: =H31-H52 -> 61077 | I53: =I31-I52 -> 70931 | J53: =J31-J52 -> 89338
...

Sheet Income Statement
B2: Shake Shack, Inc (SHAK)
B3: Income Statement
B4: (units in USD '000)
H7: Historical Year Ending December 31, | K7: Projected year Ending December 31, | V7: CAGR
F8: 2013 | G8: =F8+1 -> 2014 | H8: =G8+1 -> 2015 | I8: =H8+1 -> 2016 | J8: =I8+1 -> 2017 | K8: =J8+1 -> 2018 | L8: =K8+1 -> 2019 | M8: =L8+1 -> 2020 | N8: =M8+1 -> 2021 | ... T8: =S8+1 -> 2027 | V8: 2017-2022
A10: x | B10: Total Revenue | F10: =Operations!F30 -> 82456 | G10: =Operations!G30 -> 118530 | H10: =Operations!H30 -> 190592 | I10: =Operations!I30 -> 268475 | J10: =Operations!J30 -> 358810 | K10: =Operations!K30 -> 456021.93 | L10: =Operations!L30 -> 581236.37 | M10: =Operations!M30 -> 716363.54 | ... O10: =Operations!O30 -> 940457.65 | V10: =(O10/J10)^(1/COLUMNS(F10:J10))-1 -> 0.21253684
C11: Domestic Company Operated | F11: =Operations!F31 -> 78587 | G11: =Operations!G31 -> 112042 | H11: =Operations!H31 -> 183219 | I11: =Operations!I31 -> 259350 | J11: =Operations!J31 -> 346388 | K11: =Operations!K31 -> 440767.48 | L11: =Operations!L31 -> 562237.21 | M11: =Operations!M31 -> 692200.5 | ... O11: =Operations!O31 -> 905772.01
C12: Licensing | F12: =Operations!F32 -> 3869 | G12: =Operations!G32 -> 6488 | H12: =Operations!H32 -> 7373 | I12: =Operations!I32 -> 9125 | J12: =Operations!J32 -> 12422 | K12: =Operations!K32 -> 15254.442 | L12: =Operations!L32 -> 18999.161 | M12: =Operations!M32 -> 24163.035 | ... O12: =Operations!O32 -> 34685.648
B14: Store Level Costs | F14: =Operations!F70 -> 58168 | G14: =Operations!G70 -> 85181 | H14: =Operations!H70 -> 130345 | I14: =Operations!I70 -> 186058 | J14: =Operations!J70 -> 254079 | K14: =Operations!K70 -> 335068.2 | L14: =Operations!L70 -> 436523.53 | M14: =Operations!M70 -> 544456.84 | ... O14: =Operations!O70 -> 707890.5
A15: x | B15: Gross Profit | F15: =F10-F14 -> 24288 | G15: =G10-G14 -> 33349 | H15: =H10-H14 -> 60247 | I15: =I10-I14 -> 82417 | J15: =J10-J14 -> 104731 | K15: =K10-K14 -> 120953.73 | L15: =L10-L14 -> 144712.84 | M15: =M10-M14 -> 171906.7 | ... O15: =O10-O14 -> 232567.15 | V15: =(O15/J15)^(1/COLUMNS(F15:J15))-1 -> 0.17299085
C16: Gross Profit Margin % | F16: =F15/F10 -> 0.2945571 | G16: =G15/G10 -> 0.28135493 | H16: =H15/H10 -> 0.31610456 | I16: =I15/I10 -> 0.30698203 | J16: =J15/J10 -> 0.29188428 | K16: =K15/K10 -> 0.26523665 | L16: =L15/L10 -> 0.24897417 | M16: =M15/M10 -> 0.23997131 | ... O16: =O15/O10 -> 0.24729146
B18: SG&A | F18: =Operations!F89+Operations!F92 -> 14787 | G18: =Operations!G89+Operations!G92 -> 24292 | H18: =Operations!H89+Operations!H92 -> 43255 | I18: =Operations!I89+Operations!I92 -> 40076 | J18: =Operations!J89+Operations!J92 -> 48606 | K18: =Operations!K89+Operations!K92 -> 59022.987 | L18: =Operations!L89+Operations!L92 -> 71857.257 | M18: =Operations!M89+Operations!M92 -> 82436.781 | ... O18: =Operations!O89+Operations!O92 -> 98416.055
B19: Depreciation | F19: =Operations!F93 -> 3541 | G19: =Operations!G93 -> 5809 | H19: =Operations!H93 -> 10222 | I19: =Operations!I93 -> 14502 | J19: =Operations!J93 -> 21704 | K19: =Operations!K93 -> 29216.938 | L19: =Operations!L93 -> 36370.255 | M19: =Operations!M93 -> 42532.247 | ... O19: =Operations!O93 -> 46155.145
B20: Other Operating Costs | F20: =Operations!F94 -> 25 | G20: =Operations!G94 -> 105 | H20: =Operations!H94 -> 17 | I20: =Operations!I94 -> 34 | J20: =Operations!J94 -> 608 | K20: =Operations!K94 -> 50 | L20: =Operations!L94 -> 50 | M20: =Operations!M94 -> 50 | ... O20: =Operations!O94 -> 50
A21: x | B21: EBIT | F21: =Operations!F110 -> 5935 | G21: =Operations!G110 -> 3143 | H21: =Operations!H110 -> 6753 | I21: =Operations!I110 -> 27805 | J21: =Operations!J110 -> 33813 | K21: =Operations!K110 -> 32663.801 | L21: =Operations!L110 -> 36435.328 | M21: =Operations!M110 -> 46887.671 | ... O21: =Operations!O110 -> 87945.948 | V21: =(O21/J21)^(1/COLUMNS(F21:J21))-1 -> 0.2106718
C22: EBIT Margin % | H22: =H21/H10 -> 0.035431708 | I22: =I21/I10 -> 0.10356644 | J22: =J21/J10 -> 0.094236504 | K22: =K21/K10 -> 0.0716277 | L22: =L21/L10 -> 0.062685906 | M22: =M21/M10 -> 0.065452342 | N22: =N21/N10 -> 0.084891811 | O22: =O21/O10 -> 0.093513991
B24: Other Income | F24: 0 | G24: 0 | H24: 7 | I24: 1065 | J24: 128123 | K24: 0 | L24: 0 | M24: 0 | N24: 0 | O24: 0 | P24: 0 | Q24: 0 | R24: 0 | S24: 0 | T24: 0 | U24: 0 고정.
B25: Interest Expense/(Income) | F25: 52 | G25: 363 | H25: 332 | I25: 374 | J25: 1643 | K25: =IF(Circ=0,0,'Debt&Interest'!K55+'Debt&Interest'!K59) -> 1209.1954 | L25: =IF(Circ=0,0,'Debt&Interest'!L55+'Debt&Interest'!L59) -> 1268.3362 | M25: =IF(Circ=0,0,'Debt&Interest'!M55+'Debt&Interest'!M59) -> 1024.0566 | N25: =IF(Circ=0,0,'Debt&Interest'!N55+'Debt&Interest'!N59) -> -107.95514 | O25: =IF(Circ=0,0,'Debt&Interest'!O55+'Debt&Interest'!O59) -> -2032.4278
B26: Pre-tax Income | F26: =F21+F24-F25 -> 5883 | G26: =G21+G24-G25 -> 2780 | H26: =H21+H24-H25 -> 6428 | I26: =I21+I24-I25 -> 28496 | J26: =J21+J24-J25 -> 160293 | K26: =K21+K24-K25 -> 31454.606 | L26: =L21+L24-L25 -> 35166.992 | M26: =M21+M24-M25 -> 45863.614 | ... O26: =O21+O24-O25 -> 89978.376
B28: Income Tax | F28: 460 | G28: 662 | H28: 3304 | I28: 6350 | J28: 151409 | K28: =K26*K29 -> 6605.4673 | L28: =L26*L29 -> 7385.0683 | M28: =M26*M29 -> 9631.359 | N28: =N26*N29 -> 15001.894 | O28: =O26*O29 -> 18895.459
C29: Tax Rate % | F29: =F28/F26 -> 0.078191399 | G29: =G28/G26 -> 0.2381295 | H29: =H28/H26 -> 0.51400124 | I29: =I28/I26 -> 0.22283829 | J29: =J28/J26 -> 0.94457649 | K29: 0.21 | L29: 0.21 | M29: 0.21 | N29: 0.21 | O29: 0.21 | P29: 0.21 | Q29: 0.21 | R29: 0.21 | S29: 0.21 | T29: 0.21 | U29: 21% 고정.
A30: x | B30: Net Income | F30: =F26-F28 -> 5423 | G30: =G26-G28 -> 2118 | H30: =H26-H28 -> 3124 | I30: =I26-I28 -> 22146 | J30: =J26-J28 -> 8884 | K30: =K26-K28 -> 24849.139 | L30: =L26-L28 -> 27781.924 | M30: =M26-M28 -> 36232.255 | ... O30: =O26-O28 -> 71082.917 | V30: =(O30/J30)^(1/COLUMNS(F30:J30))-1 -> 0.51576313
C31: Net Income Margin % | F31: =F30/F10 -> 0.06576841 | G31: =G30/G10 -> 0.017868894 | H31: =H30/H10 -> 0.016391034 | I31: =I30/I10 -> 0.082488127 | J31: =J30/J10 -> 0.024759622 | K31: =K30/K10 -> 0.054491105 | L31: =L30/L10 -> 0.047797979 | M31: =M30/M10 -> 0.050578029 | ... O31: =O30/O10 -> 0.075583326
B33: Non-Controlling Interests | F33: 0 | G33: 0 | H33: 11900 | I33: 9700 | J33: 9204 | K33: 0 | L33: 0 | M33: 0 | N33: 0 | O33: 0 | P33: 0 | Q33: 0 | R33: 0 | S33: 0 | T33: 0
A34: x | B34: Net Income to Common | F34: =F30-F33 -> 5423 | G34: =G30-G33 -> 2118 | H34: =H30-H33 -> -8776 | I34: =I30-I33 -> 12446 | J34: =J30-J33 -> -320 | K34: =K30-K33 -> 24849.139 | L34: =L30-L33 -> 27781.924 | M34: =M30-M33 -> 36232.255 | ... O34: =O30-O33 -> 71082.917
B36: Diluted Shares Outstanding (in '000 shares) | H36: 20982.881 | I36: 25470.089 | J36: 27078.149 | K36: =Shares!K20 -> 37777.325 | L36: =Shares!L20 -> 37787.325 | M36: =Shares!M20 -> 37794.825 | N36: =Shares!N20 -> 37799.825 | O36: =Shares!O20 -> 37804.825
B37: Diluted Earnings Per Shares (EPS) | H37: =H30/H36 -> 0.14888327 | I37: =I30/I36 -> 0.86949048 | J37: =J30/J36 -> 0.32808742 | K37: =K30/K36 -> 0.65777921 | L37: =L30/L36 -> 0.73521806 | M37: =M30/M36 -> 0.95865653 | N37: =N30/N36 -> 1.4930148 | O37: =O30/O36 -> 1.8802605 | V37: =(O37/J37)^(1/COLUMNS(F37:J37))-1 -> 0.41790028
B39: S&P Capital IQ Consensus GAAP EPS | K39: 0.51 | L39: 0.82 | M39: 1.22 | N39: 1.57
B40: S&P Capital IQ Consensus Adjusted EPS | K40: 0.54 | L40: 0.76 | M40: 0.98 | N40: 1.57

Sheet Balance Sheet
B2: Shake Shack, Inc (SHAK)
B3: Balance Sheet
B4: (units in USD '000)
H7: Historical Year Ending December 31, | K7: Projected year Ending December 31,
F8: 2013 | G8: =F8+1 -> 2014 | H8: =G8+1 -> 2015 | I8: =H8+1 -> 2016 | J8: =I8+1 -> 2017 | K8: =J8+1 -> 2018 | L8: =K8+1 -> 2019 | M8: =L8+1 -> 2020 | N8: =M8+1 -> 2021 | ... T8: =S8+1 -> 2027
A10: x | B10: Cash & Cash Equivalents | G10: 2677 | H10: 70849 | I10: 73647 | J10: 84543 | K10: ='Cash Flow'!K41 -> 71330.965 | L10: ='Cash Flow'!L41 -> 59011.741 | M10: ='Cash Flow'!M41 -> 70073.327 | N10: ='Cash Flow'!N41 -> 128772.68 | O10: ='Cash Flow'!O41 -> 203231.14
B11: Accounts Receivable | G11: 3278 | H11: 4217 | I11: 6006 | J11: 5641 | K11: ='Working Capital'!K14 -> 7496.2508 | L11: ='Working Capital'!L14 -> 9554.5704 | M11: ='Working Capital'!M14 -> 11775.839 | N11: ='Working Capital'!N14 -> 13812.192 | O11: ='Working Capital'!O14 -> 15459.578
B12: Inventories | G12: 529 | H12: 543 | I12: 806 | J12: 1258 | K12: ='Working Capital'!K15 -> 1468.7921 | L12: ='Working Capital'!L15 -> 1913.5278 | M12: ='Working Capital'!M15 -> 2386.6601 | N12: ='Working Capital'!N15 -> 2776.4415 | O12: ='Working Capital'!O15 -> 3103.0817
B13: Prepaid Expenses & Other | G13: 1441 | H13: 3325 | I13: 3485 | J13: 1757 | K13: ='Working Capital'!K16 -> 3648.1754 | L13: ='Working Capital'!L16 -> 4649.891 | M13: ='Working Capital'!M16 -> 5730.9083 | N13: ='Working Capital'!N16 -> 6721.9332 | O13: ='Working Capital'!O16 -> 7523.6612
C14: Total Current Assets | G14: =SUM(G10:G13) -> 7925 | H14: =SUM(H10:H13) -> 78934 | I14: =SUM(I10:I13) -> 83944 | J14: =SUM(J10:J13) -> 93199 | K14: =SUM(K10:K13) -> 83944.184 | L14: =SUM(L10:L13) -> 75129.73 | M14: =SUM(M10:M13) -> 89966.734 | N14: =SUM(N10:N13) -> 152083.25 | O14: =SUM(O10:O13) -> 229317.46
B16: PP&E | G16: 70124 | H16: 93041 | I16: 136264 | J16: 187095 | K16: ='PP&E'!K30 -> 233778.06 | L16: ='PP&E'!L30 -> 285407.81 | M16: ='PP&E'!M30 -> 320575.56 | N16: ='PP&E'!N30 -> 325028.85 | O16: ='PP&E'!O30 -> 326373.71
B17: Deferred Income Taxes | G17: 161 | H17: 201957 | I17: 313207 | J17: 185914 | K17: ='Other LT Items'!K11 -> 185914 | L17: ='Other LT Items'!L11 -> 185914 | M17: ='Other LT Items'!M11 -> 185914 | N17: ='Other LT Items'!N11 -> 185914 | O17: ='Other LT Items'!O11 -> 185914
B18: Goodwill | G18: 0 | H18: 0 | I18: 0 | J18: 0 | K18: ='Other LT Items'!K12 -> 0
B19: Other Long-term Assets | G19: 4752 | H19: 5615 | I19: 4779 | J19: 4398 | K19: ='Other LT Items'!K13 -> 3898 | L19: ='Other LT Items'!L13 -> 3398 | M19: ='Other LT Items'!M13 -> 2898 | N19: ='Other LT Items'!N13 -> 2398 | O19: ='Other LT Items'!O13 -> 1898
A20: x | C20: Total Assets | G20: =SUM(G16:G19)+G14 -> 82962 | H20: =SUM(H16:H19)+H14 -> 379547 | I20: =SUM(I16:I19)+I14 -> 538194 | J20: =SUM(J16:J19)+J14 -> 470606 | K20: =SUM(K16:K19)+K14 -> 507534.25 | L20: =SUM(L16:L19)+L14 -> 549849.54 | M20: =SUM(M16:M19)+M14 -> 599354.29 | N20: =SUM(N16:N19)+N14 -> 665424.1 | O20: =SUM(O16:O19)+O14 -> 743503.17
B22: Accounts Payable | G22: 6440 | H22: 6786 | I22: 6921 | J22: 8210 | K22: ='Working Capital'!K19 -> 10097.946 | L22: ='Working Capital'!L19 -> 13155.504 | M22: ='Working Capital'!M19 -> 16408.288 | N22: ='Working Capital'!N19 -> 19088.035 | O22: ='Working Capital'!O19 -> 21333.686
B23: Accrued Expenses | G23: 5578 | H23: 6801 | I23: 8538 | J23: 11649 | K23: ='Working Capital'!K20 -> 15078.069 | L23: ='Working Capital'!L20 -> 19643.559 | M23: ='Working Capital'!M20 -> 24500.558 | N23: ='Working Capital'!N20 -> 28501.907 | O23: ='Working Capital'!O20 -> 31855.073
B24: Accrued Wages & Related | G24: 2410 | H24: 5804 | I24: 6084 | J24: 6228 | K24: ='Working Capital'!K21 -> 8376.7049 | L24: ='Working Capital'!L21 -> 10913.088 | M24: ='Working Capital'!M21 -> 13611.421 | N24: ='Working Capital'!N21 -> 15834.393 | O24: ='Working Capital'!O21 -> 17697.263
B25: Other Current Liabilities | G25: 1749 | H25: 4614 | I25: 10173 | J25: 7937 | K25: ='Working Capital'!K22 -> 11727.387 | L25: ='Working Capital'!L22 -> 15278.323 | M25: ='Working Capital'!M22 -> 19055.989 | N25: ='Working Capital'!N22 -> 22168.15 | O25: ='Working Capital'!O22 -> 24776.168
C26: Total Current Liabilities | G26: =SUM(G22:G25) -> 16177 | H26: =SUM(H22:H25) -> 24005 | I26: =SUM(I22:I25) -> 31716 | J26: =SUM(J22:J25) -> 34024 | K26: =SUM(K22:K25) -> 45280.106 | L26: =SUM(L22:L25) -> 58990.474 | M26: =SUM(M22:M25) -> 73576.256 | N26: =SUM(N22:N25) -> 85592.485 | O26: =SUM(O22:O25) -> 95662.189
B28: Revolver | G28: 32000 | H28: 0 | I28: 0 | J28: 0 | K28: ='Debt&Interest'!K43 -> 0 | L28: ='Debt&Interest'!L43 -> 0 | M28: ='Debt&Interest'!M43 -> 0 | N28: ='Debt&Interest'!N43 -> 0 | O28: ='Debt&Interest'!O43 -> 0
B29: Capital Leases | G29: 313 | H29: 313 | I29: 2007 | J29: 14518 | K29: ='Debt&Interest'!K47 -> 14018 | L29: ='Debt&Interest'!L47 -> 13018 | M29: ='Debt&Interest'!M47 -> 12018 | N29: ='Debt&Interest'!N47 -> 11018 | O29: ='Debt&Interest'!O47 -> 10018
B30: Long-term Debt | G30: 17853 | H30: 22927 | I30: 31107 | J30: 36596 | K30: ='Debt&Interest'!K51 -> 35096 | L30: ='Debt&Interest'!L51 -> 32096 | M30: ='Debt&Interest'!M51 -> 29096 | N30: ='Debt&Interest'!N51 -> 26096 | O30: ='Debt&Interest'!O51 -> 23096
B31: Other Long-term Liabilities | G31: 4019 | H31: 175283 | I31: =267902+4109 -> 272011 | J31: =158436+2553 -> 160989 | K31: ='Other LT Items'!K19 -> 159989 | L31: ='Other LT Items'!L19 -> 158989 | M31: ='Other LT Items'!M19 -> 157989 | N31: ='Other LT Items'!N19 -> 156989 | O31: ='Other LT Items'!O19 -> 155989
A32: x | C32: Total Liabilites | G32: =SUM(G28:G31)+G26 -> 70362 | H32: =SUM(H28:H31)+H26 -> 222528 | I32: =SUM(I28:I31)+I26 -> 336841 | J32: =SUM(J28:J31)+J26 -> 246127 | K32: =SUM(K28:K31)+K26 -> 254383.11 | L32: =SUM(L28:L31)+L26 -> 263093.47 | M32: =SUM(M28:M31)+M26 -> 272679.26 | N32: =SUM(N28:N31)+N26 -> 279695.49 | O32: =SUM(O28:O31)+O26 -> 284765.19
B34: Common Equity | G34: =G36-G35 -> 12600 | H34: =H36-H35 -> 100615 | I34: =I36-I35 -> 152188 | J34: =J36-J35 -> 169492 | K34: =K36-K35 -> 200164.14 | L34: =L36-L35 -> 234724.33 | M34: =M36-M35 -> 275645.29 | N34: =N36-N35 -> 335507.87 | O34: =O36-O35 -> 408431.95
B35: Non-Controlling Interests | H35: 56404 | I35: 49165 | J35: 54987 | K35: 54987 | L35: 54987 | M35: 54987 | N35: 54987 | O35: 54987 | U35: 직전년 고정
A36: x | C36: Total Equity | G36: 12600 | H36: 157019 | I36: 201353 | J36: 224479 | K36: =Equity!K17 -> 255151.14 | L36: =Equity!L17 -> 289711.33 | M36: =Equity!M17 -> 330632.29 | N36: =Equity!N17 -> 390494.87 | O36: =Equity!O17 -> 463418.95
A38: x | C38: Total Liabilities & Equity | G38: =G36+G32 -> 82962 | H38: =H36+H32 -> 379547 | I38: =I36+I32 -> 538194 | J38: =J36+J32 -> 470606 | K38: =K36+K32 -> 509534.25 | L38: =L36+L32 -> 552804.8 | M38: =M36+M32 -> 603311.54 | N38: =N36+N32 -> 670190.36 | O38: =O36+O32 -> 748184.14
C39: Check | G39: =BS!D66 -> 82962 | H39: =BS!E66 -> 379547 | I39: =BS!F66 -> 538194 | J39: =BS!G66 -> 470606
F90: =SCF!C24 -> 93 | G90: =SCF!D24 -> 165 | H90: =SCF!E24 -> 16681 | I90: =SCF!F24 -> 5354 | J90: =SCF!G24 -> 5623 | K90: 5623 | L90: 5623 | M90: 5623 | N90: 5623 | O90: 5623 | U90: FY 2017 flat
F91: =F89-F90 -> -93 | G91: =G89-G90 -> -165 | H91: =H89-H90 -> -16681 | I91: =I89-I90 -> -5354 | J91: =J89-J90 -> -5623

Sheet Cash Flow
B2: Shake Shack, Inc (SHAK)
B3: Cash Flow Statement
B4: (units in USD '000)
H7: Historical Year Ending December 31, | K7: Projected year Ending December 31,
F8: 2013 | G8: =F8+1 -> 2014 | H8: =G8+1 -> 2015 | I8: =H8+1 -> 2016 | J8: =I8+1 -> 2017 | K8: =J8+1 -> 2018 | L8: =K8+1 -> 2019 | M8: =L8+1 -> 2020 | N8: =M8+1 -> 2021 | ... T8: =S8+1 -> 2027
A10: x | B10: Operating
C11: Net Income | K11: ='Income Statement'!K30 -> 24849.139 | L11: ='Income Statement'!L30 -> 27781.924 | M11: ='Income Statement'!M30 -> 36232.255 | N11: ='Income Statement'!N30 -> 56435.696 | O11: ='Income Statement'!O30 -> 71082.917
C12: Depreciation | K12: =Operations!K93 -> 29216.938 | L12: =Operations!L93 -> 36370.255 | M12: =Operations!M93 -> 42532.247 | N12: =Operations!N93 -> 45546.708 | O12: =Operations!O93 -> 46155.145
C13: Amortization | K13: 0 | L13: 0 | M13: 0 | N13: 0 | O13: 0 | P13: 0 | Q13: 0 | R13: 0 | S13: 0 | T13: 0
C14: Stock-based Compensation Expense | K14: =Operations!K90 -> 5623 | L14: =Operations!L90 -> 5623 | M14: =Operations!M90 -> 5623 | N14: =Operations!N90 -> 5623 | O14: =Operations!O90 -> 5623
C15: Change in Working Capital | K15: ='Working Capital'!K27 -> 7298.8881 | L15: ='Working Capital'!L27 -> 10205.597 | M15: ='Working Capital'!M27 -> 10810.364 | N15: ='Working Capital'!N27 -> 8599.0702 | O15: ='Working Capital'!O27 -> 7293.9496
C16: Change in Other LT Assets & Liabilities | K16: ='Other LT Items'!K23 -> -500 | L16: ='Other LT Items'!L23 -> -500 | M16: ='Other LT Items'!M23 -> -500 | N16: ='Other LT Items'!N23 -> -500 | O16: ='Other LT Items'!O23 -> -500
D17: Cash Flow from Operations | K17: =SUM(K11:K16) -> 66487.965 | L17: =SUM(L11:L16) -> 79480.776 | M17: =SUM(M11:M16) -> 94697.867 | N17: =SUM(N11:N16) -> 115704.47 | O17: =SUM(O11:O16) -> 129655.01
A19: x | B19: Investing
C20: Capital Expenditures | K20: =-'PP&E'!K12 -> -75900 | L20: =-'PP&E'!L12 -> -88000 | M20: =-'PP&E'!M12 -> -77700 | N20: =-'PP&E'!N12 -> -50000 | O20: =-'PP&E'!O12 -> -47500
C21: Asset Sales | K21: 0 | L21: 0 | M21: 0 | N21: 0 | O21: 0
C22: Additions to Intangibles | K22: 0 | L22: 0 | M22: 0 | N22: 0 | O22: 0 | P22: 0 | Q22: 0 | R22: 0 | S22: 0 | T22: 0
D23: Cash Flow from Investing | K23: =SUM(K20:K22) -> -75900 | L23: =SUM(L20:L22) -> -88000 | M23: =SUM(M20:M22) -> -77700 | N23: =SUM(N20:N22) -> -50000 | O23: =SUM(O20:O22) -> -47500
A25: x | B25: Cash Flow Available for Financing | K25: =K17+K23 -> -9412.0346 | L25: =L17+L23 -> -8519.2241 | M25: =M17+M23 -> 16997.867 | N25: =N17+N23 -> 65704.475 | O25: =O17+O23 -> 82155.011
A27: x | B27: Financing
C28: Issuance/(Repayment) of Revolver | K28: ='Debt&Interest'!K27 -> 0 | L28: ='Debt&Interest'!L27 -> 0 | M28: ='Debt&Interest'!M27 -> 0 | N28: ='Debt&Interest'!N27 -> 0 | O28: ='Debt&Interest'!O27 -> 0
C29: Increase in Capital Leases | K29: ='Debt&Interest'!K19 -> 1000 | L29: ='Debt&Interest'!L19 -> 1000 | M29: ='Debt&Interest'!M19 -> 1000 | N29: ='Debt&Interest'!N19 -> 1000 | O29: ='Debt&Interest'!O19 -> 1000
C30: Repayment of Capital Leases | K30: ='Debt&Interest'!K20 -> -2000 | L30: ='Debt&Interest'!L20 -> -2000 | M30: ='Debt&Interest'!M20 -> -2000 | N30: ='Debt&Interest'!N20 -> -2000 | O30: ='Debt&Interest'!O20 -> -2000
C31: Increase in Long-term Debt | K31: ='Debt&Interest'!K21 -> 3000 | L31: ='Debt&Interest'!L21 -> 3000 | M31: ='Debt&Interest'!M21 -> 3000 | N31: ='Debt&Interest'!N21 -> 3000 | O31: ='Debt&Interest'!O21 -> 3000
C32: Repayment of Long-term Debt | K32: ='Debt&Interest'!K22 -> -6000 | L32: ='Debt&Interest'!L22 -> -6000 | M32: ='Debt&Interest'!M22 -> -6000 | N32: ='Debt&Interest'!N22 -> -6000 | O32: ='Debt&Interest'!O22 -> -6000
C33: Repurchase of Equity | K33: =Equity!K13 -> 0 | L33: =Equity!L13 -> 0 | M33: =Equity!M13 -> -284.21789 | N33: =Equity!N13 -> -387.59722 | O33: =Equity!O13 -> -422.69152
C34: Dividends Paid Out | K34: =Equity!K14 -> 0 | L34: =Equity!L14 -> 0 | M34: =Equity!M14 -> -1852.063 | N34: =Equity!N14 -> -2817.5206 | O34: =Equity!O14 -> -3473.865
C35: Proceeds from Options | K35: =Equity!K15 -> 200 | L35: =Equity!L15 -> 200 | M35: =Equity!M15 -> 200 | N35: =Equity!N15 -> 200 | O35: =Equity!O15 -> 200
C36: Change in Non-Controlling Interest | K36: =Equity!K16 -> 0 | L36: =Equity!L16 -> 0 | M36: =Equity!M16 -> 0 | N36: =Equity!N16 -> 0 | O36: =Equity!O16 -> 0
D37: Cash Flow from Financing | K37: =SUM(K28:K36) -> -3800 | L37: =SUM(L28:L36) -> -3800 | M37: =SUM(M28:M36) -> -5936.2809 | N37: =SUM(N28:N36) -> -7005.1178 | O37: =SUM(O28:O36) -> -7696.5565
B39: Net Change in Cash | K39: =K25+K37 -> -13212.035 | L39: =L25+L37 -> -12319.224 | M39: =M25+M37 -> 11061.586 | N39: =N25+N37 -> 58699.357 | O39: =O25+O37 -> 74458.455
C40: Beginning Cash Balance | K40: ='Balance Sheet'!J10 -> 84543 | L40: ='Balance Sheet'!K10 -> 71330.965 | M40: ='Balance Sheet'!L10 -> 59011.741 | N40: ='Balance Sheet'!M10 -> 70073.327 | O40: ='Balance Sheet'!N10 -> 128772.68
C41: Ending Cash Balance | K41: =SUM(K39:K40) -> 71330.965 | L41: =SUM(L39:L40) -> 59011.741 | M41: =SUM(M39:M40) -> 70073.327 | N41: =SUM(N39:N40) -> 128772.68 | O41: =SUM(O39:O40) -> 203231.14
A42: x

Sheet Working Capital
B2: Shake Shack, Inc (SHAK)
B3: Working Capital
B4: (units in USD '000)
H7: Historical Year Ending December 31, | K7: Projected year Ending December 31,
F8: 2013 | G8: =F8+1 -> 2014 | H8: =G8+1 -> 2015 | I8: =H8+1 -> 2016 | J8: =I8+1 -> 2017 | K8: =J8+1 -> 2018 | L8: =K8+1 -> 2019 | M8: =L8+1 -> 2020 | N8: =M8+1 -> 2021 | ... T8: =S8+1 -> 2027
A10: x | B10: Total Revenue | G10: =Operations!G30 -> 118530 | H10: =Operations!H30 -> 190592 | I10: =Operations!I30 -> 268475 | J10: =Operations!J30 -> 358810 | K10: =Operations!K30 -> 456021.93 | L10: =Operations!L30 -> 581236.37 | M10: =Operations!M30 -> 716363.54 | N10: =Operations!N30 -> 840241.65 | O10: =Operations!O30 -> 940457.65
B11: Cost of Goods Sold | G11: =Operations!G70 -> 85181 | H11: =Operations!H70 -> 130345 | I11: =Operations!I70 -> 186058 | J11: =Operations!J70 -> 254079 | K11: =Operations!K70 -> 335068.2 | L11: =Operations!L70 -> 436523.53 | M11: =Operations!M70 -> 544456.84 | N11: =Operations!N70 -> 633375.71 | O11: =Operations!O70 -> 707890.5
A13: x | B13: Working Capital Balances
C14: Accounts Receivable | G14: ='Balance Sheet'!G11 -> 3278 | H14: ='Balance Sheet'!H11 -> 4217 | I14: ='Balance Sheet'!I11 -> 6006 | J14: ='Balance Sheet'!J11 -> 5641 | K14: =K10/365*K32 -> 7496.2508 | L14: =L10/365*L32 -> 9554.5704 | M14: =M10/365*M32 -> 11775.839 | N14: =N10/365*N32 -> 13812.192 | O14: =O10/365*O32 -> 15459.578
C15: Inventories | G15: ='Balance Sheet'!G12 -> 529 | H15: ='Balance Sheet'!H12 -> 543 | I15: ='Balance Sheet'!I12 -> 806 | J15: ='Balance Sheet'!J12 -> 1258 | K15: =K11/365*K33 -> 1468.7921 | L15: =L11/365*L33 -> 1913.5278 | M15: =M11/365*M33 -> 2386.6601 | N15: =N11/365*N33 -> 2776.4415 | O15: =O11/365*O33 -> 3103.0817
C16: Prepaid Expenses & Other | G16: ='Balance Sheet'!G13 -> 1441 | H16: ='Balance Sheet'!H13 -> 3325 | I16: ='Balance Sheet'!I13 -> 3485 | J16: ='Balance Sheet'!J13 -> 1757 | K16: =K10*K34 -> 3648.1754 | L16: =L10*L34 -> 4649.891 | M16: =M10*M34 -> 5730.9083 | N16: =N10*N34 -> 6721.9332 | O16: =O10*O34 -> 7523.6612
D17: Total Non-cash Current Assets | G17: =SUM(G14:G16) -> 5248 | H17: =SUM(H14:H16) -> 8085 | I17: =SUM(I14:I16) -> 10297 | J17: =SUM(J14:J16) -> 8656 | K17: =SUM(K14:K16) -> 12613.218 | L17: =SUM(L14:L16) -> 16117.989 | M17: =SUM(M14:M16) -> 19893.407 | N17: =SUM(N14:N16) -> 23310.566 | O17: =SUM(O14:O16) -> 26086.321
C19: Accounts Payable | G19: ='Balance Sheet'!G22 -> 6440 | H19: ='Balance Sheet'!H22 -> 6786 | I19: ='Balance Sheet'!I22 -> 6921 | J19: ='Balance Sheet'!J22 -> 8210 | K19: =K11/365*K36 -> 10097.946 | L19: =L11/365*L36 -> 13155.504 | M19: =M11/365*M36 -> 16408.288 | N19: =N11/365*N36 -> 19088.035 | O19: =O11/365*O36 -> 21333.686
C20: Accrued Expenses | G20: ='Balance Sheet'!G23 -> 5578 | H20: ='Balance Sheet'!H23 -> 6801 | I20: ='Balance Sheet'!I23 -> 8538 | J20: ='Balance Sheet'!J23 -> 11649 | K20: =K$11*K37 -> 15078.069 | L20: =L$11*L37 -> 19643.559 | M20: =M$11*M37 -> 24500.558 | N20: =N$11*N37 -> 28501.907 | O20: =O$11*O37 -> 31855.073
C21: Accrued Wages & Related | G21: ='Balance Sheet'!G24 -> 2410 | H21: ='Balance Sheet'!H24 -> 5804 | I21: ='Balance Sheet'!I24 -> 6084 | J21: ='Balance Sheet'!J24 -> 6228 | K21: =K$11*K38 -> 8376.7049 | L21: =L$11*L38 -> 10913.088 | M21: =M$11*M38 -> 13611.421 | N21: =N$11*N38 -> 15834.393 | O21: =O$11*O38 -> 17697.263
C22: Other Current Liabilities | G22: ='Balance Sheet'!G25 -> 1749 | H22: ='Balance Sheet'!H25 -> 4614 | I22: ='Balance Sheet'!I25 -> 10173 | J22: ='Balance Sheet'!J25 -> 7937 | K22: =K$11*K39 -> 11727.387 | L22: =L$11*L39 -> 15278.323 | M22: =M$11*M39 -> 19055.989 | N22: =N$11*N39 -> 22168.15 | O22: =O$11*O39 -> 24776.168
D23: Total Non-debt Current Liabilities | G23: =SUM(G19:G22) -> 16177 | H23: =SUM(H19:H22) -> 24005 | I23: =SUM(I19:I22) -> 31716 | J23: =SUM(J19:J22) -> 34024 | K23: =SUM(K19:K22) -> 45280.106 | L23: =SUM(L19:L22) -> 58990.474 | M23: =SUM(M19:M22) -> 73576.256 | N23: =SUM(N19:N22) -> 85592.485 | O23: =SUM(O19:O22) -> 95662.189
B25: Net Working Capital / (Deficit) | G25: =G17-G23 -> -10929 | H25: =H17-H23 -> -15920 | I25: =I17-I23 -> -21419 | J25: =J17-J23 -> -25368 | K25: =K17-K23 -> -32666.888 | L25: =L17-L23 -> -42872.485 | M25: =M17-M23 -> -53682.849 | N25: =N17-N23 -> -62281.919 | O25: =O17-O23 -> -69575.869
A27: x | B27: (Increase) / Decrease in Net Working Capital | H27: =G25-H25 -> 4991 | I27: =H25-I25 -> 5499 | J27: =I25-J25 -> 3949 | K27: =J25-K25 -> 7298.8881 | L27: =K25-L25 -> 10205.597 | M27: =L25-M25 -> 10810.364 | N27: =M25-N25 -> 8599.0702 | O27: =N25-O25 -> 7293.9496
B29: Ratios & Assumptions
C30: Numbers of days in a period | H30: 365
C32: Accounts Receivable (Collection Period in Days) | G32: =G14/G10*Days -> 10.094238 | H32: =H14/H10*Days -> 8.0759161 | I32: =I14/I10*Days -> 8.1653413 | J32: =J14/J10*Days -> 5.7383155 | K32: 6 | L32: 6 | M32: 6 | N32: 6 | O32: 6 | P32: 6 | Q32: 6 | R32: 6 | S32: 6 | T32: 6 | U32: 6 고정
C33: Inventories (Days Outstanding) | G33: =G15/G11*Days -> 2.2667614 | H33: =H15/H11*Days -> 1.5205416 | I33: =I15/I11*Days -> 1.5811736 | J33: =J15/J11*Days -> 1.8071938 | K33: 1.6 | L33: 1.6 | M33: 1.6 | N33: 1.6 | O33: 1.6 | P33: 1.6 | Q33: 1.6 | R33: 1.6 | S33: 1.6 | T33: 1.6 | U33: 1.6 고정
C34: Other Current Assets (% of Revenue) | G34: =G16/G10 -> 0.01215726 | H34: =H16/H10 -> 0.017445643 | I34: =I16/I10 -> 0.012980724 | J34: =J16/J10 -> 0.004896742 | K34: 0.008 | L34: 0.008 | M34: 0.008 | N34: 0.008 | O34: 0.008 | P34: 0.008 | Q34: 0.008 | R34: 0.008 | S34: 0.008 | T34: 0.008 | U34: 0.8% 고정
C36: Accounts Payable (Days Outstanding) | G36: =G19/G11*Days -> 27.595356 | H36: =H19/H11*Days -> 19.00257 | I36: =I19/I11*Days -> 13.577298 | J36: =J19/J11*Days -> 11.794166 | K36: 11 | L36: 11 | M36: 11 | N36: 11 | O36: 11 | P36: 11 | Q36: 11 | R36: 11 | S36: 11 | T36: 11 | U36: 11고정
C37: Accrued Expenses (% of COGS) | G37: =G20/G$11 -> 0.065484087 | H37: =H20/H$11 -> 0.052176915 | I37: =I20/I$11 -> 0.045888916 | J37: =J20/J$11 -> 0.045847945 | K37: 0.045 | L37: 0.045 | M37: 0.045 | N37: 0.045 | O37: 0.045 | P37: 0.045 | Q37: 0.045 | R37: 0.045 | S37: 0.045 | T37: 0.045 | U37: 4.5% 고정
C38: Accrued Wages & Related (% of COGS) | G38: =G21/G$11 -> 0.028292694 | H38: =H21/H$11 -> 0.044527983 | I38: =I21/I$11 -> 0.032699481 | J38: =J21/J$11 -> 0.024512061 | K38: 0.025 | L38: 0.025 | M38: 0.025 | N38: 0.025 | O38: 0.025 | P38: 0.025 | Q38: 0.025 | R38: 0.025 | S38: 0.025 | T38: 0.025 | U38: 2.5% 고정
C39: Other Current Liabilities (% of COGS) | G39: =G22/G$11 -> 0.020532748 | H39: =H22/H$11 -> 0.035398366 | I39: =I22/I$11 -> 0.054676499 | J39: =J22/J$11 -> 0.031238316 | K39: 0.035 | L39: 0.035 | M39: 0.035 | N39: 0.035 | O39: 0.035 | P39: 0.035 | Q39: 0.035 | R39: 0.035 | S39: 0.035 | T39: 0.035 | U39: 3.5% 고정
A40: x

Sheet PP&E
B2: Shake Shack, Inc (SHAK)
B3: PP&E and Depreciation Schedule
B4: (units in USD '000)
H7: Historical Year Ending December 31, | K7: Projected year Ending December 31,
F8: 2013 | G8: =F8+1 -> 2014 | H8: =G8+1 -> 2015 | I8: =H8+1 -> 2016 | J8: =I8+1 -> 2017 | K8: =J8+1 -> 2018 | L8: =K8+1 -> 2019 | M8: =L8+1 -> 2020 | N8: =M8+1 -> 2021 | ... T8: =S8+1 -> 2027
A10: x | B10: Total Revenue | F10: ='Working Capital'!F10 -> 0 | G10: ='Working Capital'!G10 -> 118530 | H10: ='Working Capital'!H10 -> 190592 | I10: ='Working Capital'!I10 -> 268475 | J10: ='Working Capital'!J10 -> 358810 | K10: ='Working Capital'!K10 -> 456021.93 | L10: ='Working Capital'!L10 -> 581236.37 | M10: ='Working Capital'!M10 -> 716363.54 | ... O10: ='Working Capital'!O10 -> 940457.65
