Workbook
Name _toc1: 하이트진로_DART!#REF!
Name Case_Financing: #REF!
Name Case_Operating: #REF!
Name Circ: Cover!$K$6
Name Circ: #REF!
Name Circ_LBO: #REF!
Name Date: [1]WACC!$H$1
Name Days: #REF!
Name GVKey: ""
Name IQ_CH: 110000
Name IQ_CQ: 5000
Name IQ_CY: 10000
Name IQ_DAILY: 500000
Name IQ_FH: 100000
Name IQ_FQ: 500
Name IQ_FY: 1000
Name IQ_LTM: 2000
Name IQ_MONTH: 15000
Name IQ_NTM: 6000
Name IQ_WEEK: 50000
Name IQ_YTD: 3000
Name List: '[1]Input Tab'!$AD$15:$AD$19
Name SPSet: "current"
Name SPWS_WBID: "D37EBD5C-BA90-4B94-B2F1-78539D014FA9"

Sheet Cover
B2: 가치평가 시트 구성하기 | K2: OB맥주 가치평가 실습
D6: Latest update: | F6: =TODAY() -> 45831
C29: © 2021 Wall Street Training Asia Inc.
C30: No portion of this report may be reproduced, reused, or otherwise distributed in any form without prior written consent.
C31: For more information, please visit/contatct Wall Street Training Asia Inc. through www.wallstreettraining.co.kr
C33: © 2021 (주)월스트릿트레이닝아시아.
C34: 이 파일은 대한민국 및 미국 저작권법의 보호를 받는 저작물 입니다.
C35: 파일의 원 저자로부터 서면에 의한 허락없이 이 파일의 일부나 전체를 어떠한 형태로도 가공/배포할 수 없습니다.
C36: 이를 위반시에는 형사/민사상의 법적 책임을 질수 있으며, 특별한 문의가 있는경우 www.wallstreettraining.co.kr에 있는 정보로 연락주시기 바랍니다.

Sheet Trading Comps >>>
A1: OB맥주 – Trading Comps >>>
B84: =IFERROR((B79+B82)/(B66+B83),0) -> 0 | C84: =IFERROR((C79+C82)/(C66+C83),0) -> 0 | D84: =IFERROR((D79+D82)/(D66+D83),0) -> 0 | F84: =IFERROR((F79+F82)/(F66+F83),0) -> 0 | G84: =IFERROR((G79+G82)/(G66+G83),0) -> 0 | H84: =IFERROR((H79+H82)/(H66+H83),0) -> 0 | I84: =IFERROR((I79+I82)/(I66+I83),0) -> 0

Sheet Trading Comps_Input
A1: OB맥주
A2: Comparable Company Analysis ("Trading Comps") - Input
A4: x | B4: Market Data Inputs
B5: (Reported currencies in millions, except per share data)
C6: Korea | E6: Asia | G6: Other Markets
C7: Korea | D7: Korea | E7: Japan | F7: China | G7: Denmark | H7: Netherlands | I7: Canada | J7: USA
C8: KRW | D8: KRW | E8: JPY | F8: CNY | G8: DKK | H8: EUR | I8: USD | J8: USD
B9: Company Name | C9: Oriental Brewery | D9: Hite Brewery | E9: ASAHI GROUP | F9: TSINGTAO BREWERY | G9: CARLSBERG | H9: HEINEKEN | I9: MOLSON COORS | J9: BOSTON BEER
B10: Ticker | C10: OB | D10: KRX: 103150 | E10: TYO: 2502 | F10: SEHK:168 | G10: CPSE:CARL B | H10: ENXTAM:HEIA | I10: NYSE: TAP | J10: NYSE: SAM
B11: Date of latest quarter | C11: 40178 | D11: 40178 | E11: 40178 | F11: 40178 | G11: 40178 | H11: 40178 | I11: 40178 | J11: 40178
B12: Date of latest fiscal year end | C12: 40178 | D12: 40178 | E12: 40178 | F12: 40178 | G12: 40178 | H12: 40178 | I12: 40178 | J12: 40178
B13: Latest quarter | C13: Q4 | D13: Q4 | E13: Q4 | F13: Q4 | G13: Q4 | H13: Q4 | I13: Q4 | J13: Q4
B14: Stock price on current date | D14: 170000 | E14: 1732 | F14: 16.48 | G14: 396.1 | H14: 35.81 | I14: =45.92/2 -> 22.96 | J14: 47.53
B15: Preferred stock price on current date | D15: 68700
B16: Corporate tax rate (marginal tax rate) | C16: 0.242 | D16: 0.242 | E16: 0.4069 | F16: 0.25 | G16: 0.25 | H16: 0.255 | I16: 0.392 | J16: 0.392
B17: Currency conversion rate to KRW on the date below | C17: 1 | D17: 1 | E17: 12.68258 | F17: 170.70285 | G17: 224.05884 | H17: 1680.3066 | I17: 1171.5775 | J17: 1171.5775
B18: Share price date | C18: 40179 | D18: 40182 | E18: 40182 | F18: 40180 | G18: 40182 | H18: 40182 | I18: 40182 | J18: 40182
B19: Market Capitalization in USD
A21: x | B21: Shares Data
B23: Basic shares outstanding | C23: 20.11 | D23: 41.973814 | E23: 464.87462 | F23: 1315.3464 | G23: 152.55 | H23: 488.66661 | I23: 184.4 | J23: 14.059
B24: Options exercisable
B25: 1 | E25: 0.018 | G25: 0.024715 | H25: 0.032265 | I25: 7.4 | J25: 2.159604
B26: =B25+1 -> 2 | E26: 0.1966 | G26: 0.038436 | H26: 0.2814
B27: =B26+1 -> 3 | E27: 0.33 | G27: 0.045202 | H27: 0.026288
B28: =B27+1 -> 4 | E28: 0.133 | G28: 0.04429 | H28: 0.263958
B29: =B28+1 -> 5 | E29: 0.5179 | G29: 0.061938 | H29: 0.053083
B30: =B29+1 -> 6 | E30: 0.5875 | G30: 0.064416 | H30: 0.562862
B31: =B30+1 -> 7 | E31: 0.62 | G31: 0.099718
B32: =B31+1 -> 8 | G32: 0.025514
B33: =B32+1 -> 9
B34: =B33+1 -> 10
C35: =SUM(C25:C34) -> 0 | D35: =SUM(D25:D34) -> 0 | E35: =SUM(E25:E34) -> 2.403 | F35: =SUM(F25:F34) -> 0 | G35: =SUM(G25:G34) -> 0.404229 | H35: =SUM(H25:H34) -> 1.219856 | I35: =SUM(I25:I34) -> 7.4 | J35: =SUM(J25:J34) -> 2.159604
B36: Exercise price
B37: 1 | E37: 1115 | G37: 261.39 | H37: 36.03 | I37: 37 | J37: 30.23
B38: =B37+1 -> 2 | E38: 1185 | G38: 173.12 | H38: 36.03
B39: =B38+1 -> 3 | E39: 1090 | G39: 216.65 | H39: 44.22
B40: =B39+1 -> 4 | E40: 830 | G40: 232.71 | H40: 44.22
B41: =B40+1 -> 5 | E41: 1205 | G41: 306.89 | H41: 21.9
B42: =B41+1 -> 6 | E42: 1374 | G42: 472.11 | H42: 21.9
B43: =B42+1 -> 7 | E43: 1688 | G43: 446.9
...

Sheet _CIQHiddenCacheSheet
A1: 2 | B1: BAABTAVMT0NBTAFI/////wFQAwAAADBDSVEuTllTRTpJQk0uSVFfRUJJVERBX0VTVF9DSVEuRlkyMDEwLjIwMjAtMTAtMTcFAAAAAAAAAAgAAAATKENhcGFiaWxpdHkgTmVlZGVkKSxzQlbjctgIKgD79+Ry2AgmQ0lRLk5ZU0U6SUJNLklRX0VCSVREQV9FU1RfQ0lRLkZZMjAxMC4FAAAAAAAAAAgAAAATKENhcGFiaWxpdHkgTmVlZGVkKT59CVfjctgIvO0ygyBz2AgwQ0lRLk5ZU0U6SUJNLklRX0VCSVREQV9FU1RfQ0lRLkZZMjAxMC4yMDIwLTEwLTE4BQAAAAAAAAAIAAAAEyhDYXBhYmlsaXR5IE5lZWRlZCm3Ri+DIHPYCKrqsewyc9gI

Sheet 함수 실습 (실습)
C3: VLOOKUP
D4: Oriental Brewery
C5: 국내 총 선호도 | D5: =VLOOKUP(D$4,$C$10:$E$17,2,FALSE) -> 1등
C6: 국내 30대 선호도 | D6: =VLOOKUP(D$4,$C$10:$E$17,3,FALSE) -> 2등
D9: 국내 총 선호도 | E9: 국내 30대 선호도
C10: Oriental Brewery | D10: 1등 | E10: 2등
C11: Hite Brewery | D11: 5등 | E11: 3등
C12: ASAHI GROUP | D12: 3등 | E12: 5등
C13: TSINGTAO BREWERY | D13: 2등 | E13: 6등
C14: CARLSBERG | D14: 8등 | E14: 1등
C15: HEINEKEN | D15: 3등 | E15: 3등
C16: MOLSON COORS | D16: 6등 | E16: 8등
C17: BOSTON BEER | D17: 7등 | E17: 7등
C25: HLOOKUP
D26: 국내 총 선호도 | E26: 국내 30대 선호도
C27: Oriental Brewery | D27: =HLOOKUP($C$27,$C$31:$K$33,2,FALSE) -> 1등 | E27: =HLOOKUP($C$27,$C$31:$K$33,3,FALSE) -> 2등
C28: Oriental Brewery | D28: {=VLOOKUP($C$27,TRANSPOSE($C$31:$K$33),2,FALSE)} -> 1등 | E28: {=VLOOKUP($C$27,TRANSPOSE($C$31:$K$33),3,FALSE)} -> 2등
D31: Oriental Brewery | E31: Hite Brewery | F31: ASAHI GROUP | G31: TSINGTAO BREWERY | H31: CARLSBERG | I31: HEINEKEN | J31: MOLSON COORS | K31: BOSTON BEER
C32: 국내 선호도 | D32: 1등 | E32: 5등 | F32: 3등 | G32: 2등 | H32: 8등 | I32: 3등 | J32: 6등 | K32: 7등
C33: 국내 30대 선호도 | D33: 2등 | E33: 3등 | F33: 5등 | G33: 6등 | H33: 1등 | I33: 3등 | J33: 8등 | K33: 7등

Sheet 함수 실습 (정답)
C3: VLOOKUP
D4: Oriental Brewery
C5: 국내 총 선호도 | D5: =VLOOKUP(D$4,$C$10:$E$17,2,FALSE) -> 1등
C6: 국내 30대 선호도 | D6: =VLOOKUP(D$4,$C$10:$E$17,3,FALSE) -> 2등
D9: 국내 총 선호도 | E9: 국내 30대 선호도
C10: Oriental Brewery | D10: 1등 | E10: 2등
C11: Hite Brewery | D11: 5등 | E11: 3등
C12: ASAHI GROUP | D12: 3등 | E12: 5등
C13: TSINGTAO BREWERY | D13: 2등 | E13: 6등
C14: CARLSBERG | D14: 8등 | E14: 1등
C15: HEINEKEN | D15: 3등 | E15: 3등
C16: MOLSON COORS | D16: 6등 | E16: 8등
C17: BOSTON BEER | D17: 7등 | E17: 7등
C25: HLOOKUP
D26: 국내 총 선호도 | E26: 국내 30대 선호도
C27: Oriental Brewery | D27: =HLOOKUP($C27,$C$31:$K$33,2,FALSE) -> 1등 | E27: =HLOOKUP($C27,$C$31:$K$33,3,FALSE) -> 2등
D31: Oriental Brewery | E31: Hite Brewery | F31: ASAHI GROUP | G31: TSINGTAO BREWERY | H31: CARLSBERG | I31: HEINEKEN | J31: MOLSON COORS | K31: BOSTON BEER
C32: 국내 선호도 | D32: 1등 | E32: 5등 | F32: 3등 | G32: 2등 | H32: 8등 | I32: 3등 | J32: 6등 | K32: 7등
C33: 국내 30대 선호도 | D33: 2등 | E33: 3등 | F33: 5등 | G33: 6등 | H33: 1등 | I33: 3등 | J33: 8등 | K33: 7등

Sheet Trading Comps_Output (실습)
A1: OB맥주
A2: Comparable Company Analysis ("Trading Comps") - Output
B4: Company name | C4: Ticker | D4: Market capitalization (mm) | E4: Enterprise value (EV) | F4: Revenues - LFY | G4: EBITDA - LFY | H4: EBIT - LFY | I4: EPS - LFY | J4: Revenues - Calendar year 1 | K4: EBITDA - Calendar year 1 | L4: EBIT - Calendar year 1 | M4: EPS - Calendar year 1 | N4: Long-term growth rate | O4: Net debt | P4: Diluted shares outstanding (mm)
F5: EV / Revenues - LFY | G5: EV / EBITDA - LFY | H5: EV / EBIT - LFY | I5: P/E - LFY | J5: EV / Revenues - Year 1 | K5: EV / EBITDA - Year 1 | L5: EV / EBIT - Year 1 | M5: P/E - Year 1 | N5: PE/LTG (PEG ratio)
B7: 재무정보 요약
B9: 단순 링크
F11: Last Fiscal Year (LTM) | J11: Year 1 Forecast - Calendar Year
B12: Name | C12: Ticker | D12: Market cap (mm) | E12: Enterprise value | F12: Revenues | G12: EBITDA | H12: EBIT | I12: EPS | J12: Revenues | K12: EBITDA | L12: EBIT | M12: EPS | N12: LT growth rate | O12: Net debt | P12: Diluted shares outstanding
B13: Place target in first position
B14: Oriental Brewery | C14: =+'Trading Comps_Input'!C10 -> OB | F14: =+'Trading Comps_Input'!C109 -> 816110.19 | G14: =+'Trading Comps_Input'!C110 -> 251435.45 | H14: =+'Trading Comps_Input'!C111 -> 196305.66 | I14: =+'Trading Comps_Input'!C112 -> 6629.0535 | J14: =+'Trading Comps_Input'!C129 -> 840593.49 | K14: =+'Trading Comps_Input'!C130 -> 258978.51 | L14: =+'Trading Comps_Input'!C131 -> 202194.82 | M14: =+'Trading Comps_Input'!C132 -> 6827.9251 | N14: =+'Trading Comps_Input'!C146 -> 0.025 | O14: =+'Trading Comps_Input'!C123 -> 301945.91 | P14: =+'Trading Comps_Input'!C168 -> 20.611 | S14: ①
B15: HITE Brewery | C15: =+'Trading Comps_Input'!D10 -> KRX: 103150 | D15: =+'Trading Comps_Input'!D170 -> 1624834.8 | E15: =+'Trading Comps_Input'!D173 -> 2618390.5 | F15: =+'Trading Comps_Input'!D109 -> 1049536 | G15: =+'Trading Comps_Input'!D110 -> 259614.51 | H15: =+'Trading Comps_Input'!D111 -> 187129.78 | I15: =+'Trading Comps_Input'!D112 -> 10921.965 | J15: =+'Trading Comps_Input'!D129 -> 1066105.2 | K15: =+'Trading Comps_Input'!D130 -> 232221.75 | L15: =+'Trading Comps_Input'!D131 -> 151914.49 | M15: =+'Trading Comps_Input'!D132 -> 6821.3098 | N15: =+'Trading Comps_Input'!D146 -> 0.025 | O15: =+'Trading Comps_Input'!D123 -> 993555.63 | P15: =+'Trading Comps_Input'!D168 -> 9.557852 | S15: ②
B16: ASAHI GROUP | C16: =+'Trading Comps_Input'!E10 -> TYO: 2502 | D16: =+'Trading Comps_Input'!E170 -> 806123.85 | E16: =+'Trading Comps_Input'!E173 -> 1184147.9 | F16: =+'Trading Comps_Input'!E109 -> 1022318 | G16: =+'Trading Comps_Input'!E110 -> 141149 | H16: =+'Trading Comps_Input'!E111 -> 82777 | I16: =+'Trading Comps_Input'!E112 -> 103.09653 | J16: =+'Trading Comps_Input'!E129 -> 1084231.5 | K16: =+'Trading Comps_Input'!E130 -> 162376.01 | L16: =+'Trading Comps_Input'!E131 -> 95386.573 | M16: =+'Trading Comps_Input'!E132 -> 115.68564 | N16: =+'Trading Comps_Input'!E146 -> 0.035 | O16: =+'Trading Comps_Input'!E123 -> 378024 | P16: =+'Trading Comps_Input'!E168 -> 465.42948 | S16: ③
B17: TSINGTAO BREWERY | C17: =+'Trading Comps_Input'!F10 -> SEHK:168 | D17: =+'Trading Comps_Input'!F170 -> 21676.909 | E17: =+'Trading Comps_Input'!F173 -> 17888.829 | F17: =+'Trading Comps_Input'!F109 -> 18026.108 | G17: =+'Trading Comps_Input'!F110 -> 2065.4427 | H17: =+'Trading Comps_Input'!F111 -> 1520.6809 | I17: =+'Trading Comps_Input'!F112 -> 0.95009959 | J17: =+'Trading Comps_Input'!F129 -> 20524.904 | K17: =+'Trading Comps_Input'!F130 -> 2486.2697 | L17: =+'Trading Comps_Input'!F131 -> 1905.3395 | M17: =+'Trading Comps_Input'!F132 -> 1.129899 | N17: =+'Trading Comps_Input'!F146 -> 0.035 | O17: =+'Trading Comps_Input'!F123 -> -3788.0802 | P17: =+'Trading Comps_Input'!F168 -> 1315.3464
B18: CARLSBERG | C18: CPSE: CARL B | D18: =+'Trading Comps_Input'!G170 -> 60461.074 | E18: =+'Trading Comps_Input'!G173 -> 101784.07 | F18: =+'Trading Comps_Input'!G109 -> 59382 | G18: =+'Trading Comps_Input'!G110 -> 13307 | H18: =+'Trading Comps_Input'!G111 -> 9538 | I18: =+'Trading Comps_Input'!G112 -> 33.210292 | J18: =+'Trading Comps_Input'!G129 -> 60124.231 | K18: =+'Trading Comps_Input'!G130 -> 13519.078 | L18: =+'Trading Comps_Input'!G131 -> 9759.7655 | M18: =+'Trading Comps_Input'!G132 -> 33.09819 | N18: =+'Trading Comps_Input'!G146 -> 0.03 | O18: =+'Trading Comps_Input'!G123 -> 41323 | P18: =+'Trading Comps_Input'!G168 -> 152.64093 | S18: ※
B19: HEINEKEN | C19: =+'Trading Comps_Input'!H10 -> ENXTAM:HEIA | D19: =+'Trading Comps_Input'!H170 -> 17490.187 | E19: =+'Trading Comps_Input'!H173 -> 25968.187 | F19: =+'Trading Comps_Input'!H109 -> 14701 | G19: =+'Trading Comps_Input'!H110 -> 2672 | H19: =+'Trading Comps_Input'!H111 -> 1777 | I19: =+'Trading Comps_Input'!H112 -> 1.8990461 | J19: =+'Trading Comps_Input'!H129 -> 16327.516 | K19: =+'Trading Comps_Input'!H130 -> 3186.5033 | L19: =+'Trading Comps_Input'!H131 -> 1986.2587 | M19: =+'Trading Comps_Input'!H132 -> 2.711287 | N19: =+'Trading Comps_Input'!H146 -> 0.035 | O19: =+'Trading Comps_Input'!H123 -> 8478 | P19: =+'Trading Comps_Input'!H168 -> 488.41627
B20: MOLSON COORS | C20: =+'Trading Comps_Input'!I10 -> NYSE: TAP | D20: =+'Trading Comps_Input'!I170 -> 4233.824 | E20: =+'Trading Comps_Input'!I173 -> 5225.824 | F20: =+'Trading Comps_Input'!I109 -> 3032.4 | G20: =+'Trading Comps_Input'!I110 -> 631.6 | H20: =+'Trading Comps_Input'!I111 -> 423.6 | I20: =+'Trading Comps_Input'!I112 -> 0.99772668 | J20: =+'Trading Comps_Input'!I129 -> 3371.9869 | K20: =+'Trading Comps_Input'!I130 -> 639.03857 | L20: =+'Trading Comps_Input'!I131 -> 426.09416 | M20: =+'Trading Comps_Input'!I132 -> 3.668696 | N20: =+'Trading Comps_Input'!I146 -> 0.015 | O20: =+'Trading Comps_Input'!I123 -> 992 | P20: =+'Trading Comps_Input'!I168 -> 184.4
B21: BOSTON BEER | C21: =+'Trading Comps_Input'!J10 -> NYSE: SAM | D21: =+'Trading Comps_Input'!J170 -> 705.58542 | E21: =+'Trading Comps_Input'!J173 -> 650.10442 | F21: =+'Trading Comps_Input'!J109 -> 415.053 | G21: =+'Trading Comps_Input'!J110 -> 72.239 | H21: =+'Trading Comps_Input'!J111 -> 55.32 | I21: =+'Trading Comps_Input'!J112 -> 2.2702953 | J21: =+'Trading Comps_Input'!J129 -> 446.19518 | K21: =+'Trading Comps_Input'!J130 -> 102.67356 | L21: =+'Trading Comps_Input'!J131 -> 83.819889 | M21: =+'Trading Comps_Input'!J132 -> 3.407229 | N21: =+'Trading Comps_Input'!J146 -> 0.035 | O21: =+'Trading Comps_Input'!J123 -> -55.481 | P21: =+'Trading Comps_Input'!J168 -> 14.845054
B24: Vlookup
F26: Last Fiscal Year (LTM) | J26: Year 1 Forecast - Calendar Year
B27: Name | C27: Ticker | D27: Market cap (mm) | E27: Enterprise value | F27: Revenues | G27: EBITDA | H27: EBIT | I27: EPS | J27: Revenues | K27: EBITDA | L27: EBIT | M27: EPS | N27: LT growth rate | O27: Net debt | P27: Diluted shares outstanding
B29: Oriental Brewery | C29: =VLOOKUP(C$4,'Trading Comps_Input'!$B$9:$J$188,MATCH($B42,$B$42:$B$49,0)+1,FALSE) -> OB | D29: =VLOOKUP(D$4,'Trading Comps_Input'!$B$9:$J$188,MATCH($B42,$B$42:$B$49,0)+1,FALSE) -> 0 | E29: =VLOOKUP(E$4,'Trading Comps_Input'!$B$9:$J$188,MATCH($B42,$B$42:$B$49,0)+1,FALSE) -> 0 | F29: =VLOOKUP(F$4,'Trading Comps_Input'!$B$9:$J$188,MATCH($B42,$B$42:$B$49,0)+1,FALSE) -> 816110.19 | G29: =VLOOKUP(G$4,'Trading Comps_Input'!$B$9:$J$188,MATCH($B42,$B$42:$B$49,0)+1,FALSE) -> 251435.45 | H29: =VLOOKUP(H$4,'Trading Comps_Input'!$B$9:$J$188,MATCH($B42,$B$42:$B$49,0)+1,FALSE) -> 196305.66 | I29: =VLOOKUP(I$4,'Trading Comps_Input'!$B$9:$J$188,MATCH($B42,$B$42:$B$49,0)+1,FALSE) -> 6629.0535 | J29: =VLOOKUP(J$4,'Trading Comps_Input'!$B$9:$J$188,MATCH($B42,$B$42:$B$49,0)+1,FALSE) -> 840593.49 | ... P29: =VLOOKUP(P$4,'Trading Comps_Input'!$B$9:$J$188,MATCH($B42,$B$42:$B$49,0)+1,FALSE) -> 20.611
B30: HITE Brewery | C30: =VLOOKUP(C$4,'Trading Comps_Input'!$B$9:$J$188,MATCH($B43,$B$42:$B$49,0)+1,FALSE) -> KRX: 103150 | D30: =VLOOKUP(D$4,'Trading Comps_Input'!$B$9:$J$188,MATCH($B43,$B$42:$B$49,0)+1,FALSE) -> 1624834.8 | E30: =VLOOKUP(E$4,'Trading Comps_Input'!$B$9:$J$188,MATCH($B43,$B$42:$B$49,0)+1,FALSE) -> 2618390.5 | F30: =VLOOKUP(F$4,'Trading Comps_Input'!$B$9:$J$188,MATCH($B43,$B$42:$B$49,0)+1,FALSE) -> 1049536 | G30: =VLOOKUP(G$4,'Trading Comps_Input'!$B$9:$J$188,MATCH($B43,$B$42:$B$49,0)+1,FALSE) -> 259614.51 | H30: =VLOOKUP(H$4,'Trading Comps_Input'!$B$9:$J$188,MATCH($B43,$B$42:$B$49,0)+1,FALSE) -> 187129.78 | I30: =VLOOKUP(I$4,'Trading Comps_Input'!$B$9:$J$188,MATCH($B43,$B$42:$B$49,0)+1,FALSE) -> 10921.965 | J30: =VLOOKUP(J$4,'Trading Comps_Input'!$B$9:$J$188,MATCH($B43,$B$42:$B$49,0)+1,FALSE) -> 1066105.2 | ... P30: =VLOOKUP(P$4,'Trading Comps_Input'!$B$9:$J$188,MATCH($B43,$B$42:$B$49,0)+1,FALSE) -> 9.557852
B31: ASAHI GROUP | C31: =VLOOKUP(C$4,'Trading Comps_Input'!$B$9:$J$188,MATCH($B44,$B$42:$B$49,0)+1,FALSE) -> TYO: 2502 | D31: =VLOOKUP(D$4,'Trading Comps_Input'!$B$9:$J$188,MATCH($B44,$B$42:$B$49,0)+1,FALSE) -> 806123.85 | E31: =VLOOKUP(E$4,'Trading Comps_Input'!$B$9:$J$188,MATCH($B44,$B$42:$B$49,0)+1,FALSE) -> 1184147.9 | F31: =VLOOKUP(F$4,'Trading Comps_Input'!$B$9:$J$188,MATCH($B44,$B$42:$B$49,0)+1,FALSE) -> 1022318 | G31: =VLOOKUP(G$4,'Trading Comps_Input'!$B$9:$J$188,MATCH($B44,$B$42:$B$49,0)+1,FALSE) -> 141149 | H31: =VLOOKUP(H$4,'Trading Comps_Input'!$B$9:$J$188,MATCH($B44,$B$42:$B$49,0)+1,FALSE) -> 82777 | I31: =VLOOKUP(I$4,'Trading Comps_Input'!$B$9:$J$188,MATCH($B44,$B$42:$B$49,0)+1,FALSE) -> 103.09653 | J31: =VLOOKUP(J$4,'Trading Comps_Input'!$B$9:$J$188,MATCH($B44,$B$42:$B$49,0)+1,FALSE) -> 1084231.5 | ... P31: =VLOOKUP(P$4,'Trading Comps_Input'!$B$9:$J$188,MATCH($B44,$B$42:$B$49,0)+1,FALSE) -> 465.42948
B32: TSINGTAO BREWERY | C32: =VLOOKUP(C$4,'Trading Comps_Input'!$B$9:$J$188,MATCH($B45,$B$42:$B$49,0)+1,FALSE) -> SEHK:168 | D32: =VLOOKUP(D$4,'Trading Comps_Input'!$B$9:$J$188,MATCH($B45,$B$42:$B$49,0)+1,FALSE) -> 21676.909 | E32: =VLOOKUP(E$4,'Trading Comps_Input'!$B$9:$J$188,MATCH($B45,$B$42:$B$49,0)+1,FALSE) -> 17888.829 | F32: =VLOOKUP(F$4,'Trading Comps_Input'!$B$9:$J$188,MATCH($B45,$B$42:$B$49,0)+1,FALSE) -> 18026.108 | G32: =VLOOKUP(G$4,'Trading Comps_Input'!$B$9:$J$188,MATCH($B45,$B$42:$B$49,0)+1,FALSE) -> 2065.4427 | H32: =VLOOKUP(H$4,'Trading Comps_Input'!$B$9:$J$188,MATCH($B45,$B$42:$B$49,0)+1,FALSE) -> 1520.6809 | I32: =VLOOKUP(I$4,'Trading Comps_Input'!$B$9:$J$188,MATCH($B45,$B$42:$B$49,0)+1,FALSE) -> 0.95009959 | J32: =VLOOKUP(J$4,'Trading Comps_Input'!$B$9:$J$188,MATCH($B45,$B$42:$B$49,0)+1,FALSE) -> 20524.904 | ... P32: =VLOOKUP(P$4,'Trading Comps_Input'!$B$9:$J$188,MATCH($B45,$B$42:$B$49,0)+1,FALSE) -> 1315.3464
B33: CARLSBERG | C33: =VLOOKUP(C$4,'Trading Comps_Input'!$B$9:$J$188,MATCH($B46,$B$42:$B$49,0)+1,FALSE) -> CPSE:CARL B | D33: =VLOOKUP(D$4,'Trading Comps_Input'!$B$9:$J$188,MATCH($B46,$B$42:$B$49,0)+1,FALSE) -> 60461.074 | E33: =VLOOKUP(E$4,'Trading Comps_Input'!$B$9:$J$188,MATCH($B46,$B$42:$B$49,0)+1,FALSE) -> 101784.07 | F33: =VLOOKUP(F$4,'Trading Comps_Input'!$B$9:$J$188,MATCH($B46,$B$42:$B$49,0)+1,FALSE) -> 59382 | G33: =VLOOKUP(G$4,'Trading Comps_Input'!$B$9:$J$188,MATCH($B46,$B$42:$B$49,0)+1,FALSE) -> 13307 | H33: =VLOOKUP(H$4,'Trading Comps_Input'!$B$9:$J$188,MATCH($B46,$B$42:$B$49,0)+1,FALSE) -> 9538 | I33: =VLOOKUP(I$4,'Trading Comps_Input'!$B$9:$J$188,MATCH($B46,$B$42:$B$49,0)+1,FALSE) -> 33.210292 | J33: =VLOOKUP(J$4,'Trading Comps_Input'!$B$9:$J$188,MATCH($B46,$B$42:$B$49,0)+1,FALSE) -> 60124.231 | ... P33: =VLOOKUP(P$4,'Trading Comps_Input'!$B$9:$J$188,MATCH($B46,$B$42:$B$49,0)+1,FALSE) -> 152.64093
B34: HEINEKEN | C34: =VLOOKUP(C$4,'Trading Comps_Input'!$B$9:$J$188,MATCH($B47,$B$42:$B$49,0)+1,FALSE) -> ENXTAM:HEIA | D34: =VLOOKUP(D$4,'Trading Comps_Input'!$B$9:$J$188,MATCH($B47,$B$42:$B$49,0)+1,FALSE) -> 17490.187 | E34: =VLOOKUP(E$4,'Trading Comps_Input'!$B$9:$J$188,MATCH($B47,$B$42:$B$49,0)+1,FALSE) -> 25968.187 | F34: =VLOOKUP(F$4,'Trading Comps_Input'!$B$9:$J$188,MATCH($B47,$B$42:$B$49,0)+1,FALSE) -> 14701 | G34: =VLOOKUP(G$4,'Trading Comps_Input'!$B$9:$J$188,MATCH($B47,$B$42:$B$49,0)+1,FALSE) -> 2672 | H34: =VLOOKUP(H$4,'Trading Comps_Input'!$B$9:$J$188,MATCH($B47,$B$42:$B$49,0)+1,FALSE) -> 1777 | I34: =VLOOKUP(I$4,'Trading Comps_Input'!$B$9:$J$188,MATCH($B47,$B$42:$B$49,0)+1,FALSE) -> 1.8990461 | J34: =VLOOKUP(J$4,'Trading Comps_Input'!$B$9:$J$188,MATCH($B47,$B$42:$B$49,0)+1,FALSE) -> 16327.516 | ... P34: =VLOOKUP(P$4,'Trading Comps_Input'!$B$9:$J$188,MATCH($B47,$B$42:$B$49,0)+1,FALSE) -> 488.41627
B35: MOLSON COORS | C35: =VLOOKUP(C$4,'Trading Comps_Input'!$B$9:$J$188,MATCH($B48,$B$42:$B$49,0)+1,FALSE) -> NYSE: TAP | D35: =VLOOKUP(D$4,'Trading Comps_Input'!$B$9:$J$188,MATCH($B48,$B$42:$B$49,0)+1,FALSE) -> 4233.824 | E35: =VLOOKUP(E$4,'Trading Comps_Input'!$B$9:$J$188,MATCH($B48,$B$42:$B$49,0)+1,FALSE) -> 5225.824 | F35: =VLOOKUP(F$4,'Trading Comps_Input'!$B$9:$J$188,MATCH($B48,$B$42:$B$49,0)+1,FALSE) -> 3032.4 | G35: =VLOOKUP(G$4,'Trading Comps_Input'!$B$9:$J$188,MATCH($B48,$B$42:$B$49,0)+1,FALSE) -> 631.6 | H35: =VLOOKUP(H$4,'Trading Comps_Input'!$B$9:$J$188,MATCH($B48,$B$42:$B$49,0)+1,FALSE) -> 423.6 | I35: =VLOOKUP(I$4,'Trading Comps_Input'!$B$9:$J$188,MATCH($B48,$B$42:$B$49,0)+1,FALSE) -> 0.99772668 | J35: =VLOOKUP(J$4,'Trading Comps_Input'!$B$9:$J$188,MATCH($B48,$B$42:$B$49,0)+1,FALSE) -> 3371.9869 | ... P35: =VLOOKUP(P$4,'Trading Comps_Input'!$B$9:$J$188,MATCH($B48,$B$42:$B$49,0)+1,FALSE) -> 184.4
B36: BOSTON BEER | C36: =VLOOKUP(C$4,'Trading Comps_Input'!$B$9:$J$188,MATCH($B49,$B$42:$B$49,0)+1,FALSE) -> NYSE: SAM | D36: =VLOOKUP(D$4,'Trading Comps_Input'!$B$9:$J$188,MATCH($B49,$B$42:$B$49,0)+1,FALSE) -> 705.58542 | E36: =VLOOKUP(E$4,'Trading Comps_Input'!$B$9:$J$188,MATCH($B49,$B$42:$B$49,0)+1,FALSE) -> 650.10442 | F36: =VLOOKUP(F$4,'Trading Comps_Input'!$B$9:$J$188,MATCH($B49,$B$42:$B$49,0)+1,FALSE) -> 415.053 | G36: =VLOOKUP(G$4,'Trading Comps_Input'!$B$9:$J$188,MATCH($B49,$B$42:$B$49,0)+1,FALSE) -> 72.239 | H36: =VLOOKUP(H$4,'Trading Comps_Input'!$B$9:$J$188,MATCH($B49,$B$42:$B$49,0)+1,FALSE) -> 55.32 | I36: =VLOOKUP(I$4,'Trading Comps_Input'!$B$9:$J$188,MATCH($B49,$B$42:$B$49,0)+1,FALSE) -> 2.2702953 | J36: =VLOOKUP(J$4,'Trading Comps_Input'!$B$9:$J$188,MATCH($B49,$B$42:$B$49,0)+1,FALSE) -> 446.19518 | ... P36: =VLOOKUP(P$4,'Trading Comps_Input'!$B$9:$J$188,MATCH($B49,$B$42:$B$49,0)+1,FALSE) -> 14.845054
B38: Vlookup & Match
B40: Match
C41: 범위 안에서 순서
B42: Oriental Brewery | C42: =MATCH($B42,$B$42:$B$49,0)+1 -> 2
B43: HITE Brewery | C43: =MATCH($B43,$B$42:$B$49,0)+1 -> 3
B44: ASAHI GROUP | C44: =MATCH($B44,$B$42:$B$49,0)+1 -> 4
B45: TSINGTAO BREWERY | C45: =MATCH($B45,$B$42:$B$49,0)+1 -> 5
B46: CARLSBERG | C46: =MATCH($B46,$B$42:$B$49,0)+1 -> 6
B47: HEINEKEN | C47: =MATCH($B47,$B$42:$B$49,0)+1 -> 7
B48: MOLSON COORS | C48: =MATCH($B48,$B$42:$B$49,0)+1 -> 8
B49: BOSTON BEER | C49: =MATCH($B49,$B$42:$B$49,0)+1 -> 9
F53: Last Fiscal Year (LTM) | J53: Year 1 Forecast - Calendar Year
...

Sheet Trading Comps_Output (정답)
A1: OB맥주
A2: Comparable Company Analysis ("Trading Comps") - Output
B4: Company name | C4: Ticker | D4: Market capitalization (mm) | E4: Enterprise value (EV) | F4: Revenues - LFY | G4: EBITDA - LFY | H4: EBIT - LFY | I4: EPS - LFY | J4: Revenues - Calendar year 1 | K4: EBITDA - Calendar year 1 | L4: EBIT - Calendar year 1 | M4: EPS - Calendar year 1 | N4: Long-term growth rate | O4: Net debt | P4: Diluted shares outstanding (mm)
F5: EV / Revenues - LFY | G5: EV / EBITDA - LFY | H5: EV / EBIT - LFY | I5: P/E - LFY | J5: EV / Revenues - Year 1 | K5: EV / EBITDA - Year 1 | L5: EV / EBIT - Year 1 | M5: P/E - Year 1 | N5: PE/LTG (PEG ratio)
B7: 재무정보 요약
B9: 단순 링크
F11: Last Fiscal Year (LTM) | J11: Year 1 Forecast - Calendar Year
B12: Name | C12: Ticker | D12: Market cap (mm) | E12: Enterprise value | F12: Revenues | G12: EBITDA | H12: EBIT | I12: EPS | J12: Revenues | K12: EBITDA | L12: EBIT | M12: EPS | N12: LT growth rate | O12: Net debt | P12: Diluted shares outstanding
B13: Place target in first position
B14: Oriental Brewery | C14: =+'Trading Comps_Input'!C10 -> OB | F14: =+'Trading Comps_Input'!C109 -> 816110.19 | G14: =+'Trading Comps_Input'!C110 -> 251435.45 | H14: =+'Trading Comps_Input'!C111 -> 196305.66 | I14: =+'Trading Comps_Input'!C112 -> 6629.0535 | J14: =+'Trading Comps_Input'!C129 -> 840593.49 | K14: =+'Trading Comps_Input'!C130 -> 258978.51 | L14: =+'Trading Comps_Input'!C131 -> 202194.82 | M14: =+'Trading Comps_Input'!C132 -> 6827.9251 | N14: =+'Trading Comps_Input'!C146 -> 0.025 | O14: =+'Trading Comps_Input'!C123 -> 301945.91 | P14: =+'Trading Comps_Input'!C168 -> 20.611 | S14: ①
B15: HITE Brewery | C15: =+'Trading Comps_Input'!D10 -> KRX: 103150 | D15: =+'Trading Comps_Input'!D170 -> 1624834.8 | E15: =+'Trading Comps_Input'!D173 -> 2618390.5 | F15: =+'Trading Comps_Input'!D109 -> 1049536 | G15: =+'Trading Comps_Input'!D110 -> 259614.51 | H15: =+'Trading Comps_Input'!D111 -> 187129.78 | I15: =+'Trading Comps_Input'!D112 -> 10921.965 | J15: =+'Trading Comps_Input'!D129 -> 1066105.2 | K15: =+'Trading Comps_Input'!D130 -> 232221.75 | L15: =+'Trading Comps_Input'!D131 -> 151914.49 | M15: =+'Trading Comps_Input'!D132 -> 6821.3098 | N15: =+'Trading Comps_Input'!D146 -> 0.025 | O15: =+'Trading Comps_Input'!D123 -> 993555.63 | P15: =+'Trading Comps_Input'!D168 -> 9.557852 | S15: ②
B16: ASAHI GROUP | C16: =+'Trading Comps_Input'!E10 -> TYO: 2502 | D16: =+'Trading Comps_Input'!E170 -> 806123.85 | E16: =+'Trading Comps_Input'!E173 -> 1184147.9 | F16: =+'Trading Comps_Input'!E109 -> 1022318 | G16: =+'Trading Comps_Input'!E110 -> 141149 | H16: =+'Trading Comps_Input'!E111 -> 82777 | I16: =+'Trading Comps_Input'!E112 -> 103.09653 | J16: =+'Trading Comps_Input'!E129 -> 1084231.5 | K16: =+'Trading Comps_Input'!E130 -> 162376.01 | L16: =+'Trading Comps_Input'!E131 -> 95386.573 | M16: =+'Trading Comps_Input'!E132 -> 115.68564 | N16: =+'Trading Comps_Input'!E146 -> 0.035 | O16: =+'Trading Comps_Input'!E123 -> 378024 | P16: =+'Trading Comps_Input'!E168 -> 465.42948 | S16: ③
B17: TSINGTAO BREWERY | C17: =+'Trading Comps_Input'!F10 -> SEHK:168 | D17: =+'Trading Comps_Input'!F170 -> 21676.909 | E17: =+'Trading Comps_Input'!F173 -> 17888.829 | F17: =+'Trading Comps_Input'!F109 -> 18026.108 | G17: =+'Trading Comps_Input'!F110 -> 2065.4427 | H17: =+'Trading Comps_Input'!F111 -> 1520.6809 | I17: =+'Trading Comps_Input'!F112 -> 0.95009959 | J17: =+'Trading Comps_Input'!F129 -> 20524.904 | K17: =+'Trading Comps_Input'!F130 -> 2486.2697 | L17: =+'Trading Comps_Input'!F131 -> 1905.3395 | M17: =+'Trading Comps_Input'!F132 -> 1.129899 | N17: =+'Trading Comps_Input'!F146 -> 0.035 | O17: =+'Trading Comps_Input'!F123 -> -3788.0802 | P17: =+'Trading Comps_Input'!F168 -> 1315.3464
B18: CARLSBERG | C18: =+'Trading Comps_Input'!G10 -> CPSE:CARL B | D18: =+'Trading Comps_Input'!G170 -> 60461.074 | E18: =+'Trading Comps_Input'!G173 -> 101784.07 | F18: =+'Trading Comps_Input'!G109 -> 59382 | G18: =+'Trading Comps_Input'!G110 -> 13307 | H18: =+'Trading Comps_Input'!G111 -> 9538 | I18: =+'Trading Comps_Input'!G112 -> 33.210292 | J18: =+'Trading Comps_Input'!G129 -> 60124.231 | K18: =+'Trading Comps_Input'!G130 -> 13519.078 | L18: =+'Trading Comps_Input'!G131 -> 9759.7655 | M18: =+'Trading Comps_Input'!G132 -> 33.09819 | N18: =+'Trading Comps_Input'!G146 -> 0.03 | O18: =+'Trading Comps_Input'!G123 -> 41323 | P18: =+'Trading Comps_Input'!G168 -> 152.64093 | S18: ※
B19: HEINEKEN | C19: =+'Trading Comps_Input'!H10 -> ENXTAM:HEIA | D19: =+'Trading Comps_Input'!H170 -> 17490.187 | E19: =+'Trading Comps_Input'!H173 -> 25968.187 | F19: =+'Trading Comps_Input'!H109 -> 14701 | G19: =+'Trading Comps_Input'!H110 -> 2672 | H19: =+'Trading Comps_Input'!H111 -> 1777 | I19: =+'Trading Comps_Input'!H112 -> 1.8990461 | J19: =+'Trading Comps_Input'!H129 -> 16327.516 | K19: =+'Trading Comps_Input'!H130 -> 3186.5033 | L19: =+'Trading Comps_Input'!H131 -> 1986.2587 | M19: =+'Trading Comps_Input'!H132 -> 2.711287 | N19: =+'Trading Comps_Input'!H146 -> 0.035 | O19: =+'Trading Comps_Input'!H123 -> 8478 | P19: =+'Trading Comps_Input'!H168 -> 488.41627
B20: MOLSON COORS | C20: =+'Trading Comps_Input'!I10 -> NYSE: TAP | D20: =+'Trading Comps_Input'!I170 -> 4233.824 | E20: =+'Trading Comps_Input'!I173 -> 5225.824 | F20: =+'Trading Comps_Input'!I109 -> 3032.4 | G20: =+'Trading Comps_Input'!I110 -> 631.6 | H20: =+'Trading Comps_Input'!I111 -> 423.6 | I20: =+'Trading Comps_Input'!I112 -> 0.99772668 | J20: =+'Trading Comps_Input'!I129 -> 3371.9869 | K20: =+'Trading Comps_Input'!I130 -> 639.03857 | L20: =+'Trading Comps_Input'!I131 -> 426.09416 | M20: =+'Trading Comps_Input'!I132 -> 3.668696 | N20: =+'Trading Comps_Input'!I146 -> 0.015 | O20: =+'Trading Comps_Input'!I123 -> 992 | P20: =+'Trading Comps_Input'!I168 -> 184.4
B21: BOSTON BEER | C21: =+'Trading Comps_Input'!J10 -> NYSE: SAM | D21: =+'Trading Comps_Input'!J170 -> 705.58542 | E21: =+'Trading Comps_Input'!J173 -> 650.10442 | F21: =+'Trading Comps_Input'!J109 -> 415.053 | G21: =+'Trading Comps_Input'!J110 -> 72.239 | H21: =+'Trading Comps_Input'!J111 -> 55.32 | I21: =+'Trading Comps_Input'!J112 -> 2.2702953 | J21: =+'Trading Comps_Input'!J129 -> 446.19518 | K21: =+'Trading Comps_Input'!J130 -> 102.67356 | L21: =+'Trading Comps_Input'!J131 -> 83.819889 | M21: =+'Trading Comps_Input'!J132 -> 3.407229 | N21: =+'Trading Comps_Input'!J146 -> 0.035 | O21: =+'Trading Comps_Input'!J123 -> -55.481 | P21: =+'Trading Comps_Input'!J168 -> 14.845054
B24: Vlookup
F26: Last Fiscal Year (LTM) | J26: Year 1 Forecast - Calendar Year
B27: Name | C27: Ticker | D27: Market cap (mm) | E27: Enterprise value | F27: Revenues | G27: EBITDA | H27: EBIT | I27: EPS | J27: Revenues | K27: EBITDA | L27: EBIT | M27: EPS | N27: LT growth rate | O27: Net debt | P27: Diluted shares outstanding
B29: Oriental Brewery | C29: =VLOOKUP(C$4,'Trading Comps_Input'!$B$9:$J$188,2,FALSE) -> OB | D29: =VLOOKUP(D$4,'Trading Comps_Input'!$B$9:$J$188,2,FALSE) -> 0 | E29: =VLOOKUP(E$4,'Trading Comps_Input'!$B$9:$J$188,2,FALSE) -> 0 | F29: =VLOOKUP(F$4,'Trading Comps_Input'!$B$9:$J$188,2,FALSE) -> 816110.19 | G29: =VLOOKUP(G$4,'Trading Comps_Input'!$B$9:$J$188,2,FALSE) -> 251435.45 | H29: =VLOOKUP(H$4,'Trading Comps_Input'!$B$9:$J$188,2,FALSE) -> 196305.66 | I29: =VLOOKUP(I$4,'Trading Comps_Input'!$B$9:$J$188,2,FALSE) -> 6629.0535 | J29: =VLOOKUP(J$4,'Trading Comps_Input'!$B$9:$J$188,2,FALSE) -> 840593.49 | ... P29: =VLOOKUP(P$4,'Trading Comps_Input'!$B$9:$J$188,2,FALSE) -> 20.611
B30: HITE Brewery | C30: =VLOOKUP(C$4,'Trading Comps_Input'!$B$9:$J$188,3,FALSE) -> KRX: 103150 | D30: =VLOOKUP(D$4,'Trading Comps_Input'!$B$9:$J$188,3,FALSE) -> 1624834.8 | E30: =VLOOKUP(E$4,'Trading Comps_Input'!$B$9:$J$188,3,FALSE) -> 2618390.5 | F30: =VLOOKUP(F$4,'Trading Comps_Input'!$B$9:$J$188,3,FALSE) -> 1049536 | G30: =VLOOKUP(G$4,'Trading Comps_Input'!$B$9:$J$188,3,FALSE) -> 259614.51 | H30: =VLOOKUP(H$4,'Trading Comps_Input'!$B$9:$J$188,3,FALSE) -> 187129.78 | I30: =VLOOKUP(I$4,'Trading Comps_Input'!$B$9:$J$188,3,FALSE) -> 10921.965 | J30: =VLOOKUP(J$4,'Trading Comps_Input'!$B$9:$J$188,3,FALSE) -> 1066105.2 | ... P30: =VLOOKUP(P$4,'Trading Comps_Input'!$B$9:$J$188,3,FALSE) -> 9.557852
B31: ASAHI GROUP | C31: =VLOOKUP(C$4,'Trading Comps_Input'!$B$9:$J$188,5,FALSE) -> SEHK:168 | D31: =VLOOKUP(D$4,'Trading Comps_Input'!$B$9:$J$188,5,FALSE) -> 21676.909 | E31: =VLOOKUP(E$4,'Trading Comps_Input'!$B$9:$J$188,5,FALSE) -> 17888.829 | F31: =VLOOKUP(F$4,'Trading Comps_Input'!$B$9:$J$188,5,FALSE) -> 18026.108 | G31: =VLOOKUP(G$4,'Trading Comps_Input'!$B$9:$J$188,5,FALSE) -> 2065.4427 | H31: =VLOOKUP(H$4,'Trading Comps_Input'!$B$9:$J$188,5,FALSE) -> 1520.6809 | I31: =VLOOKUP(I$4,'Trading Comps_Input'!$B$9:$J$188,5,FALSE) -> 0.95009959 | J31: =VLOOKUP(J$4,'Trading Comps_Input'!$B$9:$J$188,5,FALSE) -> 20524.904 | ... P31: =VLOOKUP(P$4,'Trading Comps_Input'!$B$9:$J$188,5,FALSE) -> 1315.3464
B32: TSINGTAO BREWERY | C32: =VLOOKUP(C$4,'Trading Comps_Input'!$B$9:$J$188,6,FALSE) -> CPSE:CARL B | D32: =VLOOKUP(D$4,'Trading Comps_Input'!$B$9:$J$188,6,FALSE) -> 60461.074 | E32: =VLOOKUP(E$4,'Trading Comps_Input'!$B$9:$J$188,6,FALSE) -> 101784.07 | F32: =VLOOKUP(F$4,'Trading Comps_Input'!$B$9:$J$188,6,FALSE) -> 59382 | G32: =VLOOKUP(G$4,'Trading Comps_Input'!$B$9:$J$188,6,FALSE) -> 13307 | H32: =VLOOKUP(H$4,'Trading Comps_Input'!$B$9:$J$188,6,FALSE) -> 9538 | I32: =VLOOKUP(I$4,'Trading Comps_Input'!$B$9:$J$188,6,FALSE) -> 33.210292 | J32: =VLOOKUP(J$4,'Trading Comps_Input'!$B$9:$J$188,6,FALSE) -> 60124.231 | ... P32: =VLOOKUP(P$4,'Trading Comps_Input'!$B$9:$J$188,6,FALSE) -> 152.64093
B33: CARLSBERG | C33: =VLOOKUP(C$4,'Trading Comps_Input'!$B$9:$J$188,8,FALSE) -> NYSE: TAP | D33: =VLOOKUP(D$4,'Trading Comps_Input'!$B$9:$J$188,8,FALSE) -> 4233.824 | E33: =VLOOKUP(E$4,'Trading Comps_Input'!$B$9:$J$188,8,FALSE) -> 5225.824 | F33: =VLOOKUP(F$4,'Trading Comps_Input'!$B$9:$J$188,8,FALSE) -> 3032.4 | G33: =VLOOKUP(G$4,'Trading Comps_Input'!$B$9:$J$188,8,FALSE) -> 631.6 | H33: =VLOOKUP(H$4,'Trading Comps_Input'!$B$9:$J$188,8,FALSE) -> 423.6 | I33: =VLOOKUP(I$4,'Trading Comps_Input'!$B$9:$J$188,8,FALSE) -> 0.99772668 | J33: =VLOOKUP(J$4,'Trading Comps_Input'!$B$9:$J$188,8,FALSE) -> 3371.9869 | ... P33: =VLOOKUP(P$4,'Trading Comps_Input'!$B$9:$J$188,8,FALSE) -> 184.4
B34: HEINEKEN | C34: =VLOOKUP(C$4,'Trading Comps_Input'!$B$9:$J$188,9,FALSE) -> NYSE: SAM | D34: =VLOOKUP(D$4,'Trading Comps_Input'!$B$9:$J$188,9,FALSE) -> 705.58542 | E34: =VLOOKUP(E$4,'Trading Comps_Input'!$B$9:$J$188,9,FALSE) -> 650.10442 | F34: =VLOOKUP(F$4,'Trading Comps_Input'!$B$9:$J$188,9,FALSE) -> 415.053 | G34: =VLOOKUP(G$4,'Trading Comps_Input'!$B$9:$J$188,9,FALSE) -> 72.239 | H34: =VLOOKUP(H$4,'Trading Comps_Input'!$B$9:$J$188,9,FALSE) -> 55.32 | I34: =VLOOKUP(I$4,'Trading Comps_Input'!$B$9:$J$188,9,FALSE) -> 2.2702953 | J34: =VLOOKUP(J$4,'Trading Comps_Input'!$B$9:$J$188,9,FALSE) -> 446.19518 | ... P34: =VLOOKUP(P$4,'Trading Comps_Input'!$B$9:$J$188,9,FALSE) -> 14.845054
B35: MOLSON COORS | C35: =VLOOKUP(C$4,'Trading Comps_Input'!$B$9:$J$188,10,FALSE) -> #REF! | D35: =VLOOKUP(D$4,'Trading Comps_Input'!$B$9:$J$188,10,FALSE) -> #REF! | E35: =VLOOKUP(E$4,'Trading Comps_Input'!$B$9:$J$188,10,FALSE) -> #REF! | F35: =VLOOKUP(F$4,'Trading Comps_Input'!$B$9:$J$188,10,FALSE) -> #REF! | G35: =VLOOKUP(G$4,'Trading Comps_Input'!$B$9:$J$188,10,FALSE) -> #REF! | H35: =VLOOKUP(H$4,'Trading Comps_Input'!$B$9:$J$188,10,FALSE) -> #REF! | I35: =VLOOKUP(I$4,'Trading Comps_Input'!$B$9:$J$188,10,FALSE) -> #REF! | J35: =VLOOKUP(J$4,'Trading Comps_Input'!$B$9:$J$188,10,FALSE) -> #REF! | ... P35: =VLOOKUP(P$4,'Trading Comps_Input'!$B$9:$J$188,10,FALSE) -> #REF!
B36: BOSTON BEER | C36: =VLOOKUP(C$4,'Trading Comps_Input'!$B$9:$J$188,11,FALSE) -> #REF! | D36: =VLOOKUP(D$4,'Trading Comps_Input'!$B$9:$J$188,11,FALSE) -> #REF! | E36: =VLOOKUP(E$4,'Trading Comps_Input'!$B$9:$J$188,11,FALSE) -> #REF! | F36: =VLOOKUP(F$4,'Trading Comps_Input'!$B$9:$J$188,11,FALSE) -> #REF! | G36: =VLOOKUP(G$4,'Trading Comps_Input'!$B$9:$J$188,11,FALSE) -> #REF! | H36: =VLOOKUP(H$4,'Trading Comps_Input'!$B$9:$J$188,11,FALSE) -> #REF! | I36: =VLOOKUP(I$4,'Trading Comps_Input'!$B$9:$J$188,11,FALSE) -> #REF! | J36: =VLOOKUP(J$4,'Trading Comps_Input'!$B$9:$J$188,11,FALSE) -> #REF! | ... P36: =VLOOKUP(P$4,'Trading Comps_Input'!$B$9:$J$188,11,FALSE) -> #REF!
B38: Vlookup & Match
B40: Match
C41: 범위 안에서 순서
B42: Oriental Brewery | C42: =MATCH(B42,$B$42:$B$49,0) -> 1
B43: HITE Brewery | C43: =MATCH(B43,$B$42:$B$49,0) -> 2
B44: ASAHI GROUP | C44: =MATCH(B44,$B$42:$B$49,0) -> 3
B45: TSINGTAO BREWERY | C45: =MATCH(B45,$B$42:$B$49,0) -> 4
B46: CARLSBERG | C46: =MATCH(B46,$B$42:$B$49,0) -> 5
B47: HEINEKEN | C47: =MATCH(B47,$B$42:$B$49,0) -> 6
B48: MOLSON COORS | C48: =MATCH(B48,$B$42:$B$49,0) -> 7
B49: BOSTON BEER | C49: =MATCH(B49,$B$42:$B$49,0) -> 8
F53: Last Fiscal Year (LTM) | J53: Year 1 Forecast - Calendar Year
...

Sheet OB_IS
A4: Oriental Brewery Co., Ltd. > Financials > Income Statement
A5: (In KRW millions, except per share items)
B6: Template: | C6: Standard | E6: Restatement: | F6: Latest Filings
B7: Period Type: | C7: Annual | E7: Order: | F7: Latest on Right
B8: Currency: | C8: Reported Currency | E8: Conversion: | F8: Historical
B9: Units: | C9: S&P Capital IQ (Default) | E9: Decimals: | F9: Capital IQ (Default)
B10: Source: | C10: Capital IQ & Proprietary Data
A12: Income Statement
A13: For the Fiscal Period Ending | B13: 39447 | C13: =+B13+366 -> 39813 | D13: =+C13+365 -> 40178 | E13: =+D13+365 -> 40543 | F13: =+E13+365 -> 40908 | G13: =+F13+366 -> 41274 | H13: =+G13+365 -> 41639
A15: Total Revenue | B15: 662072.62 | C15: 750526.94 | D15: 816110.19 | E15: 914149.16 | F15: 1073545.8 | G15: 1259710.9 | H15: 1484804.1
E16: =+E15/D15-1 -> 0.12012958 | F16: =+F15/E15-1 -> 0.17436617 | G16: =+G15/F15-1 -> 0.17341139 | H16: =+H15/G15-1 -> 0.17868641
A17: Cost Of Goods Sold | B17: 265158.53 | C17: 315913.47 | D17: 349660.5 | E17: 406299.97 | F17: 470314.39 | G17: 536603.93 | H17: 606993.14
A18: Gross Profit | B18: 396914.09 | C18: 434613.48 | D18: 466449.68 | E18: 507849.19 | F18: 603231.46 | G18: 723106.99 | H18: 877811
E19: =+E18/E15 -> 0.55554302 | F19: =+F18/F15 -> 0.56190563 | G19: =+G18/G15 -> 0.57402613 | H19: =+H18/H15 -> 0.59119649
A20: Selling General & Admin Exp. | B20: 253281.82 | C20: 256313.7 | D20: 262873.2 | E20: 277598.13 | F20: 314661.23 | G20: 350889.41 | H20: 398398.75
A21: Other Operating Expense/(Income) | B21: 0 | C21: 8158.752 | D21: 7270.824 | E21: 4314.8515 | F21: 4120.79 | G21: 4243.746 | H21: 6680.279
A23: Other Operating Exp., Total | B23: 253281.82 | C23: 264472.45 | D23: 270144.03 | E23: 281912.98 | F23: 318782.02 | G23: 355133.15 | H23: 405079.03
E24: =+E20/E15 -> 0.30366831 | F24: =+F20/F15 -> 0.2931046 | G24: =+G20/G15 -> 0.27854756 | H24: =+H20/H15 -> 0.26831738
A25: Operating Income | B25: 143632.27 | C25: 170141.03 | D25: 196305.66 | E25: 225936.21 | F25: 284449.44 | G25: 367973.83 | H25: 472731.97 | I25: =+H25+OB_SCF!H18 -> 528953.74
A27: Interest Expense | B27: -5668 | C27: -3224.3 | D27: -5138.9 | E27: -71687.2 | F27: -42354 | G27: -26167 | H27: -33001.5
A28: Interest and Invest. Income | B28: 13049.877 | C28: 14630.322 | D28: 12756.581 | E28: 10694.386 | F28: 10212.608 | G28: 9954.414 | H28: 10805.082
A29: Net Interest Exp. | B29: 7381.83 | C29: 11406.065 | D29: 7617.654 | E29: -60992.8 | F29: -32141.4 | G29: -16212.6 | H29: -22196.4
A31: Income/(Loss) from Affiliates | B31: 0 | C31: 8549.355 | D31: 1553.68 | E31: 0 | F31: 0 | G31: 0 | H31: 0
A32: Currency Exchange Gains (Loss) | B32: -217.5 | C32: -2011.5 | D32: 3222.256 | E32: -11663.5 | F32: -24.7 | G32: 905.117 | H32: -240.7
A33: Other Non-Operating Inc. (Exp.) | B33: 2343.007 | C33: 2774.987 | D33: -31669 | E33: -39490.2 | F33: -14453.5 | G33: -3241 | H33: -13374.6
A34: EBT Excl. Unusual Items | B34: 153139.64 | C34: 190859.97 | D34: 177030.28 | E34: 113789.66 | F34: 237829.86 | G34: 349425.3 | H34: 436920.28
A36: Gain (Loss) On Sale Of Assets | B36: 17778.667 | C36: 8630.429 | D36: 537.236 | E36: 3410.393 | F36: 157.526 | G36: -849.2 | H36: -73.5
A37: EBT Incl. Unusual Items | B37: 170918.3 | C37: 199490.4 | D37: 177567.48 | E37: 117200.06 | F37: 237987.39 | G37: 348576.11 | H37: 436846.83
A39: Income Tax Expense | B39: 54995.362 | C39: 80275.802 | D39: 50768.022 | E39: -14364.8 | F39: 66042.093 | G39: 82529.94 | H39: 126675.18
A40: Net Income | B40: 115922.94 | C40: 119214.6 | D40: 126799.45 | E40: 131564.89 | F40: 171945.3 | G40: 266046.17 | H40: 310171.65
D41: =SUM(D39:D40) -> 177567.47
D43: =sum -> #NAME?

Sheet OB_BS
A4: Oriental Brewery Co., Ltd. > Financials > Balance Sheet
A5: (In KRW millions, except per share items)
B6: Template: | C6: Standard | E6: Restatement: | F6: Latest Filings
B7: Period Type: | C7: Annual | E7: Order: | F7: Latest on Right
B8: Currency: | C8: Reported Currency | E8: Conversion: | F8: Historical
B9: Units: | C9: S&P Capital IQ (Default) | E9: Decimals: | F9: Capital IQ (Default)
B10: Source: | C10: Capital IQ & Proprietary Data
A12: Balance Sheet
A13: For the Fiscal Period Ending | B13: 39447 | C13: =+B13+366 -> 39813 | D13: =+C13+365 -> 40178 | E13: =+D13+365 -> 40543 | F13: =+E13+365 -> 40908 | G13: =+F13+366 -> 41274 | H13: =+G13+365 -> 41639
A14: ASSETS
A15: Cash And Equivalents | B15: 141202.33 | C15: 81719.097 | D15: 134104.49 | E15: 175503.16 | F15: 167647.66 | G15: 177904.76 | H15: 444287.57
A16: Short Term Investments | B16: 89.244 | C16: 188.98 | D16: 4.235 | E16: 3.60977 | F16: 2.445 | G16: 108.77177 | H16: 0
A17: Total Cash & ST Investments | B17: 141291.58 | C17: 81908.077 | D17: 134108.72 | E17: 175506.77 | F17: 167650.11 | G17: 178013.53 | H17: 444287.57
A19: Total Receivables | B19: 226950.08 | C19: 229792.84 | D19: 258384.84 | E19: 260889.7 | F19: 271626.56 | G19: 280582.46 | H19: 312554.32
A21: Inventory | B21: 48102.141 | C21: 52157.859 | D21: 53492.258 | E21: 55540.348 | F21: 66835.084 | G21: 79230.575 | H21: 79888.535
A22: Prepaid Exp. | B22: 1152.09 | C22: 1080.39 | D22: 3597.209 | E22: 2066.914 | F22: 2264.013 | G22: 2596.118 | H22: 2608.543
A23: Other Current Assets | B23: 13358.04 | C23: 12582.742 | D23: 10870.469 | E23: 1257.6361 | F23: 242.61466 | G23: 68.01793 | H23: 2623.8174
A24: Total Current Assets | B24: =+SUM(B17,B19,B21:B23) -> 430853.92 | C24: =+SUM(C17,C19,C21:C23) -> 377521.91 | D24: =+SUM(D17,D19,D21:D23) -> 460453.5 | E24: =+SUM(E17,E19,E21:E23) -> 495261.37 | F24: =+SUM(F17,F19,F21:F23) -> 508618.39 | G24: =+SUM(G17,G19,G21:G23) -> 540490.7 | H24: =+SUM(H17,H19,H21:H23) -> 841962.79
A26: Net Property, Plant & Equipment | B26: 437536.34 | C26: 596454.36 | D26: 593634.67 | E26: 674308.3 | F26: 685008.4 | G26: 692900.25 | H26: 735282.5
A28: Long-term Investments | B28: 1286.272 | C28: 2447.457 | D28: 3989.137 | E28: 86.177 | F28: 190.929 | G28: 76.321 | H28: 70.906
A29: Goodwill | B29: 227469.21 | C29: 207826.93 | D29: 188184.65 | E29: 1154161.9 | F29: 1154161.9 | G29: 1154161.9 | H29: 1154161.9
A30: Other Intangibles | B30: 2152.108 | C30: 2117.013 | D30: 1526.279 | E30: 318637.24 | F30: 320029.15 | G30: 319782.61 | H30: 320981.33
A31: Other Long-Term Assets | B31: 40981.933 | C31: 35771.736 | D31: 34348.367 | E31: 42059.105 | F31: 31510.953 | G31: 26742.144 | H31: 26919.647
A32: Total Assets | B32: 1140279.8 | C32: 1222139.4 | D32: 1282136.6 | E32: 2691722.1 | F32: 2705668.6 | G32: 2739546.8 | H32: 3084051.6
A34: LIABILITIES
A35: Accounts Payable | B35: 24162.548 | C35: 33300.754 | D35: 24499.906 | E35: 58075.117 | F35: 92453.967 | G35: 81839.462 | H35: 95145.573
A36: Accrued Exp. | B36: 203701.35 | C36: 132604.03 | D36: 177498.84 | E36: 15329.192 | F36: 14650.694 | G36: 11473.718 | H36: 16989.548
A37: Short-term Borrowings | B37: 5363.161 | C37: 57020.228 | D37: 543.518 | E37: 62462.076 | F37: 2744.347 | G37: 83763.821 | H37: 109562.34
A38: Curr. Port. of LT Debt | B38: 30000 | C38: 40000 | D38: 0 | E38: 0 | F38: 0 | G38: 0 | H38: 56000
A39: Curr. Income Taxes Payable | B39: 46644.962 | C39: 69712.11 | D39: 56040.605 | E39: 104411.86 | F39: 155952.82 | G39: 159134.77 | H39: 176159.6
A40: Other Current Liabilities | B40: 64549.265 | C40: 66266.028 | D40: 73223.31 | E40: 221759.47 | F40: 336808.56 | G40: 288577.95 | H40: 369116.16
A41: Total Current Liabilities | B41: =+SUM(B35:B40) -> 374421.29 | C41: =+SUM(C35:C40) -> 398903.15 | D41: =+SUM(D35:D40) -> 331806.18 | E41: =+SUM(E35:E40) -> 462037.71 | F41: =+SUM(F35:F40) -> 602610.39 | G41: =+SUM(G35:G40) -> 624789.72 | H41: =+SUM(H35:H40) -> 822973.23
A43: Long-Term Debt | B43: 40000 | C43: 0 | D43: 435506.88 | E43: 756323.79 | F43: 469282.64 | G43: 320000 | H43: 652000
A44: Pension & Other Post-Retire. Benefits | B44: 14269.711 | C44: 12573.013 | D44: 12191.977 | E44: 17200.424 | F44: 24024.284 | G44: 31647.672 | H44: 23523.297
A45: Total Liabilities | B45: 428691 | C45: 411476.16 | D45: 779505.04 | E45: 1236478.8 | F45: 1096497.9 | G45: 976972.22 | H45: 1499281.7
A47: EQUITIES
A48: Pref. Stock, Non-Redeem. | B48: 1000 | C48: 1000 | D48: 1000 | E48: 0 | F48: 0 | G48: 0 | H48: 0
A49: Total Pref. Equity | B49: 1000 | C49: 1000 | D49: 1000 | E49: 0 | F49: 0 | G49: 0 | H49: 0
A51: Common Stock | B51: 52800 | C51: 52800 | D51: 40222 | E51: 22011 | F51: 22011 | G51: 22011 | H51: 22011
A52: Additional Paid In Capital | B52: 464625.34 | C52: 464625.34 | D52: 42495.798 | E52: 1295399.1 | F52: 1295399.1 | G52: 31926.5 | H52: 31926.5
...

Sheet OB_SCF
A4: Oriental Brewery Co., Ltd. > Financials > Cash Flow
A5: (In KRW millions, except per share items)
B6: Template: | C6: Standard | E6: Restatement: | F6: Latest Filings
B7: Period Type: | C7: Annual | E7: Order: | F7: Latest on Right
B8: Currency: | C8: Reported Currency | E8: Conversion: | F8: Historical
B9: Units: | C9: S&P Capital IQ (Default) | E9: Decimals: | F9: Capital IQ (Default)
B10: Source: | C10: Capital IQ & Proprietary Data
A12: Cash Flow
A13: For the Fiscal Period Ending | B13: 39447 | C13: =+B13+366 -> 39813 | D13: =+C13+365 -> 40178 | E13: =+D13+365 -> 40543 | F13: =+E13+365 -> 40908 | G13: =+F13+366 -> 41274 | H13: =+G13+365 -> 41639
A15: Net Income | B15: 115922.94 | C15: 119214.6 | D15: 126799.45 | E15: 131564.89 | F15: 171945.3 | G15: 266046.16 | H15: 310171.65
A16: Depreciation & Amort. | B16: 39936.53 | C16: 35844.876 | D16: 34788.295 | E16: 73202.869 | F16: 60511.428 | G16: 51203.203 | H16: 54341.732
A17: Amort. of Goodwill and Intangibles | B17: 20354.736 | C17: 20382.632 | D17: 20341.495 | E17: 646.51103 | F17: 1307.0763 | G17: 1463.8054 | H17: 1880.0388
A18: Depreciation & Amort., Total | B18: 60291.266 | C18: 56227.508 | D18: 55129.79 | E18: 73849.38 | F18: 61818.505 | G18: 52667.009 | H18: 56221.771
A20: (Gain) Loss From Sale Of Assets | B20: -2404.7 | C20: -8630.4 | D20: -871.4 | E20: -3410.4 | F20: -157.5 | G20: 849.19228 | H20: 73.45231
A21: (Gain) Loss On Sale Of Invest. | B21: -15373.9 | C21: 0 | D21: 238.2 | E21: 0 | F21: 0 | G21: 0 | H21: 0
A22: Asset Writedown & Restructuring Costs | B22: 0 | C22: 0 | D22: 96.045 | E22: 0 | F22: 0 | G22: 0 | H22: 0
A23: (Income) Loss on Equity Invest. | B23: 0 | C23: -8549.4 | D23: -1553.7 | E23: 0 | F23: 0 | G23: 0 | H23: 0
A24: Provision & Write-off of Bad debts | B24: 0 | C24: -41.5 | D24: 0 | E24: 0 | F24: 0 | G24: 0 | H24: 0
A25: Other Operating Activities | B25: 8267.89 | C25: 14797.511 | D25: 13328.396 | E25: -2887.4 | F25: 75230.673 | G25: 10824.419 | H25: 28873.066
A26: Change in Acc. Receivable | B26: 20997.179 | C26: -3283 | D26: -29408.4 | E26: 15029.931 | F26: -1283.3 | G26: -4046.8 | H26: -20143.1
A27: Change In Inventories | B27: 4003.087 | C27: -3902.2 | D27: -1334.4 | E27: -1735.4 | F27: -11294.7 | G27: -12395.5 | H27: -658
A28: Change in Acc. Payable | B28: 5027.253 | C28: 9402.063 | D28: -8488.5 | E28: 31714.339 | F28: 34321.705 | G28: -10527.1 | H28: 13346.441
A29: Change in Inc. Taxes | B29: 25966.695
A30: Change in Def. Taxes | B30: -2430.2 | C30: -802.8 | D30: 3098.86 | E30: 0 | F30: 0 | G30: 0 | H30: 0
A31: Change in Other Net Operating Assets | B31: 67769.167 | C31: -85183.8 | D31: 35982.529 | E31: -50629.4 | F31: 100329.21 | G31: -54350.4 | H31: 51774.873
A32: Cash from Ops. | B32: 288036.59 | C32: 79984.676 | D32: 178762.76 | E32: 193495.89 | F32: 430909.79 | G32: 249066.98 | H32: 439660.14
A34: Capital Expenditure | B34: -27941.8 | C34: -24923.9 | D34: -32498.4 | E34: -40189.3 | F34: -67237.1 | G34: -54157.2 | H34: -94961.3
A35: Sale of Property, Plant, and Equipment | B35: 2423.77 | C35: 809.897 | D35: 951.18 | E35: 15467.406 | F35: 1543.2296 | G35: 824.12039 | H35: 1144.5641
A36: Sale (Purchase) of Real Estate properties | B36: 37471 | C36: 13518.224 | D36: 289.615 | E36: 0 | F36: 0 | G36: 0 | H36: 0
A37: Sale (Purchase) of Intangible assets | B37: -975.3 | C37: -705.3 | D37: -104.8 | E37: -2008.5 | F37: -1967.8 | G37: -1823.5 | H37: -2919.4
A38: Invest. in Marketable & Equity Securt. | B38: 581.971 | C38: 88.434 | D38: -43.4 | E38: 2.47 | F38: 1.705 | G38: 8.2815 | H38: 114.18677
A39: Net (Inc.) Dec. in Loans Originated/Sold | B39: 10389.694 | C39: -100.3 | D39: 941.405 | E39: 703.314 | F39: 1435.5665 | G39: 893.74656 | H39: 755.96244
A40: Other Investing Activities | B40: 584.613 | C40: 7294.786 | D40: 529.646 | E40: -683.7 | F40: 4079.1382 | G40: -1378.7 | H40: -3355.9
A41: Cash from Investing | B41: 22533.946 | C41: -4018.2 | D41: -29934.7 | E41: -26708.3 | F41: -62145.3 | G41: -55633.3 | H41: -99221.9
A43: Short Term Debt Issued | B43: 5275.372 | C43: 51850.678 | D43: 30781.22 | E43: 22318.951 | F43: 0 | G43: 80806.583 | H43: 26470.337
... A59: Net Change in Cash | B59: 131603.65 | C59: -59483.2 | D59: 52385.39 | E59: 37359.039 | F59: -7855.5 | G59: 10257.098 | H59: 266382.81

Sheet OB맥주_DART
A1: 2009년 감사보고서
B2: http://dart.fss.or.kr/dsaf001/main.do?rcpNo=20100405001258
A4: Balance Sheet
B5: 오비맥주주식회사 | D5: 1000000 | F5: (단위 : 백만원)
B6: 과 목 | C6: 2008.12 | E6: 2009.12
B7: 자 산
B8: Ⅰ. 유동자산 | C8: 0 | D8: 339045.18 | E8: 0 | F8: 422042.33
B9: (1) 당좌자산 | C9: 0 | D9: 286887.32 | E9: 0 | F9: 368550.07
B10: 현금및현금성자산(주17) | C10: 81719.097 | D10: 0 | E10: 134104.49 | F10: 0
B11: 매출채권(주6,17,18,19) | C11: 218112.47 | D11: 0 | E11: 249749.45 | F11: 0
B12: 대손충당금 | C12: -29030.693 | D12: 0 | E12: -31213.61 | F12: 0
B13: 미수금(주6) | C13: 2110.6583 | D13: 0 | E13: 1574.6837 | F13: 0
B14: 대손충당금 | C14: -240.3611 | D14: 0 | E14: -240.3611 | F14: 0
B15: 단기대여금 | C15: 250 | D15: 0 | E15: - | F15: 0
B16: 미수수익 | C16: 114.03914 | D16: 0 | E16: 103.51522 | F16: 0
B17: 선급비용 | C17: 1080.3904 | D17: 0 | E17: 3597.2095 | F17: 0
B18: 만기보유증권(주4) | C18: 188.98 | D18: 0 | E18: 4.235 | F18: 0
B19: 통화선도(주20) | C19: - | D19: 0 | E19: 214.90201 | F19: 0
B20: 기타의당좌자산 | C20: 226.20197 | D20: 0 | E20: 776.41008 | F20: 0
B21: 이연법인세자산(주24) | C21: 12356.54 | D21: 0 | E21: 9879.1557 | F21: 0
B22: (2) 재고자산(주8) | C22: 0 | D22: 52157.859 | E22: 0 | F22: 53492.258
B23: 제품 | C23: 9789.9654 | D23: 0 | E23: 8069.5017 | F23: 0
B24: 평가손실충당금 | C24: -80.042788 | D24: 0 | E24: -101.64298 | F24: 0
B25: 원재료 | C25: 10526.066 | D25: 0 | E25: 18631.857 | F25: 0
B26: 소모품 | C26: 1559.7621 | D26: 0 | E26: 1599.1537 | F26: 0
B27: 재공품 | C27: 24101.728 | D27: 0 | E27: 23290.793 | F27: 0
B28: 미착품 | C28: 4939.6034 | D28: 0 | E28: 1109.8461 | F28: 0
B29: 선전품 | C29: 1320.776 | D29: 0 | E29: 892.75027 | F29: 0
B30: Ⅱ. 비유동자산 | C30: 0 | D30: 883094.22 | E30: 0 | F30: 860094.27
B31: (1) 투자자산 | C31: 0 | D31: 3709.466 | E31: 0 | F31: 5251.1457
... B41: 감가상각누계액 | C41: -23263.284 | D41: 0 | E41: -25155.059 | F41: 0
B42: 손상차손누계액 | C42: - | D42: 0 | E42: -24.234369 | F42: 0
B43: 기계장치 | C43: 465570.66 | D43: 0 | E43: 473922.11 | F43: 0
B44: 감가상각누계액 | C44: -415512.47 | D44: 0 | E44: -429375.57 | F44: 0
B45: 손상차손누계액 | C45: - | D45: 0 | E45: -71.810625 | F45: 0
B46: 용기 | C46: 98372.943 | D46: 0 | E46: 106995.1 | F46: 0
B47: 감가상각누계액 | C47: -84572.16 | D47: 0 | E47: -87964.871 | F47: 0
B48: 차량운반구 | C48: 3872.726 | D48: 0 | E48: 4087.868 | F48: 0
B49: 감가상각누계액 | C49: -2900.251 | D49: 0 | E49: -2960.3549 | F49: 0
B50: 공구와기구 | C50: 6272.3338 | D50: 0 | E50: 6624.4296 | F50: 0
...

Sheet 하이트진로_DART
A1: 2009년 연결감사보고서
B2: http://dart.fss.or.kr/dsaf001/main.do?rcpNo=20100331000603&dcmNo=2586232
B4: 하이트맥주 연결재무제표
A6: Balance Sheet
B7: 회사명 : 하이트맥주 주식회사와 그 종속회사 | C7: (단위 : 원)
B8: 과 목 | C8: 제 2(당) 기
B9: 자 산
B10: I.유동자산 | D10: 572179733499
B11: (1)당좌자산 | D11: 451266611275
B12: 현금및현금성자산 <주석 18> | C12: 44233059985
B13: 단기투자자산 <주석 8,9,20> | C13: 10360561262
B14: 매출채권 <주석 13,18,20> | C14: 375090064170
B15: 대손충당금 | C15: -34918594728
B16: 미수금 <주석 20> | C16: 38129508346
B17: 대손충당금 | C17: -2478586454
B18: 미수수익 | C18: 418068883
B19: 선급금 | C19: 4514000725
B20: 선급비용 | C20: 6944756405
B21: 유동성이연법인세자산 <주석 26> | C21: 8973772681
B22: (2)재고자산 <주석 12> | D22: 120913122224
B23: 제품 | C23: 15100040414
B24: 재공품 | C24: 23986082064
B25: 원재료 | C25: 47232429099
B26: 저장품 | C26: 9734469435
B27: 상품 | C27: 6484855483
B28: 미착품 | C28: 18375245729
B29: II.비유동자산 | D29: 1729565479684
B30: (1)투자자산 | D30: 1965768911
B31: 장기금융상품 <주석 7> | C31: 183700000
B32: 매도가능증권 <주석 9> | C32: 1655400911
B33: 장기대여금 <주석 20> | C33: 126668000
B34: (2)유형자산 <주석 2,10,12,23> | D34: 1643409698974
B35: 토지 | C35: 445545967978
B36: 설비자산 | C36: 1827294910673
B37: 감가상각누계액 | C37: -663346149670
B38: 건설중인 자산 | C38: 33914969993
B39: (3)무형자산 <주석 11> | D39: 12555632493
B40: 영업권 | C40: 12546520208
B41: 기타의무형자산 | C41: 9112285
B42: (4)기타비유동자산 | D42: 71634379306
...
