Workbook
Name Ccy: WACC!$E$1
Name circ: [1]Cover!$K$6
Name Circ: Cover!$K$6
Name Conv: WACC!#REF!
Name Date: WACC!$H$1
Name Days: #REF!
Name Days: 'Working Capital'!$H$30
Name Fil: WACC!#REF!
Name GVKey: ""
Name img_1675017080: SHAK_10K!#REF!
Name IQ_CH: 110000
Name IQ_CQ: 5000
Name IQ_CY: 10000
Name IQ_DAILY: 500000
Name IQ_FH: 100000
Name IQ_FQ: 500
Name IQ_FY: 1000
Name IQ_LTM: 2000
Name IQ_MONTH: 15000
Name IQ_NTM: 6000
Name IQ_WEEK: 50000
Name IQ_YTD: 3000
Name List: 'Input Tab'!$AD$15:$AD$19
Name SPSet: "current"
Name SPWS_WBID: "D37EBD5C-BA90-4B94-B2F1-78539D014FA9"

Sheet _CIQHiddenCacheSheet
A1: 26 | B1: AwABTAVMT0NBTAFI/////wFQuQAAACNDSVEuS1IuSVFfRlhfUkFURS5ERUMyMDEzLjgvMjUvMjAxNwEAAADIS5MGAgAAAAsxMDU3LjEwOTA5MQCqPkp9LevVCPiMZn0t69UIMENJUS5ORExTLklRX1BSRUZfRVFVSVRZLjUwMC4yMDE4LTA3LTEwLkxGUi4uVVNELgEAAAD5n3sAAwAAAAAAFPwQcS/r1Qh2NzSKL+vVCCRDSVEuQ01HLklRX01BUktFVENBUC4yMDE4LTA3LTEwLlVTRC4BAAAATmcAAAIAAAALMTI2MjQuMDE5MzIBBgAAAAUAAAABMQEAAAAKMTg4NDk2MzMzMAMAAAADMTYwAgAAAAYxMDAwNTQEAAAAATAHAAAACTcvMTAvMjAxOBT8EHEv69UIdjc0ii/r1QgjQ0lRLktSLklRX0ZYX1JBVEUuU0VQMjAxNS44LzI1LzIwMTcBAAAAyEuTBgIAAAALMTE4NS4yNDA5MDkAqj5KfS3r1QgHZmZ9LevVCCtDSVEuTllTRTpTSEFLLklRX0VCVC4uMjAxOC0wNy0xMC5MRlIuLlVTRC5IAQAAAJ0Tpg0CAAAABjE2MC45NQEIAAAABQAAAAExAQAAAAoxODg3MjkwNTQxAwAAAAMxNjACAAAAAzEzOQQAAAABMAcAAAAJNy8xMC8yMDE4CAAAAAkzLzI4LzIwMTgJAAAAATBOt2twL+vVCFRmdLcv69UII0NJUS5LUi5JUV9GWF9SQVRFLk5PVjIwMTUuOC8yNS8yMDE3AQAAAMhLkwYCAAAACzExNTIuOTM4MDk1AKo+Sn0t69UIB2ZmfS3r1QgwQ0lRLlpPRVMuSVFfUFJFRl9FUVVJVFkuNTAwLjIwMTgtMDctMTAuTEZSLi5V | C1: U0QuAQAAANTGTwIDAAAAAAAU/BBxL+vVCG5eNIov69UIMUNJUS5IQUJULklRX1BSRUZfRVFVSVRZLjUwMC4yMDE4LTA3LTEwLkxGUi4uVVNELkgBAAAAI9YREAMAAAAAAIIe/FQv69UIVoU0ii/r1QgmQ0lRLk5ZU0U6TUNELklRX0NPTVBBTllfVElDS0VSX05PX0VYQ0gBAAAA4CACAAMAAAADTUNEAKFSM1Qv69UIghA0ii/r1QgtQ0lRQVZHLk5ETFMuSVFfRUZGRUNUX1RBWF9SQVRFLjk5Ni4yMDE4LTA3LTEwAQAAAPmfewACAAAABzQwLjA0NjEAgh78VC/r1QhuXjSKL+vVCB1DSVEuTllTRTpTSEFLLklRX1FVSUNLX0NPTVAuNgEAAACdE6YNAwAAAAhOWVNFOk1DRABOt2twL+vVCIIQNIov69UIL0NJUS5DTUcuSVFfVE9UQUxfREVCVC41MDAuMjAxOC0wNy0xMC5MRlIuLlVTRC5IAQAAAE5nAAACAAAAATABCAAAAAUAAAABMQEAAAAKMTg4NDk2MzMzMAMAAAADMTYwAgAAAAQ0MTczBAAAAAEwBwAAAAk3LzEwLzIwMTgIAAAACTMvMzEvMjAxOAkAAAABMIIe/FQv69UIUqw0ii/r1QgmQ0lRLktSLklRX0ZYX1JBVEVfRkMuU0VQMjAxOS44LzI0LzIwMTcBAAAAxDGUBgIAAAAKMTExNS41NzgzOQCqPkp9LevVCAE/Zn0t69UIKkNJUS5OWVNFOlNIQUsuSVFfRUJULi4yMDE4LTA3LTEwLkxGUi4uVVNELgEAAACdE6YNAgAAAAYxNjAuOTUBCAAAAAUAAAABMQEAAAAKMTg4NzI5MDU0MQMAAAADMTYwAgAAAAMxMzkE | D1: AAAAATAHAAAACTcvMTAvMjAxOAgAAAAJMy8yOC8yMDE4CQAAAAEwFPwQcS/r1QhUZnS3L+vVCCZDSVEuS1IuSVFfRlhfUkFURV9GQy5NQVkyMDIwLjgvMjQvMjAxNwEAAADEMZQGAgAAAAoxMTMyLjExMzQyAKo+Sn0t69UIAT9mfS3r1QgvQ0lRLk1DRC5JUV9UT1RBTF9ERUJULjUwMC4yMDE4LTA3LTEwLkxGUi4uVVNELkgBAAAA4CACAAIAAAAFMzA4ODgBCAAAAAUAAAABMQEAAAAKMTg4NzY2NTU5NgMAAAADMTYwAgAAAAQ0MTczBAAAAAEwBwAAAAk3LzEwLzIwMTgIAAAACTMvMzEvMjAxOAkAAAABMIIe/FQv69UIVEQkiy/r1Qg+Q0lRUkFOR0UuTllTRTpTSEFLLklRX0ZJWEVEX0lOQ09NRV9MSVNULjEuNTAwLi4uLi5GSVhFRCBJTkNPTUUDAAAAnROmDQAAAABOt2twL+vVCGw/dLcv69UIF0NJUS5NQ0QuSVFfQ09NUEFOWV9OQU1FAQAAAOAgAgADAAAAFk1jRG9uYWxkJ3MgQ29ycG9yYXRpb24Agh78VC/r1Qh2NzSKL+vVCBhDSVEuTkRMUy5JUV9DT01QQU5ZX05BTUUBAAAA+Z97AAMAAAARTm9vZGxlcyAmIENvbXBhbnkAgh78VC/r1QhuXjSKL+vVCCZDSVEuS1IuSVFfRlhfUkFURV9GQy5BUFIyMDIwLjgvMjQvMjAxNwEAAADEMZQGAgAAAAoxMTI4Ljg0NjM5AKo+Sn0t69UIAT9mfS3r1QgmQ0lRLkhBQlQuSVFfTUFSS0VUQ0FQLjIwMTgtMDctMTAuVVNELkgBAAAAI9YREAIAAAAKMjE1LjI5NTUyOAEG | E1: AAAABQAAAAExAQAAAAoxODg2NDUxNTgyAwAAAAMxNjACAAAABjEwMDA1NAQAAAABMAcAAAAJNy8xMC8yMDE4gh78VC/r1QhWhTSKL+vVCDFDSVEuWk9FUy5JUV9QUkVGX0VRVUlUWS41MDAuMjAxOC0wNy0xMC5MRlIuLlVTRC5IAQAAANTGTwIDAAAAAACCHvxUL+vVCFaFNIov69UII0NJUS5LUi5JUV9GWF9SQVRFLkRFQzIwMTUuOC8yNS8yMDE3AQAAAMhLkwYCAAAACzExNzIuMjEzMDQzAKo+Sn0t69UI+IxmfS3r1QgrQ0lRLk5ZU0U6U0hBSy5JUV9NQVJLRVRDQVAuMjAxOC0wNy0xMC5VU0QuSAEAAACdE6YNAgAAAAsxNzcxLjU5MTI3NgEGAAAABQAAAAExAQAAAAoxODg3MjkwMTI1AwAAAAMxNjACAAAABjEwMDA1NAQAAAABMAcAAAAJNy8xMC8yMDE4TrdrcC/r1QhUZnS3L+vVCBxDSVEuTllTRTpTSEFLLklRX1FVSUNLX0NPTVAuAQAAAJ0Tpg0DAAAACU5ZU0U6Wk9FUwAU/BBxL+vVCBT8EHEv69UII0NJUS5LUi5JUV9GWF9SQVRFLkpVTDIwMTMuOC8yNS8yMDE3AQAAAMhLkwYCAAAACzExMjYuNTc4MjYxAKo+Sn0t69UI+IxmfS3r1QgsQ0lRQVZHLk1DRC5JUV9FRkZFQ1RfVEFYX1JBVEUuOTk2LjIwMTgtMDctMTABAAAA4CACAAIAAAAIMzMuODkzODgAgh78VC/r1QhuXjSKL+vVCC9DSVEuTllTRTpTSEFLLklRX1BFUklPRERBVEUuMTAwMC4yMDE4LTA3LTEwLkxGUgEAAACdE6YNBQAAAAoyMDE3LTEy | F1: LTI3AE63a3Av69UIVGZ0ty/r1QgjQ0lRLktSLklRX0ZYX1JBVEUuTUFZMjAxMy44LzI1LzIwMTcBAAAAyEuTBgIAAAALMTExMC40OTU2NTIAvhdKfS3r1Qj4jGZ9LevVCCNDSVEuS1IuSVFfRlhfUkFURS5KVU4yMDEzLjgvMjUvMjAxNwEAAADIS5MGAgAAAAcxMTM0LjU0AKo+Sn0t69UI+IxmfS3r1QgjQ0lRLktSLklRX0ZYX1JBVEUuSkFOMjAxNS44LzI1LzIwMTcBAAAAyEuTBgIAAAALMTA4OS42NDA5MDkAqj5KfS3r1QgHZmZ9LevVCCZDSVEuS1IuSVFfRlhfUkFURV9GQy5KQU4yMDE5LjgvMjQvMjAxNwEAAADEMZQGAgAAAAoxMTAxLjYwMjY3AKo+Sn0t69UIAT9mfS3r1QguQ0lRLk5ZU0U6U0hBSy5JUV9JTkNfVEFYLi4yMDE4LTA3LTEwLkxGUi4uVVNELgEAAACdE6YNAgAAAAcxNTAuOTQ5AQgAAAAFAAAAATEBAAAACjE4ODcyOTA1NDEDAAAAAzE2MAIAAAACNzUEAAAAATAHAAAACTcvMTAvMjAxOAgAAAAJMy8yOC8yMDE4CQAAAAEwFPwQcS/r1QhUZnS3L+vVCDBDSVEuQ01HLklRX1BSRUZfRVFVSVRZLjUwMC4yMDE4LTA3LTEwLkxGUi4uVVNELkgBAAAATmcAAAMAAAAAAIIe/FQv69UIUqw0ii/r1QgjQ0lRLktSLklRX0ZYX1JBVEUuU0VQMjAxMy44LzI1LzIwMTcBAAAAyEuTBgIAAAAKMTA4Ni42NzYxOQC+F0p9LevVCPiMZn0t69UIOUNJUS5OWVNFOlNIQUsuSVFfU1BfSVNTVUVSX1JBVElORy4y | G1: MDE4LTA3LTEwLkxUX0xDLlJBVElORwEAAACdE6YNAwAAAAAATrdrcC/r1QhUZnS3L+vVCB1DSVEuTllTRTpTSEFLLklRX1FVSUNLX0NPTVAuNAEAAACdE6YNAwAAAA1OYXNkYXFHTTpIQUJUAE63a3Av69UIghA0ii/r1QgdQ0lRLk5ZU0U6U0hBSy5JUV9RVUlDS19DT01QLjIBAAAAnROmDQMAAAAITllTRTpDTUcATrdrcC/r1QiCEDSKL+vVCCVDSVFQQy5eU1BYLklRX0xBU1RTQUxFUFJJQ0UuLTFZLjQwMTc4AQAAAJu4KAACAAAAEDIzLjQ1MzgxNzQxOTA1ODQATrdrcC/r1Qg8tHS3L+vVCC9DSVEuWk9FUy5JUV9UT1RBTF9ERUJULjUwMC4yMDE4LTA3LTEwLkxGUi4uVVNELgEAAADUxk8CAgAAAAY0Ny42MzQBCAAAAAUAAAABMQEAAAAKMTg5MDY1MzA5OAMAAAADMTYwAgAAAAQ0MTczBAAAAAEwBwAAAAk3LzEwLzIwMTgIAAAACTQvMTYvMjAxOAkAAAABMBT8EHEv69UIdjc0ii/r1QgdQ0lRLi5JUV9SQVRFX0xFVkVMLjIwMTgtMDctMTAFAAAAAAAAAAgAAAAUKEludmFsaWQgSWRlbnRpZmllcikU/BBxL+vVCIIQNIov69UIJkNJUS5LUi5JUV9GWF9SQVRFX0ZDLkFQUjIwMTkuOC8yNC8yMDE3AQAAAMQxlAYCAAAACjExMTEuMzM4NTYAqj5KfS3r1QgBP2Z9LevVCCZDSVEuS1IuSVFfRlhfUkFURV9GQy5KVU4yMDIwLjgvMjQvMjAxNwEAAADEMZQGAgAAAAoxMTMyLjIyNjQ0AKo+Sn0t69UIAT9mfS3r1Qge | H1: Q0lRLkNNRy5JUV9CRVRBXzVZUi4yMDE4LTA3LTEwAQAAAE5nAAACAAAAETAuNDEzMzAxODc0MzM1OTYxAIIe/FQv69UIdjc0ii/r1QglQ0lRUEMuXlNQWC5JUV9MQVNUU0FMRVBSSUNFLi0xWS4zOTgxMwEAAACbuCgAAgAAABEtMzguNDg1MjU2MzYwNzMzOQBOt2twL+vVCDy0dLcv69UILkNJUS5OWVNFOlNIQUsuSVFfUEVSSU9EREFURS41MDAuMjAxOC0wNy0xMC5MRlIBAAAAnROmDQUAAAAKMjAxOC0wMy0yOABOt2twL+vVCFRmdLcv69UIL0NJUS5XRU4uSVFfVE9UQUxfREVCVC41MDAuMjAxOC0wNy0xMC5MRlIuLlVTRC5IAQAAAAVcAAACAAAACDI4MDguMDIxAQgAAAAFAAAAATEBAAAACjE4ODgwNTUxODADAAAAAzE2MAIAAAAENDE3MwQAAAABMAcAAAAJNy8xMC8yMDE4CAAAAAg0LzEvMjAxOAkAAAABMIIe/FQv69UIVoU0ii/r1QgcQ0lRLklRVDM2MTgzODM5LklRX1JBVEVfTkFNRQEAAAAdHygCAwAAADJVbml0ZWQgU3RhdGVzIFRyZWFzdXJ5IENvbnN0YW50IE1hdHVyaXR5IC0gMTAgWWVhcgBOt2twL+vVCFRmdLcv69UIJUNJUVBDLl5TUFguSVFfTEFTVFNBTEVQUklDRS4tMVkuNDMxMDABAAAAm7goAAIAAAAQMTkuNDIwMTY1MjU4NzMxOQBOt2twL+vVCFCNdLcv69UIJkNJUS5LUi5JUV9GWF9SQVRFX0ZDLk1BUjIwMTkuOC8yNC8yMDE3AQAAAMQxlAYCAAAACTExMDguMjMwOQCqPkp9LevVCAE/ | I1: Zn0t69UIJUNJUS5DTUcuSVFfTUFSS0VUQ0FQLjIwMTgtMDctMTAuVVNELkgBAAAATmcAAAIAAAALMTI2MjQuMDE5MzIBBgAAAAUAAAABMQEAAAAKMTg4NDk2MzMzMAMAAAADMTYwAgAAAAYxMDAwNTQEAAAAATAHAAAACTcvMTAvMjAxOIIe/FQv69UIVoU0ii/r1QgjQ0lRLktSLklRX0ZYX1JBVEUuSkFOMjAxMy44LzI1LzIwMTcBAAAAyEuTBgIAAAALMTA2NS45ODY5NTcAvhdKfS3r1Qj4jGZ9LevVCCBDSVEuTllTRTpTSEFLLklRX0lORFVTVFJZX1NFQ1RPUgEAAACdE6YNAwAAABZDb25zdW1lciBEaXNjcmV0aW9uYXJ5AE63a3Av69UIVGZ0ty/r1QgRQ0lRLi5JUV9SQVRFX05BTUUFAAAAAAAAAAgAAAAUKEludmFsaWQgSWRlbnRpZmllcikU/BBxL+vVCIIQNIov69UIL0NJUS5XRU4uSVFfUFJFRl9FUVVJVFkuNTAwLjIwMTgtMDctMTAuTEZSLi5VU0QuAQAAAAVcAAADAAAAAAAU/BBxL+vVCG5eNIov69UILENJUS5OWVNFOlNIQUsuSVFfUEVSSU9EREFURS4xMDAwLjIwMTgtMDctMTAuAQAAAJ0Tpg0FAAAACjIwMTctMTItMjcAFPwQcS/r1QhsP3S3L+vVCCVDSVEuTUNELklRX01BUktFVENBUC4yMDE4LTA3LTEwLlVTRC5IAQAAAOAgAgACAAAADTEyNjExNS4xOTM2NjcBBgAAAAUAAAABMQEAAAAKMTg4NzY2NTU5NgMAAAADMTYwAgAAAAYxMDAwNTQEAAAAATAHAAAACTcvMTAvMjAxOIIe/FQv69UIVEQk | J1: iy/r1QhCQ0lRLlVTRC5JUV9GVUxMX0NVUlZFX0FOTlVBTC5DT05TVU1FUkRJU0NSRVRJT05BUlkuMC41WS4yMDE4LTA3LTEwAQAAAAAAAAACAAAACTAuMDM4MjYyOQCVeTNUL+vVCFaFNIov69UII0NJUS5LUi5JUV9GWF9SQVRFLk1BWTIwMTUuOC8yNS8yMDE3AQAAAMhLkwYCAAAACzEwODkuMjgwOTUyAKo+Sn0t69UIB2ZmfS3r1QguQ0lRLk1DRC5JUV9UT1RBTF9ERUJULjUwMC4yMDE4LTA3LTEwLkxGUi4uVVNELgEAAADgIAIAAgAAAAUzMDg4OAEIAAAABQAAAAExAQAAAAoxODg3NjY1NTk2AwAAAAMxNjACAAAABDQxNzMEAAAAATAHAAAACTcvMTAvMjAxOAgAAAAJMy8zMS8yMDE4CQAAAAEwBOAdiy/r1QgE4B2LL+vVCCRDSVEuTllTRTpTSEFLLklRX0JFVEFfNVlSLjIwMTgtMDctMTABAAAAnROmDQIAAAAQMS4zNDc2NDIyNjAzNTM5NABOt2twL+vVCFRmdLcv69UIJkNJUS5LUi5JUV9GWF9SQVRFX0ZDLkZFQjIwMTkuOC8yNC8yMDE3AQAAAMQxlAYCAAAACjExMDUuMDkwNjIAqj5KfS3r1QgBP2Z9LevVCCNDSVEuS1IuSVFfRlhfUkFURS5KVUwyMDE2LjgvMjUvMjAxNwEAAADIS5MGAgAAAAsxMTQ0LjMzMzMzMwCqPkp9LevVCAdmZn0t69UIH0NJUS5LUi5JUV9GWF9SQVRFX0ZDLi44LzI0LzIwMTcBAAAARJe+BgMAAAAAAKo+Sn0t69UIqj5KfS3r1QgXQ0lRLkNNRy5JUV9DT01QQU5ZX05BTUUBAAAA | K1: TmcAAAMAAAAcQ2hpcG90bGUgTWV4aWNhbiBHcmlsbCwgSW5jLgCCHvxUL+vVCG5eNIov69UIJkNJUS5LUi5JUV9GWF9SQVRFX0ZDLkpVTjIwMTkuOC8yNC8yMDE3AQAAAMQxlAYCAAAACjExMTUuMTY0NjcAqj5KfS3r1QgBP2Z9LevVCCpDSVEuTkFTREFRR1M6V0VOLklRX0NPTVBBTllfVElDS0VSX05PX0VYQ0gBAAAABVwAAAMAAAADV0VOAKFSM1Qv69UIghA0ii/r1QgmQ0lRLktSLklRX0ZYX1JBVEVfRkMuRkVCMjAyMC44LzI0LzIwMTcBAAAAxDGUBgIAAAAKMTExMS4xODA4MwCqPkp9LevVCAE/Zn0t69UII0NJUS5LUi5JUV9GWF9SQVRFLk1BWTIwMTcuOC8yNS8yMDE3AQAAAMhLkwYCAAAACzExMjYuMzA4Njk2AKo+Sn0t69UIB2ZmfS3r1QgjQ0lRLktSLklRX0ZYX1JBVEUuSlVMMjAxNy44LzI1LzIwMTcBAAAAyEuTBgIAAAALMTEzMy45MzgwOTUAqj5KfS3r1QgBP2Z9LevVCDBDSVEuSEFCVC5JUV9UT1RBTF9ERUJULjUwMC4yMDE4LTA3LTEwLkxGUi4uVVNELkgBAAAAI9YREAIAAAAGMTcuMjIxAQgAAAAFAAAAATEBAAAACjE4ODY0NTE1ODIDAAAAAzE2MAIAAAAENDE3MwQAAAABMAcAAAAJNy8xMC8yMDE4CAAAAAkzLzI3LzIwMTgJAAAAATCCHvxUL+vVCFaFNIov69UII0NJUS5LUi5JUV9GWF9SQVRFLkpVTDIwMTQuOC8yNS8yMDE3AQAAAMhLkwYCAAAACzEwMTkuOTM0NzgzAKo+Sn0t69UI+Ixm | L1: fS3r1QgvQ0lRLkhBQlQuSVFfVE9UQUxfREVCVC41MDAuMjAxOC0wNy0xMC5MRlIuLlVTRC4BAAAAI9YREAIAAAAGMTcuMjIxAQgAAAAFAAAAATEBAAAACjE4ODY0NTE1ODIDAAAAAzE2MAIAAAAENDE3MwQAAAABMAcAAAAJNy8xMC8yMDE4CAAAAAkzLzI3LzIwMTgJAAAAATAU/BBxL+vVCHY3NIov69UII0NJUS5LUi5JUV9GWF9SQVRFLk1BUjIwMTUuOC8yNS8yMDE3AQAAAMhLkwYCAAAACzExMTIuNTY4MTgyAKo+Sn0t69UIB2ZmfS3r1QgjQ0lRLktSLklRX0ZYX1JBVEUuTUFZMjAxNi44LzI1LzIwMTcBAAAAyEuTBgIAAAALMTE2OC40NTkwOTEAqj5KfS3r1QgHZmZ9LevVCCtDSVEuTllTRTpTSEFLLklRX1BFUklPRERBVEUuNTAwLjIwMTgtMDctMTAuAQAAAJ0Tpg0FAAAACjIwMTgtMDMtMjgAFPwQcS/r1QhUZnS3L+vVCDBDSVEuTUNELklRX1BSRUZfRVFVSVRZLjUwMC4yMDE4LTA3LTEwLkxGUi4uVVNELkgBAAAA4CACAAMAAAAAAIIe/FQv69UIVEQkiy/r1QgsQ0lRLlVTRC5JUV9GVUxMX0NVUlZFX0FOTlVBTC4uLjVZLjIwMTgtMDctMTABAAAAAAAAAAIAAAAJMC4wMzg3OTU3AKFSM1Qv69UIghA0ii/r1QgjQ0lRLktSLklRX0ZYX1JBVEUuQVVHMjAxNS44LzI1LzIwMTcBAAAAyEuTBgIAAAALMTE3OS42MzMzMzMAqj5KfS3r1QgHZmZ9LevVCCNDSVEuS1IuSVFfRlhfUkFURS5KVUwyMDE1LjgvMjUv | M1: MjAxNwEAAADIS5MGAgAAAAsxMTQzLjAxNzM5MQCqPkp9LevVCAdmZn0t69UII0NJUS5LUi5JUV9GWF9SQVRFLkZFQjIwMTMuOC8yNS8yMDE3AQAAAMhLkwYCAAAACDEwODcuMDk1AL4XSn0t69UI+IxmfS3r1QgtQ0lRQVZHLkhBQlQuSVFfRUZGRUNUX1RBWF9SQVRFLjk5Ni4yMDE4LTA3LTEwAQAAACPWERACAAAACTM4Ljk0Njg3NQCCHvxUL+vVCHY3NIov69UIMENJUS5IQUJULklRX1BSRUZfRVFVSVRZLjUwMC4yMDE4LTA3LTEwLkxGUi4uVVNELgEAAAAj1hEQAwAAAAAAFPwQcS/r1QhuXjSKL+vVCBhDSVEuXlNQWC5JUV9DT01QQU5ZX05BTUUBAAAAm7goAAMAAAAHUyZQIDUwMABOt2twL+vVCIIQNIov69UIL0NJUS5NQ0QuSVFfUFJFRl9FUVVJVFkuNTAwLjIwMTgtMDctMTAuTEZSLi5VU0QuAQAAAOAgAgADAAAAAAAE4B2LL+vVCATgHYsv69UIGENJUS5IQUJULklRX0NPTVBBTllfTkFNRQEAAAAj1hEQAwAAABtUaGUgSGFiaXQgUmVzdGF1cmFudHMsIEluYy4Agh78VC/r1QhuXjSKL+vVCCNDSVEuS1IuSVFfRlhfUkFURS5BVUcyMDE0LjgvMjUvMjAxNwEAAADIS5MGAgAAAAsxMDI1LjQ5MDQ3NgCqPkp9LevVCPiMZn0t69UIGENJUS5aT0VTLklRX0NPTVBBTllfTkFNRQEAAADUxk8CAwAAABNab2UncyBLaXRjaGVuLCBJbmMuAIIe/FQv69UIdjc0ii/r1QglQ0lRUEMuXlNQWC5JUV9MQVNUU0FMRVBS | N1: SUNFLi0xWS40MTYzOQEAAACbuCgAAgAAABAyOS42MDExODUwNzE2NTkxAE63a3Av69UIUI10ty/r1QgjQ0lRLktSLklRX0ZYX1JBVEUuT0NUMjAxMy44LzI1LzIwMTcBAAAAyEuTBgIAAAALMTA2Ny41MTczOTEAqj5KfS3r1Qj4jGZ9LevVCCZDSVEuS1IuSVFfRlhfUkFURV9GQy5KQU4yMDIwLjgvMjQvMjAxNwEAAADEMZQGAgAAAAkxMTA4LjQ3ODMAqj5KfS3r1QgBP2Z9LevVCCNDSVEuS1IuSVFfRlhfUkFURS5BUFIyMDE2LjgvMjUvMjAxNwEAAADIS5MGAgAAAAsxMTQ3LjU5MDQ3NgCqPkp9LevVCAdmZn0t69UILENJUUFWRy5XRU4uSVFfRUZGRUNUX1RBWF9SQVRFLjk5Ni4yMDE4LTA3LTEwAQAAAAVcAAACAAAACTM1LjE4MTUyNQCCHvxUL+vVCG5eNIov69UII0NJUS5LUi5JUV9GWF9SQVRFLk9DVDIwMTYuOC8yNS8yMDE3AQAAAMhLkwYCAAAACzExMjMuNjg1NzE0AKo+Sn0t69UIB2ZmfS3r1QgmQ0lRLktSLklRX0ZYX1JBVEVfRkMuQVVHMjAxOS44LzI0LzIwMTcBAAAAxDGUBgIAAAAKMTExNi44Mjc2OQCqPkp9LevVCAE/Zn0t69UII0NJUS5LUi5JUV9GWF9SQVRFLkZFQjIwMTQuOC8yNS8yMDE3AQAAAMhLkwYCAAAABjEwNzEuNACqPkp9LevVCPiMZn0t69UIJkNJUS5LUi5JUV9GWF9SQVRFX0ZDLk5PVjIwMTguOC8yNC8yMDE3AQAAAMQxlAYCAAAACjEwOTMuMTE1NDQAqj5KfS3r1QgBP2Z9LevV | O1: CCVDSVEuTkRMUy5JUV9NQVJLRVRDQVAuMjAxOC0wNy0xMC5VU0QuAQAAAPmfewACAAAACjQ4OS44MTA0MjYBBgAAAAUAAAABMQEAAAAKMTg4ODc0NzA4MwMAAAADMTYwAgAAAAYxMDAwNTQEAAAAATAHAAAACTcvMTAvMjAxOBT8EHEv69UIdjc0ii/r1QgdQ0lRLk5ZU0U6U0hBSy5JUV9RVUlDS19DT01QLjUBAAAAnROmDQMAAAAMTmFzZGFxR1M6V0VOAE63a3Av69UIghA0ii/r1QgmQ0lRLktSLklRX0ZYX1JBVEVfRkMuT0NUMjAxOS44LzI0LzIwMTcBAAAAxDGUBgIAAAAKMTExMC4yMjYxNACqPkp9LevVCAE/Zn0t69UII0NJUS5LUi5JUV9GWF9SQVRFLkFQUjIwMTcuOC8yNS8yMDE3AQAAAMhLkwYCAAAACDExMzIuNzI1AKo+Sn0t69UIB2ZmfS3r1QgdQ0lRLk5ZU0U6U0hBSy5JUV9RVUlDS19DT01QLjMBAAAAnROmDQMAAAANTmFzZGFxR1M6TkRMUwBOt2twL+vVCIIQNIov69UIJkNJUS5ORExTLklRX01BUktFVENBUC4yMDE4LTA3LTEwLlVTRC5IAQAAAPmfewACAAAACjQ4OS44MTA0MjYBBgAAAAUAAAABMQEAAAAKMTg4ODc0NzA4MwMAAAADMTYwAgAAAAYxMDAwNTQEAAAAATAHAAAACTcvMTAvMjAxOIIe/FQv69UIVoU0ii/r1QgjQ0lRLktSLklRX0ZYX1JBVEUuU0VQMjAxNC44LzI1LzIwMTcBAAAAyEuTBgIAAAALMTAzMS4xMDQ1NDUAvhdKfS3r1Qj4jGZ9LevVCCNDSVEuS1IuSVFfRlhfUkFURS5O | P1: T1YyMDE0LjgvMjUvMjAxNwEAAADIS5MGAgAAAAkxMDk1LjQ0MDUAqj5KfS3r1Qj4jGZ9LevVCCNDSVEuS1IuSVFfRlhfUkFURS5ERUMyMDE2LjgvMjUvMjAxNwEAAADIS5MGAgAAAAsxMTgyLjA1NDU0NQCqPkp9LevVCAdmZn0t69UIHUNJUS5OWVNFOlNIQUsuSVFfQ09NUEFOWV9OQU1FAQAAAJ0Tpg0DAAAAEFNoYWtlIFNoYWNrIEluYy4AYicwGi3r1Qj9vj1SL+vVCB5DSVEuTUNELklRX0JFVEFfNVlSLjIwMTgtMDctMTABAAAA4CACAAIAAAARMC42ODE0MzUwMDM5OTcxOTkAgh78VC/r1QhuXjSKL+vVCCNDSVEuS1IuSVFfRlhfUkFURS5KVU4yMDE2LjgvMjUvMjAxNwEAAADIS5MGAgAAAAsxMTcxLjM3MjcyNwCqPkp9LevVCAdmZn0t69UII0NJUS5LUi5JUV9GWF9SQVRFLkFVRzIwMTMuOC8yNS8yMDE3AQAAAMhLkwYCAAAACzExMTYuOTU0NTQ1AKo+Sn0t69UI+IxmfS3r1QgiQ0lRLk5ZU0U6U0hBSy5JUV9DT01QQU5ZX05BTUVfTE9ORwEAAACdE6YNAwAAABxTaGFrZSBTaGFjayBJbmMuIChOWVNFOlNIQUspAE63a3Av69UIe+kzii/r1QglQ0lRLkhBQlQuSVFfTUFSS0VUQ0FQLjIwMTgtMDctMTAuVVNELgEAAAAj1hEQAgAAAAoyMTUuMjk1NTI4AQYAAAAFAAAAATEBAAAACjE4ODY0NTE1ODIDAAAAAzE2MAIAAAAGMTAwMDU0BAAAAAEwBwAAAAk3LzEwLzIwMTgU/BBxL+vVCG5eNIov69UII0NJUS5L | Q1: Ui5JUV9GWF9SQVRFLk1BUjIwMTMuOC8yNS8yMDE3AQAAAMhLkwYCAAAACzExMDEuNjA0NzYyAKo+Sn0t69UI+IxmfS3r1QgjQ0lRLktSLklRX0ZYX1JBVEUuU0VQMjAxNi44LzI1LzIwMTcBAAAAyEuTBgIAAAALMTEwNy45OTA5MDkAqj5KfS3r1QgHZmZ9LevVCCNDSVEuS1IuSVFfRlhfUkFURS5OT1YyMDE2LjgvMjUvMjAxNwEAAADIS5MGAgAAAAcxMTYxLjM1AKo+Sn0t69UIB2ZmfS3r1QgjQ0lRLktSLklRX0ZYX1JBVEUuREVDMjAxNC44LzI1LzIwMTcBAAAAyEuTBgIAAAALMTEwMy45OTU2NTIAqj5KfS3r1Qj4jGZ9LevVCCNDSVEuS1IuSVFfRlhfUkFURS5KVU4yMDE3LjgvMjUvMjAxNwEAAADIS5MGAgAAAAsxMTI5LjYyMjcyNwCqPkp9LevVCAdmZn0t69UIMENJUS5XRU4uSVFfUFJFRl9FUVVJVFkuNTAwLjIwMTgtMDctMTAuTEZSLi5VU0QuSAEAAAAFXAAAAwAAAAAAgh78VC/r1QhWhTSKL+vVCCZDSVEuS1IuSVFfRlhfUkFURV9GQy5ERUMyMDE4LjgvMjQvMjAxNwEAAADEMZQGAgAAAAoxMDk1Ljg4MzE0AKo+Sn0t69UIB2ZmfS3r1QgjQ0lRLktSLklRX0ZYX1JBVEUuSlVOMjAxNC44LzI1LzIwMTcBAAAAyEuTBgIAAAALMTAxOS43OTUyMzgAqj5KfS3r1Qj4jGZ9LevVCC9DSVEuQ01HLklRX1BSRUZfRVFVSVRZLjUwMC4yMDE4LTA3LTEwLkxGUi4uVVNELgEAAABOZwAAAwAAAAAAFPwQcS/r1Qh2 | R1: NzSKL+vVCCpDSVEuTllTRTpTSEFLLklRX01BUktFVENBUC4yMDE4LTA3LTEwLlVTRC4BAAAAnROmDQIAAAALMTc3MS41OTEyNzYBBgAAAAUAAAABMQEAAAAKMTg4NzI5MDEyNQMAAAADMTYwAgAAAAYxMDAwNTQEAAAAATAHAAAACTcvMTAvMjAxOBT8EHEv69UIVGZ0ty/r1QgmQ0lRLktSLklRX0ZYX1JBVEVfRkMuSlVMMjAxOS44LzI0LzIwMTcBAAAAxDGUBgIAAAAKMTExNi45MzU1OQCqPkp9LevVCAE/Zn0t69UII0NJUS5LUi5JUV9GWF9SQVRFLkpVTjIwMTUuOC8yNS8yMDE3AQAAAMhLkwYCAAAACzExMTIuMTk1NDU1AKo+Sn0t69UI+IxmfS3r1QgoQ0lRLklRVDM2MTgzODM5LklRX1JBVEVfTEVWRUwuMjAxOC0wNy0xMAEAAAAdHygCAgAAAAQyLjg3AE63a3Av69UIVoU0ii/r1QglQ0lRUEMuXlNQWC5JUV9MQVNUU0FMRVBSSUNFLi0xWS40MjAwNAEAAACbuCgAAgAAABAxMS4zOTA5NzY1NTI5MjQ2AE63a3Av69UIUI10ty/r1QgdQ0lRLk5ZU0U6U0hBSy5JUV9RVUlDS19DT01QLjEBAAAAnROmDQMAAAAJTllTRTpaT0VTAE63a3Av69UIghA0ii/r1QgvQ0lRUkFOR0UuTllTRTpTSEFLLklRX0JPTkRfTElTVC4xLjUwMC4uLi4uQk9ORFMDAAAAnROmDQAAAABOt2twL+vVCGw/dLcv69UIJUNJUVBDLl5TUFguSVFfTEFTVFNBTEVQUklDRS4tMVkuNDEyNzQBAAAAm7goAAIAAAAQMTMuNDA1MDk5MzU1NDA2 | S1: OABOt2twL+vVCFCNdLcv69UIHkNJUS4zNjAyLklRX0VWX09WRVJfTFRNX0VCSVREQQUAAAAAAAAACAAAABQoSW52YWxpZCBJZGVudGlmaWVyKU63a3Av69UIYwV6cC/r1QgwQ0lRLlpPRVMuSVFfVE9UQUxfREVCVC41MDAuMjAxOC0wNy0xMC5MRlIuLlVTRC5IAQAAANTGTwICAAAABjQ3LjYzNAEIAAAABQAAAAExAQAAAAoxODkwNjUzMDk4AwAAAAMxNjACAAAABDQxNzMEAAAAATAHAAAACTcvMTAvMjAxOAgAAAAJNC8xNi8yMDE4CQAAAAEwgh78VC/r1QhSrDSKL+vVCCVDSVFQQy5eU1BYLklRX0xBU1RTQUxFUFJJQ0UuLTFZLjQwOTA4AQAAAJu4KAACAAAAFC0wLjAwMjQ3OTQ1MDgwNzg3OTc5AE63a3Av69UIPLR0ty/r1QgXQ0lRLldFTi5JUV9DT01QQU5ZX05BTUUBAAAABVwAAAMAAAATVGhlIFdlbmR5J3MgQ29tcGFueQCCHvxUL+vVCG5eNIov69UIJkNJUS5LUi5JUV9GWF9SQVRFX0ZDLk1BWTIwMTkuOC8yNC8yMDE3AQAAAMQxlAYCAAAACjExMTMuNTQ0NzgAqj5KfS3r1QgBP2Z9LevVCB5DSVEuV0VOLklRX0JFVEFfNVlSLjIwMTgtMDctMTABAAAABVwAAAIAAAARMC41NjA1NzAxMzUxNjI1OTQAgh78VC/r1QhuXjSKL+vVCCVDSVEuV0VOLklRX01BUktFVENBUC4yMDE4LTA3LTEwLlVTRC5IAQAAAAVcAAACAAAACjQxODguNjI3NTEBBgAAAAUAAAABMQEAAAAKMTg4ODA1NTE4MAMAAAADMTYwAgAA | T1: AAYxMDAwNTQEAAAAATAHAAAACTcvMTAvMjAxOIIe/FQv69UIVoU0ii/r1QgmQ0lRLktSLklRX0ZYX1JBVEVfRkMuU0VQMjAxOC44LzI0LzIwMTcBAAAAxDGUBgIAAAAKMTA5NC4wNDczOQCqPkp9LevVCAdmZn0t69UIM0NJUS5OWVNFOlNIQUsuSVFfUFJFRl9FUVVJVFkuLjIwMTgtMDctMTAuTEZSLi5VU0QuSAEAAACdE6YNAwAAAAAATrdrcC/r1QhUZnS3L+vVCCNDSVEuS1IuSVFfRlhfUkFURS5BUFIyMDEzLjgvMjUvMjAxNwEAAADIS5MGAgAAAAsxMTIxLjgzMTgxOACqPkp9LevVCPiMZn0t69UIJUNJUVBDLl5TUFguSVFfTEFTVFNBTEVQUklDRS4tMVkuNDIzNjkBAAAAm7goAAIAAAASLTAuNzI2ODY4NjYzMTIxMzI2AE63a3Av69UIUI10ty/r1QgvQ0lRLk5ZU0U6U0hBSy5JUV9JTkNfVEFYLi4yMDE4LTA3LTEwLkxGUi4uVVNELkgBAAAAnROmDQIAAAAHMTUwLjk0OQEIAAAABQAAAAExAQAAAAoxODg3MjkwNTQxAwAAAAMxNjACAAAAAjc1BAAAAAEwBwAAAAk3LzEwLzIwMTgIAAAACTMvMjgvMjAxOAkAAAABME63a3Av69UIVGZ0ty/r1QgfQ0lRLlpPRVMuSVFfQkVUQV81WVIuMjAxOC0wNy0xMAEAAADUxk8CAgAAABEwLjE0Nzk3NDYyODU4Nzg0NgCCHvxUL+vVCG5eNIov69UII0NJUS5LUi5JUV9GWF9SQVRFLk1BUjIwMTcuOC8yNS8yMDE3AQAAAMhLkwYCAAAACzExMzUuMTA4Njk2AKo+Sn0t69UI | U1: B2ZmfS3r1QgjQ0lRLktSLklRX0ZYX1JBVEUuSkFOMjAxNC44LzI1LzIwMTcBAAAAyEuTBgIAAAAKMTA2NS43NjA4NwCqPkp9LevVCPiMZn0t69UIJkNJUS5LUi5JUV9GWF9SQVRFX0ZDLkpVTDIwMjAuOC8yNC8yMDE3AQAAAMQxlAYCAAAACjExMjEuNTM2NzcAqj5KfS3r1QgBP2Z9LevVCCNDSVEuS1IuSVFfRlhfUkFURS5NQVkyMDE0LjgvMjUvMjAxNwEAAADIS5MGAgAAAAsxMDI1Ljk5MDkwOQCqPkp9LevVCPiMZn0t69UIJkNJUS5aT0VTLklRX01BUktFVENBUC4yMDE4LTA3LTEwLlVTRC5IAQAAANTGTwICAAAACjE5NS42NDAxNTYBBgAAAAUAAAABMQEAAAAKMTg5MDY1MzA5OAMAAAADMTYwAgAAAAYxMDAwNTQEAAAAATAHAAAACTcvMTAvMjAxOIIe/FQv69UIUqw0ii/r1QgwQ0lRLk5ETFMuSVFfVE9UQUxfREVCVC41MDAuMjAxOC0wNy0xMC5MRlIuLlVTRC5IAQAAAPmfewACAAAABjYyLjg3MQEIAAAABQAAAAExAQAAAAoxODg4NzQ3MDgzAwAAAAMxNjACAAAABDQxNzMEAAAAATAHAAAACTcvMTAvMjAxOAgAAAAINC8zLzIwMTgJAAAAATCCHvxUL+vVCFaFNIov69UIJUNJUS5aT0VTLklRX01BUktFVENBUC4yMDE4LTA3LTEwLlVTRC4BAAAA1MZPAgIAAAAKMTk1LjY0MDE1NgEGAAAABQAAAAExAQAAAAoxODkwNjUzMDk4AwAAAAMxNjACAAAABjEwMDA1NAQAAAABMAcAAAAJNy8xMC8yMDE4FPwQcS/r | V1: 1Qh2NzSKL+vVCCZDSVEuS1IuSVFfRlhfUkFURV9GQy5NQVIyMDIwLjgvMjQvMjAxNwEAAADEMZQGAgAAAAoxMTE1Ljc0MjYzAKo+Sn0t69UIAT9mfS3r1QgmQ0lRLktSLklRX0ZYX1JBVEVfRkMuT0NUMjAxOC44LzI0LzIwMTcBAAAAxDGUBgIAAAAKMTA5MS40MTU3MwCqPkp9LevVCAdmZn0t69UIJkNJUS5LUi5JUV9GWF9SQVRFX0ZDLkFVRzIwMTguOC8yNC8yMDE3AQAAAMQxlAYCAAAACjEwOTIuMDM5MjMAqj5KfS3r1QgBP2Z9LevVCCNDSVEuS1IuSVFfRlhfUkFURS5NQVIyMDE2LjgvMjUvMjAxNwEAAADIS5MGAgAAAAsxMTkwLjUxNzM5MQCqPkp9LevVCAdmZn0t69UIJkNJUS5LUi5JUV9GWF9SQVRFX0ZDLk5PVjIwMTkuOC8yNC8yMDE3AQAAAMQxlAYCAAAACjExMDguOTEzNDEAqj5KfS3r1QgBP2Z9LevVCCNDSVEuS1IuSVFfRlhfUkFURS5OT1YyMDEzLjgvMjUvMjAxNwEAAADIS5MGAgAAAAsxMDYyLjcwOTUyNACqPkp9LevVCPiMZn0t69UII0NJUS5LUi5JUV9GWF9SQVRFLkpBTjIwMTYuOC8yNS8yMDE3AQAAAMhLkwYCAAAACzEyMDAuMzQyODU3AKo+Sn0t69UIB2ZmfS3r1QgjQ0lRLktSLklRX0ZYX1JBVEUuQVVHMjAxNi44LzI1LzIwMTcBAAAAyEuTBgIAAAALMTExMS4xMDg2OTYAqj5KfS3r1QgHZmZ9LevVCCxDSVFBVkcuQ01HLklRX0VGRkVDVF9UQVhfUkFURS45OTYuMjAxOC0wNy0xMAEA | W1: AABOZwAAAgAAAAgzOC4yOTUzNgCCHvxUL+vVCG5eNIov69UII0NJUS5LUi5JUV9GWF9SQVRFLkFQUjIwMTQuOC8yNS8yMDE3AQAAAMhLkwYCAAAACzEwNDQuNTU4MTgyAKo+Sn0t69UI+IxmfS3r1QgjQ0lRLktSLklRX0ZYX1JBVEUuT0NUMjAxNC44LzI1LzIwMTcBAAAAyEuTBgIAAAALMTA2MC42ODY5NTcAqj5KfS3r1Qj4jGZ9LevVCCVDSVFQQy5eU1BYLklRX0xBU1RTQUxFUFJJQ0UuLTFZLjQwNTQzAQAAAJu4KAACAAAADzEyLjc4MjA3OTAzNDM4OABOt2twL+vVCDy0dLcv69UII0NJUS5LUi5JUV9GWF9SQVRFLk1BUjIwMTQuOC8yNS8yMDE3AQAAAMhLkwYCAAAACzEwNzAuNzM4MDk1AKo+Sn0t69UI+IxmfS3r1QgfQ0lRLkhBQlQuSVFfQkVUQV81WVIuMjAxOC0wNy0xMAEAAAAj1hEQAgAAABEwLjUyMzI4OTkwNzM4MjQ5NgCCHvxUL+vVCG5eNIov69UII0NJUS5LUi5JUV9GWF9SQVRFLkpBTjIwMTcuOC8yNS8yMDE3AQAAAMhLkwYCAAAACzExODYuMDI3MjczAKo+Sn0t69UIB2ZmfS3r1QgcQ0lRLktSLklRX0ZYX1JBVEUuLjgvMjUvMjAxNwEAAABEl74GAwAAAAAAqj5KfS3r1QiqPkp9LevVCCNDSVEuS1IuSVFfRlhfUkFURS5GRUIyMDE2LjgvMjUvMjAxNwEAAADIS5MGAgAAAAsxMjE0LjgzODA5NQCqPkp9LevVCAdmZn0t69UIMkNJUS5OWVNFOlNIQUsuSVFfUFJFRl9FUVVJVFkuLjIwMTgtMDct | X1: MTAuTEZSLi5VU0QuAQAAAJ0Tpg0DAAAAAAAU/BBxL+vVCFRmdLcv69UIJENJUS5XRU4uSVFfTUFSS0VUQ0FQLjIwMTgtMDctMTAuVVNELgEAAAAFXAAAAgAAAAo0MTg4LjYyNzUxAQYAAAAFAAAAATEBAAAACjE4ODgwNTUxODADAAAAAzE2MAIAAAAGMTAwMDU0BAAAAAEwBwAAAAk3LzEwLzIwMTgU/BBxL+vVCG5eNIov69UILkNJUS5XRU4uSVFfVE9UQUxfREVCVC41MDAuMjAxOC0wNy0xMC5MRlIuLlVTRC4BAAAABVwAAAIAAAAIMjgwOC4wMjEBCAAAAAUAAAABMQEAAAAKMTg4ODA1NTE4MAMAAAADMTYwAgAAAAQ0MTczBAAAAAEwBwAAAAk3LzEwLzIwMTgIAAAACDQvMS8yMDE4CQAAAAEwFPwQcS/r1QhuXjSKL+vVCB9DSVEuTkRMUy5JUV9CRVRBXzVZUi4yMDE4LTA3LTEwAQAAAPmfewACAAAAES0wLjYyNzcyNzE0MTM4Nzg4AIIe/FQv69UIbl40ii/r1QgmQ0lRLk5ZU0U6Q01HLklRX0NPTVBBTllfVElDS0VSX05PX0VYQ0gBAAAATmcAAAMAAAADQ01HAKFSM1Qv69UIghA0ii/r1QglQ0lRUEMuXlNQWC5JUV9MQVNUU0FMRVBSSUNFLi0xWS40MjczNQEAAACbuCgAAgAAABA5LjUzNTAyMTQ4NzU1ODU3AE63a3Av69UIUI10ty/r1QgjQ0lRLktSLklRX0ZYX1JBVEUuQVBSMjAxNS44LzI1LzIwMTcBAAAAyEuTBgIAAAALMTA4OC42NjM2MzYAqj5KfS3r1QgHZmZ9LevVCCNDSVEuS1IuSVFfRlhfUkFURS5P | Y1: Q1QyMDE1LjgvMjUvMjAxNwEAAADIS5MGAgAAAAsxMTQ5LjIxODE4MgCqPkp9LevVCPiMZn0t69UIMUNJUS5ORExTLklRX1BSRUZfRVFVSVRZLjUwMC4yMDE4LTA3LTEwLkxGUi4uVVNELkgBAAAA+Z97AAMAAAAAAIIe/FQv69UIVoU0ii/r1QgjQ0lRLktSLklRX0ZYX1JBVEUuRkVCMjAxNy44LzI1LzIwMTcBAAAAyEuTBgIAAAAGMTE0NC42AKo+Sn0t69UIB2ZmfS3r1QgmQ0lRLktSLklRX0ZYX1JBVEVfRkMuREVDMjAxOS44LzI0LzIwMTcBAAAAxDGUBgIAAAAKMTEwOC42Nzg2OQCqPkp9LevVCAE/Zn0t69UIJ0NJUS5OWVNFOlpPRVMuSVFfQ09NUEFOWV9USUNLRVJfTk9fRVhDSAEAAADUxk8CAwAAAARaT0VTAKFSM1Qv69UIghA0ii/r1QgrQ0lRLk5BU0RBUUdTOk5ETFMuSVFfQ09NUEFOWV9USUNLRVJfTk9fRVhDSAEAAAD5n3sAAwAAAARORExTAKFSM1Qv69UIghA0ii/r1QgjQ0lRLktSLklRX0ZYX1JBVEUuRkVCMjAxNS44LzI1LzIwMTcBAAAAyEuTBgIAAAAHMTEwMC42NgCqPkp9LevVCAdmZn0t69UIL0NJUS5ORExTLklRX1RPVEFMX0RFQlQuNTAwLjIwMTgtMDctMTAuTEZSLi5VU0QuAQAAAPmfewACAAAABjYyLjg3MQEIAAAABQAAAAExAQAAAAoxODg4NzQ3MDgzAwAAAAMxNjACAAAABDQxNzMEAAAAATAHAAAACTcvMTAvMjAxOAgAAAAINC8zLzIwMTgJAAAAATAU/BBxL+vVCG5eNIov69UIJENJ | Z1: US5NQ0QuSVFfTUFSS0VUQ0FQLjIwMTgtMDctMTAuVVNELgEAAADgIAIAAgAAAA0xMjYxMTUuMTkzNjY3AQYAAAAFAAAAATEBAAAACjE4ODc2NjU1OTYDAAAAAzE2MAIAAAAGMTAwMDU0BAAAAAEwBwAAAAk3LzEwLzIwMTgE4B2LL+vVCATgHYsv69UILkNJUS5DTUcuSVFfVE9UQUxfREVCVC41MDAuMjAxOC0wNy0xMC5MRlIuLlVTRC4BAAAATmcAAAIAAAABMAEIAAAABQAAAAExAQAAAAoxODg0OTYzMzMwAwAAAAMxNjACAAAABDQxNzMEAAAAATAHAAAACTcvMTAvMjAxOAgAAAAJMy8zMS8yMDE4CQAAAAEwFPwQcS/r1Qh2NzSKL+vVCC1DSVFBVkcuWk9FUy5JUV9FRkZFQ1RfVEFYX1JBVEUuOTk2LjIwMTgtMDctMTABAAAA1MZPAgIAAAAIMzcuNTMwMjUAgh78VC/r1QhuXjSKL+vVCCtDSVEuTkFTREFRR006SEFCVC5JUV9DT01QQU5ZX1RJQ0tFUl9OT19FWENIAQAAACPWERADAAAABEhBQlQAoVIzVC/r1QiCEDSKL+vVCA==

Sheet Cover
B2: Shake Shack - 3 Statement Model with DCF
D6: Company name: | F6: Shake Shack | I6: Circ switch: | K6: 0
D7: Ticker: | F7: SHAK
D9: Latest update: | F9: 44407 | I9: Enterprise value: | K9: 1526428.3
D10: Created by: | F10: Wall Street Training | I10: Equity value: | K10: 1559857.3
I11: Target price per share: | K11: 57.605758
I12: Share price: | K12: 43.2
K13: (units in USD '000 except per share number)
C29: © 2021 Wall Street Training Asia Inc.
C30: No portion of this report may be reproduced, reused, or otherwise distributed in any form without prior written consent.
C31: For more information, please visit/contatct Wall Street Training Asia Inc. through www.wallstreettraining.co.kr
C33: © 2021 (주)월스트릿트레이닝아시아.
C34: 이 파일은 대한민국 및 미국 저작권법의 보호를 받는 저작물 입니다.
C35: 파일의 원 저자로부터 서면에 의한 허락없이 이 파일의 일부나 전체를 어떠한 형태로도 가공/배포할 수 없습니다.
C36: 이를 위반시에는 형사/민사상의 법적 책임을 질수 있으며, 특별한 문의가 있는경우 www.wallstreettraining.co.kr에 있는 정보로 연락주시기 바랍니다.

Sheet Operations
B2: Shake Shack, Inc (SHAK)
B3: Operations Analysis & Assumptions
B4: (units in USD '000)
H7: Historical Year Ending December 31, | K7: Projected year Ending December 31,
F8: 2013 | G8: 2014 | H8: 2015 | I8: 2016 | J8: 2017 | K8: 2018 | L8: 2019 | M8: 2020 | N8: 2021 | O8: 2022 | P8: 2023 | Q8: 2024 | R8: 2025 | S8: 2026 | T8: 2027
A10: x | B10: Store
B11: Store Count (stores)
C12: Domestic Company Operated | F12: 21 | G12: 31 | H12: 44 | I12: 64 | J12: 90 | K12: 123 | L12: 163 | M12: 200 | N12: 225 | O12: 250 | P12: 270 | Q12: 290 | R12: 305 | S12: 315 | T12: 320
C13: Domestic Licensed | F13: 4 | G13: 5 | H13: 5 | I13: 7 | J13: 10 | K13: 13 | L13: 16 | M13: 19 | N13: 22 | O13: 24 | P13: 26 | Q13: 28 | R13: 29 | S13: 30 | T13: 31
C14: International Licensed | F14: 15 | G14: 27 | H14: 35 | I14: 43 | J14: 59 | K14: 73 | L14: 93 | M14: 120 | N14: 145 | O14: 165 | P14: 180 | Q14: 195 | R14: 210 | S14: 220 | T14: 230
B15: Total Stores | F15: 40 | G15: 63 | H15: 84 | I15: 114 | J15: 159 | K15: 209 | L15: 272 | M15: 339 | N15: 392 | O15: 439 | P15: 476 | Q15: 513 | R15: 544 | S15: 565 | T15: 581
C16: Comp Store Base | F16: 8 | G16: 13 | H16: 21 | I16: 29 | J16: 43 | K16: 64 | L16: 90 | M16: 123 | N16: 163 | O16: 200 | P16: 225 | Q16: 250 | R16: 270 | S16: 290 | T16: 305
B18: New Store Openings (net)
C19: Domestic Company Operated | G19: 10 | H19: 13 | I19: 20 | J19: 26 | K19: 33 | L19: 40 | M19: 37 | N19: 25 | O19: 25 | P19: 20 | Q19: 20 | R19: 15 | S19: 10 | T19: 5
C20: Domestic Licensed | G20: 1 | H20: 0 | I20: 2 | J20: 3 | K20: 3 | L20: 3 | M20: 3 | N20: 3 | O20: 2 | P20: 2 | Q20: 2 | R20: 1 | S20: 1 | T20: 1
C21: International Licensed | G21: 12 | H21: 8 | I21: 8 | J21: 16 | K21: 14 | L21: 20 | M21: 27 | N21: 25 | O21: 20 | P21: 15 | Q21: 15 | R21: 15 | S21: 10 | T21: 10
B23: Closures (implied) | G23: 0 | H23: 0 | I23: -2 | J23: -1 | K23: 0 | L23: 0 | M23: 0 | N23: 0 | O23: 0 | P23: 0 | Q23: 0 | R23: 0 | S23: 0 | T23: 0
B24: New Domestic Company Store Openings (gross) | G24: 10 | H24: 13 | I24: 22 | J24: 27 | K24: 33 | L24: 40 | M24: 37 | N24: 25 | O24: 25 | P24: 20 | Q24: 20 | R24: 15 | S24: 10 | T24: 5
A26: x | B26: Revenue
B27: System-wide Revenue | F27: 139903 | G27: 217442 | H27: 295257 | I27: 402791 | J27: 532137 | K27: 675451.2 | L27: 854531.99 | M27: 1063939.5 | N27: 1269105.6 | O27: 1439397.4 | P27: 1583666.3 | Q27: 1710906 | R27: 1827112.4 | S27: 1915256.2 | T27: 1976836.4
B28: Licensed Location Revenue | F28: 61316 | G28: 105400 | H28: 112038 | I28: 143441 | J28: 185749 | K28: 234683.72 | L28: 292294.78 | M28: 371739.01 | N28: 458677.97 | O28: 533625.35 | P28: 592084.3 | Q28: 643048.52 | R28: 692513.79 | S28: 732985.38 | T28: 765962.22
B30: Corporate Revenue | F30: 82456 | G30: 118530 | H30: 190592 | I30: 268475 | J30: 358810 | K30: 456021.93 | L30: 581236.37 | M30: 716363.54 | N30: 840241.65 | O30: 940457.65 | P30: 1030067.5 | Q30: 1109655.7 | R30: 1179612 | S30: 1229914.9 | T30: 1260661.7
B31: Company Operated Stores Revenue | F31: 78587 | G31: 112042 | H31: 183219 | I31: 259350 | J31: 346388 | K31: 440767.48 | L31: 562237.21 | M31: 692200.5 | N31: 810427.58 | O31: 905772.01 | P31: 991581.99 | Q31: 1067857.5 | R31: 1134598.6 | S31: 1182270.8 | T31: 1210874.2
B32: Licensing Revenue | F32: 3869 | G32: 6488 | H32: 7373 | I32: 9125 | J32: 12422 | K32: 15254.442 | L32: 18999.161 | M32: 24163.035 | N32: 29814.068 | O32: 34685.648 | P32: 38485.48 | Q32: 41798.154 | R32: 45013.397 | S32: 47644.05 | T32: 49787.545
C33: Royalty Rate | F33: 0.063099354 | G33: 0.061555977 | H33: 0.065808029 | I33: 0.063615005 | J33: 0.066875192 | K33: 0.065 | L33: 0.065 | M33: 0.065 | N33: 0.065 | O33: 0.065 | P33: 0.065 | Q33: 0.065 | R33: 0.065 | S33: 0.065 | T33: 0.065
B35: Avg Unit Volume (Reported)
C36: Domestic Company Operated | F36: 5017 | G36: 4611 | H36: 4976 | I36: 4981 | J36: 4598
C37: International Licensed | F37: 6077 | G37: 4588 | H37: 3413 | I37: 3334 | J37: 3176
B39: Avg Unit Volume (Implied)
C40: Domestic Company Operated | G40: 4309.3077 | H40: 4885.84 | I40: 4802.7778 | J40: 4498.5455 | K40: 4138.6618 | L40: 3931.7287 | M40: 3813.7769 | N40: 3813.7769 | O40: 3813.7769 | P40: 3813.7769 | Q40: 3813.7769 | R40: 3813.7769 | S40: 3813.7769 | T40: 3813.7769
C41: Licensed (total) | G41: 4133.3333 | H41: 3112.1667 | I41: 3187.5778 | J41: 3121.8319 | K41: 3028.177 | L41: 2997.8952 | M41: 2997.8952 | N41: 2997.8952 | O41: 2997.8952 | P41: 2997.8952 | Q41: 2997.8952 | R41: 2997.8952 | S41: 2997.8952 | T41: 2997.8952
C42: Systemwide | G42: 4222.1748 | H42: 4017.102 | I42: 4068.596 | J42: 3898.4396 | K42: 3670.9304 | L42: 3553.1476 | M42: 3482.617 | N42: 3472.245 | O42: 3464.2536 | P42: 3461.5657 | Q42: 3459.8707 | R42: 3457.1663 | S42: 3454.0238 | T42: 3449.9762
B44: Avg Unit Volume (% yoy)
C45: Domestic Company Operated | H45: 0.13378769 | I45: -0.017000602 | J45: -0.063345076 | K45: -0.08 | L45: -0.05 | M45: -0.03 | N45: 0 | O45: 0 | P45: 0 | Q45: 0 | R45: 0 | S45: 0 | T45: 0
C46: Licensed (total) | H46: -0.24705645 | I46: 0.024231064 | J46: -0.020625644 | K46: -0.03 | L46: -0.01 | M46: 0 | N46: 0 | O46: 0 | P46: 0 | Q46: 0 | R46: 0 | S46: 0 | T46: 0 | U46: << add f/x conversion
C47: Systemwide | H47: -0.0485704 | I47: 0.012818673 | J47: -0.041821897 | K47: -0.058359025 | L47: -0.032085288 | M47: -0.019850154 | N47: -0.0029782301 | O47: -0.0023015233 | P47: -0.00077589528 | Q47: -0.00048966049 | R47: -0.00078162648 | S47: -0.00090898793 | T47: -0.0011718466
B49: Same Shack Sales (% yoy) - Actual | G49: 0.041 | H49: 0.133 | I49: 0.042341 | J49: -0.01264
B51: Company Operated Stores Revenue
C52: Existing Shack Sales (Respt. Yr) | F52: 57900 | G52: 80887 | H52: 122142 | I52: 188419 | J52: 257050
C53: New Shack Contribution (Respt. Yr) | F53: 20687 | G53: 31155 | H53: 61077 | I53: 70931 | J53: 89338
...

Sheet Income Statement
B2: Shake Shack, Inc (SHAK)
B3: Income Statement
B4: (units in USD '000)
H7: Historical Year Ending December 31, | K7: Projected year Ending December 31,
F8: 2013 | G8: 2014 | H8: 2015 | I8: 2016 | J8: 2017 | K8: 2018 | L8: 2019 | M8: 2020 | N8: 2021 | O8: 2022 | P8: 2023 | Q8: 2024 | R8: 2025 | S8: 2026 | T8: 2027
A10: x | B10: Total Revenue | F10: 82456 | G10: 118530 | H10: 190592 | I10: 268475 | J10: 358810 | K10: 456021.93 | L10: 581236.37 | M10: 716363.54 | N10: 840241.65 | O10: 940457.65 | P10: 1030067.5 | Q10: 1109655.7 | R10: 1179612 | S10: 1229914.9 | T10: 1260661.7
C11: Domestic Company Operated | F11: 78587 | G11: 112042 | H11: 183219 | I11: 259350 | J11: 346388 | K11: 440767.48 | L11: 562237.21 | M11: 692200.5 | N11: 810427.58 | O11: 905772.01 | P11: 991581.99 | Q11: 1067857.5 | R11: 1134598.6 | S11: 1182270.8 | T11: 1210874.2
C12: Licensing | F12: 3869 | G12: 6488 | H12: 7373 | I12: 9125 | J12: 12422 | K12: 15254.442 | L12: 18999.161 | M12: 24163.035 | N12: 29814.068 | O12: 34685.648 | P12: 38485.48 | Q12: 41798.154 | R12: 45013.397 | S12: 47644.05 | T12: 49787.545
B14: Store Level Costs | F14: 58168 | G14: 85181 | H14: 130345 | I14: 186058 | J14: 254079 | K14: 335068.2 | L14: 436523.53 | M14: 544456.84 | N14: 633375.71 | O14: 707890.5 | P14: 774953.82 | Q14: 834565.65 | R14: 886726 | S14: 923983.4 | T14: 946337.83
A15: x | B15: Gross Profit | F15: 24288 | G15: 33349 | H15: 60247 | I15: 82417 | J15: 104731 | K15: 120953.73 | L15: 144712.84 | M15: 171906.7 | N15: 206865.94 | O15: 232567.15 | P15: 255113.65 | Q15: 275090.03 | R15: 292886.01 | S15: 305931.48 | T15: 314323.87
C16: Gross Profit Margin % | F16: 0.2945571 | G16: 0.28135493 | H16: 0.31610456 | I16: 0.30698203 | J16: 0.29188428 | K16: 0.26523665 | L16: 0.24897417 | M16: 0.23997131 | N16: 0.24619815 | O16: 0.24729146 | P16: 0.24766693 | Q16: 0.24790576 | R16: 0.24829012 | S16: 0.248742 | T16: 0.24933245
B18: SG&A | F18: 14787 | G18: 24292 | H18: 43255 | I18: 40076 | J18: 48606 | K18: 59022.987 | L18: 71857.257 | M18: 82436.781 | N18: 89939.593 | O18: 98416.055 | P18: 105578.2 | Q18: 112959.37 | R18: 118417.9 | S18: 122031.13 | T18: 123799.07
B19: Depreciation | F19: 3541 | G19: 5809 | H19: 10222 | I19: 14502 | J19: 21704 | K19: 29216.938 | L19: 36370.255 | M19: 42532.247 | N19: 45546.708 | O19: 46155.145 | P19: 45327.737 | Q19: 43214.486 | R19: 39965.392 | S19: 35444.61 | T19: 29952.141
B20: Other Operating Costs | F20: 25 | G20: 105 | H20: 17 | I20: 34 | J20: 608 | K20: 50 | L20: 50 | M20: 50 | N20: 50 | O20: 50 | P20: 50 | Q20: 50 | R20: 50 | S20: 50 | T20: 50
A21: x | B21: EBIT | F21: 5935 | G21: 3143 | H21: 6753 | I21: 27805 | J21: 33813 | K21: 32663.801 | L21: 36435.328 | M21: 46887.671 | N21: 71329.635 | O21: 87945.948 | P21: 104157.71 | Q21: 118866.17 | R21: 134452.72 | S21: 148405.74 | T21: 160522.66
C22: EBIT Margin % | H22: 0.035431708 | I22: 0.10356644 | J22: 0.094236504 | K22: 0.0716277 | L22: 0.062685906 | M22: 0.065452342 | N22: 0.084891811 | O22: 0.093513991 | P22: 0.10111736 | Q22: 0.10711987 | R22: 0.11398046 | S22: 0.12066343 | T22: 0.12733207
B24: Other Income | F24: 0 | G24: 0 | H24: 7 | I24: 1065 | J24: 128123 | K24: 0 | L24: 0 | M24: 0 | N24: 0 | O24: 0 | P24: 0 | Q24: 0 | R24: 0 | S24: 0 | T24: 0
B25: Interest Expense/(Income) | F25: 52 | G25: 363 | H25: 332 | I25: 374 | J25: 1643 | K25: 0 | L25: 0 | M25: 0 | N25: 0 | O25: 0 | P25: 0 | Q25: 0 | R25: 0 | S25: 0 | T25: 0
B26: Pre-tax Income | F26: 5883 | G26: 2780 | H26: 6428 | I26: 28496 | J26: 160293 | K26: 32663.801 | L26: 36435.328 | M26: 46887.671 | N26: 71329.635 | O26: 87945.948 | P26: 104157.71 | Q26: 118866.17 | R26: 134452.72 | S26: 148405.74 | T26: 160522.66
B28: Income Tax | F28: 460 | G28: 662 | H28: 3304 | I28: 6350 | J28: 151409 | K28: 6859.3983 | L28: 7651.4189 | M28: 9846.4109 | N28: 14979.223 | O28: 18468.649 | P28: 21873.119 | Q28: 24961.895 | R28: 28235.072 | S28: 31165.206 | T28: 33709.758
C29: Tax Rate % | F29: 0.078191399 | G29: 0.2381295 | H29: 0.51400124 | I29: 0.22283829 | J29: 0.94457649 | K29: 0.21 | L29: 0.21 | M29: 0.21 | N29: 0.21 | O29: 0.21 | P29: 0.21 | Q29: 0.21 | R29: 0.21 | S29: 0.21 | T29: 0.21
A30: x | B30: Net Income | F30: 5423 | G30: 2118 | H30: 3124 | I30: 22146 | J30: 8884 | K30: 25804.403 | L30: 28783.909 | M30: 37041.26 | N30: 56350.412 | O30: 69477.299 | P30: 82284.589 | Q30: 93904.273 | R30: 106217.65 | S30: 117240.54 | T30: 126812.9
C31: Net Income Margin % | F31: 0.06576841 | G31: 0.017868894 | H31: 0.016391034 | I31: 0.082488127 | J31: 0.024759622 | K31: 0.056585883 | L31: 0.049521865 | M31: 0.05170735 | N31: 0.06706453 | O31: 0.073876053 | P31: 0.079882718 | Q31: 0.084624695 | R31: 0.090044566 | S31: 0.095324107 | T31: 0.10059233
B33: Non-Controlling Interests | F33: 0 | G33: 0 | H33: 11900 | I33: 9700 | J33: 9204 | K33: 0 | L33: 0 | M33: 0 | N33: 0 | O33: 0 | P33: 0 | Q33: 0 | R33: 0 | S33: 0 | T33: 0
A34: x | B34: Net Income to Common | F34: 5423 | G34: 2118 | H34: -8776 | I34: 12446 | J34: -320 | K34: 25804.403 | L34: 28783.909 | M34: 37041.26 | N34: 56350.412 | O34: 69477.299 | P34: 82284.589 | Q34: 93904.273 | R34: 106217.65 | S34: 117240.54 | T34: 126812.9
B36: Diluted Shares Outstanding (in '000 shares) | H36: 20982.881 | I36: 25470.089 | J36: 27078.149 | K36: 37777.325 | L36: 37787.325 | M36: 37794.825 | N36: 37799.825 | O36: 37804.825 | P36: 37809.825 | Q36: 37814.825 | R36: 37819.825 | S36: 37824.825 | T36: 37829.825
B37: Diluted Earnings Per Shares (EPS) | H37: 0.14888327 | I37: 0.86949048 | J37: 0.32808742 | K37: 0.68306592 | L37: 0.76173451 | M37: 0.9800617 | N37: 1.4907585 | O37: 1.8377892 | P37: 2.1762753 | Q37: 2.4832661 | R37: 2.8085178 | S37: 3.0995659 | T37: 3.3521937
B39: S&P Capital IQ Consensus GAAP EPS | K39: 0.51 | L39: 0.82 | M39: 1.22 | N39: 1.57
B40: S&P Capital IQ Consensus Adjusted EPS | K40: 0.54 | L40: 0.76 | M40: 0.98 | N40: 1.57

Sheet Balance Sheet
B2: Shake Shack, Inc (SHAK)
B3: Balance Sheet
B4: (units in USD '000)
H7: Historical Year Ending December 31, | K7: Projected year Ending December 31,
F8: 2013 | G8: 2014 | H8: 2015 | I8: 2016 | J8: 2017 | K8: 2018 | L8: 2019 | M8: 2020 | N8: 2021 | O8: 2022 | P8: 2023 | Q8: 2024 | R8: 2025 | S8: 2026 | T8: 2027
A10: x | B10: Cash & Cash Equivalents | G10: 2677 | H10: 70849 | I10: 73647 | J10: 84543 | K10: 72286.23 | L10: 60968.991 | M10: 72839.582 | N10: 131453.65 | O10: 204306.49 | P10: 299271.17 | Q10: 397749.8 | R10: 512351.41 | S10: 639936.76 | T10: 778246.86
B11: Accounts Receivable | G11: 3278 | H11: 4217 | I11: 6006 | J11: 5641 | K11: 7496.2508 | L11: 9554.5704 | M11: 11775.839 | N11: 13812.192 | O11: 15459.578 | P11: 16932.616 | Q11: 18240.915 | R11: 19390.882 | S11: 20217.779 | T11: 20723.206
B12: Inventories | G12: 529 | H12: 543 | I12: 806 | J12: 1258 | K12: 1468.7921 | L12: 1913.5278 | M12: 2386.6601 | N12: 2776.4415 | O12: 3103.0817 | P12: 3397.0578 | Q12: 3658.37 | R12: 3887.0181 | S12: 4050.3382 | T12: 4148.3302
B13: Prepaid Expenses & Other | G13: 1441 | H13: 3325 | I13: 3485 | J13: 1757 | K13: 3648.1754 | L13: 4649.891 | M13: 5730.9083 | N13: 6721.9332 | O13: 7523.6612 | P13: 8240.5397 | Q13: 8877.2454 | R13: 9436.8961 | S13: 9839.319 | T13: 10085.294
C14: Total Current Assets | G14: 7925 | H14: 78934 | I14: 83944 | J14: 93199 | K14: 84899.448 | L14: 77086.98 | M14: 92732.989 | N14: 154764.22 | O14: 230392.81 | P14: 327841.39 | Q14: 428526.33 | R14: 545066.21 | S14: 674044.2 | T14: 813203.69
B16: PP&E | G16: 70124 | H16: 93041 | I16: 136264 | J16: 187095 | K16: 233778.06 | L16: 285407.81 | M16: 320575.56 | N16: 325028.85 | O16: 326373.71 | P16: 317045.97 | Q16: 309831.48 | R16: 296866.09 | S16: 279421.48 | T16: 258469.34
B17: Deferred Income Taxes | G17: 161 | H17: 201957 | I17: 313207 | J17: 185914 | K17: 185914 | L17: 185914 | M17: 185914 | N17: 185914 | O17: 185914 | P17: 185914 | Q17: 185914 | R17: 185914 | S17: 185914 | T17: 185914
B18: Goodwill | G18: 0 | H18: 0 | I18: 0 | J18: 0 | K18: 0 | L18: 0 | M18: 0 | N18: 0 | O18: 0 | P18: 0 | Q18: 0 | R18: 0 | S18: 0 | T18: 0
B19: Other Long-term Assets | G19: 4752 | H19: 5615 | I19: 4779 | J19: 4398 | K19: 3898 | L19: 3398 | M19: 2898 | N19: 2398 | O19: 1898 | P19: 1398 | Q19: 898 | R19: 398 | S19: -102 | T19: -602
A20: x | C20: Total Assets | G20: 82962 | H20: 379547 | I20: 538194 | J20: 470606 | K20: 508489.51 | L20: 551806.79 | M20: 602120.55 | N20: 668105.07 | O20: 744578.52 | P20: 832199.36 | Q20: 925169.81 | R20: 1028244.3 | S20: 1139277.7 | T20: 1256985
B22: Accounts Payable | G22: 6440 | H22: 6786 | I22: 6921 | J22: 8210 | K22: 10097.946 | L22: 13155.504 | M22: 16408.288 | N22: 19088.035 | O22: 21333.686 | P22: 23354.773 | Q22: 25151.293 | R22: 26723.249 | S22: 27846.075 | T22: 28519.77
B23: Accrued Expenses | G23: 5578 | H23: 6801 | I23: 8538 | J23: 11649 | K23: 15078.069 | L23: 19643.559 | M23: 24500.558 | N23: 28501.907 | O23: 31855.073 | P23: 34872.922 | Q23: 37555.454 | R23: 39902.67 | S23: 41579.253 | T23: 42585.202
B24: Accrued Wages & Related | G24: 2410 | H24: 5804 | I24: 6084 | J24: 6228 | K24: 8376.7049 | L24: 10913.088 | M24: 13611.421 | N24: 15834.393 | O24: 17697.263 | P24: 19373.845 | Q24: 20864.141 | R24: 22168.15 | S24: 23099.585 | T24: 23658.446
B25: Other Current Liabilities | G25: 1749 | H25: 4614 | I25: 10173 | J25: 7937 | K25: 11727.387 | L25: 15278.323 | M25: 19055.989 | N25: 22168.15 | O25: 24776.168 | P25: 27123.384 | Q25: 29209.798 | R25: 31035.41 | S25: 32339.419 | T25: 33121.824
C26: Total Current Liabilities | G26: 16177 | H26: 24005 | I26: 31716 | J26: 34024 | K26: 45280.106 | L26: 58990.474 | M26: 73576.256 | N26: 85592.485 | O26: 95662.189 | P26: 104724.92 | Q26: 112780.69 | R26: 119829.48 | S26: 124864.33 | T26: 127885.24
B28: Revolver | G28: 32000 | H28: 0 | I28: 0 | J28: 0 | K28: 0 | L28: 0 | M28: 0 | N28: 0 | O28: 0 | P28: 0 | Q28: 0 | R28: 0 | S28: 0 | T28: 0
B29: Capital Leases | G29: 313 | H29: 313 | I29: 2007 | J29: 14518 | K29: 13518 | L29: 12518 | M29: 11518 | N29: 10518 | O29: 9518 | P29: 8518 | Q29: 7518 | R29: 6518 | S29: 5518 | T29: 4518
B30: Long-term Debt | G30: 17853 | H30: 22927 | I30: 31107 | J30: 36596 | K30: 33596 | L30: 30596 | M30: 27596 | N30: 24596 | O30: 21596 | P30: 18596 | Q30: 15596 | R30: 12596 | S30: 9596 | T30: 6596
B31: Other Long-term Liabilities | G31: 4019 | H31: 175283 | I31: 272011 | J31: 160989 | K31: 159989 | L31: 158989 | M31: 157989 | N31: 156989 | O31: 155989 | P31: 154989 | Q31: 153989 | R31: 152989 | S31: 151989 | T31: 150989
A32: x | C32: Total Liabilites | G32: 70362 | H32: 222528 | I32: 336841 | J32: 246127 | K32: 252383.11 | L32: 261093.47 | M32: 270679.26 | N32: 277695.49 | O32: 282765.19 | P32: 286827.92 | Q32: 289883.69 | R32: 291932.48 | S32: 291967.33 | T32: 289988.24
B34: Common Equity | G34: 12600 | H34: 100615 | I34: 152188 | J34: 169492 | K34: 201119.4 | L34: 235726.31 | M34: 276454.29 | N34: 335422.59 | O34: 406826.33 | P34: 490384.43 | Q34: 580299.12 | R34: 681324.82 | S34: 792323.35 | T34: 912009.78
B35: Non-Controlling Interests | H35: 56404 | I35: 49165 | J35: 54987 | K35: 54987 | L35: 54987 | M35: 54987 | N35: 54987 | O35: 54987 | P35: 54987 | Q35: 54987 | R35: 54987 | S35: 54987 | T35: 54987
A36: x | C36: Total Equity | G36: 12600 | H36: 157019 | I36: 201353 | J36: 224479 | K36: 256106.4 | L36: 290713.31 | M36: 331441.29 | N36: 390409.59 | O36: 461813.33 | P36: 545371.43 | Q36: 635286.12 | R36: 736311.82 | S36: 847310.35 | T36: 966996.78
A38: x | C38: Total Liabilities & Equity | G38: 82962 | H38: 379547 | I38: 538194 | J38: 470606 | K38: 508489.51 | L38: 551806.79 | M38: 602120.55 | N38: 668105.07 | O38: 744578.52 | P38: 832199.36 | Q38: 925169.81 | R38: 1028244.3 | S38: 1139277.7 | T38: 1256985
C39: Check | G39: 0 | H39: 0 | I39: 0 | J39: 0 | K39: 0 | L39: 0 | M39: 0 | N39: 0 | O39: 0 | P39: 0 | Q39: 0 | R39: 0 | S39: 0 | T39: 0

Sheet Cash Flow
B2: Shake Shack, Inc (SHAK)
B3: Cash Flow Statement
B4: (units in USD '000)
H7: Historical Year Ending December 31, | K7: Projected year Ending December 31,
F8: 2013 | G8: 2014 | H8: 2015 | I8: 2016 | J8: 2017 | K8: 2018 | L8: 2019 | M8: 2020 | N8: 2021 | O8: 2022 | P8: 2023 | Q8: 2024 | R8: 2025 | S8: 2026 | T8: 2027
A10: x | B10: Operating
C11: Net Income | K11: 25804.403 | L11: 28783.909 | M11: 37041.26 | N11: 56350.412 | O11: 69477.299 | P11: 82284.589 | Q11: 93904.273 | R11: 106217.65 | S11: 117240.54 | T11: 126812.9
C12: Depreciation | K12: 29216.938 | L12: 36370.255 | M12: 42532.247 | N12: 45546.708 | O12: 46155.145 | P12: 45327.737 | Q12: 43214.486 | R12: 39965.392 | S12: 35444.61 | T12: 29952.141
C13: Amortization | K13: 0 | L13: 0 | M13: 0 | N13: 0 | O13: 0 | P13: 0 | Q13: 0 | R13: 0 | S13: 0 | T13: 0
C14: Stock-based Compensation Expense | K14: 5623 | L14: 5623 | M14: 5623 | N14: 5623 | O14: 5623 | P14: 5623 | Q14: 5623 | R14: 5623 | S14: 5623 | T14: 5623
C15: Change in Working Capital | K15: 7298.8881 | L15: 10205.597 | M15: 10810.364 | N15: 8599.0702 | O15: 7293.9496 | P15: 6578.8411 | Q15: 5849.4461 | R15: 5110.5269 | S15: 3642.2127 | T15: 2171.5174
C16: Change in Other LT Assets & Liabilities | K16: -500 | L16: -500 | M16: -500 | N16: -500 | O16: -500 | P16: -500 | Q16: -500 | R16: -500 | S16: -500 | T16: -500
D17: Cash Flow from Operations | K17: 67443.23 | L17: 80482.761 | M17: 95506.871 | N17: 115619.19 | O17: 128049.39 | P17: 139314.17 | Q17: 148091.21 | R17: 156416.57 | S17: 161450.36 | T17: 164059.56
A19: x | B19: Investing
C20: Capital Expenditures | K20: -75900 | L20: -88000 | M20: -77700 | N20: -50000 | O20: -47500 | P20: -36000 | Q20: -36000 | R20: -27000 | S20: -18000 | T20: -9000
C21: Asset Sales | K21: 0 | L21: 0 | M21: 0 | N21: 0 | O21: 0 | P21: 0 | Q21: 0 | R21: 0 | S21: 0 | T21: 0
C22: Additions to Intangibles | K22: 0 | L22: 0 | M22: 0 | N22: 0 | O22: 0 | P22: 0 | Q22: 0 | R22: 0 | S22: 0 | T22: 0
D23: Cash Flow from Investing | K23: -75900 | L23: -88000 | M23: -77700 | N23: -50000 | O23: -47500 | P23: -36000 | Q23: -36000 | R23: -27000 | S23: -18000 | T23: -9000
A25: x | B25: Cash Flow Available for Financing | K25: -8456.7702 | L25: -7517.2385 | M25: 17806.871 | N25: 65619.19 | O25: 80549.393 | P25: 103314.17 | Q25: 112091.21 | R25: 129416.57 | S25: 143450.36 | T25: 155059.56
A27: x | B27: Financing
C28: Issuance/(Repayment) of Revolver | K28: 0 | L28: 0 | M28: 0 | N28: 0 | O28: 0 | P28: 0 | Q28: 0 | R28: 0 | S28: 0 | T28: 0
C29: Increase in Capital Leases | K29: 1000 | L29: 1000 | M29: 1000 | N29: 1000 | O29: 1000 | P29: 1000 | Q29: 1000 | R29: 1000 | S29: 1000 | T29: 1000
C30: Repayment of Capital Leases | K30: -2000 | L30: -2000 | M30: -2000 | N30: -2000 | O30: -2000 | P30: -2000 | Q30: -2000 | R30: -2000 | S30: -2000 | T30: -2000
C31: Increase in Long-term Debt | K31: 3000 | L31: 3000 | M31: 3000 | N31: 3000 | O31: 3000 | P31: 3000 | Q31: 3000 | R31: 3000 | S31: 3000 | T31: 3000
C32: Repayment of Long-term Debt | K32: -6000 | L32: -6000 | M32: -6000 | N32: -6000 | O32: -6000 | P32: -6000 | Q32: -6000 | R32: -6000 | S32: -6000 | T32: -6000
C33: Repurchase of Equity | K33: 0 | L33: 0 | M33: -284.21789 | N33: -387.59722 | O33: -422.69152 | P33: -435.25507 | Q33: -422.15524 | R33: -393.1925 | S33: -340.95225 | T33: -268.1755
C34: Dividends Paid Out | K34: 0 | L34: 0 | M34: -1852.063 | N34: -2817.5206 | O34: -3473.865 | P34: -4114.2294 | Q34: -9390.4273 | R34: -10621.765 | S34: -11724.054 | T34: -12681.29
C35: Proceeds from Options | K35: 200 | L35: 200 | M35: 200 | N35: 200 | O35: 200 | P35: 200 | Q35: 200 | R35: 200 | S35: 200 | T35: 200
C36: Change in Non-Controlling Interest | K36: 0 | L36: 0 | M36: 0 | N36: 0 | O36: 0 | P36: 0 | Q36: 0 | R36: 0 | S36: 0 | T36: 0
D37: Cash Flow from Financing | K37: -3800 | L37: -3800 | M37: -5936.2809 | N37: -7005.1178 | O37: -7696.5565 | P37: -8349.4845 | Q37: -13612.583 | R37: -14814.958 | S37: -15865.006 | T37: -16749.466
B39: Net Change in Cash | K39: -12256.77 | L39: -11317.239 | M39: 11870.591 | N39: 58614.072 | O39: 72852.837 | P39: 94964.682 | Q39: 98478.623 | R39: 114601.61 | S39: 127585.35 | T39: 138310.09
C40: Beginning Cash Balance | K40: 84543 | L40: 72286.23 | M40: 60968.991 | N40: 72839.582 | O40: 131453.65 | P40: 204306.49 | Q40: 299271.17 | R40: 397749.8 | S40: 512351.41 | T40: 639936.76
C41: Ending Cash Balance | K41: 72286.23 | L41: 60968.991 | M41: 72839.582 | N41: 131453.65 | O41: 204306.49 | P41: 299271.17 | Q41: 397749.8 | R41: 512351.41 | S41: 639936.76 | T41: 778246.86
A42: x

Sheet Working Capital
B2: Shake Shack, Inc (SHAK)
B3: Working Capital
B4: (units in USD '000)
H7: Historical Year Ending December 31, | K7: Projected year Ending December 31,
F8: 2013 | G8: 2014 | H8: 2015 | I8: 2016 | J8: 2017 | K8: 2018 | L8: 2019 | M8: 2020 | N8: 2021 | O8: 2022 | P8: 2023 | Q8: 2024 | R8: 2025 | S8: 2026 | T8: 2027
A10: x | B10: Total Revenue | G10: 118530 | H10: 190592 | I10: 268475 | J10: 358810 | K10: 456021.93 | L10: 581236.37 | M10: 716363.54 | N10: 840241.65 | O10: 940457.65 | P10: 1030067.5 | Q10: 1109655.7 | R10: 1179612 | S10: 1229914.9 | T10: 1260661.7
B11: Cost of Goods Sold | G11: 85181 | H11: 130345 | I11: 186058 | J11: 254079 | K11: 335068.2 | L11: 436523.53 | M11: 544456.84 | N11: 633375.71 | O11: 707890.5 | P11: 774953.82 | Q11: 834565.65 | R11: 886726 | S11: 923983.4 | T11: 946337.83
A13: x | B13: Working Capital Balances
C14: Accounts Receivable | G14: 3278 | H14: 4217 | I14: 6006 | J14: 5641 | K14: 7496.2508 | L14: 9554.5704 | M14: 11775.839 | N14: 13812.192 | O14: 15459.578 | P14: 16932.616 | Q14: 18240.915 | R14: 19390.882 | S14: 20217.779 | T14: 20723.206
C15: Inventories | G15: 529 | H15: 543 | I15: 806 | J15: 1258 | K15: 1468.7921 | L15: 1913.5278 | M15: 2386.6601 | N15: 2776.4415 | O15: 3103.0817 | P15: 3397.0578 | Q15: 3658.37 | R15: 3887.0181 | S15: 4050.3382 | T15: 4148.3302
C16: Prepaid Expenses & Other | G16: 1441 | H16: 3325 | I16: 3485 | J16: 1757 | K16: 3648.1754 | L16: 4649.891 | M16: 5730.9083 | N16: 6721.9332 | O16: 7523.6612 | P16: 8240.5397 | Q16: 8877.2454 | R16: 9436.8961 | S16: 9839.319 | T16: 10085.294
D17: Total Non-cash Current Assets | G17: 5248 | H17: 8085 | I17: 10297 | J17: 8656 | K17: 12613.218 | L17: 16117.989 | M17: 19893.407 | N17: 23310.566 | O17: 26086.321 | P17: 28570.213 | Q17: 30776.531 | R17: 32714.797 | S17: 34107.436 | T17: 34956.83
C19: Accounts Payable | G19: 6440 | H19: 6786 | I19: 6921 | J19: 8210 | K19: 10097.946 | L19: 13155.504 | M19: 16408.288 | N19: 19088.035 | O19: 21333.686 | P19: 23354.773 | Q19: 25151.293 | R19: 26723.249 | S19: 27846.075 | T19: 28519.77
C20: Accrued Expenses | G20: 5578 | H20: 6801 | I20: 8538 | J20: 11649 | K20: 15078.069 | L20: 19643.559 | M20: 24500.558 | N20: 28501.907 | O20: 31855.073 | P20: 34872.922 | Q20: 37555.454 | R20: 39902.67 | S20: 41579.253 | T20: 42585.202
C21: Accrued Wages & Related | G21: 2410 | H21: 5804 | I21: 6084 | J21: 6228 | K21: 8376.7049 | L21: 10913.088 | M21: 13611.421 | N21: 15834.393 | O21: 17697.263 | P21: 19373.845 | Q21: 20864.141 | R21: 22168.15 | S21: 23099.585 | T21: 23658.446
C22: Other Current Liabilities | G22: 1749 | H22: 4614 | I22: 10173 | J22: 7937 | K22: 11727.387 | L22: 15278.323 | M22: 19055.989 | N22: 22168.15 | O22: 24776.168 | P22: 27123.384 | Q22: 29209.798 | R22: 31035.41 | S22: 32339.419 | T22: 33121.824
D23: Total Non-debt Current Liabilities | G23: 16177 | H23: 24005 | I23: 31716 | J23: 34024 | K23: 45280.106 | L23: 58990.474 | M23: 73576.256 | N23: 85592.485 | O23: 95662.189 | P23: 104724.92 | Q23: 112780.69 | R23: 119829.48 | S23: 124864.33 | T23: 127885.24
B25: Net Working Capital / (Deficit) | G25: -10929 | H25: -15920 | I25: -21419 | J25: -25368 | K25: -32666.888 | L25: -42872.485 | M25: -53682.849 | N25: -62281.919 | O25: -69575.869 | P25: -76154.71 | Q25: -82004.156 | R25: -87114.683 | S25: -90756.895 | T25: -92928.413
A27: x | B27: (Increase) / Decrease in Net Working Capital | H27: 4991 | I27: 5499 | J27: 3949 | K27: 7298.8881 | L27: 10205.597 | M27: 10810.364 | N27: 8599.0702 | O27: 7293.9496 | P27: 6578.8411 | Q27: 5849.4461 | R27: 5110.5269 | S27: 3642.2127 | T27: 2171.5174
B29: Ratios & Assumptions
C30: Numbers of days in a period | H30: 365
C32: Accounts Receivable (Collection Period in Days) | G32: 10.094238 | H32: 8.0759161 | I32: 8.1653413 | J32: 5.7383155 | K32: 6 | L32: 6 | M32: 6 | N32: 6 | O32: 6 | P32: 6 | Q32: 6 | R32: 6 | S32: 6 | T32: 6
C33: Inventories (Days Outstanding) | G33: 2.2667614 | H33: 1.5205416 | I33: 1.5811736 | J33: 1.8071938 | K33: 1.6 | L33: 1.6 | M33: 1.6 | N33: 1.6 | O33: 1.6 | P33: 1.6 | Q33: 1.6 | R33: 1.6 | S33: 1.6 | T33: 1.6
C34: Other Current Assets (% of Revenue) | G34: 0.01215726 | H34: 0.017445643 | I34: 0.012980724 | J34: 0.004896742 | K34: 0.008 | L34: 0.008 | M34: 0.008 | N34: 0.008 | O34: 0.008 | P34: 0.008 | Q34: 0.008 | R34: 0.008 | S34: 0.008 | T34: 0.008
C36: Accounts Payable (Days Outstanding) | G36: 27.595356 | H36: 19.00257 | I36: 13.577298 | J36: 11.794166 | K36: 11 | L36: 11 | M36: 11 | N36: 11 | O36: 11 | P36: 11 | Q36: 11 | R36: 11 | S36: 11 | T36: 11
C37: Accrued Expenses (% of COGS) | G37: 0.065484087 | H37: 0.052176915 | I37: 0.045888916 | J37: 0.045847945 | K37: 0.045 | L37: 0.045 | M37: 0.045 | N37: 0.045 | O37: 0.045 | P37: 0.045 | Q37: 0.045 | R37: 0.045 | S37: 0.045 | T37: 0.045
C38: Accrued Wages & Related (% of COGS) | G38: 0.028292694 | H38: 0.044527983 | I38: 0.032699481 | J38: 0.024512061 | K38: 0.025 | L38: 0.025 | M38: 0.025 | N38: 0.025 | O38: 0.025 | P38: 0.025 | Q38: 0.025 | R38: 0.025 | S38: 0.025 | T38: 0.025
C39: Other Current Liabilities (% of COGS) | G39: 0.020532748 | H39: 0.035398366 | I39: 0.054676499 | J39: 0.031238316 | K39: 0.035 | L39: 0.035 | M39: 0.035 | N39: 0.035 | O39: 0.035 | P39: 0.035 | Q39: 0.035 | R39: 0.035 | S39: 0.035 | T39: 0.035
A40: x

Sheet PP&E
B2: Shake Shack, Inc (SHAK)
B3: PP&E and Depreciation Schedule
B4: (units in USD '000)
H7: Historical Year Ending December 31, | K7: Projected year Ending December 31,
F8: 2013 | G8: 2014 | H8: 2015 | I8: 2016 | J8: 2017 | K8: 2018 | L8: 2019 | M8: 2020 | N8: 2021 | O8: 2022 | P8: 2023 | Q8: 2024 | R8: 2025 | S8: 2026 | T8: 2027
A10: x | B10: Total Revenue | F10: 82456 | G10: 118530 | H10: 190592 | I10: 268475 | J10: 358810 | K10: 456021.93 | L10: 581236.37 | M10: 716363.54 | N10: 840241.65 | O10: 940457.65 | P10: 1030067.5 | Q10: 1109655.7 | R10: 1179612 | S10: 1229914.9 | T10: 1260661.7
A12: x | B12: Capital Expenditure | F12: 16194 | G12: 28515 | H12: 32117 | I12: 54433 | J12: 61533 | K12: 75900 | L12: 88000 | M12: 77700 | N12: 50000 | O12: 47500 | P12: 36000 | Q12: 36000 | R12: 27000 | S12: 18000 | T12: 9000
C13: Capex as % of Revenue | F13: 0.19639565 | G13: 0.24057201 | H13: 0.16851179 | I13: 0.20274886 | J13: 0.17149188 | K13: 0.16643937 | L13: 0.1514014 | M13: 0.10846448 | N13: 0.059506691 | O13: 0.050507325 | P13: 0.034949167 | Q13: 0.032442496 | R13: 0.022888882 | S13: 0.014635159 | T13: 0.007139108
C15: New Store Openings (gross) | G15: 10 | H15: 13 | I15: 22 | J15: 27 | K15: 33 | L15: 40 | M15: 37 | N15: 25 | O15: 25 | P15: 20 | Q15: 20 | R15: 15 | S15: 10 | T15: 5 | U15: Step
C16: Capex / New Stores Opened | G16: 2851.5 | H16: 2470.5385 | I16: 2474.2273 | J16: 2279 | K16: 2300 | L16: 2200 | M16: 2100 | N16: 2000 | O16: 1900 | P16: 1800 | Q16: 1800 | R16: 1800 | S16: 1800 | T16: 1800 | U16: -100
A18: x | B18: Depreciation Expense | F18: 3541 | G18: 5809 | H18: 10222 | I18: 14502 | J18: 21704 | K18: 29216.938 | L18: 36370.255 | M18: 42532.247 | N18: 45546.708 | O18: 46155.145 | P18: 45327.737 | Q18: 43214.486 | R18: 39965.392 | S18: 35444.61 | T18: 29952.141
C19: Capex / Depreciation | F19: 4.5732844 | G19: 4.9087623 | H19: 3.1419487 | I19: 3.7534823 | J19: 2.8350995 | K19: 2.5978081 | L19: 2.4195596 | M19: 1.8268492 | N19: 1.0977742 | O19: 1.0291377 | P19: 0.79421569 | Q19: 0.83305399 | R19: 0.67558452 | S19: 0.50783462 | T19: 0.30047936 | U19: Step
C20: Depreciation / Existing Store | G20: 223.42308 | H20: 272.58667 | I20: 268.55556 | J20: 281.87013 | K20: 274.33745 | L20: 254.33745 | M20: 234.33745 | N20: 214.33745 | O20: 194.33745 | P20: 174.33745 | Q20: 154.33745 | R20: 134.33745 | S20: 114.33745 | T20: 94.337451 | U20: -20
C22: Depreciation as % of Net PP&E | G22: 0.082838971 | H22: 0.10986554 | I22: 0.10642576 | J22: 0.11600524 | K22: 0.12497725 | L22: 0.12743259 | M22: 0.13267464 | N22: 0.14013128 | O22: 0.14141809 | P22: 0.14296898 | Q22: 0.13947739 | R22: 0.13462431 | S22: 0.12684998 | T22: 0.11588276
C23: Implied Useful Life (Years) | G23: 12.071613 | H23: 9.1020348 | I23: 9.3962212 | J23: 8.6203004 | K23: 8.0014565 | L23: 7.8472863 | M23: 7.5372354 | N23: 7.1361655 | O23: 7.0712314 | P23: 6.9945245 | Q23: 7.1696209 | R23: 7.4280791 | S23: 7.8833279 | T23: 8.6294113
A25: x | B25: PP&E BASE Table
C26: Beginning Net PP&E | K26: 187095 | L26: 233778.06 | M26: 285407.81 | N26: 320575.56 | O26: 325028.85 | P26: 326373.71 | Q26: 317045.97 | R26: 309831.48 | S26: 296866.09 | T26: 279421.48
D27: Capital Expenditure | K27: 75900 | L27: 88000 | M27: 77700 | N27: 50000 | O27: 47500 | P27: 36000 | Q27: 36000 | R27: 27000 | S27: 18000 | T27: 9000
D28: (Depreciation Expense) | K28: -29216.938 | L28: -36370.255 | M28: -42532.247 | N28: -45546.708 | O28: -46155.145 | P28: -45327.737 | Q28: -43214.486 | R28: -39965.392 | S28: -35444.61 | T28: -29952.141
D29: (Asset Sales) | K29: 0 | L29: 0 | M29: 0 | N29: 0 | O29: 0 | P29: 0 | Q29: 0 | R29: 0 | S29: 0 | T29: 0
A30: x | C30: Ending Net PP&E | G30: 70124 | H30: 93041 | I30: 136264 | J30: 187095 | K30: 233778.06 | L30: 285407.81 | M30: 320575.56 | N30: 325028.85 | O30: 326373.71 | P30: 317045.97 | Q30: 309831.48 | R30: 296866.09 | S30: 279421.48 | T30: 258469.34

Sheet Other LT Items
B2: Shake Shack, Inc (SHAK)
B3: Other Long-term Items
B4: (units in USD '000)
H7: Historical Year Ending December 31, | K7: Projected year Ending December 31,
F8: 2013 | G8: 2014 | H8: 2015 | I8: 2016 | J8: 2017 | K8: 2018 | L8: 2019 | M8: 2020 | N8: 2021 | O8: 2022 | P8: 2023 | Q8: 2024 | R8: 2025 | S8: 2026 | T8: 2027
B10: Assets
C11: Deferred Income Taxes | G11: 161 | H11: 201957 | I11: 313207 | J11: 185914 | K11: 185914 | L11: 185914 | M11: 185914 | N11: 185914 | O11: 185914 | P11: 185914 | Q11: 185914 | R11: 185914 | S11: 185914 | T11: 185914
C12: Goodwill | G12: 0 | H12: 0 | I12: 0 | J12: 0 | K12: 0 | L12: 0 | M12: 0 | N12: 0 | O12: 0 | P12: 0 | Q12: 0 | R12: 0 | S12: 0 | T12: 0 | U12: Step
C13: Other Long-term Assets | G13: 4752 | H13: 5615 | I13: 4779 | J13: 4398 | K13: 3898 | L13: 3398 | M13: 2898 | N13: 2398 | O13: 1898 | P13: 1398 | Q13: 898 | R13: 398 | S13: -102 | T13: -602 | U13: -500
D14: Total Other Long-term Assets | G14: 4913 | H14: 207572 | I14: 317986 | J14: 190312 | K14: 189812 | L14: 189312 | M14: 188812 | N14: 188312 | O14: 187812 | P14: 187312 | Q14: 186812 | R14: 186312 | S14: 185812 | T14: 185312
D16: (Increase)/Decrease in Other LT Assets | H16: -202659 | I16: -110414 | J16: 127674 | K16: 500 | L16: 500 | M16: 500 | N16: 500 | O16: 500 | P16: 500 | Q16: 500 | R16: 500 | S16: 500 | T16: 500
B18: Liabilities | U18: Step
C19: Other Long-term Liabilities | G19: 4019 | H19: 175283 | I19: 272011 | J19: 160989 | K19: 159989 | L19: 158989 | M19: 157989 | N19: 156989 | O19: 155989 | P19: 154989 | Q19: 153989 | R19: 152989 | S19: 151989 | T19: 150989 | U19: -1000
D21: Increase/(Decrease) in Other LT Liabilities | H21: 171264 | I21: 96728 | J21: -111022 | K21: -1000 | L21: -1000 | M21: -1000 | N21: -1000 | O21: -1000 | P21: -1000 | Q21: -1000 | R21: -1000 | S21: -1000 | T21: -1000
A23: x | B23: Change in Other Long-term Assets and Liabilities | H23: -31395 | I23: -13686 | J23: 16652 | K23: -500 | L23: -500 | M23: -500 | N23: -500 | O23: -500 | P23: -500 | Q23: -500 | R23: -500 | S23: -500 | T23: -500

Sheet Equity
B2: Shake Shack, Inc (SHAK)
B3: Equity
B4: (units in USD '000)
H7: Historical Year Ending December 31, | K7: Projected year Ending December 31,
F8: 2013 | G8: 2014 | H8: 2015 | I8: 2016 | J8: 2017 | K8: 2018 | L8: 2019 | M8: 2020 | N8: 2021 | O8: 2022 | P8: 2023 | Q8: 2024 | R8: 2025 | S8: 2026 | T8: 2027
A10: x | B10: Beginning equity balance | K10: 224479 | L10: 256106.4 | M10: 290713.31 | N10: 331441.29 | O10: 390409.59 | P10: 461813.33 | Q10: 545371.43 | R10: 635286.12 | S10: 736311.82 | T10: 847310.35
C11: Net income | K11: 25804.403 | L11: 28783.909 | M11: 37041.26 | N11: 56350.412 | O11: 69477.299 | P11: 82284.589 | Q11: 93904.273 | R11: 106217.65 | S11: 117240.54 | T11: 126812.9
C12: Stock-based compensation expense | G12: 165 | H12: 16681 | I12: 5354 | J12: 5623 | K12: 5623 | L12: 5623 | M12: 5623 | N12: 5623 | O12: 5623 | P12: 5623 | Q12: 5623 | R12: 5623 | S12: 5623 | T12: 5623
C13: Repurchase of equity | K13: 0 | L13: 0 | M13: -284.21789 | N13: -387.59722 | O13: -422.69152 | P13: -435.25507 | Q13: -422.15524 | R13: -393.1925 | S13: -340.95225 | T13: -268.1755
C14: Dividends paid | K14: 0 | L14: 0 | M14: -1852.063 | N14: -2817.5206 | O14: -3473.865 | P14: -4114.2294 | Q14: -9390.4273 | R14: -10621.765 | S14: -11724.054 | T14: -12681.29
C15: Option proceeds | K15: 200 | L15: 200 | M15: 200 | N15: 200 | O15: 200 | P15: 200 | Q15: 200 | R15: 200 | S15: 200 | T15: 200
C16: Inc/(Dec) in Non-Controlling Interest | K16: 0 | L16: 0 | M16: 0 | N16: 0 | O16: 0 | P16: 0 | Q16: 0 | R16: 0 | S16: 0 | T16: 0
A17: x | B17: Ending equity balance | G17: 12600 | H17: 157019 | I17: 201353 | J17: 224479 | K17: 256106.4 | L17: 290713.31 | M17: 331441.29 | N17: 390409.59 | O17: 461813.33 | P17: 545371.43 | Q17: 635286.12 | R17: 736311.82 | S17: 847310.35 | T17: 966996.78
A19: x | B19: Share repurchase
C20: Projected EPS | H20: 0.14888327 | I20: 0.86949048 | J20: 0.32808742 | K20: 0.68306592 | L20: 0.76173451 | M20: 0.9800617 | N20: 1.4907585 | O20: 1.8377892 | P20: 2.1762753 | Q20: 2.4832661 | R20: 2.8085178 | S20: 3.0995659 | T20: 3.3521937 | U20: Step
C21: Assumed P/E Multiple | H21: 240.25533 | I21: 35.825579 | J21: 118.87076 | K21: 70 | L21: 64 | M21: 58 | N21: 52 | O21: 46 | P21: 40 | Q21: 34 | R21: 28 | S21: 22 | T21: 16 | U21: -6
