Workbook
Name Com_Data_sum_035900: '요약 재무제표'!$B$2

Sheet Estimate ▶
A3: 클래시스(214150.KQ)_PER
A5: Estimate Sheets >>>
C7: Chungang-Univ. Financial Institute
C8: R.F.S .
C9: Valuation Model
C19: RFS 정식 회원 외 본 가치평가 모델의 무단 사용 및 수정을 금하며, 본 양식의 원 저작권은 중앙대학교 R.F.S. 학회에 있음을 밝힙니다.
C20: 원 제작자: 28기 김 건 (zzkan103@gmail.com)
C21: 1st Version: 2021.03.02

Sheet Valuation
A1: 클래시스(214150.KQ)
A2: Assumption Sheet
A3: (units in Millions KRW )
B6: 클래시스 PER Valuation | H6: 일자 | I6: 선행 PER
B7: 12M Fwd 당기순이익 | D7: =SUM('비용 추정'!O54:R54) -> 147350.08 | E7: (백만원) | F7: (A) | H7: 43800 | I7: 24.2295
C8: Target P/E | D8: =AVERAGE(I10:I11)*1.5 -> 34.625025 | E8: (배) | F8: (B) | H8: 44166 | I8: 20.1253
B9: 적정 기업가치 | D9: =D8*D7/100 -> 51020.004 | E9: (억원) | F9: (C) = (A)*(B) | H9: 44531 | I9: 22.1561
B10: 발행 주식 수 | D10: 65505 | E10: (천 주) | F10: (D) | H10: 44896 | I10: 17.8089
B11: 적정주가 | D11: =(D9*100000000)/(D10*1000) -> 77887.19 | E11: 원 | F11: (E) = (C)/(D) | H11: 45261 | I11: 28.3578
B12: Target Price | D12: 77900 | E12: 원 | F12: 목표주가 | H12: 45627 | I12: 24.9142
B13: Current Price | D13: 58000 | E13: 원 | F13: 25.04.01 기준 | H13: 45992 | I13: 26.0792
B14: Upside | D14: =(D12/D13-1)*100 -> 34.310345 | E14: %

Sheet Expected IS
A1: 클래시스(214150.KQ)
A2: Assumption Sheet
A3: (units in Millions KRW )
B5: 단위: 백만원 | C5: 1Q22 | D5: 2Q22 | E5: 3Q22 | F5: 4Q22 | G5: 1Q23 | H5: 2Q23 | I5: 3Q23 | J5: 4Q23 | K5: 1Q24 | L5: 2Q24 | M5: 3Q24 | N5: 4Q24 | O5: 1Q25E | P5: 2Q25E | Q5: 3Q25E | R5: 4Q25E | S5: 2023 | T5: 2024 | U5: 2025
B6: 매출액 | C6: ='비용 추정'!C6 -> 35382 | D6: ='비용 추정'!D6 -> 32686 | E6: ='비용 추정'!E6 -> 33268 | F6: ='비용 추정'!F6 -> 40467 | G6: ='비용 추정'!G6 -> 38974 | H6: ='비용 추정'!H6 -> 45897 | I6: ='비용 추정'!I6 -> 48243 | J6: ='비용 추정'!J6 -> 47008 | ... N6: ='비용 추정'!N6 -> 74403 | O6: ='매출액 추정'!O6 -> 80584.532 | P6: ='매출액 추정'!P6 -> 82456.052 | Q6: ='매출액 추정'!Q6 -> 91470.968 | R6: ='매출액 추정'!R6 -> 100949.82 | T6: =SUM(K6:N6) -> 242939 | U6: =SUM(O6:R6) -> 355461.37
B7: 매출원가 | C7: ='비용 추정'!C7 -> 8800 | D7: ='비용 추정'!D7 -> 8277 | E7: ='비용 추정'!E7 -> 7317 | F7: ='비용 추정'!F7 -> 9241 | G7: ='비용 추정'!G7 -> 8764 | H7: ='비용 추정'!H7 -> 9577 | I7: ='비용 추정'!I7 -> 11234 | J7: ='비용 추정'!J7 -> 10099 | ... R7: ='비용 추정'!R7 -> 19180.466 | T7: =SUM(K7:N7) -> 51812 | U7: =SUM(O7:R7) -> 73322.96
B8: (%) | C8: 0.24872106 | D8: 0.25324318 | E8: 0.21994108 | F8: 0.22835891 | G8: 0.22486786 | H8: 0.20865833 | I8: 0.23284832 | J8: 0.21484948 | K8: 0.20200877 | L8: 0.19114418 | M8: 0.21567307 | N8: 0.23645234 | O8: =O7/O6 -> 0.22484164 | P8: =P7/P6 -> 0.21322776 | Q8: =Q7/Q6 -> 0.20161388 | R8: =R7/R6 -> 0.19 | T8: =SUM(K8:N8) -> 0.84527836 | U8: =SUM(O8:R8) -> 0.82968328
B9: 매출총이익 | C9: =C6-C7 -> 26582 | D9: =D6-D7 -> 24409 | E9: =E6-E7 -> 25951 | F9: =F6-F7 -> 31226 | G9: =G6-G7 -> 30210 | H9: =H6-H7 -> 36320 | I9: =I6-I7 -> 37009 | J9: =J6-J7 -> 36909 | ... R9: =R6-R7 -> 81769.356 | T9: =SUM(K9:N9) -> 191127 | U9: =SUM(O9:R9) -> 282138.41
B10: GPM(%) | C10: 0.75127894 | D10: 0.74675682 | E10: 0.78005892 | F10: 0.77164109 | G10: 0.77513214 | H10: 0.79134167 | I10: 0.76715168 | J10: 0.78515052 | K10: 0.79799123 | L10: 0.80885582 | M10: 0.78432693 | N10: 0.76354766 | O10: =O9/O6 -> 0.77515836 | P10: =P9/P6 -> 0.78677224 | Q10: =Q9/Q6 -> 0.79838612 | R10: =R9/R6 -> 0.81 | T10: =SUM(K10:N10) -> 3.1547216 | U10: =SUM(O10:R10) -> 3.1703167
B11: 판매비와 관리비 | C11: ='비용 추정'!C11 -> 9876.724 | D11: ='비용 추정'!D11 -> 9144.9522 | E11: ='비용 추정'!E11 -> 8471.9286 | F11: ='비용 추정'!F11 -> 11797.212 | G11: ='비용 추정'!G11 -> 10318.628 | H11: ='비용 추정'!H11 -> 13174.374 | I11: ='비용 추정'!I11 -> 12348.212 | J11: ='비용 추정'!J11 -> 14985.469 | ... R11: ='비용 추정'!R11 -> 27636.256 | T11: =SUM(K11:N11) -> 68671.739 | U11: =SUM(O11:R11) -> 97266.365
B12: (%) | C12: 0.27913287 | D12: 0.27976992 | E12: 0.25462907 | F12: 0.29152149 | G12: 0.26476625 | H12: 0.28702776 | I12: 0.25593832 | J12: 0.31879587 | K12: 0.27181961 | L12: 0.27793194 | M12: 0.29703437 | N12: 0.28228993 | O12: =O11/O6 -> 0.27399257 | P12: =P11/P6 -> 0.27386846 | Q12: =Q11/Q6 -> 0.27296567 | R12: =R11/R6 -> 0.2737623 | T12: =SUM(K12:N12) -> 1.1290758 | U12: =SUM(O12:R12) -> 1.094589
B13: 영업이익 | C13: ='비용 추정'!C44 -> 16705.276 | D13: ='비용 추정'!D44 -> 15264.048 | E13: ='비용 추정'!E44 -> 17479.071 | F13: ='비용 추정'!F44 -> 19428.788 | G13: ='비용 추정'!G44 -> 19891.372 | H13: ='비용 추정'!H44 -> 23145.626 | I13: ='비용 추정'!I44 -> 24660.788 | J13: ='비용 추정'!J44 -> 21923.531 | ... N13: ='비용 추정'!N44 -> 35806.308 | O13: =O9-O11 -> 40386.211 | P13: =P9-P11 -> 42292.021 | Q13: =Q9-Q11 -> 48060.717 | R13: =R9-R11 -> 54133.1 | T13: =SUM(K13:N13) -> 122455.26 | U13: =SUM(O13:R13) -> 184872.05
B14: OPM(%) | C14: 0.47214607 | D14: 0.4669869 | E14: 0.52542984 | F14: 0.4801196 | G14: 0.51036588 | H14: 0.50431391 | I14: 0.51121336 | J14: 0.46635464 | K14: 0.52617162 | L14: 0.53092389 | M14: 0.48729256 | N14: 0.48125773 | O14: =O13/O6 -> 0.50116579 | P14: =P13/P6 -> 0.51290378 | Q14: =Q13/Q6 -> 0.52542045 | R14: =R13/R6 -> 0.5362377 | T14: =SUM(K14:N14) -> 2.0256458 | U14: =SUM(O14:R14) -> 2.0757277
B15: 지분법손익 | C15: 0 | D15: 0 | E15: 0 | F15: 0 | G15: 0 | H15: 0 | I15: 0 | J15: 0 | K15: 0 | L15: 267 | M15: -822.65555 | N15: -511 | O15: ='비용 추정'!O46 -> -511 | P15: ='비용 추정'!P46 -> -511 | Q15: ='비용 추정'!Q46 -> -511 | R15: ='비용 추정'!R46 -> -511 | T15: =SUM(K15:N15) -> -1066.6555 | U15: =SUM(O15:R15) -> -2044
B16: 금융수익 | C16: 704 | D16: 2974 | E16: 5432 | F16: -6526 | G16: 4394 | H16: 2027 | I16: 4088 | J16: -1850 | K16: 6480 | L16: 4854 | M16: -3060 | N16: 15933 | O16: ='비용 추정'!O47 -> 2419 | P16: ='비용 추정'!P47 -> 2419 | Q16: ='비용 추정'!Q47 -> 2419 | R16: ='비용 추정'!R47 -> 2419 | T16: =SUM(K16:N16) -> 24207 | U16: =SUM(O16:R16) -> 9676
B17: 금융비용 | C17: -792 | D17: -731 | E17: -770 | F17: -2380 | G17: -1145 | H17: -489 | I17: -564 | J17: -1395 | K17: -556 | L17: -536 | M17: -2674.6856 | N17: -144 | O17: {='비용 추정'!O48:R48} -> -937.9607 | P17: -937.9607 | Q17: -937.9607 | R17: -937.9607 | T17: =SUM(K17:N17) -> -3910.6856 | U17: =SUM(O17:R17) -> -3751.8428
B18: 기타수익 | C18: 2 | D18: 27 | E18: 5 | F18: 30338 | G18: 1 | H18: 15 | I18: 15 | J18: 17.429602 | K18: 0.4 | L18: 10 | M18: 1.375159 | N18: 17.402788 | O18: ='비용 추정'!O49 -> 0 | P18: ='비용 추정'!P49 -> 0 | Q18: ='비용 추정'!Q49 -> 0 | R18: ='비용 추정'!R49 -> 0 | T18: =SUM(K18:N18) -> 29.177947 | U18: =SUM(O18:R18) -> 0
B19: 기타비용 | C19: -0.002 | D19: -0.2 | E19: -0.06 | F19: -400 | G19: -11 | H19: -51 | I19: -434 | J19: -398 | K19: -346 | L19: -1241 | M19: -2.069708 | N19: -12190 | O19: ='비용 추정'!O50 -> 0 | P19: ='비용 추정'!P50 -> 0 | Q19: ='비용 추정'!Q50 -> 0 | R19: ='비용 추정'!R50 -> 0 | T19: =SUM(K19:N19) -> -13779.07 | U19: =SUM(O19:R19) -> 0
B20: 법인세차감전순이익 | C20: =C13+SUM(C16:C19) -> 16619.274 | D20: =D13+SUM(D16:D19) -> 17533.848 | E20: =E13+SUM(E16:E19) -> 22146.011 | F20: =F13+SUM(F16:F19) -> 40460.788 | G20: =G13+SUM(G16:G19) -> 23130.372 | H20: =H13+SUM(H16:H19) -> 24647.626 | I20: =I13+SUM(I16:I19) -> 27765.788 | J20: =J13+SUM(J16:J19) -> 18297.961 | K20: =K13+SUM(K16:K19) -> 32056.101 | L20: =L13+SUM(L15:L19) -> 34573.482 | M20: =M13+SUM(M15:M19) -> 22393.734 | N20: =N13+SUM(N15:N19) -> 38911.711 | O20: ='비용 추정'!O51 -> 41356.752 | P20: ='비용 추정'!P51 -> 43262.573 | Q20: ='비용 추정'!Q51 -> 49031.281 | R20: ='비용 추정'!R51 -> 55103.676 | T20: =SUM(K20:N20) -> 127935.03 | U20: =SUM(O20:R20) -> 188754.28
B21: 법인세비용 | C21: -3802 | D21: -3725 | E21: -3430 | F21: -10424 | G21: -4355 | H21: -6089 | I21: -6575 | J21: -2597 | K21: -6002.4 | L21: -7961 | M21: -5908.5838 | N21: -10514.903 | O21: ='비용 추정'!O52 -> -9027.2983 | P21: ='비용 추정'!P52 -> -9405.4734 | Q21: ='비용 추정'!Q52 -> -10679.875 | R21: ='비용 추정'!R52 -> -12291.551 | T21: =SUM(K21:N21) -> -30386.887 | U21: =SUM(O21:R21) -> -41404.197
B22: 당기순이익 | C22: 12816.998 | D22: 13807.8 | E22: 18716.94 | F22: 30037 | G22: 18775 | H22: 18560 | I22: 21194 | J22: 15698.43 | K22: 26084 | L22: 26580 | M22: 16485.381 | N22: 28398 | O22: ='비용 추정'!O54 -> 32329.453 | P22: ='비용 추정'!P54 -> 33857.1 | Q22: ='비용 추정'!Q54 -> 38351.407 | R22: ='비용 추정'!R54 -> 42812.125 | T22: =SUM(K22:N22) -> 97547.381 | U22: =SUM(O22:R22) -> 147350.08
B23: (%) | C23: 0.36225652 | D23: 0.42246359 | E23: 0.56261092 | F23: 0.74225912 | G23: 0.48173141 | H23: 0.40437492 | I23: 0.4392903 | J23: 0.33397361 | K23: 0.51775541 | L23: 0.45249485 | M23: 0.27746626 | N23: 0.38167303 | O23: =O22/O6 -> 0.40118683 | P23: =P22/P6 -> 0.41060782 | Q23: =Q22/Q6 -> 0.41927409 | R23: =R22/R6 -> 0.42409312 | T23: =SUM(K23:N23) -> 1.6293896 | U23: =SUM(O23:R23) -> 1.6551619
B24: 감가상각비 | C24: 946 | D24: 974 | E24: 1003 | F24: 976 | G24: 984.205 | H24: 1033 | I24: 1103 | J24: 1158 | K24: 1159.778 | L24: 1176.567 | M24: 1204 | N24: 3664 | T24: =SUM(K24:N24) -> 7204.345 | U24: =SUM(O24:R24) -> 0
B25: EBITDA | C25: 17651 | D25: 16237 | E25: 18483 | F25: 20405 | G25: 20875.205 | H25: 24180 | I25: 25767 | J25: 23079 | K25: 27667.778 | L25: 32363.567 | M25: 30156 | N25: 39471.5 | T25: =SUM(K25:N25) -> 129658.84 | U25: =SUM(O25:R25) -> 0
B26: (%) | C26: 0.49888358 | D26: 0.49678742 | E26: 0.55557893 | F26: 0.50423802 | G26: 0.53561875 | H26: 0.52682034 | I26: 0.53407536 | J26: 0.49099032 | K26: 0.54919268 | L26: 0.55095363 | M26: 0.50755714 | N26: 0.53050239 | T26: =SUM(K26:N26) -> 2.1382058 | U26: =SUM(O26:R26) -> 0

Sheet 매출액 추정
A1: 클래시스(214150.KQ)
A2: Assumption Sheet
A3: (units in Millions KRW )
B5: (단위: 백만 원) | C5: 1Q22 | D5: 2Q22 | E5: 3Q22 | F5: 4Q22 | G5: 1Q23 | H5: 2Q23 | I5: 3Q23 | J5: 4Q23 | K5: 1Q24 | L5: 2Q24 | M5: 3Q24 | N5: 4Q24 | O5: 1Q25E | P5: 2Q25E | Q5: 3Q25E | R5: 4Q25E | S5: 1Q26E | T5: 2Q26E | U5: 3Q26E | V5: 4Q26E | W5: 2024 | X5: 2025E | Y5: 2026E
B6: 전체 매출액 | C6: =SUM(C8,C18,C20) -> 35382 | D6: =SUM(D8,D18,D20) -> 32686 | E6: =SUM(E8,E18,E20) -> 33268 | F6: =SUM(F8,F18,F20) -> 40467 | G6: =SUM(G8,G18,G20) -> 38974 | H6: =SUM(H8,H18,H20) -> 45897 | I6: =SUM(I8,I18,I20) -> 48243 | J6: =SUM(J8,J18,J20) -> 47008 | ... M6: =SUM(M8,M18,M20) -> 59414 | N6: =SUM(N8,N18,N20,N16) -> 74403 | O6: =SUM(O8,O18,O20,O16) -> 80584.532 | P6: =SUM(P8,P18,P20,P16) -> 82456.052 | Q6: =SUM(Q8,Q18,Q20,Q16) -> 91470.968 | R6: =SUM(R8,R18,R20,R16) -> 100949.82 | S6: =SUM(S8,S18,S20,S16) -> 107625.71 | T6: =SUM(T8,T18,T20,T16) -> 116479.59 | U6: =SUM(U8,U18,U20,U16) -> 124912.66 | V6: =SUM(V8,V18,V20,V16) -> 131740.97 | W6: =SUM(W8,W16,W18,W20) -> 242939 | X6: =SUM(X8,X18,X20,X16) -> 355461.37 | Y6: =SUM(Y8,Y18,Y20,Y16) -> 480758.93
B7: YoY% | G7: =G6/C6-1 -> 0.10152055 | H7: =H6/D6-1 -> 0.40417916 | I7: =I6/E6-1 -> 0.45013226 | J7: =J6/F6-1 -> 0.16163788 | K7: =K6/G6-1 -> 0.29186124 | L7: =L6/H6-1 -> 0.28054121 | M7: =M6/I6-1 -> 0.23155691 | N7: =N6/J6-1 -> 0.58277314 | ... V7: =V6/R6-1 -> 0.30501441 | X7: =X6/W6-1 -> 0.46317131 | Y7: =Y6/X6-1 -> 0.35249275
B8: 의료기기 | C8: =SUM(C10,C12,C14) -> 34293 | D8: =SUM(D10,D12,D14) -> 31395 | E8: =SUM(E10,E12,E14) -> 32305 | F8: =SUM(F10,F12,F14) -> 39694 | G8: =SUM(G10,G12,G14) -> 38207 | H8: =SUM(H10,H12,H14) -> 45263 | I8: =SUM(I10,I12,I14) -> 47201 | J8: =SUM(J10,J12,J14) -> 45445 | ... V8: =SUM(V10,V12,V14) -> 106584.25 | W8: =SUM(K8:N8) -> 225735 | X8: =SUM(X10,X12,X14) -> 286160.9 | Y8: =SUM(Y10,Y12,Y14) -> 385796.95
B9: % of sales | C9: =C8/C6 -> 0.96922164 | D9: =D8/D6 -> 0.96050297 | E9: =E8/E6 -> 0.97105326 | F9: =F8/F6 -> 0.98089802 | G9: =G8/G6 -> 0.98032021 | H9: =H8/H6 -> 0.98618646 | I9: =I8/I6 -> 0.97840101 | J9: =J8/J6 -> 0.96675034 | ... Y9: =Y8/Y6 -> 0.80247484
B10: 클래시스 | C10: =8752+11789 -> 20541 | D10: =18116+19559-C10 -> 17134 | E10: =29609+23586-D10-C10 -> 15520 | F10: =44284+29903-SUM(C10:E10) -> 20992 | G10: =12460+5893 -> 18353 | H10: =28766+11544-G10 -> 21957 | I10: =46546+19586-G10-H10 -> 25822 | J10: =63157+26822-SUM(G10:I10) -> 23847 | K10: =14261+6537 -> 20798 | L10: =37562+13130-K10 -> 29894 | M10: =62935+19296-K10-L10 -> 31539 | N10: =84686+26302-SUM(K10:M10) -> 28757 | O10: =의료기기!O6 -> 32402.688 | P10: =의료기기!P6 -> 35838.045 | Q10: =의료기기!Q6 -> 38404.647 | R10: =의료기기!R6 -> 42455.888 | S10: =의료기기!S6 -> 45291.604 | T10: =의료기기!T6 -> 48588.353 | U10: =의료기기!U6 -> 52429.855 | V10: =의료기기!V6 -> 55663.928 | W10: =SUM(K10:N10) -> 110988 | X10: =SUM(O10:R10) -> 149101.27 | Y10: =SUM(S10:V10) -> 201973.74
B11: % of sales | C11: =C10/C6 -> 0.58054943 | D11: =D10/D6 -> 0.52419996 | E11: =E10/E6 -> 0.46651437 | F11: =F10/F6 -> 0.51874367 | G11: =G10/G6 -> 0.47090368 | H11: =H10/H6 -> 0.47839728 | I11: =I10/I6 -> 0.53524864 | J11: =J10/J6 -> 0.50729663 | ... Y11: =Y10/Y6 -> 0.42011438
B12: 클루덤 | C12: =1864+130 -> 1994 | D12: =3991+308-C12 -> 2305 | E12: =5376+446-C12-D12 -> 1523 | F12: =7397+519-SUM(C12:E12) -> 2094 | G12: =1042+126 -> 1168 | H12: =2449+251-G12 -> 1532 | I12: =3266+316-G12-H12 -> 882 | J12: =4770+325-SUM(G12:I12) -> 1513 | K12: =1332+66 -> 1398 | L12: =2277+125-K12 -> 1004 | M12: =3395+203-L12-K12 -> 1196 | N12: =4524+363-SUM(K12:M12) -> 1289 | O12: =의료기기!Q75 -> 1221.75 | P12: =의료기기!R75 -> 1177.6875 | Q12: =의료기기!S75 -> 1221.1094 | R12: =의료기기!T75 -> 1227.3867 | S12: =의료기기!U75 -> 1211.9834 | T12: =의료기기!V75 -> 1209.5417 | U12: =의료기기!W75 -> 1217.5053 | V12: =의료기기!X75 -> 1216.6043 | ... Y12: =의료기기!AA75 -> 4855.6348
B13: % of sales | C13: =C12/C6 -> 0.056356339 | D13: =D12/D6 -> 0.070519488 | E13: =E12/E6 -> 0.045779728 | F13: =F12/F6 -> 0.051745867 | G13: =G12/G6 -> 0.029968697 | H13: =H12/H6 -> 0.033379088 | I13: =I12/I6 -> 0.018282445 | J13: =J12/J6 -> 0.032186011 | ... Y13: =Y12/Y6 -> 0.010099937
B14: 소모품 등 | C14: =8300+3458 -> 11758 | D14: =15836+7878-C14 -> 11956 | E14: =25620+13356-C14-D14 -> 15262 | F14: =34715+20869-SUM(C14:E14) -> 16608 | G14: =10478+8208 -> 18686 | H14: =23984+16476-G14 -> 21774 | I14: =36143+24814-G14-H14 -> 20497 | J14: =47778+33264-SUM(G14:I14) -> 20085 | K14: =17358+9138 -> 26496 | L14: =32836+19725-K14 -> 26065 | M14: =46414+32158-L14-K14 -> 26011 | N14: =64512+45348-SUM(K14:M14) -> 31288 | O14: =소모품!P6 -> 32450.63 | P14: =소모품!Q6 -> 29635.387 | Q14: =소모품!R6 -> 33324.639 | R14: =소모품!S6 -> 36801.046 | S14: =소모품!T6 -> 39398.318 | T14: =소모품!U6 -> 43497.969 | U14: =소모품!V6 -> 46367.57 | V14: =소모품!W6 -> 49703.714 | W14: =SUM(K14:N14) -> 109860 | X14: =SUM(O14:R14) -> 132211.7 | Y14: =SUM(S14:V14) -> 178967.57
B15: % of sales | C15: =C14/C6 -> 0.33231587 | D15: =D14/D6 -> 0.36578352 | E15: =E14/E6 -> 0.45875917 | F15: =F14/F6 -> 0.41040848 | G15: =G14/G6 -> 0.47944784 | H15: =H14/H6 -> 0.47441009 | I15: =I14/I6 -> 0.42486993 | J15: =J14/J6 -> 0.4272677 | ... Y15: =Y14/Y6 -> 0.37226052
B16: 이루다 | N16: =8350+3334 -> 11684 | O16: ='이루다 및 기타'!L6 -> 13129.464 | P16: ='이루다 및 기타'!M6 -> 14494.183 | Q16: ='이루다 및 기타'!N6 -> 17334.635 | R16: ='이루다 및 기타'!O6 -> 19150.079 | S16: ='이루다 및 기타'!P6 -> 20425.775 | T16: ='이루다 및 기타'!Q6 -> 21906.191 | U16: ='이루다 및 기타'!R6 -> 23628.502 | V16: ='이루다 및 기타'!S6 -> 23866.673 | W16: =N16 -> 11684 | X16: =SUM(O16:R16) -> 64108.361 | Y16: =SUM(S16:V16) -> 89827.141
B17: % of sales | N17: =N16/N6 -> 0.15703668 | O17: =O16/O6 -> 0.16292784 | P17: =P16/P6 -> 0.17578071 | Q17: =Q16/Q6 -> 0.18950969 | R17: =R16/R6 -> 0.18969899 | S17: =S16/S6 -> 0.18978528 | T17: =T16/T6 -> 0.18806892 | U17: =U16/U6 -> 0.18916018 | ... Y17: =Y16/Y6 -> 0.18684446
B18: 화장품 및 개인용 미용기기 | C18: =366+212 -> 578 | D18: =818+450-C18 -> 690 | E18: =978+725-C18-D18 -> 435 | F18: =1073+891-SUM(C18:E18) -> 261 | G18: =63+213 -> 276 | H18: =97+420-G18 -> 241 | I18: =375+782-G18-H18 -> 640 | J18: =1358+1073-SUM(G18:I18) -> 1274 | K18: =669+696 -> 1365 | L18: =1295+1616-K18 -> 1546 | M18: =1451+1892-K18-L18 -> 432 | N18: =1680+2828-SUM(K18:M18) -> 1165 | O18: ='이루다 및 기타'!Q16 -> 1127 | P18: ='이루다 및 기타'!R16 -> 1067.5 | Q18: ='이루다 및 기타'!S16 -> 947.875 | R18: ='이루다 및 기타'!T16 -> 1076.8438 | S18: ='이루다 및 기타'!U16 -> 1054.8047 | T18: ='이루다 및 기타'!V16 -> 1036.7559 | U18: ='이루다 및 기타'!W16 -> 1029.0698 | V18: ='이루다 및 기타'!X16 -> 1049.3685 | W18: =SUM(K18:N18) -> 4508 | X18: =SUM(O18:R18) -> 4219.2188 | Y18: =SUM(S18:V18) -> 4169.9989
B19: % of sales | C19: =C18/C6 -> 0.01633599 | D19: =D18/D6 -> 0.021109955 | E19: =E18/E6 -> 0.013075628 | F19: =F18/F6 -> 0.0064496998 | G19: =G18/G6 -> 0.0070816442 | H19: =H18/H6 -> 0.0052508879 | I19: =I18/I6 -> 0.013266173 | J19: =J18/J6 -> 0.02710177 | ... Y19: =Y18/Y6 -> 0.0086737835
B20: 기타 | C20: =511 -> 511 | D20: =1112-C20 -> 601 | E20: =1640-C20-D20 -> 528 | F20: =2152-SUM(C20:E20) -> 512 | G20: =491 -> 491 | H20: =884-G20 -> 393 | I20: =1286-G20-H20 -> 402 | J20: =1575-SUM(G20:I20) -> 289 | K20: =292 -> 292 | L20: =556-K20 -> 264 | M20: =792-K20-L20 -> 236 | N20: =1012-SUM(K20:M20) -> 220 | O20: ='이루다 및 기타'!Q18 -> 253 | P20: ='이루다 및 기타'!R18 -> 243.25 | Q20: ='이루다 및 기타'!S18 -> 238.0625 | R20: ='이루다 및 기타'!T18 -> 238.57812 | S20: ='이루다 및 기타'!U18 -> 243.22266 | T20: ='이루다 및 기타'!V18 -> 240.77832 | U20: ='이루다 및 기타'!W18 -> 240.1604 | V20: ='이루다 및 기타'!X18 -> 240.68488 | W20: =SUM(K20:N20) -> 1012 | X20: =SUM(O20:R20) -> 972.89062 | Y20: =SUM(S20:V20) -> 964.84625
B21: % of sales | C21: =C20/C6 -> 0.014442372 | D21: =D20/D6 -> 0.018387077 | E21: =E20/E6 -> 0.015871107 | F21: =F20/F6 -> 0.012652285 | G21: =G20/G6 -> 0.012598142 | H21: =H20/H6 -> 0.0085626512 | I21: =I20/I6 -> 0.0083328151 | J21: =J20/J6 -> 0.0061478897 | ... Y21: =Y20/Y6 -> 0.0020069232

Sheet 의료기기
A1: 클래시스(214150.KQ)
A2: Assumption Sheet
A3: (units in Millions KRW )
Q4: =O6/N6-1 -> 0.12677568 | R4: =O8/N8-1 -> 0.14466002 | S4: =P8/O8-1 -> 0.11793023 | T4: =Q8/P8-1 -> 0.074277458 | U4: =R8/Q8-1 -> 0.11879344 | V4: =S8/R8-1 -> 0.069844814 | W4: =T8/S8-1 -> 0.078166722 | X4: =U8/T8-1 -> 0.086617113
B5: (단위: 백만 원) | C5: 1Q22 | D5: 2Q22 | E5: 3Q22 | F5: 4Q22 | G5: 1Q23 | H5: 2Q23 | I5: 3Q23 | J5: 4Q23 | K5: 1Q24 | L5: 2Q24 | M5: 3Q24 | N5: 4Q24 | O5: 1Q25E | P5: 2Q25E | Q5: 3Q25E | R5: 4Q25E | S5: 1Q26E | T5: 2Q26E | U5: 3Q26E | V5: 4Q26E | W5: 2024 | X5: 2025E | Y5: 2026E
B6: 클래시스 | C6: =C8+C24 -> 20541 | D6: =D8+D24 -> 17134 | E6: =E8+E24 -> 15520 | F6: =F8+F24 -> 20992 | G6: =G8+G24 -> 18353 | H6: =H8+H24 -> 21957 | I6: =I8+I24 -> 25826 | J6: =J8+J24 -> 23843 | ... V6: =V8+V24 -> 55663.928 | W6: =SUM(W8,W24) -> 110988 | X6: =SUM(X8,X18,X20,X16) -> 144138.02 | Y6: =SUM(Y8,Y18,Y20,Y16) -> 226898.85
B7: YoY% | G7: =G6/C6-1 -> -0.10651867 | H7: =H6/D6-1 -> 0.2814871 | I7: =I6/E6-1 -> 0.66404639 | J7: =J6/F6-1 -> 0.13581364 | K7: =K6/G6-1 -> 0.13322073 | L7: =L6/H6-1 -> 0.36147925 | M7: =M6/I6-1 -> 0.22121118 | N7: =N6/J6-1 -> 0.20609823 | ... V7: =V6/R6-1 -> 0.31110032 | X7: =X6/W6-1 -> 0.29868116 | Y7: =Y6/X6-1 -> 0.57417757
B8: 수출 | C8: 8752 | D8: =18116-C8 -> 9364 | E8: =29609-D8-C8 -> 11493 | F8: =44284-SUM(C8:E8) -> 14675 | G8: =12460 -> 12460 | H8: =28766-G8 -> 16306 | I8: =46547-G8-H8 -> 17781 | J8: =63157-SUM(G8:I8) -> 16610 | K8: 14261 | L8: =37562-K8 -> 23301 | M8: =62935-L8-K8 -> 25373 | N8: =84686-SUM(K8:M8) -> 21751 | O8: =SUM(O10,O12,O14,O16,O18,O20,O22) -> 24897.5 | P8: =SUM(P10,P12,P14,P16,P18,P20,P22) -> 27833.668 | Q8: =SUM(Q10,Q12,Q14,Q16,Q18,Q20,Q22) -> 29901.082 | R8: =SUM(R10,R12,R14,R16,R18,R20,R22) -> 33453.134 | S8: =SUM(S10,S12,S14,S16,S18,S20,S22) -> 35789.662 | T8: =SUM(T10,T12,T14,T16,T18,T20,T22) -> 38587.223 | U8: =SUM(U10,U12,U14,U16,U18,U20,U22) -> 41929.537 | V8: =SUM(V10,V12,V14,V16,V18,V20,V22) -> 44664.421 | W8: =SUM(K8:N8) -> 84686 | X8: =SUM(O8:R8) -> 116085.38 | Y8: =SUM(S8:V8) -> 160970.84
B9: YoY% | G9: =G8/C8-1 -> 0.42367459 | H9: =H8/D8-1 -> 0.74134985 | I9: =I8/E8-1 -> 0.54711564 | J9: =J8/F8-1 -> 0.1318569 | K9: =K8/G8-1 -> 0.14454254 | L9: =L8/H8-1 -> 0.4289832 | M9: =M8/I8-1 -> 0.42697261 | N9: =N8/J8-1 -> 0.30951234 | ... V9: =V8/R8-1 -> 0.33513412 | W9: =W8/W6 -> 0.76301943 | X9: =X8/X6 -> 0.80537655 | Y9: =Y8/Y6 -> 0.70943879
B10: 브라질 | C10: =D29 -> 1951.2059 | D10: =E29 -> 1891.7553 | E10: =F29 -> 4334.8029 | F10: =G29 -> 7807.1331 | G10: =H29 -> 5591.1359 | H10: =I29 -> 7369.2029 | I10: =J29 -> 8161.6163 | J10: =K29 -> 6176.9533 | ... V10: =W29 -> 7266.8986 | W10: =SUM(K10:N10) -> 24335.661 | X10: =SUM(O10:R10) -> 25349.646 | Y10: =SUM(S10:V10) -> 28053.609
B11: % of sales | C11: =C10/C6 -> 0.094990796 | D11: =D10/D6 -> 0.11040944 | E11: =E10/E6 -> 0.27930431 | F11: =F10/F6 -> 0.37190992 | G11: =G10/G6 -> 0.30464425 | H11: =H10/H6 -> 0.33561975 | I11: =I10/I6 -> 0.31602325 | J11: =J10/J6 -> 0.25906779 | ... Y11: =Y10/Y6 -> 0.12363927
B12: 태국 | C12: =D34 -> 780.23817 | D12: =E34 -> 1126.6227 | E12: =F34 -> 1977.4494 | F12: =G34 -> 845.13544 | G12: =H34 -> 1562.9588 | H12: =I34 -> 3043.3784 | I12: =J34 -> 1705.71 | J12: =K34 -> 1178.7979 | ... V12: =W34 -> 3768.8525 | W12: =SUM(K12:N12) -> 11242.389 | X12: =SUM(O12:R12) -> 12063.75 | Y12: =SUM(S12:V12) -> 14254.048
B13: % of sales | C13: =C12/C6 -> 0.03798443 | D13: =D12/D6 -> 0.06575363 | E13: =E12/E6 -> 0.12741298 | F13: =F12/F6 -> 0.040259882 | G13: =G12/G6 -> 0.085160944 | H13: =H12/H6 -> 0.13860629 | I13: =I12/I6 -> 0.066046233 | J13: =J12/J6 -> 0.04944 | ... Y13: =Y12/Y6 -> 0.062821158
B14: 일본 | C14: =D39 -> 2468.9227 | D14: =E39 -> 2443.5705 | E14: =F39 -> 2507.6452 | F14: =G39 -> 2281.3472 | G14: =H39 -> 2568.3709 | H14: =I39 -> 2161.6156 | I14: =J39 -> 2315.9367 | J14: =K39 -> 2245.4536 | ... V14: =W39 -> 2277.52 | W14: =SUM(K14:N14) -> 6692.3571 | X14: =SUM(O14:R14) -> 7210.4406 | Y14: =SUM(S14:V14) -> 8591.9967
B15: % of sales | C15: =C14/C6 -> 0.12019486 | D15: =D14/D6 -> 0.1426153 | E15: =E14/E6 -> 0.16157508 | F15: =F14/F6 -> 0.10867698 | G15: =G14/G6 -> 0.13994284 | H15: =H14/H6 -> 0.098447674 | I15: =I14/I6 -> 0.08967462 | J15: =J14/J6 -> 0.094176637 | ... Y15: =Y14/Y6 -> 0.03786708
B16: 미국 | C16: - | D16: - | E16: - | F16: - | G16: - | H16: - | I16: - | J16: - | N16: =E44 -> 3312 | O16: =F44 -> 4554 | P16: =G44 -> 5796 | Q16: =H44 -> 7038 | R16: =I44 -> 8280 | S16: =J44 -> 9522 | T16: =K44 -> 10764 | U16: =L44 -> 12006 | V16: =M44 -> 13248 | W16: =N16 -> 3312 | X16: =SUM(O16:R16) -> 25668 | Y16: =SUM(S16:V16) -> 45540
B17: % of sales | K17: =K16/K6 -> 0 | L17: =L16/L6 -> 0 | M17: =M16/M6 -> 0 | N17: =N16/N6 -> 0.11517196 | O17: =O16/O6 -> 0.14054389 | P17: =P16/P6 -> 0.16172757 | Q17: =Q16/Q6 -> 0.18325907 | R17: =R16/R6 -> 0.19502595 | ... Y17: =Y16/Y6 -> 0.20070618
B18: 유럽 | C18: - | D18: - | E18: - | F18: - | G18: - | H18: - | I18: - | J18: - | R18: =E51 -> 2384.64 | S18: =F51 -> 3278.88 | T18: =G51 -> 4173.12 | U18: =H51 -> 5067.36 | V18: =I51 -> 5961.6 | X18: =R18 -> 2384.64 | Y18: =SUM(S18:V18) -> 18480.96
B19: % of sales | K19: =K18/K6 -> 0 | L19: =L18/L6 -> 0 | M19: =M18/M6 -> 0 | N19: =N18/N6 -> 0 | O19: =O18/O6 -> 0 | P19: =P18/P6 -> 0 | Q19: =Q18/Q6 -> 0 | R19: =R18/R6 -> 0.056167475 | ... Y19: =Y18/Y6 -> 0.081450216
B20: 중국 | C20: - | D20: - | E20: - | F20: - | G20: - | H20: - | I20: - | J20: - | U20: =G56 -> 802.96509 | V20: =H56 -> 1104.077 | Y20: =SUM(U20:V20) -> 1907.0421
B21: % of sales | K21: =K20/K6 -> 0 | L21: =L20/L6 -> 0 | M21: =M20/M6 -> 0 | N21: =N20/N6 -> 0 | O21: =O20/O6 -> 0 | P21: =P20/P6 -> 0 | Q21: =Q20/Q6 -> 0 | R21: =R20/R6 -> 0 | ... Y21: =Y20/Y6 -> 0.0084048118
B22: 기타 | C22: =C8-SUM(C10,C12,C14) -> 3551.6332 | D22: =D8-SUM(D10,D12,D14) -> 3902.0514 | E22: =E8-SUM(E10,E12,E14) -> 2673.1026 | F22: =F8-SUM(F10,F12,F14) -> 3741.3843 | G22: =G8-SUM(G10,G12,G14) -> 2737.5344 | H22: =H8-SUM(H10,H12,H14) -> 3731.8031 | I22: =I8-SUM(I10,I12,I14) -> 5597.7369 | J22: =J8-SUM(J10,J12,J14) -> 7008.7953 | ... M22: =M8-SUM(M10,M12,M14) -> 13378.307 | N22: =N8-SUM(N10,N12,N14,N16) -> 11811.98 | O22: =AVERAGE(K22:N22) -> 9775.8984 | P22: =AVERAGE(L22:O22) -> 11077.828 | Q22: =AVERAGE(M22:P22) -> 11511.003 | R22: =AVERAGE(N22:Q22) -> 11044.177 | S22: =AVERAGE(O22:R22) -> 10852.227 | T22: =AVERAGE(P22:S22) -> 11121.309 | U22: =AVERAGE(Q22:T22) -> 11132.179 | V22: =AVERAGE(R22:U22) -> 11037.473 | W22: =SUM(K22:N22) -> 39103.594 | X22: =SUM(O22:R22) -> 43408.907 | Y22: =SUM(S22:V22) -> 44143.187
B23: % of sales | C23: =C22/C8 -> 0.40580818 | D23: =D22/D8 -> 0.41670775 | E23: =E22/E8 -> 0.23258528 | F23: =F22/F8 -> 0.25494953 | G23: =G22/G8 -> 0.21970581 | H23: =H22/H8 -> 0.22886073 | I23: =I22/I8 -> 0.31481564 | J23: =J22/J8 -> 0.42196239 | ... Y23: =Y22/Y8 -> 0.27423095
B24: 내수 | C24: 11789 | D24: =19559-C24 -> 7770 | E24: =23586-C24-D24 -> 4027 | F24: =29903-SUM(C24:E24) -> 6317 | G24: =5893 -> 5893 | H24: =11544-G24 -> 5651 | I24: =19589-G24-H24 -> 8045 | J24: =26822-SUM(G24:I24) -> 7233 | K24: =6537 -> 6537 | L24: =13130-K24 -> 6593 | M24: =19296-L24-K24 -> 6166 | N24: =26302-K24-L24-M24 -> 7006 | O24: 7505.1884 | P24: 8004.3767 | Q24: 8503.5651 | R24: 9002.7534 | S24: 9501.9418 | T24: 10001.13 | U24: 10500.318 | V24: 10999.507 | W24: =SUM(K24:N24) -> 26302 | X24: =SUM(O24:R24) -> 33015.884 | Y24: =SUM(S24:V24) -> 41002.897
B25: YoY% | G25: =G24/C24-1 -> -0.50012724 | H25: =H24/D24-1 -> -0.27271557 | I25: =I24/E24-1 -> 0.99776509 | J25: =J24/F24-1 -> 0.14500554 | K25: =K24/G24-1 -> 0.1092822 | L25: =L24/H24-1 -> 0.16669616 | M25: =M24/I24-1 -> -0.23356122 | N25: =N24/J24-1 -> -0.031383935 | ... V25: =V24/R24-1 -> 0.22179364 | W25: =W24/W6 -> 0.23698057 | X25: =X24/X6 -> 0.22905742 | Y25: =Y24/Y6 -> 0.18071003
Q26: =O24/N24-1 -> 0.071251549 | R26: =P24/O24-1 -> 0.066512435 | S26: =Q24/P24-1 -> 0.062364425 | T26: =R24/Q24-1 -> 0.05870342 | U26: =S24/R24-1 -> 0.055448409 | V26: =T24/S24-1 -> 0.052535404 | W26: =U24/T24-1 -> 0.049913194 | X26: =V24/U24-1 -> 0.047540306
B28: (단위: 백만 원) | D28: 1Q22 | E28: 2Q22 | F28: 3Q22 | G28: 4Q22 | H28: 1Q23 | I28: 2Q23 | J28: 3Q23 | K28: 4Q23 | L28: 1Q24 | M28: 2Q24 | N28: 3Q24 | O28: 4Q24 | P28: 1Q25E | Q28: 2Q25E | R28: 3Q25E | S28: 4Q25E | T28: 1Q26E | U28: 2Q26E | V28: 3Q26E | W28: 4Q26E | X28: 2024 | Y28: 2025E | Z28: 2026E | AB28: EBD 침투율 | AC28: (단위:%) | AD28: 24E | AE28: 25E | AF28: 26E | AG28: 27E | AH28: 28E | AI28: 29E | AJ28: 30E | AM28: 2022 | AN28: 2023 | AO28: 2024
B29: 브라질 | D29: 1951.2059 | E29: 1891.7553 | F29: 4334.8029 | G29: 7807.1331 | H29: 5591.1359 | I29: 7369.2029 | J29: 8161.6163 | K29: 6176.9533 | L29: 4355.3811 | M29: 7579.674 | N29: 9015.3743 | O29: 3385.2312 | P29: 6083.9151 | Q29: 6252.9128 | R29: 6421.9104 | S29: 6590.9081 | T29: 6759.9057 | U29: 6928.9033 | V29: 7097.901 | W29: =AVERAGE(L29:O29)*AF38/AD38 -> 7266.8986 | X29: =SUM(L29:O29) -> 24335.661 | Y29: =SUM(P29:S29) -> 25349.646 | Z29: =SUM(T29:W29) -> 28053.609 | AB29: HIFU | AC29: BR | AD29: 12.8 | AE29: 13.266667 | AF29: 13.733333 | AG29: 14.2 | AH29: 14.666667 | AI29: 15.133333 | AJ29: 15.6 | AL29: 원/달러 | AM29: 1205.5 | AN29: 1231.9 | AO29: 1334.6
C30: YoY% | H30: =H29/D29-1 -> 1.8654771 | I30: =I29/E29-1 -> 2.8954313 | J30: =J29/F29-1 -> 0.88281142 | K30: =K29/G29-1 -> -0.20880646 | L30: =L29/H29-1 -> -0.22102034 | M30: =M29/I29-1 -> 0.028560895 | N30: =N29/J29-1 -> 0.10460648 | O30: =O29/K29-1 -> -0.45195778 | ... W30: =W29/S29-1 -> 0.1025641 | AC30: TH | AD30: 38.7 | AE30: 43.066667 | AF30: 47.433333 | AG30: 51.8 | AH30: 56.166667 | AI30: 60.533333 | AJ30: 64.9
F31: =G29/F29-1 -> 0.80103533 | M31: =M29/L29-1 -> 0.74030097 | N31: =N29/M29-1 -> 0.18941452 | AC31: JP | AD31: 11.9 | AE31: 12.3 | AF31: 12.7 | AG31: 13.1 | AH31: 13.5 | AI31: 13.9 | AJ31: 14.3
AB32: MRF | AC32: BR | AD32: 1 | AE32: 1.5 | AF32: 2 | AG32: 2.5 | AH32: 3 | AI32: 3.5 | AJ32: 4
B33: (단위: 백만 원) | D33: 1Q22 | E33: 2Q22 | F33: 3Q22 | G33: 4Q22 | H33: 1Q23 | I33: 2Q23 | J33: 3Q23 | K33: 4Q23 | L33: 1Q24 | M33: 2Q24 | N33: 3Q24 | O33: 4Q24 | P33: 1Q25E | Q33: 2Q25E | R33: 3Q25E | S33: 4Q25E | T33: 1Q26E | U33: 2Q26E | V33: 3Q26E | W33: 4Q26E | X33: 2024 | Y33: 2025E | Z33: 2026E | AC33: TH | AD33: 23 | AE33: 29.166667 | AF33: 35.333333 | AG33: 41.5 | AH33: 47.666667 | AI33: 53.833333 | AJ33: 60
B34: 태국 | D34: 780.23817 | E34: 1126.6227 | F34: 1977.4494 | G34: 845.13544 | H34: 1562.9588 | I34: 3043.3784 | J34: 1705.71 | K34: 1178.7979 | L34: 3080.5705 | M34: 4877.3794 | N34: 1639.159 | O34: 1645.2797 | P34: 2810.5972 | Q34: 2947.4908 | R34: 3084.3844 | S34: 3221.278 | T34: 3358.1716 | U34: 3495.0653 | V34: 3631.9589 | W34: =AVERAGE(L34:O34)*AF39/AD39 -> 3768.8525 | X34: =SUM(L34:O34) -> 11242.389 | Y34: =SUM(P34:S34) -> 12063.75 | Z34: =SUM(T34:W34) -> 14254.048 | AC34: JP | AD34: 3 | AE34: 4.8333333 | AF34: 6.6666667 | AG34: 8.5 | AH34: 10.333333 | AI34: 12.166667 | AJ34: 14
C35: YoY% | H35: =H34/D34-1 -> 1.0031817 | I35: =I34/E34-1 -> 1.7013288 | J35: =J34/F34-1 -> -0.13741913 | K35: =K34/G34-1 -> 0.39480356 | L35: =L34/H34-1 -> 0.97098636 | M35: =M34/I34-1 -> 0.60262012 | N35: =N34/J34-1 -> -0.039016626 | O35: =O34/K34-1 -> 0.39572671 | ... W35: =W34/S34-1 -> 0.16998672 | AB35: MNRF | AC35: BR | AD35: 3 | AE35: 3.6666667 | AF35: 4.3333333 | AG35: 5 | AH35: 5.6666667 | AI35: 6.3333333 | AJ35: 7
M36: =M34/L34-1 -> 0.58327148 | AC36: TH | AD36: 4 | AE36: 4.6666667 | AF36: 5.3333333 | AG36: 6 | AH36: 6.6666667 | AI36: 7.3333333 | AJ36: 8
AC37: JP | AD37: 3 | AE37: 4 | AF37: 5 | AG37: 6 | AH37: 7 | AI37: 8 | AJ37: 9
B38: (단위: 백만 원) | D38: 1Q22 | E38: 2Q22 | F38: 3Q22 | G38: 4Q22 | H38: 1Q23 | I38: 2Q23 | J38: 3Q23 | K38: 4Q23 | L38: 1Q24 | M38: 2Q24 | N38: 3Q24 | O38: 4Q24 | P38: 1Q25E | Q38: 2Q25E | R38: 3Q25E | S38: 4Q25E | T38: 1Q26E | U38: 2Q26E | V38: 3Q26E | W38: 4Q26E | X38: 2024 | Y38: 2025E | Z38: 2026E | AB38: EBD(Average) | AC38: BR | AD38: =AVERAGE(AD29,AD32,AD35) -> 5.6 | AE38: =AVERAGE(AE29,AE32,AE35) -> 6.1444444 | AF38: =AVERAGE(AF29,AF32,AF35) -> 6.6888889 | AG38: =AVERAGE(AG29,AG32,AG35) -> 7.2333333 | AH38: =AVERAGE(AH29,AH32,AH35) -> 7.7777778 | AI38: =AVERAGE(AI29,AI32,AI35) -> 8.3222222 | AJ38: =AVERAGE(AJ29,AJ32,AJ35) -> 8.8666667
B39: 일본 | D39: 2468.9227 | E39: 2443.5705 | F39: 2507.6452 | G39: 2281.3472 | H39: 2568.3709 | I39: 2161.6156 | J39: 2315.9367 | K39: 2245.4536 | L39: 2256.8672 | M39: 1498.8212 | N39: 1340.1593 | O39: 1596.5095 | P39: 1673.0893 | Q39: 1759.4365 | R39: 1845.7838 | S39: 1932.131 | T39: 2018.4783 | U39: 2104.8255 | V39: 2191.1728 | W39: =AVERAGE(L39:O39)*AF40/AD40 -> 2277.52 | X39: =SUM(L39:O39) -> 6692.3571 | Y39: =SUM(P39:S39) -> 7210.4406 | Z39: =SUM(T39:W39) -> 8591.9967 | AC39: TH | AD39: =AVERAGE(AD30,AD33,AD36) -> 21.9 | AE39: =AVERAGE(AE30,AE33,AE36) -> 25.633333 | AF39: =AVERAGE(AF30,AF33,AF36) -> 29.366667 | AG39: =AVERAGE(AG30,AG33,AG36) -> 33.1 | AH39: =AVERAGE(AH30,AH33,AH36) -> 36.833333 | AI39: =AVERAGE(AI30,AI33,AI36) -> 40.566667 | AJ39: =AVERAGE(AJ30,AJ33,AJ36) -> 44.3
C40: YoY% | H40: =H39/D39-1 -> 0.040280018 | I40: =I39/E39-1 -> -0.11538647 | J40: =J39/F39-1 -> -0.076449588 | K40: =K39/G39-1 -> -0.015733528 | L40: =L39/H39-1 -> -0.12128455 | M40: =M39/I39-1 -> -0.30661992 | N40: =N39/J39-1 -> -0.42133166 | O40: =O39/K39-1 -> -0.28900357 | ... W40: =W39/S39-1 -> 0.17876065 | AC40: JP | AD40: =AVERAGE(AD31,AD34,AD37) -> 5.9666667 | AE40: =AVERAGE(AE31,AE34,AE37) -> 7.0444444 | AF40: =AVERAGE(AF31,AF34,AF37) -> 8.1222222 | AG40: =AVERAGE(AG31,AG34,AG37) -> 9.2 | AH40: =AVERAGE(AH31,AH34,AH37) -> 10.277778 | AI40: =AVERAGE(AI31,AI34,AI37) -> 11.355556 | AJ40: =AVERAGE(AJ31,AJ34,AJ37) -> 12.433333
B43: (단위: 백만 원) | E43: 4Q24 | F43: 1Q25E | G43: 2Q25E | H43: 3Q25E | I43: 4Q25E | J43: 1Q26E | K43: 2Q26E | L43: 3Q26E | M43: 4Q26E | N43: 2024 | O43: 2025E | P43: 2026E
...

Sheet 소모품
A1: 클래시스(214150.KQ)
A2: Assumption Sheet
A3: (units in Millions KRW )
B5: (단위: 백만 원) | D5: 1Q22 | E5: 2Q22 | F5: 3Q22 | G5: 4Q22 | H5: 1Q23 | I5: 2Q23 | J5: 3Q23 | K5: 4Q23 | L5: 1Q24 | M5: 2Q24 | N5: 3Q24 | O5: 4Q24 | P5: 1Q25E | Q5: 2Q25E | R5: 3Q25E | S5: 4Q25E | T5: 1Q26E | U5: 2Q26E | V5: 3Q26E | W5: 4Q26E | X5: 2024 | Y5: 2025E | Z5: 2026E
B6: 소모품 | D6: 11758 | E6: 11956 | F6: 15252 | G6: 16618 | H6: 18686 | I6: 26556 | J6: 15715 | K6: 20086 | L6: 26496 | M6: 26065 | N6: 26011 | O6: 31288 | P6: =의료기기!M6*1.01194946+534.756199 -> 32450.63 | Q6: =의료기기!N6*1.01194946+534.756199 -> 29635.387 | R6: =의료기기!O6*1.01194946+534.756199 -> 33324.639 | S6: =의료기기!P6*1.01194946+534.756199 -> 36801.046 | T6: =의료기기!Q6*1.01194946+534.756199 -> 39398.318 | U6: =의료기기!R6*1.01194946+534.756199 -> 43497.969 | V6: =의료기기!S6*1.01194946+534.756199 -> 46367.57 | W6: =의료기기!T6*1.01194946+534.756199 -> 49703.714 | X6: =SUM(L6:O6) -> 109860 | Y6: =SUM(P6:S6) -> 132211.7 | Z6: =SUM(T6:W6) -> 178967.57
C7: YoY% | H7: =H6/D6-1 -> 0.58921585 | I7: =I6/E6-1 -> 1.2211442 | J7: =J6/F6-1 -> 0.030356675 | K7: =K6/G6-1 -> 0.20868937 | L7: =L6/H6-1 -> 0.41795997 | M7: =M6/I6-1 -> -0.01848923 | N7: =N6/J6-1 -> 0.65517022 | O7: =O6/K6-1 -> 0.55770188 | ... W7: =W6/S6-1 -> 0.35060601 | Y7: =Y6/X6-1 -> 0.20345624 | Z7: =Z6/Y6-1 -> 0.35364395
D9: 계수 | E9: 표준 오차 | F9: t 통계량 | G9: P-값 | H9: 하위 95% | I9: 상위 95% | J9: 하위 95.0% | K9: 상위 95.0%
C10: Y 절편 | D10: 534.7562 | E10: 6488.9559 | F10: 0.082410207 | G10: 0.93634515 | H10: -14428.803 | I10: 15498.315 | J10: -14428.803 | K10: 15498.315
C11: X 1 | D11: 1.0119495 | E11: 0.29670873 | F11: 3.4105821 | G11: 0.009215214 | H11: 0.32773791 | I11: 1.696161 | J11: 0.32773791 | K11: 1.696161

Sheet 이루다 및 기타
A1: 클래시스(214150.KQ)
A2: Assumption Sheet
A3: (units in Millions KRW )
B5: (단위: 백만 원) | D5: 1Q23 | E5: 2Q23 | F5: 3Q23 | G5: 4Q23 | H5: 1Q24 | I5: 2Q24 | J5: 3Q24 | K5: 4Q24 | L5: 1Q25E | M5: 2Q25E | N5: 3Q25E | O5: 4Q25E | P5: 1Q26E | Q5: 2Q26E | R5: 3Q26E | S5: 4Q26E | T5: 2024 | U5: 2025E | V5: 2026E
B6: 이루다 | D6: 11161 | E6: 14372 | F6: 13971 | G6: 16702 | H6: 14088 | I6: 12241 | K6: =SUM(K8,K10) -> 11684 | L6: =L8+L10 -> 13129.464 | M6: =SUM(M8,M10) -> 14494.183 | N6: =SUM(N8,N10) -> 17334.635 | O6: =SUM(O8,O10) -> 19150.079 | P6: =SUM(P8,P10) -> 20425.775 | Q6: =SUM(Q8,Q10) -> 21906.191 | R6: =SUM(R8,R10) -> 23628.502 | S6: =SUM(S8,S10) -> 23866.673 | T6: =SUM(T8,X18,X20,X16) -> 28797.053 | U6: =U8+U10 -> 64108.361 | V6: =V8+V10 -> 89827.141
C7: YoY% | H7: 0.26225249 | I7: -0.14827442 | J7: =J6/F6-1 -> -1 | L7: =L6/H6-1 -> -0.068039197 | M7: =M6/I6-1 -> 0.18406855 | N7: =N6/J6-1 -> #DIV/0! | O7: =O6/K6-1 -> 0.63900029 | P7: =P6/L6-1 -> 0.55572046 | Q7: =Q6/M6-1 -> 0.51137811 | R7: =R6/N6-1 -> 0.36308044 | S7: =S6/O6-1 -> 0.24629628 | U7: =U6/T6-1 -> 1.2262125 | V7: =V6/U6-1 -> 0.40117668
C8: 수출 | D8: 8316 | E8: 10718 | F8: 10597 | G8: 13168 | H8: 10352 | I8: 8805 | K8: 8350 | L8: =K8*(의료기기!R4+1) -> 9557.9111 | M8: =L8*(의료기기!S4+1) -> 10685.078 | N8: =M8*(G12+1) -> 13277.447 | O8: =N8*(의료기기!U4+1) -> 14854.72 | P8: =O8*(의료기기!V4+1) -> 15892.246 | Q8: =P8*(의료기기!W4+1) -> 17134.49 | R8: =Q8*(의료기기!X4+1) -> 18618.63 | S8: =R8*(의료기기!Y4+1) -> 18618.63 | T8: =SUM(H8:K8) -> 27507 | U8: =SUM(L8:O8) -> 48375.156 | V8: =SUM(P8:S8) -> 70263.997
C9: % of sales | D9: 0.74509453 | E9: 0.74575564 | F9: 0.75849975 | G9: 0.78840857 | H9: 0.73480977 | I9: 0.71930398 | J9: =J8/J6 -> #DIV/0! | K9: =K8/K6 -> 0.71465252 | L9: =L8/L6 -> 0.72797422 | M9: =M8/M6 -> 0.73719765 | N9: =N8/N6 -> 0.76594903 | O9: =O8/O6 -> 0.7757002 | P9: =P8/P6 -> 0.77804858 | Q9: =Q8/Q6 -> 0.7821757 | ... V9: =V8/V6 -> 0.78221344
C10: 내수 | D10: 2845 | E10: 3654 | F10: 3374 | G10: 3534 | H10: 3736 | I10: 3436 | K10: 3334 | L10: =K10*(의료기기!Q26+1) -> 3571.5527 | M10: =L10*(의료기기!R26+1) -> 3809.1053 | N10: =M10*G25 -> 4057.1882 | O10: ='이루다 및 기타'!N10*(의료기기!T26+1) -> 4295.359 | P10: ='이루다 및 기타'!O10*(의료기기!U26+1) -> 4533.5298 | Q10: ='이루다 및 기타'!P10*(의료기기!V26+1) -> 4771.7006 | R10: ='이루다 및 기타'!Q10*(의료기기!W26+1) -> 5009.8715 | S10: ='이루다 및 기타'!R10*(의료기기!X26+1) -> 5248.0423 | T10: =SUM(H10:K10) -> 10506 | U10: =SUM(L10:O10) -> 15733.205 | V10: =SUM(P10:S10) -> 19563.144
C11: % of sales | D11: 0.25490547 | E11: 0.25424436 | F11: 0.24150025 | G11: 0.21159143 | H11: 0.26519023 | I11: 0.28069602 | J11: =J10/J6 -> #DIV/0! | K11: =K10/K6 -> 0.28534748 | L11: =L10/L6 -> 0.27202578 | M11: =M10/M6 -> 0.26280235 | N11: =N10/N6 -> 0.23405097 | O11: =O10/O6 -> 0.2242998 | P11: =P10/P6 -> 0.22195142 | Q11: =Q10/Q6 -> 0.2178243 | ... V11: =V10/V6 -> 0.21778656
G12: =G8/F8-1 -> 0.24261583
B15: (단위: 백만 원) | E15: 1Q22 | F15: 2Q22 | G15: 3Q22 | H15: 4Q22 | I15: 1Q23 | J15: 2Q23 | K15: 3Q23 | L15: 4Q23 | M15: 1Q24 | N15: 2Q24 | O15: 3Q24 | P15: 4Q24 | Q15: 1Q25E | R15: 2Q25E | S15: 3Q25E | T15: 4Q25E | U15: 1Q26E | V15: 2Q26E | W15: 3Q26E | X15: 4Q26E | Y15: 2024 | Z15: 2025E | AA15: 2026E
B16: 화장품 및 개인용 의료기기 | E16: =366+212 -> 578 | F16: =818+450-E16 -> 690 | G16: =978+725-E16-F16 -> 435 | H16: =1073+891-SUM(E16:G16) -> 261 | I16: =63+213 -> 276 | J16: =97+420-I16 -> 241 | K16: =375+782-I16-J16 -> 640 | L16: =1358+1073-SUM(I16:K16) -> 1274 | M16: =669+696 -> 1365 | N16: =1295+1616-M16 -> 1546 | O16: =1451+1892-M16-N16 -> 432 | P16: =1680+2828-SUM(M16:O16) -> 1165 | Q16: =AVERAGE(M16:P16) -> 1127 | R16: =AVERAGE(N16:Q16) -> 1067.5 | S16: =AVERAGE(O16:R16) -> 947.875 | T16: =AVERAGE(P16:S16) -> 1076.8438 | U16: =AVERAGE(Q16:T16) -> 1054.8047 | V16: =AVERAGE(R16:U16) -> 1036.7559 | W16: =AVERAGE(S16:V16) -> 1029.0698 | X16: =AVERAGE(T16:W16) -> 1049.3685 | Y16: =SUM(M16:P16) -> 4508 | Z16: =SUM(Q16:T16) -> 4219.2188 | AA16: =SUM(U16:X16) -> 4169.9989
C17: YoY% | I17: =I16/E16-1 -> -0.52249135 | J17: =J16/F16-1 -> -0.65072464 | K17: =K16/G16-1 -> 0.47126437 | L17: =L16/H16-1 -> 3.8812261 | M17: =M16/I16-1 -> 3.9456522 | N17: =N16/J16-1 -> 5.4149378 | O17: =O16/K16-1 -> -0.325 | P17: =P16/L16-1 -> -0.0855573 | ... X17: =X16/T16-1 -> -0.025514583 | Z17: =Z16/Y16-1 -> -0.064059727 | AA17: =AA16/Z16-1 -> -0.011665631
B18: 기타 | E18: =511 -> 511 | F18: =1112-E18 -> 601 | G18: =1640-E18-F18 -> 528 | H18: =2152-SUM(E18:G18) -> 512 | I18: =491 -> 491 | J18: =884-I18 -> 393 | K18: =1286-I18-J18 -> 402 | L18: =1575-SUM(I18:K18) -> 289 | M18: =292 -> 292 | N18: =556-M18 -> 264 | O18: =792-M18-N18 -> 236 | P18: =1012-SUM(M18:O18) -> 220 | Q18: =AVERAGE(M18:P18) -> 253 | R18: =AVERAGE(N18:Q18) -> 243.25 | S18: =AVERAGE(O18:R18) -> 238.0625 | T18: =AVERAGE(P18:S18) -> 238.57812 | U18: =AVERAGE(Q18:T18) -> 243.22266 | V18: =AVERAGE(R18:U18) -> 240.77832 | W18: =AVERAGE(S18:V18) -> 240.1604 | X18: =AVERAGE(T18:W18) -> 240.68488 | Y18: =SUM(M18:P18) -> 1012 | Z18: =SUM(Q18:T18) -> 972.89062 | AA18: =SUM(U18:X18) -> 964.84625
C19: YoY% | I19: =I18/E18-1 -> -0.039138943 | J19: =J18/F18-1 -> -0.34608985 | K19: =K18/G18-1 -> -0.23863636 | L19: =L18/H18-1 -> -0.43554688 | M19: =M18/I18-1 -> -0.40529532 | N19: =N18/J18-1 -> -0.32824427 | O19: =O18/K18-1 -> -0.41293532 | P19: =P18/L18-1 -> -0.23875433 | ... X19: =X18/T18-1 -> 0.0088304428 | Z19: =Z18/Y18-1 -> -0.038645627 | AA19: =AA18/Z18-1 -> -0.0082685272
C22: 이루다 매출 | D22: 시크릿 듀오 21년 7월 출시
C23: 1Q21 | D23: 2Q21 | E23: 3Q21 | F23: 4Q21
B24: 수출 | C24: =3265+437 -> 3702 | D24: =6669+700-C24 -> 3667 | E24: =11113+1312-D24-C24 -> 5056 | F24: =15725+2031-SUM(C24:E24) -> 5331
B25: 내수 | C25: =860+186 -> 1046 | D25: =1896+736-C25 -> 1586 | E25: =2480+889-C25-D25 -> 737 | F25: =3636+1255-SUM(C25:E25) -> 1522 | G25: =F25/E25-1 -> 1.0651289
C26: =SUM(C24:C25) -> 4748 | D26: =SUM(D24:D25) -> 5253 | E26: =SUM(E24:E25) -> 5793 | F26: =SUM(F24:F25) -> 6853
D27: =D26/C26-1 -> 0.10636057
D29: =D25/C25-1 -> 0.51625239 | F29: =E25/D25-1 -> -0.53530895

Sheet 비용 추정
A1: 클래시스(214150.KQ)
A2: Assumption Sheet
A3: (units in Millions KRW )
W4: 2024
B5: (단위: 백만원) | C5: 1Q22 | D5: 2Q22 | E5: 3Q22 | F5: 4Q22 | G5: 1Q23 | H5: 2Q23 | I5: 3Q23 | J5: 4Q23 | K5: 1Q24 | L5: 2Q24 | M5: 3Q24 | N5: 4Q24 | O5: 1Q25E | P5: 2Q25E | Q5: 3Q25E | R5: 4Q25E | Z5: Description
B6: 매출액 | C6: ='매출액 추정'!C6 -> 35382 | D6: ='매출액 추정'!D6 -> 32686 | E6: ='매출액 추정'!E6 -> 33268 | F6: ='매출액 추정'!F6 -> 40467 | G6: ='매출액 추정'!G6 -> 38974 | H6: ='매출액 추정'!H6 -> 45897 | I6: ='매출액 추정'!I6 -> 48243 | J6: ='매출액 추정'!J6 -> 47008 | ... R6: ='매출액 추정'!R6 -> 100949.82
B7: 매출원가 | C7: 8800 | D7: 8277 | E7: 7317 | F7: 9241 | G7: 8764 | H7: 9577 | I7: 11234 | J7: 10099 | K7: 10177 | L7: 11228 | M7: 12814 | N7: 17593 | O7: =O6*O8 -> 18118.758 | P7: =P6*P8 -> 17581.919 | Q7: =Q6*Q8 -> 18441.817 | R7: =R6*R8 -> 19180.466 | Z7: 매출원가율의 경우, 소모품의 판매 비중이 높아짐에 따라 하락할 것으로 예상됨. 이에 따라 4Q25E의 매출원가율을 과거 최소치였던 19%로 가정하고 점차 감소하는 시나리오로 추정.
B8: 매출원가율(%) | C8: =C7/C6 -> 0.24871404 | D8: =D7/D6 -> 0.25322768 | E8: =E7/E6 -> 0.21994108 | F8: =F7/F6 -> 0.22835891 | G8: =G7/G6 -> 0.22486786 | H8: =H7/H6 -> 0.20866288 | I8: =I7/I6 -> 0.2328628 | J8: =J7/J6 -> 0.21483577 | ... M8: =M7/M6 -> 0.21567307 | N8: 0.23645552 | O8: 0.22484164 | P8: 0.21322776 | Q8: 0.20161388 | R8: 0.19
B9: 매출총이익 | C9: =C6-C7 -> 26582 | D9: =D6-D7 -> 24409 | E9: =E6-E7 -> 25951 | F9: =F6-F7 -> 31226 | G9: =G6-G7 -> 30210 | H9: =H6-H7 -> 36320 | I9: =I6-I7 -> 37009 | J9: =J6-J7 -> 36909 | ... R9: =R6-R7 -> 81769.356
B10: GPM(%) | C10: =C9/C6 -> 0.75128596 | D10: =D9/D6 -> 0.74677232 | E10: =E9/E6 -> 0.78005892 | F10: =F9/F6 -> 0.77164109 | G10: =G9/G6 -> 0.77513214 | H10: =H9/H6 -> 0.79133712 | I10: =I9/I6 -> 0.7671372 | J10: =J9/J6 -> 0.78516423 | ... R10: =R9/R6 -> 0.81
B11: 판매비와 관리비 | C11: 9876.724 | D11: 9144.9522 | E11: 8471.9286 | F11: 11797.212 | G11: 10318.628 | H11: 13174.374 | I11: 12348.212 | J11: 14985.469 | K11: 13694.299 | L11: 16325.518 | M11: 17648.23 | N11: 21003.692 | O11: =SUM(O12:O43) -> 22079.563 | P11: =SUM(P12:P43) -> 22582.112 | Q11: =SUM(Q12:Q43) -> 24968.435 | R11: =SUM(R12:R43) -> 27636.256 | T11: of sales(%) | U11: 2022 | V11: 2023 | W11: 2024 | X11: 2025E
B12: 급여 | C12: 2562.656 | D12: =(2546211-40)/1000 -> 2546.171 | E12: 2828.2032 | F12: 2085.9336 | G12: 2200.0245 | H12: 2437.2019 | I12: 2533.016 | J12: 2500.849 | K12: 2749.218 | L12: 2864.951 | M12: 3187.89 | N12: 3684.084 | O12: =K12*(1.036) -> 2848.1898 | P12: =L12*(1.036) -> 2968.0892 | Q12: =M12*(1.036) -> 3302.654 | R12: =N12*(1.036) -> 3816.711 | T12: 급여 | U12: =SUM(C12:F12)/SUM('매출액 추정'!$C$6:$F$6) -> 0.070682311 | V12: =SUM(G12:J12)/SUM('매출액 추정'!$G$6:$J$6) -> 0.053691894 | W12: =SUM(K12:N12)/SUM('매출액 추정'!$K$6:$N$6) -> 0.051396206 | X12: =SUM(O12:R12)/SUM($O$6:$R$6) -> 0.036391139 | Z12: 급여의 경우, 국회예산정책처에서 발표한 명목임금상승률 전망치를 이용하여 25년 각 분기 추정
B13: 경상연구개발비 | C13: 1092.835 | D13: 1018.4202 | E13: 1003.5314 | F13: 1314.9905 | G13: 2115.6629 | H13: 2282.4004 | I13: 2213.2935 | J13: 2589.286 | K13: 2799.651 | L13: 2824.206 | M13: 3075.951 | N13: 3917.86 | O13: =N13*(1+(O$6/N$6-1)) -> 4243.3627 | P13: =O13*(1+(P$6/O$6-1)) -> 4341.9119 | Q13: =P13*(1+(Q$6/P$6-1)) -> 4816.6129 | R13: =Q13*(1+(R$6/Q$6-1)) -> 5315.7436 | T13: 경상연구개발비 | U13: =SUM(C13:F13)/SUM('매출액 추정'!$C$6:$F$6) -> 0.031238952 | V13: =SUM(G13:J13)/SUM('매출액 추정'!$G$6:$J$6) -> 0.051080061 | W13: =SUM(K13:N13)/SUM('매출액 추정'!$K$6:$N$6) -> 0.051937598 | X13: =SUM(O13:R13)/SUM($O$6:$R$6) -> 0.052657285 | Z13: 경상연구개발비의 경우, 해외 수출 확대와 함께 신제품 출시를 위해 가속화될 것으로 예상. 매출액 연동
B14: 광고선전비 | C14: 1609.318 | D14: 2002.1938 | E14: 1112.29 | F14: 1190.3856 | G14: 1318.6465 | H14: 3702.8743 | I14: 1466.4202 | J14: 2541.797 | K14: 2227.27 | L14: 2516.354 | M14: 4737.623 | N14: 3339.496 | O14: =N14*(1+(O$6/N$6-1)) -> 3616.9472 | P14: =O14*(1+(P$6/O$6-1)) -> 3700.9483 | Q14: =P14*(1+(Q$6/P$6-1)) -> 4105.5728 | R14: =Q14*(1+(R$6/Q$6-1)) -> 4531.0206 | T14: 광고선전비 | U14: =SUM(C14:F14)/SUM('매출액 추정'!$C$6:$F$6) -> 0.041707068 | V14: =SUM(G14:J14)/SUM('매출액 추정'!$G$6:$J$6) -> 0.050131233 | W14: =SUM(K14:N14)/SUM('매출액 추정'!$K$6:$N$6) -> 0.052773507 | X14: =SUM(O14:R14)/SUM($O$6:$R$6) -> 0.044883889 | Z14: 광고선전비의 경우, 해외 수출 확대와 함께 증가할 것으로 예상. 매출액 연동
B15: 지급수수료 | C15: 949.162 | D15: 1007.9808 | E15: 1128.655 | F15: 3590.6121 | G15: 1768.3492 | H15: 1043.257 | I15: 1980.7434 | J15: 2706.989 | K15: 1694.518 | L15: 3164.735 | M15: 2169.672 | N15: 3366.532 | O15: =O$6*(AVERAGE($U15:$W15)) -> 3532.4891 | P15: =P6*(AVERAGE($U15:$W15)) -> 3614.5287 | Q15: =Q6*(AVERAGE($U15:$W15)) -> 4009.705 | R15: =R6*(AVERAGE($U15:$W15)) -> 4425.2183 | T15: 지급수수료 | U15: =SUM(C15:F15)/SUM('매출액 추정'!$C$6:$F$6) -> 0.047082289 | V15: =SUM(G15:J15)/SUM('매출액 추정'!$G$6:$J$6) -> 0.041634773 | W15: =SUM(K15:N15)/SUM('매출액 추정'!$K$6:$N$6) -> 0.0427904 | X15: =SUM(O15:R15)/SUM($O$6:$R$6) -> 0.043835821 | Z15: 지급수수료의 경우, 상대방에게 용역 서비스를 제공받고 지급하는 비용이기에 변동비적 성격을 지님. of sales(%)를 3Y Average Flat하게 적용.
B16: 판매수수료 | C16: 1687.354 | D16: 1004.6254 | E16: 487.68333 | F16: 646.59672 | G16: 578.01816 | H16: 748.22562 | I16: 1013.4578 | J16: 855.827 | K16: 800.017 | L16: 1167.424 | M16: 841.407 | N16: 614.918 | O16: =O$6*(AVERAGE($U16:$W16)) -> 1579.912 | P16: =P$6*(AVERAGE($U16:$W16)) -> 1616.6044 | Q16: =Q$6*(AVERAGE($U16:$W16)) -> 1793.3476 | R16: =R$6*(AVERAGE($U16:$W16)) -> 1979.1867 | T16: 판매수수료 | U16: =SUM(C16:F16)/SUM('매출액 추정'!$C$6:$F$6) -> 0.026982923 | V16: =SUM(G16:J16)/SUM('매출액 추정'!$G$6:$J$6) -> 0.017740912 | W16: =SUM(K16:N16)/SUM('매출액 추정'!$K$6:$N$6) -> 0.01409311 | X16: =SUM(O16:R16)/SUM($O$6:$R$6) -> 0.019605649 | Z16: 판매수수료의 경우, 지급수수료와 유사하게 of sales(%)를 3Y Average Flat으로 적용
B17: 감가상각비 | C17: 372.006 | D17: 375.74756 | E17: 279.53081 | F17: 402.86608 | G17: 437.11959 | H17: 469.51039 | I17: 517.76484 | J17: 548.078 | K17: 572.452 | L17: 586.394 | M17: 602.235 | N17: 800.573 | O17: =O$6*(AVERAGE($U17:$W17)) -> 848.30443 | P17: =P$6*(AVERAGE($U17:$W17)) -> 868.00571 | Q17: =Q$6*(AVERAGE($U17:$W17)) -> 962.90473 | R17: =R$6*(AVERAGE($U17:$W17)) -> 1062.6876 | T17: 감가상각비 | U17: =SUM(C17:F17)/SUM('매출액 추정'!$C$6:$F$6) -> 0.010085474 | V17: =SUM(G17:J17)/SUM('매출액 추정'!$G$6:$J$6) -> 0.01095076 | W17: =SUM(K17:N17)/SUM('매출액 추정'!$K$6:$N$6) -> 0.010544433 | X17: =SUM(O17:R17)/SUM($O$6:$R$6) -> 0.010526889 | Z17: 감가상각비의 경우, CAPEX 투자 규모와 그에 따른 상각비를 알 수 없기에 of sales(%)를 3Y Average Flat하게 적용.
B18: 복리후생비 | C18: 454.866 | D18: 266.88399 | E18: 340.25054 | F18: 529.43001 | G18: 233.44265 | H18: 305.30156 | I18: 348.89246 | J18: 546.723 | K18: 278.994 | L18: 545.755 | M18: 438.022 | N18: 831.262 | O18: =O12*(AVERAGE($C18:$N18)/AVERAGE($C12:$N12)) -> 453.1429 | P18: =P12*(AVERAGE($C18:$N18)/AVERAGE($C12:$N12)) -> 472.21872 | Q18: =Q12*(AVERAGE($C18:$N18)/AVERAGE($C12:$N12)) -> 525.4475 | R18: =R12*(AVERAGE($C18:$N18)/AVERAGE($C12:$N12)) -> 607.23323 | T18: 복리후생비 | U18: =SUM(C18:F18)/SUM('매출액 추정'!$C$6:$F$6) -> 0.011222827 | V18: =SUM(G18:J18)/SUM('매출액 추정'!$G$6:$J$6) -> 0.0079632675 | W18: =SUM(K18:N18)/SUM('매출액 추정'!$K$6:$N$6) -> 0.0086195835 | X18: =SUM(O18:R18)/SUM($O$6:$R$6) -> 0.0057897778 | Z18: 복리후생비의 경우, 과거 3개년 급여 대비 복리후생비의 비중을 이용하여 추정.
B19: 판매보증비 | C19: 203.873 | D19: 232.85805 | E19: 281.3032 | F19: 441.71843 | G19: 64.267548 | H19: 318.97146 | I19: 294.51956 | J19: 368.287 | K19: 132.081 | L19: 332.43 | M19: 367.562 | N19: 51.542 | O19: =AVERAGE(C19:N19) -> 257.4511 | P19: =O19 -> 257.4511 | Q19: =P19 -> 257.4511 | R19: =Q19 -> 257.4511 | T19: 판매보증비 | U19: =SUM(C19:F19)/SUM('매출액 추정'!$C$6:$F$6) -> 0.0081786187 | V19: =SUM(G19:J19)/SUM('매출액 추정'!$G$6:$J$6) -> 0.0058074281 | W19: =SUM(K19:N19)/SUM('매출액 추정'!$K$6:$N$6) -> 0.0036371888 | X19: =SUM(O19:R19)/SUM($O$6:$R$6) -> 0.0028970923 | Z19: 판매보증비의 경우, 무상 보증 및 수비 서리스에 대한 비용을 판매되는 시점에 회계상 비용으로 인식하는 계정. of sales(%)가 감소하는 것을 확인하고 고정비라 판단. 이에 과거 3개년 판매보증비를 Average Flat하게 적용.
B20: 퇴직급여 | C20: 209.562 | D20: 142.01616 | E20: 197.85279 | F20: 238.0868 | G20: 150.03006 | H20: 232.56943 | I20: 181.35998 | J20: 183.42 | K20: 246.473 | L20: 202.922 | M20: 231.603 | N20: 240.495 | O20: =K20*(1.036) -> 255.34603 | P20: =L20*(1.036) -> 210.22719 | Q20: =M20*(1.036) -> 239.94071 | R20: =N20*(1.036) -> 249.15282 | T20: 퇴직급여 | U20: =SUM(C20:F20)/SUM('매출액 추정'!$C$6:$F$6) -> 0.0055536043 | V20: =SUM(G20:J20)/SUM('매출액 추정'!$G$6:$J$6) -> 0.0041492959 | W20: =SUM(K20:N20)/SUM('매출액 추정'!$K$6:$N$6) -> 0.0037931044 | X20: =SUM(O20:R20)/SUM($O$6:$R$6) -> 0.0026857116 | Z20: 퇴직급여의 경우, 급여 상승분을 적용하여 추정.
B21: 주식보상비용 | C21: - | D21: - | E21: - | F21: - | G21: 11.087277 | H21: 505.73929 | I21: 505.94601 | J21: 505.946 | K21: 420.395 | L21: 366.752 | M21: 570.868 | N21: 600.095 | O21: =AVERAGE(G21:N21) -> 435.85357 | P21: =O21 -> 435.85357 | Q21: =P21 -> 435.85357 | R21: =Q21 -> 435.85357 | T21: 주식보상비용 | U21: =SUM(C21:F21)/SUM('매출액 추정'!$C$6:$F$6) -> 0 | V21: =SUM(G21:J21)/SUM('매출액 추정'!$G$6:$J$6) -> 0.0084871286 | W21: =SUM(K21:N21)/SUM('매출액 추정'!$K$6:$N$6) -> 0.0080600892 | X21: =SUM(O21:R21)/SUM($O$6:$R$6) -> 0.0049046518 | Z21: 주식보상비용의 대표적인 예로는 스톡옵션, 추정이 불가하기에 과거 2개년 Average Flat 적용.
B22: 여비교통비 | C22: 27.038 | D22: 83.06734 | E22: 21.423727 | F22: 181.33515 | G22: 297.81258 | H22: 205.48039 | I22: 329.74875 | J22: 178.56 | K22: 360.69 | L22: 297.809 | M22: 201.619 | N22: 371.605 | O22: =N22*(1+(O$6/N$6-1)) -> 402.4786 | P22: =O22*(1+(P$6/O$6-1)) -> 411.82588 | Q22: =P22*(1+(Q$6/P$6-1)) -> 456.85079 | R22: =Q22*(1+(R$6/Q$6-1)) -> 504.19282 | T22: 여비교통비 | U22: =SUM(C22:F22)/SUM('매출액 추정'!$C$6:$F$6) -> 0.00220633 | V22: =SUM(G22:J22)/SUM('매출액 추정'!$G$6:$J$6) -> 0.005616203 | W22: =SUM(K22:N22)/SUM('매출액 추정'!$K$6:$N$6) -> 0.0050700917 | X22: =SUM(O22:R22)/SUM($O$6:$R$6) -> 0.0049944895 | Z22: 여비교통비의 경우, 23년 이후 증가세에 있음. 증가세 반영하기 위해 매출액 연동.
B23: 접대비 | C23: 0.791 | D23: 15.033637 | E23: 12.58849 | F23: 30.456055 | G23: 57.180141 | H23: 36.38579 | I23: 40.064523 | J23: 46.426 | K23: 49.115 | L23: 61.862 | M23: 46.462 | N23: 79.42 | O23: =N23*(1+(O$6/N$6-1)) -> 86.018354 | P23: =O23*(1+(P$6/O$6-1)) -> 88.01607 | Q23: =P23*(1+(Q$6/P$6-1)) -> 97.638862 | R23: =Q23*(1+(R$6/Q$6-1)) -> 107.75688 | T23: 접대비 | U23: =SUM(C23:F23)/SUM('매출액 추정'!$C$6:$F$6) -> 0.00041514765 | V23: =SUM(G23:J23)/SUM('매출액 추정'!$G$6:$J$6) -> 0.0009996361 | W23: =SUM(K23:N23)/SUM('매출액 추정'!$K$6:$N$6) -> 0.00097497314 | X23: =SUM(O23:R23)/SUM($O$6:$R$6) -> 0.0010674301 | Z23: 접대비 또한, 23년 이후 증가세에 있음. 증가세 반영하기 위해 매출액 연동
B24: 통신비 | C24: 8.457 | D24: 7.177509 | E24: 8.819771 | F24: 12.125935 | G24: 14.199509 | H24: 11.701801 | I24: 9.973207 | J24: 19.741 | K24: 12.244 | L24: 13.321 | M24: 12.759 | N24: 20.369 | O24: =O$6*(AVERAGE($U24:$W24)) -> 21.71287 | P24: =P$6*(AVERAGE($U24:$W24)) -> 22.217137 | Q24: =Q$6*(AVERAGE($U24:$W24)) -> 24.646135 | R24: =R$6*(AVERAGE($U24:$W24)) -> 27.200138 | T24: 통신비 | U24: =SUM(C24:F24)/SUM('매출액 추정'!$C$6:$F$6) -> 0.00025796503 | V24: =SUM(G24:J24)/SUM('매출액 추정'!$G$6:$J$6) -> 0.00030876582 | W24: =SUM(K24:N24)/SUM('매출액 추정'!$K$6:$N$6) -> 0.00024159563 | X24: =SUM(O24:R24)/SUM($O$6:$R$6) -> 0.00026944216 | Z24: 통신비의 경우, 금액적 유의성이 낮고 of sales(%)가 일정한 것을 이용하여 of sales(%)를 3Y Average Flat하게 적용.
B25: 수도광열비 | C25: 35.083 | D25: 33.5948 | E25: 44.243822 | F25: 21.433001 | G25: 50.38956 | H25: 25.129489 | I25: 41.697079 | J25: 32.992 | K25: 56.122 | L25: 31.164 | M25: 54.83 | N25: 40.246 | O25: =O$6*(AVERAGE($U25:$W25)) -> 68.014621 | P25: =P$6*(AVERAGE($U25:$W25)) -> 69.594213 | Q25: =Q$6*(AVERAGE($U25:$W25)) -> 77.202945 | R25: =R$6*(AVERAGE($U25:$W25)) -> 85.203248 | T25: 수도광열비 | U25: =SUM(C25:F25)/SUM('매출액 추정'!$C$6:$F$6) -> 0.00094747377 | V25: =SUM(G25:J25)/SUM('매출액 추정'!$G$6:$J$6) -> 0.00083392438 | W25: =SUM(K25:N25)/SUM('매출액 추정'!$K$6:$N$6) -> 0.00075064934 | X25: =SUM(O25:R25)/SUM($O$6:$R$6) -> 0.00084401583 | Z25: 수도광열비 또한 금액적 유의성이 낮고 of sales(%)가 일정한 것을 이용하여 of sales(%)를 3Y Average Flat하게 적용.
B26: 세금과공과금 | C26: 56.388 | D26: 14.398234 | E26: 173.238 | F26: 130.98468 | G26: 120.27808 | H26: 20.276854 | I26: 146.90984 | J26: 130.556 | K26: 153.551 | L26: 20.03 | M26: 196.536 | N26: 165.5 | O26: =O$6*(AVERAGE($U26:$W26)) -> 192.59918 | P26: =P$6*(AVERAGE($U26:$W26)) -> 197.07216 | Q26: =Q$6*(AVERAGE($U26:$W26)) -> 218.61805 | R26: =R$6*(AVERAGE($U26:$W26)) -> 241.27277 | T26: 세금과공과금 | U26: =SUM(C26:F26)/SUM('매출액 추정'!$C$6:$F$6) -> 0.0026445767 | V26: =SUM(G26:J26)/SUM('매출액 추정'!$G$6:$J$6) -> 0.0023207646 | W26: =SUM(K26:N26)/SUM('매출액 추정'!$K$6:$N$6) -> 0.0022047386 | X26: =SUM(O26:R26)/SUM($O$6:$R$6) -> 0.0023900267 | Z26: 세금과공과금의 경우, of sales(%)를 3Y Average Flat 적용.
B27: 지급임차료 | C27: 1.422 | D27: 1.4286 | E27: 1.4658 | F27: 1.4307 | G27: 3.39635 | H27: 5.40565 | I27: 2.712442 | J27: 1.037 | K27: 3.088 | L27: 3.499 | M27: 5.337 | N27: 21.762 | O27: =AVERAGE(C27:M27) -> 2.7475038 | P27: =O27 -> 2.7475038 | Q27: =P27 -> 2.7475038 | R27: =Q27 -> 2.7475038 | T27: 지급임차료 | U27: =SUM(C27:F27)/SUM('매출액 추정'!$C$6:$F$6) -> 4.0528762e-05 | V27: =SUM(G27:J27)/SUM('매출액 추정'!$G$6:$J$6) -> 6.9683004e-05 | W27: =SUM(K27:N27)/SUM('매출액 추정'!$K$6:$N$6) -> 0.00013866032 | X27: =SUM(O27:R27)/SUM($O$6:$R$6) -> 3.0917608e-05 | Z27: 지급임차료의 경우, 4Q24를 제외하고 고정비적 성격을 지님, 이에 4Q24 제외한 3Y Average Flat 적용
B28: 수선비 | C28: 4.804 | D28: 4.572074 | E28: 0.405 | F28: 59.746849 | G28: 18.80726 | H28: 17.956078 | I28: 11.445129 | J28: 4.679 | K28: 4.37 | L28: 2.863 | M28: 23.274 | N28: 59.781 | O28: =O$6*(AVERAGE($U28:$W28)) -> 31.040694 | P28: =P$6*(AVERAGE($U28:$W28)) -> 31.761593 | Q28: =Q$6*(AVERAGE($U28:$W28)) -> 35.234086 | R28: =R$6*(AVERAGE($U28:$W28)) -> 38.885285 | T28: 수선비 | U28: =SUM(C28:F28)/SUM('매출액 추정'!$C$6:$F$6) -> 0.00049031348 | V28: =SUM(G28:J28)/SUM('매출액 추정'!$G$6:$J$6) -> 0.00029362025 | W28: =SUM(K28:N28)/SUM('매출액 추정'!$K$6:$N$6) -> 0.00037164885 | X28: =SUM(O28:R28)/SUM($O$6:$R$6) -> 0.0003851942 | Z28: 수선비의 경우, of sales(%)를 3Y Average Flat 적용.
B29: 보험료 | C29: 9.639 | D29: 16.886823 | E29: 20.170973 | F29: 44.28228 | G29: 19.556208 | H29: 13.572042 | I29: 15.336374 | J29: 19.056 | K29: 17.312 | L29: 16.168 | M29: 16.893 | N29: 22.999 | O29: =AVERAGE(C29:N29) -> 19.322642 | P29: =O29 -> 19.322642 | Q29: =P29 -> 19.322642 | R29: =Q29 -> 19.322642 | T29: 보험료 | U29: =SUM(C29:F29)/SUM('매출액 추정'!$C$6:$F$6) -> 0.00064158781 | V29: =SUM(G29:J29)/SUM('매출액 추정'!$G$6:$J$6) -> 0.00037486051 | W29: =SUM(K29:N29)/SUM('매출액 추정'!$K$6:$N$6) -> 0.0003020182 | X29: =SUM(O29:R29)/SUM($O$6:$R$6) -> 0.00021743731 | Z29: 보험료의 경우, 지속적으로 하락하는 경향을 가짐. 고정비라 판단한 후 3Y Average Flat 적용.
B30: 차량유지비 | C30: 44.571 | D30: 53.847982 | E30: 44.451177 | F30: 51.430019 | G30: 44.444368 | H30: 50.81905 | I30: 53.849183 | J30: 56.368 | K30: 55.029 | L30: 64.144 | M30: 58.103 | N30: 78.839 | O30: =AVERAGE(C30:M30) -> 52.459707 | P30: =O30 -> 52.459707 | Q30: =P30 -> 52.459707 | R30: =Q30 -> 52.459707 | T30: 차량유지비 | U30: =SUM(C30:F30)/SUM('매출액 추정'!$C$6:$F$6) -> 0.001370212 | V30: =SUM(G30:J30)/SUM('매출액 추정'!$G$6:$J$6) -> 0.0011407857 | W30: =SUM(K30:N30)/SUM('매출액 추정'!$K$6:$N$6) -> 0.0010542358 | X30: =SUM(O30:R30)/SUM($O$6:$R$6) -> 0.00059032807 | Z30: 차량유지비의 경우, 4Q24를 제외하고 고정비적 성격을 지님. 이에 4Q24 제외한 3Y Average Flat 적용
B31: 운반비 | C31: 73.371 | D31: 91.085303 | E31: 80.111605 | F31: 153.96195 | G31: 131.2097 | H31: 131.01561 | I31: 79.050153 | J31: 66.116 | K31: 74.62 | L31: 77.12 | M31: 111.517 | N31: 143.761 | O31: =N31*(1+(O$6/N$6-1)) -> 155.70492 | P31: =O31*(1+(P$6/O$6-1)) -> 159.32106 | Q31: =P31*(1+(Q$6/P$6-1)) -> 176.73962 | R31: =Q31*(1+(R$6/Q$6-1)) -> 195.0546 | T31: 운반비 | U31: =SUM(C31:F31)/SUM('매출액 추정'!$C$6:$F$6) -> 0.0028104473 | V31: =SUM(G31:J31)/SUM('매출액 추정'!$G$6:$J$6) -> 0.0022617529 | W31: =SUM(K31:N31)/SUM('매출액 추정'!$K$6:$N$6) -> 0.0016753918 | X31: =SUM(O31:R31)/SUM($O$6:$R$6) -> 0.0019321936 | Z31: 운반비의 경우, 제품 판매가 늘어날수록 늘어날 것으로 예상되는 계정이기에 매출액과 연동.
B32: 교육훈련비 | C32: 0.945 | D32: 2.242995 | E32: 0.969 | F32: 0.518 | G32: 1.471 | H32: 4.65 | I32: 6.124335 | J32: 3.561 | K32: 7.955 | L32: 24.12 | M32: 1.441 | N32: 8.459 | O32: =AVERAGE(C32:K32,M32:N32) -> 3.4851209 | P32: =O32 -> 3.4851209 | Q32: =P32 -> 3.4851209 | R32: =Q32 -> 3.4851209 | T32: 교육훈련비 | U32: =SUM(C32:F32)/SUM('매출액 추정'!$C$6:$F$6) -> 3.2968238e-05 | V32: =SUM(G32:J32)/SUM('매출액 추정'!$G$6:$J$6) -> 8.7753495e-05 | W32: =SUM(K32:N32)/SUM('매출액 추정'!$K$6:$N$6) -> 0.00017278 | X32: =SUM(O32:R32)/SUM($O$6:$R$6) -> 3.9217998e-05 | Z32: 교육훈련비의 경우, 금액적 유의성이 낮고 2Q24 특이값을 제외하면 고정비적 성격을 지니는 것으로 파악됨. 이에 2Q24제외하여 3Y Average Flat
B33: 도서인쇄비 | C33: 129.95 | D33: 25.52452 | E33: 49.280889 | F33: 65.498146 | G33: 64.94883 | H33: 58.761779 | I33: 19.258518 | J33: 86.635 | K33: 96.108 | L33: 50.777 | M33: 144.327 | N33: 141.717 | O33: =O$6*(AVERAGE($U33:$W33)) -> 133.30295 | P33: =P$6*(AVERAGE($U33:$W33)) -> 136.39882 | Q33: =Q$6*(AVERAGE($U33:$W33)) -> 151.3113 | R33: =R$6*(AVERAGE($U33:$W33)) -> 166.99122 | T33: 도서인쇄비 | U33: =SUM(C33:F33)/SUM('매출액 추정'!$C$6:$F$6) -> 0.0019058381 | V33: =SUM(G33:J33)/SUM('매출액 추정'!$G$6:$J$6) -> 0.0012747145 | W33: =SUM(K33:N33)/SUM('매출액 추정'!$K$6:$N$6) -> 0.0017820482 | X33: =SUM(O33:R33)/SUM($O$6:$R$6) -> 0.0016542002 | Z33: 도서인쇄비의 경우, of sales(%)를 3Y Average Flat 적용
B34: 사무용품비 | C34: 4.576 | D34: 3.36409 | E34: 4.331566 | F34: 10.280646 | G34: 5.484949 | H34: 3.45338 | I34: 6.524536 | J34: 3.936 | K34: 5.001 | L34: 4.627 | M34: 4.072 | N34: 4.943 | O34: =AVERAGE(C34:N34) -> 5.0495139 | P34: =O34 -> 5.0495139 | Q34: =P34 -> 5.0495139 | R34: =Q34 -> 5.0495139 | T34: 사무용품비 | U34: =SUM(C34:F34)/SUM('매출액 추정'!$C$6:$F$6) -> 0.00015903967 | V34: =SUM(G34:J34)/SUM('매출액 추정'!$G$6:$J$6) -> 0.00010769848 | W34: =SUM(K34:N34)/SUM('매출액 추정'!$K$6:$N$6) -> 7.6739428e-05 | X34: =SUM(O34:R34)/SUM($O$6:$R$6) -> 5.6822083e-05 | Z34: 사무용품비의 경우, 금액적 유의성이 낮음. 3Y Average Flat 적용
B35: 소모품비 | C35: 44.045 | D35: 37.768633 | E35: 37.536 | F35: 25.192686 | G35: 15.141788 | H35: 66.614672 | I35: 26.903271 | J35: 29.285 | K35: 58.144 | L35: 47.667 | M35: 54.434 | N35: 34.818 | O35: =O$6*(AVERAGE($U35:$W35)) -> 69.519961 | P35: =P$6*(AVERAGE($U35:$W35)) -> 71.134514 | Q35: =Q$6*(AVERAGE($U35:$W35)) -> 78.911647 | R35: =R$6*(AVERAGE($U35:$W35)) -> 87.089017 | T35: 소모품비 | U35: =SUM(C35:F35)/SUM('매출액 추정'!$C$6:$F$6) -> 0.0010193178 | V35: =SUM(G35:J35)/SUM('매출액 추정'!$G$6:$J$6) -> 0.00076584055 | W35: =SUM(K35:N35)/SUM('매출액 추정'!$K$6:$N$6) -> 0.00080292995 | X35: =SUM(O35:R35)/SUM($O$6:$R$6) -> 0.00086269609 | Z35: 소모품비의 경우, of sales(%)를 3Y Average Flay 적용
B36: 판매촉진비 | C36: 31.414 | D36: 14.068715 | E36: 11.994956 | F36: 116.45084 | G36: 4.917 | H36: 0.061 | I36: 0.067 | J36: 185.621 | K36: 0.756 | L36: 2.604 | M36: 2.181 | N36: 16.705 | O36: =AVERAGE(G36:N36) -> 26.614 | P36: =AVERAGE(H36:O36) -> 29.326125 | Q36: =AVERAGE(I36:P36) -> 32.984266 | R36: =AVERAGE(J36:Q36) -> 37.098924 | T36: 판매촉진비 | U36: =SUM(C36:F36)/SUM('매출액 추정'!$C$6:$F$6) -> 0.0012265503 | V36: =SUM(G36:J36)/SUM('매출액 추정'!$G$6:$J$6) -> 0.0010585381 | W36: =SUM(K36:N36)/SUM('매출액 추정'!$K$6:$N$6) -> 9.1570312e-05 | X36: =SUM(O36:R36)/SUM($O$6:$R$6) -> 0.00035453448 | Z36: 판매촉진비의 경우 판매실적 등에 따라 장려금을 지급하는 비용. 분기별 편차가 크고 연도별 편차도 큰 것을 확인. 이에 과거 8개 분기 이동평균 적용.
B37: 대손상각비 | C37: 33.86 | D37: -37.278755 | E37: 60.165 | F37: -37.021383 | G37: 98.425215 | H37: 55.146087 | I37: 114.90418 | J37: 181.214 | K37: -21.588 | L37: 399.49 | M37: -231.911 | N37: -109.558 | O37: =AVERAGE(G37:N37) -> 60.76531 | P37: =AVERAGE(H37:O37) -> 56.057822 | Q37: =AVERAGE(I37:P37) -> 56.171789 | R37: =AVERAGE(J37:Q37) -> 48.83024 | T37: 대손상각비 | U37: =SUM(C37:F37)/SUM('매출액 추정'!$C$6:$F$6) -> 0.00013910046 | V37: =SUM(G37:J37)/SUM('매출액 추정'!$G$6:$J$6) -> 0.0024965828 | W37: =SUM(K37:N37)/SUM('매출액 추정'!$K$6:$N$6) -> 0.00014996769 | X37: =SUM(O37:R37)/SUM($O$6:$R$6) -> 0.00062404857 | Z37: 대손상각비의 경우, 대손충당금의 환입이 이뤄질 경우 (-)의 값으로 나타나는 것으로 확인. 이에 과거 8개 분기 이동평균 사용.
B38: 수출제비용 | C38: 57.458 | D38: 33.599286 | E38: 93.052617 | F38: 45.360547 | G38: 52.9771 | H38: 52.276433 | I38: 67.488317 | J38: 36.13 | K38: 33.728 | L38: 51.594 | M38: 38.889 | N38: 69.262 | O38: =N38*(의료기기!O10/의료기기!N10) -> 124.47721 | P38: =O38*(의료기기!P10/의료기기!O10) -> 127.93491 | Q38: =P38*(의료기기!Q10/의료기기!P10) -> 131.39261 | R38: =Q38*(의료기기!R10/의료기기!Q10) -> 134.85031 | T38: 수출제비용 | U38: =SUM(C38:F38)/SUM('매출액 추정'!$C$6:$F$6) -> 0.0016182341 | V38: =SUM(G38:J38)/SUM('매출액 추정'!$G$6:$J$6) -> 0.0011596132 | W38: =SUM(K38:N38)/SUM('매출액 추정'!$K$6:$N$6) -> 0.0007963851 | X38: =SUM(O38:R38)/SUM($O$6:$R$6) -> 0.0014591038 | Z38: 수출제비용의 경우 상품 및 제품의 수출과정에서 발생하는 비용. 동사의 수출 매출 성장률을 적용하여 추정.
B39: 무형고정자산상각비 | C39: 35.301 | D39: 37.984363 | E39: 42.474 | F39: 47.204268 | G39: 55.694633 | H39: 60.048096 | I39: 62.690651 | J39: 73.491 | K39: 77.32 | L39: 77.891 | M39: 85.728 | N39: 1925.538 | O39: =N39*(1+(O$6/N$6-1)) -> 2085.5151 | P39: =O39*(1+(P$6/O$6-1)) -> 2133.9497 | Q39: =P39*(1+(Q$6/P$6-1)) -> 2367.2543 | R39: =Q39*(1+(R$6/Q$6-1)) -> 2612.5656 | T39: 무형고정자산상각비 | U39: =SUM(C39:F39)/SUM('매출액 추정'!$C$6:$F$6) -> 0.0011492256 | V39: =SUM(G39:J39)/SUM('매출액 추정'!$G$6:$J$6) -> 0.0013986319 | W39: =SUM(K39:N39)/SUM('매출액 추정'!$K$6:$N$6) -> 0.0089177818 | X39: =SUM(O39:R39)/SUM($O$6:$R$6) -> 0.025879844 | Z39: 무형고정자산상각비의 경우 특이값인 4Q24를 제외하고 지속적으로 상승하고 있는 것을 확인. 추세를 반영하기 위해 매출액 연동.
