Workbook
Name _MOD1: #REF!
Name _MOD1: #REF!
Name _MOD1: #REF!
Name _MOD1: #REF!
Name \a: #N/A
Name \b: #N/A
Name \I: #REF!
Name \I: #REF!
Name \I: #REF!
Name \I: #REF!
Name \P: #REF!
Name \P: #REF!
Name A_K___s__Global__I_T: #REF!
Name A_K___s__Global__I_T: #REF!
Name Acc_payable_growth_fore: #REF!
Name Acc_payable_growth_fore: #REF!
Name Acc_Rec_growth_fore: #REF!
Name Acc_Rec_growth_fore: #REF!
Name Accrued_compensation_growth_fore: #REF!
Name Accrued_compensation_growth_fore: #REF!
Name Accrued_expenses_growth_fore: #REF!
Name Accrued_expenses_growth_fore: #REF!
Name Accum_Cap_Expenses_growth_fore: #REF!
Name Accum_Cap_Expenses_growth_fore: #REF!
Name Accum_Goodwill_Amort_growth_fore: #REF!
Name Accum_Goodwill_Amort_growth_fore: #REF!
Name Adj_net_oper_fore: #REF!
Name Adj_net_oper_fore: #REF!
Name AveSize: #REF!
Name AveSize: #REF!
Name BS_C: #REF!
Name BS_C: #REF!
Name Case_Offset: #REF!
Name Case_Offset: #REF!
Name Case_Offset: #REF!
Name Case_Offset: #REF!
Name Cash_fore: #REF!
Name Cash_fore: #REF!
Name Cash_growth_fore: #REF!
Name Cash_growth_fore: #REF!
Name Cash_operating_taxes_fore: #REF!
Name Cash_operating_taxes_fore: #REF!
Name CDS: #REF!
Name CDS: #REF!
Name CE_C: #REF!
Name CE_C: #REF!
Name CF_C: #REF!
Name CF_C: #REF!
Name CFormats: #REF!
Name CFormats: #REF!
Name codeDestination: #REF!
Name codeDestination: #REF!
Name CODELK_Path: #REF!
Name CODELK_Path: #REF!
Name ColumnHeading: #REF!
Name ColumnHeading: #REF!
Name Com_Data_sum_035900: '요약 재무제표'!$B$5
Name Comdty: #REF!
Name Comdty: #REF!
Name Corp: #REF!

Sheet Estimate Logic - HRSG
B1: Estimation
B2: Estimate Logic - HRSG
B5: (단위: 백만 원) | C5: 2025 | D5: 2026 | E5: 2027 | F5: 2028
B6: HRSG | C6: 377429.13 | D6: 733774.78 | E6: 753165.03 | F6: 794672.44 | H6: HRSG 사업부 매출은 기존 공시 수주와 신규 수주로 나누어 추정하였다.
B7: YoY % | C7: 0.45717656 | D7: 0.94413923 | E7: 0.026425352 | F7: 0.055110636 | H7: 신규 수주의 경우 국내외 해외 주요 시장 (중동, 미국, 일본)으로 구분하고, 수주 가능성에 따라 Bull/Base/Bear 세 가지 케이스로 분류했다.
B8: 국내 | C8: 121883.49 | D8: 143683.12 | E8: 137753.31 | F8: 72697.732
B9: 해외 | C9: 255545.64 | D9: 590091.65 | E9: 615411.72 | F9: 721974.7
B10: 중동 | C10: 204714.19 | D10: 480874.94 | E10: 444139.64 | F10: 513181.5
B11: 일본 | C11: 35999.228 | D11: 109216.71 | E11: 136552.5 | F11: 113425.37
B12: 미국 | C12: 0 | D12: 0 | E12: 34719.574 | F12: 95367.834
B13: 기타 | C13: 14832.22 | D13: 0 | E13: 0 | F13: 0
B15: 기존수주 매출 (추정) | C15: 2025 | D15: 2026 | E15: 2027 | F15: 2028
B16: 국내 | C16: 121883.49 | D16: 130988.42 | E16: 79532.855 | F16: 10609.75 | H16: 기존 수주는 공시된 수주 계약을 대상으로, 유사한 계약의 진행율을 반영하여 분기별로 분배하였다.
B17: 중동 | C17: 251483.67 | D17: 561196.44 | E17: 140217.35 | F17: 0
B18: 일본 | C18: 35999.228 | D18: 104798.67 | E18: 119343.66 | F18: 79288.997
B19: 기타 | C19: 14832.22 | D19: 0 | E19: 0 | F19: 0

Sheet Estimate Logic - BOP

Sheet Estimate Logic - 비용

Sheet Valuation ▶
A3: 비에이치아이(083650.KQ)
A5: Valuation Sheets >>>

Sheet EVEBITDA
B1: 비에이치아이(083650.KQ)
B2: EV/EBITDA Valuation Sheet
B3: (In KRW millions)
B5: EV/EBITDA Valuation Table | G5: EV/EBITDA Valuation Table
B6: 26F EBITDA (Bull) | C6: =M42 -> 1115.0315 | D6: (억원) | G6: 26F EBITDA (Base) | H6: =M43 -> 1074.9139 | I6: (억원)
B7: Target EV/EBITDA | C7: =$P$44 -> 18.5745 | D7: (배) | G7: Target EV/EBITDA | H7: =$P$44 -> 18.5745 | I7: (배)
B8: EV | C8: =C6*C7 -> 20711.152 | D8: (억원) | E8: (A) | G8: EV | H8: =H6*H7 -> 19965.988 | I8: (억원) | J8: (A)
B9: 비영업가치 | C9: =#REF! -> #REF! | D9: (억원) | E9: (B) | G9: 비영업가치 | H9: =#REF! -> #REF! | I9: (억원) | J9: (B)
B10: 순차입금 | C10: =$M$45 -> 819.46968 | D10: (억원) | E10: (C) | G10: 순차입금 | H10: =$M$45 -> 819.46968 | I10: (억원) | J10: (C)
B11: 주주가치 | C11: =C8+C9-C10 -> #REF! | D11: (억원) | E11: (A)+(B)-(C)-(D) | G11: 주주가치 | H11: =H8+H9-H10 -> #REF! | I11: (억원) | J11: (A)+(B)-(C)-(D)
B12: 발행주식수 | C12: =$P$48 -> 30944375 | G12: 발행주식수 | H12: =$P$48 -> 30944375
B13: Target Price | C13: =ROUND(C11*100000000/C12,-2) -> #REF! | G13: Target Price | H13: =ROUND(H11*100000000/H12,-2) -> #REF!
B14: Current Price | C14: =$P$49 -> 40300 | G14: Current Price | H14: =$P$49 -> 40300
B15: Upside | C15: =C13/C14-1 -> #REF! | G15: Upside | H15: =H13/H14-1 -> #REF!
B17: EV/EBITDA Valuation Table | G17: EV/EBITDA Valuation Table
B18: 27F EBITDA (Bull) | C18: =N42 -> 1265.8318 | D18: (억원) | G18: 27F EBITDA (Base) | H18: =N43 -> 1182.1407 | I18: (억원)
B19: Target EV/EBITDA | C19: =$P$44 -> 18.5745 | D19: (배) | G19: Target EV/EBITDA | H19: =$P$44 -> 18.5745 | I19: (배)
B20: EV | C20: =C18*C19 -> 23512.193 | D20: (억원) | E20: (A) | G20: EV | H20: =H18*H19 -> 21957.673 | I20: (억원) | J20: (A)
B21: 비영업가치 | C21: =#REF! -> #REF! | D21: (억원) | E21: (B) | G21: 비영업가치 | H21: =#REF! -> #REF! | I21: (억원) | J21: (B)
B22: 순차입금 | C22: =$N$45 -> 148.58324 | D22: (억원) | E22: (C) | G22: 순차입금 | H22: =$N$45 -> 148.58324 | I22: (억원) | J22: (C)
B23: 주주가치 | C23: =C20+C21-C22 -> #REF! | D23: (억원) | E23: (A)+(B)-(C)-(D) | G23: 주주가치 | H23: =H20+H21-H22 -> #REF! | I23: (억원) | J23: (A)+(B)-(C)-(D)
B24: 발행주식수 | C24: =$P$48 -> 30944375 | G24: 발행주식수 | H24: =$P$48 -> 30944375
B25: Target Price | C25: =ROUND(C23*100000000/C24,-2) -> #REF! | G25: Target Price | H25: =ROUND(H23*100000000/H24,-2) -> #REF!
B26: Current Price | C26: =$P$49 -> 40300 | G26: Current Price | H26: =$P$49 -> 40300
B27: Upside | C27: =C25/C26-1 -> #REF! | G27: Upside | H27: =H25/H26-1 -> #REF!
B29: EV/EBITDA Valuation Table | G29: EV/EBITDA Valuation Table
B30: 28F EBITDA (Bull) | C30: =O42 -> 1551.7574 | D30: (억원) | G30: 28F EBITDA (Base) | H30: =O43 -> 1149.2465 | I30: (억원)
B31: Target EV/EBITDA | C31: =$P$44 -> 18.5745 | D31: (배) | G31: Target EV/EBITDA | H31: =$P$44 -> 18.5745 | I31: (배)
B32: EV | C32: =C30*C31 -> 28823.118 | D32: (억원) | E32: (A) | G32: EV | H32: =H30*H31 -> 21346.68 | I32: (억원) | J32: (A)
B33: 비영업가치 | C33: =#REF! -> #REF! | D33: (억원) | E33: (B) | G33: 비영업가치 | H33: =#REF! -> #REF! | I33: (억원) | J33: (B)
B34: 순차입금 | C34: =$O$45 -> -104.86935 | D34: (억원) | E34: (C) | G34: 순차입금 | H34: =$O$45 -> -104.86935 | I34: (억원) | J34: (C)
B35: 주주가치 | C35: =C32+C33-C34 -> #REF! | D35: (억원) | E35: (A)+(B)-(C)-(D) | G35: 주주가치 | H35: =H32+H33-H34 -> #REF! | I35: (억원) | J35: (A)+(B)-(C)-(D)
B36: 발행주식수 | C36: =$P$48 -> 30944375 | G36: 발행주식수 | H36: =$P$48 -> 30944375
B37: Target Price | C37: =ROUND(C35*100000000/C36,-2) -> #REF! | G37: Target Price | H37: =ROUND(H35*100000000/H36,-2) -> #REF!
B38: Current Price | C38: =$P$49 -> 40300 | G38: Current Price | H38: =$P$49 -> 40300
B39: Upside | C39: =C37/C38-1 -> #REF! | G39: Upside | H39: =H37/H38-1 -> #REF!
S40: Peer Group Valuation Table
B41: EV/EBITDA Valuation Table | G41: EV/EBITDA Valuation Table | M41: 2026 | N41: 2027 | O41: 2028 | P41: Avg | Q41: 100 | S41: Ticker | T41: 기업명 | U41: Refinitiv | V41: Cap IQ | W41: 시가총액
B42: 27-28F avg. EBITDA (Bull) | C42: =P42 -> 1408.7946 | D42: (억원) | G42: 27-28F avg. EBITDA (Base) | H42: =P43 -> 1165.6936 | I42: (억원) | L42: EBITDA - Bull Case | M42: 1115.0315 | N42: 1265.8318 | O42: 1551.7574 | P42: =AVERAGE(N42:O42) -> 1408.7946 | S42: GEV | T42: GE Vernova | U42: 36.91 | V42: 38.75
B43: Target EV/EBITDA | C43: =$P$44 -> 18.5745 | D43: (배) | G43: Target EV/EBITDA | H43: =$P$44 -> 18.5745 | I43: (배) | L43: EBITDA - Base Case | M43: 1074.9139 | N43: 1182.1407 | O43: 1149.2465 | P43: =AVERAGE(N43:O43) -> 1165.6936 | S43: 7011 | T43: Mitsubishi Heavy Industry | U43: 19.2 | V43: 21.02 | W43: 81211.93 | X43: 12121184
...

Sheet Estimate ▶
A2: ='Valuation ▶'!A3 -> 비에이치아이(083650.KQ)
A4: Estimate Sheets (추정재무제표 작성) >>>

Sheet Expected IS
B1: Estimation
B2: Expected IS
B5: 계정명 | C5: 단위 | D5: 202112 | E5: 202212 | F5: 202312 | G5: 202412 | H5: 202512 | I5: 202612 | J5: 202712 | K5: 202812
D6: IFRS(연결) | E6: IFRS(연결) | F6: IFRS(연결) | G6: IFRS(연결) | H6: IFRS(연결) | I6: IFRS(연결) | J6: IFRS(연결) | K6: IFRS(연결)
B7: 매출액(수익)(*) | C7: 백만원 | D7: 234883.72 | E7: 330197.11 | F7: 367399.21 | G7: 404741.04 | H7: ='Case Summary'!U9 -> 818060.13 | I7: ='Case Summary'!V9 -> 1055423.5 | J7: ='Case Summary'!W9 -> 1121745.8 | K7: ='Case Summary'!X9 -> 1225142.9
B8: 매출원가(*) | C8: 백만원 | D8: 241249.52 | E8: 295265.47 | F8: 323957.62 | G8: 345623.02 | H8: ='비용 세부항목 추정'!G7+'비용 세부항목 추정'!G38+'비용 세부항목 추정'!G49+'비용 세부항목 추정'!G61 -> 715009.6 | I8: ='비용 세부항목 추정'!H7+'비용 세부항목 추정'!H38+'비용 세부항목 추정'!H49+'비용 세부항목 추정'!H61 -> 895855.7 | J8: ='비용 세부항목 추정'!I7+'비용 세부항목 추정'!I38+'비용 세부항목 추정'!I49+'비용 세부항목 추정'!I61 -> 962321.77 | K8: ='비용 세부항목 추정'!J7+'비용 세부항목 추정'!J38+'비용 세부항목 추정'!J49+'비용 세부항목 추정'!J61 -> 1062888.4
B9: 매출원가율(%) | D9: =D8/D7 -> 1.0271019 | E9: =E8/E7 -> 0.89420974 | F9: =F8/F7 -> 0.88175917 | G9: =G8/G7 -> 0.85393619 | H9: =H8/H7 -> 0.87403062 | I9: =I8/I7 -> 0.84881161 | J9: =J8/J7 -> 0.85787861 | K9: =K8/K7 -> 0.86756283
B10: 매출총이익(손실) | C10: 백만원 | D10: -6365.8024 | E10: 34931.638 | F10: 43441.587 | G10: 59118.018 | H10: =H7-H8 -> 103050.53 | I10: =I7-I8 -> 159567.78 | J10: =J7-J8 -> 159424.08 | K10: =K7-K8 -> 162254.45
B11: 판매비와관리비(*) | C11: 백만원 | D11: 24245.078 | E11: 26823.584 | F11: 28354.888 | G11: 37190.759 | H11: =SUM(H12:H14) -> 39220.871 | I11: =SUM(I12:I14) -> 47346.999 | J11: =SUM(J12:J14) -> 52260.258 | K11: =SUM(K12:K14) -> 58465.989
B12: 인건비(*) | C12: 백만원 | D12: 13000.707 | E12: 13948.49 | F12: 14157.436 | G12: 17165.349 | H12: ='비용 세부항목 추정'!G74 -> 20255.34 | I12: ='비용 세부항목 추정'!H74 -> 23564.003 | J12: ='비용 세부항목 추정'!I74 -> 27131.2 | K12: ='비용 세부항목 추정'!J74 -> 31238.412
B13: 유무형자산상각비(*) | C13: 백만원 | D13: 1041.959 | E13: 1176.78 | F13: 1715.522 | G13: 1913.114 | H13: ='비용 세부항목 추정'!G75 -> 1913.114 | I13: ='비용 세부항목 추정'!H75 -> 1913.114 | J13: ='비용 세부항목 추정'!I75 -> 1913.114 | K13: ='비용 세부항목 추정'!J75 -> 1913.114
B14: 기타 | C14: 백만원 | D14: 21175 | E14: 31102 | F14: 16399 | G14: 13332 | H14: ='비용 세부항목 추정'!G76+'비용 세부항목 추정'!G78+'비용 세부항목 추정'!G79 -> 17052.417 | I14: ='비용 세부항목 추정'!H76+'비용 세부항목 추정'!H78+'비용 세부항목 추정'!H79 -> 21869.882 | J14: ='비용 세부항목 추정'!I76+'비용 세부항목 추정'!I78+'비용 세부항목 추정'!I79 -> 23215.944 | K14: ='비용 세부항목 추정'!J76+'비용 세부항목 추정'!J78+'비용 세부항목 추정'!J79 -> 25314.463
B15: 영업이익(손실) | C15: 백만원 | D15: -30610.88 | E15: 8108.0541 | F15: 15086.698 | G15: 21927.258 | H15: =H10-H11 -> 63829.657 | I15: =I10-I11 -> 112220.78 | J15: =J10-J11 -> 107163.82 | K15: =K10-K11 -> 103788.46
B16: 영업이익률(%) | D16: =D15/D7 -> -0.13032355 | E16: =E15/E7 -> 0.024555194 | F16: =F15/F7 -> 0.041063502 | G16: =G15/G7 -> 0.054176019 | H16: =H15/H7 -> 0.07802563 | I16: =I15/I7 -> 0.10632773 | J16: =J15/J7 -> 0.095533063 | K16: =K15/K7 -> 0.084715398
B17: EBITDA | E17: =E15+'비용 세부항목 추정'!D75+'비용 세부항목 추정'!D62 -> 18664.418 | F17: =F15+'비용 세부항목 추정'!E75+'비용 세부항목 추정'!E62 -> 25681.561 | G17: =G15+'비용 세부항목 추정'!F75+'비용 세부항목 추정'!F62 -> 27985.154 | H17: =H15+'비용 세부항목 추정'!G75+'비용 세부항목 추정'!G62 -> 75077.104 | I17: =I15+'비용 세부항목 추정'!H75+'비용 세부항목 추정'!H62 -> 123331.65 | J17: =J15+'비용 세부항목 추정'!I75+'비용 세부항목 추정'!I62 -> 118214.07 | K17: =K15+'비용 세부항목 추정'!J75+'비용 세부항목 추정'!J62 -> 114924.65
B18: EBITDA Margin(%) | E18: =E17/E7 -> 0.05652508 | F18: =F17/F7 -> 0.06990097 | G18: =G17/G7 -> 0.069143358 | H18: =H17/H7 -> 0.091774554 | I18: =I17/I7 -> 0.11685513 | J18: =J17/J7 -> 0.10538401 | K18: =K17/K7 -> 0.093805105
B19: 금융수익(*) | C19: 백만원 | D19: 7196.576 | E19: 8323.576 | F19: 10770.512 | G19: 18569.587 | H19: =SUM(H20:H22) -> 8406.7293 | I19: =SUM(I20:I22) -> 8406.7293 | J19: =SUM(J20:J22) -> 8406.7293 | K19: =SUM(K20:K22) -> 8406.7293
B20: 이자수익 | C20: 백만원 | D20: 141.376 | E20: 281.418 | F20: 958.346 | G20: 1352.583 | H20: ='비용 세부항목 추정'!G86 -> 864.11567 | I20: ='비용 세부항목 추정'!H86 -> 864.11567 | J20: ='비용 세부항목 추정'!I86 -> 864.11567 | K20: ='비용 세부항목 추정'!J86 -> 864.11567
B21: 외환이익(*) | C21: 백만원 | D21: 5857.794 | E21: 7309.414 | F21: 8337.759 | G21: 16104.774 | H21: ='비용 세부항목 추정'!G87 -> 7168.3223 | I21: ='비용 세부항목 추정'!H87 -> 7168.3223 | J21: ='비용 세부항목 추정'!I87 -> 7168.3223 | K21: ='비용 세부항목 추정'!J87 -> 7168.3223
B22: 파생상품이익(*) | C22: 백만원 | D22: 553.496 | E22: 2.7 | F22: 769.799 | G22: 350.375 | H22: ='비용 세부항목 추정'!G88 -> 374.29133 | I22: ='비용 세부항목 추정'!H88 -> 374.29133 | J22: ='비용 세부항목 추정'!I88 -> 374.29133 | K22: ='비용 세부항목 추정'!J88 -> 374.29133
B23: 금융원가(*) | C23: 백만원 | D23: 13853.979 | E23: 37272.428 | F23: 22758.852 | G23: 44883.533 | H23: =SUM(H24:H27) -> 36955.902 | I23: =SUM(I24:I27) -> 36955.902 | J23: =SUM(J24:J27) -> 36955.902 | K23: =SUM(K24:K27) -> 36955.902
B24: 이자비용 | C24: 백만원 | D24: 6922.606 | E24: 9204.768 | F24: 11546.804 | G24: 10416.514 | H24: ='비용 세부항목 추정'!G91 -> 10389.362 | I24: ='비용 세부항목 추정'!H91 -> 10389.362 | J24: ='비용 세부항목 추정'!I91 -> 10389.362 | K24: ='비용 세부항목 추정'!J91 -> 10389.362
B25: 외환손실(*) | C25: 백만원 | D25: 2956.485 | E25: 7109.659 | F25: 7083.603 | G25: 10073.078 | H25: ='비용 세부항목 추정'!G92 -> 10073.078 | I25: ='비용 세부항목 추정'!H92 -> 10073.078 | J25: ='비용 세부항목 추정'!I92 -> 10073.078 | K25: ='비용 세부항목 추정'!J92 -> 10073.078
B26: 파생상품손실(*) | C26: 백만원 | D26: 3914.981 | E26: 20942.7 | F26: 2631.475 | G26: 21948.104 | H26: ='비용 세부항목 추정'!G93 -> 15174.093 | I26: ='비용 세부항목 추정'!H93 -> 15174.093 | J26: ='비용 세부항목 추정'!I93 -> 15174.093 | K26: ='비용 세부항목 추정'!J93 -> 15174.093
B27: 기타금융원가(*) | C27: 백만원 | G27: 2412 | H27: ='비용 세부항목 추정'!G94 -> 1319.3693 | I27: ='비용 세부항목 추정'!H94 -> 1319.3693 | J27: ='비용 세부항목 추정'!I94 -> 1319.3693 | K27: ='비용 세부항목 추정'!J94 -> 1319.3693
B28: 금융손익 | D28: =D19-D23 -> -6657.403 | E28: =E19-E23 -> -28948.852 | F28: =F19-F23 -> -11988.34 | G28: =G19-G23 -> -26313.946 | H28: =H19-H23 -> -28549.173 | I28: =I19-I23 -> -28549.173 | J28: =J19-J23 -> -28549.173 | K28: =K19-K23 -> -28549.173
B29: 기타손익 | D29: 3506.399 | E29: 1286.204 | F29: 2118.717 | G29: 840.821 | H29: ='비용 세부항목 추정'!G95 -> 840.821 | I29: ='비용 세부항목 추정'!H95 -> 840.821 | J29: ='비용 세부항목 추정'!I95 -> 840.821 | K29: ='비용 세부항목 추정'!J95 -> 840.821
B30: 종속기업,공동지배기업및관계기업관련손익(*) | C30: 백만원 | D30: -722.69736 | E30: -1220.522 | F30: -1392.16 | G30: -399.343 | H30: ='비용 세부항목 추정'!G96 -> -399.343 | I30: ='비용 세부항목 추정'!H96 -> -399.343 | J30: ='비용 세부항목 추정'!I96 -> -399.343 | K30: ='비용 세부항목 추정'!J96 -> -399.343
B31: 법인세비용차감전계속사업이익 | C31: 백만원 | D31: -34484.581 | E31: -20775.115 | F31: 3824.9159 | G31: -3945.2096 | H31: =H15+H28+H29+H30 -> 35721.962 | I31: =I15+I28+I29+I30 -> 84113.084 | J31: =J15+J28+J29+J30 -> 79056.122 | K31: =K15+K28+K29+K30 -> 75680.77
B32: 법인세비용 | C32: 백만원 | D32: 102.52471 | E32: -1657.3597 | F32: -3638.8661 | G32: -23530.262 | H32: =H31*21% -> 7501.6119 | I32: =I31*21% -> 17663.748 | J32: =J31*21% -> 16601.786 | K32: =K31*21% -> 15892.962
B33: 유효법인세율 | D33: =D32/D31 -> -0.0029730594 | E33: =E32/E31 -> 0.079776194 | F33: =F32/F31 -> -0.95135847 | G33: =G32/G31 -> 5.9642616 | H33: =H32/H31 -> 0.21 | I33: =I32/I31 -> 0.21 | J33: =J32/J31 -> 0.21 | K33: =K32/K31 -> 0.21 | AE33: 1000
B34: 당기순이익(손실) | C34: 백만원 | D34: -34587.106 | E34: -19117.756 | F34: 7463.782 | G34: 19585.052 | H34: =H31-H32 -> 28220.35 | I34: =I31-I32 -> 66449.336 | J34: =J31-J32 -> 62454.336 | K34: =K31-K32 -> 59787.808
O36: 매출원가+판관비 | AG36: 2024 | AT36: 1000
B37: 계정명 | C37: 단위 | D37: 202112 | E37: 202212 | F37: 202312 | G37: 202412 | H37: 202512 | I37: 202612 | J37: 202712 | K37: 202812 | O37: 구 분 | P37: 2021 | Q37: 2022 | R37: 2023 | S37: 2024 | V37: 판관비 | X37: 계정명 | Y37: 단위 | Z37: 202012 | AA37: 202112 | AB37: 202212 | AC37: 202312 | AD37: 202412 | AG37: 사업부문 | AH37: 매입유형 | AI37: 품 목 | AJ37: 구체적용도 | AK37: 매입액 | AL37: 비율 | AQ37: 31065.084 | AR37: 33357.715 | AS37: 37304.193 | AT37: 43458.932
B38: 매출액(수익)(*) | C38: 백만원 | D38: 234883.72 | E38: 330197.11 | F38: 367399.21 | G38: 404741.04 | O38: 원재료 사용액 | P38: 118149580 | Q38: 107443312 | R38: 92510020 | S38: 106199675 | U38: 종업원급여 | V38: 직원급여 | X38: 매출액(수익)(*) | Z38: 243441.15 | AA38: 234883.72 | AB38: 330197.11 | AC38: 367399.21 | AD38: 404741.04 | AG38: 비에이치아이 | AH38: 원재료 | AI38: Tube | AJ38: 제품 제작에 | AK38: 44240 | AL38: 15.5
B39: 매출원가(*) | C39: 백만원 | D39: 241249.52 | E39: 295265.47 | F39: 323957.62 | G39: 345623.02 | O39: 종업원급여 | P39: 31065084 | Q39: 33357715 | R39: 37304193 | S39: 43458932 | V39: 퇴직급여 | X39: 매출원가(*) | Z39: 209367.57 | AA39: 241249.52 | AB39: 295265.47 | AC39: 323957.62 | AD39: 345623.02 | AI39: Plate | AJ39: 필요한 원재료 | AK39: 30388 | AL39: 10.6
B40: 원재료 사용액 | C40: 백만원 | D40: =P50 -> 118149580 | E40: =Q50 -> 107443312 | F40: =R50 -> 92510020 | G40: =S50 -> 106199675 | O40: 감가상각비 | P40: 8451273 | Q40: 8194515 | R40: 8384344 | S40: 4360717 | V40: 복리후생비 | X40: 원재료 사용액 | AA40: 118149.58 | AB40: 107443.31 | AC40: 92510.02 | AD40: 106199.68 | AI40: Pipe | AK40: 13429 | AL40: 4.7
B41: 외주가공비 | C41: 백만원 | D41: =P56 -> 68726184 | E41: =Q56 -> 124425012 | F41: =R56 -> 162700676 | G41: =S56 -> 169062007 | O41: 무형자산상각비 | P41: 2334760 | Q41: 2361849 | R41: 2210519 | S41: 1697179 | U41: 감가상각비 | V41: 감가상각비 | AA41: =AA40/AA38 -> 0.50301307 | AB41: =AB40/AB38 -> 0.32539144 | AC41: =AC40/AC38 -> 0.251797 | AD41: =AD40/AD38 -> 0.26238919 | AE41: =AVERAGE(AC41:AD41) -> 0.2570931 | AI41: Forging | AK41: 3162 | AL41: 1.1
B42: 종업원급여 | C42: 백만원 | D42: =P51 -> #REF! | E42: =Q51 -> #REF! | F42: =R51 -> #REF! | G42: =S51 -> #REF! | O42: 지급수수료 | P42: 9545010 | Q42: 13135121 | R42: 13777995 | S42: 19144745 | U42: 무형자산상각비 | V42: 무형자산상각비 | X42: 외주가공비 | AA42: 68726.184 | AB42: 124425.01 | AC42: 162700.68 | AD42: 169062.01 | AI42: 기타 | AK42: 7708 | AL42: 2.7
B43: 감가상각비 및 무형자산상각비 | C43: 백만원 | D43: =P52+P53 -> #REF! | E43: =Q52+Q53 -> #REF! | F43: =R52+R53 -> #REF! | G43: =S52+S53 -> #REF! | O43: 지급임차료 | P43: 439149 | Q43: 454860 | R43: 547485 | S43: 803576 | U43: 지급수수료 | V43: 지급수수료 | AA43: =AA42/AA38 -> 0.29259663 | AB43: =AB42/AB38 -> 0.37682042 | AC43: =AC42/AC38 -> 0.44284438 | AD43: =AD42/AD38 -> 0.41770414 | AH43: 외주가공비 등 | AI43: 가공·제작 | AJ43: 가공 및 제작 | AK43: 187057 | AL43: 65.4
...

Sheet Case Summary
B1: Estimation
B2: Case Summary
B5: Active Scenario | C5: Base
B6: Scenario Number | C6: =IF(C5="Bull",1, IF(C5="Base",2,3)) -> 2
C7: =2000+RIGHT(C8,2) -> 2025 | D7: =2000+RIGHT(D8,2) -> 2025 | E7: =2000+RIGHT(E8,2) -> 2025 | F7: =2000+RIGHT(F8,2) -> 2025 | G7: =2000+RIGHT(G8,2) -> 2026 | H7: =2000+RIGHT(H8,2) -> 2026 | I7: =2000+RIGHT(I8,2) -> 2026 | J7: =2000+RIGHT(J8,2) -> 2026 | ... R7: =2000+RIGHT(R8,2) -> 2028
A8: x | B8: (단위: 백만 원) | C8: 1Q25 | D8: 2Q25 | E8: 3Q25 | F8: 4Q25 | G8: 1Q26 | H8: 2Q26 | I8: 3Q26 | J8: 4Q26 | K8: 1Q27 | L8: 2Q27 | M8: 3Q27 | N8: 4Q27 | O8: 1Q28 | P8: 2Q28 | Q8: 3Q28 | R8: 4Q28 | T8: 2024 | U8: 2025 | V8: 2026 | W8: 2027 | X8: 2028 | Z8: CAGR
B9: 매출액 | C9: 135275 | D9: =SUM(D11,D13,D15,D17) -> 144360.4 | E9: =SUM(E11,E13,E15,E17) -> 196610.33 | F9: =SUM(F11,F13,F15,F17) -> 247366.4 | G9: =SUM(G11,G13,G15,G17) -> 270455.87 | H9: =SUM(H11,H13,H15,H17) -> 273993.95 | I9: =SUM(I11,I13,I15,I17) -> 265735.06 | J9: =SUM(J11,J13,J15,J17) -> 245238.61 | K9: =SUM(K11,K13,K15,K17) -> 253748.96 | ... R9: =SUM(R11,R13,R15,R17) -> 276407.28 | T9: 404742 | U9: =SUM(U11,U13,U15,U17) -> 818060.13 | V9: =SUM(V11,V13,V15,V17) -> 1055423.5 | W9: =SUM(W11,W13,W15,W17) -> 1121745.8 | X9: =SUM(X11,X13,X15,X17) -> 1225142.9 | Z9: =RATE(3,0,-U9,X9) -> 0.14410839
B10: YoY / QoQ % | D10: =D9/C9-1 -> 0.067162443 | E10: =E9/D9-1 -> 0.36194088 | F10: =F9/E9-1 -> 0.25815566 | G10: =G9/F9-1 -> 0.093341188 | H10: =H9/G9-1 -> 0.013081892 | I10: =I9/H9-1 -> -0.030142603 | J10: =J9/I9-1 -> -0.077131148 | K10: =K9/J9-1 -> 0.034702361 | ... R10: =R9/Q9-1 -> -0.1797091 | U10: =U9/T9-1 -> 1.0211891 | V10: =V9/U9-1 -> 0.29015392 | W10: =W9/V9-1 -> 0.062839579 | X10: =X9/W9-1 -> 0.092175082
B11: HRSG | C11: =CHOOSE($C$6,HRSG!C42,HRSG!C47,HRSG!C52) -> 98656 | D11: =CHOOSE($C$6,HRSG!D42,HRSG!D47,HRSG!D52) -> 100885.48 | E11: =CHOOSE($C$6,HRSG!E42,HRSG!E47,HRSG!E52) -> 136278.53 | F11: =CHOOSE($C$6,HRSG!F42,HRSG!F47,HRSG!F52) -> 187034.6 | G11: =CHOOSE($C$6,HRSG!G42,HRSG!G47,HRSG!G52) -> 210124.07 | H11: =CHOOSE($C$6,HRSG!H42,HRSG!H47,HRSG!H52) -> 213662.14 | I11: =CHOOSE($C$6,HRSG!I42,HRSG!I47,HRSG!I52) -> 205403.25 | J11: =CHOOSE($C$6,HRSG!J42,HRSG!J47,HRSG!J52) -> 184906.8 | ... R11: =CHOOSE($C$6,HRSG!R42,HRSG!R47,HRSG!R52) -> 161686.25 | T11: 259014 | U11: =SUMIF($C$7:$R$7,U$8,$C11:$R11) -> 522854.61 | V11: =SUMIF($C$7:$R$7,V$8,$C11:$R11) -> 814096.27 | W11: =SUMIF($C$7:$R$7,W$8,$C11:$R11) -> 753165.03 | X11: =SUMIF($C$7:$R$7,X$8,$C11:$R11) -> 794672.44 | Z11: =RATE(3,0,-U11,X11) -> 0.14974731
B12: YoY % | D12: =D11/C11-1 -> 0.022598557 | E12: =E11/D11-1 -> 0.35082396 | F12: =F11/E11-1 -> 0.37244362 | G12: =G11/F11-1 -> 0.12345028 | H12: =H11/G11-1 -> 0.016838026 | I12: =I11/H11-1 -> -0.038653973 | J12: =J11/I11-1 -> -0.099786393 | K12: =K11/J11-1 -> -0.11114149 | ... R12: =R11/Q11-1 -> -0.27247493 | U12: =U11/T11-1 -> 1.0186345 | V12: =V11/U11-1 -> 0.55702228 | W12: =W11/V11-1 -> -0.07484525 | X12: =X11/W11-1 -> 0.055110636
B13: Boiler | C13: =Boiler!C9 -> 20124 | D13: =Boiler!D9 -> 20124 | E13: =Boiler!E9 -> 36980.886 | F13: =Boiler!F9 -> 36980.886 | G13: =Boiler!G9 -> 36980.886 | H13: =Boiler!H9 -> 36980.886 | I13: =Boiler!I9 -> 36980.886 | J13: =Boiler!J9 -> 36980.886 | ... R13: =Boiler!R9 -> 57400.886 | T13: 68413 | U13: =SUMIF($C$7:$R$7,U$8,$C13:$R13) -> 114209.77 | V13: =SUMIF($C$7:$R$7,V$8,$C13:$R13) -> 147923.54 | W13: =SUMIF($C$7:$R$7,W$8,$C13:$R13) -> 229603.54 | X13: =SUMIF($C$7:$R$7,X$8,$C13:$R13) -> 229603.54 | Z13: =RATE(3,0,-재무분석!W40,재무분석!Z40) -> 0.10708628
B14: YoY % | D14: =D13/C13-1 -> 0 | E14: =E13/D13-1 -> 0.83765085 | F14: =F13/E13-1 -> 0 | G14: =G13/F13-1 -> 0 | H14: =H13/G13-1 -> 0 | I14: =I13/H13-1 -> 0 | J14: =J13/I13-1 -> 0 | K14: =K13/J13-1 -> 0.55217715 | ... R14: =R13/Q13-1 -> 0 | U14: =U13/T13-1 -> 0.66941621 | V14: =V13/U13-1 -> 0.29519165 | W14: =W13/V13-1 -> 0.55217715 | X14: =X13/W13-1 -> 0
B15: BOP | C15: =CHOOSE($C$6,BOP!C53,BOP!C58,BOP!C63) -> 98656 | D15: =CHOOSE($C$6,BOP!D53,BOP!D58,BOP!D63) -> 11063.916 | E15: =CHOOSE($C$6,BOP!E53,BOP!E58,BOP!E63) -> 11063.916 | F15: =CHOOSE($C$6,BOP!F53,BOP!F58,BOP!F63) -> 11063.916 | G15: =CHOOSE($C$6,BOP!G53,BOP!G58,BOP!G63) -> 11063.916 | H15: =CHOOSE($C$6,BOP!H53,BOP!H58,BOP!H63) -> 11063.916 | I15: =CHOOSE($C$6,BOP!I53,BOP!I58,BOP!I63) -> 11063.916 | J15: =CHOOSE($C$6,BOP!J53,BOP!J58,BOP!J63) -> 11063.916 | ... R15: =CHOOSE($C$6,BOP!R53,BOP!R58,BOP!R63) -> 45033.147 | T15: 14305 | U15: =SUMIF($C$7:$R$7,U$8,$C15:$R15) -> 131847.75 | V15: =SUMIF($C$7:$R$7,V$8,$C15:$R15) -> 44255.665 | W15: =SUMIF($C$7:$R$7,W$8,$C15:$R15) -> 89829.271 | X15: =SUMIF($C$7:$R$7,X$8,$C15:$R15) -> 151718.88 | Z15: =RATE(3,0,-U15,X15) -> 0.047905947
B16: YoY % | D16: =D15/C15-1 -> -0.88785359 | E16: =E15/D15-1 -> 0 | F16: =F15/E15-1 -> 0 | G16: =G15/F15-1 -> 0 | H16: =H15/G15-1 -> 0 | I16: =I15/H15-1 -> 0 | J16: =J15/I15-1 -> 0 | K16: =K15/J15-1 -> 0.78102331 | ... R16: =R15/Q15-1 -> 0 | U16: =U15/T15-1 -> 8.2168996 | V16: =V15/U15-1 -> -0.66434266 | W16: =W15/V15-1 -> 1.0297802 | X16: =X15/W15-1 -> 0.68896932
B17: 기타 | C17: 12287 | D17: =C17 -> 12287 | E17: =D17 -> 12287 | F17: =E17 -> 12287 | G17: =F17 -> 12287 | H17: =G17 -> 12287 | I17: =H17 -> 12287 | J17: =I17 -> 12287 | K17: =J17 -> 12287 | ... R17: =Q17 -> 12287 | T17: 63010 | U17: =SUMIF($C$7:$R$7,U$8,$C17:$R17) -> 49148 | V17: =SUMIF($C$7:$R$7,V$8,$C17:$R17) -> 49148 | W17: =SUMIF($C$7:$R$7,W$8,$C17:$R17) -> 49148 | X17: =SUMIF($C$7:$R$7,X$8,$C17:$R17) -> 49148 | Z17: =RATE(3,0,-U17,X17) -> 4.5814405e-14
B18: YoY % | D18: =D17/C17-1 -> 0 | E18: =E17/D17-1 -> 0 | F18: =F17/E17-1 -> 0 | G18: =G17/F17-1 -> 0 | H18: =H17/G17-1 -> 0 | I18: =I17/H17-1 -> 0 | J18: =J17/I17-1 -> 0 | K18: =K17/J17-1 -> 0 | ... R18: =R17/Q17-1 -> 0 | U18: =U17/T17-1 -> -0.21999683 | V18: =V17/U17-1 -> 0 | W18: =W17/V17-1 -> 0 | X18: =X17/W17-1 -> 0
B20: (단위: 백만 원) | C20: 2016 | D20: =C20+1 -> 2017 | E20: =D20+1 -> 2018 | F20: =E20+1 -> 2019 | G20: =F20+1 -> 2020 | H20: =G20+1 -> 2021 | I20: =H20+1 -> 2022 | J20: =I20+1 -> 2023 | K20: =J20+1 -> 2024 | ... O20: =N20+1 -> 2028
A21: x | B21: 신규수주 | C21: =SUMIF(수주내역!$G$4:$G$68,C$20,수주내역!$E$4:$E$68) -> 255521.71 | D21: =SUMIF(수주내역!$G$4:$G$68,D$20,수주내역!$E$4:$E$68) -> 47224.688 | E21: =SUMIF(수주내역!$G$4:$G$68,E$20,수주내역!$E$4:$E$68) -> 50863.127 | F21: =SUMIF(수주내역!$G$4:$G$68,F$20,수주내역!$E$4:$E$68) -> 118121.03 | G21: =SUMIF(수주내역!$G$4:$G$68,G$20,수주내역!$E$4:$E$68) -> 143578.22 | H21: =SUMIF(수주내역!$G$4:$G$68,H$20,수주내역!$E$4:$E$68) -> 349188.39 | I21: =SUMIF(수주내역!$G$4:$G$68,I$20,수주내역!$E$4:$E$68) -> 313975.63 | J21: =SUMIF(수주내역!$G$4:$G$68,J$20,수주내역!$E$4:$E$68) -> 360259.61 | K21: =SUMIF(수주내역!$G$4:$G$68,K$20,수주내역!$E$4:$E$68) -> 1344171.6 | L21: =SUM(L22,L29,L30,L31,L32) -> 1613571.5 | M21: =SUM(M22,M29,M30,M31,M32) -> 995986.71 | N21: =SUM(N22,N29,N30,N31,N32) -> 1273498.1 | O21: =SUM(O22,O29,O30,O31,O32) -> 390261.74
B22: HRSG | C22: =SUMIFS(수주내역!$E$4:$E$68,수주내역!$C$4:$C$68,$B22,수주내역!$G$4:$G$68,C$20) -> 65858.959 | D22: =SUMIFS(수주내역!$E$4:$E$68,수주내역!$C$4:$C$68,$B22,수주내역!$G$4:$G$68,D$20) -> 47224.688 | E22: =SUMIFS(수주내역!$E$4:$E$68,수주내역!$C$4:$C$68,$B22,수주내역!$G$4:$G$68,E$20) -> 0 | F22: =SUMIFS(수주내역!$E$4:$E$68,수주내역!$C$4:$C$68,$B22,수주내역!$G$4:$G$68,F$20) -> 57152.291 | G22: =SUMIFS(수주내역!$E$4:$E$68,수주내역!$C$4:$C$68,$B22,수주내역!$G$4:$G$68,G$20) -> 143578.22 | H22: =SUMIFS(수주내역!$E$4:$E$68,수주내역!$C$4:$C$68,$B22,수주내역!$G$4:$G$68,H$20) -> 180863.44 | I22: =SUMIFS(수주내역!$E$4:$E$68,수주내역!$C$4:$C$68,$B22,수주내역!$G$4:$G$68,I$20) -> 206944.62 | J22: =SUMIFS(수주내역!$E$4:$E$68,수주내역!$C$4:$C$68,$B22,수주내역!$G$4:$G$68,J$20) -> 104341.65 | K22: =SUMIFS(수주내역!$E$4:$E$68,수주내역!$C$4:$C$68,$B22,수주내역!$G$4:$G$68,K$20) -> 1071639.3 | L22: =SUMIFS(수주내역!$E$4:$E$68,수주내역!$C$4:$C$68,$B22,수주내역!$G$4:$G$68,L$20)+CHOOSE($C$6,'Case Summary'!J36,'Case Summary'!J37,'Case Summary'!J38) -> 777716.77 | M22: =CHOOSE($C$6,'Case Summary'!K36,'Case Summary'!K37,'Case Summary'!K38) -> 838618.5 | N22: =CHOOSE($C$6,'Case Summary'!L36,'Case Summary'!L37,'Case Summary'!L38) -> 688599.07 | O22: =CHOOSE($C$6,'Case Summary'!M36,'Case Summary'!M37,'Case Summary'!M38) -> 66187.838
B23: 국내 | C23: =SUMIFS(수주내역!$E$4:$E$68,수주내역!$C$4:$C$68,'Case Summary'!$B$22,수주내역!$D$4:$D$68,'Case Summary'!$B23,수주내역!$G$4:$G$68,'Case Summary'!C$20) -> 0 | D23: =SUMIFS(수주내역!$E$4:$E$68,수주내역!$C$4:$C$68,'Case Summary'!$B$22,수주내역!$D$4:$D$68,'Case Summary'!$B23,수주내역!$G$4:$G$68,'Case Summary'!D$20) -> 0 | E23: =SUMIFS(수주내역!$E$4:$E$68,수주내역!$C$4:$C$68,'Case Summary'!$B$22,수주내역!$D$4:$D$68,'Case Summary'!$B23,수주내역!$G$4:$G$68,'Case Summary'!E$20) -> 0 | F23: =SUMIFS(수주내역!$E$4:$E$68,수주내역!$C$4:$C$68,'Case Summary'!$B$22,수주내역!$D$4:$D$68,'Case Summary'!$B23,수주내역!$G$4:$G$68,'Case Summary'!F$20) -> 0 | G23: =SUMIFS(수주내역!$E$4:$E$68,수주내역!$C$4:$C$68,'Case Summary'!$B$22,수주내역!$D$4:$D$68,'Case Summary'!$B23,수주내역!$G$4:$G$68,'Case Summary'!G$20) -> 92547.218 | H23: =SUMIFS(수주내역!$E$4:$E$68,수주내역!$C$4:$C$68,'Case Summary'!$B$22,수주내역!$D$4:$D$68,'Case Summary'!$B23,수주내역!$G$4:$G$68,'Case Summary'!H$20) -> 41326.552 | I23: =SUMIFS(수주내역!$E$4:$E$68,수주내역!$C$4:$C$68,'Case Summary'!$B$22,수주내역!$D$4:$D$68,'Case Summary'!$B23,수주내역!$G$4:$G$68,'Case Summary'!I$20) -> 153838.69 | J23: =SUMIFS(수주내역!$E$4:$E$68,수주내역!$C$4:$C$68,'Case Summary'!$B$22,수주내역!$D$4:$D$68,'Case Summary'!$B23,수주내역!$G$4:$G$68,'Case Summary'!J$20) -> 87500 | K23: =SUMIFS(수주내역!$E$4:$E$68,수주내역!$C$4:$C$68,'Case Summary'!$B$22,수주내역!$D$4:$D$68,'Case Summary'!$B23,수주내역!$G$4:$G$68,'Case Summary'!K$20) -> 272266.21 | L23: =SUMIFS(수주내역!$E$4:$E$68,수주내역!$C$4:$C$68,'Case Summary'!$B$22,수주내역!$D$4:$D$68,'Case Summary'!$B23,수주내역!$G$4:$G$68,'Case Summary'!L$20)+CHOOSE($C$6,'Case Summary'!C36,'Case Summary'!C37,'Case Summary'!C38) -> 43475 | M23: =CHOOSE($C$6,'Case Summary'!D36,'Case Summary'!D37,'Case Summary'!D38) -> 43475 | N23: =CHOOSE($C$6,'Case Summary'!E36,'Case Summary'!E37,'Case Summary'!E38) -> 165707.14 | O23: =CHOOSE($C$6,'Case Summary'!F36,'Case Summary'!F37,'Case Summary'!F38) -> 0
B24: 해외 | C24: =SUM(C25:C28) -> 65858.959 | D24: =SUM(D25:D28) -> 47224.688 | E24: =SUM(E25:E28) -> 0 | F24: =SUM(F25:F28) -> 57152.291 | G24: =SUM(G25:G28) -> 51031 | H24: =SUM(H25:H28) -> 139536.89 | I24: =SUM(I25:I28) -> 53105.933 | J24: =SUM(J25:J28) -> 16841.65 | ... O24: =SUM(O25:O28) -> 66187.838
B25: 중동 | C25: =SUMIFS(수주내역!$E$4:$E$68,수주내역!$C$4:$C$68,'Case Summary'!$B$22,수주내역!$D$4:$D$68,'Case Summary'!$B25,수주내역!$G$4:$G$68,'Case Summary'!C$20) -> 0 | D25: =SUMIFS(수주내역!$E$4:$E$68,수주내역!$C$4:$C$68,'Case Summary'!$B$22,수주내역!$D$4:$D$68,'Case Summary'!$B25,수주내역!$G$4:$G$68,'Case Summary'!D$20) -> 47224.688 | E25: =SUMIFS(수주내역!$E$4:$E$68,수주내역!$C$4:$C$68,'Case Summary'!$B$22,수주내역!$D$4:$D$68,'Case Summary'!$B25,수주내역!$G$4:$G$68,'Case Summary'!E$20) -> 0 | F25: =SUMIFS(수주내역!$E$4:$E$68,수주내역!$C$4:$C$68,'Case Summary'!$B$22,수주내역!$D$4:$D$68,'Case Summary'!$B25,수주내역!$G$4:$G$68,'Case Summary'!F$20) -> 0 | G25: =SUMIFS(수주내역!$E$4:$E$68,수주내역!$C$4:$C$68,'Case Summary'!$B$22,수주내역!$D$4:$D$68,'Case Summary'!$B25,수주내역!$G$4:$G$68,'Case Summary'!G$20) -> 0 | H25: =SUMIFS(수주내역!$E$4:$E$68,수주내역!$C$4:$C$68,'Case Summary'!$B$22,수주내역!$D$4:$D$68,'Case Summary'!$B25,수주내역!$G$4:$G$68,'Case Summary'!H$20) -> 0 | I25: =SUMIFS(수주내역!$E$4:$E$68,수주내역!$C$4:$C$68,'Case Summary'!$B$22,수주내역!$D$4:$D$68,'Case Summary'!$B25,수주내역!$G$4:$G$68,'Case Summary'!I$20) -> 0 | J25: =SUMIFS(수주내역!$E$4:$E$68,수주내역!$C$4:$C$68,'Case Summary'!$B$22,수주내역!$D$4:$D$68,'Case Summary'!$B25,수주내역!$G$4:$G$68,'Case Summary'!J$20) -> 0 | K25: =SUMIFS(수주내역!$E$4:$E$68,수주내역!$C$4:$C$68,'Case Summary'!$B$22,수주내역!$D$4:$D$68,'Case Summary'!$B25,수주내역!$G$4:$G$68,'Case Summary'!K$20) -> 409476.53 | L25: =SUMIFS(수주내역!$E$4:$E$68,수주내역!$C$4:$C$68,'Case Summary'!$B$22,수주내역!$D$4:$D$68,'Case Summary'!$B25,수주내역!$G$4:$G$68,'Case Summary'!L$20)+CHOOSE($C$6,'Case Summary'!C41,'Case Summary'!C42,'Case Summary'!C43) -> 601866.09 | M25: =CHOOSE($C$6,'Case Summary'!D41,'Case Summary'!D42,'Case Summary'!D43) -> 634608.99 | N25: =CHOOSE($C$6,'Case Summary'!E41,'Case Summary'!E42,'Case Summary'!E43) -> 359582.52 | O25: =CHOOSE($C$6,'Case Summary'!F41,'Case Summary'!F42,'Case Summary'!F43) -> 0
B26: 일본 | C26: =SUMIFS(수주내역!$E$4:$E$68,수주내역!$C$4:$C$68,'Case Summary'!$B$22,수주내역!$D$4:$D$68,'Case Summary'!$B26,수주내역!$G$4:$G$68,'Case Summary'!C$20) -> 0 | D26: =SUMIFS(수주내역!$E$4:$E$68,수주내역!$C$4:$C$68,'Case Summary'!$B$22,수주내역!$D$4:$D$68,'Case Summary'!$B26,수주내역!$G$4:$G$68,'Case Summary'!D$20) -> 0 | E26: =SUMIFS(수주내역!$E$4:$E$68,수주내역!$C$4:$C$68,'Case Summary'!$B$22,수주내역!$D$4:$D$68,'Case Summary'!$B26,수주내역!$G$4:$G$68,'Case Summary'!E$20) -> 0 | F26: =SUMIFS(수주내역!$E$4:$E$68,수주내역!$C$4:$C$68,'Case Summary'!$B$22,수주내역!$D$4:$D$68,'Case Summary'!$B26,수주내역!$G$4:$G$68,'Case Summary'!F$20) -> 0 | G26: =SUMIFS(수주내역!$E$4:$E$68,수주내역!$C$4:$C$68,'Case Summary'!$B$22,수주내역!$D$4:$D$68,'Case Summary'!$B26,수주내역!$G$4:$G$68,'Case Summary'!G$20) -> 0 | H26: =SUMIFS(수주내역!$E$4:$E$68,수주내역!$C$4:$C$68,'Case Summary'!$B$22,수주내역!$D$4:$D$68,'Case Summary'!$B26,수주내역!$G$4:$G$68,'Case Summary'!H$20) -> 0 | I26: =SUMIFS(수주내역!$E$4:$E$68,수주내역!$C$4:$C$68,'Case Summary'!$B$22,수주내역!$D$4:$D$68,'Case Summary'!$B26,수주내역!$G$4:$G$68,'Case Summary'!I$20) -> 0 | J26: =SUMIFS(수주내역!$E$4:$E$68,수주내역!$C$4:$C$68,'Case Summary'!$B$22,수주내역!$D$4:$D$68,'Case Summary'!$B26,수주내역!$G$4:$G$68,'Case Summary'!J$20) -> 16841.65 | K26: =SUMIFS(수주내역!$E$4:$E$68,수주내역!$C$4:$C$68,'Case Summary'!$B$22,수주내역!$D$4:$D$68,'Case Summary'!$B26,수주내역!$G$4:$G$68,'Case Summary'!K$20) -> 389896.53 | L26: =SUMIFS(수주내역!$E$4:$E$68,수주내역!$C$4:$C$68,'Case Summary'!$B$22,수주내역!$D$4:$D$68,'Case Summary'!$B26,수주내역!$G$4:$G$68,'Case Summary'!L$20)+CHOOSE($C$6,'Case Summary'!C51,'Case Summary'!C52,'Case Summary'!C53) -> 132375.68 | M26: =CHOOSE($C$6,'Case Summary'!D51,'Case Summary'!D52,'Case Summary'!D53) -> 66187.838 | N26: =CHOOSE($C$6,'Case Summary'!E51,'Case Summary'!E52,'Case Summary'!E53) -> 66187.838 | O26: =CHOOSE($C$6,'Case Summary'!F51,'Case Summary'!F52,'Case Summary'!F53) -> 66187.838
B27: 미국 | C27: 0 | D27: 0 | E27: 0 | F27: 0 | G27: 0 | H27: 0 | I27: 0 | J27: 0 | K27: 0 | L27: 0 | M27: =CHOOSE($C$6,'Case Summary'!D46,'Case Summary'!D47,'Case Summary'!D48) -> 94346.67 | N27: =CHOOSE($C$6,'Case Summary'!E46,'Case Summary'!E47,'Case Summary'!E48) -> 97121.572 | O27: =CHOOSE($C$6,'Case Summary'!F46,'Case Summary'!F47,'Case Summary'!F48) -> 0
B28: 기타 | C28: =SUMIFS(수주내역!$E$4:$E$68,수주내역!$C$4:$C$68,'Case Summary'!$B$22,수주내역!$D$4:$D$68,"해외",수주내역!$G$4:$G$68,'Case Summary'!C$20) -> 65858.959 | D28: =SUMIFS(수주내역!$E$4:$E$68,수주내역!$C$4:$C$68,'Case Summary'!$B$22,수주내역!$D$4:$D$68,"해외",수주내역!$G$4:$G$68,'Case Summary'!D$20) -> 0 | E28: =SUMIFS(수주내역!$E$4:$E$68,수주내역!$C$4:$C$68,'Case Summary'!$B$22,수주내역!$D$4:$D$68,"해외",수주내역!$G$4:$G$68,'Case Summary'!E$20) -> 0 | F28: =SUMIFS(수주내역!$E$4:$E$68,수주내역!$C$4:$C$68,'Case Summary'!$B$22,수주내역!$D$4:$D$68,"해외",수주내역!$G$4:$G$68,'Case Summary'!F$20) -> 57152.291 | G28: =SUMIFS(수주내역!$E$4:$E$68,수주내역!$C$4:$C$68,'Case Summary'!$B$22,수주내역!$D$4:$D$68,"해외",수주내역!$G$4:$G$68,'Case Summary'!G$20) -> 51031 | H28: =SUMIFS(수주내역!$E$4:$E$68,수주내역!$C$4:$C$68,'Case Summary'!$B$22,수주내역!$D$4:$D$68,"해외",수주내역!$G$4:$G$68,'Case Summary'!H$20) -> 139536.89 | I28: =SUMIFS(수주내역!$E$4:$E$68,수주내역!$C$4:$C$68,'Case Summary'!$B$22,수주내역!$D$4:$D$68,"해외",수주내역!$G$4:$G$68,'Case Summary'!I$20) -> 53105.933 | J28: =SUMIFS(수주내역!$E$4:$E$68,수주내역!$C$4:$C$68,'Case Summary'!$B$22,수주내역!$D$4:$D$68,"해외",수주내역!$G$4:$G$68,'Case Summary'!J$20) -> 0 | ... L28: =SUMIFS(수주내역!$E$4:$E$68,수주내역!$C$4:$C$68,'Case Summary'!$B$22,수주내역!$D$4:$D$68,"해외",수주내역!$G$4:$G$68,'Case Summary'!L$20) -> 0 | M28: 0 | N28: 0 | O28: 0
B29: Boiler | C29: =SUMIFS(수주내역!$E$4:$E$68,수주내역!$C$4:$C$68,$B29,수주내역!$G$4:$G$68,C$20) -> 113969.99 | D29: =SUMIFS(수주내역!$E$4:$E$68,수주내역!$C$4:$C$68,$B29,수주내역!$G$4:$G$68,D$20) -> 0 | E29: =SUMIFS(수주내역!$E$4:$E$68,수주내역!$C$4:$C$68,$B29,수주내역!$G$4:$G$68,E$20) -> 50863.127 | F29: =SUMIFS(수주내역!$E$4:$E$68,수주내역!$C$4:$C$68,$B29,수주내역!$G$4:$G$68,F$20) -> 32268.741 | G29: =SUMIFS(수주내역!$E$4:$E$68,수주내역!$C$4:$C$68,$B29,수주내역!$G$4:$G$68,G$20) -> 0 | H29: =SUMIFS(수주내역!$E$4:$E$68,수주내역!$C$4:$C$68,$B29,수주내역!$G$4:$G$68,H$20) -> 77427.682 | I29: =SUMIFS(수주내역!$E$4:$E$68,수주내역!$C$4:$C$68,$B29,수주내역!$G$4:$G$68,I$20) -> 107031 | J29: =SUMIFS(수주내역!$E$4:$E$68,수주내역!$C$4:$C$68,$B29,수주내역!$G$4:$G$68,J$20) -> 255917.96 | ... L29: =SUMIFS(수주내역!$E$4:$E$68,수주내역!$C$4:$C$68,$B29,수주내역!$G$4:$G$68,L$20) -> 517732.4 | M29: 0 | N29: 0 | O29: 0
B30: BOP | C30: =SUMIFS(수주내역!$E$4:$E$68,수주내역!$C$4:$C$68,$B30,수주내역!$G$4:$G$68,C$20) -> 75692.754 | D30: =SUMIFS(수주내역!$E$4:$E$68,수주내역!$C$4:$C$68,$B30,수주내역!$G$4:$G$68,D$20) -> 0 | E30: =SUMIFS(수주내역!$E$4:$E$68,수주내역!$C$4:$C$68,$B30,수주내역!$G$4:$G$68,E$20) -> 0 | F30: =SUMIFS(수주내역!$E$4:$E$68,수주내역!$C$4:$C$68,$B30,수주내역!$G$4:$G$68,F$20) -> 0 | G30: =SUMIFS(수주내역!$E$4:$E$68,수주내역!$C$4:$C$68,$B30,수주내역!$G$4:$G$68,G$20) -> 0 | H30: =SUMIFS(수주내역!$E$4:$E$68,수주내역!$C$4:$C$68,$B30,수주내역!$G$4:$G$68,H$20) -> 90897.264 | I30: =SUMIFS(수주내역!$E$4:$E$68,수주내역!$C$4:$C$68,$B30,수주내역!$G$4:$G$68,I$20) -> 0 | J30: =SUMIFS(수주내역!$E$4:$E$68,수주내역!$C$4:$C$68,$B30,수주내역!$G$4:$G$68,J$20) -> 0 | K30: =SUMIFS(수주내역!$E$4:$E$68,수주내역!$C$4:$C$68,$B30,수주내역!$G$4:$G$68,K$20) -> 91538.3 | L30: =SUMIFS(수주내역!$E$4:$E$68,수주내역!$C$4:$C$68,$B30,수주내역!$G$4:$G$68,L$20)+CHOOSE($C$6,J41,J42,J43) -> 318122.29 | M30: =CHOOSE($C$6,K41,K42,K43) -> 157368.21 | N30: =CHOOSE($C$6,L41,L42,L43) -> 584898.99 | O30: =CHOOSE($C$6,M41,M42,M43) -> 324073.9
B31: EPC | C31: =SUMIFS(수주내역!$E$4:$E$68,수주내역!$C$4:$C$68,$B31,수주내역!$G$4:$G$68,C$20) -> 0 | D31: =SUMIFS(수주내역!$E$4:$E$68,수주내역!$C$4:$C$68,$B31,수주내역!$G$4:$G$68,D$20) -> 0 | E31: =SUMIFS(수주내역!$E$4:$E$68,수주내역!$C$4:$C$68,$B31,수주내역!$G$4:$G$68,E$20) -> 0 | F31: =SUMIFS(수주내역!$E$4:$E$68,수주내역!$C$4:$C$68,$B31,수주내역!$G$4:$G$68,F$20) -> 0 | G31: =SUMIFS(수주내역!$E$4:$E$68,수주내역!$C$4:$C$68,$B31,수주내역!$G$4:$G$68,G$20) -> 0 | H31: =SUMIFS(수주내역!$E$4:$E$68,수주내역!$C$4:$C$68,$B31,수주내역!$G$4:$G$68,H$20) -> 0 | I31: =SUMIFS(수주내역!$E$4:$E$68,수주내역!$C$4:$C$68,$B31,수주내역!$G$4:$G$68,I$20) -> 0 | J31: =SUMIFS(수주내역!$E$4:$E$68,수주내역!$C$4:$C$68,$B31,수주내역!$G$4:$G$68,J$20) -> 0 | ... L31: =SUMIFS(수주내역!$E$4:$E$68,수주내역!$C$4:$C$68,$B31,수주내역!$G$4:$G$68,L$20) -> 0 | M31: 0 | N31: 0 | O31: 0
B32: 기타 | C32: =SUMIFS(수주내역!$E$4:$E$68,수주내역!$C$4:$C$68,$B32,수주내역!$G$4:$G$68,C$20) -> 0 | D32: =SUMIFS(수주내역!$E$4:$E$68,수주내역!$C$4:$C$68,$B32,수주내역!$G$4:$G$68,D$20) -> 0 | E32: =SUMIFS(수주내역!$E$4:$E$68,수주내역!$C$4:$C$68,$B32,수주내역!$G$4:$G$68,E$20) -> 0 | F32: =SUMIFS(수주내역!$E$4:$E$68,수주내역!$C$4:$C$68,$B32,수주내역!$G$4:$G$68,F$20) -> 28700 | G32: =SUMIFS(수주내역!$E$4:$E$68,수주내역!$C$4:$C$68,$B32,수주내역!$G$4:$G$68,G$20) -> 0 | H32: =SUMIFS(수주내역!$E$4:$E$68,수주내역!$C$4:$C$68,$B32,수주내역!$G$4:$G$68,H$20) -> 0 | I32: =SUMIFS(수주내역!$E$4:$E$68,수주내역!$C$4:$C$68,$B32,수주내역!$G$4:$G$68,I$20) -> 0 | J32: =SUMIFS(수주내역!$E$4:$E$68,수주내역!$C$4:$C$68,$B32,수주내역!$G$4:$G$68,J$20) -> 0 | ... L32: =SUMIFS(수주내역!$E$4:$E$68,수주내역!$C$4:$C$68,$B32,수주내역!$G$4:$G$68,L$20) -> 0 | M32: 0 | N32: 0 | O32: 0
B35: HRSG 국내 | C35: 2025 | D35: 2026 | E35: 2027 | F35: 2028 | G35: 2029 | I35: HRSG 전체 | J35: 2025 | K35: 2026 | L35: 2027 | M35: 2028 | N35: 2029
B36: Bull | C36: =C37+SUMIFS('HRSG 수주 시나리오'!$F$16:$F$21,'HRSG 수주 시나리오'!$B$16:$B$21,"잠재",'HRSG 수주 시나리오'!$I$16:$I$21,C$40) -> 107646.88 | D36: =D37+SUMIFS('HRSG 수주 시나리오'!$F$16:$F$21,'HRSG 수주 시나리오'!$B$16:$B$21,"잠재",'HRSG 수주 시나리오'!$I$16:$I$21,D$40) -> 43475 | E36: =E37+SUMIFS('HRSG 수주 시나리오'!$F$16:$F$21,'HRSG 수주 시나리오'!$B$16:$B$21,"잠재",'HRSG 수주 시나리오'!$I$16:$I$21,E$40) -> 229879.02 | F36: =F37+SUMIFS('HRSG 수주 시나리오'!$F$16:$F$21,'HRSG 수주 시나리오'!$B$16:$B$21,"잠재",'HRSG 수주 시나리오'!$I$16:$I$21,F$40) -> 0 | G36: =G37+SUMIFS('HRSG 수주 시나리오'!$F$16:$F$21,'HRSG 수주 시나리오'!$B$16:$B$21,"잠재",'HRSG 수주 시나리오'!$I$16:$I$21,G$40) -> 0 | I36: Bull | J36: =SUMIF($B$35:$B$53,$I36,C$35:C$53) -> 173834.71 | K36: =SUMIF($B$35:$B$53,$I36,D$35:D$53) -> 838618.5 | L36: =SUMIF($B$35:$B$53,$I36,E$35:E$53) -> 930518.01 | M36: =SUMIF($B$35:$B$53,$I36,F$35:F$53) -> 66187.838 | N36: =SUMIF($B$35:$B$53,$I36,G$35:G$53) -> 0
B37: Base | C37: =C38+SUMIFS('HRSG 수주 시나리오'!$F$16:$F$21,'HRSG 수주 시나리오'!$B$16:$B$21,"가능",'HRSG 수주 시나리오'!$I$16:$I$21,C$40) -> 43475 | D37: =D38+SUMIFS('HRSG 수주 시나리오'!$F$16:$F$21,'HRSG 수주 시나리오'!$B$16:$B$21,"가능",'HRSG 수주 시나리오'!$I$16:$I$21,D$40) -> 43475 | E37: =E38+SUMIFS('HRSG 수주 시나리오'!$F$16:$F$21,'HRSG 수주 시나리오'!$B$16:$B$21,"가능",'HRSG 수주 시나리오'!$I$16:$I$21,E$40) -> 165707.14 | F37: =F38+SUMIFS('HRSG 수주 시나리오'!$F$16:$F$21,'HRSG 수주 시나리오'!$B$16:$B$21,"가능",'HRSG 수주 시나리오'!$I$16:$I$21,F$40) -> 0 | G37: =G38+SUMIFS('HRSG 수주 시나리오'!$F$16:$F$21,'HRSG 수주 시나리오'!$B$16:$B$21,"가능",'HRSG 수주 시나리오'!$I$16:$I$21,G$40) -> 0 | I37: Base | J37: =SUMIF($B$35:$B$53,$I37,C$35:C$53) -> 109662.84 | K37: =SUMIF($B$35:$B$53,$I37,D$35:D$53) -> 838618.5 | L37: =SUMIF($B$35:$B$53,$I37,E$35:E$53) -> 688599.07 | M37: =SUMIF($B$35:$B$53,$I37,F$35:F$53) -> 66187.838 | N37: =SUMIF($B$35:$B$53,$I37,G$35:G$53) -> 0
B38: Bear | C38: =SUMIFS('HRSG 수주 시나리오'!$F$16:$F$21,'HRSG 수주 시나리오'!$B$16:$B$21,"확실",'HRSG 수주 시나리오'!$I$16:$I$21,C$40) -> 43475 | D38: =SUMIFS('HRSG 수주 시나리오'!$F$16:$F$21,'HRSG 수주 시나리오'!$B$16:$B$21,"확실",'HRSG 수주 시나리오'!$I$16:$I$21,D$40) -> 43475 | E38: =SUMIFS('HRSG 수주 시나리오'!$F$16:$F$21,'HRSG 수주 시나리오'!$B$16:$B$21,"확실",'HRSG 수주 시나리오'!$I$16:$I$21,E$40) -> 0 | F38: =SUMIFS('HRSG 수주 시나리오'!$F$16:$F$21,'HRSG 수주 시나리오'!$B$16:$B$21,"확실",'HRSG 수주 시나리오'!$I$16:$I$21,F$40) -> 0 | G38: =SUMIFS('HRSG 수주 시나리오'!$F$16:$F$21,'HRSG 수주 시나리오'!$B$16:$B$21,"확실",'HRSG 수주 시나리오'!$I$16:$I$21,G$40) -> 0 | I38: Bear | J38: =SUMIF($B$35:$B$53,$I38,C$35:C$53) -> 43475 | K38: =SUMIF($B$35:$B$53,$I38,D$35:D$53) -> 388111.99 | L38: =SUMIF($B$35:$B$53,$I38,E$35:E$53) -> 140922.57 | M38: =SUMIF($B$35:$B$53,$I38,F$35:F$53) -> 0 | N38: =SUMIF($B$35:$B$53,$I38,G$35:G$53) -> 0
B40: HRSG 중동 | C40: 2025 | D40: 2026 | E40: 2027 | F40: 2028 | G40: 2029 | I40: BOP 전체 | J40: 2025 | K40: 2026 | L40: 2027 | M40: 2028 | N40: 2029
B41: Bull | C41: =C42+SUMIFS('HRSG 수주 시나리오'!$F$38:$F$44,'HRSG 수주 시나리오'!$B$38:$B$44,"잠재",'HRSG 수주 시나리오'!$I$38:$I$44,C$40) -> 0 | D41: =D42+SUMIFS('HRSG 수주 시나리오'!$F$38:$F$44,'HRSG 수주 시나리오'!$B$38:$B$44,"잠재",'HRSG 수주 시나리오'!$I$38:$I$44,D$40) -> 634608.99 | E41: =E42+SUMIFS('HRSG 수주 시나리오'!$F$38:$F$44,'HRSG 수주 시나리오'!$B$38:$B$44,"잠재",'HRSG 수주 시나리오'!$I$38:$I$44,E$40) -> 454082.52 | F41: =F42+SUMIFS('HRSG 수주 시나리오'!$F$38:$F$44,'HRSG 수주 시나리오'!$B$38:$B$44,"잠재",'HRSG 수주 시나리오'!$I$38:$I$44,F$40) -> 0 | G41: =G42+SUMIFS('HRSG 수주 시나리오'!$F$38:$F$44,'HRSG 수주 시나리오'!$B$38:$B$44,"잠재",'HRSG 수주 시나리오'!$I$38:$I$44,G$40) -> 0 | I41: Bull | J41: =J42+SUMIFS('BOP 수주 시나리오'!$G$20:$G$83,'BOP 수주 시나리오'!$B$20:$B$83,"잠재",'BOP 수주 시나리오'!$J$20:$J$83,J$40) -> 171154.99 | K41: =K42+SUMIFS('BOP 수주 시나리오'!$G$20:$G$83,'BOP 수주 시나리오'!$B$20:$B$83,"잠재",'BOP 수주 시나리오'!$J$20:$J$83,K$40) -> 476829.61 | L41: =L42+SUMIFS('BOP 수주 시나리오'!$G$20:$G$83,'BOP 수주 시나리오'!$B$20:$B$83,"잠재",'BOP 수주 시나리오'!$J$20:$J$83,L$40) -> 1005729.2 | M41: =M42+SUMIFS('BOP 수주 시나리오'!$G$20:$G$83,'BOP 수주 시나리오'!$B$20:$B$83,"잠재",'BOP 수주 시나리오'!$J$20:$J$83,M$40) -> 648647.85 | N41: =N42+SUMIFS('BOP 수주 시나리오'!$G$20:$G$83,'BOP 수주 시나리오'!$B$20:$B$83,"잠재",'BOP 수주 시나리오'!$J$20:$J$83,N$40) -> 155140.76
B42: Base | C42: =C43+SUMIFS('HRSG 수주 시나리오'!$F$38:$F$44,'HRSG 수주 시나리오'!$B$38:$B$44,"가능",'HRSG 수주 시나리오'!$I$38:$I$44,C$40) -> 0 | D42: =D43+SUMIFS('HRSG 수주 시나리오'!$F$38:$F$44,'HRSG 수주 시나리오'!$B$38:$B$44,"가능",'HRSG 수주 시나리오'!$I$38:$I$44,D$40) -> 634608.99 | E42: =E43+SUMIFS('HRSG 수주 시나리오'!$F$38:$F$44,'HRSG 수주 시나리오'!$B$38:$B$44,"가능",'HRSG 수주 시나리오'!$I$38:$I$44,E$40) -> 359582.52 | F42: =F43+SUMIFS('HRSG 수주 시나리오'!$F$38:$F$44,'HRSG 수주 시나리오'!$B$38:$B$44,"가능",'HRSG 수주 시나리오'!$I$38:$I$44,F$40) -> 0 | G42: =G43+SUMIFS('HRSG 수주 시나리오'!$F$38:$F$44,'HRSG 수주 시나리오'!$B$38:$B$44,"가능",'HRSG 수주 시나리오'!$I$38:$I$44,G$40) -> 0 | I42: Base | J42: =J43+SUMIFS('BOP 수주 시나리오'!$G$20:$G$83,'BOP 수주 시나리오'!$B$20:$B$83,"가능",'BOP 수주 시나리오'!$J$20:$J$83,J$40) -> 171154.99 | K42: =K43+SUMIFS('BOP 수주 시나리오'!$G$20:$G$83,'BOP 수주 시나리오'!$B$20:$B$83,"가능",'BOP 수주 시나리오'!$J$20:$J$83,K$40) -> 157368.21 | L42: =L43+SUMIFS('BOP 수주 시나리오'!$G$20:$G$83,'BOP 수주 시나리오'!$B$20:$B$83,"가능",'BOP 수주 시나리오'!$J$20:$J$83,L$40) -> 584898.99 | M42: =M43+SUMIFS('BOP 수주 시나리오'!$G$20:$G$83,'BOP 수주 시나리오'!$B$20:$B$83,"가능",'BOP 수주 시나리오'!$J$20:$J$83,M$40) -> 324073.9 | N42: =N43+SUMIFS('BOP 수주 시나리오'!$G$20:$G$83,'BOP 수주 시나리오'!$B$20:$B$83,"가능",'BOP 수주 시나리오'!$J$20:$J$83,N$40) -> 0
B43: Bear | C43: =SUMIFS('HRSG 수주 시나리오'!$F$38:$F$44,'HRSG 수주 시나리오'!$B$38:$B$44,"확실",'HRSG 수주 시나리오'!$I$38:$I$44,C$40) -> 0 | D43: =SUMIFS('HRSG 수주 시나리오'!$F$38:$F$44,'HRSG 수주 시나리오'!$B$38:$B$44,"확실",'HRSG 수주 시나리오'!$I$38:$I$44,D$40) -> 344636.99 | E43: =SUMIFS('HRSG 수주 시나리오'!$F$38:$F$44,'HRSG 수주 시나리오'!$B$38:$B$44,"확실",'HRSG 수주 시나리오'!$I$38:$I$44,E$40) -> 140922.57 | F43: =SUMIFS('HRSG 수주 시나리오'!$F$38:$F$44,'HRSG 수주 시나리오'!$B$38:$B$44,"확실",'HRSG 수주 시나리오'!$I$38:$I$44,F$40) -> 0 | G43: =SUMIFS('HRSG 수주 시나리오'!$F$38:$F$44,'HRSG 수주 시나리오'!$B$38:$B$44,"확실",'HRSG 수주 시나리오'!$I$38:$I$44,G$40) -> 0 | I43: Bear | J43: =SUMIFS('BOP 수주 시나리오'!$G$20:$G$83,'BOP 수주 시나리오'!$B$20:$B$83,"확실",'BOP 수주 시나리오'!$J$20:$J$83,J$40) -> 171154.99 | K43: =SUMIFS('BOP 수주 시나리오'!$G$20:$G$83,'BOP 수주 시나리오'!$B$20:$B$83,"확실",'BOP 수주 시나리오'!$J$20:$J$83,K$40) -> 0 | L43: =SUMIFS('BOP 수주 시나리오'!$G$20:$G$83,'BOP 수주 시나리오'!$B$20:$B$83,"확실",'BOP 수주 시나리오'!$J$20:$J$83,L$40) -> 394232.27 | M43: =SUMIFS('BOP 수주 시나리오'!$G$20:$G$83,'BOP 수주 시나리오'!$B$20:$B$83,"확실",'BOP 수주 시나리오'!$J$20:$J$83,M$40) -> 32394.625 | N43: =SUMIFS('BOP 수주 시나리오'!$G$20:$G$83,'BOP 수주 시나리오'!$B$20:$B$83,"확실",'BOP 수주 시나리오'!$J$20:$J$83,N$40) -> 0
B45: HRSG 미국 | C45: 2025 | D45: 2026 | E45: 2027 | F45: 2028 | G45: 2029
B46: Bull | C46: =C47+SUMIFS('HRSG 수주 시나리오'!$F$54:$F$56,'HRSG 수주 시나리오'!$B$54:$B$56,"잠재",'HRSG 수주 시나리오'!$I$54:$I$56,C$40) -> 0 | D46: =D47+SUMIFS('HRSG 수주 시나리오'!$F$54:$F$56,'HRSG 수주 시나리오'!$B$54:$B$56,"잠재",'HRSG 수주 시나리오'!$I$54:$I$56,D$40) -> 94346.67 | E46: =E47+SUMIFS('HRSG 수주 시나리오'!$F$54:$F$56,'HRSG 수주 시나리오'!$B$54:$B$56,"잠재",'HRSG 수주 시나리오'!$I$54:$I$56,E$40) -> 180368.63 | F46: =F47+SUMIFS('HRSG 수주 시나리오'!$F$54:$F$56,'HRSG 수주 시나리오'!$B$54:$B$56,"잠재",'HRSG 수주 시나리오'!$I$54:$I$56,F$40) -> 0 | G46: =G47+SUMIFS('HRSG 수주 시나리오'!$F$54:$F$56,'HRSG 수주 시나리오'!$B$54:$B$56,"잠재",'HRSG 수주 시나리오'!$I$54:$I$56,G$40) -> 0
B47: Base | C47: =C48+SUMIFS('HRSG 수주 시나리오'!$F$54:$F$56,'HRSG 수주 시나리오'!$B$54:$B$56,"가능",'HRSG 수주 시나리오'!$I$54:$I$56,C$40) -> 0 | D47: =D48+SUMIFS('HRSG 수주 시나리오'!$F$54:$F$56,'HRSG 수주 시나리오'!$B$54:$B$56,"가능",'HRSG 수주 시나리오'!$I$54:$I$56,D$40) -> 94346.67 | E47: =E48+SUMIFS('HRSG 수주 시나리오'!$F$54:$F$56,'HRSG 수주 시나리오'!$B$54:$B$56,"가능",'HRSG 수주 시나리오'!$I$54:$I$56,E$40) -> 97121.572 | F47: =F48+SUMIFS('HRSG 수주 시나리오'!$F$54:$F$56,'HRSG 수주 시나리오'!$B$54:$B$56,"가능",'HRSG 수주 시나리오'!$I$54:$I$56,F$40) -> 0 | G47: =G48+SUMIFS('HRSG 수주 시나리오'!$F$54:$F$56,'HRSG 수주 시나리오'!$B$54:$B$56,"가능",'HRSG 수주 시나리오'!$I$54:$I$56,G$40) -> 0
...

Sheet 요약 재무제표
B1: Estimation
B2: 요약재무제표
B4: (단위: 억원), Base | C4: 100 | O4: =SUM(O23,O29)-O15 -> -21.706776 | P4: =SUM(P23,P29)-P15 -> -40.19508 | Q4: =SUM(Q23,Q29)-Q15 -> 1.671835 | R4: =SUM(R23,R29)-R15 -> 6.8882414
B5: 예상 포괄손익계산서 (요약) | C5: 2022 | D5: 2023 | E5: 2024 | F5: 2025E | G5: 2026E | H5: 2027E | I5: 2028E | K5: 예상 재무상태표 (요약) | L5: 2022 | M5: 2023 | N5: 2024 | O5: 2025E | P5: 2026E | Q5: 2027E | R5: 2028E | V5: Historical | Y5: Projection
B6: 매출액 | C6: =('Expected IS'!E7)/100 -> 3301.9711 | D6: =('Expected IS'!F7)/100 -> 3673.9921 | E6: =('Expected IS'!G7)/100 -> 4047.4104 | F6: =('Expected IS'!H7)/100 -> 8180.6013 | G6: =('Expected IS'!I7)/100 -> 10554.235 | H6: =('Expected IS'!J7)/100 -> 11217.458 | I6: =('Expected IS'!K7)/100 -> 12251.429 | K6: 유동자산 | L6: 2022.3102 | M6: 1880.8048 | N6: 2473.2046 | O6: =SUM(O7:O10) -> 3903.2216 | P6: =SUM(P7:P10) -> 5299.524 | Q6: =SUM(Q7:Q10) -> 5875.6656 | R6: =SUM(R7:R10) -> 6940.9499 | U6: in KRW Mn | V6: 2022 | W6: 2023 | X6: 2024 | Y6: 2025 | Z6: 2026 | AA6: 2027 | AB6: 2028
B7: 매출원가 | C7: =('Expected IS'!E8)/100 -> 2952.6547 | D7: =('Expected IS'!F8)/100 -> 3239.5762 | E7: =('Expected IS'!G8)/100 -> 3456.2302 | F7: =('Expected IS'!H8)/100 -> 7150.096 | G7: =('Expected IS'!I8)/100 -> 8958.557 | H7: =('Expected IS'!J8)/100 -> 9623.2177 | I7: =('Expected IS'!K8)/100 -> 10628.884 | K7: 현금 및 현금성자산 | L7: 236.03234 | M7: 138.72466 | N7: 176.07752 | O7: =F53 -> 348.66451 | P7: =G53 -> 744.30945 | Q7: =H53 -> 1112.901 | R7: =I53 -> 1649.1484 | U7: EBIT | V7: =C11 -> 81.080541 | W7: =D11 -> 150.86698 | X7: =E11 -> 219.27258 | Y7: =F11 -> 638.29657 | Z7: =G11 -> 1122.2078 | AA7: =H11 -> 1071.6382 | AB7: =I11 -> 1037.8846 | AD7: FCFF = NI + NCC + Int*(1-tex rate) - Capex -WC
B8: 매출총이익 | C8: =('Expected IS'!E10)/100 -> 349.31638 | D8: =('Expected IS'!F10)/100 -> 434.41587 | E8: =('Expected IS'!G10)/100 -> 591.18018 | F8: =('Expected IS'!H10)/100 -> 1030.5053 | G8: =('Expected IS'!I10)/100 -> 1595.6778 | H8: =('Expected IS'!J10)/100 -> 1594.2408 | I8: =('Expected IS'!K10)/100 -> 1622.5445 | K8: 매출채권 | L8: 1609.6437 | M8: 1439.2019 | N8: 1891.4084 | O8: =(Y20) -> 3204.5623 | P8: =(Z20) -> 4134.3787 | Q8: =(AA20) -> 4394.1813 | R8: =(AB20) -> 4799.2153 | U8: % effective tax rate | V8: 0.21 | W8: 0.21 | X8: 0.21 | Y8: ='Expected IS'!H33 -> 0.21 | Z8: ='Expected IS'!I33 -> 0.21 | AA8: ='Expected IS'!J33 -> 0.21 | AB8: ='Expected IS'!K33 -> 0.21 | AD8: FCF = NI + NCC - Capex -WC
B9: 판매비와관리비 | C9: =('Expected IS'!E11)/100 -> 268.23584 | D9: =('Expected IS'!F11)/100 -> 283.54888 | E9: =('Expected IS'!G11)/100 -> 371.90759 | F9: =('Expected IS'!H11)/100 -> 392.20871 | G9: =('Expected IS'!I11)/100 -> 473.46999 | H9: =('Expected IS'!J11)/100 -> 522.60258 | I9: =('Expected IS'!K11)/100 -> 584.65989 | K9: 재고자산 | L9: 43.527623 | M9: 55.213445 | N9: 108.05143 | O9: =(Y21) -> 198.11453 | P9: =(Z21) -> 216.37699 | Q9: =(AA21) -> 198.22156 | R9: =(AB21) -> 181.15249 | U9: (-) EBIT법인세 | V9: =V7*V8 -> 17.026914 | W9: =W7*W8 -> 31.682066 | X9: =X7*X8 -> 46.047243 | Y9: =Y7*Y8 -> 134.04228 | Z9: =Z7*Z8 -> 235.66364 | AA9: =AA7*AA8 -> 225.04402 | AB9: =AB7*AB8 -> 217.95578 | AD9: FCF = FCFF - Int*(1-tex rate)
B10: 조정영업이익 | C10: =('Expected IS'!E15)/100 -> 81.080541 | D10: =('Expected IS'!F15)/100 -> 150.86698 | E10: =('Expected IS'!G15)/100 -> 219.27258 | F10: =('Expected IS'!H15)/100 -> 638.29657 | G10: =('Expected IS'!I15)/100 -> 1122.2078 | H10: =('Expected IS'!J15)/100 -> 1071.6382 | I10: =('Expected IS'!K15)/100 -> 1037.8846 | K10: 기타유동자산 | L10: 133.1065 | M10: 247.66479 | N10: 297.66724 | O10: =N10/SUM(N10,N14)*O30 -> 151.8802 | P10: =O10/SUM(O10,O14)*P30 -> 204.45892 | Q10: =P10/SUM(P10,P14)*Q30 -> 170.36177 | R10: =Q10/SUM(Q10,Q14)*R30 -> 311.43367 | U10: NOPAT(세후영업이익) | V10: =V7-V9 -> 64.053627 | W10: =W7-W9 -> 119.18492 | X10: =X7-X9 -> 173.22534 | Y10: =Y7-Y9 -> 504.25429 | Z10: =Z7-Z9 -> 886.54415 | AA10: =AA7-AA9 -> 846.59415 | AB10: =AB7-AB9 -> 819.92887
B11: 영업이익 | C11: =(C10) -> 81.080541 | D11: =(D10) -> 150.86698 | E11: =(E10) -> 219.27258 | F11: =(F10) -> 638.29657 | G11: =(G10) -> 1122.2078 | H11: =(H10) -> 1071.6382 | I11: =(I10) -> 1037.8846 | K11: 비유동자산 | L11: 2471.4332 | M11: 2373.6906 | N11: 2774.5595 | O11: =SUM(O12:O14) -> 2659.8413 | P11: =SUM(P12:P14) -> 2784.2032 | Q11: =SUM(Q12:Q14) -> 2796.6844 | R11: =SUM(R12:R14) -> 3035.9988 | U11: % Yoy Growth | W11: =W10/V10-1 -> 0.86070517 | X11: =X10/W10-1 -> 0.45341665 | Y11: =Y10/X10-1 -> 1.910973 | Z11: =Z10/Y10-1 -> 0.75812913 | AA11: =AA10/Z10-1 -> -0.045062613 | AB11: =AB10/AA10-1 -> -0.031497129
B12: 비영업손익 | C12: =('Expected IS'!E29)/100 -> 12.86204 | D12: =('Expected IS'!F29)/100 -> 21.18717 | E12: =('Expected IS'!G29)/100 -> 8.40821 | F12: =('Expected IS'!H29)/100 -> 8.40821 | G12: =('Expected IS'!I29)/100 -> 8.40821 | H12: =('Expected IS'!J29)/100 -> 8.40821 | I12: =('Expected IS'!K29)/100 -> 8.40821 | K12: 유형자산 | L12: 1960.9198 | M12: 1920.7693 | N12: 2223.3244 | O12: =Y40 -> 2288.3185 | P12: =Z40 -> 2348.9877 | Q12: =AA40 -> 2405.9075 | R12: =AB40 -> 2460.3473 | U12: Change in NWC | V12: =V26 -> 0 | W12: =W26 -> -734.41241 | X12: =X26 -> 371.61774 | Y12: =Y26 -> -294.43955 | Z12: =Z26 -> 135.32106 | AA12: =AA26 -> -39.361017 | AB12: =AB26 -> -44.619731
B13: 금융손익 | C13: =('Expected IS'!E28)/100 -> -289.48852 | D13: =('Expected IS'!F28)/100 -> -119.8834 | E13: =('Expected IS'!G28)/100 -> -263.13946 | F13: =('Expected IS'!H28)/100 -> -285.49173 | G13: =('Expected IS'!I28)/100 -> -285.49173 | H13: =('Expected IS'!J28)/100 -> -285.49173 | I13: =('Expected IS'!K28)/100 -> -285.49173 | K13: 무형자산 | L13: 188.05134 | M13: 170.08757 | N13: 164.58958 | O13: =AVERAGE(L13:N13) -> 174.24283 | P13: =AVERAGE(M13:O13) -> 169.63999 | Q13: =AVERAGE(N13:P13) -> 169.4908 | R13: =AVERAGE(O13:Q13) -> 171.12454 | U13: Net Capex | V13: =V41 -> 35.126903 | W13: =W41 -> 65.798162 | X13: =X41 -> 363.13407 | Y13: =Y41 -> 177.46854 | Z13: =Z41 -> 171.77794 | AA13: =AA41 -> 167.42233 | AB13: =AB41 -> 165.80172
B14: 관계기업등 투자손익 | C14: =('Expected IS'!E30)/100 -> -12.20522 | D14: =('Expected IS'!F30)/100 -> -13.9216 | E14: =('Expected IS'!G30)/100 -> -3.99343 | F14: =('Expected IS'!H30)/100 -> -3.99343 | G14: =('Expected IS'!I30)/100 -> -3.99343 | H14: =('Expected IS'!J30)/100 -> -3.99343 | I14: =('Expected IS'!K30)/100 -> -3.99343 | K14: 기타비유동자산 | L14: 322.46206 | M14: 282.83377 | N14: 386.64546 | O14: =N14/SUM(N10,N14)*O30 -> 197.28 | P14: =O14/SUM(O10,O14)*P30 -> 265.57546 | Q14: =P14/SUM(P10,P14)*Q30 -> 221.28604 | R14: =Q14/SUM(Q10,Q14)*R30 -> 404.52694 | U14: (-) Reinvestment | V14: =V12+V13 -> 35.126903 | W14: =W12+W13 -> -668.61425 | X14: =X12+X13 -> 734.75181 | Y14: =Y12+Y13 -> -116.97102 | Z14: =Z12+Z13 -> 307.099 | AA14: =AA12+AA13 -> 128.06132 | AB14: =AB12+AB13 -> 121.18199
B15: 세전계속사업손익 | C15: =('Expected IS'!E31)/100 -> -207.75115 | D15: =('Expected IS'!F31)/100 -> 38.249159 | E15: =('Expected IS'!G31)/100 -> -39.452096 | F15: =('Expected IS'!H31)/100 -> 357.21962 | G15: =('Expected IS'!I31)/100 -> 841.13084 | H15: =('Expected IS'!J31)/100 -> 790.56122 | I15: =('Expected IS'!K31)/100 -> 756.8077 | K15: 자산총계 | L15: 4493.7433 | M15: 4254.4954 | N15: 5247.7641 | O15: =O11+O6 -> 6563.0629 | P15: =P11+P6 -> 8083.7272 | Q15: =Q11+Q6 -> 8672.35 | R15: =R11+R6 -> 9976.9487 | U15: FCFF(기업잉여현금흐름) | V15: =V10-V14 -> 28.926724 | W15: =W10-W14 -> 787.79917 | X15: =X10-X14 -> -561.52647 | Y15: =Y10-Y14 -> 621.2253 | Z15: =Z10-Z14 -> 579.44515 | AA15: =AA10-AA14 -> 718.53284 | AB15: =AB10-AB14 -> 698.74688
B16: 법인세 비용 | C16: =('Expected IS'!E32)/100 -> -16.573597 | D16: =('Expected IS'!F32)/100 -> -36.388661 | E16: =('Expected IS'!G32)/100 -> -235.30262 | F16: =('Expected IS'!H32)/100 -> 75.016119 | G16: =('Expected IS'!I32)/100 -> 176.63748 | H16: =('Expected IS'!J32)/100 -> 166.01786 | I16: =('Expected IS'!K32)/100 -> 158.92962 | K16: 유동부채 | L16: 3098.9525 | M16: 3211.3515 | N16: 3799.0561 | O16: =SUM(O17:O19) -> 4959.4812 | P16: =SUM(P17:P19) -> 5801.5541 | Q16: =SUM(Q17:Q19) -> 5806.8636 | R16: =SUM(R17:R19) -> 6501.2406 | U16: 이자비용 | V16: =C37 -> 0.92436 | W16: =D37 -> 2.42705 | X16: =E37 -> 1.905745 | Y16: =F37 -> 1.752385 | Z16: =G37 -> 2.0283933 | AA16: =H37 -> 1.8955078 | AB16: =I37 -> 1.8920954
B17: 계속사업이익 | C17: =('Expected IS'!E34)/100 -> -191.17756 | D17: =('Expected IS'!F34)/100 -> 74.637821 | E17: =('Expected IS'!G34)/100 -> 195.85052 | F17: =('Expected IS'!H34)/100 -> 282.2035 | G17: =('Expected IS'!I34)/100 -> 664.49336 | H17: =('Expected IS'!J34)/100 -> 624.54336 | I17: =('Expected IS'!K34)/100 -> 597.87808 | K17: 단기차입금 및 유동성장기부채 | L17: 1544.2791 | M17: 1563.7791 | N17: 1261.4843 | O17: =L17 -> 1544.2791 | P17: =M17 -> 1563.7791 | Q17: =N17 -> 1261.4843 | R17: =O17 -> 1544.2791 | U17: FCF(잉여현금흐름) | V17: =V15+V16 -> 29.851084 | W17: =W15+W16 -> 790.22622 | X17: =X15+X16 -> -559.62073 | Y17: =Y15+Y16 -> 622.97769 | Z17: =Z15+Z16 -> 581.47354 | AA17: =AA15+AA16 -> 720.42835 | AB17: =AB15+AB16 -> 700.63898
B18: 중단사업이익 | C18: 0 | D18: 0 | E18: 0 | F18: 0 | G18: 0 | H18: 0.01 | I18: 0.02 | K18: 매입채무 | L18: 1471.9461 | M18: 1605.3729 | N18: 2325.9805 | O18: =Y23 -> 3303.0295 | P18: =Z23 -> 4115.7872 | Q18: =AA23 -> 4396.7954 | R18: =AB23 -> 4829.3801
B19: 당기순이익 | C19: =C17 -> -191.17756 | D19: =D17 -> 74.637821 | E19: =E17 -> 195.85052 | F19: =F17 -> 282.2035 | G19: =G17 -> 664.49336 | H19: =H17 -> 624.54336 | I19: =I17 -> 597.87808 | K19: 기타유동부채 | L19: 82.727322 | M19: 42.199431 | N19: 211.59123 | O19: =AVERAGE(L19:N19) -> 112.17266 | P19: =AVERAGE(M19:O19) -> 121.98777 | Q19: =AVERAGE(N19:P19) -> 148.58389 | R19: =AVERAGE(O19:Q19) -> 127.58144 | U19: Change in Net Working Capital | V19: 2022 | W19: 2023 | X19: 2024 | Y19: 2025 | Z19: 2026 | AA19: 2027 | AB19: 2028
B20: 지배주주 | C20: 0 | D20: 0 | E20: 0 | F20: 0 | G20: 0 | H20: 0 | I20: 0 | K20: 비유동부채 | L20: 899.40531 | M20: 306.11393 | N20: 284.24241 | O20: =SUM(O21:O22) -> 304.41837 | P20: =SUM(P21:P22) -> 298.25824 | Q20: =SUM(Q21:Q22) -> 295.63967 | R20: =SUM(R21:R22) -> 299.43876 | U20: 매출채권 | V20: =('BS (Yearly)'!E8)/100 -> 1609.6437 | W20: =('BS (Yearly)'!F8)/100 -> 1439.2019 | X20: =('BS (Yearly)'!G8)/100 -> 1891.4084 | Y20: =Y29*Y33/365 -> 3204.5623 | Z20: =Z29*Z33/365 -> 4134.3787 | AA20: =AA29*AA33/365 -> 4394.1813 | AB20: =AB29*AB33/365 -> 4799.2153
B21: 비지배주주 | C21: 0 | D21: 0 | E21: 0 | F21: 0 | G21: 0 | H21: 0 | I21: 0 | K21: 장기차입금 | L21: 576.50654 | M21: 0 | N21: 0 | O21: =N21 -> 0 | P21: =O21 -> 0 | Q21: =P21 -> 0 | R21: =Q21 -> 0 | U21: 재고자산 | V21: =('BS (Yearly)'!E6)/100 -> 43.527623 | W21: =('BS (Yearly)'!F6)/100 -> 55.213445 | X21: =('BS (Yearly)'!G6)/100 -> 108.05143 | Y21: =Y30*Y34/365 -> 198.11453 | Z21: =Z30*Z34/365 -> 216.37699 | AA21: =AA30*AA34/365 -> 198.22156 | AB21: =AB30*AB34/365 -> 181.15249
B22: 총포괄이익 | C22: =(C19)/100 -> -1.9117756 | D22: =(D19)/100 -> 0.74637821 | E22: =(E19)/100 -> 1.9585052 | F22: =(F19)/100 -> 2.822035 | G22: =(G19)/100 -> 6.6449336 | H22: =(H19)/100 -> 6.2454336 | I22: =(I19)/100 -> 5.9787808 | K22: 기타비유동부채 | L22: 322.89876 | M22: 306.11393 | N22: 284.24241 | O22: =AVERAGE(L22:N22) -> 304.41837 | P22: =AVERAGE(M22:O22) -> 298.25824 | Q22: =AVERAGE(N22:P22) -> 295.63967 | R22: =AVERAGE(O22:Q22) -> 299.43876 | U22: 영업용 유동자산 | V22: =V20+V21 -> 1653.1713 | W22: =W20+W21 -> 1494.4153 | X22: =X20+X21 -> 1999.4598 | Y22: =Y20+Y21 -> 3402.6769 | Z22: =Z20+Z21 -> 4350.7557 | AA22: =AA20+AA21 -> 4592.4028 | AB22: =AB20+AB21 -> 4980.3678
B23: 지배주주 | C23: 0 | D23: 0 | E23: 0 | F23: 0 | G23: 0 | H23: 0 | I23: 0 | K23: 부채총계 | L23: 3998.3578 | M23: 3517.4654 | N23: 4083.2985 | O23: =O20+O16 -> 5263.8996 | P23: =P20+P16 -> 6099.8124 | Q23: =Q20+Q16 -> 6102.5033 | R23: =R20+R16 -> 6800.6794 | U23: 매입채무 | V23: =('BS (Yearly)'!D25)/100 -> 896.28975 | W23: =('BS (Yearly)'!E25)/100 -> 1471.9461 | X23: =('BS (Yearly)'!F25)/100 -> 1605.3729 | Y23: =Y31*Y34/365 -> 3303.0295 | Z23: =Z31*Z34/365 -> 4115.7872 | AA23: =AA31*AA34/365 -> 4396.7954 | AB23: =AB31*AB34/365 -> 4829.3801
B24: 비지배주주 | C24: 0 | D24: 0 | E24: 0 | F24: 0 | G24: 0 | H24: 0 | I24: 0 | K24: 지배주주지분 | L24: 493.33303 | M24: 735.44422 | N24: 1163.6119 | O24: =N24+(O27+N27) -> 1276.5952 | P24: =O24+(P27-O27) -> 1941.0886 | Q24: =P24+(Q27-P27) -> 2565.6319 | R24: =Q24+(R27-Q27) -> 3163.51 | U24: 영업용 유동부채 | V24: =V23 -> 896.28975 | W24: =W23 -> 1471.9461 | X24: =X23 -> 1605.3729 | Y24: =Y23 -> 3303.0295 | Z24: =Z23 -> 4115.7872 | AA24: =AA23 -> 4396.7954 | AB24: =AB23 -> 4829.3801
B25: EBITDA | C25: =('Expected IS'!E17)/100 -> 186.64418 | D25: =('Expected IS'!F17)/100 -> 256.81561 | E25: =('Expected IS'!G17)/100 -> 279.85154 | F25: =('Expected IS'!H17)/100 -> 750.77104 | G25: =('Expected IS'!I17)/100 -> 1233.3165 | H25: =('Expected IS'!J17)/100 -> 1182.1407 | I25: =('Expected IS'!K17)/100 -> 1149.2465 | K25: 자본금 | L25: 130 | M25: 154.72188 | N25: 154.72188 | O25: =N25 -> 154.72188 | P25: =O25 -> 154.72188 | Q25: =P25 -> 154.72188 | R25: =Q25 -> 154.72188 | U25: 순운전자본 | V25: =V22-V24 -> 756.88158 | W25: =W22-W24 -> 22.469173 | X25: =X22-X24 -> 394.08692 | Y25: =Y22-Y24 -> 99.647364 | Z25: =Z22-Z24 -> 234.96842 | AA25: =AA22-AA24 -> 195.60741 | AB25: =AB22-AB24 -> 150.98768
B26: FCF | K26: 자본잉여금 | L26: 109.11501 | M26: 260.98611 | N26: 260.2861 | O26: =N26 -> 260.2861 | P26: =O26 -> 260.2861 | Q26: =P26 -> 260.2861 | R26: =Q26 -> 260.2861 | U26: 순운전자본의 변동 | W26: =W25-V25 -> -734.41241 | X26: =X25-W25 -> 371.61774 | Y26: =Y25-X25 -> -294.43955 | Z26: =Z25-Y25 -> 135.32106 | AA26: =AA25-Z25 -> -39.361017 | AB26: =AB25-AA25 -> -44.619731
B27: EBITDA 마진율 (%) | C27: =C25/C6*100 -> 5.652508 | D27: =D25/D6*100 -> 6.990097 | E27: =E25/E6*100 -> 6.9143358 | F27: =F25/F6*100 -> 9.1774554 | G27: =G25/G6*100 -> 11.685513 | H27: =H25/H6*100 -> 10.538401 | I27: =I25/I6*100 -> 9.3805105 | K27: 이익잉여금 | L27: -339.7232 | M27: -271.77552 | N27: -84.61008 | O27: =N27+F19 -> 197.59342 | P27: =O27+G19 -> 862.08678 | Q27: =P27+H19 -> 1486.6301 | R27: =Q27+I19 -> 2084.5082 | U27: Ratio & Assumption
B28: 영업이익률 (%) | C28: =C11/C6*100 -> 2.4555194 | D28: =D11/D6*100 -> 4.1063502 | E28: =E11/E6*100 -> 5.4176019 | F28: =F11/F6*100 -> 7.802563 | G28: =G11/G6*100 -> 10.632773 | H28: =H11/H6*100 -> 9.5533063 | I28: =I11/I6*100 -> 8.4715398 | K28: 비지배주주지분 | L28: 2.0524881 | M28: 1.5857823 | N28: 0.8537268 | O28: =N28/E19*O27 -> 0.8613242 | P28: =O28/F19*P27 -> 2.6312084 | Q28: =P28/G19*Q27 -> 5.8866407 | R28: =Q28/H19*R27 -> 19.647556 | U28: 회전일수
B29: 지배주주귀속 순이익률 (%) | K29: 자본총계 | L29: 495.38552 | M29: 737.03 | N29: 1164.4656 | O29: =SUM(O28,O24) -> 1277.4565 | P29: =SUM(P28,P24) -> 1943.7198 | Q29: =SUM(Q28,Q24) -> 2571.5186 | R29: =SUM(R28,R24) -> 3183.1576 | U29: 매출채권회전일수 | V29: =365*V20/V33 -> 177.93007 | W29: =365*W20/W33 -> 142.98035 | X29: =365*X20/X33 -> 170.56933 | Y29: =W29 -> 142.98035 | Z29: =Y29 -> 142.98035 | AA29: =Z29 -> 142.98035 | AB29: =AA29 -> 142.98035
O30: 349.1602 | P30: 470.03438 | Q30: 391.6478 | R30: 715.96062 | U30: 재고자산회전일수 | V30: =365*V21/V34 -> 5.380779 | W30: =365*W21/W34 -> 6.2208469 | X30: =365*X21/X34 -> 11.410922 | Y30: =X30-($X30-$AB30)/4 -> 10.113403 | Z30: =Y30-($X30-$AB30)/4 -> 8.8158843 | AA30: =Z30-($X30-$AB30)/4 -> 7.5183656 | AB30: =W30 -> 6.2208469
B31: 예상 현금흐름표 (요약) (십억원) | C31: 2022 | D31: 2023 | E31: 2024 | F31: 2025E | G31: 2026E | H31: 2027E | I31: 2028E | K31: 예상 주당가치 및 valuation (요약) | L31: 2022 | M31: 2023 | N31: 2024 | O31: 2025E | P31: 2026E | Q31: 2027E | R31: 2028E | U31: 매입채무회전일수 | V31: =365*V23/V34 -> 110.79716 | W31: =365*W23/W34 -> 165.84279 | X31: =365*X23/X34 -> 169.53764 | Y31: =X31-($X31-$AB31)/4 -> 168.61393 | Z31: =Y31-($X31-$AB31)/4 -> 167.69021 | AA31: =Z31-($X31-$AB31)/4 -> 166.7665 | AB31: =W31 -> 165.84279
