Workbook

Sheet Estimation >>>
B2: VISA Valuation&Estimation Logic
B7: RFS Research Team 2

Sheet DCF Summary
A1: VISA
A2: DCF Valuation
A3: (In USD millions)
E5: 2020 | F5: 2021 | G5: 2022 | H5: 2023 | I5: 2024 | J5: 2025 | K5: 2026 | L5: 2027 | M5: 2028 | N5: 2029 | O5: 2030 | P5: Terminal Value
A6: 매출액 | E6: ='IS(Yearly)'!C6 -> 21846 | F6: ='IS(Yearly)'!D6 -> 24105 | G6: ='IS(Yearly)'!E6 -> 29310 | H6: ='IS(Yearly)'!F6 -> 32653 | I6: ='IS(Yearly)'!G6 -> 35926 | J6: =매출액!H7 -> 40006.27 | K6: =매출액!I7 -> 44476.037 | L6: =매출액!J7 -> 49343.119 | M6: =매출액!K7 -> 54598.474 | N6: =매출액!L7 -> 60480.687 | O6: =매출액!M7 -> 67081.16
A7: 영업비용 | E7: ='IS(Yearly)'!C11 -> 7765 | F7: ='IS(Yearly)'!D11 -> 8301 | G7: ='IS(Yearly)'!E11 -> 10497 | H7: ='IS(Yearly)'!F11 -> 11653 | I7: ='IS(Yearly)'!G11 -> 12331 | J7: =IS!I8 -> 12961.248 | K7: =IS!J8 -> 13561.501 | L7: =IS!K8 -> 14335.187 | M7: =IS!L8 -> 15177.682 | N7: =IS!M8 -> 16133.707 | O7: =IS!N8 -> 17250.283 | S7: DCF Valuation | V7: (단위: $ Mn, %)
A8: 일반판매관리비 | E8: ='IS(Yearly)'!C12 -> 2067 | F8: ='IS(Yearly)'!D12 -> 2121 | G8: ='IS(Yearly)'!E12 -> 2530 | H8: ='IS(Yearly)'!F12 -> 2671 | I8: ='IS(Yearly)'!G12 -> 3158 | J8: =IS!I9 -> 3617.7366 | K8: =IS!J9 -> 4088.4844 | L8: =IS!K9 -> 4718.423 | M8: =IS!L9 -> 5402.2944 | N8: =IS!M9 -> 6184.4208 | O8: =IS!N9 -> 7109.1388 | S8: WACC | V8: =F30 -> 0.080215443
A9: 감가상각&무형자산상각비 | E9: ='IS(Yearly)'!C16 -> 767 | F9: ='IS(Yearly)'!D16 -> 804 | G9: ='IS(Yearly)'!E16 -> 861 | H9: ='IS(Yearly)'!F16 -> 943 | I9: ='IS(Yearly)'!G16 -> 1034 | J9: =IS!I11 -> 1204.5118 | K9: =IS!J11 -> 1334.0163 | L9: =IS!K11 -> 1477.764 | M9: =IS!L11 -> 1636.3877 | N9: =IS!M11 -> 1810.2865 | O9: =IS!N11 -> 2002.1442 | S9: Terminal growth rate(g) | V9: =F29 -> 0.04
A10: 기타 영업비용 | E10: ='IS(Yearly)'!C17 -> 4931 | F10: ='IS(Yearly)'!D17 -> 5376 | G10: ='IS(Yearly)'!E17 -> 7106 | H10: ='IS(Yearly)'!F17 -> 8039 | I10: ='IS(Yearly)'!G17 -> 8139 | J10: =IS!I13 -> 8139 | K10: =IS!J13 -> 8139 | L10: =IS!K13 -> 8139 | M10: =IS!L13 -> 8139 | N10: =IS!M13 -> 8139 | O10: =IS!N13 -> 8139 | S10: ∑ PV of FCF | V10: =F34 -> 121914.79
A11: 영업이익 | E11: =E6-E7 -> 14081 | F11: =F6-F7 -> 15804 | G11: =G6-G7 -> 18813 | H11: =H6-H7 -> 21000 | I11: =I6-I7 -> 23595 | J11: =J6-J7 -> 27045.022 | K11: =K6-K7 -> 30914.536 | L11: =L6-L7 -> 35007.932 | ... O11: =O6-O7 -> 49830.878 | S11: PV of TV | V11: =F35 -> 585188.69
A12: (-) 법인세 비용 | E12: ='IS(Yearly)'!C27 -> 2924 | F12: ='IS(Yearly)'!D27 -> 3752 | G12: ='IS(Yearly)'!E27 -> 3179 | H12: ='IS(Yearly)'!F27 -> 3764 | I12: ='IS(Yearly)'!G27 -> 4173 | J12: =IS!I21 -> 4752.5462 | K12: =IS!J21 -> 5437.4462 | L12: =IS!K21 -> 6163.1294 | M12: =IS!L21 -> 6946.0737 | N12: =IS!M21 -> 7819.5505 | O12: =IS!N21 -> 8791.6203 | S12: 영업가치 | V12: =V10+V11 -> 707103.48
A13: (-) 영업외손실 | E13: ='IS(Yearly)'!C19 -> 291 | F13: ='IS(Yearly)'!D19 -> -259 | G13: ='IS(Yearly)'!E19 -> 677 | H13: ='IS(Yearly)'!F19 -> -37 | I13: ='IS(Yearly)'!G19 -> -321 | J13: =IS!I19 -> -500.2 | K13: =IS!J19 -> -500.2 | L13: =IS!K19 -> -500.2 | M13: =IS!L19 -> -500.2 | N13: =IS!M19 -> -500.2 | O13: =IS!N19 -> -500.2 | S13: (+) 비영업자산가치 | V13: =F37 -> 32048
A14: 세후영업이익(NOPLAT) | E14: =E11-E12-E13 -> 10866 | F14: =F11-F12-F13 -> 12311 | G14: =G11-G12-G13 -> 14957 | H14: =H11-H12-H13 -> 17273 | I14: =I11-I12-I13 -> 19743 | J14: =J11-J12-J13 -> 22792.676 | K14: =K11-K12-K13 -> 25977.29 | L14: =L11-L12-L13 -> 29345.003 | ... O14: =O11-O12-O13 -> 41539.457 | S14: (-) 타인자본가치 (순차입금) | V14: =F38 -> 21671
A15: (+) 상각비 | E15: ='FA Schedule'!D24 -> 80 | F15: ='FA Schedule'!E24 -> 83 | G15: ='FA Schedule'!F24 -> 90 | H15: ='FA Schedule'!G24 -> 76 | I15: ='FA Schedule'!H24 -> 79 | J15: ='FA Schedule'!I24 -> 82.097231 | K15: ='FA Schedule'!J24 -> 85.207477 | L15: ='FA Schedule'!K24 -> 88.67608 | ... O15: ='FA Schedule'!N24 -> 101.5653 | S15: 주주가치(Equity Value) | V15: =V13+V12-V14 -> 717480.48
A16: 매출 대비 비중 | E16: =E15/E6 -> 0.0036619976 | F16: =F15/F6 -> 0.003443269 | G16: =G15/G6 -> 0.0030706244 | H16: =H15/H6 -> 0.0023275044 | I16: =I15/I6 -> 0.0021989645 | J16: =J15/J6 -> 0.0020521091 | K16: =K15/K6 -> 0.0019158064 | L16: =L15/L6 -> 0.0017971316 | ... O16: =O15/O6 -> 0.001514066 | S16: 발행주식수 | V16: =F40 -> 1698682527
S17: 적정주가: | V17: =V15*1000000/V16 -> 422.37468
A18: (-) 순운전자본(NWC) 변동 (기말-기초) | F18: ='Change in NWC'!E19 -> -337 | G18: ='Change in NWC'!F19 -> 1441 | H18: ='Change in NWC'!G19 -> 995 | I18: ='Change in NWC'!H19 -> 710 | J18: ='Change in NWC'!I19 -> 399.61113 | K18: ='Change in NWC'!J19 -> 305.97508 | L18: ='Change in NWC'!K19 -> 329.1067 | M18: ='Change in NWC'!L19 -> 355.12114 | ... O18: ='Change in NWC'!N19 -> 444.036 | S18: 현재주가: | V18: 344.47
A19: 기초 순운전자본 | F19: ='Change in NWC'!D17 -> 2395 | G19: ='Change in NWC'!E17 -> 2058 | H19: ='Change in NWC'!F17 -> 3499 | I19: ='Change in NWC'!G17 -> 4494 | J19: =I20 -> 5204 | K19: =J20 -> 5603.6111 | L19: =K20 -> 5909.5862 | M19: =L20 -> 6238.6929 | N19: =M20 -> 6593.814 | O19: =N20 -> 6990.8525 | S19: 상승(하락)여력: | V19: =V17/V18-1 -> 0.22615808
A20: 기말 순운전자본 | F20: ='Change in NWC'!E17 -> 2058 | G20: ='Change in NWC'!F17 -> 3499 | H20: ='Change in NWC'!G17 -> 4494 | I20: ='Change in NWC'!H17 -> 5204 | J20: ='Change in NWC'!I17 -> 5603.6111 | K20: ='Change in NWC'!J17 -> 5909.5862 | L20: ='Change in NWC'!K17 -> 6238.6929 | M20: ='Change in NWC'!L17 -> 6593.814 | ... O20: ='Change in NWC'!N17 -> 7434.8885 | S20: 투자의견 | V20: BUY
A21: 순운전자본 증감 매출 대비 비중 | F21: =F18/F6 -> -0.013980502 | G21: =G18/G6 -> 0.049164108 | H21: =H18/H6 -> 0.030471932 | I21: =I18/I6 -> 0.019762846
A23: (-) Capex | F23: ='FA Schedule'!D31 -> 2091 | G23: ='FA Schedule'!E31 -> 1201 | H23: ='FA Schedule'!F31 -> 564 | I23: ='FA Schedule'!G31 -> 2402 | J23: ='FA Schedule'!H31 -> 3547 | K23: ='FA Schedule'!I31 -> 3469.7025 | L23: ='FA Schedule'!J31 -> 3857.3607 | M23: ='FA Schedule'!K31 -> 4279.4778 | ... O23: ='FA Schedule'!M31 -> 5245.4275
A24: 매출 대비 비중 | F24: =F23/F6 -> 0.086745488 | G24: =G23/G6 -> 0.040975776 | H24: =H23/H6 -> 0.017272532 | I24: =I23/I6 -> 0.066859656 | J24: =J23/J6 -> 0.088661102 | K24: =K23/K6 -> 0.078012852 | L24: =L23/L6 -> 0.078174236 | M24: =M23/M6 -> 0.078380904 | ... O24: =O23/O6 -> 0.078195241
A26: 잉여현금흐름(FCF) | F26: =F14+F15-F18-F23 -> 10640 | G26: =G14+G15-G18-G23 -> 12405 | H26: =H14+H15-H18-H23 -> 15790 | I26: =I14+I15-I18-I23 -> 16710 | J26: =J14+J15-J18-J23 -> 18928.162 | K26: =K14+K15-K18-K23 -> 22286.82 | L26: =L14+L15-L18-L23 -> 25247.212 | M26: =M14+M15-M18-M23 -> 28432.854 | ... O26: =O14+O15-O18-O23 -> 35951.559 | P26: =(O26*(1+F29))/(F30-F29) -> 929732.93
A28: 잔존가치(Terminal Value) | F28: =P26 -> 929732.93
A29: 영구성장률(g) | F29: 0.04
A30: WACC(Wacc sheet 참고) | F30: =WACC!E15 -> 0.080215443
A31: 현재가치 계수 | J31: =1/(1+$F$30)^J32 -> 0.92574126 | K31: =1/(1+$F$30)^K32 -> 0.85699687 | L31: =1/(1+$F$30)^L32 -> 0.79335736 | M31: =1/(1+$F$30)^M32 -> 0.73444364 | N31: =1/(1+$F$30)^N32 -> 0.67990478 | O31: =1/(1+$F$30)^O32 -> 0.6294159
A32: 연도 | J32: 1 | K32: 2 | L32: 3 | M32: 4 | N32: 5 | O32: 6
A33: 추정연도(2025~2029) FCF의 현재가치 | J33: =J26*J31 -> 17522.58 | K33: =K26*K31 -> 19099.735 | L33: =L26*L31 -> 20030.061 | M33: =M26*M31 -> 20882.329 | N33: =N26*N31 -> 21751.606 | O33: =O26*O31 -> 22628.483
A34: 추정연도 FCF의 현재가치의 합 | F34: =SUM(J33:O33) -> 121914.79
A35: 잔존가치(Terminal Value)의 현재가치 | F35: =F28*O31 -> 585188.69
A36: 기업가치(EV) | F36: =F34+F35 -> 707103.48
A37: (+) 비영업용 자산 가치 | F37: 32048
A38: (-) 타인자본가치 (순차입금) | F38: =WACC!E23 -> 21671
A39: 보통주 자기자본의 가치(주주가치) | F39: =F36+F37-F38 -> 717480.48
A40: (÷) 발행주식수 | F40: =WACC!E26 -> 1698682527
A42: 목표 가격(Target Price,$) | F42: =F39*1000000/F40 -> 422.37468
A43: 시가총액($mn) | F43: =F39 -> 717480.48

Sheet IS
A1: VISA
A2: Income Statement
A3: (In USD millions)
A5: Historical | I5: Pro Forma
D6: 2020A | E6: 2021A | F6: 2022A | G6: 2023A | H6: 2024A | I6: 2025E | J6: 2026E | K6: 2027E | L6: 2028E | M6: 2029E | N6: 2030E
A7: 매출액 | D7: ='IS(Yearly)'!C6 -> 21846 | E7: ='IS(Yearly)'!D6 -> 24105 | F7: ='IS(Yearly)'!E6 -> 29310 | G7: ='IS(Yearly)'!F6 -> 32653 | H7: ='IS(Yearly)'!G6 -> 35926 | I7: =매출액!H7 -> 40006.27 | J7: =매출액!I7 -> 44476.037 | K7: =매출액!J7 -> 49343.119 | L7: =매출액!K7 -> 54598.474 | M7: =매출액!L7 -> 60480.687 | N7: =매출액!M7 -> 67081.16
B8: (-) 영업비용 | D8: ='IS(Yearly)'!C11 -> 7765 | E8: ='IS(Yearly)'!D11 -> 8301 | F8: ='IS(Yearly)'!E11 -> 10497 | G8: ='IS(Yearly)'!F11 -> 11653 | H8: ='IS(Yearly)'!G11 -> 12331 | I8: ='비용 추정'!I7 -> 12961.248 | J8: ='비용 추정'!J7 -> 13561.501 | K8: ='비용 추정'!K7 -> 14335.187 | L8: ='비용 추정'!L7 -> 15177.682 | M8: ='비용 추정'!M7 -> 16133.707 | N8: ='비용 추정'!N7 -> 17250.283
B9: (-) 일반판매관리비 | D9: ='IS(Yearly)'!C12 -> 2067 | E9: ='IS(Yearly)'!D12 -> 2121 | F9: ='IS(Yearly)'!E12 -> 2530 | G9: ='IS(Yearly)'!F12 -> 2671 | H9: ='IS(Yearly)'!G12 -> 3158 | I9: ='비용 추정'!I9 -> 3617.7366 | J9: ='비용 추정'!J9 -> 4088.4844 | K9: ='비용 추정'!K9 -> 4718.423 | L9: ='비용 추정'!L9 -> 5402.2944 | M9: ='비용 추정'!M9 -> 6184.4208 | N9: ='비용 추정'!N9 -> 7109.1388
B10: % of sales | D10: =D9/D$7 -> 0.094616863 | E10: =E9/E$7 -> 0.087990044 | F10: =F9/F$7 -> 0.086318663 | G10: =G9/G$7 -> 0.081799528 | H10: =H9/H$7 -> 0.087902912 | I10: =I9/I$7 -> 0.09042924 | J10: =J9/J$7 -> 0.091925557 | K10: =K9/K$7 -> 0.095624741 | ... N10: =N9/N$7 -> 0.10597817
B11: (-) 감가상각&무형자산상각 | D11: ='IS(Yearly)'!C16 -> 767 | E11: ='IS(Yearly)'!D16 -> 804 | F11: ='IS(Yearly)'!E16 -> 861 | G11: ='IS(Yearly)'!F16 -> 943 | H11: ='IS(Yearly)'!G16 -> 1034 | I11: ='FA Schedule'!I33 -> 1204.5118 | J11: ='FA Schedule'!J33 -> 1334.0163 | K11: ='FA Schedule'!K33 -> 1477.764 | L11: ='FA Schedule'!L33 -> 1636.3877 | M11: ='FA Schedule'!M33 -> 1810.2865 | N11: ='FA Schedule'!N33 -> 2002.1442
B12: % of sales | D12: =D11/D$7 -> 0.035109402 | E12: =E11/E$7 -> 0.033354076 | F12: =F11/F$7 -> 0.02937564 | G12: =G11/G$7 -> 0.028879429 | H12: =H11/H$7 -> 0.028781384 | I12: =I11/I$7 -> 0.030108076 | J12: =J11/J$7 -> 0.029994046 | K12: =K11/K$7 -> 0.029948735 | ... N12: =N11/N$7 -> 0.029846595
B13: (-) 기타 영업비용 | D13: ='IS(Yearly)'!C17 -> 4931 | E13: ='IS(Yearly)'!D17 -> 5376 | F13: ='IS(Yearly)'!E17 -> 7106 | G13: ='IS(Yearly)'!F17 -> 8039 | H13: ='IS(Yearly)'!G17 -> 8139 | I13: ='비용 추정'!I17 -> 8139 | J13: ='비용 추정'!J17 -> 8139 | K13: ='비용 추정'!K17 -> 8139 | L13: ='비용 추정'!L17 -> 8139 | M13: ='비용 추정'!M17 -> 8139 | N13: ='비용 추정'!N17 -> 8139
B14: % of sales | D14: =D13/D$7 -> 0.22571638 | E14: =E13/E$7 -> 0.22302427 | F14: =F13/F$7 -> 0.24244285 | G14: =G13/G$7 -> 0.24619484 | H14: =H13/H$7 -> 0.22654902 | I14: =I13/I$7 -> 0.20344311 | J14: =J13/J$7 -> 0.18299742 | K14: =K13/K$7 -> 0.16494701 | ... N14: =N13/N$7 -> 0.12133064
A15: 영업이익 | D15: =D7-D8 -> 14081 | E15: =E7-E8 -> 15804 | F15: =F7-F8 -> 18813 | G15: =G7-G8 -> 21000 | H15: =H7-H8 -> 23595 | I15: =I7-I8 -> 27045.022 | J15: =J7-J8 -> 30914.536 | K15: =K7-K8 -> 35007.932 | ... N15: =N7-N8 -> 49830.878
B16: OPM | D16: =D15/D7 -> 0.64455736 | E16: =E15/E7 -> 0.65563161 | F16: =F15/F7 -> 0.64186285 | G16: =G15/G7 -> 0.64312621 | H16: =H15/H7 -> 0.65676669 | I16: =I15/I7 -> 0.67601957 | J16: =J15/J7 -> 0.69508298 | K16: =K15/K7 -> 0.70947951 | ... N16: =N15/N7 -> 0.7428446
B17: (+) D&A | D17: ='FA Schedule'!D33 -> 767 | E17: ='FA Schedule'!E33 -> 804 | F17: ='FA Schedule'!F33 -> 861 | G17: ='FA Schedule'!G33 -> 943 | H17: ='FA Schedule'!H33 -> 1034 | I17: ='FA Schedule'!I33 -> 1204.5118 | J17: ='FA Schedule'!J33 -> 1334.0163 | K17: ='FA Schedule'!K33 -> 1477.764 | ... N17: ='FA Schedule'!N33 -> 2002.1442
A18: EBITDA | D18: =D15+D17 -> 14848 | E18: =E15+E17 -> 16608 | F18: =F15+F17 -> 19674 | G18: =G15+G17 -> 21943 | H18: =H15+H17 -> 24629 | I18: =I15+I17 -> 28249.534 | J18: =J15+J17 -> 32248.552 | K18: =K15+K17 -> 36485.696 | ... N18: =N15+N17 -> 51833.022
B19: (+) 영업외손익 | D19: ='IS(Yearly)'!C25 -> -225 | E19: ='IS(Yearly)'!D25 -> -772 | F19: ='IS(Yearly)'!E25 -> 139 | G19: ='IS(Yearly)'!F25 -> -681 | H19: ='IS(Yearly)'!G25 -> -962 | I19: =AVERAGE(D19:H19) -> -500.2 | J19: =I19 -> -500.2 | K19: =J19 -> -500.2 | L19: =K19 -> -500.2 | M19: =L19 -> -500.2 | N19: =M19 -> -500.2
A20: 법인세비용차감전순이익(손실) | D20: =D18+D19 -> 14623 | E20: =E18+E19 -> 15836 | F20: =F18+F19 -> 19813 | G20: =G18+G19 -> 21262 | H20: =H18+H19 -> 23667 | I20: =I18+I19 -> 27749.334 | J20: =J18+J19 -> 31748.352 | K20: =K18+K19 -> 35985.496 | ... N20: =N18+N19 -> 51332.822
B21: (-) 법인세비용 | D21: ='IS(Yearly)'!C27 -> 2924 | E21: ='IS(Yearly)'!D27 -> 3752 | F21: ='IS(Yearly)'!E27 -> 3179 | G21: ='IS(Yearly)'!F27 -> 3764 | H21: ='IS(Yearly)'!G27 -> 4173 | I21: =I20*I37 -> 4752.5462 | J21: =J20*J37 -> 5437.4462 | K21: =K20*K37 -> 6163.1294 | L21: =L20*L37 -> 6946.0737 | M21: =M20*M37 -> 7819.5505 | N21: =N20*N37 -> 8791.6203
A22: 당기순이익 | D22: =D20-D21 -> 11699 | E22: =E20-E21 -> 12084 | F22: =F20-F21 -> 16634 | G22: =G20-G21 -> 17498 | H22: =H20-H21 -> 19494 | I22: =I20-I21 -> 22996.787 | J22: =J20-J21 -> 26310.906 | K22: =K20-K21 -> 29822.367 | ... N22: =N20-N21 -> 42541.201
A25: Ratio and Assumption
A26: 매출액성장률 Yoy | E26: =(E7-D7)/D7 -> 0.10340566 | F26: =(F7-E7)/E7 -> 0.2159303 | G26: =(G7-F7)/F7 -> 0.11405664 | H26: =H7/G7-1 -> 0.10023581 | I26: =I7/H7-1 -> 0.1135743 | J26: =J7/I7-1 -> 0.11172664 | K26: =K7/J7-1 -> 0.10943158 | L26: =L7/K7-1 -> 0.10650633 | M26: =M7/L7-1 -> 0.10773585 | N26: =N7/M7-1 -> 0.10913357
A27: EBIT Yoy | E27: =(E15-D15)/D15 -> 0.12236347 | F27: =(F15-E15)/E15 -> 0.19039484 | G27: =(G15-F15)/F15 -> 0.1162494 | H27: =H15/G15-1 -> 0.12357143 | I27: =I15/H15-1 -> 0.14621834 | J27: =J15/I15-1 -> 0.14307676 | K27: =K15/J15-1 -> 0.13241009 | L27: =L15/K15-1 -> 0.12605312 | M27: =M15/L15-1 -> 0.12496421 | N27: =N15/M15-1 -> 0.12365888
A28: EBITDA Yoy | E28: =(E18-D18)/D18 -> 0.11853448 | F28: =(F18-E18)/E18 -> 0.18460983 | G28: =(G18-F18)/F18 -> 0.11532988 | H28: =(H18-G18)/G18 -> 0.12240806 | I28: =(I18-H18)/H18 -> 0.14700287 | J28: =(J18-I18)/I18 -> 0.14156051 | K28: =(K18-J18)/J18 -> 0.13139022 | L28: =(L18-K18)/K18 -> 0.12529521 | ... N28: =(N18-M18)/M18 -> 0.12296559
A29: 세전이익 Yoy | E29: =(E20-D20)/D20 -> 0.082951515 | F29: =(F20-E20)/E20 -> 0.25113665 | G29: =(G20-F20)/F20 -> 0.073133801 | H29: =(H20-G20)/G20 -> 0.1131126 | I29: =(I20-H20)/H20 -> 0.17249054 | J29: =(J20-I20)/I20 -> 0.14411224 | K29: =(K20-J20)/J20 -> 0.13346029 | L29: =(L20-K20)/K20 -> 0.12703682 | ... N29: =(N20-M20)/M20 -> 0.12431275
A30: 당기순이익 Yoy | E30: =(E22-D22)/D22 -> 0.032908796 | F30: =(F22-E22)/E22 -> 0.37653095 | G30: =(G22-F22)/F22 -> 0.051941806 | H30: =(H22-G22)/G22 -> 0.11407018 | I30: =(I22-H22)/H22 -> 0.17968541 | J30: =(J22-I22)/I22 -> 0.14411224 | K30: =(K22-J22)/J22 -> 0.13346029 | L30: =(L22-K22)/K22 -> 0.12703682 | ... N30: =(N22-M22)/M22 -> 0.12431275
A32: EBIT margin | D32: =D15/D7 -> 0.64455736 | E32: =E15/E7 -> 0.65563161 | F32: =F15/F7 -> 0.64186285 | G32: =G15/G7 -> 0.64312621 | H32: =H15/H7 -> 0.65676669 | I32: =I15/I7 -> 0.67601957 | J32: =J15/J7 -> 0.69508298 | K32: =K15/K7 -> 0.70947951 | ... N32: =N15/N7 -> 0.7428446
A33: EBITDA margin | D33: =D18/D7 -> 0.67966676 | E33: =E18/E7 -> 0.68898569 | F33: =F18/F7 -> 0.67123849 | G33: =G18/G7 -> 0.67200564 | H33: =H18/H7 -> 0.68554807 | I33: =I18/I7 -> 0.70612765 | J33: =J18/J7 -> 0.72507702 | K33: =K18/K7 -> 0.73942825 | ... N33: =N18/N7 -> 0.77269119
A34: 영업비용율 | D34: =D8/D7 -> 0.35544264 | E34: =E8/E7 -> 0.34436839 | F34: =F8/F7 -> 0.35813715 | G34: =G8/G7 -> 0.35687379 | H34: =H8/H7 -> 0.34323331 | I34: =H34 -> 0.34323331 | J34: =I34 -> 0.34323331 | K34: =J34 -> 0.34323331 | L34: =K34 -> 0.34323331 | M34: =L34 -> 0.34323331 | N34: =M34 -> 0.34323331
A35: 판관비율 | D35: =D9/D7 -> 0.094616863 | E35: =E9/E7 -> 0.087990044 | F35: =F9/F7 -> 0.086318663 | G35: =G9/G7 -> 0.081799528 | H35: =H9/H7 -> 0.087902912 | I35: =H35 -> 0.087902912 | J35: =I35 -> 0.087902912 | K35: =J35 -> 0.087902912 | L35: =K35 -> 0.087902912 | M35: =L35 -> 0.087902912 | N35: =M35 -> 0.087902912
A36: D&A/Sales | D36: =D17/D7 -> 0.035109402 | E36: =E17/E7 -> 0.033354076 | F36: =F17/F7 -> 0.02937564 | G36: =G17/G7 -> 0.028879429 | H36: =H17/H7 -> 0.028781384 | I36: =I17/I7 -> 0.030108076 | J36: =J17/J7 -> 0.029994046 | K36: =K17/K7 -> 0.029948735 | ... N36: =N17/N7 -> 0.029846595
A37: 법인세율 | D37: =D21/D20 -> 0.19995897 | E37: =E21/E20 -> 0.23692852 | F37: =F21/F20 -> 0.16045021 | G37: =G21/G20 -> 0.17702944 | H37: =H21/H20 -> 0.17632146 | I37: =AVERAGE(F37:H37) -> 0.17126704 | J37: =I37 -> 0.17126704 | K37: =J37 -> 0.17126704 | L37: =K37 -> 0.17126704 | M37: =L37 -> 0.17126704 | N37: =M37 -> 0.17126704

Sheet FA Schedule
A1: VISA
A2: Asset Schedule
A3: (In USD millions)
A5: Historical | I5: Pro Forma | P5: Description
D6: 2020A | E6: 2021A | F6: 2022A | G6: 2023A | H6: 2024A | I6: 2025E | J6: 2026E | K6: 2027E | L6: 2028E | M6: 2029E | N6: 2030E
A7: 유형자산 | D7: ='BS 표준화'!C23 -> 2737 | E7: ='BS 표준화'!D23 -> 3230 | F7: ='BS 표준화'!E23 -> 3703 | G7: ='BS 표준화'!F23 -> 3913 | H7: ='BS 표준화'!G23 -> 4697 | I7: =I16 -> 5225.9255 | J7: =J16 -> 5812.9554 | K7: =K16 -> 6460.605 | L7: =L16 -> 7170.4149 | M7: =M16 -> 7953.406 | N7: =N16 -> 8821.7383
A8: 무형자산 | D8: ='BS 표준화'!C29 -> 43718 | E8: ='BS 표준화'!D29 -> 43622 | F8: ='BS 표준화'!E29 -> 42852 | G8: ='BS 표준화'!F29 -> 44101 | H8: ='BS 표준화'!G29 -> 45830 | I8: =I25 -> 47566.265 | J8: =J25 -> 49502.58 | K8: =K25 -> 51656.644 | L8: =L25 -> 54045.715 | M8: =M25 -> 56697.865 | N8: =N25 -> 59645.269
A9: 기타 | D9: =D10-SUM(D7:D8) -> 7165 | E9: =E10-SUM(E7:E8) -> 3535 | F9: =F10-SUM(F7:F8) -> 5186 | G9: =G10-SUM(G7:G8) -> 5118 | H9: =H10-SUM(H7:H8) -> 11102 | I9: =AVERAGE(F9:H9) -> 7135.3333 | J9: =AVERAGE(G9:I9) -> 7785.1111 | K9: =AVERAGE(H9:J9) -> 8674.1481 | L9: =AVERAGE(I9:K9) -> 7864.8642 | M9: =AVERAGE(J9:L9) -> 8108.0412 | N9: =AVERAGE(K9:M9) -> 8215.6845 | P9: 직전 3개년 Average flat 적용.
A10: 비유동자산 | D10: ='BS(Yearly)'!B17+'BS(Yearly)'!B22+'BS(Yearly)'!B26+'BS(Yearly)'!B28+'BS(Yearly)'!B25+'BS(Yearly)'!B31 -> 53620 | E10: ='BS(Yearly)'!C9+'BS(Yearly)'!C17+'BS(Yearly)'!C22+'BS(Yearly)'!C23+'BS(Yearly)'!C24 -> 50387 | F10: ='BS(Yearly)'!D9+'BS(Yearly)'!D17+'BS(Yearly)'!D22+'BS(Yearly)'!D23+'BS(Yearly)'!D24 -> 51741 | G10: ='BS(Yearly)'!E9+'BS(Yearly)'!E17+'BS(Yearly)'!E22+'BS(Yearly)'!E23+'BS(Yearly)'!E24 -> 53132 | H10: ='BS(Yearly)'!F9+'BS(Yearly)'!F17+'BS(Yearly)'!F22+'BS(Yearly)'!F23+'BS(Yearly)'!F24 -> 61629 | I10: =SUM(I7:I9) -> 59927.524 | J10: =SUM(J7:J9) -> 63100.646 | K10: =SUM(K7:K9) -> 66791.397 | L10: =SUM(L7:L9) -> 69080.994 | M10: =SUM(M7:M9) -> 72759.312 | N10: =SUM(N7:N9) -> 76682.691
A12: 유형자산 Schedule
A13: 기초 유형자산 | D13: 2695 | E13: =D16 -> 2737 | F13: =E16 -> 3230 | G13: =F16 -> 3703 | H13: =G16 -> 3913 | I13: =H16 -> 4697 | J13: =I16 -> 5225.9255 | K13: =J16 -> 5812.9554 | L13: =K16 -> 6460.605 | ... N13: =M16 -> 7953.406
A14: Capex | D14: =D16+D15-D13 -> 729 | E14: =E16+E15-E13 -> 1214 | F14: =F16+F15-F13 -> 1244 | G14: =G16+G15-G13 -> 1077 | H14: =H16+H15-H13 -> 1739 | I14: =매출액!H7*I18 -> 1651.3401 | J14: =매출액!I7*J18 -> 1835.8388 | K14: =매출액!J7*K18 -> 2036.7375 | L14: =매출액!K7*L18 -> 2253.6629 | M14: =매출액!L7*M18 -> 2496.4632 | N14: =매출액!M7*N18 -> 2768.9112
A15: 감가상각비 | D15: ='IS(Yearly)'!C68 -> 687 | E15: ='IS(Yearly)'!D68 -> 721 | F15: ='IS(Yearly)'!E68 -> 771 | G15: ='IS(Yearly)'!F68 -> 867 | H15: ='IS(Yearly)'!G68 -> 955 | I15: =I13*I19 -> 1122.4146 | J15: =J13*J19 -> 1248.8088 | K15: =K13*K19 -> 1389.0879 | L15: =L13*L19 -> 1543.853 | M15: =M13*M19 -> 1713.4721 | N15: =N13*N19 -> 1900.5789
A16: 기말 유형자산 | D16: =D7 -> 2737 | E16: =E7 -> 3230 | F16: =F7 -> 3703 | G16: =G7 -> 3913 | H16: =H7 -> 4697 | I16: =I13+I14-I15 -> 5225.9255 | J16: =J13+J14-J15 -> 5812.9554 | K16: =K13+K14-K15 -> 6460.605 | L16: =L13+L14-L15 -> 7170.4149 | M16: =M13+M14-M15 -> 7953.406 | N16: =N13+N14-N15 -> 8821.7383
A18: 매출액 대비 Capex | D18: =D14/'IS(Yearly)'!C6 -> 0.033369953 | E18: =E14/'IS(Yearly)'!D6 -> 0.050362995 | F18: =F14/'IS(Yearly)'!E6 -> 0.042442852 | G18: =G14/'IS(Yearly)'!F6 -> 0.032983187 | H18: =H14/'IS(Yearly)'!G6 -> 0.048405055 | I18: =AVERAGE(F18:H18) -> 0.041277031 | J18: =I18 -> 0.041277031 | K18: =J18 -> 0.041277031 | L18: =K18 -> 0.041277031 | M18: =L18 -> 0.041277031 | N18: =M18 -> 0.041277031 | P18: 직전 3개년 Average flat 적용.
A19: 기초 유형자산 대비 감가상각비 | D19: =D15/D13 -> 0.25491651 | E19: =E15/E13 -> 0.26342711 | F19: =F15/F13 -> 0.23869969 | G19: =G15/G13 -> 0.23413449 | H19: =H15/H13 -> 0.24405827 | I19: =AVERAGE(F19:H19) -> 0.23896415 | J19: =I19 -> 0.23896415 | K19: =J19 -> 0.23896415 | L19: =K19 -> 0.23896415 | M19: =L19 -> 0.23896415 | N19: =M19 -> 0.23896415 | P19: 직전 3개년 Average flat 적용.
A21: 무형자산 Schedule
A22: 기초 무형자산 | D22: 42436 | E22: =D25 -> 43718 | F22: =E25 -> 43622 | G22: =F25 -> 42852 | H22: =G25 -> 44101 | I22: =H25 -> 45830 | J22: =I25 -> 47566.265 | K22: =J25 -> 49502.58 | L22: =K25 -> 51656.644 | ... N22: =M25 -> 56697.865
A23: Capex | D23: =D25+D24-D22 -> 1362 | E23: =E25+E24-E22 -> -13 | F23: =F25+F24-F22 -> -680 | G23: =G25+G24-G22 -> 1325 | H23: =H25+H24-H22 -> 1808 | I23: =매출액!H7*I27 -> 1818.3624 | J23: =매출액!I7*J27 -> 2021.5219 | K23: =매출액!J7*K27 -> 2242.7403 | L23: =매출액!K7*L27 -> 2481.6063 | M23: =매출액!L7*M27 -> 2748.9643 | N23: =매출액!M7*N27 -> 3048.9686
A24: 상각비 | D24: ='CF(Yearly)'!C9-D15 -> 80 | E24: ='CF(Yearly)'!D9-E15 -> 83 | F24: ='CF(Yearly)'!E9-F15 -> 90 | G24: ='CF(Yearly)'!F9-G15 -> 76 | H24: ='CF(Yearly)'!G9-H15 -> 79 | I24: =I22*I28 -> 82.097231 | J24: =J22*J28 -> 85.207477 | K24: =K22*K28 -> 88.67608 | L24: =L22*L28 -> 92.534747 | M24: =M22*M28 -> 96.814392 | N24: =N22*N28 -> 101.5653
A25: 기말 무형자산 | D25: =D8 -> 43718 | E25: =E8 -> 43622 | F25: =F8 -> 42852 | G25: =G8 -> 44101 | H25: =H8 -> 45830 | I25: =I22+I23-I24 -> 47566.265 | J25: =J22+J23-J24 -> 49502.58 | K25: =K22+K23-K24 -> 51656.644 | L25: =L22+L23-L24 -> 54045.715 | M25: =M22+M23-M24 -> 56697.865 | N25: =N22+N23-N24 -> 59645.269
A27: 매출액 대비 Capex | D27: =D23/'IS(Yearly)'!C6 -> 0.062345509 | E27: =E23/'IS(Yearly)'!D6 -> -0.0005393072 | F27: =F23/'IS(Yearly)'!E6 -> -0.023200273 | G27: =G23/'IS(Yearly)'!F6 -> 0.040578201 | H27: =H23/'IS(Yearly)'!G6 -> 0.050325669 | I27: =AVERAGEA(G27:H27) -> 0.045451935 | J27: =I27 -> 0.045451935 | K27: =J27 -> 0.045451935 | L27: =K27 -> 0.045451935 | M27: =L27 -> 0.045451935 | N27: =M27 -> 0.045451935 | P27: 직전 2개년 Average flat 적용.
A28: 기초 무형자산 대비 상각비 | D28: =D24/D22 -> 0.0018851918 | E28: =E24/E22 -> 0.0018985315 | F28: =F24/F22 -> 0.0020631791 | G28: =G24/G22 -> 0.0017735462 | H28: =H24/H22 -> 0.0017913426 | I28: =H28 -> 0.0017913426 | J28: =I28 -> 0.0017913426 | K28: =J28 -> 0.0017913426 | L28: =K28 -> 0.0017913426 | M28: =L28 -> 0.0017913426 | N28: =M28 -> 0.0017913426 | P28: 직전 3개년 Average flat 적용.
A30: Capex / D&A
A31: Total Capex | D31: =D14+D23 -> 2091 | E31: =E14+E23 -> 1201 | F31: =F14+F23 -> 564 | G31: =G14+G23 -> 2402 | H31: =H14+H23 -> 3547 | I31: =I14+I23 -> 3469.7025 | J31: =J14+J23 -> 3857.3607 | K31: =K14+K23 -> 4279.4778 | ... N31: =N14+N23 -> 5817.8797
A32: of revenue (%) | D32: =D31/'IS(Yearly)'!C6 -> 0.095715463 | E32: =E31/'IS(Yearly)'!D6 -> 0.049823688 | F32: =F31/'IS(Yearly)'!E6 -> 0.019242579 | G32: =G31/'IS(Yearly)'!F6 -> 0.073561388 | H32: =H31/'IS(Yearly)'!G6 -> 0.098730724 | I32: =I31/매출액!H7 -> 0.086728967 | J32: =J31/매출액!I7 -> 0.086728967 | K32: =K31/매출액!J7 -> 0.086728967 | L32: =L31/매출액!K7 -> 0.086728967 | M32: =M31/매출액!L7 -> 0.086728967 | N32: =N31/매출액!M7 -> 0.086728967
A33: Total D&A | D33: =D15+D24 -> 767 | E33: =E15+E24 -> 804 | F33: =F15+F24 -> 861 | G33: =G15+G24 -> 943 | H33: =H15+H24 -> 1034 | I33: =I15+I24 -> 1204.5118 | J33: =J15+J24 -> 1334.0163 | K33: =K15+K24 -> 1477.764 | ... N33: =N15+N24 -> 2002.1442
A34: of revenue (%) | D34: =D33/'IS(Yearly)'!C6 -> 0.035109402 | E34: =E33/'IS(Yearly)'!D6 -> 0.033354076 | F34: =F33/'IS(Yearly)'!E6 -> 0.02937564 | G34: =G33/'IS(Yearly)'!F6 -> 0.028879429 | H34: =H33/'IS(Yearly)'!G6 -> 0.028781384 | I34: =I33/매출액!H7 -> 0.030108076 | J34: =J33/매출액!I7 -> 0.029994046 | K34: =K33/매출액!J7 -> 0.029948735 | L34: =L33/매출액!K7 -> 0.029971308 | M34: =M33/매출액!L7 -> 0.029931645 | N34: =N33/매출액!M7 -> 0.029846595

Sheet Change in NWC
A1: VISA
A2: Change in NWC
A3: (In USD millions)
A5: Historical | I5: Pro Forma
D6: 2020A | E6: 2021A | F6: 2022A | G6: 2023A | H6: 2024A | I6: 2025E | J6: 2026E | K6: 2027E | L6: 2028E | M6: 2029E | N6: 2030E
A7: 매출채권 | D7: ='BS(Yearly)'!B11 -> 1618 | E7: ='BS(Yearly)'!C11 -> 1968 | F7: ='BS(Yearly)'!D11 -> 2020 | G7: ='BS(Yearly)'!E11 -> 2291 | H7: ='BS(Yearly)'!F11 -> 2561 | I7: =I21/$B$26*I27 -> 2920.5447 | J7: =J21/$B$26*J27 -> 3246.8474 | K7: =K21/$B$26*K27 -> 3602.155 | L7: =L21/$B$26*L27 -> 3985.8073 | M7: =M21/$B$26*M27 -> 4415.2217 | N7: =N21/$B$26*N27 -> 4897.0706
A8: 선급비용 및 기타유동자산 | D8: ='BS(Yearly)'!B12 -> 757 | E8: ='BS(Yearly)'!C12 -> 856 | F8: ='BS(Yearly)'!D12 -> 2668 | G8: ='BS(Yearly)'!E12 -> 2584 | H8: ='BS(Yearly)'!F12 -> 3312 | I8: =H8 -> 3312 | J8: =I8 -> 3312 | K8: =J8 -> 3312 | L8: =K8 -> 3312 | M8: =L8 -> 3312 | N8: =M8 -> 3312
A9: 결제대금 수취채권 | D9: ='BS(Yearly)'!B13 -> 901 | E9: ='BS(Yearly)'!C13 -> 894 | F9: ='BS(Yearly)'!D13 -> 1449 | G9: ='BS(Yearly)'!E13 -> 1764 | H9: ='BS(Yearly)'!F13 -> 3089 | I9: =H9 -> 3089 | J9: =I9 -> 3089 | K9: =J9 -> 3089 | L9: =K9 -> 3089 | M9: =L9 -> 3089 | N9: =M9 -> 3089
A10: 고객 인센티브 | D10: ='BS(Yearly)'!B14 -> 1850 | E10: ='BS(Yearly)'!C14 -> 2260 | F10: ='BS(Yearly)'!D14 -> 2342 | G10: ='BS(Yearly)'!E14 -> 3005 | H10: ='BS(Yearly)'!F14 -> 3524 | I10: =H10 -> 3524 | J10: =I10 -> 3524 | K10: =J10 -> 3524 | L10: =K10 -> 3524 | M10: =L10 -> 3524 | N10: =M10 -> 3524
A11: 영업용 유동자산 | D11: =SUM(D7:D10) -> 5126 | E11: =SUM(E7:E10) -> 5978 | F11: =SUM(F7:F10) -> 8479 | G11: =SUM(G7:G10) -> 9644 | H11: =SUM(H7:H10) -> 12486 | I11: =SUM(I7:I10) -> 12845.545 | J11: =SUM(J7:J10) -> 13171.847 | K11: =SUM(K7:K10) -> 13527.155 | ... N11: =SUM(N7:N10) -> 14822.071
A13: 매입채무 | D13: ='BS(Yearly)'!B38 -> 174 | E13: ='BS(Yearly)'!C38 -> 266 | F13: ='BS(Yearly)'!D38 -> 340 | G13: ='BS(Yearly)'!E38 -> 375 | H13: ='BS(Yearly)'!F38 -> 479 | I13: =I22/$B$30*I31 -> 438.93359 | J13: =J22/$B$30*J31 -> 459.26117 | K13: =K22/$B$30*K31 -> 485.46211 | L13: =L22/$B$30*L31 -> 513.99327 | M13: =M22/$B$30*M31 -> 546.36912 | N13: =N22/$B$30*N31 -> 584.18204
A14: 미지급 급여 및 복리후생 | D14: ='BS(Yearly)'!B40 -> 821 | E14: ='BS(Yearly)'!C40 -> 1211 | F14: ='BS(Yearly)'!D40 -> 1359 | G14: ='BS(Yearly)'!E40 -> 1506 | H14: ='BS(Yearly)'!F40 -> 1538 | I14: =H14 -> 1538 | J14: =I14 -> 1538 | K14: =J14 -> 1538 | L14: =K14 -> 1538 | M14: =L14 -> 1538 | N14: =M14 -> 1538
A15: 결제대금 지급부채 | D15: ='BS(Yearly)'!B48 -> 1736 | E15: ='BS(Yearly)'!C48 -> 2443 | F15: ='BS(Yearly)'!D48 -> 3281 | G15: ='BS(Yearly)'!E48 -> 3269 | H15: ='BS(Yearly)'!F48 -> 5265 | I15: =H15 -> 5265 | J15: =I15 -> 5265 | K15: =J15 -> 5265 | L15: =K15 -> 5265 | M15: =L15 -> 5265 | N15: =M15 -> 5265
A16: 영업용 유동부채 | D16: =SUM(D13:D15) -> 2731 | E16: =SUM(E13:E15) -> 3920 | F16: =SUM(F13:F15) -> 4980 | G16: =SUM(G13:G15) -> 5150 | H16: =SUM(H13:H15) -> 7282 | I16: =SUM(I13:I15) -> 7241.9336 | J16: =SUM(J13:J15) -> 7262.2612 | K16: =SUM(K13:K15) -> 7288.4621 | ... N16: =SUM(N13:N15) -> 7387.182
A17: 순운전자본 | D17: =D11-D16 -> 2395 | E17: =E11-E16 -> 2058 | F17: =F11-F16 -> 3499 | G17: =G11-G16 -> 4494 | H17: =H11-H16 -> 5204 | I17: =I11-I16 -> 5603.6111 | J17: =J11-J16 -> 5909.5862 | K17: =K11-K16 -> 6238.6929 | ... N17: =N11-N16 -> 7434.8885
A19: 순운전자본의 증감 | E19: =E17-D17 -> -337 | F19: =F17-E17 -> 1441 | G19: =G17-F17 -> 995 | H19: =H17-G17 -> 710 | I19: =I17-H17 -> 399.61113 | J19: =J17-I17 -> 305.97508 | K19: =K17-J17 -> 329.1067 | L19: =L17-K17 -> 355.12114 | ... N19: =N17-M17 -> 444.036
A20: IS Data
A21: 매출액 | D21: ='IS(Yearly)'!C6 -> 21846 | E21: ='IS(Yearly)'!D6 -> 24105 | F21: ='IS(Yearly)'!E6 -> 29310 | G21: ='IS(Yearly)'!F6 -> 32653 | H21: ='IS(Yearly)'!G6 -> 35926 | I21: =매출액!H7 -> 40006.27 | J21: =매출액!I7 -> 44476.037 | K21: =매출액!J7 -> 49343.119 | L21: =매출액!K7 -> 54598.474 | M21: =매출액!L7 -> 60480.687 | N21: =매출액!M7 -> 67081.16
A22: 영업비용 | D22: ='IS(Yearly)'!C11 -> 7765 | E22: ='IS(Yearly)'!D11 -> 8301 | F22: ='IS(Yearly)'!E11 -> 10497 | G22: ='IS(Yearly)'!F11 -> 11653 | H22: ='IS(Yearly)'!G11 -> 12331 | I22: ='비용 추정'!I7 -> 12961.248 | J22: ='비용 추정'!J7 -> 13561.501 | K22: ='비용 추정'!K7 -> 14335.187 | L22: ='비용 추정'!L7 -> 15177.682 | M22: ='비용 추정'!M7 -> 16133.707 | N22: ='비용 추정'!N7 -> 17250.283
A24: Assumptions
A25: 순운전자본(Net Working Capital) 항목
A26: 영업일: | B26: 365
A27: 매출채권회수일(DSO) | D27: =D7/D21*$B$26 -> 27.033324 | E27: =E7/E21*$B$26 -> 29.799627 | F27: =F7/F21*$B$26 -> 25.155237 | G27: =G7/G21*$B$26 -> 25.609132 | H27: =H7/H21*$B$26 -> 26.019178 | I27: =AVERAGE(E27:H27) -> 26.645794 | J27: =I27 -> 26.645794 | K27: =J27 -> 26.645794 | L27: =K27 -> 26.645794 | M27: =L27 -> 26.645794 | N27: =M27 -> 26.645794
A29: 순운전자본(Net Working Capital) 항목
A30: 영업일: | B30: 365
A31: 매입채무회수일(DPO) | D31: =D13/D22*$B$30 -> 8.1790084 | E31: =E13/E22*$B$30 -> 11.696181 | F31: =F13/F22*$B$30 -> 11.822425 | G31: =G13/G22*$B$30 -> 11.745902 | H31: =H13/H22*$B$30 -> 14.178493 | I31: =AVERAGE(E31:H31) -> 12.360751 | J31: =I31 -> 12.360751 | K31: =J31 -> 12.360751 | L31: =K31 -> 12.360751 | M31: =L31 -> 12.360751 | N31: =M31 -> 12.360751
A34: Ratio
A35: 매출채권/매출 | D35: =D7/D21 -> 0.074063902 | E35: =E7/E21 -> 0.081642813 | F35: =F7/F21 -> 0.068918458 | G35: =G7/G21 -> 0.070162007 | H35: =H7/H21 -> 0.07128542 | I35: =I7/I21 -> 0.073002174 | J35: =J7/J21 -> 0.073002174 | K35: =K7/K21 -> 0.073002174 | ... N35: =N7/N21 -> 0.073002174
A36: 매출채권/영업비용 | D36: =D7/D22 -> 0.2083709 | E36: =E7/E22 -> 0.23707987 | F36: =F7/F22 -> 0.19243593 | G36: =G7/G22 -> 0.19660173 | H36: =H7/H22 -> 0.20768794 | I36: =I7/I22 -> 0.22532897 | J36: =J7/J22 -> 0.23941652 | K36: =K7/K22 -> 0.25128064 | ... N36: =N7/N22 -> 0.28388349
A37: 순운전자본/매출 | D37: =D17/D21 -> 0.10963105 | E37: =E17/E21 -> 0.085376478 | F37: =F17/F21 -> 0.11937905 | G37: =G17/G21 -> 0.13762901 | H37: =H17/H21 -> 0.14485331 | I37: =I17/I21 -> 0.14006832 | J37: =J17/J21 -> 0.13287124 | K37: =K17/K21 -> 0.12643491 | ... N37: =N17/N21 -> 0.11083423
A38: 영업용유동자산/영업용유동부채 | D38: =D11/D16 -> 1.8769681 | E38: =E11/E16 -> 1.525 | F38: =F11/F16 -> 1.7026104 | G38: =G11/G16 -> 1.8726214 | H38: =H11/H16 -> 1.7146388 | I38: =I11/I16 -> 1.7737728 | J38: =J11/J16 -> 1.8137391 | K38: =K11/K16 -> 1.8559684 | ... N38: =N11/N16 -> 2.006458
A39: 순운전자본/총자산 | D39: =D17/D44 -> 0.029597499 | E39: =E17/E44 -> 0.024826288 | F39: =F17/F44 -> 0.040923498 | G39: =G17/G44 -> 0.049658007 | H39: =H17/H44 -> 0.055062374 | I39: =I17/I44 -> 0.057998626 | J39: =J17/J44 -> 0.060101433 | K39: =K17/K44 -> 0.061294731 | ... N39: =N17/N44 -> 0.067681038
A42: 총자산 추정
A43: 총자산 회전율 | D43: =D45/D44 -> 0.26997368 | E43: =E45/E44 -> 0.29078605 | F43: =F45/F44 -> 0.34280301 | G43: =G45/G44 -> 0.36081062 | H43: =H45/H44 -> 0.38012506 | I43: =H43*(H43/D43)^0.25 -> 0.41407383 | J43: =I43*(I43/E43)^0.25 -> 0.45232838 | K43: =J43*(J43/F43)^0.25 -> 0.48479277 | L43: =K43*(K43/G43)^0.25 -> 0.52194572 | M43: =L43*(L43/H43)^0.25 -> 0.56500208 | N43: =M43*(M43/I43)^0.25 -> 0.61065106
A44: 총자산 | D44: ='BS(Yearly)'!B36 -> 80919 | E44: ='BS(Yearly)'!C36 -> 82896 | F44: ='BS(Yearly)'!D36 -> 85501 | G44: ='BS(Yearly)'!E36 -> 90499 | H44: ='BS(Yearly)'!F36 -> 94511 | I44: =I45*(1/I43) -> 96616.274 | J44: =J45*(1/J43) -> 98326.877 | K44: =K45*(1/K43) -> 101781.88 | L44: =L45*(1/L43) -> 104605.65 | M44: =M45*(1/M43) -> 107045.07 | N44: =N45*(1/N43) -> 109851.87
A45: 매출액 | D45: ='IS(Yearly)'!C6 -> 21846 | E45: ='IS(Yearly)'!D6 -> 24105 | F45: ='IS(Yearly)'!E6 -> 29310 | G45: ='IS(Yearly)'!F6 -> 32653 | H45: ='IS(Yearly)'!G6 -> 35926 | I45: =매출액!H7 -> 40006.27 | J45: =매출액!I7 -> 44476.037 | K45: =매출액!J7 -> 49343.119 | L45: =매출액!K7 -> 54598.474 | M45: =매출액!L7 -> 60480.687 | N45: =매출액!M7 -> 67081.16

Sheet WACC
A1: VISA
A2: Weighted Average Cost of Capital
B4: WACC Calculation Table | G4: Description
B5: Wd(Debt/Capital) | E5: =E27 -> 0.035712628 | G5: 시가 총액 대비 차입금 비율
B6: We(Equity/Capital) | E6: =1-E5 -> 0.96428737
B7: Rd(타인자본비용) | E7: 0.0406
B8: (1-t) | E8: =1-IS!I37 -> 0.82873296 | G8: IS sheet 참고
B9: Rd*(1-t)*Wd | E9: =E7*E8*E5 -> 0.001201607
B10: 무위험수익률(Rf) | E10: 0.03633 | G10: 미국채 3년 수익률
B11: 시장위험프리미엄(MRP, Rm-Rf) | E11: 0.0532 | G11: 미국 리스크 프리미엄
B12: β(조정베타) | E12: =0.786*2/3+1*1/3 -> 0.85733333 | G12: 메릴린치 조정 베타
B13: Re(자기자본비용) | E13: =E10+E12*(E11) -> 0.081940133 | G13: Re=Rf+β(Rm-Rf)
B14: Re*We | E14: =E13*E6 -> 0.079013836
B15: WACC | E15: =E14+E9 -> 0.080215443
B18: Wd(Debt/Capital)
B19: FY24 차입금 시가/자본 시가
B20: 차입금 | E20: 금액($mn)
B21: 단기차입금&유동성장기부채 | E21: 150
B22: 장기차입금 | E22: 21521
B23: 합계 | E23: =SUM(E21:E22) -> 21671
B24: 시가총액 | E24: =E25*E26 -> 5.8514517e+11
B25: 주가 | E25: 344.47
B26: 발행주식수 | E26: 1698682527
B27: Wd | E27: =E23/(E23*1000000+E24)*1000000 -> 0.035712628

Sheet 매출액
A1: VISA
A2: Revenue Expectation
A3: (In USD millions)
A5: Historical | H5: Pro Forma | O5: Description
C6: 2020A | D6: 2021A | E6: 2022A | F6: 2023A | G6: 2024A | H6: 2025E | I6: 2026E | J6: 2027E | K6: 2028E | L6: 2029E | M6: 2030E
A7: 순매출액 | C7: =C9+C11+C13+C15+C17 -> 21846 | D7: =D9+D11+D13+D15+D17 -> 24105 | E7: =E9+E11+E13+E15+E17 -> 29310 | F7: =F9+F11+F13+F15+F17 -> 32653 | G7: =G9+G11+G13+G15+G17 -> 35926 | H7: =H9+H11+H13+H15+H17 -> 40006.27 | I7: =I9+I11+I13+I15+I17 -> 44476.037 | J7: =J9+J11+J13+J15+J17 -> 49343.119 | ... M7: =M9+M11+M13+M15+M17 -> 67081.16
A8: YoY% | D8: =D7/C7-1 -> 0.10340566 | E8: =E7/D7-1 -> 0.2159303 | F8: =F7/E7-1 -> 0.11405664 | G8: =G7/F7-1 -> 0.10023581 | H8: =H7/G7-1 -> 0.1135743 | I8: =I7/H7-1 -> 0.11172664 | J8: =J7/I7-1 -> 0.10943158 | K8: =K7/J7-1 -> 0.10650633 | ... M8: =M7/L7-1 -> 0.10913357
A9: 결제 서비스 | C9: 9804 | D9: 11475 | E9: 13361 | F9: 14826 | G9: 16114 | H9: ='매출 세부 추정'!I23 -> 17518.271 | I9: ='매출 세부 추정'!J23 -> 19092.953 | J9: ='매출 세부 추정'!K23 -> 20861.572 | K9: ='매출 세부 추정'!L23 -> 22850.258 | L9: ='매출 세부 추정'!M23 -> 25088.151 | M9: ='매출 세부 추정'!N23 -> 27607.347 | O9: 매출 세부 추정 시트 - 결제 서비스 부문 참고.
A10: YoY% | D10: =D9/C9-1 -> 0.17044064 | E10: =E9/D9-1 -> 0.1643573 | F10: =F9/E9-1 -> 0.10964748 | G10: =G9/F9-1 -> 0.08687441 | H10: =H9/G9-1 -> 0.087146051 | I10: =I9/H9-1 -> 0.089887957 | J10: =J9/I9-1 -> 0.09263205 | K10: =K9/J9-1 -> 0.095327678 | ... M10: =M9/L9-1 -> 0.10041375
A11: 데이터 처리 | C11: 10975 | D11: 12792 | E11: 14438 | F11: 16007 | G11: 17714 | H11: ='매출 세부 추정'!I46 -> 19662.54 | I11: ='매출 세부 추정'!J46 -> 21825.419 | J11: ='매출 세부 추정'!K46 -> 24226.216 | K11: ='매출 세부 추정'!L46 -> 26891.099 | L11: ='매출 세부 추정'!M46 -> 29849.12 | M11: ='매출 세부 추정'!N46 -> 33132.523 | O11: 매출 세부 추정 시트 - 데이터 처리 부문 참고.
A12: YoY% | D12: =D11/C11-1 -> 0.16555809 | E12: =E11/D11-1 -> 0.12867417 | F12: =F11/E11-1 -> 0.10867156 | G12: =G11/F11-1 -> 0.10664084 | H12: 0.10664084 | I12: 0.10664084 | J12: 0.10664084 | K12: 0.10664084 | L12: 0.10664084 | M12: 0.10664084
A13: 해외 결제 수수료 | C13: 6299 | D13: 6530 | E13: 9815 | F13: 11638 | G13: 12665 | H13: ='매출 세부 추정'!I54 -> 14184.8 | I13: ='매출 세부 추정'!J54 -> 15603.28 | J13: ='매출 세부 추정'!K54 -> 16851.542 | K13: ='매출 세부 추정'!L54 -> 17862.635 | L13: ='매출 세부 추정'!M54 -> 18755.767 | M13: ='매출 세부 추정'!N54 -> 19505.997 | O13: 매출 세부 추정 시트 - 해외 결제 수수료 부문 참고.
A14: YoY% | D14: =D13/C13-1 -> 0.036672488 | E14: =E13/D13-1 -> 0.50306279 | F14: =F13/E13-1 -> 0.18573612 | G14: =G13/F13-1 -> 0.088245403 | H14: =H13/G13-1 -> 0.12 | I14: =I13/H13-1 -> 0.1 | J14: =J13/I13-1 -> 0.08 | K14: =K13/J13-1 -> 0.06 | ... M14: =M13/L13-1 -> 0.04
A15: 기타 | C15: 1432 | D15: 1675 | E15: 1991 | F15: 2479 | G15: 3197 | H15: =G15*(1+H16) -> 3967.8954 | I15: =H15*(1+I16) -> 4994.0814 | J15: =I15*(1+J16) -> 6308.1674 | K15: =J15*(1+K16) -> 7912.2961 | L15: =K15*(1+L16) -> 9959.0617 | M15: =L15*(1+M16) -> 12535.485 | O15: 특별한 경향성이 없으므로, 직전 3개년 avg flat 적용함.
A16: YoY% | D16: =D15/C15-1 -> 0.16969274 | E16: =E15/D15-1 -> 0.18865672 | F16: =F15/E15-1 -> 0.24510296 | G16: =G15/F15-1 -> 0.28963292 | H16: =AVERAGE(E16:G16) -> 0.24113087 | I16: =AVERAGE(F16:H16) -> 0.25862225 | J16: =AVERAGE(G16:I16) -> 0.26312868 | K16: =AVERAGE(H16:J16) -> 0.25429393 | L16: =AVERAGE(I16:K16) -> 0.25868162 | M16: =AVERAGE(J16:L16) -> 0.25870141
A17: 고객 인센티브 | C17: -6664 | D17: -8367 | E17: -10295 | F17: -12297 | G17: -13764 | H17: =(H9+H11+H13+H15)*H19*(-1) -> -15327.237 | I17: =(I9+I11+I13+I15)*I19*(-1) -> -17039.697 | J17: =(J9+J11+J13+J15)*J19*(-1) -> -18904.378 | K17: =(K9+K11+K13+K15)*K19*(-1) -> -20917.814 | L17: =(L9+L11+L13+L15)*L19*(-1) -> -23171.413 | M17: =(M9+M11+M13+M15)*M19*(-1) -> -25700.192 | O17: 고객 인센티브의 경우, 동사의 매출액에 비례하여 증가하는 성격을 가짐.
A18: YoY% | D18: =D17/C17-1 -> 0.25555222 | E18: =E17/D17-1 -> 0.23042907 | F18: =F17/E17-1 -> 0.19446333 | G18: =G17/F17-1 -> 0.11929739 | H18: =H17/G17-1 -> 0.1135743 | I18: =I17/H17-1 -> 0.11172664 | J18: =J17/I17-1 -> 0.10943158 | K18: =K17/J17-1 -> 0.10650633 | ... M18: =M17/L17-1 -> 0.10913357 | O18: 허나 직전 2개년 거의 고정되는 수치를 기록하였으므로 직전년도 인센티브 비중을 flat 적용함.
A19: 인센티브 비중 | C19: =ABS(C17)/(C9+C11+C13+C15) -> 0.23374255 | D19: =ABS(D17)/(D9+D11+D13+D15) -> 0.25766814 | E19: =ABS(E17)/(E9+E11+E13+E15) -> 0.25994193 | F19: =ABS(F17)/(F9+F11+F13+F15) -> 0.27357063 | G19: =ABS(G17)/(G9+G11+G13+G15) -> 0.27699738 | H19: =G19 -> 0.27699738 | I19: =H19 -> 0.27699738 | J19: =I19 -> 0.27699738 | K19: =J19 -> 0.27699738 | L19: =K19 -> 0.27699738 | M19: =L19 -> 0.27699738

Sheet 매출 세부 추정
A1: VISA
A2: Revenue Estimation
A3: (In USD millions)
B5: 결제 서비스(Service Revenue)
A7: 지역별 연간 결제 금액(bn) | D7: 2020A | E7: 2021A | F7: 2022A | G7: 2023A | H7: 2024A | I7: 2025E | J7: 2026E | K7: 2027E | L7: 2028E | M7: 2029E | N7: 2030E | P7: 결제액 성장률 | Q7: 2025E | R7: 2026E | S7: 2027E | T7: 2028E | U7: 2029E | V7: 2030E | X7: 지역별 존재하는 침투여력 중 동사가 차지할 시장점유율을 곱하여 동사의 지역별 향후 결제액 성장률을 추정함.
A8: Asia Pacific | D8: 1799 | E8: 1929 | F8: 2045 | G8: 2042 | H8: 2023 | I8: =H8*(1+I9) -> 2294.4866 | J8: =I8*(1+J9) -> 2603.4592 | K8: =J8*(1+K9) -> 2954.9778 | L8: =K8*(1+L9) -> 3354.7292 | M8: =L8*(1+M9) -> 3809.0898 | N8: =M8*(1+N9) -> 4325.1909 | P8: Asia Pacific | Q8: =Q16*(1-Q24) -> 0.1342 | R8: =R16*(1-R24) -> 0.13465872 | S8: =S16*(1-S24) -> 0.1350198 | T8: =T16*(1-T24) -> 0.13528067 | U8: =U16*(1-U24) -> 0.13543885 | V8: =V16*(1-V24) -> 0.13549196
C9: yoy | E9: =(E8-D8)/D8 -> 0.072262368 | F9: =(F8-E8)/E8 -> 0.060134785 | G9: =(G8-F8)/F8 -> -0.0014669927 | H9: =(H8-G8)/G8 -> -0.0093046033 | I9: =Q8 -> 0.1342 | J9: =R8 -> 0.13465872 | K9: =S8 -> 0.1350198 | L9: =T8 -> 0.13528067 | M9: =U8 -> 0.13543885 | N9: =V8 -> 0.13549196 | P9: Canada | Q9: =Q17*(1-Q25) -> 0.0434 | R9: =R17*(1-R25) -> 0.0443982 | S9: =S17*(1-S25) -> 0.045419359 | T9: =T17*(1-T25) -> 0.046464004 | U9: =U17*(1-U25) -> 0.047532676 | V9: =V17*(1-V25) -> 0.048340731
A10: Canada | D10: 259 | E10: 311 | F10: 374 | G10: 389 | H10: 409 | I10: =H10*(1+I11) -> 426.7506 | J10: =I10*(1+J11) -> 445.69756 | K10: =J10*(1+K11) -> 465.94086 | L10: =K10*(1+L11) -> 487.59033 | M10: =L10*(1+M11) -> 510.76681 | N10: =M10*(1+N11) -> 535.45765 | P10: CEMEA | Q10: =Q18*(1-Q26) -> 0.1064 | R10: =R18*(1-R26) -> 0.1083684 | S10: =S18*(1-S26) -> 0.11037322 | T10: =T18*(1-T26) -> 0.11241512 | U10: =U18*(1-U26) -> 0.1144948 | V10: =V18*(1-V26) -> 0.11661295
C11: yoy | E11: =(E10-D10)/D10 -> 0.2007722 | F11: =(F10-E10)/E10 -> 0.20257235 | G11: =(G10-F10)/F10 -> 0.040106952 | H11: =(H10-G10)/G10 -> 0.051413882 | I11: =Q9 -> 0.0434 | J11: =R9 -> 0.0443982 | K11: =S9 -> 0.045419359 | L11: =T9 -> 0.046464004 | M11: =U9 -> 0.047532676 | N11: =V9 -> 0.048340731 | P11: LAC | Q11: =Q19*(1-Q27) -> 0.2257 | R11: =R19*(1-R27) -> 0.222589 | S11: =S19*(1-S27) -> 0.21912793 | T11: =T19*(1-T27) -> 0.21530665 | U11: =U19*(1-U27) -> 0.21111506 | V11: =V19*(1-V27) -> 0.20654314
A12: CEMEA | D12: 523 | E12: 665 | F12: 648 | G12: 658 | H12: 757 | I12: =H12*(1+I13) -> 837.5448 | J12: =I12*(1+J13) -> 928.30819 | K12: =J12*(1+K13) -> 1030.7685 | L12: =K12*(1+L13) -> 1146.6425 | M12: =L12*(1+M13) -> 1277.9271 | N12: =M12*(1+N13) -> 1426.95 | P12: US | Q12: =Q20*(1-Q28) -> 0.056 | R12: =R20*(1-R28) -> 0.057064 | S12: =S20*(1-S28) -> 0.058176748 | T12: =T20*(1-T28) -> 0.059340283 | U12: =U20*(1-U28) -> 0.060556759 | V12: =V20*(1-V28) -> 0.061828451
C13: yoy | E13: =(E12-D12)/D12 -> 0.27151052 | F13: =(F12-E12)/E12 -> -0.02556391 | G13: =(G12-F12)/F12 -> 0.015432099 | H13: =(H12-G12)/G12 -> 0.15045593 | I13: =Q10 -> 0.1064 | J13: =R10 -> 0.1083684 | K13: =S10 -> 0.11037322 | L13: =T10 -> 0.11241512 | M13: =U10 -> 0.1144948 | N13: =V10 -> 0.11661295 | P13: EUROPE | Q13: =Q21*(1-Q29) -> 0.0816 | R13: =R21*(1-R29) -> 0.082824 | S13: =S21*(1-S29) -> 0.084004242 | T13: =T21*(1-T29) -> 0.085138299 | U13: =U21*(1-U29) -> 0.086223813 | V13: =V21*(1-V29) -> 0.087258498
A14: LAC | D14: 384 | E14: 495 | F14: 667 | G14: 803 | H14: 895 | I14: =H14*(1+I15) -> 1097.0015 | J14: =I14*(1+J15) -> 1341.182 | K14: =J14*(1+K15) -> 1635.0724 | L14: =K14*(1+L15) -> 1987.1143 | M14: =L14*(1+M15) -> 2406.6241 | N14: =M14*(1+N15) -> 2903.6958
C15: yoy | E15: =(E14-D14)/D14 -> 0.2890625 | F15: =(F14-E14)/E14 -> 0.34747475 | G15: =(G14-F14)/F14 -> 0.20389805 | H15: =(H14-G14)/G14 -> 0.11457036 | I15: =Q11 -> 0.2257 | J15: =R11 -> 0.222589 | K15: =S11 -> 0.21912793 | L15: =T11 -> 0.21530665 | M15: =U11 -> 0.21111506 | N15: =V11 -> 0.20654314 | P15: Visa M/S | Q15: 2025E | R15: 2026E | S15: 2027E | T15: 2028E | U15: 2029E | V15: 2030E | X15: 25년 동사의 지역별 시장점유율에 지역별 실질 GDP를 곱하여, 각 지역의 결제시장 성장치만큼만 동사의 시장점유율도 증가한다고 보수적으로 추정함.
A16: US | D16: 4083 | E16: 4954 | F16: 5700 | G16: 6135 | H16: 6467 | I16: =H16*(1+I17) -> 6829.152 | J16: =I16*(1+J17) -> 7218.8507 | K16: =J16*(1+K17) -> 7638.82 | L16: =K16*(1+L17) -> 8092.1097 | M16: =L16*(1+M17) -> 8582.1417 | N16: =M16*(1+N17) -> 9112.7622 | P16: Asia Pacific | Q16: 0.61 | R16: =Q16*(1+Q32) -> 0.62342 | S16: =R16*(1+R32) -> 0.63688587 | T16: =S16*(1+S32) -> 0.65038785 | U16: =T16*(1+T32) -> 0.66391592 | V16: =U16*(1+U32) -> 0.6774598
C17: yoy | E17: =(E16-D16)/D16 -> 0.21332354 | F17: =(F16-E16)/E16 -> 0.15058539 | G17: =(G16-F16)/F16 -> 0.076315789 | H17: =(H16-G16)/G16 -> 0.054115729 | I17: =Q12 -> 0.056 | J17: =R12 -> 0.057064 | K17: =S12 -> 0.058176748 | L17: =T12 -> 0.059340283 | M17: =U12 -> 0.060556759 | N17: =V12 -> 0.061828451 | P17: Canada | Q17: 0.62 | R17: =Q17*(1+Q33) -> 0.63426 | S17: =R17*(1+R33) -> 0.64884798 | T17: =S17*(1+S33) -> 0.66377148 | U17: =T17*(1+T33) -> 0.67903823 | V17: =U17*(1+U33) -> 0.69058188
A18: EUROPE | D18: 1748 | E18: 2054 | F18: 2172 | G18: 2331 | H18: 2638 | I18: =H18*(1+I19) -> 2853.2608 | J18: =I18*(1+J19) -> 3089.5793 | K18: =J18*(1+K19) -> 3349.117 | L18: =K18*(1+L19) -> 3634.2552 | M18: =L18*(1+M19) -> 3947.6145 | N18: =M18*(1+N19) -> 4292.0774 | P18: CEMEA | Q18: 0.56 | R18: =Q18*(1+Q34) -> 0.57036 | S18: =R18*(1+R34) -> 0.58091166 | T18: =S18*(1+S34) -> 0.59165853 | U18: =T18*(1+T34) -> 0.60260421 | V18: =U18*(1+U34) -> 0.61375239
C19: yoy | E19: =(E18-D18)/D18 -> 0.17505721 | F19: =(F18-E18)/E18 -> 0.05744888 | G19: =(G18-F18)/F18 -> 0.07320442 | H19: =(H18-G18)/G18 -> 0.13170313 | I19: =Q13 -> 0.0816 | J19: =R13 -> 0.082824 | K19: =S13 -> 0.084004242 | L19: =T13 -> 0.085138299 | M19: =U13 -> 0.086223813 | N19: =V13 -> 0.087258498 | P19: LAC | Q19: 0.61 | R19: =Q19*(1+Q35) -> 0.62525 | S19: =R19*(1+R35) -> 0.64072494 | T19: =S19*(1+S35) -> 0.6564227 | U19: =T19*(1+T35) -> 0.67234095 | V19: =U19*(1+U35) -> 0.68847713
A20: SUM | D20: =SUM(D8:D18) -> 8796 | E20: =SUM(E8:E18) -> 10409.047 | F20: =SUM(F8:F18) -> 11606.735 | G20: =SUM(G8:G18) -> 12358.334 | H20: =SUM(H8:H18) -> 13189.361 | I20: =SUM(I8:I18) -> 14338.762 | J20: =SUM(J8:J18) -> 15627.644 | K20: =SUM(K8:K18) -> 17075.265 | ... N20: =SUM(N8:N18) -> 22596.703 | P20: US | Q20: 0.7 | R20: =Q20*(1+Q36) -> 0.7133 | S20: =R20*(1+R36) -> 0.72720935 | T20: =S20*(1+S36) -> 0.74175354 | U20: =T20*(1+T36) -> 0.75695948 | V20: =U20*(1+U36) -> 0.77285563
C21: yoy | E21: =(E20-D20)/D20 -> 0.18338414 | F21: =(F20-E20)/E20 -> 0.11506224 | G21: =(G20-F20)/F20 -> 0.064755426 | H21: =(H20-G20)/G20 -> 0.067244254 | I21: =(I20-H20)/H20 -> 0.087146051 | J21: =(J20-I20)/I20 -> 0.089887957 | K21: =(K20-J20)/J20 -> 0.09263205 | L21: =(L20-K20)/K20 -> 0.095327678 | ... N21: =(N20-M20)/M20 -> 0.10041375 | P21: EUROPE | Q21: 0.51 | R21: =Q21*(1+Q37) -> 0.51765 | S21: =R21*(1+R37) -> 0.52502651 | T21: =S21*(1+S37) -> 0.53211437 | U21: =T21*(1+T37) -> 0.53889883 | V21: =U21*(1+U37) -> 0.54536561
A22: 수수료율=매출액/총 결제액 | D22: =D23/D20/1000 -> 0.0011145975 | E22: =E23/E20/1000 -> 0.0011024064 | F22: =F23/F20/1000 -> 0.001151142 | G22: =G23/G20/1000 -> 0.0011996762 | H22: =H23/H20/1000 -> 0.0012217423 | I22: =H22 -> 0.0012217423 | J22: =I22 -> 0.0012217423 | K22: =J22 -> 0.0012217423 | L22: =K22 -> 0.0012217423 | M22: =L22 -> 0.0012217423 | N22: =M22 -> 0.0012217423
A23: 결제 서비스 매출(mn) | D23: =매출액!C9 -> 9804 | E23: =매출액!D9 -> 11475 | F23: =매출액!E9 -> 13361 | G23: =매출액!F9 -> 14826 | H23: =매출액!G9 -> 16114 | I23: =I20*I22*1000 -> 17518.271 | J23: =J20*J22*1000 -> 19092.953 | K23: =K20*K22*1000 -> 20861.572 | L23: =L20*L22*1000 -> 22850.258 | M23: =M20*M22*1000 -> 25088.151 | N23: =N20*N22*1000 -> 27607.347 | P23: 지역별 침투율 | Q23: 2025E | R23: 2026E | S23: 2027E | T23: 2028E | U23: 2029E | V23: 2030E
C24: yoy | E24: =(E23-D23)/D23 -> 0.17044064 | F24: =(F23-E23)/E23 -> 0.1643573 | G24: =(G23-F23)/F23 -> 0.10964748 | H24: =(H23-G23)/G23 -> 0.08687441 | I24: =(I23-H23)/H23 -> 0.087146051 | J24: =(J23-I23)/I23 -> 0.089887957 | K24: =(K23-J23)/J23 -> 0.09263205 | L24: =(L23-K23)/K23 -> 0.095327678 | ... N24: =(N23-M23)/M23 -> 0.10041375 | P24: Asia Pacific | Q24: 0.78 | R24: =0.4%+Q24 -> 0.784 | S24: =0.4%+R24 -> 0.788 | T24: =0.4%+S24 -> 0.792 | U24: =0.4%+T24 -> 0.796 | V24: =0.4%+U24 -> 0.8 | X24: Asia Pacific 지역의 경우, 향후 침투율이 CEMEA 지역 시장점유율에 수렴할 것으로 가정하고 점진적으로 증가한다고 추정함.
P25: Canada | Q25: 0.93 | R25: =Q25 -> 0.93 | S25: =R25 -> 0.93 | T25: =S25 -> 0.93 | U25: =T25 -> 0.93 | V25: =U25 -> 0.93 | X25: Canada 지역의 경우, 이미 침투율이 93%이므로 flat을 적용함.
B26: 지역별 연간 결제 금액을 산출하여 모두 합한 후, 평균 수수료율을 곱하여 총 매출을 추정함. | P26: CEMEA | Q26: 0.81 | R26: =Q26 -> 0.81 | S26: =R26 -> 0.81 | T26: =S26 -> 0.81 | U26: =T26 -> 0.81 | V26: =U26 -> 0.81 | X26: CEMEA 지역의 경우, 이미 침투율이 81%이므로 flat을 적용함.
B27: 수수료의 경우, 직전 5개년간 변동성이 거의 없으므로 직전년도 수수료을을 flat 적용함. | P27: LAC | Q27: 0.63 | R27: =Q27+1.4% -> 0.644 | S27: =R27+1.4% -> 0.658 | T27: =S27+1.4% -> 0.672 | U27: =T27+1.4% -> 0.686 | V27: =U27+1.4% -> 0.7 | X27: LAC 지역의 경우, 디지털 결제 전환 잠재여력이 존재하므로 동사의 침투율이 증가할 여지가 있다고 판단함.
P28: US | Q28: 0.92 | R28: =Q28 -> 0.92 | S28: =R28 -> 0.92 | T28: =S28 -> 0.92 | U28: =T28 -> 0.92 | V28: =U28 -> 0.92 | X28: US 지역의 경우, 이미 침투율이 93%이므로 flat을 적용함.
P29: EUROPE | Q29: 0.84 | R29: =Q29 -> 0.84 | S29: =R29 -> 0.84 | T29: =S29 -> 0.84 | U29: =T29 -> 0.84 | V29: =U29 -> 0.84 | X29: EUROPE 지역의 경우, 이미 침투율이 84%이므로 flat을 적용함.
P31: 실질 GDP | Q31: 2025E | R31: 2026E | S31: 2027E | T31: 2028E | U31: 2029E | V31: 2030E | X31: 모든 국가/지역별 소비성장률은 IMF에서 발표한 World Economic Outlook의 전망치를 참조함.
P32: Asia Pacific | Q32: 0.022 | R32: =Q32-0.04% -> 0.0216 | S32: =R32-0.04% -> 0.0212 | T32: =S32-0.04% -> 0.0208 | U32: =T32-0.04% -> 0.0204 | V32: 0.02
P33: Canada | Q33: 0.023 | R33: =Q33 -> 0.023 | S33: =R33 -> 0.023 | T33: =S33 -> 0.023 | U33: 0.017 | V33: =U33 -> 0.017
P34: CEMEA | Q34: =(Q32+Q37)/2 -> 0.0185 | R34: =Q34 -> 0.0185 | S34: =R34 -> 0.0185 | T34: =S34 -> 0.0185 | U34: =T34 -> 0.0185 | V34: =U34 -> 0.0185
P35: LAC | Q35: 0.025 | R35: =Q35-0.025% -> 0.02475 | S35: =R35-0.025% -> 0.0245 | T35: =S35-0.025% -> 0.02425 | U35: =T35-0.025% -> 0.024 | V35: =U35 -> 0.024
P36: US | Q36: 0.019 | R36: =Q36+0.05% -> 0.0195 | S36: =R36+0.05% -> 0.02 | T36: =S36+0.05% -> 0.0205 | U36: =T36+0.05% -> 0.021 | V36: =U36 -> 0.021
P37: EUROPE | Q37: 0.015 | R37: =Q37-0.075% -> 0.01425 | S37: =R37-0.075% -> 0.0135 | T37: =S37-0.075% -> 0.01275 | U37: =T37-0.075% -> 0.012 | V37: =U37 -> 0.012
B40: 데이터 처리(Data Processing Revenue)
D42: 2020A | E42: 2021A | F42: 2022A | G42: 2023A | H42: 2024A | I42: 2025E | J42: 2026E | K42: 2027E | L42: 2028E | M42: 2029E | N42: 2030E
A43: 건당 수수료($) | D43: =D46/D44 -> 0.077925859 | E43: =E46/E44 -> 0.077652929 | F43: =F46/F44 -> 0.074990911 | G43: =G46/G44 -> 0.075299065 | H43: =H46/H44 -> 0.075779225 | I43: =H43 -> 0.075779225 | J43: =I43 -> 0.075779225 | K43: =J43 -> 0.075779225 | L43: =K43 -> 0.075779225 | M43: =L43 -> 0.075779225 | N43: =M43 -> 0.075779225 | P43: 과거 동사의 연간 데이터 처리 매출액을 연간 데이터 처리량으로 나누어 처리 건수당 수수료를 추정함. 해당 금액의 변동성이 없으므로, 수수료는 직전 년도의 $0.0758를 flat 적용.
A44: 데이터 처리량(mn) | D44: 140839 | E44: 164733 | F44: 192530 | G44: 212579 | H44: 233758 | I44: =(1+I45)*H44 -> 259471.38 | J44: =(1+J45)*I44 -> 288013.23 | K44: =(1+K45)*J44 -> 319694.69 | L44: =(1+L45)*K44 -> 354861.1 | M44: =(1+M45)*L44 -> 393895.82 | N44: =(1+N45)*M44 -> 437224.36 | P44: 글로벌 결제 처리량의 CAGR은, Gran View Research의 분석 결과 '30년까지 약 21.4% & IMARC Group의 분석 결과 '33년까지 약 14.2%로 추정됨.
C45: yoy | E45: 0.17 | F45: 0.17 | G45: 0.1 | H45: 0.1 | I45: 0.11 | J45: 0.11 | K45: 0.11 | L45: 0.11 | M45: 0.11 | N45: 0.11 | P45: 허나, 동사의 결제 처리량은 1Q25 YoY +11%를 기록함. 따라서 보수적 추정을 위하여 시장의 전망치보다 낮은 동사의 1Q25 YoY를 flat 적용함.
A46: 데이터 처리 매출(mn) | D46: 10975 | E46: 12792 | F46: 14438 | G46: 16007 | H46: 17714 | I46: =I44*I43 -> 19662.54 | J46: =J44*J43 -> 21825.419 | K46: =K44*K43 -> 24226.216 | L46: =L44*L43 -> 26891.099 | M46: =M44*M43 -> 29849.12 | N46: =N44*N43 -> 33132.523
...

Sheet 비용 추정
A1: VISA
A2: Expenses Estimation
A3: (In USD millions)
A5: Historical | I5: Pro Forma
D6: 2020A | E6: 2021A | F6: 2022A | G6: 2023A | H6: 2024A | I6: 2025E | J6: 2026E | K6: 2027E | L6: 2028E | M6: 2029E | N6: 2030E
A7: 영업비용 | D7: =D9+D15+D17 -> 7765 | E7: =E9+E15+E17 -> 8301.0687 | F7: =F9+F15+F17 -> 10497.388 | G7: =G9+G15+G17 -> 11653.118 | H7: =H9+H15+H17 -> 12331.365 | I7: =I9+I15+I17 -> 12961.248 | J7: =J9+J15+J17 -> 13561.501 | K7: =K9+K15+K17 -> 14335.187 | ... N7: =N9+N15+N17 -> 17250.283
A8: YoY% | E8: =E7/D7-1 -> 0.069036529 | F8: =F7/E7-1 -> 0.26458275 | G8: =G7/F7-1 -> 0.11009685 | H8: =H7/G7-1 -> 0.058203065 | I8: =I7/H7-1 -> 0.051079797 | J8: =J7/I7-1 -> 0.046311302 | K8: =K7/J7-1 -> 0.0570502 | L8: =L7/K7-1 -> 0.058771125 | ... N8: =N7/M7-1 -> 0.069207635
A9: 일반판매관리비 | D9: =SUM(D11:D14) -> 2067 | E9: =SUM(E11:E14) -> 2121.0687 | F9: =SUM(F11:F14) -> 2530.3882 | G9: =SUM(G11:G14) -> 2671.1176 | H9: =SUM(H11:H14) -> 3158.3648 | I9: =SUM(I11:I14) -> 3617.7366 | J9: =SUM(J11:J14) -> 4088.4844 | K9: =SUM(K11:K14) -> 4718.423 | ... N9: =SUM(N11:N14) -> 7109.1388
A10: YoY% | E10: =E9/D9-1 -> 0.026158031 | F10: =F9/E9-1 -> 0.192978 | G10: =G9/F9-1 -> 0.055615737 | H10: =H9/G9-1 -> 0.18241322 | I10: =I9/H9-1 -> 0.14544608 | J10: =J9/I9-1 -> 0.13012219 | K10: =K9/J9-1 -> 0.15407632 | L10: =L9/K9-1 -> 0.14493643 | ... N10: =N9/M9-1 -> 0.14952379
A11: 판매 및 마케팅 비용 | D11: 971 | E11: 1136 | F11: 1336 | G11: 1341 | H11: 1560 | I11: =H11*(1+I12) -> 1738.4171 | J11: =I11*(1+J12) -> 1901.4942 | K11: =J11*(1+K12) -> 2136.9554 | L11: =K11*(1+L12) -> 2373.4503 | M11: =L11*(1+M12) -> 2633.19 | N11: =M11*(1+N12) -> 2935.0714 | P11: 직전 3개년 YoY 성장치의 Average flat 적용.
A12: YoY% | E12: =E11/D11-1 -> 0.16992791 | F12: =F11/E11-1 -> 0.17605634 | G12: =G11/F11-1 -> 0.003742515 | H12: =H11/G11-1 -> 0.16331096 | I12: =AVERAGE(F12:H12) -> 0.11436994 | J12: =AVERAGE(G12:I12) -> 0.093807805 | K12: =AVERAGE(H12:J12) -> 0.12382957 | L12: =AVERAGE(I12:K12) -> 0.1106691 | M12: =AVERAGE(J12:L12) -> 0.10943549 | N12: =AVERAGE(K12:M12) -> 0.11464472
A13: 일반 관리비 | D13: 1096 | E13: 985 | F13: 1194 | G13: 1330 | H13: 1598 | I13: =H13*(1+I14) -> 1879.0293 | J13: =I13*(1+J14) -> 2186.7327 | K13: =J13*(1+K14) -> 2581.1634 | L13: =K13*(1+L14) -> 3028.5601 | M13: =L13*(1+M14) -> 3550.9488 | N13: =M13*(1+N14) -> 4173.7773 | P13: 직전 3개년 YoY 성장치의 Average flat 적용.
A14: YoY% | E14: =E13/D13-1 -> -0.10127737 | F14: =F13/E13-1 -> 0.21218274 | G14: =G13/F13-1 -> 0.11390285 | H14: =H13/G13-1 -> 0.20150376 | I14: =AVERAGE(F14:H14) -> 0.17586312 | J14: =AVERAGE(G14:I14) -> 0.16375657 | K14: =AVERAGE(H14:J14) -> 0.18037448 | L14: =AVERAGE(I14:K14) -> 0.17333139 | M14: =AVERAGE(J14:L14) -> 0.17248748 | N14: =AVERAGE(K14:M14) -> 0.17539779
A15: 감가상각비&무형자산상각비 | D15: 767 | E15: 804 | F15: 861 | G15: 943 | H15: 1034 | I15: ='FA Schedule'!I33 -> 1204.5118 | J15: ='FA Schedule'!J33 -> 1334.0163 | K15: ='FA Schedule'!K33 -> 1477.764 | L15: ='FA Schedule'!L33 -> 1636.3877 | M15: ='FA Schedule'!M33 -> 1810.2865 | N15: ='FA Schedule'!N33 -> 2002.1442 | P15: FA Schedule Sheet 참고.
A16: YoY% | E16: =E15/D15-1 -> 0.048239896 | F16: =F15/E15-1 -> 0.070895522 | G16: =G15/F15-1 -> 0.095238095 | H16: =H15/G15-1 -> 0.09650053 | I16: =I15/H15-1 -> 0.16490506 | J16: =J15/I15-1 -> 0.10751615 | K16: =K15/J15-1 -> 0.10775559 | L16: =L15/K15-1 -> 0.10734034 | ... N16: =N15/M15-1 -> 0.10598196
A17: 기타영업비용 | D17: 4931 | E17: 5376 | F17: 7106 | G17: 8039 | H17: 8139 | I17: 8139 | J17: 8139 | K17: 8139 | L17: 8139 | M17: 8139 | N17: 8139
A18: YoY% | E18: =E17/D17-1 -> 0.090245386 | F18: =F17/E17-1 -> 0.3218006 | G18: =G17/F17-1 -> 0.1312975 | H18: =H17/G17-1 -> 0.012439358 | I18: =I17/H17-1 -> 0 | J18: =J17/I17-1 -> 0 | K18: =K17/J17-1 -> 0 | L18: =L17/K17-1 -> 0 | ... N18: =N17/M17-1 -> 0

Sheet HISTORY>>>
B2: VISA Historical DATA
B7: RFS Research Team 2

Sheet IS(Yearly)
A2: 비자 (V US) - BBG GAAP
A4: 단위: USD 백만(주당수치 제외) | C4: FY 2020 | D4: FY 2021 | E4: FY 2022 | F4: FY 2023 | G4: FY 2024 | H4: 최근12개월
A5: 12 개월 결산 | C5: 09/30/2020 | D5: 09/30/2021 | E5: 09/30/2022 | F5: 09/30/2023 | G5: 09/30/2024 | H5: 06/30/2025
A6: 매출액 | B6: SALES_REV_TURN | C6: 21846 | D6: 24105 | E6: 29310 | F6: 32653 | G6: 35926 | H6: 38893
A7: + 매출 & 서비스 수익 | B7: IS_SALES_AND_SERVICES_REVENUES | C7: 21846 | D7: 24105 | E7: 29310 | F7: 14826 | G7: 16114 | H7: 17136
A8: + 기타수익 | B8: IS_OTHER_REVENUE | C8: — | D8: — | E8: — | F8: 17827 | G8: 19812 | H8: 21757
A9: 매출총이익 | B9: GROSS_PROFIT | C9: — | D9: — | E9: — | F9: — | G9: —
A10: + 기타영업이익 | B10: IS_OTHER_OPER_INC | C10: 0 | D10: 0 | E10: 0 | F10: 0 | G10: 0 | H10: 0
A11: - 영업비용 | B11: IS_OPERATING_EXPN | C11: 7765 | D11: 8301 | E11: 10497 | F11: 11653 | G11: 12331 | H11: 14698
A12: + 일반판매관리비 | B12: IS_SGA_EXPENSE | C12: 2067 | D12: 2121 | E12: 2530 | F12: 2671 | G12: 3158 | H12: 3465
A13: + 판매 및 마케팅 비용 | B13: IS_SELLING_EXPENSES | C13: 971 | D13: 1136 | E13: 1336 | F13: 1341 | G13: 1560 | H13: 1659
A14: + 일반관리비 | B14: IS_GENERAL_AND_ADMINISTRATIVE | C14: 1096 | D14: 985 | E14: 1194 | F14: 1330 | G14: 1598 | H14: 1806
A15: + 연구개발 (R&D) | B15: IS_OPER_EXPENSES_RD_GAAP | C15: — | D15: — | E15: — | F15: — | G15: —
A16: + 감가상각 & 무형자산상각 | B16: IS_DEPRECIATION_AND_AMORTIZATION | C16: 767 | D16: 804 | E16: 861 | F16: 943 | G16: 1034 | H16: 1178
A17: + 기타 영업비용 | B17: OTHER_OPERATING_EXPENSES_RATIO | C17: 4931 | D17: 5376 | E17: 7106 | F17: 8039 | G17: 8139 | H17: 10055
A18: 영업이익 (손실) | B18: IS_OPER_INC | C18: 14081 | D18: 15804 | E18: 18813 | F18: 21000 | G18: 23595 | H18: 24195
A19: - 영업외 (이익) 손실 | B19: NONOP_INCOME_LOSS | C19: 291 | D19: -259 | E19: 677 | F19: -37 | G19: -321 | H19: -148
A20: + 순 이자비용 | B20: IS_NET_INTEREST_EXPENSE | C20: 516 | D20: 513 | E20: 538 | F20: 644 | G20: 641
A21: + 이자비용 | B21: IS_INT_EXPENSE | C21: 516 | D21: 513 | E21: 538 | F21: 644 | G21: 641 | H21: 555
A22: - 이자수익 | B22: IS_INT_INC | C22: 0 | D22: 0 | E22: 0 | F22: 0 | G22: 0
A23: + 외환 (이익) 손실 | B23: IS_FOREIGN_EXCH_LOSS | C23: 0 | D23: 0 | E23: 0 | F23: 0 | G23: 0 | H23: -195
A24: + 관계회사 (이익) 손실 | B24: INCOME_LOSS_FROM_AFFILIATES | C24: 0 | D24: 0 | E24: 0 | F24: 0 | G24: 0 | H24: 0
A25: + 기타 영업외 (이익) 손실 | B25: OTHER_NONOP_INCOME_LOSS | C25: -225 | D25: -772 | E25: 139 | F25: -681 | G25: -962 | H25: -508
A26: 세전이익 | B26: PRETAX_INC | C26: 13790 | D26: 16063 | E26: 18136 | F26: 21037 | G26: 23916 | H26: 24343
A27: - 법인세 비용(수익) | B27: IS_INC_TAX_EXP | C27: 2924 | D27: 3752 | E27: 3179 | F27: 3764 | G27: 4173 | H27: 4057
A28: + 당기법인세 | B28: IS_CURRENT_INCOME_TAX_BENEFIT | C28: 2617 | D28: 2881 | E28: 3515 | F28: 4247 | G28: 4273 | H28: 4057
A29: + 이연법인세 | B29: IS_DEFERRED_INCOME_TAX_BENEFIT | C29: 307 | D29: 871 | E29: -336 | F29: -483 | G29: -100
A30: 계속사업 이익 (손실) | B30: IS_INC_BEF_XO_ITEM | C30: 10866 | D30: 12311 | E30: 14957 | F30: 17273 | G30: 19743 | H30: 20286
A31: - 순 특별손실(이익) | B31: XO_GL_NET_OF_TAX | C31: 0 | D31: 0 | E31: 0 | F31: 0 | G31: 0 | H31: 0
A32: + 중단사업 | B32: IS_DISCONTINUED_OPERATIONS | C32: 0 | D32: 0 | E32: 0 | F32: 0 | G32: 0 | H32: 0
A33: + 특별항목 & 회계기준 변경 | B33: EXTRAORD_ITEMS_ACCOUNTING_CHANGS | C33: 0 | D33: 0 | E33: 0 | F33: 0 | G33: 0 | H33: 0
A34: 소수주주지분 포함 이익 (손실) | B34: NI_INCLUDING_MINORITY_INT_RATIO | C34: 10866 | D34: 12311 | E34: 14957 | F34: 17273 | G34: 19743 | H34: 20286
A35: - 소수주주지분 | B35: MIN_NONCONTROL_INTEREST_CREDITS | C35: 0 | D35: 0 | E35: 0 | F35: 0 | G35: 0 | H35: 0
A36: 순이익, GAAP | B36: NET_INCOME | C36: 10866 | D36: 12311 | E36: 14957 | F36: 17273 | G36: 19743 | H36: 20286
A37: - 우선주 배당 | B37: IS_TOT_CASH_PFD_DVD | C37: 0 | D37: 0 | E37: 0 | F37: 0 | G37: 0 | H37: 0
A38: - 기타조정액 | B38: OTHER_ADJUSTMENTS | C38: 0 | D38: 0 | E38: 0 | F38: 0 | G38: 0 | H38: 0
A39: 보통주 순이익, GAAP | B39: EARN_FOR_COMMON | C39: 10866 | D39: 12311 | E39: 14957 | F39: 17273 | G39: 19743 | H39: 20286
A41: 보통주주에 대한 배당가능 순이익, 조정 | B41: EARN_FOR_COMMON | C41: 11166.69 | D41: 12896.37 | E41: 15940 | F41: 18142 | G41: 20302 | H41: 22011
A42: 비정상손익 | B42: IS_NET_ABNORMAL_ITEMS | C42: 300.69 | D42: 585.37 | E42: 983 | F42: 869 | G42: 559 | H42: 1725
... A53: 계속사업 희석 EPS, 조정 | B53: IS_DIL_EPS_CONT_OPS | C53: 4.5045 | D53: 5.2789 | E53: 7.4625 | F53: 8.7012 | G53: 10.0059 | H53: 10.581762
...

Sheet BS(Yearly)
A2: 비자 (V US) - 공시기준
A4: 단위: USD 백만(주당수치 제외) | B4: FY 2020 | C4: FY 2021 | D4: FY 2022 | E4: FY 2023 | F4: FY 2024
A5: 12 개월 결산 | B5: 09/30/2020 | C5: 09/30/2021 | D5: 09/30/2022 | E5: 09/30/2023 | F5: 09/30/2024
A6: 대차대조표
A7: 유동자산
B8: 16289 | C8: 16487 | D8: 15689 | E8: 16286 | F8: 11975
A9: Available-for-Sale Securities(단기투자) | B9: 3752 | C9: 2025 | D9: 2833 | E9: 3842 | F9: 0
A10: Trading Securities | B10: — | C10: — | D10: — | E10: — | F10: 3200
A11: Accounts Receivable(매출채권) | B11: 1618 | C11: 1968 | D11: 2020 | E11: 2291 | F11: 2561
A12: Prepaid Expenses And Other Current Assets(선급비용 및 기타 유동자산) | B12: 757 | C12: 856 | D12: 2668 | E12: 2584 | F12: 3312
A13: Restricted Cash—Litigation Escrow.(제한된 현금 - 소송 에스크로) | B13: 901 | C13: 894 | D13: 1449 | E13: 1764 | F13: 3089
A14: Customer Collateral (Other Current Assets)(고객담보자산(기타유동자산)) | B14: 1850 | C14: 2260 | D14: 2342 | E14: 3005 | F14: 3524
A15: Settlement Receivable(결제대금 수취채권) | B15: 1264 | C15: 1758 | D15: 1932 | E15: 2183 | F15: 4454
A16: Cash And Cash Equivalents(현금 및 현금성 자산) | B16: 16289 | C16: 16487 | D16: 1449 | E16: 3842 | F16: 3089
A17: Investment securities(단기투자) | B17: 3752 | C17: 2025 | D17: 2833 | E17: 1764 | F17: 11975
A18: Restricted cash equivalents—U.S. litigation escrow | B18: 901 | C18: 894 | D18: 15689 | E18: 16286 | F18: 3200
A19: Current portion of client incentives | B19: 1214 | C19: 1359 | D19: 1272 | E19: 1577 | F19: 1918
A20: Total Current Assets(총 유동자산) | B20: 27645 | C20: 27607 | D20: 30205 | E20: 33532 | F20: 34033
A21: Investment Securities, Available-for-Sale(매도가능 투자증권) | B21: 231 | C21: 1705 | D21: 2136 | E21: 1921 | F21: 2545
A22: Property, Equipment And Technology, Net(유형자산 및 기술자산 순액) | B22: 2737 | C22: 2715 | D22: 3223 | E22: 3425 | F22: 3824
... A36: Total assets(총 자산) | B36: 80919 | C36: 82896 | D36: 85501 | E36: 90499 | F36: 94511
A37: 유동부채
A38: Accounts Payable(매입채무) | B38: 174 | C38: 266 | D38: 340 | E38: 375 | F38: 479
A39: Current Portion of Long-Term Debt(유동성 장기부채) | B39: 2999 | C39: 999 | D39: 2250 | E39: 0 | F39: —
A40: Accrued Compensation And Benefits(미지급 급여 및 복리후생) | B40: 821 | C40: 1211 | D40: 1359 | E40: 1506 | F40: 1538
A41: Accrued Liabilities(미지급 부채) | B41: 914 | C41: 983 | D41: 1456 | E41: 1751 | F41: 4909
A42: Current Portion of Accrued Litigation | B42: 1840 | C42: — | D42: — | E42: — | F42: —
A43: Accrued Liabilities | B43: — | C43: — | D43: — | E43: — | F43: 1727
A44: Other Current Liabilities - Redeemable Common Stock | B44: 4176 | C44: 5243 | D44: 6099 | E44: 8177 | F44: —
A45: Settlement Payable - Current Liabilities | B45: — | C45: — | D45: — | E45: — | F45: 9075
A46: Current Portion Of Member Deposits | B46: 1850 | C46: 2260 | D46: 2342 | E46: 3005 | F46: —
