Workbook
Name _MOD1: #REF!
Name \a: #N/A
Name \b: #N/A
Name \I: #REF!
Name \P: #REF!
Name A_K___s__Global__I_T: #REF!
Name Acc_payable_growth_fore: #REF!
Name Acc_Rec_growth_fore: #REF!
Name Accrued_compensation_growth_fore: #REF!
Name Accrued_expenses_growth_fore: #REF!
Name Accum_Cap_Expenses_growth_fore: #REF!
Name Accum_Goodwill_Amort_growth_fore: #REF!
Name Adj_net_oper_fore: #REF!
Name AveSize: #REF!
Name BS_C: #REF!
Name Cash_fore: #REF!
Name Cash_growth_fore: #REF!
Name Cash_operating_taxes_fore: #REF!
Name CDS: #REF!
Name CE_C: #REF!
Name CF_C: #REF!
Name CFormats: #REF!
Name codeDestination: #REF!
Name CODELK_Path: #REF!
Name ColumnHeading: #REF!
Name Comdty: #REF!
Name Corp: #REF!
Name CR3RT: #REF!
Name CR3RTDK: #REF!
Name CR5RTDK: #REF!
Name CTopics: #REF!
Name Cur: #REF!
Name Customer_deposits_growth_fore: #REF!
Name Debt_Market_Cap_Ratio: #REF!
Name Deferred_tax_asset_growth_fore: #REF!
Name Deferred_tax_liability_growth_fore: #REF!
Name Dep_margin_fore: #REF!
Name Depreciation_fore: #REF!
Name DetailColumns: #REF!
Name DnA_fore: #REF!
Name DnA_growth_fore: #REF!
Name DR: #REF!
Name DSDDE_Path: #REF!
Name EBIT_fore: #REF!
Name EBIT_margin_fore: #REF!
Name EBITA_fore: #REF!
Name EBITDA_fore: #REF!
Name EBITDA_margin_fore: #REF!
Name Excel_Version: #REF!
Name Expl_forecast_1st_yr: #REF!
Name Expl_forecast_2nd_yr: #REF!
Name Expl_forecast_3rd_yr: #REF!
Name ExtFiles: #REF!
Name Fixed_asset_turns_fore: #REF!
Name Formats: #REF!
Name FR_COM_ABBR: " "
Name FR_COM_ABBR_LINK: " "
Name FR_COM_AGG: 0
Name FR_COM_NAME_LINK: " "
Name FR_COU_ABBR: " "

Sheet Valuation
B2: 테크윙(089030.KQ) Valuation&Estimation Logic
B10: RFS Research Team 2

Sheet Expected IS
A1: 테크윙(089030.KQ)
A2: Expected IS Sheet
A3: (units in Millions KRW )
B5: 단위: 백만 원 | C5: 1Q25 | D5: 2Q25 | E5: 3Q25 | F5: 4Q25E | G5: 1Q26E | H5: 2Q26E | I5: 3Q26E | J5: 4Q26E | K5: 2025E | L5: 2026E
B6: 매출액 | C6: ='매출 추정'!C6 -> 34587.215 | D6: ='매출 추정'!D6 -> 48893.653 | E6: ='매출 추정'!E6 -> 41765.844 | F6: ='매출 추정'!F6 -> 50314.986 | G6: ='매출 추정'!G6 -> 143990.83 | H6: ='매출 추정'!H6 -> 219447.31 | I6: ='매출 추정'!I6 -> 212606.61 | J6: ='매출 추정'!J6 -> 215989.92 | ... L6: ='매출 추정'!L6 -> 792034.67 | M6: =(L6-K6)/K6 -> 3.511432
B7: 매출원가 | C7: ='비용 추정'!G17 -> 19942.025 | D7: ='비용 추정'!H17 -> 30065.138 | E7: ='비용 추정'!I17 -> 22406.702 | F7: ='비용 추정'!J17 -> 28341.068 | G7: ='비용 추정'!K17 -> 75986.5 | H7: ='비용 추정'!L17 -> 115125.19 | I7: ='비용 추정'!M17 -> 110887.51 | J7: ='비용 추정'!N17 -> 112989.9 | K7: ='비용 추정'!R17 -> 100754.93 | L7: ='비용 추정'!S17 -> 414989.09
B8: (%) | C8: =C7/C6 -> 0.57657217 | D8: =D7/D6 -> 0.61490881 | E8: =E7/E6 -> 0.53648389 | F8: =F7/F6 -> 0.5632729 | G8: =G7/G6 -> 0.52771762 | H8: =H7/H6 -> 0.52461426 | I8: =I7/I6 -> 0.5215619 | J8: =J7/J6 -> 0.5231258 | ... L8: =L7/L6 -> 0.52395319
B9: 매출총이익 | C9: =C6-C7 -> 14645.189 | D9: =D6-D7 -> 18828.515 | E9: =E6-E7 -> 19359.141 | F9: =F6-F7 -> 21973.918 | G9: =G6-G7 -> 68004.333 | H9: =H6-H7 -> 104322.12 | I9: =I6-I7 -> 101719.1 | J9: =J6-J7 -> 103000.02 | ... L9: =L6-L7 -> 377045.57
B10: GPM(%) | C10: =C9/C6 -> 0.42342783 | D10: =D9/D6 -> 0.38509119 | E10: =E9/E6 -> 0.46351611 | F10: =F9/F6 -> 0.4367271 | G10: =G9/G6 -> 0.47228238 | H10: =H9/H6 -> 0.47538574 | I10: =I9/I6 -> 0.4784381 | J10: =J9/J6 -> 0.4768742 | ... L10: =L9/L6 -> 0.47604681
B11: 판매비와 관리비 | C11: ='비용 추정'!G29 -> 13347.369 | D11: ='비용 추정'!H29 -> 12624.412 | E11: ='비용 추정'!I29 -> 12248 | F11: ='비용 추정'!J29 -> 13792.022 | G11: ='비용 추정'!K29 -> 24877.947 | H11: ='비용 추정'!L29 -> 33524.442 | I11: ='비용 추정'!M29 -> 32755.164 | J11: ='비용 추정'!N29 -> 33160.866 | K11: ='비용 추정'!R29 -> 52011.803 | L11: ='비용 추정'!S29 -> 124318.42
B12: (%) | C12: =C11/C6 -> 0.38590471 | D12: =D11/D6 -> 0.25820145 | E12: =E11/E6 -> 0.29325398 | F12: =F11/F6 -> 0.2741136 | G12: =G11/G6 -> 0.17277452 | H12: =H11/H6 -> 0.15276761 | I12: =I11/I6 -> 0.15406466 | J12: =J11/J6 -> 0.15352969 | ... L12: =L11/L6 -> 0.15696083
B13: 영업이익 | C13: =C9-C11 -> 1297.8204 | D13: =D9-D11 -> 6204.103 | E13: =E9-E11 -> 7111.1414 | F13: =F9-F11 -> 8181.8958 | G13: =G9-G11 -> 43126.386 | H13: =H9-H11 -> 70797.681 | I13: =I9-I11 -> 68963.936 | J13: =J9-J11 -> 69839.153 | ... L13: =L9-L11 -> 252727.16 | M13: =(L13-K13)/K13 -> 10.086975
B14: OPM(%) | C14: =C13/C6 -> 0.037523125 | D14: =D13/D6 -> 0.12688974 | E14: =E13/E6 -> 0.17026213 | F14: =F13/F6 -> 0.1626135 | G14: =G13/G6 -> 0.29950786 | H14: =H13/H6 -> 0.32261813 | I14: =I13/I6 -> 0.32437344 | J14: =J13/J6 -> 0.3233445 | ... L14: =L13/L6 -> 0.31908598
B15: 금융수익 | C15: ='비용 추정'!G61 -> 857.441 | D15: ='비용 추정'!H61 -> 4146.555 | E15: ='비용 추정'!I61 -> -4293 | F15: ='비용 추정'!J61 -> 434.0035 | G15: ='비용 추정'!K61 -> 286.24987 | H15: ='비용 추정'!L61 -> 143.45209 | I15: ='비용 추정'!M61 -> -857.32363 | J15: ='비용 추정'!N61 -> 1.595459 | K15: ='비용 추정'!R61 -> 1144.9995 | L15: ='비용 추정'!S61 -> -426.02621
B16: 금융원가 | C16: ='비용 추정'!G65 -> 2220.026 | D16: ='비용 추정'!H65 -> 4778.148 | E16: ='비용 추정'!I65 -> 3088 | F16: ='비용 추정'!J65 -> 4537.9902 | G16: ='비용 추정'!K65 -> 3656.0411 | H16: ='비용 추정'!L65 -> 4015.0448 | I16: ='비용 추정'!M65 -> 3824.269 | J16: ='비용 추정'!N65 -> 4008.3363 | K16: ='비용 추정'!R65 -> 14624.164 | L16: ='비용 추정'!S65 -> 15503.691
B17: 기타수익 | C17: ='비용 추정'!G69 -> 2295.6 | D17: ='비용 추정'!H69 -> 22828.642 | E17: ='비용 추정'!I69 -> -6173 | F17: ='비용 추정'!J69 -> 5559.9407 | G17: ='비용 추정'!K69 -> 6127.7957 | H17: ='비용 추정'!L69 -> 7085.8446 | I17: ='비용 추정'!M69 -> 3150.1453 | J17: ='비용 추정'!N69 -> 5480.9316 | K17: ='비용 추정'!R69 -> 24511.183 | L17: ='비용 추정'!S69 -> 21844.717
B18: 기타비용 | C18: ='비용 추정'!G75 -> 4444.638 | D18: ='비용 추정'!H75 -> 574.804 | E18: ='비용 추정'!I75 -> 1711 | F18: ='비용 추정'!J75 -> 11819.798 | G18: ='비용 추정'!K75 -> 4637.5599 | H18: ='비용 추정'!L75 -> 4685.7904 | I18: ='비용 추정'!M75 -> 5713.537 | J18: ='비용 추정'!N75 -> 6714.1713 | K18: ='비용 추정'!R75 -> 18550.24 | L18: ='비용 추정'!S75 -> 21751.059
B19: 법인세차감전순이익 | C19: =C13+C15-C16+C17-C18 -> -2213.8026 | D19: =D13+D15-D16+D17-D18 -> 27826.348 | E19: =E13+E15-E16+E17-E18 -> -8153.8586 | F19: =F13+F15-F16+F17-F18 -> -2181.9479 | G19: =G13+G15-G16+G17-G18 -> 41246.831 | H19: =H13+H15-H16+H17-H18 -> 69326.143 | I19: =I13+I15-I16+I17-I18 -> 61718.952 | J19: =J13+J15-J16+J17-J18 -> 64599.172 | ... L19: =L13+L15-L16+L17-L18 -> 236891.1
B20: 법인세비용 | C20: ='비용 추정'!G82 -> -140.8909 | D20: ='비용 추정'!H82 -> 6260.4964 | E20: ='비용 추정'!I82 -> -1468 | F20: ='비용 추정'!J82 -> -1768.9954 | G20: ='비용 추정'!K82 -> 8244.3662 | H20: ='비용 추정'!L82 -> 13860.229 | I20: ='비용 추정'!M82 -> 12338.79 | J20: ='비용 추정'!N82 -> 12914.834 | K20: ='비용 추정'!R82 -> 2882.6101 | L20: ='비용 추정'!S82 -> 47358.219
B21: 당기순이익 | C21: =C19-C20 -> -2072.9117 | D21: =D19-D20 -> 21565.852 | E21: =E19-E20 -> -6685.8586 | F21: =F19-F20 -> -412.95249 | G21: =G19-G20 -> 33002.465 | H21: =H19-H20 -> 55465.914 | I21: =I19-I20 -> 49380.161 | J21: =J19-J20 -> 51684.338 | ... L21: =L19-L20 -> 189532.88
B22: (%) | C22: 0.13039223 | D22: 0.11330898 | E22: 0.12402988 | F22: 0.13575303 | G22: 0.12971337 | H22: 0.126987 | I22: 0.13464847 | J22: 0.13476415 | K22: 0.13476415 | L22: 0.13476415

Sheet 매출 추정
A1: 테크윙(089030.KQ)
A2: Revenue Estimation Sheet
A3: (units in Millions KRW )
B5: 단위: 백만 원 | C5: 1Q25 | D5: 2Q25 | E5: 3Q25 | F5: 4Q25E | G5: 1Q26E | H5: 2Q26E | I5: 3Q26E | J5: 4Q26E | K5: 2025E | L5: 2026E
B6: 매출 | C6: ='IS(Quaterly)'!L10 -> 34587.215 | D6: ='IS(Quaterly)'!M10 -> 48893.653 | E6: ='IS(Quaterly)'!N10 -> 41765.844 | F6: =F8+F10+F12+F14 -> 50314.986 | G6: =G8+G10+G12+G14 -> 143990.83 | H6: =H8+H10+H12+H14 -> 219447.31 | I6: =I8+I10+I12+I14 -> 212606.61 | J6: =J8+J10+J12+J14 -> 215989.92 | K6: =SUM(C6:F6) -> 175561.7 | L6: =SUM(G6:J6) -> 792034.67
B7: YoY(%) or QoQ(%) | C7: - | D7: =(D6-C6)/C6 -> 0.4136337 | E7: =(E6-D6)/D6 -> -0.14578189 | F7: =(F6-E6)/E6 -> 0.20469221 | G7: =(G6-F6)/F6 -> 1.8617882 | H7: =(H6-G6)/G6 -> 0.52403669 | I7: =(I6-H6)/H6 -> -0.031172435 | J7: =(J6-I6)/I6 -> 0.015913483 | K7: - | L7: =(L6-K6)/K6 -> 3.511432
B8: 큐브 프로버 | C8: 3000 | D8: 10000 | E8: 5000 | F8: =C20 -> 8000 | G8: =D20 -> 103950 | H8: =E20 -> 173250 | I8: =F20 -> 173250 | J8: =G20 -> 173250 | K8: =SUM(C8:F8) -> 26000 | L8: =SUM(G8:J8) -> 623700
B9: of Revenue(%) | C9: =C8/C$6 -> 0.086737253 | D9: =D8/D$6 -> 0.20452553 | E9: =E8/E$6 -> 0.11971505 | F9: =F8/F$6 -> 0.15899835 | G9: =G8/G$6 -> 0.72192096 | H9: =H8/H$6 -> 0.78948335 | I9: =I8/I$6 -> 0.81488531 | J9: =J8/J$6 -> 0.80212078 | ... L9: =L8/L$6 -> 0.78746553
B10: 핸들러 | C10: =12922-3000 -> 9922 | D10: =35790-D8-C10-C8 -> 12868 | E10: =49828-D10-C10-E8-D8-C8 -> 9038 | F10: =C44 -> 14276.143 | G10: =D44 -> 11210.702 | H10: =E44 -> 18433.584 | I10: =F44 -> 11415.143 | J10: =G44 -> 14561.476 | K10: =SUM(C10:F10) -> 46104.143 | L10: =SUM(G10:J10) -> 55620.905
B11: of Revenue(%) | C11: =C10/C$6 -> 0.28686901 | D11: =D10/D$6 -> 0.26318345 | E11: =E10/E$6 -> 0.21639692 | F11: =F10/F$6 -> 0.2837354 | G11: =G10/G$6 -> 0.077857055 | H11: =H10/H$6 -> 0.084000043 | I11: =I10/I$6 -> 0.053691384 | J11: =J10/J$6 -> 0.067417389 | ... L11: =L10/L$6 -> 0.070225341
B12: C.O.K | C12: 12512 | D12: 12688 | E12: 19189 | F12: =C54 -> 19500 | G12: =D54 -> 18691.684 | H12: =E54 -> 18691.684 | I12: =F54 -> 18691.684 | J12: =G54 -> 18691.684 | K12: =SUM(C12:F12) -> 63889 | L12: =SUM(G12:J12) -> 74766.737
B13: of Revenue(%) | C13: =C12/C$6 -> 0.36175217 | D13: =D12/D$6 -> 0.25950199 | E13: =E12/E$6 -> 0.45944241 | F13: =F12/F$6 -> 0.38755849 | G13: =G12/G$6 -> 0.12981163 | H13: =H12/H$6 -> 0.085176182 | I13: =I12/I$6 -> 0.087916762 | J13: =J12/J$6 -> 0.086539615 | ... L13: =L12/L$6 -> 0.094398314
B14: 기타 | C14: 9153.2149 | D14: 13337.653 | E14: 8538.8437 | F14: =E14 -> 8538.8437 | G14: =AVERAGE(D14:F14) -> 10138.447 | H14: =AVERAGE(E14:G14) -> 9072.0447 | I14: =AVERAGE(F14:H14) -> 9249.7783 | J14: =AVERAGE(G14:I14) -> 9486.7566 | K14: =SUM(C14:F14) -> 39568.555 | L14: =SUM(G14:J14) -> 37947.026
B15: of Revenue(%) | C15: =C14/C$6 -> 0.26464157 | D15: =D14/D$6 -> 0.27278904 | E15: =E14/E$6 -> 0.20444562 | F15: =F14/F$6 -> 0.16970776 | G15: =G14/G$6 -> 0.070410362 | H15: =H14/H$6 -> 0.041340423 | I15: =I14/I$6 -> 0.043506543 | J15: =J14/J$6 -> 0.04392222 | ... L15: =L14/L$6 -> 0.047910815
B17: 큐브 프로버 추정
B19: 단위: 백만 원 | C19: 4Q25E | D19: 1Q26E | E19: 2Q26E | F19: 3Q26E | G19: 4Q26E | H19: 2026E | J19: 단위: 대/백만 원
B20: 큐브 프로버 | C20: 8000 | D20: =D34 -> 103950 | E20: =E34 -> 173250 | F20: =F34 -> 173250 | G20: =G34 -> 173250 | H20: =SUM(D20:G20) -> 623700 | J20: 웨이퍼 출하량 1K당 필요한 큐브 프로버수 | M20: 1.5
B21: YoY(%) or QoQ(%) | C21: - | D21: =(D20-C20)/C20 -> 11.99375 | E21: =(E20-D20)/D20 -> 0.66666667 | F21: =(F20-E20)/E20 -> 0 | G21: =(G20-F20)/F20 -> 0 | H21: - | J21: 큐브 프로버 ASP | M21: 2200
B23: 단위: K | C23: 4Q25E | D23: 1Q26E | E23: 2Q26E | F23: 3Q26E | G23: 4Q26E | H23: 2026E
B24: 2026년 신규 라인 웨이퍼 증가량 | C24: - | D24: =D25+D28 -> 45 | E24: =E25+E28 -> 75 | F24: =F25+F28 -> 75 | G24: =G25+G28 -> 75 | H24: =SUM(D24:G24) -> 270 | J24: 동사가 퀄리피케이션을 통과한 2개사의 '26년 HBM 신규 증설 라인에 투입될 큐브 프로버의 매출만을 추정함.
B25: SK하이닉스(분기 총 출하량) | C25: - | D25: =D27*3 -> 15 | E25: =E27*3 -> 45 | F25: =F27*3 -> 30 | G25: =G27*3 -> 30 | H25: =SUM(D25:G25) -> 120
B26: M15X 분기별 월평균 웨이퍼 출하량 | C26: - | D26: =D27 -> 5 | E26: =D26+E27 -> 20 | F26: =E26+F27 -> 30 | G26: =F26+G27 -> 40 | H26: =SUM(D26:G26) -> 95 | J26: SK하이닉스의 경우, HBM용 증설 라인인 M15X의 웨이퍼 출하량 증가분을 기준으로 동사의 납품 대수를 추정함.
B27: M15X 웨이퍼 출하량 증가분 | C27: - | D27: 5 | E27: 15 | F27: 10 | G27: 10 | H27: -
B28: 삼성전자(분기 총 출하량) | C28: - | D28: =D30*3 -> 30 | E28: =E30*3 -> 30 | F28: =F30*3 -> 45 | G28: =G30*3 -> 45 | H28: =SUM(D28:G28) -> 150
B29: P4L 분기별 월평균 웨이퍼 출하량 | C29: - | D29: =D30 -> 10 | E29: =D29+E30 -> 20 | F29: =E29+F30 -> 35 | G29: =F29+G30 -> 50 | H29: =SUM(D29:G29) -> 115 | J29: 삼성전자의 경우, HBM용 증설 라인인 P4L의 웨이퍼 출하량 증가분을 기준으로 동사의 납품 대수를 추정함.
B30: P4L 웨이퍼 출하량 증가분 | C30: - | D30: 10 | E30: 10 | F30: 15 | G30: 15 | H30: -
B31: 판매대수(침투율 100%) | C31: 4 | D31: =D24*$M$20 -> 67.5 | E31: =E24*$M$20 -> 112.5 | F31: =F24*$M$20 -> 112.5 | G31: =G24*$M$20 -> 112.5 | H31: =H24*$M$20 -> 405 | J31: CAPA 증설이 앞당겨질 경우, 300대 이상의 판매량 기록도 가능할 것으로 전망함.
B32: Bull 큐브 프로버 매출 | C32: =C31*$M$21 -> 8800 | D32: =D31*$M$21 -> 148500 | E32: =E31*$M$21 -> 247500 | F32: =F31*$M$21 -> 247500 | G32: =G31*$M$21 -> 247500 | H32: =H31*$M$21 -> 891000 | J32: 침투율 100%를 Bull 케이스로 선정함.
B33: 판매대수(침투율 70%) | C33: 4 | D33: =D31*0.7 -> 47.25 | E33: =E31*0.7 -> 78.75 | F33: =F31*0.7 -> 78.75 | G33: =G31*0.7 -> 78.75 | H33: =H31*0.7 -> 283.5 | J33: 현재 동사의 CAPA 계획대로라면, 연간 큐브 프로버 약 290~300대 생산 가능함.
B34: Base 큐브 프로버 매출 | C34: =C33*$M$21 -> 8800 | D34: =D33*$M$21 -> 103950 | E34: =E33*$M$21 -> 173250 | F34: =F33*$M$21 -> 173250 | G34: =G33*$M$21 -> 173250 | H34: =H33*$M$21 -> 623700 | J34: 침투율 70%가 Base 케이스로 적합하다고 판단함.
B36: 단위: 대/% | C36: 4Q25E | D36: 1Q26E | E36: 2Q26E | F36: 3Q26E | G36: 4Q26E | H36: 2026E
B37: 분기당 큐브 프로버 생산 대수 | C37: =C38*C39*3 -> 54 | D37: =D38*D39*3 -> 54 | E37: =E38*E39*3 -> 68.25 | F37: =F38*F39*3 -> 84 | G37: =G38*G39*3 -> 84 | H37: =SUM(D37:G37) -> 290.25 | J37: 4Q25 큐브 프로버 매출의 경우, 전방사 장비 반입을 감안하여 1Q26부터 매출로 인식될 것으로 가정함.
B38: 월간 큐브프로버 최대 생산 CAPA | C38: 30 | D38: 30 | E38: 35 | F38: 40 | G38: 40 | H38: =SUM(D38:G38) -> 145
B39: 가동률 | C39: 0.6 | D39: 0.6 | E39: 0.65 | F39: 0.7 | G39: 0.7 | H39: -
B41: 핸들러 추정
B43: 단위: 백만 원 | C43: 4Q25E | D43: 1Q26E | E43: 2Q26E | F43: 3Q26E | G43: 4Q26E | H43: 2026E | J43: 단위: 백만 원 | M43: ASP
B44: 핸들러 | C44: =C46+C48 -> 14276.143 | D44: =D46+D48 -> 11210.702 | E44: =E46+E48 -> 18433.584 | F44: =F46+F48 -> 11415.143 | G44: =G46+G48 -> 14561.476 | H44: =H46+H48 -> 69897.048 | J44: 메모리핸들러 ASP | M44: 500
B45: YoY(%) or QoQ(%) | C45: - | D45: =(D44-C44)/C44 -> -0.2147247 | E45: =(E44-D44)/D44 -> 0.64428448 | F45: =(F44-E44)/E44 -> -0.38074207 | G45: =(G44-F44)/F44 -> 0.27562804 | H45: - | J45: 비메모리핸들러 ASP | M45: 300
B46: 메모리 핸들러 | C46: =C47*$M$44 -> 8276.1427 | D46: =D47*$M$44 -> 8060.7022 | E46: =E47*$M$44 -> 8458.5836 | F46: =F47*$M$44 -> 8265.1428 | G46: =G47*$M$44 -> 8261.4762 | H46: =H47*$M$44 -> 41322.048 | J46: 메모리 핸들러의 경우, 더 이상 성장여력이 제한될 것으로 판단. 25년 3분기 Avg Flat을 적용하여 동사의 납품대수를 추정함.
B47: 메모리 핸들러 Q | C47: 16.552285 | D47: 16.121404 | E47: 16.917167 | F47: 16.530286 | G47: 16.522952 | H47: =SUM(C47:G47) -> 82.644095
...

Sheet PER
A1: 테크윙(089030.KQ)
A2: Historical PER Valuation
A3: (units in Millions KRW )
B5: 테크윙 Historical P/E Valuation
B6: '26E 당기순이익 | C6: ='Expected IS'!L21 -> 189532.88 | D6: 백만 원 | E6: (A)
B7: Target P/E | C7: =18 -> 18 | D7: 배 | E7: (B)
B8: 발행 주식 수 | C8: =WACC!E29 -> 38366816 | D8: 주 | E8: (C)
B9: '26E EPS | C9: =C6/C8*10^6 -> 4940.021 | D9: 원 | E9: (D)
B10: 적정주가 | C10: =C6*C7/C8*10^6 -> 88920.379 | D10: 원 | E10: (E)=(B)*(D)
B11: Target Price | C11: =ROUND(C10,-3) -> 89000 | D11: 원
B12: Current Price | C12: 47500 | D12: 원 | E12: '25.11.28 기준
B13: Upside | C13: =(C11-C12)/C12*100 -> 87.368421 | D13: %

Sheet DCF>>>
A1: 테크윙(089030.KQ)
A2: PEER PER Valuation
A3: (units in Millions KRW )
E5: 2022 | F5: 2023 | G5: 2024 | H5: 2025E | I5: 2026E | J5: 2027E | K5: 2028E | L5: 2029E | M5: 2030E | N5: Terminal Value | Q5: DCF Valuation | T5: (단위: 백만원, %)
A6: 매출액 | E6: 267491 | F6: 133604 | G6: 185507 | H6: ='매출 추정'!K6 -> 175561.7 | I6: ='매출 추정'!L6 -> 792034.67 | J6: =I6*1.1 -> 871238.14 | K6: =J6*1.05 -> 914800.04 | L6: =K6*1.05 -> 960540.04 | M6: =L6*1.05 -> 1008567 | Q6: WACC | T6: =F32 -> 0.098434027
A7: %YoY Growth | F7: =F6/E6-1 -> -0.50052899 | G7: =G6/F6-1 -> 0.38848388 | H7: =H6/G6-1 -> -0.053611467 | I7: =I6/H6-1 -> 3.511432 | J7: =J6/I6-1 -> 0.1 | K7: =K6/J6-1 -> 0.05 | L7: =L6/K6-1 -> 0.05 | M7: =M6/L6-1 -> 0.05 | Q7: Terminal growth rate(g) | T7: =F31 -> 0.03
A8: 매출원가 | E8: 158044 | F8: 84056 | G8: 114022 | H8: ='비용 추정'!R17 -> 100754.93 | I8: ='비용 추정'!S17 -> 414989.09 | J8: =I8*1.05 -> 435738.55 | K8: =J8*1.05 -> 457525.48 | L8: =K8*1.05 -> 480401.75 | M8: =L8*1.05 -> 504421.84 | Q8: ∑ PV of FCF | T8: =F36 -> 776428.28
A9: 매출총이익 | E9: =E6-E8 -> 109447 | F9: =F6-F8 -> 49548 | G9: =G6-G8 -> 71485 | H9: =H6-H8 -> 74806.764 | I9: =I6-I8 -> 377045.57 | J9: =J6-J8 -> 435499.59 | K9: =K6-K8 -> 457274.57 | L9: =L6-L8 -> 480138.29 | M9: =M6-M8 -> 504145.21 | Q9: PV of TV | T9: =F37 -> 2556667.5
A10: %GP Margin | E10: =E9/E6 -> 0.40916143 | F10: =F9/F6 -> 0.37085716 | G10: =G9/G6 -> 0.38534934 | H10: =H9/H6 -> 0.42609957 | I10: =I9/I6 -> 0.47604681 | J10: =J9/J6 -> 0.49986286 | K10: =K9/K6 -> 0.49986286 | L10: =L9/L6 -> 0.49986286 | M10: =M9/M6 -> 0.49986286 | Q10: 영업가치 | T10: =T8+T9 -> 3333095.8
A11: 판매비와관리비 | E11: 51774 | F11: 46388 | G11: 48075 | H11: ='비용 추정'!R29 -> 52011.803 | I11: ='비용 추정'!S29 -> 124318.42 | J11: =I11*1.05 -> 130534.34 | K11: =J11*1.05 -> 137061.06 | L11: =K11*1.05 -> 143914.11 | M11: =L11*1.05 -> 151109.81 | Q11: (+) 비영업자산가치 | T11: =F39 -> 103519
A12: 영업이익 | E12: =E9-E11 -> 57673 | F12: =F9-F11 -> 3160 | G12: =G9-G11 -> 23410 | H12: =H9-H11 -> 22794.961 | I12: =I9-I11 -> 252727.16 | J12: =J9-J11 -> 304965.25 | K12: =K9-K11 -> 320213.51 | L12: =L9-L11 -> 336224.19 | M12: =M9-M11 -> 353035.39 | Q12: (-) 타인자본가치 (순차입금) | T12: =F40 -> 287909
A13: %OP Margin | E13: =E12/E6 -> 0.21560725 | F13: =F12/F6 -> 0.023651986 | G13: =G12/G6 -> 0.1261947 | H13: =H12/H6 -> 0.12984017 | I13: =I12/I6 -> 0.31908598 | J13: =J12/J6 -> 0.35003661 | K13: =K12/K6 -> 0.35003661 | L13: =L12/L6 -> 0.35003661 | M13: =M12/M6 -> 0.35003661 | Q13: 주주가치(Equity Value) | T13: =T11+T10-T12 -> 3148705.8
A14: %YoY Growth | F14: =F12/E12-1 -> -0.94520833 | G14: =G12/F12-1 -> 6.4082278 | H14: =H12/G12-1 -> -0.026272508 | I14: =I12/H12-1 -> 10.086975 | J14: =J12/I12-1 -> 0.20669758 | K14: =K12/J12-1 -> 0.05 | L14: =L12/K12-1 -> 0.05 | M14: =M12/L12-1 -> 0.05 | Q14: 발행주식수 | T14: =F42 -> 38366816
A15: 세율 | E15: 0.19 | F15: 0.19 | G15: 0.19 | H15: ='비용 추정'!R83 -> 0.18869083 | I15: ='비용 추정'!$S$83 -> 0.19991557 | J15: ='비용 추정'!$S$83 -> 0.19991557 | K15: ='비용 추정'!$S$83 -> 0.19991557 | L15: ='비용 추정'!$S$83 -> 0.19991557 | M15: ='비용 추정'!$S$83 -> 0.19991557 | Q15: 적정주가: | T15: =F44 -> 82068.468
A16: 세후영업이익(NOPLAT) | E16: =E12*(1-E15) -> 46715.13 | F16: =F12*(1-F15) -> 2559.6 | G16: =G12*(1-G15) -> 18962.1 | H16: =H12*(1-H15) -> 18493.76 | I16: =I12*(1-I15) -> 202203.06 | J16: =J12*(1-J15) -> 243997.95 | K16: =K12*(1-K15) -> 256197.84 | L16: =L12*(1-L15) -> 269007.73 | M16: =M12*(1-M15) -> 282458.12 | Q16: 현재주가: | T16: 47500
A17: (+) 상각비 | E17: ='FA Schedule'!D37 -> 11152 | F17: ='FA Schedule'!E37 -> 10136 | G17: ='FA Schedule'!F37 -> 11856 | H17: ='FA Schedule'!G37 -> 15390.286 | I17: ='FA Schedule'!H37 -> 10927.578 | J17: ='FA Schedule'!I37 -> 10758.453 | K17: ='FA Schedule'!J37 -> 10534.246 | L17: ='FA Schedule'!K37 -> 8925.9794 | M17: ='FA Schedule'!L37 -> 8419.7898 | Q17: 상승(하락)여력: | T17: =T15/T16-1 -> 0.72775722
A18: 매출 대비 비중 | E18: =E17/E6 -> 0.041691122 | F18: =F17/F6 -> 0.075865992 | G18: =G17/G6 -> 0.063911335 | H18: =H17/H6 -> 0.087663118 | I18: =I17/I6 -> 0.013796843 | J18: =J17/J6 -> 0.012348465 | K18: =K17/K6 -> 0.011515354 | L18: =L17/L6 -> 0.0092926676 | M18: =M17/M6 -> 0.0083482698 | Q18: 투자의견 | T18: BUY
A20: (-) 순운전자본(NWC) 변동 (기말-기초) | F20: =F22-F21 -> -19842 | G20: =G22-G21 -> 1184 | H20: =H22-H21 -> 18691.054 | I20: =I22-I21 -> 133976.01 | J20: =J22-J21 -> 9768.0305 | K20: =K22-K21 -> 27441.32 | L20: =L22-L21 -> 2323.242 | M20: =M22-M21 -> 10321.127
A21: 기초 순운전자본 | F21: ='Change in NWC'!D15 -> 125560 | G21: ='Change in NWC'!E15 -> 105718 | H21: ='Change in NWC'!F15 -> 106902 | I21: ='Change in NWC'!G15 -> 125593.05 | J21: ='Change in NWC'!H15 -> 259569.06 | K21: ='Change in NWC'!I15 -> 269337.09 | L21: ='Change in NWC'!J15 -> 296778.41 | M21: ='Change in NWC'!K15 -> 299101.66
A22: 기말 순운전자본 | E22: ='Change in NWC'!D15 -> 125560 | F22: ='Change in NWC'!E15 -> 105718 | G22: ='Change in NWC'!F15 -> 106902 | H22: ='Change in NWC'!G15 -> 125593.05 | I22: ='Change in NWC'!H15 -> 259569.06 | J22: ='Change in NWC'!I15 -> 269337.09 | K22: ='Change in NWC'!J15 -> 296778.41 | L22: ='Change in NWC'!K15 -> 299101.66 | M22: ='Change in NWC'!L15 -> 309422.78
A23: 순운전자본 증감 매출 대비 비중 | F23: =F20/F6 -> -0.14851352 | G23: =G20/G6 -> 0.0063825085 | H23: =H20/H6 -> 0.10646431 | I23: =I20/I6 -> 0.16915422
A25: (-) Capex | E25: ='FA Schedule'!D35 -> 14158 | F25: ='FA Schedule'!E35 -> 53157 | G25: ='FA Schedule'!F35 -> 54010 | H25: ='FA Schedule'!G35 -> 35029.056 | I25: ='FA Schedule'!H35 -> 15390.286 | J25: ='FA Schedule'!I35 -> 10927.578 | K25: ='FA Schedule'!J35 -> 10758.453 | L25: ='FA Schedule'!K35 -> 10534.246 | M25: ='FA Schedule'!L35 -> 8925.9794
A26: 매출 대비 비중 | F26: =F25/F6 -> 0.39786982 | G26: =G25/G6 -> 0.29114804 | H26: =H25/H6 -> 0.19952562 | I26: =I25/I6 -> 0.019431328 | J26: =J25/J6 -> 0.012542584 | K26: =K25/K6 -> 0.011760443 | L26: =L25/L6 -> 0.010967003 | M26: =M25/M6 -> 0.0088501596
A28: 잉여현금흐름(FCF) | F28: =F16+F17-F20-F25 -> -20619.4 | G28: =G16+G17-G20-G25 -> -24375.9 | H28: =H16+H17-H20-H25 -> -19836.064 | I28: =I16+I17-I20-I25 -> 63764.344 | J28: =J16+J17-J20-J25 -> 234060.79 | K28: =K16+K17-K20-K25 -> 228532.32 | L28: =L16+L17-L20-L25 -> 265076.23 | M28: =M16+M17-M20-M25 -> 271630.8
A30: 잔존가치(Terminal Value) | F30: =N31 -> 4088313.1
A31: 영구성장률(g) | F31: 0.03 | N31: =(M28*(1+F31))/(F32-F31) -> 4088313.1
A32: WACC(Wacc sheet 참고) | F32: =WACC!E16 -> 0.098434027
A33: 현재가치 계수 | I33: =1/(1+$F$32)^I34 -> 0.91038695 | J33: =1/(1+$F$32)^J34 -> 0.82880439 | K33: =1/(1+$F$32)^K34 -> 0.7545327 | L33: =1/(1+$F$32)^L34 -> 0.68691672 | M33: =1/(1+$F$32)^M34 -> 0.62536002
A34: 연도 | I34: 1 | J34: 2 | K34: 3 | L34: 4 | M34: 5
A35: 추정연도(2026~2030) FCF의 현재가치 | I35: =I28*I33 -> 58050.227 | J35: =J28*J33 -> 193990.61 | K35: =K28*K33 -> 172435.1 | L35: =L28*L33 -> 182085.29 | M35: =M28*M33 -> 169867.04
A36: 추정연도 FCF의 현재가치의 합 | F36: =SUM(H35:M35) -> 776428.28
A37: 잔존가치(Terminal Value)의 현재가치 | F37: =F30*M33 -> 2556667.5
A38: 기업가치(EV) | F38: =F36+F37 -> 3333095.8
A39: (+) 비영업용 자산 가치 | F39: 103519
A40: (-) 타인자본가치 (순차입금) | F40: 287909
A41: 보통주 자기자본의 가치(주주가치) | F41: =F38+F39-F40 -> 3148705.8
A42: (÷) 발행주식수 | F42: =WACC!E29 -> 38366816
A44: 목표 가격(Target Price,원) | F44: =F41*1000000/F42 -> 82068.468
A45: 시가총액(백만원) | F45: =F41 -> 3148705.8

Sheet WACC
A1: 테크윙(089030.KQ)
A2: Weighted Average Cost of Capital
A3: (units in Millions KRW )
B5: WACC Calculation Table | G5: Description | K5: 이자부 부채 | L5: 24년말 | M5: 3Q25 | N5: 평균이자부부채 | O5: 3Q25 누적 이자비용 | P5: 이자율
B6: Wd(Debt/Capital) | E6: =E30 -> 0.14339891 | G6: 시가 총액 대비 차입금 비율 | K6: 단기차입금 | L6: 69135 | M6: 85500
B7: We(Equity/Capital) | E7: =1-E6 -> 0.85660109 | K7: 유동성장기차입금 | L7: 95718 | M7: 42181
B8: Rd(타인자본비용) | E8: =P10 -> 0.034899784 | K8: 장기차입금 | L8: 87726 | M8: 177236
B9: (1-t) | E9: 0.81 | G9: IS sheet 참고 | K9: 기타부채 | L9: 203 | M9: 165
B10: Rd*(1-t)*Wd | E10: =E8*E9*E6 -> 0.0040537187 | K10: 합계 | L10: =SUM(L6:L9) -> 252782 | M10: =SUM(M6:M9) -> 305082 | N10: =AVERAGE(L10:M10) -> 278932 | O10: 7301 | P10: =O10/N10*12/9 -> 0.034899784
B11: 무위험수익률(Rf) | E11: 0.0308 | G11: 국고채 5년 수익률(2025.11.19)
B12: 시장위험프리미엄(MRP, Rm-Rf) | E12: 0.07 | G12: 한공회 리스크프리미엄(25.06.10)
B13: β(조정베타) | E13: =1.201*2/3+1*1/3 -> 1.134 | G13: 5년베타 1.201
B14: Re(자기자본비용) | E14: =E11+E13*(E12) -> 0.11018 | G14: Re=Rf+β(Rm-Rf)
B15: Re*We | E15: =E14*E7 -> 0.094380308
B16: WACC | E16: =E15+E10 -> 0.098434027
B19: Wd(Debt/Capital)
B20: FY25 차입금 시가/자본 시가
B21: 차입금 | E21: 금액(백만원)
B22: 단기차입금 | E22: 85500
B23: 유동성장기차입금 | E23: 42181
B24: 장기차입금 | E24: 177236
B25: 기타부채 | E25: 165
B26: 합계 | E26: =SUM(E22:E25) -> 305082
B27: 시가총액(백만원) | E27: =E28*E29*0.000001 -> 1822423.8
B28: 주가(원) | E28: 47500
B29: 발행주식수 | E29: 38366816
B30: Wd | E30: =E26/(E26+E27) -> 0.14339891

Sheet Change in NWC
A1: 테크윙(089030.KQ)
A2: Change in NWC
A3: (units in Millions KRW )
A5: Historical | G5: Pro Forma | N5: Description
D6: 2022A | E6: 2023A | F6: 2024A | G6: 2025E | H6: 2026E | I6: 2027E | J6: 2028E | K6: 2029E | L6: 2030E
A7: 매출채권 | D7: 53299 | E7: 39462 | F7: 43796 | G7: =G25/$B$24*G19 -> 56793.526 | H7: =H25/$B$24*H19 -> 236304.01 | I7: =I25/$B$24*I19 -> 245762.72 | J7: =J25/$B$24*J19 -> 275638.75 | K7: =K25/$B$24*K19 -> 282317.26 | L7: =L25/$B$24*L19 -> 294941.97 | N7: 매출채권회전일로 추정
A8: 재고자산 | D8: 86833 | E8: 81331 | F8: 79266 | G8: =AVERAGE(D8:F8) -> 82476.667 | H8: =AVERAGE(E8:G8) -> 81024.556 | I8: =AVERAGE(F8:H8) -> 80922.407 | J8: =AVERAGE(G8:I8) -> 81474.543 | K8: =AVERAGE(H8:J8) -> 81140.502 | L8: =AVERAGE(I8:K8) -> 81179.151 | N8: 동사는 주문제작 방식을 이용하기에 재고자산 잔액 변동이 크게 없을것이라 판단. 직전 3개년 average flat
A9: 기타 유동자산 | D9: 2185 | E9: 1940 | F9: 1536 | G9: =AVERAGE(D9:F9) -> 1887 | H9: =AVERAGE(E9:G9) -> 1787.6667 | I9: =AVERAGE(F9:H9) -> 1736.8889 | J9: =AVERAGE(G9:I9) -> 1803.8519 | K9: =AVERAGE(H9:J9) -> 1776.1358 | L9: =AVERAGE(I9:K9) -> 1772.2922 | N9: 직전 3개년 이동평균 적용.
A10: 영업용 유동자산 | D10: =SUM(D7:D9) -> 142317 | E10: =SUM(E7:E9) -> 122733 | F10: =SUM(F7:F9) -> 124598 | G10: =SUM(G7:G9) -> 141157.19 | H10: =SUM(H7:H9) -> 319116.23 | I10: =SUM(I7:I9) -> 328422.02 | J10: =SUM(J7:J9) -> 358917.14 | K10: =SUM(K7:K9) -> 365233.9 | L10: =SUM(L7:L9) -> 377893.42
A12: 매입채무 | D12: 12617 | E12: 14156 | F12: 14953 | G12: =G30/$B$29*G20 -> 12316.805 | H12: =H30/$B$29*H20 -> 56597.392 | I12: =I30/$B$29*I20 -> 56104.888 | J12: =J30/$B$29*J20 -> 59079.68 | K12: =K30/$B$29*K20 -> 63135.953 | L12: =L30/$B$29*L20 -> 65458.84 | N12: 매입채무회전일로 추정
A13: 기타 유동부채 | D13: 4140 | E13: 2859 | F13: 2743 | G13: =AVERAGE(D13:F13) -> 3247.3333 | H13: =AVERAGE(E13:G13) -> 2949.7778 | I13: =AVERAGE(F13:H13) -> 2980.037 | J13: =AVERAGE(G13:I13) -> 3059.0494 | K13: =AVERAGE(H13:J13) -> 2996.2881 | L13: =AVERAGE(I13:K13) -> 3011.7915 | N13: 직전 3개년 이동평균 적용.
A14: 영업용 유동부채 | D14: =SUM(D12:D13) -> 16757 | E14: =SUM(E12:E13) -> 17015 | F14: =SUM(F12:F13) -> 17696 | G14: =SUM(G12:G13) -> 15564.138 | H14: =SUM(H12:H13) -> 59547.169 | I14: =SUM(I12:I13) -> 59084.925 | J14: =SUM(J12:J13) -> 62138.73 | K14: =SUM(K12:K13) -> 66132.241 | L14: =SUM(L12:L13) -> 68470.631
A15: 순운전자본 | D15: =D10-D14 -> 125560 | E15: =E10-E14 -> 105718 | F15: =F10-F14 -> 106902 | G15: =G10-G14 -> 125593.05 | H15: =H10-H14 -> 259569.06 | I15: =I10-I14 -> 269337.09 | J15: =J10-J14 -> 296778.41 | K15: =K10-K14 -> 299101.66 | L15: =L10-L14 -> 309422.78
A17: 순운전자본의 증감 | E17: =E15-D15 -> -19842 | F17: =F15-E15 -> 1184 | G17: =G15-F15 -> 18691.054 | H17: =H15-G15 -> 133976.01 | I17: =I15-H15 -> 9768.0305 | J17: =J15-I15 -> 27441.32 | K17: =K15-J15 -> 2323.242 | L17: =L15-K15 -> 10321.127
A18: IS Data
A19: 매출액 | D19: ='DCF>>>'!E6 -> 267491 | E19: ='DCF>>>'!F6 -> 133604 | F19: ='DCF>>>'!G6 -> 185507 | G19: ='DCF>>>'!H6 -> 175561.7 | H19: ='DCF>>>'!I6 -> 792034.67 | I19: ='DCF>>>'!J6 -> 871238.14 | J19: ='DCF>>>'!K6 -> 914800.04 | K19: ='DCF>>>'!L6 -> 960540.04 | L19: ='DCF>>>'!M6 -> 1008567
A20: 매출원가 | D20: ='DCF>>>'!E8 -> 158044 | E20: ='DCF>>>'!F8 -> 84056 | F20: ='DCF>>>'!G8 -> 114022 | G20: ='DCF>>>'!H8 -> 100754.93 | H20: ='DCF>>>'!I8 -> 414989.09 | I20: ='DCF>>>'!J8 -> 435738.55 | J20: ='DCF>>>'!K8 -> 457525.48 | K20: ='DCF>>>'!L8 -> 480401.75 | L20: ='DCF>>>'!M8 -> 504421.84
A22: Assumptions
A23: 순운전자본(Net Working Capital) 항목
A24: 영업일: | B24: 365
A25: 매출채권회전일수(DSO) | D25: =(AVERAGE(D7)/E19*$B$24) -> 145.61042 | E25: =(AVERAGE(D7:E7)/E19*$B$24) -> 126.7094 | F25: =(AVERAGE(E7:F7)/F19*$B$24) -> 81.908419 | G25: =AVERAGE(D25:F25) -> 118.07608 | H25: =AVERAGE(E25:G25) -> 108.89797 | I25: =AVERAGE(F25:H25) -> 102.96082 | J25: =AVERAGE(G25:I25) -> 109.97829 | K25: =AVERAGE(H25:J25) -> 107.27903 | L25: =AVERAGE(I25:K25) -> 106.73938 | N25: 직전 3개년 이동평균
A28: 순운전자본(Net Working Capital) 항목
A29: 영업일: | B29: 365
A30: 매입채무회전일수(DPO) | D30: =AVERAGE(D12)/D20*$B$29 -> 29.138752 | E30: =AVERAGE(D12:E12)/E20*$B$29 -> 58.128777 | F30: =AVERAGE(E12:F12)/F20*$B$29 -> 46.590943 | G30: =AVERAGE(D30:F30) -> 44.619491 | H30: =AVERAGE(E30:G30) -> 49.779737 | I30: =AVERAGE(F30:H30) -> 46.996724 | J30: =AVERAGE(G30:I30) -> 47.131984 | K30: =AVERAGE(H30:J30) -> 47.969482 | L30: =AVERAGE(I30:K30) -> 47.366063 | N30: 직전 3개년 이동평균
A32: Ratio
A33: 매출채권/매출 | D33: =D7/D19 -> 0.1992553 | E33: =E7/E19 -> 0.29536541 | F33: =F7/F19 -> 0.23608813 | G33: =G7/G19 -> 0.32349611 | H33: =H7/H19 -> 0.29835059 | I33: =I7/I19 -> 0.28208444 | J33: =J7/J19 -> 0.30131038 | K33: =K7/K19 -> 0.29391514 | L33: =L7/L19 -> 0.29243665
A34: 매출채권/매출원가 | D34: =D7/D20 -> 0.33724153 | E34: =E7/E20 -> 0.46947273 | F34: =F7/F20 -> 0.38410131 | G34: =G7/G20 -> 0.56367985 | H34: =H7/H20 -> 0.56942222 | I34: =I7/I20 -> 0.56401419 | J34: =J7/J20 -> 0.60245552 | K34: =K7/K20 -> 0.58766909 | L34: =L7/L20 -> 0.58471293
A35: 순운전자본/매출 | D35: =D15/D19 -> 0.46939897 | E35: =E15/E19 -> 0.7912787 | F35: =F15/F19 -> 0.57626936 | G35: =G15/G19 -> 0.71537845 | H35: =H15/H19 -> 0.32772437 | I35: =I15/I19 -> 0.30914291 | J35: =J15/J19 -> 0.32441889 | K35: =K15/K19 -> 0.31138906 | L35: =L15/L19 -> 0.30679446
A36: 영업용유동자산/영업용유동부채 | D36: =D10/D14 -> 8.492988 | E36: =E10/E14 -> 7.2132236 | F36: =F10/F14 -> 7.0410262 | G36: =G10/G14 -> 9.0693869 | H36: =H10/H14 -> 5.3590496 | I36: =I10/I14 -> 5.558474 | J36: =J10/J14 -> 5.7760618 | K36: =K10/K14 -> 5.5227812 | L36: =L10/L14 -> 5.5190584
A37: 순운전자본/총자산 | D37: =D15/D42 -> 0.25716229 | E37: =E15/E42 -> 0.21757734 | F37: =F15/F42 -> 0.21117654 | G37: =G15/G42 -> 0.22467452 | H37: =H15/H42 -> 0.30182449 | I37: =I15/I42 -> 0.28471152 | J37: =J15/J42 -> 0.29878024 | K37: =K15/K42 -> 0.28678015 | L37: =L15/L42 -> 0.28254866
A40: 총자산 추정
A41: 총자산 회전율 | D41: =D43/D42 -> 0.54785439 | E41: =E43/E42 -> 0.27496928 | F41: =F43/F42 -> 0.36645457 | G41: =G43/G42 -> 0.31406386 | H41: =H43/H42 -> 0.92097054 | I41: =I43/I42 -> 0.92097054 | J41: =J43/J42 -> 0.92097054 | K41: =K43/K42 -> 0.92097054 | L41: =L43/L42 -> 0.92097054
A42: 총자산 | D42: 488252 | E42: 485887 | F42: 506221 | G42: 559000 | H42: 860000 | I42: =H42*1.1 -> 946000 | J42: =I42*1.05 -> 993300 | K42: =J42*1.05 -> 1042965 | L42: =K42*1.05 -> 1095113.3
A43: 매출액 | D43: =D19 -> 267491 | E43: =E19 -> 133604 | F43: =F19 -> 185507 | G43: =G19 -> 175561.7 | H43: =H19 -> 792034.67 | I43: =I19 -> 871238.14 | J43: =J19 -> 914800.04 | K43: =K19 -> 960540.04 | L43: =L19 -> 1008567

Sheet FA Schedule
A1: 테크윙(089030.KQ)
A2: FA Schedule
A3: (units in Millions KRW )
A5: Historical | G5: Pro Forma | N5: Description
D6: 2022A | E6: 2023A | F6: 2024A | G6: 2025E | H6: 2026E | I6: 2027E | J6: 2028E | K6: 2029E | L6: 2030E
A7: 유형자산 | D7: 242657 | E7: 270619 | F7: 232023 | G7: =G17 -> 233189.32 | H7: =H17 -> 219219.96 | I7: =I17 -> 203297.02 | J7: =J17 -> 188060.41 | K7: =K17 -> 175418 | L7: =L17 -> 162836.49
A8: 무형자산 | D8: 18200 | E8: 20950 | F8: 11736 | G8: 44101 | H8: 45830 | I8: =I28 -> 5834.2273 | J8: =J28 -> 4555.3381 | K8: =K28 -> 3509.4401 | L8: =L28 -> 2696.7893
A9: 기타 | D9: =D10-SUM(D7:D8) -> 46117 | E9: =E10-SUM(E7:E8) -> 50524 | F9: =F10-SUM(F7:F8) -> 106386 | G9: =AVERAGE(D9:F9) -> 67675.667 | H9: =AVERAGE(E9:G9) -> 74861.889 | I9: =AVERAGE(F9:H9) -> 82974.519 | J9: =AVERAGE(G9:I9) -> 75170.691 | K9: =AVERAGE(H9:J9) -> 77669.033 | L9: =AVERAGE(I9:K9) -> 78604.748 | N9: 직전 3개년 이동 평균 적용.
A10: 비유동자산 | D10: 306974 | E10: 342093 | F10: 350145 | G10: 53132 | H10: 61629 | I10: =SUM(I7:I9) -> 292105.77 | J10: =SUM(J7:J9) -> 267786.44 | K10: =SUM(K7:K9) -> 256596.47 | L10: =SUM(L7:L9) -> 244138.03
A12: 유형자산 Schedule
A13: 기초 유형자산 | D13: 241596 | E13: =D17 -> 242657 | F13: =E17 -> 270619 | G13: =F17 -> 232023 | H13: =G17 -> 233189.32 | I13: =H17 -> 219219.96 | J13: =I17 -> 203297.02 | K13: =J17 -> 188060.41 | L13: =K17 -> 175418
A14: Capex | D14: 9594 | E14: 44070 | F14: 52218 | G14: =G13*G19 -> 32041.056 | H14: =G15 -> 13488 | I14: =H15 -> 9349.3683 | J14: =I15 -> 9572.2362 | K14: =J15 -> 9615.3135 | L14: =K15 -> 8215.4396
A15: 감가상각비 | D15: 7601 | E15: 7129 | F15: 8868 | G15: =10116*4/3 -> 13488 | H15: =H13*H20 -> 9349.3683 | I15: =I13*I20 -> 9572.2362 | J15: =J13*J20 -> 9615.3135 | K15: =K13*K20 -> 8215.4396 | L15: =L13*L20 -> 7873.1671 | N15: 4Q25의 경우 앞선 3개분기의 감가상각비 지출액이 큰 변화가 없기에 이를 고려하여 반영함.
A16: 기타증감 | D16: =D17-SUM(D13:D15) -> -16134 | E16: =E17-SUM(E13:E15) -> -23237 | F16: =F17-SUM(F13:F15) -> -99682 | G16: =G13*G21 -> -17386.74 | H16: =H13*H21 -> -18107.987 | I16: =I13*I21 -> -15700.071 | J16: =J13*J21 -> -15193.531 | K16: =K13*K21 -> -14042.29 | L16: =L13*L21 -> -12923.778 | N16: 24년의 경우 일부 유형자산이 투자부동산으로 계정 대체 되었음. 이를 이상치로 판단하여 81,879로 제외한 금액 비율 산정 후 이동평균
A17: 기말 유형자산 | D17: =D7 -> 242657 | E17: =E7 -> 270619 | F17: =F7 -> 232023 | G17: =G13+G14-G15+G16 -> 233189.32 | H17: =H13+H14-H15+H16 -> 219219.96 | I17: =I13+I14-I15+I16 -> 203297.02 | J17: =J13+J14-J15+J16 -> 188060.41 | K17: =K13+K14-K15+K16 -> 175418 | L17: =L13+L14-L15+L16 -> 162836.49
A19: 기초 유형자산 대비 Capex | D19: =D14/D13 -> 0.039710922 | E19: =E14/E13 -> 0.18161438 | F19: =F14/F13 -> 0.19295763 | G19: =AVERAGE(D19:F19) -> 0.13809431 | H19: =H14/H13 -> 0.057841415 | I19: =I14/I13 -> 0.042648344 | J19: =J14/J13 -> 0.04708498 | K19: =K14/K13 -> 0.051128854 | L19: =L14/L13 -> 0.046833504 | N19: 23,'24,'25년 CAPA증설에 따라 CAPEX지출 높음. 이후 CAPA증설 일정 없기에 전기 감가상각비 만큼 지출된다 가정
A20: 기초 유형자산 대비 감가상각비 | D20: =D15/D13 -> 0.031461614 | E20: =E15/E13 -> 0.029378918 | F20: =F15/F13 -> 0.032769318 | G20: =G15/G13 -> 0.058132168 | H20: =AVERAGE(E20:G20) -> 0.040093468 | I20: =AVERAGE(F20:H20) -> 0.043664984 | J20: =AVERAGE(G20:I20) -> 0.047296873 | K20: =AVERAGE(H20:J20) -> 0.043685109 | L20: =AVERAGE(I20:K20) -> 0.044882322 | N20: 직전 3개년 Average flat 적용.
A21: 기초 유형자산 대비 기타증감 | D21: =D16/D13 -> -0.066780907 | E21: =E16/E13 -> -0.095760683 | F21: =-(98729-81879)/F13 -> -0.06226466 | G21: =AVERAGE(D21:F21) -> -0.074935417 | H21: =AVERAGE(E21:G21) -> -0.077653586 | I21: =AVERAGE(F21:H21) -> -0.071617888 | J21: =AVERAGE(G21:I21) -> -0.07473563 | K21: =AVERAGE(H21:J21) -> -0.074669035 | L21: =AVERAGE(I21:K21) -> -0.073674184 | N21: 직전 3개년 Average flat 적용.
A23: 무형자산 Schedule
A24: 기초 무형자산 | D24: 19902 | E24: =D28 -> 18200 | F24: =E28 -> 20950 | G24: =F28 -> 11736 | H24: =G28 -> 10075.075 | I24: =H28 -> 7713.3937 | J24: =I28 -> 5834.2273 | K24: =J28 -> 4555.3381 | L24: =K28 -> 3509.4401
A25: Capex | D25: =4564 -> 4564 | E25: 9087 | F25: 1792 | G25: =F26 -> 2988 | H25: =G26 -> 1902.2857 | I25: =H26 -> 1578.2096 | J25: =I26 -> 1186.2172 | K25: =J26 -> 918.93245 | L25: =K26 -> 710.53977
A26: 상각비 | D26: 3551 | E26: 3007 | F26: 2988 | G26: =G24*G31 -> 1902.2857 | H26: =H24*H31 -> 1578.2096 | I26: =I24*I31 -> 1186.2172 | J26: =J24*J31 -> 918.93245 | K26: =K24*K31 -> 710.53977 | L26: =L24*L31 -> 546.62268
A27: 기타증감 | D27: =D28-SUM(D24:D26) -> -9817 | E27: =E28-SUM(E24:E26) -> -9344 | F27: =F28-SUM(F24:F26) -> -13994 | G27: =G24*G32 -> -6551.2111 | H27: =H24*H32 -> -5842.1762 | I27: =I24*I32 -> -4643.5933 | J27: =J24*J32 -> -3384.0389 | K27: =K24*K32 -> -2675.3702 | L27: =L24*L32 -> -2069.8132
A28: 기말 무형자산 | D28: =D8 -> 18200 | E28: =E8 -> 20950 | F28: =F8 -> 11736 | G28: =SUM(G24:G27) -> 10075.075 | H28: =SUM(H24:H27) -> 7713.3937 | I28: =SUM(I24:I27) -> 5834.2273 | J28: =SUM(J24:J27) -> 4555.3381 | K28: =SUM(K24:K27) -> 3509.4401 | L28: =SUM(L24:L27) -> 2696.7893
A30: 기초 무형자산 대비 Capex | D30: =D25/D24 -> 0.22932369 | E30: =E25/E24 -> 0.49928571 | F30: =F25/F24 -> 0.085536993 | G30: =G25/G24 -> 0.25460123 | H30: =H25/H24 -> 0.18881108 | I30: =I25/I24 -> 0.20460639 | J30: =J25/J24 -> 0.20332036 | K30: =K25/K24 -> 0.20172651 | L30: =L25/L24 -> 0.20246528 | N30: 전기 상각비만큼 CAPEX 지출한다 가정
A31: 기초 무형자산 대비 상각비 | D31: =D26/D24 -> 0.17842428 | E31: =E26/E24 -> 0.16521978 | F31: =F26/F24 -> 0.1426253 | G31: =AVERAGE(D31:F31) -> 0.16208979 | H31: =AVERAGE(E31:G31) -> 0.15664495 | I31: =AVERAGE(F31:H31) -> 0.15378668 | J31: =AVERAGE(G31:I31) -> 0.15750714 | K31: =AVERAGE(H31:J31) -> 0.15597959 | L31: =AVERAGE(I31:K31) -> 0.1557578 | N31: 직전 3개년 Average flat 적용.
A32: 기초 무형자산 대비 기타증감 | D32: =D27/D24 -> -0.49326701 | E32: =E27/E24 -> -0.51340659 | F32: =F27/F24 -> -0.66797136 | G32: =AVERAGE(D32:F32) -> -0.55821499 | H32: =AVERAGE(E32:G32) -> -0.57986431 | I32: =AVERAGE(F32:H32) -> -0.60201689 | J32: =AVERAGE(G32:I32) -> -0.58003206 | K32: =AVERAGE(H32:J32) -> -0.58730442 | L32: =AVERAGE(I32:K32) -> -0.58978446 | N32: 직전 3개년 Average flat 적용.
A34: Capex / D&A
A35: Total Capex | D35: =D14+D25 -> 14158 | E35: =E14+E25 -> 53157 | F35: =F14+F25 -> 54010 | G35: =G14+G25 -> 35029.056 | H35: =H14+H25 -> 15390.286 | I35: =I14+I25 -> 10927.578 | J35: =J14+J25 -> 10758.453 | K35: =K14+K25 -> 10534.246 | L35: =L14+L25 -> 8925.9794
A36: of revenue (%) | D36: 0.052928884 | E36: 0.39786982 | F36: 0.29114804 | G36: 0.20361848 | H36: 0.057304651 | I36: 0.055696285 | J36: 0.054755468 | K36: 0.058216414 | L36: 0.059972834
A37: Total D&A | D37: =D15+D26 -> 11152 | E37: =E15+E26 -> 10136 | F37: =F15+F26 -> 11856 | G37: =G15+G26 -> 15390.286 | H37: =H15+H26 -> 10927.578 | I37: =I15+I26 -> 10758.453 | J37: =J15+J26 -> 10534.246 | K37: =K15+K26 -> 8925.9794 | L37: =L15+L26 -> 8419.7898
A38: of revenue (%) | D38: ='FA Schedule'!D37/'DCF>>>'!E6 -> 0.041691122 | E38: ='FA Schedule'!E37/'DCF>>>'!F6 -> 0.075865992 | F38: ='FA Schedule'!F37/'DCF>>>'!G6 -> 0.063911335 | G38: ='FA Schedule'!G37/'DCF>>>'!H6 -> 0.087663118 | H38: ='FA Schedule'!H37/'DCF>>>'!I6 -> 0.013796843 | I38: ='FA Schedule'!I37/'DCF>>>'!J6 -> 0.012348465 | J38: ='FA Schedule'!J37/'DCF>>>'!K6 -> 0.011515354 | K38: ='FA Schedule'!K37/'DCF>>>'!L6 -> 0.0092926676 | L38: ='FA Schedule'!L37/'DCF>>>'!M6 -> 0.0083482698

Sheet 비용 추정
A1: 테크윙(089030.KQ)
A2: Assumption Sheet
A3: (units in Millions KRW )
B5: 비용추정 | P5: 비용추정
B6: (단위: 백만원) | C6: 1Q24 | D6: 2Q24 | E6: 3Q24 | F6: 4Q24 | G6: 1Q25 | H6: 2Q25 | I6: 3Q25 | J6: 4Q25 | K6: 1Q26 | L6: 2Q26 | M6: 3Q26 | N6: 4Q26 | P6: (단위: 원) | Q6: 2024A | R6: 2025E | S6: 2026E
B7: 매출액 | C7: ='IS(Quaterly)'!H10 -> 40339.439 | D7: ='IS(Quaterly)'!I10 -> 50769.762 | E7: ='IS(Quaterly)'!J10 -> 46721.567 | F7: ='IS(Quaterly)'!K10 -> 47676.403 | G7: ='IS(Quaterly)'!L10 -> 34587.215 | H7: ='IS(Quaterly)'!M10 -> 48893.653 | I7: 41766 | J7: ='매출 추정'!F6 -> 50314.986 | K7: ='매출 추정'!G6 -> 143990.83 | L7: ='매출 추정'!H6 -> 219447.31 | M7: ='매출 추정'!I6 -> 212606.61 | N7: ='매출 추정'!J6 -> 215989.92 | P7: 매출액 | Q7: =SUM(C7:F7) -> 185507.17 | R7: =SUM(G7:J7) -> 175561.85 | S7: =SUM(K7:N7) -> 792034.67
B8: % YoY | G8: =G7/C7-1 -> -0.14259553 | H8: =H7/D7-1 -> -0.036953291 | I8: =I7/E7-1 -> -0.10606594 | J8: =J7/F7-1 -> 0.055343587 | K8: =K7/G7-1 -> 3.1631231 | L8: =L7/H7-1 -> 3.4882577 | M8: =M7/I7-1 -> 4.090423 | N8: =N7/J7-1 -> 3.2927552 | P8: % YoY | R8: =R7/Q7-1 -> -0.053611497 | S8: =S7/R7-1 -> 3.511428
B9: 큐브 프로버 | C9: 0 | D9: 0 | E9: 0 | F9: 0 | G9: ='매출 추정'!C8 -> 3000 | H9: ='매출 추정'!D8 -> 10000 | I9: ='매출 추정'!E8 -> 5000 | J9: ='매출 추정'!F8 -> 8000 | K9: ='매출 추정'!G8 -> 103950 | L9: ='매출 추정'!H8 -> 173250 | M9: ='매출 추정'!I8 -> 173250 | N9: ='매출 추정'!J8 -> 173250 | P9: 큐브 프로버 | Q9: =SUM(C9:F9) -> 0 | R9: =SUM(G9:J9) -> 26000 | S9: =SUM(K9:N9) -> 623700
B10: % of sales | C10: =C9/C7 -> 0 | D10: =D9/D7 -> 0 | E10: =E9/E7 -> 0 | F10: =F9/F7 -> 0 | G10: =G9/G7 -> 0.086737253 | H10: =H9/H7 -> 0.20452553 | I10: =I9/I7 -> 0.1197146 | J10: =J9/J7 -> 0.15899835 | ... N10: =N9/N7 -> 0.80212078 | P10: % of sales | Q10: =Q9/Q7 -> 0 | R10: =R9/R7 -> 0.14809595 | S10: =S9/S7 -> 0.78746553
B11: 핸들러 | C11: 18327 | D11: 22323 | E11: 21025 | F11: 20491 | G11: ='매출 추정'!C10 -> 9922 | H11: ='매출 추정'!D10 -> 12868 | I11: ='매출 추정'!E10 -> 9038 | J11: ='매출 추정'!F10 -> 14276.143 | K11: ='매출 추정'!G10 -> 11210.702 | L11: ='매출 추정'!H10 -> 18433.584 | M11: ='매출 추정'!I10 -> 11415.143 | N11: ='매출 추정'!J10 -> 14561.476 | P11: 핸들러 | Q11: =SUM(C11:F11) -> 82166 | R11: =SUM(G11:J11) -> 46104.143 | S11: =SUM(K11:N11) -> 55620.905
B12: % of sales | C12: =C11/C7 -> 0.45431966 | D12: =D11/D7 -> 0.43969085 | E12: =E11/E7 -> 0.45000631 | F12: =F11/F7 -> 0.42979333 | G12: =G11/G7 -> 0.28686901 | H12: =H11/H7 -> 0.26318345 | I12: =I11/I7 -> 0.21639611 | J12: =J11/J7 -> 0.2837354 | ... N12: =N11/N7 -> 0.067417389 | P12: % of sales | Q12: =Q11/Q7 -> 0.44292627 | R12: =R11/R7 -> 0.26260911 | S12: =S11/S7 -> 0.070225341
B13: C.O.K | C13: 11390 | D13: 13212 | E13: 12148 | F13: 11435 | G13: ='매출 추정'!C12 -> 12512 | H13: ='매출 추정'!D12 -> 12688 | I13: ='매출 추정'!E12 -> 19189 | J13: ='매출 추정'!F12 -> 19500 | K13: ='매출 추정'!G12 -> 18691.684 | L13: ='매출 추정'!H12 -> 18691.684 | M13: ='매출 추정'!I12 -> 18691.684 | N13: ='매출 추정'!J12 -> 18691.684 | P13: C.O.K | Q13: =SUM(C13:F13) -> 48185 | R13: =SUM(G13:J13) -> 63889 | S13: =SUM(K13:N13) -> 74766.737
B14: % of sales | C14: =C13/C7 -> 0.28235395 | D14: =D13/D7 -> 0.26023364 | E14: =E13/E7 -> 0.2600084 | F14: =F13/F7 -> 0.23984611 | G14: =G13/G7 -> 0.36175217 | H14: =H13/H7 -> 0.25950199 | I14: =I13/I7 -> 0.45944069 | J14: =J13/J7 -> 0.38755849 | ... N14: =N13/N7 -> 0.086539615 | P14: % of sales | Q14: =Q13/Q7 -> 0.25974737 | R14: =R13/R7 -> 0.36391163 | S14: =S13/S7 -> 0.094398314
B15: 기타 | C15: 10622 | D15: 15235 | E15: 13549 | F15: 15751 | G15: ='매출 추정'!C14 -> 9153.2149 | H15: ='매출 추정'!D14 -> 13337.653 | I15: ='매출 추정'!E14 -> 8538.8437 | J15: ='매출 추정'!F14 -> 8538.8437 | K15: ='매출 추정'!G14 -> 10138.447 | L15: ='매출 추정'!H14 -> 9072.0447 | M15: ='매출 추정'!I14 -> 9249.7783 | N15: ='매출 추정'!J14 -> 9486.7566 | P15: 기타 | Q15: =SUM(C15:F15) -> 55157 | R15: =SUM(G15:J15) -> 39568.555 | S15: =SUM(K15:N15) -> 37947.026
B16: % of sales | C16: =C15/C7 -> 0.26331551 | D16: =D15/D7 -> 0.30008019 | E16: =E15/E7 -> 0.28999455 | F16: =F15/F7 -> 0.33037308 | G16: =G15/G7 -> 0.26464157 | H16: =H15/H7 -> 0.27278904 | I16: =I15/I7 -> 0.20444485 | J16: =J15/J7 -> 0.16970776 | ... N16: =N15/N7 -> 0.04392222 | P16: % of sales | Q16: =Q15/Q7 -> 0.29733082 | R16: =R15/R7 -> 0.22538242 | S16: =S15/S7 -> 0.047910815
B17: 매출원가 | C17: ='IS(Quaterly)'!H13 -> 24298.609 | D17: ='IS(Quaterly)'!I13 -> 30584.084 | E17: ='IS(Quaterly)'!J13 -> 27986.516 | F17: ='IS(Quaterly)'!K13 -> 31152.326 | G17: ='IS(Quaterly)'!L13 -> 19942.025 | H17: ='IS(Quaterly)'!M13 -> 30065.138 | I17: ='IS(Quaterly)'!N13 -> 22406.702 | J17: =SUM(J19,J21,J23,J25) -> 28341.068 | K17: =SUM(K19,K21,K23,K25) -> 75986.5 | L17: =SUM(L19,L21,L23,L25) -> 115125.19 | M17: =SUM(M19,M21,M23,M25) -> 110887.51 | N17: =SUM(N19,N21,N23,N25) -> 112989.9 | P17: 매출원가 | Q17: =SUM(C17:F17) -> 114021.53 | R17: =SUM(G17:J17) -> 100754.93 | S17: =SUM(K17:N17) -> 414989.09
B18: % of sales | C18: =C17/C7 -> 0.60235367 | D18: =D17/D7 -> 0.60240747 | E18: =E17/E7 -> 0.59900636 | F18: =F17/F7 -> 0.65341183 | G18: =G17/G7 -> 0.57657217 | H18: =H17/H7 -> 0.61490881 | I18: =I17/I7 -> 0.53648188 | J18: =J17/J7 -> 0.5632729 | ... N18: =N17/N7 -> 0.5231258 | P18: % of sales | Q18: =Q17/Q7 -> 0.61464758 | R18: =R17/R7 -> 0.57389992 | S18: =S17/S7 -> 0.52395319
B19: 큐브 프로버 | C19: 0 | D19: 0 | E19: 0 | F19: 0 | G19: =G9*0.51 -> 1530 | H19: =H9*0.51 -> 5100 | I19: =I9*0.51 -> 2550 | J19: =J9*0.51 -> 4080 | K19: =K9*0.51 -> 53014.5 | L19: =L9*0.51 -> 88357.5 | M19: =M9*0.51 -> 88357.5 | N19: =N9*0.51 -> 88357.5 | P19: 큐브 프로버 | Q19: =SUM(C19:F19) -> 0 | R19: =SUM(G19:J19) -> 13260 | S19: =SUM(K19:N19) -> 318087 | V19: IR 자료를 토대로 매출원가를 역산하였음.
B20: % of cogs | C20: =C19/C17 -> 0 | D20: =D19/D17 -> 0 | E20: =E19/E17 -> 0 | F20: =F19/F17 -> 0 | G20: =G19/G17 -> 0.076722397 | H20: =H19/H17 -> 0.16963169 | I20: =I19/I17 -> 0.11380523 | J20: =J19/J17 -> 0.1439607 | ... N20: =N19/N17 -> 0.78199468 | P20: % of cogs | Q20: =Q19/Q17 -> 0 | R20: =R19/R17 -> 0.13160646 | S20: =S19/S17 -> 0.76649484
B21: 핸들러 | C21: =C11*0.62 -> 11362.74 | D21: =D11*0.62 -> 13840.26 | E21: =E11*0.62 -> 13035.5 | F21: =F11*0.62 -> 12704.42 | G21: =G11*0.62 -> 6151.64 | H21: =H11*0.62 -> 7978.16 | I21: =I11*0.62 -> 5603.56 | J21: =J11*0.62 -> 8851.2085 | ... N21: =N11*0.62 -> 9028.1153 | P21: 핸들러 | Q21: =SUM(C21:F21) -> 50942.92 | R21: =SUM(G21:J21) -> 28584.568 | S21: =SUM(K21:N21) -> 34484.961 | V21: IR 자료를 토대로 매출원가를 역산하였음.
B22: % of cogs | C22: =C21/C17 -> 0.46762924 | D22: =D21/D17 -> 0.45253145 | E22: =E21/E17 -> 0.46577788 | F22: =F21/F17 -> 0.4078161 | G22: =G21/G17 -> 0.30847619 | H22: =H21/H17 -> 0.2653625 | I22: =I21/I17 -> 0.2500841 | J22: =J21/J17 -> 0.31231033 | ... N22: =N21/N17 -> 0.079901968 | P22: % of cogs | Q22: =Q21/Q17 -> 0.44678332 | R22: =R21/R17 -> 0.28370391 | S22: =S21/S17 -> 0.083098476
B23: C.O.K | C23: =C13*0.51 -> 5808.9 | D23: =D13*0.51 -> 6738.12 | E23: =E13*0.51 -> 6195.48 | F23: =F13*0.51 -> 5831.85 | G23: =G13*0.51 -> 6381.12 | H23: =H13*0.51 -> 6470.88 | I23: =I13*0.51 -> 9786.39 | J23: =J13*0.51 -> 9945 | ... N23: =N13*0.51 -> 9532.759 | P23: C.O.K | Q23: =SUM(C23:F23) -> 24574.35 | R23: =SUM(G23:J23) -> 32583.39 | S23: =SUM(K23:N23) -> 38131.036 | V23: IR 자료를 토대로 매출원가를 역산하였음.
B24: % of cogs | C24: =C23/C17 -> 0.23906307 | D24: =D23/D17 -> 0.22031459 | E24: =E23/E17 -> 0.22137375 | F24: =F23/F17 -> 0.18720432 | G24: =G23/G17 -> 0.31998354 | H24: =H23/H17 -> 0.21522868 | I24: =I23/I17 -> 0.43676173 | J24: =J23/J17 -> 0.3509042 | ... N24: =N23/N17 -> 0.084368241 | P24: % of cogs | Q24: =Q23/Q17 -> 0.21552376 | R24: =R23/R17 -> 0.3233925 | S24: =S23/S17 -> 0.091884429
B25: 기타 | C25: =C15*0.64 -> 6798.08 | D25: =D15*0.64 -> 9750.4 | E25: =E15*0.64 -> 8671.36 | F25: =F15*0.64 -> 10080.64 | G25: =G15*0.64 -> 5858.0575 | H25: =H15*0.64 -> 8536.0977 | I25: =I15*0.64 -> 5464.86 | J25: =J15*0.64 -> 5464.86 | ... N25: =N15*0.64 -> 6071.5242 | P25: 기타 | Q25: =SUM(C25:F25) -> 35300.48 | R25: =SUM(G25:J25) -> 25323.875 | S25: =SUM(K25:N25) -> 24286.097 | V25: IR 자료를 토대로 매출원가를 역산하였음.
B26: % of cogs | C26: =C25/C17 -> 0.2797724 | D26: =D25/D17 -> 0.31880634 | E26: =E25/E17 -> 0.30984064 | F26: =F25/F17 -> 0.32359189 | G26: =G25/G17 -> 0.29375439 | H26: =H25/H17 -> 0.28392013 | I26: =I25/I17 -> 0.24389399 | J26: =J25/J17 -> 0.19282477 | ... N26: =N25/N17 -> 0.053735106 | P26: % of cogs | Q26: =Q25/Q17 -> 0.30959485 | R26: =R25/R17 -> 0.25134129 | S26: =S25/S17 -> 0.058522253
B27: 매출총이익 | C27: =C7-C17 -> 16040.83 | D27: =D7-D17 -> 20185.678 | E27: =E7-E17 -> 18735.051 | F27: =F7-F17 -> 16524.077 | G27: =G7-G17 -> 14645.189 | H27: =H7-H17 -> 18828.515 | I27: =I7-I17 -> 19359.298 | J27: =J7-J17 -> 21973.918 | ... N27: =N7-N17 -> 103000.02 | P27: 매출총이익 | Q27: =Q7-Q17 -> 71485.637 | R27: =R7-R17 -> 74806.92 | S27: =S7-S17 -> 377045.57 | AH27: 2022 | AI27: 2023 | AJ27: 2024
B28: GPM(%) | C28: =C27/C7 -> 0.39764633 | D28: =D27/D7 -> 0.39759253 | E28: =E27/E7 -> 0.40099364 | F28: =F27/F7 -> 0.34658817 | G28: =G27/G7 -> 0.42342783 | H28: =H27/H7 -> 0.38509119 | I28: =I27/I7 -> 0.46351812 | J28: =J27/J7 -> 0.4367271 | ... N28: =N27/N7 -> 0.4768742 | P28: GPM(%) | Q28: =Q27/Q7 -> 0.38535242 | R28: =R27/R7 -> 0.42610008 | S28: =S27/S7 -> 0.47604681 | U28: 25년 | V28: 26년 | AG28: 매출액 | AH28: 267491 | AI28: 133604 | AJ28: 185507
B29: 판매비와 관리비 | C29: =SUM(C31,C33,C35,C37,C39,C41,C43,C45,C47,C49,C51,C53,C55,C57) -> 10467 | D29: =SUM(D31,D33,D35,D37,D39,D41,D43,D45,D47,D49,D51,D53,D55,D57) -> 13010.248 | E29: =SUM(E31,E33,E35,E37,E39,E41,E43,E45,E47,E49,E51,E53,E55,E57) -> 12557.111 | F29: =SUM(F31,F33,F35,F37,F39,F41,F43,F45,F47,F49,F51,F53,F55,F57) -> 12037.136 | G29: =SUM(G31,G33,G35,G37,G39,G41,G43,G45,G47,G49,G51,G53,G55,G57) -> 13347.369 | H29: =SUM(H31,H33,H35,H37,H39,H41,H43,H45,H47,H49,H51,H53,H55,H57) -> 12624.412 | I29: =SUM(I31,I33,I35,I37,I39,I41,I43,I45,I47,I49,I51,I53,I55,I57) -> 12248 | J29: =SUM(J31,J33,J35,J37,J39,J41,J43,J45,J47,J49,J51,J53,J55,J57) -> 13792.022 | ... N29: =SUM(N31,N33,N35,N37,N39,N41,N43,N45,N47,N49,N51,N53,N55,N57) -> 33160.866 | P29: 판매비와 관리비 | Q29: =SUM(C29:F29) -> 48071.495 | R29: =SUM(G29:J29) -> 52011.803 | S29: =SUM(K29:N29) -> 124318.42 | U29: =(1+3.6%)^0.25/100 -> 0.01008881 | V29: =(1+3.9%)^0.25/100 -> 0.010096106 | AG29: 판매관리비 | AH29: =SUM(AH31,AH33,AH35,AH37,AH39,AH41,AH43,AH45,AH47,AH49,AH51,AH53,AH55,AH57,) -> 51773 | AI29: =SUM(AI31,AI33,AI35,AI37,AI39,AI41,AI43,AI45,AI47,AI49,AI51,AI53,AI55,AI57,) -> 46388 | AJ29: =SUM(AJ31,AJ33,AJ35,AJ37,AJ39,AJ41,AJ43,AJ45,AJ47,AJ49,AJ51,AJ53,AJ55,AJ57,) -> 48071
B30: % of sales | C30: =C29/C7 -> 0.25947312 | D30: =D29/D7 -> 0.25625978 | E30: =E29/E7 -> 0.26876477 | F30: =F29/F7 -> 0.25247576 | G30: =G29/G7 -> 0.38590471 | H30: =H29/H7 -> 0.25820145 | I30: =I29/I7 -> 0.29325289 | J30: =J29/J7 -> 0.2741136 | ... N30: =N29/N7 -> 0.15352969 | P30: % of sales | Q30: =Q29/Q7 -> 0.25913551 | R30: =R29/R7 -> 0.29625914 | S30: =S29/S7 -> 0.15696083
B31: 인건비 | C31: 4266 | D31: 5320 | E31: ='IS(Quaterly)'!J16 -> 4101.076 | F31: ='IS(Quaterly)'!K16 -> 4100.136 | G31: ='IS(Quaterly)'!L16 -> 4167.65 | H31: ='IS(Quaterly)'!M16 -> 4289.259 | I31: 3755 | J31: =$AD$31*J7 -> 4958.7355 | K31: =$AD$31*K7 -> 14190.851 | L31: =$AD$31*L7 -> 21627.377 | M31: =$AD$31*M7 -> 20953.199 | N31: =$AD$31*N7 -> 21286.638 | P31: 인건비 | Q31: =SUM(C31:F31) -> 17787.212 | R31: =SUM(G31:J31) -> 17170.645 | S31: =SUM(K31:N31) -> 78058.065 | V31: 매출액과 상관계수가 높기에 직전 3개년 매출액 대비 비율 average 하여 적용. | AD31: =AVERAGE(AH32:AJ32) -> 0.098553848 | AG31: 인건비 | AH31: 19491 | AI31: 16956 | AJ31: 17787
B32: % of sales | C32: =C31/C7 -> 0.10575259 | D32: =D31/D7 -> 0.10478678 | E32: =E31/E7 -> 0.087776936 | F32: =F31/F7 -> 0.085999273 | G32: =G31/G7 -> 0.12049684 | H32: =H31/H7 -> 0.087726295 | I32: =I31/I7 -> 0.089905665 | J32: =J31/J7 -> 0.098553848 | ... N32: =N31/N7 -> 0.098553848 | P32: % of sales | Q32: =Q31/Q7 -> 0.095884229 | R32: =R31/R7 -> 0.09780396 | S32: =S31/S7 -> 0.098553848 | AH32: =AH31/$AH$28 -> 0.072866003 | AI32: =AI31/$AI$28 -> 0.12691237 | AJ32: =AJ31/$AJ$28 -> 0.095883174
B33: 여비교통비 | C33: 309 | D33: 428 | E33: 394 | F33: 412 | G33: 301 | H33: 278 | I33: 329 | J33: =J7*$AD$33 -> 553.33879 | K33: =K7*$AD$33 -> 1583.5384 | L33: =L7*$AD$33 -> 2413.3707 | M33: =M7*$AD$33 -> 2338.14 | N33: =N7*$AD$33 -> 2375.348 | P33: 여비교통비 | Q33: =SUM(C33:F33) -> 1543 | R33: =SUM(G33:J33) -> 1461.3388 | S33: =SUM(K33:N33) -> 8710.397 | V33: 매출액과 상관계수가 높기에 직전 3개년 매출액 대비 비율 average 하여 적용. | AD33: =AVERAGE(AH34:AJ34) -> 0.010997495 | AG33: 여비교통비 | AH33: 3509 | AI33: 1544 | AJ33: 1543
B34: % of sales | C34: =C33/C7 -> 0.0076599975 | D34: =D33/D7 -> 0.0084302147 | E34: =E33/E7 -> 0.0084329363 | F34: =F33/F7 -> 0.0086415915 | G34: =G33/G7 -> 0.0087026377 | H34: =H33/H7 -> 0.0056858096 | I34: =I33/I7 -> 0.0078772207 | J34: =J33/J7 -> 0.010997495 | ... N34: =N33/N7 -> 0.010997495 | P34: % of sales | Q34: =Q33/Q7 -> 0.0083177378 | R34: =R33/R7 -> 0.0083237831 | S34: =S33/S7 -> 0.010997495 | AH34: =AH33/$AH$28 -> 0.013118198 | AI34: =AI33/$AI$28 -> 0.01155654 | AJ34: =AJ33/$AJ$28 -> 0.0083177454
B35: 대손상각비 | C35: -585 | D35: -398 | E35: 160 | F35: -1047 | G35: 367 | H35: -47 | I35: 1039 | J35: =AVERAGE(F35:I35) -> 78 | K35: =AVERAGE(G35:J35) -> 359.25 | L35: =AVERAGE(H35:K35) -> 357.3125 | M35: =AVERAGE(I35:L35) -> 458.39062 | N35: =AVERAGE(J35:M35) -> 313.23828 | P35: 대손상각비 | Q35: =SUM(C35:F35) -> -1870 | R35: =SUM(G35:J35) -> 1437 | S35: =SUM(K35:N35) -> 1488.1914 | V35: 직전 4Q Average Flat 적용함. | AD35: =AVERAGE(AH36:AJ36) -> 0.001393074 | AG35: 대손상각비 | AH35: 655 | AI35: 1578 | AJ35: -1870
B36: % of sales | C36: =C35/C7 -> -0.014501937 | D36: =D35/D7 -> -0.0078393118 | E36: =E35/E7 -> 0.0034245427 | F36: =F35/F7 -> -0.021960549 | G36: =G35/G7 -> 0.010610857 | H36: =H35/H7 -> -0.00096126997 | I36: =I35/I7 -> 0.024876694 | J36: =J35/J7 -> 0.0015502339 | ... N36: =N35/N7 -> 0.0014502449 | P36: % of sales | Q36: =Q35/Q7 -> -0.010080473 | R36: =R35/R7 -> 0.0081851494 | S36: =S35/S7 -> 0.0018789473 | AH36: =AH35/$AH$28 -> 0.0024486805 | AI36: =AI35/$AI$28 -> 0.011811024 | AJ36: =AJ35/$AJ$28 -> -0.010080482
B37: 감가상각비 | C37: 738 | D37: 843 | E37: 1226 | F37: 1275 | G37: 1639 | H37: 1664 | I37: 1746 | J37: =AVERAGE(F37:I37) -> 1581 | K37: =AVERAGE(G37:J37) -> 1657.5 | L37: =AVERAGE(H37:K37) -> 1662.125 | M37: =AVERAGE(I37:L37) -> 1661.6562 | N37: =AVERAGE(J37:M37) -> 1640.5703 | P37: 감가상각비 | Q37: =SUM(C37:F37) -> 4082 | R37: =SUM(G37:J37) -> 6630 | S37: =SUM(K37:N37) -> 6621.8516 | V37: 직전 4Q Average Flat 적용함. | AD37: =AVERAGE(AH38:AJ38) -> 0.018397598 | AG37: 감가상각비 | AH37: 2683 | AI37: 3094 | AJ37: 4082
B38: % of sales | C38: =C37/C7 -> 0.018294751 | D38: =D37/D7 -> 0.016604372 | E38: =E37/E7 -> 0.026240558 | F38: =F37/F7 -> 0.026742789 | G38: =G37/G7 -> 0.047387452 | H38: =H37/H7 -> 0.034033047 | I38: =I37/I7 -> 0.041804338 | J38: =J37/J7 -> 0.03142205 | ... N38: =N37/N7 -> 0.0075955875 | P38: % of sales | Q38: =Q37/Q7 -> 0.02200454 | R38: =R37/R7 -> 0.037764468 | S38: =S37/S7 -> 0.0083605577 | AH38: =AH37/$AH$28 -> 0.010030244 | AI38: =AI37/$AI$28 -> 0.023157989 | AJ38: =AJ37/$AJ$28 -> 0.02200456
B39: 무형자산상각비 | C39: 199 | D39: 205 | E39: 203 | F39: 193 | G39: 191 | H39: 140 | I39: 135 | J39: =AVERAGE(F39:I39) -> 164.75 | K39: =AVERAGE(G39:J39) -> 157.6875 | L39: =AVERAGE(H39:K39) -> 149.35938 | M39: =AVERAGE(I39:L39) -> 151.69922 | N39: =AVERAGE(J39:M39) -> 155.87402 | P39: 무형자산상각비 | Q39: =SUM(C39:F39) -> 800 | R39: =SUM(G39:J39) -> 630.75 | S39: =SUM(K39:N39) -> 614.62012 | V39: 직전 4Q Average Flat 적용함. | AD39: =AVERAGE(AH40:AJ40) -> 0.0042819844 | AG39: 무형자산상각비 | AH39: 751 | AI39: 765 | AJ39: 800
B40: % of sales | C40: =C39/C7 -> 0.0049331376 | D40: =D39/D7 -> 0.0040378365 | E40: =E39/E7 -> 0.0043448885 | F40: =F39/F7 -> 0.0040481242 | G40: =G39/G7 -> 0.0055222718 | H40: =H39/H7 -> 0.0028633574 | I40: =I39/I7 -> 0.0032322942 | J40: =J39/J7 -> 0.0032743723 | ... N40: =N39/N7 -> 0.00072167269 | P40: % of sales | Q40: =Q39/Q7 -> 0.0043125018 | R40: =R39/R7 -> 0.0035927509 | S40: =S39/S7 -> 0.00077600153 | AH40: =AH39/$AH$28 -> 0.0028075711 | AI40: =AI39/$AI$28 -> 0.0057258765 | AJ40: =AJ39/$AJ$28 -> 0.0043125057
B41: 임차료 | C41: 98 | D41: 92 | E41: 114 | F41: 56 | G41: 33 | H41: 135 | I41: 72 | J41: =AVERAGE(F41:I41) -> 74 | K41: =AVERAGE(G41:J41) -> 78.5 | L41: =AVERAGE(H41:K41) -> 89.875 | M41: =AVERAGE(I41:L41) -> 78.59375 | N41: =AVERAGE(J41:M41) -> 80.242188 | P41: 임차료 | Q41: =SUM(C41:F41) -> 360 | R41: =SUM(G41:J41) -> 314 | S41: =SUM(K41:N41) -> 327.21094 | V41: 직전 4Q Average Flat 적용함. | AD41: =AVERAGE(AH42:AJ42) -> 0.0021471267 | AG41: 임차료 | AH41: 343 | AI41: 430 | AJ41: 360
...

Sheet RAW DATA>>>
B2: 테크윙(089030.KQ) RAW DATA
B10: RFS Research Team 2

Sheet IS(Quaterly)
A1: Financial Statements
A2: Company | B2: A089030(테크윙) - Fiscal Month:12, 201106부터 IFRS 적용
A3: Type | B3: 연결 | C3: Accounting Std. | D3: IFRS
A4: Report | B4: 손익계산서 | C4: New
A5: Form | B5: 약식(COMPARE)
A6: Output | B6: 당분기 | C6: 백만원
A7: Fiscal Year | B7: 2023 | C7: Current
A8: 계정코드 | B8: 계정명 | C8: 단위 | D8: 202303(1Q) | E8: 202306(2Q) | F8: 202309(3Q) | G8: 202312(4Q) | H8: 202403(1Q) | I8: 202406(2Q) | J8: 202409(3Q) | K8: 202412(4Q) | L8: 202503(1Q) | M8: 202506(2Q) | N8: 202509(3Q)
D9: IFRS(연결) | E9: IFRS(연결) | F9: IFRS(연결) | G9: IFRS(연결) | H9: IFRS(연결) | I9: IFRS(연결) | J9: IFRS(연결) | K9: IFRS(연결) | L9: IFRS(연결) | M9: IFRS(연결) | N9: IFRS(연결)
A10: 4001210000 | B10: 매출액(수익)(*) | C10: 백만원 | D10: 28622.483 | E10: 39490.614 | F10: 24330.7 | G10: 41160.463 | H10: 40339.439 | I10: 50769.762 | J10: 46721.567 | K10: 47676.403 | L10: 34587.215 | M10: 48893.653 | N10: 41765.844
A11: 4001210010 | B11: *수출(*) | C11: 백만원 | H11: 29844.904 | J11: 36809.142 | K11: 71635.804 | L11: 25066.01 | M11: 48893.653
A12: 4001210020 | B12: *내수 | C12: 백만원 | H12: 10494.535 | J12: 9912.425 | K12: 26810.361 | L12: 9521.205
A13: 4001210320 | B13: 매출원가(*) | C13: 백만원 | D13: 16557.603 | E13: 24010.858 | F13: 15297.826 | G13: 28189.93 | H13: 24298.609 | I13: 30584.084 | J13: 27986.516 | K13: 31152.326 | L13: 19942.025 | M13: 30065.138 | N13: 22406.702
A14: 4001210780 | B14: 매출총이익(손실) | C14: 백만원 | D14: 12064.879 | E14: 15479.756 | F14: 9032.8738 | G14: 12970.533 | H14: 16040.83 | I14: 20185.678 | J14: 18735.051 | K14: 16524.077 | L14: 14645.189 | M14: 18828.515 | N14: 19359.141
A15: 4001290000 | B15: 판매비와관리비(*) | C15: 백만원 | D15: 11673.425 | E15: 13048.805 | F15: 11722.846 | G15: 9942.4785 | H15: 10467.713 | I15: 13010.374 | J15: 12558.272 | K15: 12038.2 | L15: 12861.812 | M15: 12467.433 | N15: 12248.046
A16: 4001290010 | B16: 인건비(*) | C16: 백만원 | D16: 4417.614 | E16: 4361.619 | F16: 4091.537 | G16: 4084.438 | H16: 4266.409 | I16: 5320.179 | J16: 4101.076 | K16: 4100.136 | L16: 4167.65 | M16: 4289.259 | N16: 3754.945
A17: 4001290020 | B17: 유무형자산상각비(*) | C17: 백만원 | D17: 985.161 | E17: 984.234 | F17: 954.462 | G17: 935.893 | H17: 937.219 | I17: 1047.862 | J17: 1428.892 | K17: 1468.03 | L17: 1829.404 | M17: 1803.772 | N17: 1880.601
A18: 4001211300 | B18: 연구개발비 | C18: 백만원 | D18: 4189.642 | E18: 4113.692 | F18: 3915.861 | G18: 3433.152 | H18: 3969.884 | I18: 4518.248 | J18: 4553.035 | K18: 5626.013 | L18: 3893.984 | M18: 4376.273 | N18: 3618.253
A19: 4001211060 | B19: 광고선전비 | C19: 백만원
A20: 4001290040 | B20: 판매비(*) | C20: 백만원 | D20: 305.425 | E20: 1358.089 | F20: 1136.518 | G20: -121.172 | H20: -369.252 | I20: -109.802 | J20: 429.189 | K20: -960.53 | L20: 550.735 | M20: 170.88 | N20: 1348.717
A21: 4001290090 | B21: 관리비(*) | C21: 백만원 | D21: 1426.618 | E21: 1761.52 | F21: 1419.439 | G21: 1406.761 | H21: 1523.623 | I21: 1720.977 | J21: 1404.204 | K21: 1466.843 | L21: 2193.347 | M21: 1237.775 | N21: 1337.31
A22: 4001290110 | B22: 기타원가성비용(*) | C22: 백만원
A23: 4001211420 | B23: 기타 | C23: 백만원 | D23: 348.965 | E23: 469.651 | F23: 205.029 | G23: 203.408 | H23: 139.83 | I23: 512.91 | J23: 641.876 | K23: 337.708 | L23: 226.692 | M23: 589.474 | N23: 308.22
A24: 4001211430 | B24: 영업이익(손실) | C24: 백만원 | D24: 391.45394 | E24: 2430.9511 | F24: -2689.9726 | G24: 3028.0547 | H24: 5573.1168 | I24: 7175.3038 | J24: 6176.779 | K24: 4485.8777 | L24: 1783.3769 | M24: 6361.0817 | N24: 7111.0949
A25: 4001290120 | B25: 금융수익(*) | C25: 백만원 | D25: 567.531 | E25: 656.843 | F25: 510.283 | G25: 2147.428 | H25: 549.529 | I25: 756.944 | J25: 362.569 | K25: 1031.955 | L25: 857.441 | M25: 4146.555 | N25: -4293.175
A26: 4001290750 | B26: 이자수익 | C26: 백만원 | D26: 288.958 | E26: 279.396 | F26: 332.861 | G26: 266.95 | H26: 273.223 | I26: 248.92 | J26: 204.423 | K26: 124.029 | L26: 112.246 | M26: 90.621 | N26: 106.93
A27: 4001290760 | B27: 배당금수익 | C27: 백만원
A28: 4001211480 | B28: 외환이익(*) | C28: 백만원 | D28: 278.573 | E28: 377.447 | F28: 177.422 | G28: 1775.97 | H28: 276.306 | I28: 116.236 | J28: 158.146 | K28: 900.989 | L28: 745.195 | M28: 4055.934 | N28: -4400.105
A29: 4001211520 | B29: 대손충당금환입액 | C29: 백만원 | G29: 104.508 | I29: 391.788 | K29: 6.937
A30: 4001211600 | B30: 매출채권처분이익 | C30: 백만원
A31: 4001211605 | B31: 당기손익-공정가치측정 금융자산관련이익 | C31: 백만원
A32: 4001290130 | B32: 금융자산처분이익(*) | C32: 백만원
A33: 4001290150 | B33: 금융자산평가이익(*) | C33: 백만원
A34: 4001211720 | B34: 금융자산손상차손환입(*) | C34: 백만원
A35: 4001211680 | B35: 파생상품이익(*) | C35: 백만원
A36: 4001290170 | B36: 기타금융수익(*) | C36: 백만원
A37: 4001290180 | B37: 금융원가(*) | C37: 백만원 | D37: 2623.478 | E37: 1992.308 | F37: 241.71 | G37: 1655.046 | H37: 4431.189 | I37: 3954.907 | J37: -458.31 | K37: 8065.787 | L37: 2220.026 | M37: 4778.148 | N37: 3088.027
A38: 4001290770 | B38: 이자비용 | C38: 백만원 | D38: 1022.592 | E38: 1201.502 | F38: 1408.632 | G38: 2041.622 | H38: 1897.945 | I38: 2036.685 | J38: 2317.653 | K38: 2120.32 | L38: 2070.21 | M38: 2473.559 | N38: 2757.012
A39: 4001211820 | B39: 외환손실(*) | C39: 백만원 | D39: 1600.886 | E39: 790.806 | F39: -1166.922 | G39: -386.576 | H39: 2533.244 | I39: 1918.222 | J39: -2775.963 | K39: 5945.467 | L39: 149.816 | M39: 454.589 | N39: 331.015
A40: 4001211860 | B40: 대손상각비 | C40: 백만원 | M40: 1850
...

Sheet IS(Yearly)
A2: Financial Statements
A3: Company | B3: A089030(테크윙) - Fiscal Month:12, 201106부터 IFRS 적용
A4: Type | B4: 연결 | C4: Accounting Std. | D4: IFRS
A5: Report | B5: 손익계산서 | C5: New
A6: Form | B6: 약식(COMPARE)
A7: Output | B7: 결산 | C7: 백만원
A8: Fiscal Year | B8: 2023 | C8: Current
A9: 계정코드 | B9: 계정명 | C9: 단위 | D9: 202312 | E9: 202412
D10: IFRS(연결) | E10: IFRS(연결)
A11: 4001210000 | B11: 매출액(수익)(*) | C11: 백만원 | D11: 133604.26 | E11: 185507.17
A12: 4001210010 | B12: *수출(*) | C12: 백만원 | E12: 138289.85
A13: 4001210020 | B13: *내수 | C13: 백만원 | E13: 47217.321
A14: 4001210320 | B14: 매출원가(*) | C14: 백만원 | D14: 84056.218 | E14: 114021.53
A15: 4001210780 | B15: 매출총이익(손실) | C15: 백만원 | D15: 49548.043 | E15: 71485.637
A16: 4001290000 | B16: 판매비와관리비(*) | C16: 백만원 | D16: 46387.556 | E16: 48074.559
A17: 4001290010 | B17: 인건비(*) | C17: 백만원 | D17: 16955.208 | E17: 17787.8
A18: 4001290020 | B18: 유무형자산상각비(*) | C18: 백만원 | D18: 3859.75 | E18: 4882.003
A19: 4001211300 | B19: 연구개발비 | C19: 백만원 | D19: 15652.347 | E19: 18667.18
A20: 4001211060 | B20: 광고선전비 | C20: 백만원
