Workbook

Sheet Estimate>>>
B2: HD현대마린솔루션 Valuation&Estimation Logic
B8: RFS Research Team 2

Sheet Valuation
A1: HD현대마린솔루션(443060.KS)
A2: Peer P/E Valuation Sheet
A3: (units in KRW)
B5: HD현대마린솔루션 Peer P/E Valuation | G5: 업종 | H5: 기업명 | I5: P/E | J5: 할인율
B6: '26E 당기순이익 | C6: =SUM('Expected IS'!J22:M22) -> 278630.75 | D6: 백만 원 | E6: (A) | G6: 항공 | H6: FTAI Aviation Ltd | I6: 49.21 | J6: 0
B7: Target P/E | C7: =I12 -> 47.976667 | D7: 배 | E7: (B) | G7: 항공 | H7: Heico | I7: 70.72 | J7: 0
B8: 발행 주식 수 | C8: 44829210 | D8: 주 | E8: (C) | G8: 발전설비 | H8: GE Vernova | I8: =133.2*(1-J8) -> 79.92 | J8: 0.4
B9: 적정주가 | C9: =C6*C7/C8*10^6 -> 298193.4 | D9: 원 | E9: (D)=(A)*(B)/(C) | G9: 방산 | H9: Raytheon Technologies | I9: 26.85 | J9: 0
B10: Target Price | C10: =ROUND(C9,-2) -> 298200 | D10: 원 | G10: 방산 | H10: Bae Syetems | I10: 29.66 | J10: 0
B11: Current Price | C11: 203500 | D11: 원 | E11: 25.09.22 기준 | G11: 철도 | H11: Alstom | I11: 31.5 | J11: 0
B12: Upside | C12: =(C10-C11)/C11*100 -> 46.535627 | D12: % | H12: Avg P/E | I12: =AVERAGE(I6:I11) -> 47.976667

Sheet Expected IS
A1: HD현대마린솔루션(443060.KS)
A2: Expected IS Sheet
A3: (units in Millions KRW )
B5: 단위: 백만 원 | C5: 2Q24 | D5: 3Q24 | E5: 4Q24 | F5: 1Q25 | G5: 2Q25 | H5: 3Q25E | I5: 4Q25E | J5: 1Q26E | K5: 2Q26E | L5: 3Q26E | M5: 4Q26E
B6: 매출액 | C6: ='IS(Quaterly)'!G10 -> 437855.16 | D6: ='IS(Quaterly)'!H10 -> 461261.44 | E6: ='IS(Quaterly)'!I10 -> 463372.92 | F6: ='IS(Quaterly)'!J10 -> 485597.83 | G6: ='IS(Quaterly)'!K10 -> 467721.57 | H6: =매출추정!I6*100 -> 469386.75 | I6: =매출추정!J6*100 -> 483293.63 | J6: =매출추정!K6*100 -> 508637.42 | K6: =매출추정!L6*100 -> 519267.74 | L6: =매출추정!M6*100 -> 538811.31 | M6: =매출추정!N6*100 -> 550319.23
B7: 매출원가 | C7: ='IS(Quaterly)'!G13 -> 343798 | D7: ='IS(Quaterly)'!H13 -> 355933.42 | E7: ='IS(Quaterly)'!I13 -> 373085.98 | F7: ='IS(Quaterly)'!J13 -> 377587.18 | G7: ='IS(Quaterly)'!K13 -> 358744.49 | H7: =비용추정!H7 -> 367643.87 | I7: =비용추정!I7 -> 375006.72 | J7: =비용추정!J7 -> 394395.26 | K7: =비용추정!K7 -> 404090.41 | L7: =비용추정!L7 -> 418392.04 | M7: =비용추정!M7 -> 427432.56
B8: (%) | C8: =C7/C6 -> 0.78518659 | D8: =D7/D6 -> 0.77165223 | E8: =E7/E6 -> 0.80515275 | F8: =F7/F6 -> 0.77757181 | G8: =G7/G6 -> 0.76700437 | H8: =H7/H6 -> 0.78324298 | I8: =I7/I6 -> 0.77593972 | J8: =J7/J6 -> 0.77539569 | ... M8: =M7/M6 -> 0.77669929
B9: 매출총이익 | C9: ='IS(Quaterly)'!G14 -> 94057.16 | D9: ='IS(Quaterly)'!H14 -> 105328.02 | E9: ='IS(Quaterly)'!I14 -> 90286.939 | F9: ='IS(Quaterly)'!J14 -> 108010.65 | G9: ='IS(Quaterly)'!K14 -> 108977.08 | H9: =H6-H7 -> 101742.87 | I9: =I6-I7 -> 108286.91 | J9: =J6-J7 -> 114242.16 | K9: =K6-K7 -> 115177.33 | L9: =L6-L7 -> 120419.26 | M9: =M6-M7 -> 122886.67
B10: GPM(%) | C10: =C9/C6 -> 0.21481341 | D10: =D9/D6 -> 0.22834777 | E10: =E9/E6 -> 0.19484725 | F10: =F9/F6 -> 0.22242819 | G10: =G9/G6 -> 0.23299563 | H10: =H9/H6 -> 0.21675702 | I10: =I9/I6 -> 0.22406028 | J10: =J9/J6 -> 0.22460431 | ... M10: =M9/M6 -> 0.22330071
B11: 판매비와 관리비 | C11: ='IS(Quaterly)'!G15 -> 23071.291 | D11: ='IS(Quaterly)'!H15 -> 21944.67 | E11: ='IS(Quaterly)'!I15 -> 24407.77 | F11: ='IS(Quaterly)'!J15 -> 25003.82 | G11: ='IS(Quaterly)'!K15 -> 25967.147 | H11: =비용추정!H11 -> 25534.997 | I11: =비용추정!I11 -> 25957.874 | J11: =비용추정!J11 -> 25964.082 | K11: =비용추정!K11 -> 26135.482 | L11: =비용추정!L11 -> 26176.755 | M11: =비용추정!M11 -> 26341.857
B12: (%) | C12: =C11/C6 -> 0.052691604 | D12: =D11/D6 -> 0.04757534 | E12: =E11/E6 -> 0.05267414 | F12: =F11/F6 -> 0.051490798 | G12: =G11/G6 -> 0.055518387 | H12: =H11/H6 -> 0.054400764 | I12: =I11/I6 -> 0.053710359 | J12: =J11/J6 -> 0.051046346 | ... M12: =M11/M6 -> 0.047866504
B13: 영업이익 | C13: ='IS(Quaterly)'!G24 -> 70985.869 | D13: ='IS(Quaterly)'!H24 -> 83383.35 | E13: ='IS(Quaterly)'!I24 -> 65879.169 | F13: ='IS(Quaterly)'!J24 -> 83006.827 | G13: ='IS(Quaterly)'!K24 -> 83009.935 | H13: =H9-H11 -> 76207.877 | I13: =I9-I11 -> 82329.033 | J13: =J9-J11 -> 88278.077 | K13: =K9-K11 -> 89041.843 | L13: =L9-L11 -> 94242.507 | M13: =M9-M11 -> 96544.815
B14: OPM(%) | C14: =C13/C6 -> 0.16212181 | D14: =D13/D6 -> 0.18077243 | E14: =E13/E6 -> 0.14217311 | F14: =F13/F6 -> 0.17093739 | G14: =G13/G6 -> 0.17747724 | H14: =H13/H6 -> 0.16235626 | I14: =I13/I6 -> 0.17034992 | J14: =J13/J6 -> 0.17355797 | ... M14: =M13/M6 -> 0.1754342
B15: 지분법손익 | C15: ='IS(Quaterly)'!G79 -> 0 | D15: ='IS(Quaterly)'!H79 -> -179.16728 | E15: ='IS(Quaterly)'!I79 -> -58.85354 | F15: ='IS(Quaterly)'!J79 -> -106.50236 | G15: ='IS(Quaterly)'!K79 -> -61.97999 | H15: =비용추정!H54 -> -101.62579 | I15: =비용추정!I54 -> -82.240421 | J15: =비용추정!J54 -> -88.087141 | K15: =비용추정!K54 -> -83.483336 | L15: =비용추정!L54 -> -88.859172 | M15: =비용추정!M54 -> -85.667517
B16: 금융수익 | C16: ='IS(Quaterly)'!G25 -> 10729.355 | D16: ='IS(Quaterly)'!H25 -> 9314.79 | E16: ='IS(Quaterly)'!I25 -> 29108.738 | F16: ='IS(Quaterly)'!J25 -> 15766.251 | G16: ='IS(Quaterly)'!K25 -> 16252.424 | H16: =비용추정!H56 -> 17610.551 | I16: =비용추정!I56 -> 19684.491 | J16: =비용추정!J56 -> 17328.429 | K16: =비용추정!K56 -> 17718.974 | L16: =비용추정!L56 -> 18085.611 | M16: =비용추정!M56 -> 18204.376
B17: 금융원가 | C17: ='IS(Quaterly)'!G37 -> 4267.171 | D17: ='IS(Quaterly)'!H37 -> 14714.404 | E17: ='IS(Quaterly)'!I37 -> 8263.257 | F17: ='IS(Quaterly)'!J37 -> 13365.847 | G17: ='IS(Quaterly)'!K37 -> 29691.852 | H17: =비용추정!H58 -> 16508.84 | I17: =비용추정!I58 -> 16957.449 | J17: =비용추정!J58 -> 19130.997 | K17: =비용추정!K58 -> 20572.285 | L17: =비용추정!L58 -> 18292.393 | M17: =비용추정!M58 -> 18738.281
B18: 기타수익 | C18: ='IS(Quaterly)'!G48 -> 214.759 | D18: ='IS(Quaterly)'!H48 -> -6.593 | E18: ='IS(Quaterly)'!I48 -> 424.728 | F18: ='IS(Quaterly)'!J48 -> 450.714 | G18: ='IS(Quaterly)'!K48 -> 105.875 | H18: =비용추정!H60 -> 243.681 | I18: =비용추정!I60 -> 306.2495 | J18: =비용추정!J60 -> 276.62987 | K18: =비용추정!K60 -> 233.10884 | L18: =비용추정!L60 -> 264.9173 | M18: =비용추정!M60 -> 270.22638
B19: 기타비용 | C19: ='IS(Quaterly)'!G65 -> 719.496 | D19: ='IS(Quaterly)'!H65 -> 482.051 | E19: ='IS(Quaterly)'!I65 -> 774.81 | F19: ='IS(Quaterly)'!J65 -> 1874.732 | G19: ='IS(Quaterly)'!K65 -> 1333.607 | H19: =비용추정!H62 -> 1116.3 | I19: =비용추정!I62 -> 1274.8622 | J19: =비용추정!J62 -> 1399.8753 | K19: =비용추정!K62 -> 1281.1611 | L19: =비용추정!L62 -> 1268.0497 | M19: =비용추정!M62 -> 1305.9871
B20: 법인세차감전순이익 | C20: ='IS(Quaterly)'!G83 -> 76943.316 | D20: ='IS(Quaterly)'!H83 -> 77315.925 | E20: ='IS(Quaterly)'!I83 -> 86315.712 | F20: ='IS(Quaterly)'!J83 -> 83876.711 | G20: ='IS(Quaterly)'!K83 -> 68280.796 | H20: =H13+H15+H16-H17+H18-H19 -> 76335.343 | I20: =I13+I15+I16-I17+I18-I19 -> 84005.222 | J20: =J13+J15+J16-J17+J18-J19 -> 85264.177 | K20: =K13+K15+K16-K17+K18-K19 -> 85056.997 | L20: =L13+L15+L16-L17+L18-L19 -> 92943.734 | M20: =M13+M15+M16-M17+M18-M19 -> 94889.482
B21: 법인세비용 | C21: ='IS(Quaterly)'!G84 -> 20264.116 | D21: ='IS(Quaterly)'!H84 -> 18786.758 | E21: ='IS(Quaterly)'!I84 -> 17908.97 | F21: ='IS(Quaterly)'!J84 -> 20558.525 | G21: ='IS(Quaterly)'!K84 -> 15283.742 | H21: =H20*비용추정!H66 -> 18117.363 | I21: =I20*비용추정!I66 -> 18396.648 | J21: =J20*비용추정!J66 -> 19287.103 | K21: =K20*비용추정!K66 -> 19116.747 | L21: =L20*비용추정!L66 -> 20393.614 | M21: =M20*비용추정!M66 -> 20726.178
B22: 당기순이익 | C22: ='IS(Quaterly)'!G89 -> 56679.2 | D22: ='IS(Quaterly)'!H89 -> 58529.167 | E22: ='IS(Quaterly)'!I89 -> 68406.742 | F22: ='IS(Quaterly)'!J89 -> 63318.186 | G22: ='IS(Quaterly)'!K89 -> 52997.054 | H22: =H20-H21 -> 58217.98 | I22: =I20-I21 -> 65608.574 | J22: =J20-J21 -> 65977.073 | K22: =K20-K21 -> 65940.25 | L22: =L20-L21 -> 72550.12 | M22: =M20-M21 -> 74163.304
B23: (%) | C23: =C22/C6 -> 0.12944737 | D23: =D22/D6 -> 0.12688936 | E23: =E22/E6 -> 0.14762784 | F23: =F22/F6 -> 0.13039223 | G23: =G22/G6 -> 0.11330898 | H23: =H22/H6 -> 0.12402988 | I23: =I22/I6 -> 0.13575303 | J23: =J22/J6 -> 0.12971337 | ... M23: =M22/M6 -> 0.13476415

Sheet 매출추정
A1: HD현대마린솔루션(443060.KS)
A2: Revenue Estimation Sheet
A3: (units in Hundred Millions KRW )
B5: 단위: 억 원 | C5: 1Q24 | D5: 2Q24 | E5: 3Q24 | F5: 4Q24 | G5: 1Q25 | H5: 2Q25 | I5: 3Q25E | J5: 4Q25E | K5: 1Q26E | L5: 2Q26E | M5: 3Q26E | N5: 4Q26E | P5: 2024A | Q5: 2025E | R5: 2026E
B6: 매출 | C6: 3830 | D6: ='IS(Quaterly)'!G10/100 -> 4378.5516 | E6: ='IS(Quaterly)'!H10/100 -> 4612.6144 | F6: ='IS(Quaterly)'!I10/100 -> 4633.7292 | G6: ='IS(Quaterly)'!J10/100 -> 4855.9783 | H6: ='IS(Quaterly)'!K10/100 -> 4677.2157 | I6: =I8+I14+I16+I18 -> 4693.8675 | J6: =J8+J14+J16+J18 -> 4832.9363 | K6: =K8+K14+K16+K18 -> 5086.3742 | L6: =L8+L14+L16+L18 -> 5192.6774 | M6: =M8+M14+M16+M18 -> 5388.1131 | N6: =N8+N14+N16+N18 -> 5503.1923 | P6: =SUM(C6:F6) -> 17454.895 | Q6: =SUM(G6:J6) -> 19059.998 | R6: =SUM(K6:N6) -> 21170.357
B7: YoY(%) or QoQ(%) | C7: - | D7: =(D6-C6)/C6 -> 0.14322496 | E7: =(E6-D6)/D6 -> 0.053456668 | F7: =(F6-E6)/E6 -> 0.004577633 | G7: =(G6-F6)/F6 -> 0.047963325 | H7: =(H6-G6)/G6 -> -0.036812889 | I7: =(I6-H6)/H6 -> 0.003560189 | J7: =(J6-I6)/I6 -> 0.029627773 | K7: =(K6-J6)/J6 -> 0.052439741 | ... N7: =(N6-M6)/M6 -> 0.021357983 | P7: - | Q7: =(Q6-P6)/P6 -> 0.091957159 | R7: =(R6-Q6)/Q6 -> 0.1107219
B8: AM 솔루션 | C8: 1692 | D8: =SUM(D10:D13) -> 2061 | E8: =SUM(E10:E13) -> 2192 | F8: =SUM(F10:F13) -> 2113 | G8: =SUM(G10:G13) -> 2161 | H8: =SUM(H10:H13) -> 2300 | I8: =SUM(I10:I13) -> 2468.1269 | J8: =SUM(J10:J13) -> 2567.3591 | K8: =SUM(K10:K13) -> 2668.1498 | ... N8: =SUM(N10:N13) -> 2958.9873 | P8: =SUM(C8:F8) -> 8058 | Q8: =SUM(G8:J8) -> 9496.486 | R8: =SUM(K8:N8) -> 11249.817
B9: of Revenue(%) | C9: =C8/C$6 -> 0.44177546 | D9: =D8/D$6 -> 0.4707036 | E9: =E8/E$6 -> 0.47521857 | F9: =F8/F$6 -> 0.4560042 | G9: =G8/G$6 -> 0.44501846 | H9: =H8/H$6 -> 0.49174555 | I9: =I8/I$6 -> 0.52581947 | J9: =J8/J$6 -> 0.53122139 | ... N9: =N8/N$6 -> 0.53768562 | P9: =P8/P$6 -> 0.461647 | Q9: =Q8/Q$6 -> 0.49824172 | R9: =R8/R$6 -> 0.53139475
B10: 엔진 | C10: 1081 | D10: 1245 | E10: 1547 | F10: 1450 | G10: =AM!G8 -> 1572 | H10: =AM!H8 -> 1568 | I10: =AM!I8 -> 1722.0397 | J10: =AM!J8 -> 1802.3473 | K10: =AM!K8 -> 1886.4 | L10: =AM!L8 -> 1974.3725 | M10: =AM!M8 -> 2066.4477 | N10: =AM!N8 -> 2162.8167 | P10: =SUM(C10:F10) -> 5323 | Q10: =SUM(G10:J10) -> 6664.387 | R10: =SUM(K10:N10) -> 8090.0369
B11: 비엔진 | C11: 287 | D11: 307 | E11: 262 | F11: 306 | G11: =AM!G16 -> 281 | H11: =AM!H16 -> 283 | I11: =AM!I16 -> 281.17341 | J11: =AM!J16 -> 278.91662 | K11: =AM!K16 -> 278.39409 | L11: =AM!L16 -> 277.90334 | M11: =AM!M16 -> 277.60624 | N11: =AM!N16 -> 277.45685 | P11: =SUM(C11:F11) -> 1162 | Q11: =SUM(G11:J11) -> 1124.09 | R11: =SUM(K11:N11) -> 1111.3605
B12: 육상발전 | C12: 115 | D12: 279 | E12: 193 | F12: 115 | G12: =AM!G18 -> 89 | H12: =AM!H18 -> 200 | I12: =AM!I18 -> 206.98006 | J12: =AM!J18 -> 216.26174 | K12: =AM!K18 -> 227.861 | L12: =AM!L18 -> 231.89971 | M12: =AM!M18 -> 234.82775 | N12: =AM!N18 -> 236.66213 | P12: =SUM(C12:F12) -> 702 | Q12: =SUM(G12:J12) -> 712.2418 | R12: =SUM(K12:N12) -> 931.25059
B13: 스마트케어 | C13: 209 | D13: 230 | E13: 190 | F13: 242 | G13: =AM!G20 -> 219 | H13: =AM!H20 -> 249 | I13: =AM!I20 -> 257.9337 | J13: =AM!J20 -> 269.8335 | K13: =AM!K20 -> 275.49475 | L13: =AM!L20 -> 278.74887 | M13: =AM!M20 -> 280.87326 | N13: =AM!N20 -> 282.05163 | P13: =SUM(C13:F13) -> 871 | Q13: =SUM(G13:J13) -> 995.7672 | R13: =SUM(K13:N13) -> 1117.1685
B14: 친환경 솔루션 | C14: 303 | D14: 346 | E14: 438 | F14: 548 | G14: 583 | H14: 328 | I14: =Retrofit!I6 -> 391.53745 | J14: =Retrofit!J6 -> 396.0782 | K14: =Retrofit!K6 -> 589.45501 | L14: =Retrofit!L6 -> 590.7023 | M14: =Retrofit!M6 -> 685.28887 | N14: =Retrofit!N6 -> 707.19361 | P14: =SUM(C14:F14) -> 1635 | Q14: =SUM(G14:J14) -> 1698.6156 | R14: =SUM(K14:N14) -> 2572.6398
B15: of Revenue(%) | C15: =C14/C$6 -> 0.079112272 | D15: =D14/D$6 -> 0.079021565 | E15: =E14/E$6 -> 0.094956995 | F15: =F14/F$6 -> 0.11826328 | G15: =G14/G$6 -> 0.1200582 | H15: =H14/H$6 -> 0.070127191 | I15: =I14/I$6 -> 0.083414679 | J15: =J14/J$6 -> 0.081953945 | ... N15: =N14/N$6 -> 0.12850607 | P15: =P14/P$6 -> 0.093669998 | Q15: =Q14/Q$6 -> 0.089119404 | R15: =R14/R$6 -> 0.12152085
B16: 디지털 솔루션 | C16: 174 | D16: 195 | E16: 171 | F16: 167 | G16: 198 | H16: 220 | I16: =Digital!I6 -> 230.36244 | J16: =Digital!J6 -> 233.68689 | K16: =Digital!K6 -> 230.90576 | L16: =Digital!L6 -> 232.45384 | M16: =Digital!M6 -> 232.56465 | N16: =Digital!N6 -> 232.03138 | P16: =SUM(C16:F16) -> 707 | Q16: =SUM(G16:J16) -> 882.04932 | R16: =SUM(K16:N16) -> 927.95562
B17: of Revenue(%) | C17: =C16/C$6 -> 0.045430809 | D17: =D16/D$6 -> 0.044535275 | E17: =E16/E$6 -> 0.037072252 | F17: =F16/F$6 -> 0.036040086 | G17: =G16/G$6 -> 0.040774482 | H17: =H16/H$6 -> 0.047036531 | I17: =I16/I$6 -> 0.04907732 | J17: =J16/J$6 -> 0.048352983 | ... N17: =N16/N$6 -> 0.042163051 | P17: =P16/P$6 -> 0.040504397 | Q17: =Q16/Q$6 -> 0.046277514 | R17: =R16/R$6 -> 0.043832781
B18: 벙커링 | C18: 1661 | D18: 1777 | E18: 1812 | F18: 1806 | G18: 1914 | H18: 1829 | I18: {=Bunkering!I6:N6} -> 1603.8407 | J18: 1635.8121 | K18: 1597.8636 | L18: 1606.5968 | M18: 1610.5046 | N18: 1604.9799 | P18: =SUM(C18:F18) -> 7056 | Q18: =SUM(G18:J18) -> 6982.6528 | R18: =SUM(K18:N18) -> 6419.945
B19: of Revenue(%) | C19: =C18/C$6 -> 0.43368146 | D19: =D18/D$6 -> 0.40584197 | E19: =E18/E$6 -> 0.39283579 | F19: =F18/F$6 -> 0.38975087 | G19: =G18/G$6 -> 0.39415333 | H19: =H18/H$6 -> 0.39104461 | I19: =I18/I$6 -> 0.34168854 | J19: =J18/J$6 -> 0.33847168 | ... N19: =N18/N$6 -> 0.29164526 | P19: =P18/P$6 -> 0.4042419 | Q19: =Q18/Q$6 -> 0.36635119 | R19: =R18/R$6 -> 0.30325162

Sheet AM
A1: HD현대마린솔루션(443060.KS)
A2: AM Solution Revenue Estimation Sheet
A3: (units in Hundred Millions KRW )
B5: 단위: 억 원 | C5: 2021A | D5: 2022A | E5: 2023A | F5: 2024A | G5: 1Q25 | H5: 2Q25 | I5: 3Q25E | J5: 4Q25E | K5: 1Q26E | L5: 2Q26E | M5: 3Q26E | N5: 4Q26E | P5: Description
B6: AM 솔루션 매출 | C6: =C8+C16+C18+C20 -> 3187.8931 | D6: =D8+D16+D18+D20 -> 4176.0573 | E6: =E8+E16+E18+E20 -> 5652.8282 | F6: =F8+F16+F18+F20 -> 8058 | G6: =G8+G16+G18+G20 -> 2161 | H6: =H8+H16+H18+H20 -> 2300 | I6: =I8+I16+I18+I20 -> 2468.1269 | J6: =J8+J16+J18+J20 -> 2567.3591 | ... N6: =N8+N16+N18+N20 -> 2958.9873 | P6: AM 솔루션 부문 매출의 경우, 엔진, 비엔진, 육상발전, 스마트케어 부문 매출로 구분하여 추정함.
B7: YoY(%) or QoQ(%) | C7: - | D7: =(D6-C6)/C6 -> 0.30997408 | E7: =(E6-D6)/D6 -> 0.35362804 | F7: =(F6-E6)/E6 -> 0.42548113 | G7: - | H7: =(H6-G6)/G6 -> 0.064322073 | I7: =(I6-H6)/H6 -> 0.073098645 | J7: =(J6-I6)/I6 -> 0.040205495 | K7: =(K6-J6)/J6 -> 0.03925851 | L7: =(L6-K6)/K6 -> 0.035520722 | M7: =(M6-L6)/L6 -> 0.035046366 | N7: =(N6-M6)/M6 -> 0.034699629
B8: 엔진 | C8: =D8/(1+D9) -> 1373.0093 | D8: =E8/(1+E9) -> 2045.5467 | E8: =F8/(1+F9) -> 3205.4954 | F8: =매출추정!P10 -> 5323 | G8: 1572 | H8: 1568 | I8: =I10+I13 -> 1722.0397 | J8: =J10+J13 -> 1802.3473 | K8: =K10+K13 -> 1886.4 | L8: =L10+L13 -> 1974.3725 | M8: =M10+M13 -> 2066.4477 | N8: =N10+N13 -> 2162.8167
B9: of AM Solution Revenue(%) | C9: =C8/C$6 -> 0.43069491 | D9: =D8/D$6 -> 0.48982727 | E9: =E8/E$6 -> 0.56706046 | F9: =F8/F$6 -> 0.66058575 | G9: =G8/G$6 -> 0.727441 | H9: =H8/H$6 -> 0.68173913 | I9: =I8/I$6 -> 0.69771118 | J9: =J8/J$6 -> 0.70202382 | ... N9: =N8/N$6 -> 0.73093139
B10: 2행정 엔진 매출 | G10: 572 | H10: =AVERAGE(G10,I10)-79/2 -> 559.7973 | I10: =I12*I22 -> 626.59461 | J10: =J12*J22 -> 655.81593 | K10: =K12*K22 -> 686.4 | L10: =L12*L22 -> 718.41036 | M10: =M12*M22 -> 751.91353 | N10: =N12*N22 -> 786.97912
B11: of AM Solution Revenue(%) | G11: =G10/G$6 -> 0.26469227 | H11: =H10/H$6 -> 0.24339013 | I11: =I10/I$6 -> 0.25387455 | J11: =J10/J$6 -> 0.25544378 | K11: =K10/K$6 -> 0.25725692 | L11: =L10/L$6 -> 0.2600181 | M11: =M10/M$6 -> 0.26292936 | N11: =N10/N$6 -> 0.26596231
B12: 2행정 엔진 대수 | G12: =$C$33 -> 137.375 | H12: =$C$33 -> 137.375 | I12: =$C$33 -> 137.375 | J12: =$C$33 -> 137.375 | K12: =$C$33 -> 137.375 | L12: =$C$33 -> 137.375 | M12: =$C$33 -> 137.375 | N12: =$C$33 -> 137.375
B13: 4행정 엔진 매출 | G13: 1000 | H13: =AVERAGE(G13,I13)-79/2 -> 1008.2226 | I13: =I15*I24 -> 1095.4451 | J13: =J15*J24 -> 1146.5314 | K13: =K15*K24 -> 1200 | L13: =L15*L24 -> 1255.9622 | M13: =M15*M24 -> 1314.5341 | N13: =N15*N24 -> 1375.8376
B14: of AM Solution Revenue(%) | G14: =G13/G$6 -> 0.46274873 | H14: =H13/H$6 -> 0.43835763 | I14: =I13/I$6 -> 0.44383663 | J14: =J13/J$6 -> 0.44658004 | K14: =K13/K$6 -> 0.44974985 | L14: =L13/L$6 -> 0.45457709 | M14: =M13/M$6 -> 0.45966671 | N14: =N13/N$6 -> 0.46496908
B15: 4행정 엔진 대수 | G15: =$C$42 -> 72 | H15: =$C$42 -> 72 | I15: =$C$42 -> 72 | J15: =$C$42 -> 72 | K15: =$C$42 -> 72 | L15: =$C$42 -> 72 | M15: =$C$42 -> 72 | N15: =$C$42 -> 72
B16: 비엔진 | C16: =D16/(1+D17) -> 713.75122 | D16: =E16/(1+E17) -> 860.89039 | E16: =F16/(1+F17) -> 1015.5527 | F16: =매출추정!P11 -> 1162 | G16: 281 | H16: 283 | I16: =((H16-$F$16/4)/$F$16+1)*H16 -> 281.17341 | J16: =((I16-$F$16/4)/$F$16+1)*I16 -> 278.91662 | K16: =((J16-SUM(G16:J16)/4)/SUM(G16:J16)+1)*J16 -> 278.39409 | L16: =((K16-SUM(H16:K16)/4)/SUM(H16:K16)+1)*K16 -> 277.90334 | M16: =((L16-SUM(I16:L16)/4)/SUM(I16:L16)+1)*L16 -> 277.60624 | N16: =((M16-SUM(J16:M16)/4)/SUM(J16:M16)+1)*M16 -> 277.45685 | P16: 비엔진 부문 매출의 경우, 직전 2Y와 직전 2Q 모두 큰 변동성이 존재하지 않고, 동사의 향후 사업 성장여력이 제한된다고 판단됨.
B17: of AM Solution Revenue(%) | C17: =C16/C$6 -> 0.22389434 | D17: =D16/D$6 -> 0.20614908 | E17: =E16/E$6 -> 0.17965391 | F17: =F16/F$6 -> 0.14420452 | G17: =G16/G$6 -> 0.13003239 | H17: =H16/H$6 -> 0.12304348 | I17: =I16/I$6 -> 0.11392178 | J17: =J16/J$6 -> 0.1086395 | ... N17: =N16/N$6 -> 0.093767501 | P17: 따라서, 직전년 분기별 평균 매출에 추정 분기의 성장세를 반영하여 추정함.
B18: 육상발전 | C18: =D18/(1+D19) -> 508.91502 | D18: =E18/(1+E19) -> 579.54072 | E18: =F18/(1+F19) -> 645.74384 | F18: =매출추정!P12 -> 702 | G18: 89 | H18: 200 | I18: =((H18-$F$18/4)/$F$18+1)*H18 -> 206.98006 | J18: =((I18-$F$18/4)/$F$18+1)*I18 -> 216.26174 | K18: =((J18-SUM(G18:J18)/4)/SUM(G18:J18)+1)*J18 -> 227.861 | L18: =((K18-SUM(H18:K18)/4)/SUM(H18:K18)+1)*K18 -> 231.89971 | M18: =((L18-SUM(I18:L18)/4)/SUM(I18:L18)+1)*L18 -> 234.82775 | N18: =((M18-SUM(J18:M18)/4)/SUM(J18:M18)+1)*M18 -> 236.66213 | P18: 육상발전 부문 매출의 경우, 직전 2Y와 직전 2Q 모두 큰 변동성이 존재하지 않고, 동사의 향후 사업 성장여력이 제한된다고 판단됨.
B19: of AM Solution Revenue(%) | C19: =C18/C$6 -> 0.15963993 | D19: =D18/D$6 -> 0.138777 | E19: =E18/E$6 -> 0.11423376 | F19: =F18/F$6 -> 0.087118392 | G19: =G18/G$6 -> 0.041184637 | H19: =H18/H$6 -> 0.086956522 | I19: =I18/I$6 -> 0.08386119 | J19: =J18/J$6 -> 0.084235096 | ... N19: =N18/N$6 -> 0.079980785 | P19: 따라서, 직전년 분기별 평균 매출에 추정 분기의 성장세를 고려하여 추정함.
B20: 스마트케어 | C20: =D20/(1+D21) -> 592.2175 | D20: =E20/(1+E21) -> 690.07945 | E20: =F20/(1+F21) -> 786.03629 | F20: =매출추정!P13 -> 871 | G20: 219 | H20: 249 | I20: =((H20-$F$20/4)/$F$20+1)*H20 -> 257.9337 | J20: =((I20-$F$20/4)/$F$20+1)*I20 -> 269.8335 | K20: =((J20-SUM(G20:J20)/4)/SUM(G20:J20)+1)*J20 -> 275.49475 | L20: =((K20-SUM(H20:K20)/4)/SUM(H20:K20)+1)*K20 -> 278.74887 | M20: =((L20-SUM(I20:L20)/4)/SUM(I20:L20)+1)*L20 -> 280.87326 | N20: =((M20-SUM(J20:M20)/4)/SUM(J20:M20)+1)*M20 -> 282.05163 | P20: 스마트케어 부문 매출의 경우, 직전 2Y와 직전 2Q 모두 큰 변동성이 존재하지 않고, 동사의 향후 사업 성장여력이 제한된다고 판단됨.
B21: of AM Solution Revenue(%) | C21: =C20/C$6 -> 0.18577082 | D21: =D20/D$6 -> 0.16524664 | E21: =E20/E$6 -> 0.13905186 | F21: =F20/F$6 -> 0.10809134 | G21: =G20/G$6 -> 0.10134197 | H21: =H20/H$6 -> 0.10826087 | I21: =I20/I$6 -> 0.10450585 | J21: =J20/J$6 -> 0.10510158 | ... N21: =N20/N$6 -> 0.095320322 | P21: 따라서, 직전년 분기별 평균 매출에 추정 분기의 성장세를 고려하여 추정함.
B22: 2행정 ASP | G22: =C35 -> 4.1637853 | H22: =G22*(1+$O$22) -> 4.357964 | I22: =H22*(1+$O$22) -> 4.5611982 | J22: =I22*(1+$O$22) -> 4.7739103 | K22: =J22*(1+$O$22) -> 4.9965423 | L22: =K22*(1+$O$22) -> 5.2295568 | M22: =L22*(1+$O$22) -> 5.4734379 | N22: =M22*(1+$O$22) -> 5.7286924 | O22: =1.2^0.25-1 -> 0.046635139 | P22: AM 서비스 선박 ASP의 경우, 동사가 컨퍼런스콜에서 발표한 연간 단가 상승률 20%를 분기 가중평균 계산하여 적용함.
B23: YoY(%) | G23: - | H23: =(H22-G22)/G22 -> 0.046635139 | I23: =(I22-H22)/H22 -> 0.046635139 | J23: =(J22-I22)/I22 -> 0.046635139 | K23: =(K22-J22)/J22 -> 0.046635139 | L23: =(L22-K22)/K22 -> 0.046635139 | M23: =(M22-L22)/L22 -> 0.046635139 | N23: =(N22-M22)/M22 -> 0.046635139
B24: 4행정 ASP | G24: =C44 -> 13.888889 | H24: =G24*(1+$O$22) -> 14.536599 | I24: =H24*(1+$O$22) -> 15.214515 | J24: =I24*(1+$O$22) -> 15.924047 | K24: =J24*(1+$O$22) -> 16.666667 | L24: =K24*(1+$O$22) -> 17.443919 | M24: =L24*(1+$O$22) -> 18.257419 | N24: =M24*(1+$O$22) -> 19.108856 | P24: AM 서비스 선박 ASP의 경우, 동사가 컨퍼런스콜에서 발표한 연간 단가 상승률 20%를 분기 가중평균 계산하여 적용함.
B25: YoY(%) | G25: - | H25: =(H24-G24)/G24 -> 0.046635139 | I25: =(I24-H24)/H24 -> 0.046635139 | J25: =(J24-I24)/I24 -> 0.046635139 | K25: =(K24-J24)/J24 -> 0.046635139 | L25: =(L24-K24)/K24 -> 0.046635139 | M25: =(M24-L24)/L24 -> 0.046635139 | N25: =(N24-M24)/M24 -> 0.046635139
C28: 2005 | D28: 2006 | E28: 2007 | F28: 2008 | G28: 2009 | H28: 2010 | I28: 2011 | J28: 2012 | K28: 2013 | L28: 2014 | M28: 2015 | N28: 2016 | O28: 2017 | P28: 2018 | Q28: 2019 | R28: 2020 | S28: 2021 | T28: 2022 | U28: 2023 | V28: 2024 | W28: 2025 | X28: Total
B29: HD 조선 3사 2행정 연도별 선박 대수 | C29: 140 | D29: 152 | E29: 160 | F29: 186 | G29: 197 | H29: 175 | I29: 220 | J29: 203 | K29: 163 | L29: 148 | M29: 183 | N29: 167 | O29: 131 | P29: 100 | Q29: 145 | R29: 128 | S29: 128 | T29: 131 | U29: 130 | V29: 144 | W29: 102 | X29: 3233
B31: '25~'26년 AM 선박 예상 대수 | C31: =(C29+G29+H29+L29+M29+R29+S29) -> 1099 | E31: '25~'26년, 총 8개 분기간 '05년, '09년, '10년, '14년, '15년, '20년, '21년 인도된 2행정 선박들의 점검이 균등하게 이루어질 것으로 추정함.
B32: 선박당 2행정 탑재 수 | C32: 1 | E32: 선박당 2행정 엔진 탑재 수는 1대로 전제함.
B33: 분기당 AM 선박 예상 대수 | C33: =C31*C32/8 -> 137.375 | E33: 선박들의 정기 점검이 약 4~5년 주기로 진행된다는 점 참고.
B34: 1Q25 매출액(억 원) | C34: 572 | E34: 동사의 1Q25 컨퍼런스 콜 내용을 참고함.
B35: 2행정 엔진 AM ASP | C35: =C34/C33 -> 4.1637853 | E35: 1Q25 2행정 부문 매출액을 분기당 AM 선박 예상 대수로 나누어 2행정 엔진 AM ASP를 추정함.
C37: 2005 | D37: 2006 | E37: 2007 | F37: 2008 | G37: 2009 | H37: 2010 | I37: 2011 | J37: 2012 | K37: 2013 | L37: 2014 | M37: 2015 | N37: 2016 | O37: 2017 | P37: 2018 | Q37: 2019 | R37: 2020 | S37: 2021 | T37: 2022 | U37: 2023 | V37: 2024 | W37: 2025 | X37: Total
B38: HD 조선 3사 4행정 연도별 선박 대수 | C38: 2 | D38: 2 | E38: 1 | F38: 5 | G38: 21 | H38: 20 | I38: 20 | J38: 8 | K38: 17 | L38: 24 | M38: 15 | N38: 7 | O38: 5 | P38: 10 | Q38: 7 | R38: 8 | S38: 6 | T38: 6 | U38: 10 | V38: 6 | W38: 1 | X38: 201
B40: '25~'26년 AM 선박 예상 대수 | C40: =(C38+G38+H38+L38+M38+R38+S38) -> 96 | E40: '25~'26년, 총 8개 분기간 '05년, '09년, '10년, '14년, '15년, '20년, '21년 인도된 4행정 선박들의 점검이 균등하게 이루어질 것으로 추정함.
B41: 선박당 4행정 탑재 수 | C41: 6 | E41: 선박당 4행정 엔진 탑재 수는 6대로 전제함.
B42: 분기당 AM 선박 예상 대수 | C42: =C40*C41/8 -> 72 | E42: 선박들의 정기 점검이 약 4~5년 주기로 진행된다는 점 참고.
B43: 1Q25 매출액(억 원) | C43: 1000 | E43: 동사의 1Q25 컨퍼런스 콜 내용을 참고함.
B44: 4행정 엔진 AM ASP | C44: =C43/C42 -> 13.888889 | E44: 1Q25 4행정 부문 매출액을 분기당 AM 선박 예상 대수로 나누어 4행정 엔진 AM ASP를 추정함.
C47: 2005 | D47: 2006 | E47: 2007 | F47: 2008 | G47: 2009 | H47: 2010 | I47: 2011 | J47: 2012 | K47: 2013 | L47: 2014 | M47: 2015 | N47: 2016 | O47: 2017 | P47: 2018 | Q47: 2019 | R47: 2020 | S47: 2021 | T47: 2022 | U47: 2023 | V47: 2024 | W47: 2025 | X47: Total
B48: HD 조선 3사 2행정 연도별 선박 대수 | C48: 140 | D48: 152 | E48: 160 | F48: 186 | G48: 197 | H48: 175 | I48: 220 | J48: 203 | K48: 163 | L48: 148 | M48: 183 | N48: 167 | O48: 131 | P48: 100 | Q48: 145 | R48: 128 | S48: 128 | T48: 131 | U48: 130 | V48: 144 | W48: 102 | X48: 3233
...

Sheet Retrofit
A1: HD현대마린솔루션(443060.KS)
A2: Retrofit Revenue Estimation Sheet
A3: (units in Hundred Millions KRW & Millions USD)
B5: 단위: 억 원 | C5: 2021A | D5: 2022A | E5: 2023A | F5: 2024A | G5: 1Q25 | H5: 2Q25 | I5: 3Q25E | J5: 4Q25E | K5: 1Q26E | L5: 2Q26E | M5: 3Q26E | N5: 4Q26E | P5: Description
B6: 친환경 솔루션 매출 | C6: 1530 | D6: 1940 | E6: 1690 | F6: =매출추정!P14 -> 1635 | G6: =매출추정!G14 -> 583 | H6: =매출추정!H14 -> 328 | I6: =I8+I16+I22+I24+I26 -> 391.53745 | J6: =J8+J16+J22+J24+J26 -> 396.0782 | K6: =K8+K16+K22+K24+K26 -> 589.45501 | L6: =L8+L16+L22+L24+L26 -> 590.7023 | M6: =M8+M16+M22+M24+M26 -> 685.28887 | N6: =N8+N16+N22+N24+N26 -> 707.19361 | P6: 친환경 솔루션 부문 매출의 경우, LNGC 부문 매출, 엔진 개조 부문 매출, 기타 매출, BWTS, EGCS 부문 매출로 구분하여 추정함.
B7: YoY(%) or QoQ(%) | C7: - | D7: =(D6-C6)/C6 -> 0.26797386 | E7: =(E6-D6)/D6 -> -0.12886598 | F7: =(F6-E6)/E6 -> -0.032544379 | G7: - | H7: =(H6-G6)/G6 -> -0.4373928 | I7: =(I6-H6)/H6 -> 0.19371173 | J7: =(J6-I6)/I6 -> 0.011597227 | K7: =(K6-J6)/J6 -> 0.48822889 | L7: =(L6-K6)/K6 -> 0.0021159973 | M7: =(M6-L6)/L6 -> 0.16012562 | N7: =(N6-M6)/M6 -> 0.03196424
B8: LNGC | I8: =I10+I14+I12 -> 185.29333 | J8: =J10+J14+J12 -> 187.44222 | K8: =K10+K14+K12 -> 446.43967 | L8: =L10+L14+L12 -> 446.6699 | M8: =M10+M14+M12 -> 471.45383 | N8: =N10+N14+N12 -> 493.96858 | P8: LNGC 부문 매출의 경우, 재액화, FSRU, FSU로 구분하여 추정함.
B9: YoY(%) or QoQ(%) | I9: - | J9: =(J8-I8)/I8 -> 0.011597227 | K9: =(K8-J8)/J8 -> 1.3817455 | L9: =(L8-K8)/K8 -> 0.00051571953 | M9: =(M8-L8)/L8 -> 0.055486006 | N9: =(N8-M8)/M8 -> 0.047755989
B10: 재액화 | I10: =I35*'환율&원유'!I7/100 -> 162.13167 | J10: =J35*'환율&원유'!J7/100 -> 164.01194 | K10: =K35*'환율&원유'!K7/100 -> 184.40074 | L10: =L35*'환율&원유'!L7/100 -> 208.92611 | M10: =M35*'환율&원유'!M7/100 -> 232.31461 | N10: =N35*'환율&원유'!N7/100 -> 231.65189 | P10: 재액화 부문 수주 잔고에서 매출로 전환되는 금액에 환율을 고려하여 추정함.
B11: of Retrofit Revenue(%) | I11: =I10/I$6 -> 0.41408981 | J11: =J10/J$6 -> 0.41408981 | K11: =K10/K$6 -> 0.31283259 | L11: =L10/L$6 -> 0.35369104 | M11: =M10/M$6 -> 0.33900245 | N11: =N10/N$6 -> 0.32756502
B12: FSU | I12: =I37*'환율&원유'!I7/100 -> 23.161667 | J12: =J37*'환율&원유'!J7/100 -> 23.430278 | K12: =K37*'환율&원유'!K7/100 -> 23.050093 | L12: =L37*'환율&원유'!L7/100 -> 46.428025 | M12: =M37*'환율&원유'!M7/100 -> 46.462922 | N12: =N37*'환율&원유'!N7/100 -> 69.495566 | P12: FSU 부문 수주 잔고에서 매출로 전환되는 금액에 환율을 고려하여 추정함.
B13: of Retrofit Revenue(%) | I13: =I12/I$6 -> 0.059155687 | J13: =J12/J$6 -> 0.059155687 | K13: =K12/K$6 -> 0.039104074 | L13: =L12/L$6 -> 0.078598009 | M13: =M12/M$6 -> 0.067800491 | N13: =N12/N$6 -> 0.098269505
B14: FSRU | I14: 0 | J14: 0 | K14: =K39*'환율&원유'!J7/100 -> 238.98883 | L14: =L39*'환율&원유'!K7/100 -> 191.31577 | M14: =M39*'환율&원유'!L7/100 -> 192.6763 | N14: =N39*'환율&원유'!M7/100 -> 192.82113 | P14: FSRU 부문 수주 잔고에서 매출로 전환되는 금액에 환율을 고려하여 추정함.
B15: of Retrofit Revenue(%) | I15: =I14/I$6 -> 0 | J15: =J14/J$6 -> 0 | K15: =K14/K$6 -> 0.40544033 | L15: =L14/L$6 -> 0.32387849 | M15: =M14/M$6 -> 0.28116071 | N15: =N14/N$6 -> 0.27265677
B16: 엔진 개조 | I16: =I20+I18 -> 74.222614 | J16: =J20+J18 -> 75.08339 | K16: =K20+K18 -> 73.865069 | L16: =L20+L18 -> 74.390358 | M16: =M20+M18 -> 144.14066 | N16: =N20+N18 -> 143.72947 | P16: 엔진 개조 부문 매출의 경우, EPLO, D/F로 구분하여 추정함.
B17: YoY(%) or QoQ(%) | I17: - | J17: =(J16-I16)/I16 -> 0.011597227 | K17: =(K16-J16)/J16 -> -0.016226235 | L17: =(L16-K16)/K16 -> 0.0071114575 | M17: =(M16-L16)/L16 -> 0.93762551 | N17: =(N16-M16)/M16 -> -0.0028526958
B18: EPLO | I18: =I43*'환율&원유'!I7/100 -> 74.222614 | J18: =J43*'환율&원유'!J7/100 -> 75.08339 | K18: =K43*'환율&원유'!K7/100 -> 73.865069 | L18: =L43*'환율&원유'!L7/100 -> 74.390358 | M18: =M43*'환율&원유'!M7/100 -> 74.446272 | N18: =N43*'환율&원유'!N7/100 -> 74.2339 | P18: EPLO 부문 수주 잔고에서 매출로 전환되는 금액에 환율을 고려하여 추정함.
B19: of Retrofit Revenue(%) | I19: =I18/I$6 -> 0.18956709 | J19: =J18/J$6 -> 0.18956709 | K19: =K18/K$6 -> 0.12531078 | L19: =L18/L$6 -> 0.12593545 | M19: =M18/M$6 -> 0.10863488 | N19: =N18/N$6 -> 0.1049697
B20: D/F | I20: 0 | J20: 0 | K20: 0 | L20: 0 | M20: =M45*'환율&원유'!M7/100 -> 69.694383 | N20: =N45*'환율&원유'!N7/100 -> 69.495566 | P20: D/F 부문 수주 잔고에서 매출로 전환되는 금액에 환율을 고려하여 추정함.
B21: of Retrofit Revenue(%) | I21: =I20/I$6 -> 0 | J21: =J20/J$6 -> 0 | K21: =K20/K$6 -> 0 | L21: =L20/L$6 -> 0 | M21: =M20/M$6 -> 0.10170074 | N21: =N20/N$6 -> 0.098269505
B22: 기타 | I22: =I47*'환율&원유'!I7/100 -> 69.485 | J22: =J47*'환율&원유'!J7/100 -> 70.290833 | K22: =K47*'환율&원유'!K7/100 -> 69.150278 | L22: =L47*'환율&원유'!L7/100 -> 69.642037 | M22: =M47*'환율&원유'!M7/100 -> 69.694383 | N22: =N47*'환율&원유'!N7/100 -> 69.495566 | P22: 기타 부문 수주 잔고에서 매출로 전환되는 금액에 환율을 고려하여 추정함.
B23: of Retrofit Revenue(%) | I23: =I22/I$6 -> 0.17746706 | J23: =J22/J$6 -> 0.17746706 | K23: =K22/K$6 -> 0.11731222 | L23: =L22/L$6 -> 0.11789701 | M23: =M22/M$6 -> 0.10170074 | N23: =N22/N$6 -> 0.098269505
B24: BWTS | I24: =I49*'환율&원유'!I14/100 -> 0 | J24: =J49*'환율&원유'!J14/100 -> 0 | K24: =K49*'환율&원유'!K14/100 -> 0 | L24: =L49*'환율&원유'!L14/100 -> 0 | M24: =M49*'환율&원유'!M14/100 -> 0 | N24: =N49*'환율&원유'!N14/100 -> 0 | P24: BWTS 부문 수주 잔고에서 매출로 전환되는 금액에 환율을 고려하여 추정함.
B25: of Retrofit Revenue(%) | I25: =I24/I$6 -> 0 | J25: =J24/J$6 -> 0 | K25: =K24/K$6 -> 0 | L25: =L24/L$6 -> 0 | M25: =M24/M$6 -> 0 | N25: =N24/N$6 -> 0
B26: EGCS | I26: =I51*'환율&원유'!I7/100 -> 62.5365 | J26: =J51*'환율&원유'!J7/100 -> 63.26175 | K26: =K51*'환율&원유'!K7/100 -> 0 | L26: =L51*'환율&원유'!L7/100 -> 0 | M26: =M51*'환율&원유'!M7/100 -> 0 | N26: =N51*'환율&원유'!N7/100 -> 0 | P26: EGCS 부문 수주 잔고에서 매출로 전환되는 금액에 환율을 고려하여 추정함.
B27: of Retrofit Revenue(%) | I27: =I26/I$6 -> 0.15972035 | J27: =J26/J$6 -> 0.15972035 | K27: =K26/K$6 -> 0 | L27: =L26/L$6 -> 0 | M27: =M26/M$6 -> 0 | N27: =N26/N$6 -> 0
B30: 단위: Mn $ | C30: 2021A | D30: 2022A | E30: 2023A | F30: 2024A | G30: 1Q25 | H30: 2Q25 | I30: 3Q25E | J30: 4Q25E | K30: 1Q26E | L30: 2Q26E | M30: 3Q26E | N30: 4Q26E | Q30: 수주 추정 Logic
B31: 친환경 솔루션 수주 잔고 | C31: 108 | D31: 82 | E31: 106 | F31: 125 | G31: 98 | H31: 146 | I31: =I48+I50+I33+I41+I46 -> 138.35417 | J31: =J48+J50+J33+J41+J46 -> 239.70833 | K31: =K48+K50+K33+K41+K46 -> 257.39583 | L31: =L48+L50+L33+L41+L46 -> 259.91667 | M31: =M48+M50+M33+M41+M46 -> 275.77083 | N31: =N48+N50+N33+N41+N46 -> 374.95833 | Q31: 수주 잔고의 경우, 매출 부문과 동일한 기준으로 구분함.
B32: YoY(%) or QoQ(%) | C32: - | D32: =(D31-C31)/C31 -> -0.24074074 | E32: =(E31-D31)/D31 -> 0.29268293 | F32: =(F31-E31)/E31 -> 0.17924528 | G32: - | H32: =(H31-G31)/G31 -> 0.48979592 | I32: =(I31-H31)/H31 -> -0.052368721 | J32: =(J31-I31)/I31 -> 0.7325704 | K32: =(K31-J31)/J31 -> 0.073787589 | L32: =(L31-K31)/K31 -> 0.0097936058 | M32: =(M31-L31)/L31 -> 0.060997114 | N32: =(N31-M31)/M31 -> 0.35967364
B33: LNGC 수주 잔고 | C33: 0 | D33: 0 | E33: 62 | F33: 118 | G33: 97 | H33: =H34+H36+H38 -> 80 | I33: =I34+I36+I38 -> 66.666667 | J33: =J34+J36+J38 -> 153.33333 | K33: =K34+K36+K38 -> 156.33333 | L33: =L34+L36+L38 -> 144.16667 | M33: =M34+M36+M38 -> 145.33333 | N33: =N34+N36+N38 -> 229.83333
B34: 재액화 | D34: 현재 7척 수주 잔고 | H34: 70 | I34: =H34-I35 -> 58.333333 | J34: =I34-J35 -> 46.666667 | K34: =J34+2*$P$35-K35 -> 53.333333 | L34: =K34+2*$P$35-L35 -> 58.333333 | M34: =L34+2*$P$35-M35 -> 61.666667 | N34: =M34+2*$P$35-N35 -> 65 | O34: 연간 재액화 Full CAPA(척) | P34: 10 | Q34: 동사의 재액화 CAPA는 충분하나, 선주들의 환경 규제 대비가 본격 개시되는 '26년부터 분기당 2척씩 수주할 것으로 추정함. 보유 중인 수주는 Full CAPA로 소진될 것으로 추정함.
B35: 매출 전환 | D35: 표준 공기 1.5년(6Q) | I35: =$P$35/6*7 -> 11.666667 | J35: =$P$35/6*7 -> 11.666667 | K35: =$P$35/6*8 -> 13.333333 | L35: =$P$35/6*9 -> 15 | M35: =$P$35/6*10 -> 16.666667 | N35: =$P$35/6*10 -> 16.666667 | O35: 재액화 ASP(Mn $) | P35: 10 | Q35: 2Q25 기준, 수주 잔고를 수주 척수로 나누어 ASP를 계산함. IR측 재액화 ASP 답변과 단가가 유사하므로 합리적이라 판단됨.
B36: FSU | D36: 현재 1척 수주 잔고 | H36: 10 | I36: =H36-I37 -> 8.3333333 | J36: =I36-J37 -> 6.6666667 | K36: =J36-K37+$P$37*$P$36/2 -> 20 | L36: =K36-L37 -> 16.666667 | M36: =L36-M37+$P$37*$P$36/2 -> 28.333333 | N36: =M36-N37 -> 23.333333 | O36: 연간 FSU Full CAPA(척) | P36: 3 | Q36: 동사의 엔지니어링 설비 관련 제한사항으로, 연간 FSU Full CAPA는 3척으로 확인됨.
B37: 매출 전환 | D37: 표준 공기 1.5년(6Q) | I37: =$H$36/6 -> 1.6666667 | J37: =$H$36/6 -> 1.6666667 | K37: =$H$36/6 -> 1.6666667 | L37: =$H$36/6*2 -> 3.3333333 | M37: =$H$36/6*2 -> 3.3333333 | N37: =$H$36/6*3 -> 5 | O37: FSU ASP(Mn $) | P37: 10 | Q37: 동사의 FSU Full CAPA와 관련 파이프라인 및 에너지 수요를 반영하여, 반기당 1척(1천만 불)씩 수주할 것으로 추정함. ASP의 경우 IR측 답변을 참고함.
B38: FSRU | D38: 4Q25 1척 수주 전망 | J38: =$P$38/2*$P$39 -> 100 | K38: =J38-K39 -> 83 | L38: =K38-L39 -> 69.166667 | M38: =L38-M39 -> 55.333333 | N38: =M38-N39+$P$38/2*$P$39 -> 141.5 | O38: 연간 FSRU Full CAPA(척) | P38: 2 | Q38: 동사의 설비 내 재기화 장치 관련 제한사항으로, 연간 FSRU Full CAPA는 2척으로 확인됨.
B39: 매출 전환 | D39: 표준 공기 1.5년(6Q) | K39: 17 | L39: =$K$38/6 -> 13.833333 | M39: =$K$38/6 -> 13.833333 | N39: =$K$38/6 -> 13.833333 | O39: FSRU ASP(Mn $) | P39: 100 | Q39: '26년에는 1척 수주 후, '27년부터는 Full CAPA가 가동될 것으로 전망함. ASP의 경우, IR측 답변을 참고함.
B40: 엔진 개조 수주 잔고 | C40: 0 | D40: 0 | E40: 62 | F40: 118 | G40: 97 | H40: =H44+H41 -> 47 | I40: =I44+I41 -> 61.6875 | J40: =J44+J41 -> 76.375 | K40: =K44+K41 -> 91.0625 | L40: =L44+L41 -> 105.75 | M40: =M44+M41 -> 150.4375 | N40: =N44+N41 -> 160.125
B41: EPLO | D41: 현재 88척 수주 잔고 | H41: 47 | I41: =H41-I43+$P$42*150/4 -> 61.6875 | J41: =I41-J43+$P$42*150/4 -> 76.375 | K41: =J41-K43+$P$42*150/4 -> 91.0625 | L41: =K41-L43+$P$42*150/4 -> 105.75 | M41: =L41-M43+$P$42*150/4 -> 120.4375 | N41: =M41-N43+$P$42*150/4 -> 135.125 | O41: 연간 EPLO Full CAPA(척) | P41: 40 | Q41: 엔진 Retrofit 관련 동사의 집중 사업부이므로, '25년 수주 목표 150척이 '26년에도 동일할 것으로 전제하고 이를 분기로 나눠 수주 잔고를 추정함.
B42: 선박수(척) | D42: 표준 공기 6개월(2Q) | H42: 88 | I42: =H42-$P$41/4+30 -> 108 | J42: =I42-$P$41/4+30 -> 128 | K42: =J42-$P$41/4+30 -> 148 | L42: =K42-$P$41/4+30 -> 168 | M42: =L42-$P$41/4+30 -> 188 | N42: =M42-$P$41/4+30 -> 208 | O42: EPLO ASP(Mn $) | P42: =H41/H42 -> 0.53409091 | Q42: 2Q25 기준, 수주 잔고를 수주 척수로 나누어 ASP를 계산함. IR측 EPLO ASP 답변과 단가가 유사하므로 합리적이라 판단됨.
B43: 매출 전환 | D43: 연간 150척 수주 목표 | I43: =$P$41/4*$P$42 -> 5.3409091 | J43: =$P$41/4*$P$42 -> 5.3409091 | K43: =$P$41/4*$P$42 -> 5.3409091 | L43: =$P$41/4*$P$42 -> 5.3409091 | M43: =$P$41/4*$P$42 -> 5.3409091 | N43: =$P$41/4*$P$42 -> 5.3409091 | O43: 분기당 EPLO 수주(척) | P43: =150/4 -> 37.5 | Q43: 동사의 EPLO 연간 수주 목표인 150척을 분기로 나누어 계산함.
...

Sheet Digital
A1: HD현대마린솔루션(443060.KS)
A2: Digital Soultion Revenue Estimation Sheet
A3: (units in Hundred Millions KRW & Millions USD)
B5: 단위: 억 원 | C5: 2021A | D5: 2022A | E5: 2023A | F5: 2024A | G5: 1Q25 | H5: 2Q25 | I5: 3Q25E | J5: 4Q25E | K5: 1Q26E | L5: 2Q26E | M5: 3Q26E | N5: 4Q26E | P5: Description
B6: 디지털 솔루션 매출 | C6: =D6/(1+D7) -> 487.30777 | D6: =E6/(1+E7) -> 453.68353 | E6: =F6/(1+F7) -> 622.90749 | F6: 707 | G6: =매출추정!G16 -> 198 | H6: =매출추정!H16 -> 220 | I6: =I8+I10+I12 -> 230.36244 | J6: =J8+J10+J12 -> 233.68689 | K6: =K8+K10+K12 -> 230.90576 | L6: =L8+L10+L12 -> 232.45384 | M6: =M8+M10+M12 -> 232.56465 | N6: =N8+N10+N12 -> 232.03138 | P6: 디지털 솔루션의 경우, 주요 제품인 Shaft Generator, 그 외 수주가 전환됨에 따라 인식되는 매출, 기타 매출로 구분하여 추정함.
B7: YoY(%) or QoQ(%) | C7: - | D7: -0.069 | E7: 0.373 | F7: 0.135 | G7: - | H7: =(H6-G6)/G6 -> 0.11111111 | I7: =(I6-H6)/H6 -> 0.047101978 | J7: =(J6-I6)/I6 -> 0.014431394 | K7: =(K6-J6)/J6 -> -0.011901082 | L7: =(L6-K6)/K6 -> 0.0067043649 | M7: =(M6-L6)/L6 -> 0.00047671057 | N7: =(N6-M6)/M6 -> -0.0022929968
B8: Shaft Generator | H8: =H19 -> 100.72558 | I8: =I19 -> 103.41953 | J8: =J19 -> 104.61891 | K8: =K19 -> 102.92134 | L8: =L19 -> 103.65326 | M8: =M19 -> 103.73117 | N8: =N19 -> 103.43526
B9: of Retrofit Revenue(%) | I9: =I8/I$6 -> 0.44894271 | J9: =J8/J$6 -> 0.44768843 | K9: =K8/K$6 -> 0.44572879 | L9: =L8/L$6 -> 0.44590903 | M9: =M8/M$6 -> 0.44603156 | N9: =N8/N$6 -> 0.44578135
B10: 그외 수주 전환 매출 | H10: =H21*'환율&원유'!H7/100 -> 67.675 | I10: =I21*'환율&원유'!I7/100 -> 75.343482 | J10: =J21*'환율&원유'!J7/100 -> 77.468553 | K10: =K21*'환율&원유'!K7/100 -> 76.384997 | L10: =L21*'환율&원유'!L7/100 -> 77.201153 | M10: =M21*'환율&원유'!M7/100 -> 77.234056 | N10: =N21*'환율&원유'!N7/100 -> 76.9967
B11: of Retrofit Revenue(%) | I11: =I10/I$6 -> 0.32706496 | J11: =J10/J$6 -> 0.33150578 | K11: =K10/K$6 -> 0.33080594 | L11: =L10/L$6 -> 0.33211391 | M11: =M10/M$6 -> 0.33209715 | N11: =N10/N$6 -> 0.33183744
B12: 기타 | H12: =H6-H8-H10 -> 51.599419 | I12: =H12 -> 51.599419 | J12: =I12 -> 51.599419 | K12: =J12 -> 51.599419 | L12: =K12 -> 51.599419 | M12: =L12 -> 51.599419 | N12: =M12 -> 51.599419
B13: of Retrofit Revenue(%) | I13: =I12/I$6 -> 0.22399233 | J13: =J12/J$6 -> 0.22080579 | K13: =K12/K$6 -> 0.22346527 | L13: =L12/L$6 -> 0.22197706 | M13: =M12/M$6 -> 0.22187129 | N13: =N12/N$6 -> 0.22238121
B15: 단위: Mn $ | C15: 2021A | D15: 2022A | E15: 2023A | F15: 2024A | G15: 1Q25 | H15: 2Q25 | I15: 3Q25E | J15: 4Q25E | K15: 1Q26E | L15: 2Q26E | M15: 3Q26E | N15: 4Q26E | P15: *S/G는 Shaft Generator를 의미함. HD현대그룹의 신조 물량에 탑재되는 제품. 따라서 인도 예정 물량이 곧 S/G의 매출과 이어짐.
B16: 디지털 솔루션 수주 잔고 | C16: 65 | D16: 94 | E16: 112 | F16: 134 | G16: 140 | H16: 150 | I16: =H16+10 -> 160 | J16: =I16+10 -> 170 | K16: =J16+10 -> 180 | L16: =K16+10 -> 190 | M16: =L16+10 -> 200 | N16: =M16+10 -> 210 | P16: 디지털 솔루션 수주 잔고의 경우, HD현대그룹의 신조 인도 물량이 '26년까지 큰 변동성이 없다는 점을 고려하여 직전 분기 증가세를 Flat 적용함.
B17: S/G 수주 잔고 | G17: 59 | H17: 64 | I17: =H17+(I16-H16)*H8/H6 -> 68.578436 | J17: =I17+(J16-I16)*I8/I6 -> 73.067863 | K17: =J17+(K16-J16)*J8/J6 -> 77.544747 | L17: =K17+(L16-K16)*K8/K6 -> 82.002035 | M17: =L17+(M16-L16)*L8/L6 -> 86.461125 | N17: =M17+(N16-M16)*M8/M6 -> 90.921441 | P17: S/G 수주 잔고의 경우. 디지털 솔루션 수주 잔고의 증감(HD현대그룹의 신조 인도 물량)과 매우 유사하므로, 디지털 솔루션 수주 잔고에 직전 분기 매출 비중을 곱하여 향후 수주 잔고 증가세를 추정함.
B18: S/G 척수 | H18: 43 | I18: =H18+(I17-H17)/$O$23 -> 46.076136 | J18: =I18+(J17-I17)/$O$23 -> 49.09247 | K18: =J18+(K17-J17)/$O$23 -> 52.100377 | L18: =K18+(L17-K17)/$O$23 -> 55.095117 | M18: =L18+(M17-L17)/$O$23 -> 58.091068 | N18: =M18+(N17-M17)/$O$23 -> 61.087843 | P18: S/G의 선박 수의 경우, 직전 분기 대비 수주 증가분을 ASP로 나누어 선박수 증가세를 추정함.
B19: S/G 매출 | H19: =$O$23*5*'환율&원유'!H7/100 -> 100.72558 | I19: =$O$23*5*'환율&원유'!I7/100 -> 103.41953 | J19: =$O$23*5*'환율&원유'!J7/100 -> 104.61891 | K19: =$O$23*5*'환율&원유'!K7/100 -> 102.92134 | L19: =$O$23*5*'환율&원유'!L7/100 -> 103.65326 | M19: =$O$23*5*'환율&원유'!M7/100 -> 103.73117 | N19: =$O$23*5*'환율&원유'!N7/100 -> 103.43526 | P19: S/G 매출의 경우, 분기당 공사 가능한 선박 수에 ASP와 환율 전망치를 곱하여 추정함.
B20: S/G 제외 수주 잔고 | G20: =G16-G17 -> 81 | H20: =H16-H17 -> 86 | I20: =I16-I17 -> 91.421564 | J20: =J16-J17 -> 96.932137 | K20: =K16-K17 -> 102.45525 | L20: =L16-L17 -> 107.99797 | M20: =M16-M17 -> 113.53887 | N20: =N16-N17 -> 119.07856 | P20: 분기별 수주잔고 차이만큼, 수주가 매출로 전환될 것으로 추정함.
B21: S/G 제외 수주 전환액 | H21: =H20-G20 -> 5 | I21: =I20-H20 -> 5.4215645 | J21: =J20-I20 -> 5.5105729 | K21: =K20-J20 -> 5.5231157 | L21: =L20-K20 -> 5.5427121 | M21: =M20-L20 -> 5.5409097 | N21: =N20-M20 -> 5.5396844
M23: S/G ASP(Mn $): | O23: =H17/H18 -> 1.4883721 | P23: S/G ASP의 경우, 2Q25 기준 수주 잔고와 수주 척수를 이용하여 추정함.
P24: *OceanWise 구독의 경우, 구독 선박 수가 증가세를 보이고 있으나, 관련 매출이 공개되지 않고 그 금액 또한 미미할 것으로 판단되므로 매출에 포함시키지 않음.

Sheet Bunkering
A1: HD현대마린솔루션(443060.KS)
A2: Bunkering Revenue Estimation Sheet
A3: (units in Hundred Millions KRW )
B5: 단위: 억 원 | C5: 2021A | D5: 2022A | E5: 2023A | F5: 2024A | G5: 1Q25 | H5: 2Q25 | I5: 3Q25E | J5: 4Q25E | K5: 1Q26E | L5: 2Q26E | M5: 3Q26E | N5: 4Q26E | P5: Description
B6: 벙커링 매출 | C6: 5210 | D6: 6270 | E6: 5960 | F6: 7056 | G6: 1914 | H6: 1829 | I6: =I8+I14 -> 1603.8407 | J6: =J8+J14 -> 1635.8121 | K6: =K8+K14 -> 1597.8636 | L6: =L8+L14 -> 1606.5968 | M6: =M8+M14 -> 1610.5046 | N6: =N8+N14 -> 1604.9799 | P6: 벙커링의 경우, 출항/기항 선박의 수와 벙커유 판매량에 매우 큰 영향을 받음. 향후 큰 변동폭이 없을 것으로 전망되기에, 상관관계를 이용하여 매출을 추정함.
B7: YoY(%) or QoQ(%) | C7: - | D7: =(D6-C6)/C6 -> 0.20345489 | E7: =(E6-D6)/D6 -> -0.049441786 | F7: =(F6-E6)/E6 -> 0.18389262 | G7: - | H7: =(H6-G6)/G6 -> -0.044409613 | I7: =(I6-H6)/H6 -> -0.12310514 | J7: =(J6-I6)/I6 -> 0.01993426 | K7: =(K6-J6)/J6 -> -0.023198544 | L7: =(L6-K6)/K6 -> 0.0054655159 | M7: =(M6-L6)/L6 -> 0.0024323777 | N7: =(N6-M6)/M6 -> -0.0034304
B8: 출항 선박 매출 | C8: 260 | D8: 310 | E8: 300 | F8: 353 | G8: =$I$25*G10+$I$26 -> 76.023411 | H8: =$I$25*H10+$I$26 -> 76.023411 | I8: =$I$25*I10+$I$26 -> 76.023411 | J8: =$I$25*J10+$I$26 -> 76.023411 | K8: =$I$25*K10+$I$26 -> 59.459866 | L8: =$I$25*L10+$I$26 -> 59.459866 | M8: =$I$25*M10+$I$26 -> 59.459866 | N8: =$I$25*N10+$I$26 -> 59.459866 | P8: 직전 4개년간, 출항 선박 부문 매출과 신규 인도 선박 수 간의 상관계수가 0.8659로 유의미한 상관관계를 갖고 있다고 판단되므로,
B9: of Bunkering Revenue(%) | C9: =C8/C$6 -> 0.049904031 | D9: =D8/D$6 -> 0.049441786 | E9: =E8/E$6 -> 0.05033557 | F9: =F8/F$6 -> 0.050028345 | G9: =G8/G$6 -> 0.039719651 | H9: =H8/H$6 -> 0.041565561 | I9: =I8/I$6 -> 0.047400849 | J9: =J8/J$6 -> 0.046474416 | ... N9: =N8/N$6 -> 0.037047109 | P9: 향후 매출도 동일한 상관계수와 Slope/Intercept를 통해 추정함.
B10: 신규 인도(척) | C10: 119 | D10: 120 | E10: 124 | F10: 130 | G10: =G11+G12+G13 -> 30.75 | H10: =H11+H12+H13 -> 30.75 | I10: =I11+I12+I13 -> 30.75 | J10: =J11+J12+J13 -> 30.75 | K10: =K11+K12+K13 -> 28.25 | L10: =L11+L12+L13 -> 28.25 | M10: =M11+M12+M13 -> 28.25 | N10: =N11+N12+N13 -> 28.25
B11: HD현대중공업(척) | C11: 44 | D11: 37 | E11: 40 | F11: 44 | G11: =$P26/4 -> 11.5 | H11: =$P26/4 -> 11.5 | I11: =$P26/4 -> 11.5 | J11: =$P26/4 -> 11.5 | K11: =$Q26/4 -> 8.75 | L11: =$Q26/4 -> 8.75 | M11: =$Q26/4 -> 8.75 | N11: =$Q26/4 -> 8.75 | P11: HD현대중공업의 신규 인도 선박 수의 경우, Clarksons의 수치를 참조함.
B12: HD현대미포(척) | C12: 45 | D12: 53 | E12: 51 | F12: 55 | G12: =$P27/4 -> 11.5 | H12: =$P27/4 -> 11.5 | I12: =$P27/4 -> 11.5 | J12: =$P27/4 -> 11.5 | K12: =$Q27/4 -> 11.25 | L12: =$Q27/4 -> 11.25 | M12: =$Q27/4 -> 11.25 | N12: =$Q27/4 -> 11.25 | P12: HD현대미포의 신규 인도 선박 수의 경우, Clarksons의 수치를 참조함.
B13: HD현대삼호(척) | C13: 30 | D13: 30 | E13: 33 | F13: 31 | G13: =$P28/4 -> 7.75 | H13: =$P28/4 -> 7.75 | I13: =$P28/4 -> 7.75 | J13: =$P28/4 -> 7.75 | K13: =$Q28/4 -> 8.25 | L13: =$Q28/4 -> 8.25 | M13: =$Q28/4 -> 8.25 | N13: =$Q28/4 -> 8.25 | P13: HD현대삼호의 신규 인도 선박 수의 경우, Clarksons의 수치를 참조함.
B14: 기항 선박 매출 | C14: 4950 | D14: 5960 | E14: 5660 | F14: 6703 | G14: =G16+G19 -> 1837.9766 | H14: =H16+H19 -> 1752.9766 | I14: =I16+I19 -> 1527.8173 | J14: =J16+J19 -> 1559.7887 | K14: =K16+K19 -> 1538.4038 | L14: =L16+L19 -> 1547.1369 | M14: =M16+M19 -> 1551.0448 | N14: =N16+N19 -> 1545.5201 | P14: 직전 4개년간, 기항 선박 부문 매출과 해당 지역 HSFO 벙커량 추정치의 상관계수가 각각 0.9292, 0.9628로 유의미한 상관관계를 갖고 있다고 판단되므로,
B15: of Bunkering Revenue(%) | C15: =C14/C$6 -> 0.95009597 | D15: =D14/D$6 -> 0.95055821 | E15: =E14/E$6 -> 0.94966443 | F15: =F14/F$6 -> 0.94997166 | G15: =G14/G$6 -> 0.96028035 | H15: =H14/H$6 -> 0.95843444 | I15: =I14/I$6 -> 0.95259915 | J15: =J14/J$6 -> 0.95352558 | ... N15: =N14/N$6 -> 0.96295289 | P15: 향후 매출도 동일한 상관계수와 Slope/Intercept를 통해 추정함.
B16: 한국 | C16: 1825 | D16: 2200 | E16: 2080 | F16: 2471.5 | G16: =G6-G8-G19 -> 839.74326 | H16: =H6-H8-H19 -> 792.19277 | I16: =$I$29*I18*'환율&원유'!I6*'환율&원유'!I7/10^3+$I$30 -> 561.15911 | J16: =$I$29*J18*'환율&원유'!J6*'환율&원유'!J7/10^3+$I$30 -> 584.87336 | K16: =$I$29*K18*'환율&원유'!K6*'환율&원유'!K7/10^3+$I$30 -> 570.98845 | L16: =$I$29*L18*'환율&원유'!L6*'환율&원유'!L7/10^3+$I$30 -> 577.4882 | M16: =$I$29*M18*'환율&원유'!M6*'환율&원유'!M7/10^3+$I$30 -> 580.39666 | N16: =$I$29*N18*'환율&원유'!N6*'환율&원유'!N7/10^3+$I$30 -> 576.28486
B17: of Bunkering Revenue(%) | C17: =C16/C$6 -> 0.35028791 | D17: =D16/D$6 -> 0.35087719 | E17: =E16/E$6 -> 0.34899329 | F17: =F16/F$6 -> 0.35026927 | G17: =G16/G$6 -> 0.43873734 | H17: =H16/H$6 -> 0.43312891 | I17: =I16/I$6 -> 0.34988457 | J17: =J16/J$6 -> 0.35754312 | ... N17: =N16/N$6 -> 0.35906047
B18: 한국 기항 HSFO 벙커선 판매량(천 톤) | C18: 1414.464 | D18: 1146.834 | E18: 1304.13 | F18: 1393.7 | G18: =$P$31/4 -> 373.029 | H18: =$P$31/4 -> 373.029 | I18: =$P$31/4 -> 373.029 | J18: =$P$31/4 -> 373.029 | K18: =$Q$31/4 -> 378 | L18: =$Q$31/4 -> 378 | M18: =$Q$31/4 -> 378 | N18: =$Q$31/4 -> 378 | P18: 한국 기항 벙커선 판매량의 경우, Clarksons의 기항 선박수 연간 데이터와 선박당 벙커유 연간 판매량을 곱한 후 분기별로 추정함.
B19: 싱가포르 | C19: 3125 | D19: 3760 | E19: 3570 | F19: 4231.5 | G19: =$I$34*G21*'환율&원유'!G6*'환율&원유'!G7/1000+$I$35 -> 998.23333 | H19: =$I$34*H21*'환율&원유'!H6*'환율&원유'!H7/1000+$I$35 -> 960.78382 | I19: =$I$34*I21*'환율&원유'!I6*'환율&원유'!I7/1000+$I$35 -> 966.65818 | J19: =$I$34*J21*'환율&원유'!J6*'환율&원유'!J7/1000+$I$35 -> 974.91531 | K19: =$I$34*K21*'환율&원유'!K6*'환율&원유'!K7/1000+$I$35 -> 967.4153 | L19: =$I$34*L21*'환율&원유'!L6*'환율&원유'!L7/1000+$I$35 -> 969.6487 | M19: =$I$34*M21*'환율&원유'!M6*'환율&원유'!M7/1000+$I$35 -> 970.64809 | N19: =$I$34*N21*'환율&원유'!N6*'환율&원유'!N7/1000+$I$35 -> 969.23522
B20: of Bunkering Revenue(%) | C20: =C19/C$6 -> 0.59980806 | D20: =D19/D$6 -> 0.59968102 | E20: =E19/E$6 -> 0.59899329 | F20: =F19/F$6 -> 0.59970238 | G20: =G19/G$6 -> 0.52154301 | H20: =H19/H$6 -> 0.52530553 | I20: =I19/I$6 -> 0.60271458 | J20: =J19/J$6 -> 0.59598246 | ... N20: =N19/N$6 -> 0.60389242
B21: 싱가포르 기항 HSFO 벙커선 판매량(천 톤) | C21: 0 | D21: 4664 | E21: 5572 | F21: 6718 | G21: =$P$32/4 -> 1640 | H21: =$P$32/4 -> 1640 | I21: =$P$32/4 -> 1640 | J21: =$P$32/4 -> 1640 | K21: =$Q$32/4 -> 1640 | L21: =$Q$32/4 -> 1640 | M21: =$Q$32/4 -> 1640 | N21: =$Q$32/4 -> 1640 | P21: 싱가포르 기항 벙커선 판매량의 경우, Clarksons의 기항 선박수 연간 데이터와 선박당 벙커유 연간 판매량을 곱한 후 분기별로 추정함.
B24: 출항 선박 상관관계 | C24: 2021A | D24: 2022A | E24: 2023A | F24: 2024A | H24: 상관계수 | I24: =CORREL(C25:F25,C26:F26) -> 0.86585071 | L24: HD현대그룹 조선 3사 인도 선박 수 전망 | P24: 2025E | Q24: 2026E
B25: 출항 선박 매출 | C25: =C8 -> 260 | D25: =D8 -> 310 | E25: =E8 -> 300 | F25: =F8 -> 353 | H25: Slope | I25: =SLOPE(C25:F25,C26:F26) -> 6.6254181 | L25: 신규 인도(척) | P25: =P26+P27+P28 -> 123 | Q25: =Q26+Q27+Q28 -> 113
B26: 신규 인도(척) | C26: =C10 -> 119 | D26: =D10 -> 120 | E26: =E10 -> 124 | F26: =F10 -> 130 | H26: Intercept | I26: =INTERCEPT(C25:F25,C26:F26)/4 -> -127.70819 | L26: HD현대중공업(척) | P26: 46 | Q26: 35
L27: HD현대미포(척) | P27: 46 | Q27: 45
B28: 한국 기항 선박 상관관계 | C28: 2021A | D28: 2022A | E28: 2023A | F28: 2024A | H28: 상관계수 | I28: =CORREL(C29:F29,C30:F30) -> 0.92917944 | L28: HD현대삼호(척) | P28: 31 | Q28: 33
B29: 한국 기항 선박 매출 | C29: =C16 -> 1825 | D29: =D16 -> 2200 | E29: =E16 -> 2080 | F29: =F16 -> 2471.5 | H29: Slope | I29: =SLOPE(C29:F29,C30:F30) -> 0.01588041
B30: 한국 HSFO 벙커량 추정치 | C30: =C18*'환율&원유'!C6*'환율&원유'!C7/1000 -> 115392.46 | D30: =D18*'환율&원유'!D6*'환율&원유'!D7/1000 -> 146289.44 | E30: =E18*'환율&원유'!E6*'환율&원유'!E7/1000 -> 138926.44 | F30: =F18*'환율&원유'!F6*'환율&원유'!F7/1000 -> 150641.41 | H30: Intercept | I30: =INTERCEPT(C29:F29,C30:F30)/4 -> -11.098243 | L30: 지역별 HSFO 벙커선 판매량 전망 | P30: 2025E | Q30: 2026E
B31: 한국 HSFO 벙커량 추정치의 경우, 한국 기항 벙커선 판매량에 두바이 원유 가격과 원/달러 환율을 곱하여 그 총량을 추정함. | L31: 한국 기항 HSFO 벙커선 판매량(천 톤) | P31: 1492.116 | Q31: 1512
L32: 싱가포르 기항 HSFO 벙커선 판매량(천 톤) | P32: 6560 | Q32: 6560
B33: 싱가포르 기항 선박 상관관계 | C33: 2021A | D33: 2022A | E33: 2023A | F33: 2024A | H33: 상관계수 | I33: =CORREL(D34:F34,D35:F35) -> 0.96276863
B34: 싱가포르 기항 선박 매출 | C34: =C19 -> 3125 | D34: =D19 -> 3760 | E34: =E19 -> 3570 | F34: =F19 -> 4231.5 | H34: Slope | I34: =SLOPE(C34:F34,C35:F35) -> 0.0012577093
B35: 싱가포르 HSFO 벙커량 추정치 | C35: =C21*'환율&원유'!C6*'환율&원유'!C7/1000 -> 0 | D35: =D21*'환율&원유'!D6*'환율&원유'!D7/1000 -> 594936.97 | E35: =E21*'환율&원유'!E6*'환율&원유'!E7/1000 -> 593574.36 | F35: =F21*'환율&원유'!F6*'환율&원유'!F7/1000 -> 726131.17 | H35: Intercept | I35: =INTERCEPT(C34:F34,C35:F35)/4 -> 767.40228
B36: 싱가포르 HSFO 벙커량 추정치의 경우, 한국 기항 벙커선 판매량에 두바이 원유 가격과 원/달러 환율을 곱하여 그 총량을 추정함.

Sheet 환율&원유
A1: HD현대마린솔루션(443060.KS)
A2: DBL1 Commodity & Currency
A3: (units in $ & KRW/$)
C5: 2021A | D5: 2022A | E5: 2023A | F5: 2024A | G5: 1Q25 | H5: 2Q25 | I5: 3Q25E | J5: 4Q25E | K5: 1Q26E | L5: 2Q26E | M5: 3Q26E | N5: 4Q26E | P5: Description
B6: 두바이 원유($) | C6: 70.445 | D6: 98.06075 | E6: 81.0315 | F6: 78.36225 | G6: 75.91 | H6: 69.268 | I6: 69.513 | J6: =AVERAGE(G6:I6) -> 71.563667 | K6: =AVERAGE(H6:J6) -> 70.114889 | L6: =AVERAGE(I6:K6) -> 70.397185 | M6: =AVERAGE(J6:L6) -> 70.691914 | N6: =AVERAGE(K6:M6) -> 70.401329 | P6: 두바이 원유 가격의 경우, Bloomberg의 전망치를 참조함. 전망치가 존재하지 않은 4Q25부터는 직전 3Q Average Flat 적용함.
B7: 원/달러 환율 | C7: 1158.0715 | D7: 1300.82 | E7: 1314.65 | F7: 1379.33 | G7: 1474.25 | H7: 1353.5 | I7: 1389.7 | J7: =AVERAGE(G7:I7) -> 1405.8167 | K7: =AVERAGE(H7:J7) -> 1383.0056 | L7: =AVERAGE(I7:K7) -> 1392.8407 | M7: =AVERAGE(J7:L7) -> 1393.8877 | N7: =AVERAGE(K7:M7) -> 1389.9113 | P7: 원/달러 환율의 경우, Bloomberg 전망치를 참고함. 전망치가 존재하지 않는 4Q25부터는 직전 3Q Average Flat 적용함.

Sheet 비용추정
A1: HD현대마린솔루션(443060.KS)
A2: Assumption Sheet
A3: (units in Millions KRW )
B5: 단위: 백만 원 | C5: 2Q24 | D5: 3Q24 | E5: 4Q24 | F5: 1Q25 | G5: 2Q25 | H5: 3Q25E | I5: 4Q25E | J5: 1Q26E | K5: 2Q26E | L5: 3Q26E | M5: 4Q26E | O5: Description
B6: 매출액 | C6: ='IS(Quaterly)'!G10 -> 437855.16 | D6: ='IS(Quaterly)'!H10 -> 461261.44 | E6: ='IS(Quaterly)'!I10 -> 463372.92 | F6: ='IS(Quaterly)'!J10 -> 485597.83 | G6: ='IS(Quaterly)'!K10 -> 467721.57 | H6: =매출추정!I6*100 -> 469386.75 | I6: =매출추정!J6*100 -> 483293.63 | J6: =매출추정!K6*100 -> 508637.42 | K6: =매출추정!L6*100 -> 519267.74 | L6: =매출추정!M6*100 -> 538811.31 | M6: =매출추정!N6*100 -> 550319.23
B7: 매출원가 | C7: ='IS(Quaterly)'!G13 -> 343798 | D7: ='IS(Quaterly)'!H13 -> 355933.42 | E7: ='IS(Quaterly)'!I13 -> 373085.98 | F7: ='IS(Quaterly)'!J13 -> 377587.18 | G7: ='IS(Quaterly)'!K13 -> 358744.49 | H7: =H6*H8 -> 367643.87 | I7: =I6*I8 -> 375006.72 | J7: =J6*J8 -> 394395.26 | K7: =K6*K8 -> 404090.41 | L7: =L6*L8 -> 418392.04 | M7: =M6*M8 -> 427432.56 | O7: 매출원가의 경우, 동사가 모그룹 내 계열사들의 공급망을 이용하고, 자체 생산이 아닌 상품으로 취급하는 재화가 대부분이므로 매출액 대비 경향성을 반영하기 위하여 직전 4Q Average Flat 적용함.
B8: (%) | C8: =C7/C6 -> 0.78518659 | D8: =D7/D6 -> 0.77165223 | E8: =E7/E6 -> 0.80515275 | F8: =F7/F6 -> 0.77757181 | G8: =G7/G6 -> 0.76700437 | H8: =AVERAGE(E8:G8) -> 0.78324298 | I8: =AVERAGE(F8:H8) -> 0.77593972 | J8: =AVERAGE(G8:I8) -> 0.77539569 | K8: =AVERAGE(H8:J8) -> 0.77819279 | L8: =AVERAGE(I8:K8) -> 0.7765094 | M8: =AVERAGE(J8:L8) -> 0.77669929
B9: 매출총이익 | C9: ='IS(Quaterly)'!G14 -> 94057.16 | D9: ='IS(Quaterly)'!H14 -> 105328.02 | E9: ='IS(Quaterly)'!I14 -> 90286.939 | F9: ='IS(Quaterly)'!J14 -> 108010.65 | G9: ='IS(Quaterly)'!K14 -> 108977.08 | H9: =H6-H7 -> 101742.87 | I9: =I6-I7 -> 108286.91 | J9: =J6-J7 -> 114242.16 | K9: =K6-K7 -> 115177.33 | L9: =L6-L7 -> 120419.26 | M9: =M6-M7 -> 122886.67
B10: GPM(%) | C10: =C9/C6 -> 0.21481341 | D10: =D9/D6 -> 0.22834777 | E10: =E9/E6 -> 0.19484725 | F10: =F9/F6 -> 0.22242819 | G10: =G9/G6 -> 0.23299563 | H10: =H9/H6 -> 0.21675702 | I10: =I9/I6 -> 0.22406028 | J10: =J9/J6 -> 0.22460431 | ... M10: =M9/M6 -> 0.22330071
B11: 판매비와 관리비 | C11: ='IS(Quaterly)'!G15 -> 23071.291 | D11: ='IS(Quaterly)'!H15 -> 21944.67 | E11: ='IS(Quaterly)'!I15 -> 24407.77 | F11: ='IS(Quaterly)'!J15 -> 25003.82 | G11: ='IS(Quaterly)'!K15 -> 25967.147 | H11: =H51 -> 25534.997 | I11: =I51 -> 25957.874 | J11: =J51 -> 25964.082 | K11: =K51 -> 26135.482 | L11: =L51 -> 26176.755 | M11: =M51 -> 26341.857
B12: (%) | C12: =C11/C$6 -> 0.052691604 | D12: =D11/D$6 -> 0.04757534 | E12: =E11/E$6 -> 0.05267414 | F12: =F11/F$6 -> 0.051490798 | G12: =G11/G$6 -> 0.055518387 | H12: =H11/H$6 -> 0.054400764 | I12: =I11/I$6 -> 0.053710359 | J12: =J11/J$6 -> 0.051046346 | ... M12: =M11/M$6 -> 0.047866504
B13: 급여 | C13: 8578.007 | D13: 9172.313 | E13: 9314.703 | F13: 10343.031 | G13: 10338.994 | H13: =G13*(1+$N$13) -> 10443.302 | I13: =H13*(1+$N$13) -> 10548.663 | J13: =I13*(1+$N$14) -> 10655.163 | K13: =J13*(1+$N$14) -> 10762.739 | L13: =K13*(1+$N$14) -> 10871.4 | M13: =L13*(1+$N$14) -> 10981.159 | N13: =(1+3.6%)^0.25/100 -> 0.01008881 | O13: 급여의 경우, 국회예산정책처에서 발표한 연간 명목임금상승률 전망치를 분기로 계산하여 '25년 YoY+3.6%, '26년 YoY+3.9%로 각 분기 추정함.
B14: of sales(%) | C14: =C13/C$6 -> 0.019590969 | D14: =D13/D$6 -> 0.01988528 | E14: =E13/E$6 -> 0.020101958 | F14: =F13/F$6 -> 0.021299582 | G14: =G13/G$6 -> 0.022105019 | H14: =H13/H$6 -> 0.022248822 | I14: =I13/I$6 -> 0.021826612 | J14: =J13/J$6 -> 0.020948445 | ... M14: =M13/M$6 -> 0.019954162 | N14: =(1+3.9%)^0.25/100 -> 0.010096106
B15: 퇴직급여 | C15: 307.125 | D15: 362.536 | E15: 208.154 | F15: 394.631 | G15: 420.085 | H15: =G15*(1+$N$13) -> 424.32316 | I15: =H15*(1+$N$13) -> 428.60407 | J15: =I15*(1+$N$14) -> 432.93131 | K15: =J15*(1+$N$14) -> 437.30223 | L15: =K15*(1+$N$14) -> 441.71728 | M15: =L15*(1+$N$14) -> 446.1769 | O15: 퇴직급여의 경우, 급여 상승분을 적용하여 추정함.
B16: of sales(%) | C16: =C15/C$6 -> 0.00070143058 | D16: =D15/D$6 -> 0.00078596642 | E16: =E15/E$6 -> 0.00044921485 | F16: =F15/F$6 -> 0.00081267044 | G16: =G15/G$6 -> 0.00089815187 | H16: =H15/H$6 -> 0.00090399476 | I16: =I15/I$6 -> 0.0008868399 | J16: =J15/J$6 -> 0.00085115897 | ... M16: =M15/M$6 -> 0.00081076015
B17: 여비교통비 | C17: 290.742 | D17: 349.206 | E17: 490.195 | F17: 486.744 | G17: 412.799 | H17: =AVERAGE(D17:G17) -> 434.736 | I17: =AVERAGE(E17:H17) -> 456.1185 | J17: =AVERAGE(F17:I17) -> 447.59938 | K17: =AVERAGE(G17:J17) -> 437.81322 | L17: =AVERAGE(H17:K17) -> 444.06677 | M17: =AVERAGE(I17:L17) -> 446.39947 | O17: 여비교통비의 경우, 변동성이 낮으므로 직전 4Q Average Flat 적용함.
B18: of sales(%) | C18: =C17/C$6 -> 0.0006640141 | D18: =D17/D$6 -> 0.00075706741 | E18: =E17/E$6 -> 0.0010578844 | F18: =F17/F$6 -> 0.0010023603 | G18: =G17/G$6 -> 0.00088257422 | H18: =H17/H$6 -> 0.00092617869 | I18: =I17/I$6 -> 0.00094377097 | J18: =J17/J$6 -> 0.00087999694 | ... M18: =M17/M$6 -> 0.00081116458
B19: 지급수수료 | C19: 3581.408 | D19: 1754.789 | E19: 2315.326 | F19: 1739.365 | G19: 2623.333 | H19: =AVERAGE(D19:G19) -> 2108.2033 | I19: =AVERAGE(E19:H19) -> 2196.5568 | J19: =AVERAGE(F19:I19) -> 2166.8645 | K19: =AVERAGE(G19:J19) -> 2273.7394 | L19: =AVERAGE(H19:K19) -> 2186.341 | M19: =AVERAGE(I19:L19) -> 2205.8754 | O19: 지급수수료의 경우, 상장 후 첫 분기를 제외하고 매출 대비 매우 작은 폭의 변동성을 보이므로, 직전 4Q Average Flat 적용함.
B20: of sales(%) | C20: =C19/C$6 -> 0.0081794354 | D20: =D19/D$6 -> 0.0038043263 | E20: =E19/E$6 -> 0.0049966795 | F20: =F19/F$6 -> 0.0035819044 | G20: =G19/G$6 -> 0.0056087492 | H20: =H19/H$6 -> 0.0044913992 | I20: =I19/I$6 -> 0.0045449736 | J20: =J19/J$6 -> 0.0042601358 | ... M20: =M19/M$6 -> 0.0040083561
B21: 광고선전비 | C21: 115.089 | D21: 93.163 | E21: 132.197 | F21: 123.609 | G21: 186.689 | H21: =AVERAGE(D21:G21) -> 133.9145 | I21: =AVERAGE(E21:H21) -> 144.10237 | J21: =AVERAGE(F21:I21) -> 147.07872 | K21: =AVERAGE(G21:J21) -> 152.94615 | L21: =AVERAGE(H21:K21) -> 144.51044 | M21: =AVERAGE(I21:L21) -> 147.15942 | O21: 광고선전비의 경우, 변동성이 낮으므로 직전 4Q Average Flat 적용함.
B22: of sales(%) | C22: =C21/C$6 -> 0.00026284719 | D22: =D21/D$6 -> 0.0002019744 | E22: =E21/E$6 -> 0.00028529289 | F22: =F21/F$6 -> 0.00025455015 | G22: =G21/G$6 -> 0.00039914559 | H22: =H21/H$6 -> 0.00028529672 | I22: =I21/I$6 -> 0.00029816734 | J22: =J21/J$6 -> 0.0002891622 | ... M22: =M21/M$6 -> 0.00026740737
B23: 복리후생비 | C23: 2275.023 | D23: 2050.702 | E23: 2734.056 | F23: 2627.133 | G23: 2566.983 | H23: =AVERAGE(D23:G23) -> 2494.7185 | I23: =AVERAGE(E23:H23) -> 2605.7226 | J23: =AVERAGE(F23:I23) -> 2573.6393 | K23: =AVERAGE(G23:J23) -> 2560.2659 | L23: =AVERAGE(H23:K23) -> 2558.5866 | M23: =AVERAGE(I23:L23) -> 2574.5536 | O23: 복리후생비의 경우, 변동성이 낮으므로 직전 4Q Average Flat 적용함.
B24: of sales(%) | C24: =C23/C$6 -> 0.0051958346 | D24: =D23/D$6 -> 0.0044458562 | E24: =E23/E$6 -> 0.0059003361 | F24: =F23/F$6 -> 0.0054101004 | G24: =G23/G$6 -> 0.0054882716 | H24: =H23/H$6 -> 0.0053148465 | I24: =I23/I$6 -> 0.0053915931 | J24: =J23/J$6 -> 0.0050598701 | ... M24: =M23/M$6 -> 0.0046782912
B25: 교육훈련비 | C25: 80.429 | D25: 94.596 | E25: 208.569 | F25: 99.956 | G25: 171.853 | H25: =AVERAGE(D25:G25) -> 143.7435 | I25: =AVERAGE(E25:H25) -> 156.03037 | J25: =AVERAGE(F25:I25) -> 142.89572 | K25: =AVERAGE(G25:J25) -> 153.63065 | L25: =AVERAGE(H25:K25) -> 149.07506 | M25: =AVERAGE(I25:L25) -> 150.40795 | O25: 교육훈련비의 경우, 변동성이 낮으므로 직전 4Q Average Flat 적용함.
B26: of sales(%) | C26: =C25/C$6 -> 0.0001836886 | D26: =D25/D$6 -> 0.00020508109 | E26: =E25/E$6 -> 0.00045011046 | F26: =F25/F$6 -> 0.00020584112 | G26: =G25/G$6 -> 0.00036742586 | H26: =H25/H$6 -> 0.00030623681 | I26: =I25/I$6 -> 0.00032284799 | J26: =J25/J$6 -> 0.00028093827 | ... M26: =M25/M$6 -> 0.00027331037
B27: 임차료 | C27: 591.445 | D27: 718.374 | E27: 648.01 | F27: 700.178 | G27: 644.746 | H27: =AVERAGE(D27:G27) -> 677.827 | I27: =AVERAGE(E27:H27) -> 667.69025 | J27: =AVERAGE(F27:I27) -> 672.61031 | K27: =AVERAGE(G27:J27) -> 665.71839 | L27: =AVERAGE(H27:K27) -> 670.96149 | M27: =AVERAGE(I27:L27) -> 669.24511 | O27: 임차료의 경우, 변동성이 낮으므로 직전 4Q Average Flat 적용함.
B28: of sales(%) | C28: =C27/C$6 -> 0.0013507777 | D28: =D27/D$6 -> 0.0015574118 | E28: =E27/E$6 -> 0.0013984632 | F28: =F27/F$6 -> 0.0014418887 | G28: =G27/G$6 -> 0.0013784825 | H28: =H27/H$6 -> 0.0014440693 | I28: =I27/I$6 -> 0.0013815416 | J28: =J27/J$6 -> 0.0013223768 | ... M28: =M27/M$6 -> 0.0012161034
B29: 차량유지비 | C29: 131.221 | D29: 19.715 | E29: 98.998 | F29: 103.419 | G29: 83.292 | H29: =AVERAGE(D29:G29) -> 76.356 | I29: =AVERAGE(E29:H29) -> 90.51625 | J29: =AVERAGE(F29:I29) -> 88.395813 | K29: =AVERAGE(G29:J29) -> 84.640016 | L29: =AVERAGE(H29:K29) -> 84.97702 | M29: =AVERAGE(I29:L29) -> 87.132274 | O29: 차량유지비의 경우, 고정비적 성격을 지니므로 직전 4Q Average Flat 적용함.
B30: of sales(%) | C30: =C29/C$6 -> 0.00029969043 | D30: =D29/D$6 -> 4.2741488e-05 | E30: =E29/E$6 -> 0.00021364649 | F30: =F29/F$6 -> 0.00021297253 | G30: =G29/G$6 -> 0.00017808031 | H30: =H29/H$6 -> 0.00016267183 | I30: =I29/I$6 -> 0.00018729038 | J30: =J29/J$6 -> 0.00017378944 | ... M30: =M29/M$6 -> 0.00015833042
B31: 수도광열비 | C31: 92.208 | D31: 100.073 | E31: 98.568 | F31: 96.83 | G31: 101.732 | H31: =AVERAGE(D31:G31) -> 99.30075 | I31: =AVERAGE(E31:H31) -> 99.107687 | J31: =AVERAGE(F31:I31) -> 99.242609 | K31: =AVERAGE(G31:J31) -> 99.845762 | L31: =AVERAGE(H31:K31) -> 99.374202 | M31: =AVERAGE(I31:L31) -> 99.392565 | O31: 수도광열비의 경우, 변동성이 낮으므로 직전 4Q Average Flat 적용함.
B32: of sales(%) | C32: =C31/C$6 -> 0.00021059019 | D32: =D31/D$6 -> 0.00021695505 | E32: =E31/E$6 -> 0.00021271852 | F32: =F31/F$6 -> 0.00019940369 | G32: =G31/G$6 -> 0.00021750547 | H32: =H31/H$6 -> 0.00021155423 | I32: =I31/I$6 -> 0.00020506723 | J32: =J31/J$6 -> 0.00019511464 | ... M32: =M31/M$6 -> 0.00018060893
B33: 전산처리비 | C33: 455.565 | D33: 274.345 | E33: 125.862 | F33: 467.118 | G33: 487.784 | H33: =AVERAGE(F33:G33) -> 477.451 | I33: =AVERAGE(G33:H33) -> 482.6175 | J33: =AVERAGE(H33:I33) -> 480.03425 | K33: =AVERAGE(I33:J33) -> 481.32587 | L33: =AVERAGE(J33:K33) -> 480.68006 | M33: =AVERAGE(K33:L33) -> 481.00297 | O33: 전산처리비의 경우, 1Q25에 급격히 상승하여 유지되는 경향을 보이므로 직전 2Q Average Flat 적용함.
B34: of sales(%) | C34: =C33/C$6 -> 0.0010404468 | D34: =D33/D$6 -> 0.00059477116 | E34: =E33/E$6 -> 0.0002716214 | F34: =F33/F$6 -> 0.00096194417 | G34: =G33/G$6 -> 0.001042894 | H34: =H33/H$6 -> 0.0010171804 | I34: =I33/I$6 -> 0.00099860099 | J34: =J33/J$6 -> 0.0009437651 | ... M34: =M33/M$6 -> 0.00087404354
B35: 세금과공과 | C35: 53.386 | D35: 122.787 | E35: 225.78 | F35: 489.853 | G35: 373.855 | H35: =AVERAGE(F35:G35) -> 431.854 | I35: =AVERAGE(G35:H35) -> 402.8545 | J35: =AVERAGE(H35:I35) -> 417.35425 | K35: =AVERAGE(I35:J35) -> 410.10438 | L35: =AVERAGE(J35:K35) -> 413.72931 | M35: =AVERAGE(K35:L35) -> 411.91684 | O35: 세금과공과의 경우, 1Q25에 급격히 상승하여 유지되는 경향을 보이므로 직전 2Q Average Flat 적용함.
B36: of sales(%) | C36: =C35/C$6 -> 0.00012192616 | D36: =D35/D$6 -> 0.00026619828 | E36: =E35/E$6 -> 0.00048725333 | F36: =F35/F$6 -> 0.0010087627 | G36: =G35/G$6 -> 0.00079931101 | H36: =H35/H$6 -> 0.00092003876 | I36: =I35/I$6 -> 0.00083356054 | J36: =J35/J$6 -> 0.0008205339 | ... M36: =M35/M$6 -> 0.00074850527
B37: 연구개발비 | C37: 1212.474 | D37: 1928.862 | E37: 2241.111 | F37: 1138.046 | G37: 2003.149 | H37: =AVERAGE(D37:G37) -> 1827.792 | I37: =AVERAGE(E37:H37) -> 1802.5245 | J37: =AVERAGE(F37:I37) -> 1692.8779 | K37: =AVERAGE(G37:J37) -> 1831.5858 | L37: =AVERAGE(H37:K37) -> 1788.6951 | M37: =AVERAGE(I37:L37) -> 1778.9208 | O37: 연구개발비의 경우, 2H에 몰려 집행되는 경향이 있으나, 연간 총 비용으로 계산할 경우 변동성이 크지 않으므로 직전 4Q Average Flat 적용함.
B38: of sales(%) | C38: =C37/C$6 -> 0.0027691212 | D38: =D37/D$6 -> 0.0041817109 | E38: =E37/E$6 -> 0.004836517 | F38: =F37/F$6 -> 0.0023435978 | G38: =G37/G$6 -> 0.0042827809 | H38: =H37/H$6 -> 0.003894 | I38: =I37/I$6 -> 0.0037296674 | J38: =J37/J$6 -> 0.0033282606 | ... M38: =M37/M$6 -> 0.0032325253
B39: 감가상각비 | C39: 2318.754 | D39: 2464.516 | E39: 2398.924 | F39: 2499.549 | G39: 2505.53 | H39: =AVERAGE(D39:G39) -> 2467.1298 | I39: =AVERAGE(E39:H39) -> 2467.7832 | J39: =AVERAGE(F39:I39) -> 2484.998 | K39: =AVERAGE(G39:J39) -> 2481.3602 | L39: =AVERAGE(H39:K39) -> 2475.3178 | M39: =AVERAGE(I39:L39) -> 2477.3648 | O39: 감가상각비의 경우, 변동성이 낮으므로 직전 4Q Average Flat 적용함.
B40: of sales(%) | C40: =C39/C$6 -> 0.0052957101 | D40: =D39/D$6 -> 0.0053429916 | E40: =E39/E$6 -> 0.0051770915 | F40: =F39/F$6 -> 0.0051473645 | G40: =G39/G$6 -> 0.0053568836 | H40: =H39/H$6 -> 0.0052560703 | I40: =I39/I$6 -> 0.0051061778 | J40: =J39/J$6 -> 0.004885598 | ... M40: =M39/M$6 -> 0.0045016868
B41: 외주용역비 | C41: 1262.725 | D41: 1100.379 | E41: 1225.825 | F41: 824.785 | G41: 1298.429 | H41: =AVERAGE(C41,D41,E41,G41) -> 1221.8395 | I41: =AVERAGE(D41,E41,G41,H41) -> 1211.6181 | J41: =AVERAGE(E41,G41,H41,I41) -> 1239.4279 | K41: =AVERAGE(G41:J41) -> 1242.8286 | L41: =AVERAGE(H41:K41) -> 1228.9285 | M41: =AVERAGE(I41:L41) -> 1230.7008 | O41: 외주용역비의 경우, 급격히 감소한 1Q25를 제외한 직전 4Q Average Flat 적용함.
...

Sheet RAWDATA>>>
B2: HD현대마린솔루션 RAW DATA
B8: RFS Research Team 2

