Workbook
Name _MOD1: #REF!
Name _MOD1: #REF!
Name _MOD1: #REF!
Name \a: #N/A
Name \b: #N/A
Name \I: #REF!
Name \I: #REF!
Name \I: #REF!
Name \P: #REF!
Name A_K___s__Global__I_T: #REF!
Name Acc_payable_growth_fore: #REF!
Name Acc_Rec_growth_fore: #REF!
Name Accrued_compensation_growth_fore: #REF!
Name Accrued_expenses_growth_fore: #REF!
Name Accum_Cap_Expenses_growth_fore: #REF!
Name Accum_Goodwill_Amort_growth_fore: #REF!
Name Adj_net_oper_fore: #REF!
Name AveSize: #REF!
Name BS_C: #REF!
Name Cash_fore: #REF!
Name Cash_growth_fore: #REF!
Name Cash_operating_taxes_fore: #REF!
Name CDS: #REF!
Name CE_C: #REF!
Name CF_C: #REF!
Name CFormats: #REF!
Name codeDestination: #REF!
Name CODELK_Path: #REF!
Name ColumnHeading: #REF!
Name Comdty: #REF!
Name Corp: #REF!
Name CR3RT: #REF!
Name CR3RTDK: #REF!
Name CR5RTDK: #REF!
Name CTopics: #REF!
Name Cur: #REF!
Name Customer_deposits_growth_fore: #REF!
Name Debt_Market_Cap_Ratio: #REF!
Name Deferred_tax_asset_growth_fore: #REF!
Name Deferred_tax_liability_growth_fore: #REF!
Name Dep_margin_fore: #REF!
Name Depreciation_fore: #REF!
Name DetailColumns: #REF!
Name DnA_fore: #REF!
Name DnA_growth_fore: #REF!
Name DR: #REF!
Name DSDDE_Path: #REF!
Name EBIT_fore: #REF!
Name EBIT_margin_fore: #REF!
Name EBITA_fore: #REF!
Name EBITDA_fore: #REF!
Name EBITDA_margin_fore: #REF!
Name Excel_Version: #REF!
Name Expl_forecast_1st_yr: #REF!
Name Expl_forecast_2nd_yr: #REF!
Name Expl_forecast_3rd_yr: #REF!
Name ExtFiles: #REF!
Name Fixed_asset_turns_fore: #REF!
Name Formats: #REF!
Name FR_COM_ABBR: " "

Sheet Valuation ▶
A1: 현대건설(000720.KS)- Implied PBR & Historical EV/Backlog
A8: TEAM 현대전설
C17: RFS 정식 회원 외 본 가치평가 모델의 무단 사용 및 수정을 금하며, 본 양식의 원 저작권은 중앙대학교 R.F.S. 학회에 있음을 밝힙니다.
C18: 원 제작자: 28기 김 건 (zzkan103@gmail.com)
C19: 1st Version: 2021.03.02

Sheet Implied PBR
A1: 현대건설(000720.KS)
A2: Implied PBR Valuation Sheet
A3: (In KRW Billions)
B5: 현대건설 Implied PBR Valuation | G5: 25년 Fwd BPS
B6: 구분 | D6: 단위 | E6: 비고 | G6: 25E 자본 | H6: ='Expected BS'!F61 -> 10377.153
B7: 25년 Fwd BPS | C7: =H10 -> 93189.185 | D7: 원 | E7: (A) | G7: 발행주식수 | H7: =H8+H9 -> 112410458
B8: Target PBR | C8: =(C9-C14)/(C10-C14) -> 1.1619641 | D8: (배) | E8: (B) = {(C)-(J)/(D)-(J)} | G8: 보통주 | H8: 111355765
B9: Sustainable ROE | C9: ='Expected BS'!J76*100 -> 7.5350502 | D9: % | E9: (C) 25~29년 평균 ROE | G9: 우선주 | H9: 1054693
B10: COE | C10: =H14 -> 6.484753 | D10: % | E10: (D) = (G)+{(H)-(G)}*(I) | G10: 25E BPS | H10: =H6/H8*1000000000 -> 93189.185
B11: 무위험수익률 | C11: =H15 -> 2.811 | D11: % | E11: (E)
B12: 시장기대수익률 | C12: =H16 -> 7 | D12: % | E12: (F)
B13: 조정 베타 | C13: =H17 -> 0.877 | E13: (G) | G13: COE Estimation Logic
B14: Terminal Growth | C14: =H18 -> 0 | D14: % | E14: (H) | G14: COE | H14: =H15+(H16-H15)*H17 -> 6.484753 | I14: % | J14: (D) = (G)+{(H)-(G)}*(I)
B15: 적정주가 | C15: =C7*C8 -> 108282.49 | D15: 원 | E15: (I) = (A)*(B) | G15: 무위험수익률 | H15: 2.811 | I15: % | J15: (G) | K15: 국내 10년 만기 국공채 이자율(출처:BloomBerg)
B16: 목표주가 | C16: =ROUND(C15,-2) -> 108300 | D16: 원 | E16: 12개월 목표주가 | G16: 시장기대수익률 | H16: 7 | I16: % | J16: (H) | K16: 한국의 기업규모위험 프리미엄(Size Risk Premium) 연구결과, 한국공인회계사회(2024.06.05)
B17: 현재주가 | C17: 65200 | D17: 원 | E17: 25.07.30 기준 종가 | G17: 조정 베타 | H17: 0.877 | J17: (I) | K17: 2/3*실질베타+1/3*1로 베타 조정(출처: BloomBerg)
B18: 상승여력 | C18: =(C16/C17-1)*100 -> 66.104294 | D18: % | G18: Terminal Growth | H18: 0 | I18: % | J18: (J) | K18: 보수적 추정을 위해 0%로 가정

Sheet EV.Backlog
A1: 현대건설(000720.KS)
A2: Historical EV/Backlog Valuation Sheet
A3: (In KRW Billions)
B5: 현대건설 Historical EV/Backlog
B6: 구분 | D6: 단위 | E6: 비고 | H6: EV/Backlog Multiple History
B7: 25E Backlog | C7: =총매출!F16 -> 87348.903 | D7: 십억 원 | E7: (A)
B8: Target EV/Backlog | C8: =AVERAGE('Multiple History'!F21:F24) -> 0.14279826 | D8: (배) | E8: (B) 2010년 평균 EV/Backlog
B9: EV | C9: =C7*C8 -> 12473.271 | D9: 십억 원 | E9: (C) = (A) × (B)
B10: 발행주식수 | C10: =C11+C12 -> 112410458 | D10: 주 | E10: (D) = (E) + (F)
B11: 보통주 | C11: 111355765 | D11: 주 | E11: (E)
B12: 우선주 | C12: 1054693 | D12: 주 | E12: (F)
B13: 적정주가 | C13: =C9/C10*1000000000 -> 110961.84 | D13: 원 | E13: (G) = (C) ÷ (D)
B14: 목표주가 | C14: =ROUND(C13,-2) -> 111000 | D14: 원 | E14: 12개월 목표주가
B15: 현재주가 | C15: 65200 | D15: 원 | E15: 25.07.30 기준 종가
B16: 상승여력 | C16: =(C13/C15-1)*100 -> 70.186872 | D16: %

Sheet Estimate ▶
A1: 현대건설(000720.KS)- Implied PBR & Historical EV/Backlog
A8: Estimate Sheets (추정재무제표 작성)
C17: RFS 정식 회원 외 본 가치평가 모델의 무단 사용 및 수정을 금하며, 본 양식의 원 저작권은 중앙대학교 R.F.S. 학회에 있음을 밝힙니다.
C18: 원 제작자: 28기 김 건 (zzkan103@gmail.com)
C19: 1st Version: 2021.03.02

Sheet Expected BS
B1: 추정 재무상태표
B4: 추정 재무상태표
B5: (단위: 십억 원) | C5: 2022 | D5: 2023 | E5: 2024 | F5: 2025E | G5: 2026E | H5: 2027E | I5: 2028E | J5: 2029E
B6: 자산총계 | C6: =SUM(C7, C23) -> 20911.448 | D6: =SUM(D7, D23) -> 23714.235 | E6: =SUM(E7, E23) -> 27005.385 | F6: =SUM(F7, F23) -> 29779.338 | G6: =SUM(G7, G23) -> 30530.248 | H6: =SUM(H7, H23) -> 33423.885 | I6: =SUM(I7, I23) -> 34999.721 | J6: =SUM(J7, J23) -> 34586.956
B7: 유동자산 계 | C7: =SUM(C8:C10, C16:C17, C21:C22) -> 15516.484 | D7: =SUM(D8:D10, D16:D17, D21:D22) -> 18613.17 | E7: =SUM(E8:E10, E16:E17, E21:E22) -> 21100.663 | F7: =SUM(F8:F10, F16:F17, F21:F22) -> 23575.114 | G7: =SUM(G8:G10, G16:G17, G21:G22) -> 23889.316 | H7: =SUM(H8:H10, H16:H17, H21:H22) -> 26062.13 | I7: =SUM(I8:I10, I16:I17, I21:I22) -> 26678.244 | J7: =SUM(J8:J10, J16:J17, J21:J22) -> 24930.678
B8: 재고자산 | C8: 855.394 | D8: 815.625 | E8: 776.511 | F8: =AVERAGE(C8:E8) -> 815.84333 | G8: =AVERAGE(D8:F8) -> 802.65978 | H8: =AVERAGE(E8:G8) -> 798.33804 | I8: =AVERAGE(F8:H8) -> 805.61372 | J8: =AVERAGE(G8:I8) -> 802.20384 | L8: flat한 경향으로 3개년 이동평균 적용
B9: 유동금융자산 | C9: 1528.836 | D9: 1026.49 | E9: 760.79 | F9: =E9 -> 760.79 | G9: =F9 -> 760.79 | H9: =G9 -> 760.79 | I9: =H9 -> 760.79 | J9: =I9 -> 760.79 | L9: 향후 업황 상황의 개선으로 금융자산 증가가 예상되나 보수적인 추정을 위해 flat 적용
B10: 매출채권및기타유동채권 | C10: =SUM(C11:C15) -> 7848.789 | D10: =SUM(D11:D15) -> 10659.313 | E10: =SUM(E11:E15) -> 12100.467 | F10: =SUM(F11:F15) -> 13492.19 | G10: =SUM(G11:G15) -> 13405.594 | H10: =SUM(H11:H15) -> 14597.187 | I10: =SUM(I11:I15) -> 14648.793 | J10: =SUM(J11:J15) -> 12832.971
B11: 매출채권 | C11: 4.882 | D11: 2.324 | E11: 4.603 | F11: =AVERAGE(C11:E11) -> 3.9363333 | G11: =AVERAGE(D11:F11) -> 3.6211111 | H11: =AVERAGE(E11:G11) -> 4.0534815 | I11: =AVERAGE(F11:H11) -> 3.8703086 | J11: =AVERAGE(G11:I11) -> 3.8483004 | L11: 규모 미미하고 변동성 크지 않아 3개년 이동평균 적용
B12: 공사(분양)미수금 | C12: 2010.947 | D12: 3376.372 | E12: 5314.608 | F12: =E12*(1+D73) -> 6773.4524 | G12: =F12*(1+E73) -> 6572.786 | H12: =G12*(1+F73) -> 7600.6296 | I12: =H12*(1+G73) -> 7526.2464 | J12: =I12*(1+H73) -> 6200.354 | L12: 수주 증가에 의해 미수금이 상승은 제한적일 것으로 판단하나 보수적 추정을 위해 매해 신규 수주 증가율을 적용
B13: 계약자산(미청구공사) | C13: 3734.704 | D13: 5335.234 | E13: 4684.982 | F13: =E13*(1+RATE(6, 0, -$E$13, $J$13)) -> 4668.1637 | G13: =F13*(1+RATE(6, 0, -$E$7, $J$7)) -> 4799.755 | H13: =G13*(1+RATE(6, 0, -$E$7, $J$7)) -> 4935.0558 | I13: =H13*(1+RATE(6, 0, -$E$7, $J$7)) -> 5074.1706 | J13: =AVERAGE(C13:E13) -> 4584.9733 | L13: 향후 매출 증가와 회수 효율화가 병행될 것으로 판단되나, 보수적 추정을 위해 평균 수준을 유지하도록 추정
B14: 미수금 | C14: 862.063 | D14: 895.256 | E14: 817.269 | F14: =AVERAGE(C14:E14) -> 858.196 | G14: =AVERAGE(D14:F14) -> 856.907 | H14: =AVERAGE(E14:G14) -> 844.124 | I14: =AVERAGE(F14:H14) -> 853.07567 | J14: =AVERAGE(G14:I14) -> 851.36889 | L14: flat한 경향으로 3개년 이동평균 적용
B15: 기타의 유동채권 | C15: 1236.193 | D15: 1050.127 | E15: 1279.005 | F15: =AVERAGE(C15:E15) -> 1188.4417 | G15: =AVERAGE(D15:F15) -> 1172.5246 | H15: =AVERAGE(E15:G15) -> 1213.3237 | I15: =AVERAGE(F15:H15) -> 1191.43 | J15: =AVERAGE(G15:I15) -> 1192.4261 | L15: flat한 경향으로 3개년 이동평균 적용
B16: 당기법인세자산(선급법인세) | C16: 5.789 | D16: 6.663 | E16: 29.567 | F16: ='Expected IS'!F$21*AVERAGE('Expected BS'!$C$16/'Expected IS'!$C$21, 'Expected BS'!$D$16/'Expected IS'!$D$21) -> 4.3224388 | G16: ='Expected IS'!G$21*AVERAGE('Expected BS'!$C$16/'Expected IS'!$C$21, 'Expected BS'!$D$16/'Expected IS'!$D$21) -> 7.8496706 | H16: ='Expected IS'!H$21*AVERAGE('Expected BS'!$C$16/'Expected IS'!$C$21, 'Expected BS'!$D$16/'Expected IS'!$D$21) -> 10.891219 | I16: ='Expected IS'!I$21*AVERAGE('Expected BS'!$C$16/'Expected IS'!$C$21, 'Expected BS'!$D$16/'Expected IS'!$D$21) -> 11.337392 | J16: ='Expected IS'!J$21*AVERAGE('Expected BS'!$C$16/'Expected IS'!$C$21, 'Expected BS'!$D$16/'Expected IS'!$D$21) -> 12.554528 | L16: 법인세 환급이 발생한 2024년도 제외하여 과거 법인세 비용 대비 비율로 추정
B17: 기타유동자산 | C17: =SUM(C18:C20) -> 1303.779 | D17: =SUM(D18:D20) -> 1899.414 | E17: =SUM(E18:E20) -> 2287.386 | F17: =SUM(F18:F20) -> 2915.6424 | G17: =SUM(G18:G20) -> 2829.6206 | H17: =SUM(H18:H20) -> 3271.5223 | I17: =SUM(I18:I20) -> 3239.6635 | J17: =SUM(J18:J20) -> 2669.1528
B18: 선급금 | C18: 815.937 | D18: 1266.75 | E18: 1444.048 | F18: =E18*(1+D$73) -> 1840.435 | G18: =F18*(1+E$73) -> 1785.9113 | H18: =G18*(1+F$73) -> 2065.1897 | I18: =H18*(1+G$73) -> 2044.9789 | J18: =I18*(1+H$73) -> 1684.7167 | L18: 공사 비용 중 선지급된 부분 사업 확장과 착공률 증가가 동시에 예상되기에 신규 수주 증가율 적용
B19: 선급비용 | C19: 487.84 | D19: 630.198 | E19: 842.863 | F19: =E19*(1+D$73) -> 1074.2264 | G19: =F19*(1+E$73) -> 1042.402 | H19: =G19*(1+F$73) -> 1205.4115 | I19: =H19*(1+G$73) -> 1193.6148 | J19: =I19*(1+H$73) -> 983.33668 | L19: 기간비용 중 선지급된 부분. 사업 확장과 착공률 증가가 동시에 예상되기에 신규 수주 증가율 적용
B20: 기타의유동자산 | C20: 0.002 | D20: 2.466 | E20: 0.475 | F20: =AVERAGE(C20:E20) -> 0.981 | G20: =AVERAGE(D20:F20) -> 1.3073333 | H20: =AVERAGE(E20:G20) -> 0.92111111 | I20: =AVERAGE(F20:H20) -> 1.0698148 | J20: =AVERAGE(G20:I20) -> 1.0994198 | L20: 규모 미미해 3개년 이동평균 적용
B21: 현금 및 현금성 자산 | C21: 3973.897 | D21: 4205.665 | E21: 5130.372 | F21: =E21*(1+RATE(3, 0, -$C$21, $E$21)) -> 5586.326 | G21: =F21*(1+RATE(3, 0, -$C$21, $E$21)) -> 6082.8021 | H21: =G21*(1+RATE(3, 0, -$C$21, $E$21)) -> 6623.4019 | I21: =H21*(1+RATE(3, 0, -$C$21, $E$21)) -> 7212.0466 | J21: =I21*(1+RATE(3, 0, -$C$21, $E$21)) -> 7853.0062 | L21: 미청구공사의 감소와 신규 수주의 착공으로 현금 유입이 증가할 전망, 이에 따라 과거 성장률을 적용
B22: 매각예정비유동자산및처분자산집단 | E22: 15.57 | F22: 0 | G22: 0 | H22: 0 | I22: 0 | J22: 0 | L22: 비주요항목
B23: 비유동자산 계 | C23: =SUM(C24, C29:C35) -> 5394.964 | D23: =SUM(D24, D29:D35) -> 5101.065 | E23: =SUM(E24, E29:E35) -> 5904.722 | F23: =SUM(F24, F29:F35) -> 6204.224 | G23: =SUM(G24, G29:G35) -> 6640.9316 | H23: =SUM(H24, H29:H35) -> 7361.7547 | I23: =SUM(I24, I29:I35) -> 8321.4765 | J23: =SUM(J24, J29:J35) -> 9656.278
B24: 유형자산 | C24: =SUM(C25:C28) -> 1048.81 | D24: =SUM(D25:D28) -> 1204.52 | E24: =SUM(E25:E28) -> 1289.154 | F24: =SUM(F25:F28) -> 1356.8789 | G24: =SUM(G25:G28) -> 1433.7669 | H24: =SUM(H25:H28) -> 1516.8607 | I24: =SUM(I25:I28) -> 1605.0907 | J24: =SUM(J25:J28) -> 1701.1241 | L24: =RATE(5, 0, -F24, J24) -> 0.046258457
B25: 토지 | C25: 363 | D25: 363.045 | E25: 368.27 | F25: =AVERAGE(C25:E25) -> 364.77167 | G25: =AVERAGE(D25:F25) -> 365.36222 | H25: =AVERAGE(E25:G25) -> 366.13463 | I25: =AVERAGE(F25:H25) -> 365.42284 | J25: =AVERAGE(G25:I25) -> 365.6399 | L25: flat한 경향으로 3개년 이동평균 적용
B26: 설비자산 | C26: 487.634 | D26: 628.474 | E26: 677.768 | F26: =E26*(1+$E$26/$D$26-1) -> 730.92835 | G26: =F26*(1+$E$26/$D$26-1) -> 788.2583 | H26: =G26*(1+$E$26/$D$26-1) -> 850.08489 | I26: =H26*(1+$E$26/$D$26-1) -> 916.76081 | J26: =I26*(1+$E$26/$D$26-1) -> 988.66642 | L26: 수주 증가에 따른 설비 확충 확대, 2022~2023년간 급증 이후 2024년부터 안정적 증가세로 전환, 이에 동일한 증가율로 추정
B27: 기타의유형자산 | C27: 19.959 | D27: 19.797 | E27: 19.283 | F27: =AVERAGE(C27:E27) -> 19.679667 | G27: =AVERAGE(D27:F27) -> 19.586556 | H27: =AVERAGE(E27:G27) -> 19.516407 | I27: =AVERAGE(F27:H27) -> 19.59421 | J27: =AVERAGE(G27:I27) -> 19.565724 | L27: flat한 경향으로 3개년 이동평균 적용
B28: 건설중인자산 | C28: 178.217 | D28: 193.204 | E28: 223.833 | F28: =E28*(1+RATE(3, 0, -$C$28, $E$28)) -> 241.49925 | G28: =F28*(1+RATE(3, 0, -$C$28, $E$28)) -> 260.55982 | H28: =G28*(1+RATE(3, 0, -$C$28, $E$28)) -> 281.12476 | I28: =H28*(1+RATE(3, 0, -$C$28, $E$28)) -> 303.31282 | J28: =I28*(1+RATE(3, 0, -$C$28, $E$28)) -> 327.25209 | L28: 건설업종 특성상 CAPEX 투자의 낮은 변동성이 예상되기에 과거 투자 추세를 반영하기 위해 3개년 CAGR 적용
B29: 무형자산 | C29: 720.626 | D29: 724.427 | E29: 750.741 | F29: =AVERAGE(C29:E29) -> 731.93133 | G29: =AVERAGE(D29:F29) -> 735.69978 | H29: =AVERAGE(E29:G29) -> 739.45737 | I29: =AVERAGE(F29:H29) -> 735.69616 | J29: =AVERAGE(G29:I29) -> 736.9511 | L29: flat한 경향으로 3개년 이동평균 적용
B30: 투자부동산 | C30: 444.482 | D30: 446.367 | E30: 456.522 | F30: =AVERAGE(C30:E30) -> 449.12367 | G30: =AVERAGE(D30:F30) -> 450.67089 | H30: =AVERAGE(E30:G30) -> 452.10552 | I30: =AVERAGE(F30:H30) -> 450.63336 | J30: =AVERAGE(G30:I30) -> 451.13659 | L30: flat한 경향으로 3개년 이동평균 적용
B31: 장기금융자산 | C31: 1468.342 | D31: 1130.464 | E31: 1222.068 | F31: =AVERAGE(C31:E31) -> 1273.6247 | G31: =AVERAGE(D31:F31) -> 1208.7189 | H31: =AVERAGE(E31:G31) -> 1234.8039 | I31: =AVERAGE(F31:H31) -> 1239.0491 | J31: =AVERAGE(G31:I31) -> 1227.524 | L31: flat한 경향으로 3개년 이동평균 적용
B32: 관계기업지분관련투자자산 | C32: 88.958 | D32: 86.608 | E32: 168.064 | F32: =AVERAGE(C32:D32) -> 87.783 | G32: =AVERAGE(C32:D32, F32) -> 87.783 | H32: =AVERAGE(F32:G32, D32) -> 87.391333 | I32: =AVERAGE(F32:H32) -> 87.652444 | J32: =AVERAGE(G32:I32) -> 87.608926 | L32: 2024년 일회성 요인으로 판단, 당해 연도 수치를 제외하여 3개년 이동 평균 적용
B33: 장기매출채권및기타비유동채권 | C33: 1085.757 | D33: 1003.101 | E33: 945.076 | F33: =E33*(1+RATE(3,0,-$C$33,$E$33)) -> 902.35639 | G33: =F33*(1+RATE(3,0,-$C$33,$E$33)) -> 861.56781 | H33: =G33*(1+RATE(3,0,-$C$33,$E$33)) -> 822.62297 | I33: =H33*(1+RATE(3,0,-$C$33,$E$33)) -> 785.43852 | J33: =I33*(1+RATE(3,0,-$C$33,$E$33)) -> 749.93489 | L33: 최근 3년간 연평균 약 -4.5% 감소, 이는 장기미수금 및 PF채권 회수 확대 등에 기인한 것으로 판단, 향후에도 동일한 흐름이 이어질 것으로 보아 해당 수치 적용
B34: 이연법인세자산 | C34: 248.31 | D34: 232.146 | E34: 717.126 | F34: =E34*(1+RATE(3, 0, -$C$34, $E$34)) -> 1021.2433 | G34: =F34*(1+RATE(3, 0, -$C$34, $E$34)) -> 1454.33 | H34: =G34*(1+RATE(3, 0, -$C$34, $E$34)) -> 2071.0793 | I34: =H34*(1+RATE(3, 0, -$C$34, $E$34)) -> 2949.3783 | J34: =I34*(1+RATE(3, 0, -$C$34, $E$34)) -> 4200.1445 | L34: 보수적 추정과 과거 추세를 반영하기 위해 3개년 CAGR 적용
B35: 기타비유동자산 | C35: 289.679 | D35: 273.432 | E35: 355.971 | F35: =E35*(1+RATE(3, 0, -$C$35, $E$35)) -> 381.28275 | G35: =F35*(1+RATE(3, 0, -$C$35, $E$35)) -> 408.39432 | H35: =G35*(1+RATE(3, 0, -$C$35, $E$35)) -> 437.43369 | I35: =H35*(1+RATE(3, 0, -$C$35, $E$35)) -> 468.53794 | J35: =I35*(1+RATE(3, 0, -$C$35, $E$35)) -> 501.85389 | L35: 장기선급비용, 기타의비유동자산 등 다양한 항목으로 구성되어 있기에 별도 추정이 곤란, 과거 3개년 성장률 적용
B36: 부채총계 | C36: =SUM(C37, C52) -> 10987.431 | D36: =SUM(D37, D52) -> 13258.98 | E36: =SUM(E37, E52) -> 17335.972 | F36: =SUM(F37, F52) -> 19401.996 | G36: =SUM(G37, G52) -> 19153.818 | H36: =SUM(H37, H52) -> 20626.331 | I36: =SUM(I37, I52) -> 20719.322 | J36: =SUM(J37, J52) -> 18656.691
B37: 유동부채 | C37: =SUM(C38:C41, C46, C50:C51) -> 8757.397 | D37: =SUM(D38:D41, D46, D50:D51) -> 10356.647 | E37: =SUM(E38:E41, E46, E50:E51) -> 14663.775 | F37: =SUM(F38:F41, F46, F50:F51) -> 16634.944 | G37: =SUM(G38:G41, G46, G50:G51) -> 16311.36 | H37: =SUM(H38:H41, H46, H50:H51) -> 17755.686 | I37: =SUM(I38:I41, I46, I50:I51) -> 17699.105 | J37: =SUM(J38:J41, J46, J50:J51) -> 15405.442
B38: 단기차입금 | C38: 83.142 | D38: 248.744 | E38: 744.668 | F38: =AVERAGE(C38:D38) -> 165.943 | G38: =AVERAGE(C38:D38, F38) -> 165.943 | H38: =AVERAGE(D38, F38:G38) -> 193.54333 | I38: =AVERAGE(F38:H38) -> 175.14311 | J38: =AVERAGE(G38:I38) -> 178.20981 | L38: 2024년 급증은 일회성 요인으로 판단, 해당 연도 제외 후 3개년 이동평균 적용
B39: 유동성장기부채 | C39: 519.361 | D39: 354.365 | E39: 1044.694 | F39: =AVERAGE(C39:D39) -> 436.863 | G39: =AVERAGE(C39:D39, F39) -> 436.863 | H39: =AVERAGE(D39, F39:G39) -> 409.36367 | I39: =AVERAGE(F39:H39) -> 427.69656 | J39: =AVERAGE(G39:I39) -> 424.64107 | L39: 2024년 급증은 일회성 요인으로 판단, 해당 연도 제외 후 3개년 이동평균 적용
B40: 유동금융부채 | C40: 41.815 | D40: 41.356 | E40: 142.963 | F40: =AVERAGE(C40:D40) -> 41.5855 | G40: =AVERAGE(C40:D40, F40) -> 41.5855 | H40: =AVERAGE(D40, F40:G40) -> 41.509 | I40: =AVERAGE(F40:H40) -> 41.56 | J40: =AVERAGE(G40:I40) -> 41.5515 | L40: 2024년 급증은 일회성 요인으로 판단, 해당 연도 제외 후 3개년 이동평균 적용
B41: 매입채무및기타유동채무 | C41: =SUM(C42:C45) -> 6806.363 | D41: =SUM(D42:D45) -> 7714.943 | E41: =SUM(E42:E45) -> 9940.085 | F41: =SUM(F42:F45) -> 9726.6977 | G41: =SUM(G42:G45) -> 9915.1068 | H41: =SUM(H42:H45) -> 10123.939 | I41: =SUM(I42:I45) -> 10280.581 | J41: =SUM(J42:J45) -> 10411.619
B42: 매입채무 | C42: 2598.796 | D42: 3959.03 | E42: 4038.662 | F42: =E42*(1+$E$42/$D$42-1) -> 4119.8957 | G42: =F42*(1+$E$42/$D$42-1) -> 4202.7634 | H42: =G42*(1+$E$42/$D$42-1) -> 4287.2978 | I42: =H42*(1+$E$42/$D$42-1) -> 4373.5326 | J42: =I42*(1+$E$42/$D$42-1) -> 4461.5019 | L42: 최근 급증세(2022~2023) 이후 2024년에는 증가세가 둔화, 향후 사업 확장에 따른 증가가 예상되기에 급증 시기 수치를 적용
...

Sheet Expected IS
B1: 추정 손익계산서
B5: 추정 손익계산서
B6: (단위: 십억 원) | C6: 2022 | D6: 2023 | E6: 2024 | F6: 2025E | G6: 2026E | H6: 2027E | I6: 2028E | J6: 2029E
B7: 매출액 | C7: 21239.082 | D7: 29651.357 | E7: 32670.268 | F7: =총매출!F25 -> 31025.542 | G7: =총매출!G25 -> 32003.686 | H7: =총매출!H25 -> 33081.647 | I7: =총매출!I25 -> 34552.283 | J7: =총매출!J25 -> 37172.773
B8: YoY(%) | C8: =(C7/18065534)-1 -> -0.99882433 | D8: =(D7/C7)-1 -> 0.39607526 | E8: =(E7/D7)-1 -> 0.10181359 | F8: =F7/E7-1 -> -0.050343204 | G8: =G7/F7-1 -> 0.031527069 | H8: =H7/G7-1 -> 0.033682379 | I8: =I7/H7-1 -> 0.044454745 | J8: =J7/I7-1 -> 0.075841287
B9: 매출원가 | C9: 19726.334 | D9: 27948.549 | E9: 32887.201 | F9: =영업비용추정!F10 -> 29477.928 | G9: =영업비용추정!G10 -> 29925.842 | H9: =영업비용추정!H10 -> 30504.859 | I9: =영업비용추정!I10 -> 31853.049 | J9: =영업비용추정!J10 -> 34247.952
B10: 매출총이익 | C10: 1512.748 | D10: 1702.808 | E10: -216.933 | F10: =F7-F9 -> 1547.6141 | G10: =G7-G9 -> 2077.8441 | H10: =H7-H9 -> 2576.7879 | I10: =I7-I9 -> 2699.2344 | J10: =J7-J9 -> 2924.8206
B11: GPM(%) | C11: =C10/C7 -> 0.071224736 | D11: =D10/D7 -> 0.057427658 | E11: =E10/E7 -> -0.0066400741 | F11: =F10/F7 -> 0.049881936 | G11: =G10/G7 -> 0.064925149 | H11: =H10/H7 -> 0.077891766 | I11: =I10/I7 -> 0.07812029 | J11: =J10/J7 -> 0.078681798 | O11: `
B12: 판매비와 관리비 | C12: 937.846 | D12: 917.378 | E12: 1046.487 | F12: =영업비용추정!F32 -> 1079.8136 | G12: =영업비용추정!G32 -> 1070.4019 | H12: =영업비용추정!H32 -> 1116.1486 | I12: =영업비용추정!I32 -> 1153.7349 | J12: =영업비용추정!J32 -> 1194.2343
B13: 영업이익 | C13: 574.902 | D13: 785.43 | E13: -1263.42 | F13: =F10-F12 -> 467.80055 | G13: =G10-G12 -> 1007.4422 | H13: =H10-H12 -> 1460.6393 | I13: =I10-I12 -> 1545.4995 | J13: =J10-J12 -> 1730.5863
B14: OPM(%) | C14: =C13/C7 -> 0.027068119 | D14: =D13/D7 -> 0.026488838 | E14: =E13/E7 -> -0.038671859 | F14: =F13/F7 -> 0.015077917 | G14: =G13/G7 -> 0.031478942 | H14: =H13/H7 -> 0.044152557 | I14: =I13/I7 -> 0.044729302 | J14: =J13/J7 -> 0.046555212
B15: 금융수익 | C15: 401.429 | D15: 294.585 | E15: 359.853 | F15: =AVERAGE(C15:E15) -> 351.95567 | G15: =AVERAGE(D15:F15) -> 335.46456 | H15: =AVERAGE(E15:G15) -> 349.09107 | I15: =AVERAGE(F15:H15) -> 345.50377 | J15: =AVERAGE(G15:I15) -> 343.35313 | K15: [이동평균] 특별한 경향성 없어 3개년 이동평균
B16: 금융비용 | C16: 176.777 | D16: 141.179 | E16: 171.771 | F16: =AVERAGE(C16:E16) -> 163.24233 | G16: =AVERAGE(D16:F16) -> 158.73078 | H16: =AVERAGE(E16:G16) -> 164.58137 | I16: =AVERAGE(F16:H16) -> 162.18483 | J16: =AVERAGE(G16:I16) -> 161.83233 | K16: [이동평균] 특별한 경향성 없어 3개년 이동평균
B17: 기타수익 | C17: 435.786 | D17: 504.788 | E17: 839.957 | F17: =AVERAGE(C17:E17) -> 593.51033 | G17: =AVERAGE(D17:F17) -> 646.08511 | H17: =AVERAGE(E17:G17) -> 693.18415 | I17: =AVERAGE(F17:H17) -> 644.25986 | J17: =AVERAGE(G17:I17) -> 661.17637 | K17: [이동평균] 특별한 경향성 없어 3개년 이동평균
B18: 기타비용 | C18: 468.852 | D18: 498.799 | E18: 755.911 | F18: =AVERAGE(C18:E18) -> 574.52067 | G18: =AVERAGE(D18:F18) -> 609.74356 | H18: =AVERAGE(E18:G18) -> 646.72507 | I18: =AVERAGE(F18:H18) -> 610.32977 | J18: =AVERAGE(G18:I18) -> 622.26613 | K18: [이동평균] 특별한 경향성 없어 3개년 이동평균
B19: 관계기업투자손익 | C19: -12.673 | D19: -5.28 | E19: 5.575 | F19: =AVERAGE(C19:E19) -> -4.126 | G19: =AVERAGE(D19:F19) -> -1.277 | H19: =AVERAGE(E19:G19) -> 0.057333333 | I19: =AVERAGE(F19:H19) -> -1.7818889 | J19: =AVERAGE(G19:I19) -> -1.0005185 | K19: [이동평균] 특별한 경향성 없어 3개년 이동평균
B20: 법인세비용 차감 전 순이익 | C20: 753.815 | D20: 939.545 | E20: -985.717 | F20: =F13+F15-F16+F17-F18+F19 -> 671.37755 | G20: =G13+G15-G16+G17-G18+G19 -> 1219.2405 | H20: =H13+H15-H16+H17-H18+H19 -> 1691.6654 | I20: =I13+I15-I16+I17-I18+I19 -> 1760.9666 | J20: =J13+J15-J16+J17-J18+J19 -> 1950.0168
B21: 법인세비용 | C21: 282.939 | D21: 285.264 | E21: -219.496 | F21: =F20*GEOMEAN($C$21/$C$20, $D$21/$D$20, $E$21/$E$20) -> 197.29258 | G21: =G20*GEOMEAN($C$21/$C$20, $D$21/$D$20, $E$21/$E$20) -> 358.28887 | H21: =H20*GEOMEAN($C$21/$C$20, $D$21/$D$20, $E$21/$E$20) -> 497.11674 | I21: =I20*GEOMEAN($C$21/$C$20, $D$21/$D$20, $E$21/$E$20) -> 517.48177 | J21: =J20*GEOMEAN($C$21/$C$20, $D$21/$D$20, $E$21/$E$20) -> 573.03651 | K21: [추정논리] 보수적 추정을 위해 한계세율보다 높은 법인세비용차감전순이익 대비 법인세비용 비율의 3개년 평균 29.4% 적용
B22: 당기순이익 | C22: 470.876 | D22: 654.281 | E22: -766.221 | F22: =F20-F21 -> 474.08498 | G22: =G20-G21 -> 860.95166 | H22: =H20-H21 -> 1194.5486 | I22: =I20-I21 -> 1243.4849 | J22: =J20-J21 -> 1376.9803
B23: NPM(%) | C23: =C22/C7 -> 0.022170261 | D23: =D22/D7 -> 0.022065803 | E23: =E22/E7 -> -0.023453159 | F23: =F22/F7 -> 0.015280474 | G23: =G22/G7 -> 0.02690164 | H23: =H22/H7 -> 0.036109105 | I23: =I22/I7 -> 0.035988501 | J23: =J22/J7 -> 0.037042713

Sheet 총매출
B1: 전체 매출
B5: 전체 신규수주
B6: (단위: 십억 원) | C6: 2022 | D6: 2023 | E6: 2024 | F6: 2025E | G6: 2026E | H6: 2027E | I6: 2028E | J6: 2029E
B7: 전체 신규수주(연간) | C7: =SUM(C8:C11) -> 34376.181 | D7: 29651.4 | E7: 32670.3 | F7: =SUM(F8:F11) -> 37794.116 | G7: =SUM(G8:G11) -> 31194.005 | H7: =SUM(H8:H11) -> 36473.631 | I7: =SUM(I8:I11) -> 39124.591 | J7: =SUM(J8:J11) -> 43401.898
B8: 건축주택 | C8: =건축주택!E7 -> 24480 | D8: =건축주택!F7 -> 19942.1 | E8: =건축주택!G7 -> 21454.5 | F8: =건축주택!H7 -> 25245.612 | G8: =건축주택!I7 -> 22120.445 | H8: =건축주택!J7 -> 22811.32 | I8: =건축주택!K7 -> 23489.777 | J8: =건축주택!L7 -> 22822.032
B9: 플랜트 | C9: =플랜트!C7 -> 5171.8 | D9: =플랜트!D7 -> 5584.7 | E9: =플랜트!E7 -> 5788.3 | F9: =플랜트!F7 -> 7840 | G9: =플랜트!G7 -> 5089.1 | H9: =플랜트!H7 -> 9045.525 | I9: =플랜트!I7 -> 11198.231 | J9: =플랜트!J7 -> 16233.923
B10: 토목 | C10: ='토목 및 기타'!C7 -> 3930.32 | D10: ='토목 및 기타'!D7 -> 2104.8 | E10: ='토목 및 기타'!E7 -> 3849.422 | F10: ='토목 및 기타'!F7 -> 3427.864 | G10: ='토목 및 기타'!G7 -> 2962.016 | H10: ='토목 및 기타'!H7 -> 3413.1007 | I10: ='토목 및 기타'!I7 -> 3267.6602 | J10: ='토목 및 기타'!J7 -> 3214.259
B11: 기타 | C11: ='토목 및 기타'!C8 -> 794.061 | D11: ='토목 및 기타'!D8 -> 1128.385 | E11: ='토목 및 기타'!E8 -> 1307.9721 | F11: ='토목 및 기타'!F8 -> 1280.6402 | G11: ='토목 및 기타'!G8 -> 1022.4438 | H11: ='토목 및 기타'!H8 -> 1203.6854 | I11: ='토목 및 기타'!I8 -> 1168.9231 | J11: ='토목 및 기타'!J8 -> 1131.6841
B14: 전체 수주잔고
B15: (단위: 십억 원) | C15: 2022 | D15: 2023 | E15: 2024 | F15: 2025E | G15: 2026E | H15: 2027E | I15: 2028E | J15: 2029E
B16: 전체 수주잔고(연간) | C16: =SUM(C17:C20) -> 88367.128 | D16: =SUM(D17:D20) -> 89744.978 | E16: =SUM(E17:E20) -> 89900 | F16: =SUM(F17:F20) -> 87348.903 | G16: =SUM(G17:G20) -> 92263.623 | H16: =SUM(H17:H20) -> 101808.32 | I16: =SUM(I17:I20) -> 109255.37 | J16: =SUM(J17:J20) -> 106908.2
B17: 건축주택 | C17: =건축주택!E14 -> 60033 | D17: =건축주택!F14 -> 59317.5 | E17: =건축주택!G14 -> 59333 | F17: =건축주택!H14 -> 64650.241 | G17: =건축주택!I14 -> 65710.867 | H17: =건축주택!J14 -> 67451.4 | I17: =건축주택!K14 -> 69021.794 | J17: =건축주택!L14 -> 68936.021
B18: 플랜트 | C18: =플랜트!E14 -> 13678.4 | D18: =플랜트!F14 -> 13910.3 | E18: =플랜트!G14 -> 17320 | F18: =플랜트!H14 -> 18676.184 | G18: =플랜트!I14 -> 22445.114 | H18: =플랜트!J14 -> 30206.021 | I18: =플랜트!K14 -> 36063.191 | J18: =플랜트!L14 -> 33729.563
B19: 토목 | C19: 12157.76 | D19: 13923.76 | E19: 10840 | F19: ='토목 및 기타'!H17 -> 2639.1039 | G19: ='토목 및 기타'!I17 -> 2827.541 | H19: ='토목 및 기타'!J17 -> 2934.6923 | I19: ='토목 및 기타'!K17 -> 3002.7555 | J19: ='토목 및 기타'!L17 -> 3074.7184
B20: 기타 | C20: 2497.968 | D20: 2593.418 | E20: 2407 | F20: ='토목 및 기타'!H18 -> 1383.3745 | G20: ='토목 및 기타'!I18 -> 1280.1018 | H20: ='토목 및 기타'!J18 -> 1216.2041 | I20: ='토목 및 기타'!K18 -> 1167.6279 | J20: ='토목 및 기타'!L18 -> 1167.8978
B21: *기존 수주의 경우, 연결 기준 수주잔고가 공시되지 않아, 종속 기업의 매출 비중에 따라 사업부별로 분류하였다.
B23: 전체 매출
B24: (단위: 십억 원) | C24: 2022 | D24: 2023 | E24: 2024 | F24: 2025E | G24: 2026E | H24: 2027E | I24: 2028E | J24: 2029E
B25: 전체 매출(연간) | C25: 21239.1 | D25: 29651.4 | E25: 32670.3 | F25: =SUM(F26:F30) -> 31025.542 | G25: =SUM(G26:G30) -> 32003.686 | H25: =SUM(H26:H30) -> 33081.647 | I25: =SUM(I26:I30) -> 34552.283 | J25: =SUM(J26:J30) -> 37172.773
B26: 건축주택 | C26: 12501.1 | D26: 19699.9 | E26: 21999.1 | F26: =건축주택!H21 -> 19928.372 | G26: =건축주택!I21 -> 21059.819 | H26: =건축주택!J21 -> 21070.786 | I26: =건축주택!K21 -> 21919.382 | J26: =건축주택!L21 -> 22907.805
B27: 플랜트 | C27: 5386.9 | D27: 6569.1 | E27: 6830.4 | F27: =플랜트!H21 -> 7649.6414 | G27: =플랜트!I21 -> 7429.3008 | H27: =플랜트!J21 -> 8473.0161 | I27: =플랜트!K21 -> 9102.8225 | J27: =플랜트!L21 -> 10711.219
B28: 토목 | C28: 2458 | D28: 2740 | E28: 2780.2 | F28: ='토목 및 기타'!H17 -> 2639.1039 | G28: ='토목 및 기타'!I17 -> 2827.541 | H28: ='토목 및 기타'!J17 -> 2934.6923 | I28: ='토목 및 기타'!K17 -> 3002.7555 | J28: ='토목 및 기타'!L17 -> 3074.7184
B29: 기타 | C29: 1296.5 | D29: 1336.2 | E29: 1492.4 | F29: ='토목 및 기타'!H18 -> 1383.3745 | G29: ='토목 및 기타'!I18 -> 1280.1018 | H29: ='토목 및 기타'!J18 -> 1216.2041 | I29: ='토목 및 기타'!K18 -> 1167.6279 | J29: ='토목 및 기타'!L18 -> 1167.8978
B30: 내부거래 제거 | C30: -403.5 | D30: -693.9 | E30: -431.9 | F30: =SUM(F26:F29)*E34 -> -574.94947 | G30: =SUM(G26:G29)*$E$34 -> -593.07594 | H30: =SUM(H26:H29)*$E$34 -> -613.05215 | I30: =SUM(I26:I29)*$E$34 -> -640.30523 | J30: =SUM(J26:J29)*$E$34 -> -688.8668 | K30: [Avg Rate] 내부거래 전 매출액 중 과거 내부거래액 평균 비중 적용하여 추정
B33: 내부거래 제거 비중 | C33: =C30/SUM(C26:C29) -> -0.018643872 | D33: =D30/SUM(D26:D29) -> -0.022866878 | E33: =E30/SUM(E26:E29) -> -0.013047511
D34: Geomean | E34: {=GEOMEAN(C33:E33+1)-1} -> -0.01819432

Sheet 건축주택
B1: 건축/주택 매출
B5: 건축/주택 부문 신규수주
B6: (단위: 십억 원) | C6: 2020 | D6: 2021 | E6: 2022 | F6: 2023 | G6: 2024 | H6: 2025E | I6: 2026E | J6: 2027E | K6: 2028E | L6: 2029E
B7: 건축/주택 | C7: 17263 | D7: 21451.1 | E7: 24480 | F7: 19942.1 | G7: 21454.5 | H7: =H8+H9 -> 25245.612 | I7: =I8+I9 -> 22120.445 | J7: =J8+J9 -> 22811.32 | K7: =K8+K9 -> 23489.777 | L7: =L8+L9 -> 22822.032
B8: 도시정비사업 | C8: 5301 | D8: 7402.651 | E8: 11404.6 | F8: 6902.2 | G8: 7639.4 | H8: ='건축주택-정비사업'!H7 -> 11750.9 | I8: ='건축주택-정비사업'!I7 -> 8764.1667 | J8: ='건축주택-정비사업'!J7 -> 9384.8222 | K8: ='건축주택-정비사업'!K7 -> 9966.6296 | L8: ='건축주택-정비사업'!L7 -> 9371.8728 | M8: [별도추정] '건축주택-정비사업' 시트 참고
B9: 비도시정비사업 | C9: 11962 | D9: 14048.449 | E9: 13075.4 | F9: 13039.9 | G9: 13815.1 | H9: =AVERAGE(D9:G9) -> 13494.712 | I9: =AVERAGE(E9:H9) -> 13356.278 | J9: =AVERAGE(F9:I9) -> 13426.498 | K9: =AVERAGE(G9:J9) -> 13523.147 | L9: =AVERAGE(H9:K9) -> 13450.159 | M9: [이동평균] 투자분석 과정에서 특이적 투자아이디어 발견할 수 없고 특별한 경향성 없어 4개년 이동평균 활용하여 보수적 추정
B12: 건축/주택 부문 수주잔고
B13: (단위: 십억 원) | C13: 2020 | D13: 2021 | E13: 2022 | F13: 2023 | G13: 2024 | H13: 2025E | I13: 2026E | J13: 2027E | K13: 2028E | L13: 2029E
B14: 건축/주택 | C14: 43815.6 | D14: 53361.4 | E14: 60033 | F14: 59317.5 | G14: 59333 | H14: =H15+H16 -> 64650.241 | I14: =I15+I16 -> 65710.867 | J14: =J15+J16 -> 67451.4 | K14: =K15+K16 -> 69021.794 | L14: =L15+L16 -> 68936.021
B15: 도시정비사업 | C15: 13454.585 | D15: 16136.267 | E15: 34332.009 | F15: 19083.234 | G15: 19234.017 | H15: ='건축주택-정비사업'!H8 -> 22463.255 | I15: ='건축주택-정비사업'!I8 -> 22168.273 | J15: ='건축주택-정비사업'!J8 -> 22868.601 | K15: ='건축주택-정비사업'!K8 -> 23598.041 | L15: ='건축주택-정비사업'!L8 -> 22983.524 | M15: [별도추정] '건축주택-정비사업' 시트 참고
B16: 비도시정비사업 | C16: 30361.015 | D16: 37225.133 | E16: 25700.991 | F16: 40234.266 | G16: 40098.983 | H16: =G16-H23+H9 -> 42186.986 | I16: =H16-I23+I9 -> 43542.593 | J16: =I16-J23+J9 -> 44582.799 | K16: =J16-K23+K9 -> 45423.753 | L16: =K16-L23+L9 -> 45952.498 | M16: [잔고 계산] 수주잔고 = 전기 수주잔고 - 당기 매출액 + 당기 신규수주
B17: *IR 및 언론 발표 자료를 통해 도시정비사업과 그 외 비도시정비사업의 수주잔고로 분류
B19: 건축/주택 부문 매출액
B20: (단위: 십억 원) | C20: 2020 | D20: 2021 | E20: 2022 | F20: 2023 | G20: 2024 | H20: 2025E | I20: 2026E | J20: 2027E | K20: 2028E | L20: 2029E
B21: 건축/주택 | C21: 11484.82 | D21: 14600.112 | E21: 16756.501 | F21: 20264.378 | G21: 22507.037 | H21: =H22+H23 -> 19928.372 | I21: =I22+I23 -> 21059.819 | J21: =J22+J23 -> 21070.786 | K21: =K22+K23 -> 21919.382 | L21: =L22+L23 -> 22907.805
B22: 도시정비사업 | C22: 2740.3802 | D22: 3119.9392 | E22: 7149.1992 | F22: 6337.7217 | G22: 7131.4625 | H22: ='건축주택-정비사업'!H9 -> 8521.6623 | I22: ='건축주택-정비사업'!I9 -> 9059.1481 | J22: ='건축주택-정비사업'!J9 -> 8684.4945 | K22: ='건축주택-정비사업'!K9 -> 9237.1893 | L22: ='건축주택-정비사업'!L9 -> 9986.3907 | M22: [별도추정] '건축주택-정비사업' 시트 참고
B23: 비도시정비사업 | C23: 6183.8198 | D23: 7197.4608 | E23: 5351.9008 | F23: 13362.178 | G23: 14867.637 | H23: =G16*$C$31 -> 11406.709 | I23: =H16*$C$31 -> 12000.671 | J23: =I16*$C$31 -> 12386.292 | K23: =J16*$C$31 -> 12682.193 | L23: =K16*$C$31 -> 12921.414 | M23: [전환율 기반] 5년 평균 매출전환율 고려하여 전기 수주잔고에 적용하여 매출액 추정
B26: 비정비사업 매출전환율 추정
B27: (단위: 십억 원) | C27: 2020 | D27: 2021 | E27: 2022 | F27: 2023 | G27: 2024
B28: 수주잔고 | C28: 30361.015 | D28: 37225.133 | E28: 25700.991 | F28: 40234.266 | G28: 40098.983
B29: 매출액 | C29: 6183.8198 | D29: 7197.4608 | E29: 5351.9008 | F29: 13362.178 | G29: 14867.637
B30: 매출전환율 | D30: =D29/C28 -> 0.23706259 | E30: =E29/D28 -> 0.14377117 | F30: =F29/E28 -> 0.51990906 | G30: =G29/F28 -> 0.36952675
B31: Avg 매출전환율 | C31: =GEOMEAN(D30:G30) -> 0.28446381
B32: *매출전환율(BBR) = 당기 매출액/전기 수주잔고

Sheet 건축주택-정비사업
B1: 건축/주택 - 정비사업 추정
B5: 도시정비사업 수주 및 매출 추정(종합)
B6: (단위: 십억 원) | C6: 2020 | D6: 2021 | E6: 2022 | F6: 2023 | G6: 2024 | H6: 2025E | I6: 2026E | J6: 2027E | K6: 2028E | L6: 2029E
B7: 신규수주 | C7: 5301 | D7: 7402.651 | E7: 11404.6 | F7: 6902.2 | G7: 7639.4 | H7: =H19 -> 11750.9 | I7: =I19 -> 8764.1667 | J7: =J19 -> 9384.8222 | K7: =K19 -> 9966.6296 | L7: =L19 -> 9371.8728
B8: 수주잔고 | C8: 13454.585 | D8: 16136.267 | E8: 34332.009 | F8: 19083.234 | G8: 19234.017 | H8: =G8+H7-H9 -> 22463.255 | I8: =H8+I7-I9 -> 22168.273 | J8: =I8+J7-J9 -> 22868.601 | K8: =J8+K7-K9 -> 23598.041 | L8: =K8+L7-L9 -> 22983.524
B9: 매출 | C9: 5301 | D9: 7402.651 | E9: 11404.6 | F9: 6902.2 | G9: 7639.4 | H9: =H10+H11 -> 8521.6623 | I9: =I10+I11 -> 9059.1481 | J9: =J10+J11 -> 8684.4945 | K9: =K10+K11 -> 9237.1893 | L9: =L10+L11 -> 9986.3907
B10: 신규수주분 | C10: 0 | D10: 0 | E10: 0 | F10: 0 | G10: 0 | H10: =G47 -> 0 | I10: =H47 -> 0 | J10: =I47 -> 546.69662 | K10: =J47 -> 1595.7533 | L10: =K47 -> 2808.9156
B11: 기존수주분 | C11: 0 | D11: 0 | E11: 0 | F11: 0 | G11: 0 | H11: =H56 -> 8521.6623 | I11: =I56 -> 9059.1481 | J11: =J56 -> 8137.7978 | K11: =K56 -> 7641.436 | L11: =L56 -> 7177.4751
B14: 도시정비사업 신규수주 추정
B17: 도시정비사업 신규수주 추정
B18: (단위: 십억 원) | C18: 2020 | D18: 2021 | E18: 2022 | F18: 2023 | G18: 2024 | H18: 2025E | I18: 2026E | J18: 2027E | K18: 2028E | L18: 2029E | N18: 신규수주 추정논리
B19: 신규수주 | C19: 5301 | D19: 7402.651 | E19: 11404.6 | F19: 6902.2 | G19: 7639.4 | H19: =도시정비_RAW!H134 -> 11750.9 | I19: =AVERAGE(F19:H19) -> 8764.1667 | J19: =AVERAGE(G19:I19) -> 9384.8222 | K19: =AVERAGE(H19:J19) -> 9966.6296 | L19: =AVERAGE(I19:K19) -> 9371.8728 | N19: 1. 2025년의 경우 기확보한 수주누계와 향후 연내 수주가능성 높은 사업지를 보수적으로 고려하여 추정함('2025년 신규수주 누계 및 추정' 표 참조)
B20: YoY(%) | C20: =C19/1954.3-1 -> 1.7124802 | D20: =D19/C19-1 -> 0.39646312 | E20: =E19/D19-1 -> 0.54061025 | F20: =F19/E19-1 -> -0.39478807 | G20: =G19/F19-1 -> 0.10680653 | H20: =H19/G19-1 -> 0.53819672 | I20: =I19/H19-1 -> -0.2541706 | J20: =J19/I19-1 -> 0.070817407 | K20: =K19/J19-1 -> 0.061994505 | L20: =L19/K19-1 -> -0.059674816 | N20: 2. 2026~2029년의 경우 전국 사업지 진행상황 추정에 한계가 있어, 3년 이동평균 적용하여 추정함
B23: 2025년 신규수주 누계 및 추정
B24: (단위: 십억 원) | D24: 시공사선정일 | E24: 수주금액 | F24: 비고
B25: 부산 연산5구역 재건축 | D25: 45739 | E25: 765.7 | F25: 롯데건설과의 컨소시엄 단위로서 총 공사비 1444.7십억 중 53% 지분
B26: 수원 구운1구역 재건축 | D26: 45745 | E26: 312.3 | F26: 롯데건설과의 컨소시엄 단위로서 총 공사비 665.0십억 중 47% 지분
B27: 서울 장위9구역 재개발 | D27: 45773 | E27: 350.2 | F27: DL이앤씨와의 컨소시엄 단위로서 총 공사비 875.5십억 중 40% 지분
B28: 서울 개포주공 6·7단지 재건축 | D28: 45801 | E28: 1513.8 | F28: 단독 수주
B29: 서울 면목7구역 재개발 | D29: 45822 | E29: 291.9 | F29: SK에코플랜트와의 컨소시엄 단위로서 총 공사비 595.8십억 중 49% 지분
B30: 구리 수택동 재개발 | D30: 45829 | E30: 1964.8 | F30: 포스코이앤씨와의 컨소시엄 단위로서 총 공사비 2806.9십억 중 70% 지분
B31: 서울 미아9-2구역 재건축 | D31: 45836 | E31: 337 | F31: HDC현대산업개발과의 컨소시엄 단위로서 총 공사비 635.8십억 중 53% 지분
B32: 서울 압구정2구역 재건축 | D32: 9월 총회 예정 | E32: 2748.8
B33: 서울 장위15구역 재개발 | D33: 9월 총회 추정 | E33: 1466.3 | F33: 1차 단독입찰로 유찰, 2차 입찰 9월 예정으로 가능성 높음
B34: 서울 성수1지구 재개발 | D34: 연내 선정 예정 | E34: 2000 | F34: 유력건설사인 GS건설 향응제공으로 자격박탈 가능성 높아, 박탈 시 동사 유력
B35: 총합 | E35: =SUM(E25:E34) -> 11750.8
B38: 도시정비사업 매출 추정
B40: (1) 신규수주분 매출 추정
B42: 신규수주분 매출 추정 | N42: 신규수주분 매출 추정논리
B43: 기준연도 | C43: 신규수주 누적액 | D43: 착공연도 | E43: 착공률 | F43: 착공규모 | G43: 2025E | H43: 2026E | I43: 2027E | J43: 2028E | K43: 2029E | N43: 1. 신규수주 중 지연되지 않고 정상착공 진행될 비율은, 동사 공시를 기반으로 35.4%로 추정함.('정상착공율 추정' 표 참조)
B44: 2025E | C44: =H7 -> 11750.9 | D44: 2027E | E44: 0.3542 | F44: =C44*E44 -> 4162.1688 | G44: 0 | H44: 0 | I44: =$F44*I67 -> 546.69662 | J44: =$F44*J67 -> 1188.0109 | K44: =$F44*K67 -> 1486.2445 | N44: 2. 정상착공사업은 수주에서 착공시점까지 2년 소요됨을 고려하여, 기준연도 신규수주분은 2년 뒤 착공될 것으로 가정함.('수주-착공 소요기간' 표 참조)
B45: 2026E | C45: =I7 -> 8764.1667 | D45: 2028E | E45: 0.3542 | F45: =C45*E45 -> 3104.2678 | G45: 0 | H45: 0 | I45: 0 | J45: =$F45*I67 -> 407.74241 | K45: =$F45*J67 -> 886.05345 | N45: 3. 해당연도에 착공되는 물량은 도시정비사업 기간별 진행률에 따라 매출 추정함.('기간별 진행률 추정' 표 참조)
B46: 2027E | C46: =J7 -> 9384.8222 | D46: 2029E | E46: 0.3542 | F46: =C46*E46 -> 3324.104 | G46: 0 | H46: 0 | I46: 0 | J46: 0 | K46: =F46*I67 -> 436.61767
F47: 매출액 | I47: =SUM(I44:I46) -> 546.69662 | J47: =SUM(J44:J46) -> 1595.7533 | K47: =SUM(K44:K46) -> 2808.9156
B51: (2) 기존수주분 매출 추정
B53: 기존수주분 매출 추정 | N53: 기존수주분 매출 추정논리
B54: (단위: 십억 원) | C54: 2020 | D54: 2021 | E54: 2022 | F54: 2023 | G54: 2024 | H54: 2025E | I54: 2026E | J54: 2027E | K54: 2028E | L54: 2029E | N54: 1. 기존수주 수주잔고에 매출전환율을 곱하여 매출 추정함.
B55: 기존수주 | C55: =C8 -> 13454.585 | D55: =D8 -> 16136.267 | E55: =E8 -> 34332.009 | F55: =F8 -> 19083.234 | G55: =G8 -> 19234.017 | H55: =G55-H56+H7 -> 22463.255 | I55: =H55-I56+I7 -> 22168.273 | J55: =I55-J56+J7-I47 -> 22868.601 | K55: =J55-K56+K7-J47 -> 23598.041 | L55: =K55-L56+L7-K47 -> 22983.524 | N55: 2. 매출전환율은 투자포인트1에서 언급하였듯이 규제완화와 경기진작에 따라 착공률 증가할 것으로 전망, 이에 주택경기 호황이던 2022년 매출전환율을 25년 적용 후, 29년까지 평균 수준으로 체감하도록 추정함.
B56: 기존수주 매출 | C56: 2740.3802 | D56: 3119.9392 | E56: 7149.1992 | F56: 6337.7217 | G56: 7131.4625 | H56: =G55*H57 -> 8521.6623 | I56: =H55*I57 -> 9059.1481 | J56: =I55*J57 -> 8137.7978 | K56: =J55*K57 -> 7641.436 | L56: =K55*L57 -> 7177.4751
B57: 매출전환율 | D57: =D56/C55 -> 0.2318867 | E57: =E56/D55 -> 0.44305161 | F57: =F56/E55 -> 0.18460096 | G57: =G56/F55 -> 0.37370303 | H57: =E57 -> 0.44305161 | I57: =H57*(1+RATE(4,0,-$H$57,$L$57)) -> 0.40328742 | J57: =I57*(1+RATE(4,0,-$H$57,$L$57)) -> 0.36709209 | K57: =J57*(1+RATE(4,0,-$H$57,$L$57)) -> 0.33414532 | L57: {=GEOMEAN(D57:G57+1)-1} -> 0.30415554
...

Sheet 플랜트
B1: 플랜트 매출
B5: 플랜트 부문 신규수주
B6: (단위: 십억 원) | C6: 2020 | D6: 2021 | E6: 2022 | F6: 2023 | G6: 2024 | H6: 2025E | I6: 2026E | J6: 2027E | K6: 2028E | L6: 2029E
B7: 플랜트 | C7: =C8+C9 -> 5171.8 | D7: =D8+D9 -> 5584.7 | E7: =E8+E9 -> 5788.3 | F7: =F8+F9 -> 7840 | G7: =G8+G9 -> 5089.1 | H7: =H8+H9 -> 9045.525 | I7: =I8+I9 -> 11198.231 | J7: =J8+J9 -> 16233.923 | ... L7: =L8+L9 -> 8377.5907
B8: 비원전 플랜트 | C8: 5171.8 | D8: 5584.7 | E8: 5788.3 | F8: 7840 | G8: 5089.1 | H8: =AVERAGE(D8:G8) -> 6075.525 | I8: =AVERAGE(E8:H8) -> 6198.2313 | J8: =AVERAGE(F8:I8) -> 6300.7141 | K8: =AVERAGE(G8:J8) -> 5915.8926 | L8: =AVERAGE(H8:K8) -> 6122.5907 | M8: [이동평균] 투자분석 과정에서 특이적 투자아이디어 발견할 수 없고 특별한 경향성 없어 4개년 이동평균 활용하여 보수적 추정
B9: 원전 플랜트 | C9: 0 | D9: 0 | E9: 0 | F9: 0 | G9: 0 | H9: ='플랜트-원전'!C7 -> 2970 | I9: ='플랜트-원전'!D7 -> 5000 | J9: ='플랜트-원전'!E7 -> 9933.209 | K9: ='플랜트-원전'!F7 -> 9044.1 | L9: ='플랜트-원전'!G7 -> 2255 | M9: [별도추정] '플랜트-원전' 시트 참고
B12: 플랜트 부문 수주잔고
B13: (단위: 십억 원) | C13: 2020 | D13: 2021 | E13: 2022 | F13: 2023 | G13: 2024 | H13: 2025E | I13: 2026E | J13: 2027E | K13: 2028E | L13: 2029E
B14: 플랜트 | C14: =SUM(C16,C15) -> 11692.6 | D14: =SUM(D16,D15) -> 14507 | E14: =SUM(E16,E15) -> 13678.4 | F14: =SUM(F16,F15) -> 13910.3 | G14: =SUM(G16,G15) -> 17320 | H14: =H15+H16 -> 18676.184 | I14: =I15+I16 -> 22445.114 | J14: =J15+J16 -> 30206.021 | K14: =K15+K16 -> 36063.191 | L14: =L15+L16 -> 33729.563
B15: 비원전 플랜트 | C15: 11540 | D15: 14354.4 | E15: 13561.9 | F15: 13781.7 | G15: 17280.3 | H15: =G15-H22+H8 -> 15854.684 | I15: =H15-I22+I8 -> 15170.614 | J15: =I15-J22+J8 -> 14885.972 | K15: =J15-K22+K8 -> 14340.068 | L15: =K15-L22+L8 -> 14237.832 | M15: [잔고 계산] 수주잔고 = 전기 수주잔고 - 당기 매출액 + 당기 신규수주
B16: 원전 플랜트 | C16: 152.6 | D16: 152.6 | E16: 116.5 | F16: 128.6 | G16: 39.7 | H16: ='플랜트-원전'!C10 -> 2821.5 | I16: ='플랜트-원전'!D10 -> 7274.5 | J16: ='플랜트-원전'!E10 -> 15320.049 | K16: ='플랜트-원전'!F10 -> 21723.123 | L16: ='플랜트-원전'!G10 -> 19491.731 | M16: [별도추정] '플랜트-원전' 시트 참고
B19: 플랜트 부문 매출액
B20: (단위: 십억 원) | C20: 2020 | D20: 2021 | E20: 2022 | F20: 2023 | G20: 2024 | H20: 2025E | I20: 2026E | J20: 2027E | K20: 2028E | L20: 2029E
B21: 플랜트 | C21: =C22+C23 -> 4796.65 | D21: =D22+D23 -> 4649.205 | E21: =E22+E23 -> 5386.967 | F21: =F22+F23 -> 6569.144 | G21: =G22+G23 -> 6830.398 | H21: =H22+H23 -> 7649.6414 | I21: =I22+I23 -> 7429.3008 | J21: =J22+J23 -> 8473.0161 | ... L21: =L22+L23 -> 10711.219
B22: 비원전 플랜트 | C22: 4741.45 | D22: 4649.205 | E22: 5304.267 | F22: 6541.644 | G22: 6814.398 | H22: =G15*$C$31 -> 7501.1414 | I22: =H15*$C$31 -> 6882.3008 | J22: =I15*$C$31 -> 6585.3556 | K22: =J15*$C$31 -> 6461.7966 | L22: =K15*$C$31 -> 6224.8272 | M22: [전환율 기반] 5년 평균 매출전환율 고려하여 전기 수주잔고에 적용하여 매출액 추정
B23: 원전 플랜트 | C23: 55.2 | D23: 0 | E23: 82.7 | F23: 27.5 | G23: 16 | H23: ='플랜트-원전'!C13 -> 148.5 | I23: ='플랜트-원전'!D13 -> 547 | J23: ='플랜트-원전'!E13 -> 1887.6605 | K23: ='플랜트-원전'!F13 -> 2641.0259 | L23: ='플랜트-원전'!G13 -> 4486.3913 | M23: [별도추정] '플랜트-원전' 시트 참고
B26: 비원전플랜트 매출전환율 추정
B27: (단위: 십억 원) | C27: 2020 | D27: 2021 | E27: 2022 | F27: 2023 | G27: 2024
B28: 수주잔고 | C28: 11540 | D28: 14354.4 | E28: 13561.9 | F28: 13781.7 | G28: 17280.3
B29: 매출액 | C29: 4741.45 | D29: 4649.205 | E29: 5304.267 | F29: 6541.644 | G29: 6814.398
B30: 매출전환율 | D30: =D29/C28 -> 0.40287738 | E30: =E29/D28 -> 0.36952203 | F30: =F29/E28 -> 0.48235454 | G30: =G29/F28 -> 0.49445264
B31: Avg 매출전환율 | C31: =GEOMEAN(D30:G30) -> 0.43408629
B32: *매출전환율(BBR) = 당기 매출액/전기 수주잔고

Sheet 플랜트-원전
B1: 플랜트 - 원전 플랜트 추정
B5: 원전 플랜트 수주 및 매출 추정(종합)
B6: (단위: 십억 원) | C6: 2025E | D6: 2026E | E6: 2027E | F6: 2028E | G6: 2029E | H6: 2030E | I6: 2031E | J6: 2032E | K6: 2033E | L6: 2034E
B7: 신규수주 | C7: =C8+C9 -> 2970 | D7: =D8+D9 -> 5000 | E7: =E8+E9 -> 9933.209 | F7: =F8+F9 -> 9044.1 | G7: =G8+G9 -> 2255 | H7: =H8+H9 -> 0 | I7: =I8+I9 -> 0 | J7: =J8+J9 -> 0 | ... L7: =L8+L9 -> 0
B8: 대형원전 | C8: =C27 -> 0 | D8: =D27 -> 5000 | E8: =E27 -> 7678.209 | F8: =F27 -> 9044.1 | G8: =G27 -> 0 | H8: =H27 -> 0 | I8: =I27 -> 0 | J8: =J27 -> 0 | ... L8: =L27 -> 0
B9: SMR | C9: =C58 -> 2970 | D9: =D58 -> 0 | E9: =E58 -> 2255 | F9: =F58 -> 0 | G9: =G58 -> 2255 | H9: =H58 -> 0 | I9: =I58 -> 0 | J9: =J58 -> 0 | ... L9: =L58 -> 0
B10: 수주잔고 | C10: =C11+C12 -> 2821.5 | D10: =D11+D12 -> 7274.5 | E10: =E11+E12 -> 15320.049 | F10: =F11+F12 -> 21723.123 | G10: =G11+G12 -> 19491.731 | H10: =H11+H12 -> 15372.635 | I10: =I11+I12 -> 10761.289 | J10: =J11+J12 -> 6939.1923 | ... L10: =L11+L12 -> 1641.8846
B11: 대형원전 | C11: =C28 -> 0 | D11: =D28 -> 4750 | E11: =E28 -> 11544.299 | F11: =F28 -> 18618.373 | G11: =G28 -> 15812.231 | H11: =H28 -> 12553.885 | I11: =I28 -> 9295.5386 | J11: =J28 -> 6037.1923 | ... L11: =L28 -> 1641.8846
B12: SMR | C12: =C59 -> 2821.5 | D12: =D59 -> 2524.5 | E12: =E59 -> 3775.75 | F12: =F59 -> 3104.75 | G12: =G59 -> 3679.5 | H12: =H59 -> 2818.75 | I12: =I59 -> 1465.75 | J12: =J59 -> 902 | ... L12: =L59 -> 0
B13: 매출 | C13: =C14+C15 -> 148.5 | D13: =D14+D15 -> 547 | E13: =E14+E15 -> 1887.6605 | F13: =F14+F15 -> 2641.0259 | G13: =G14+G15 -> 4486.3913 | H13: =H14+H15 -> 4119.0963 | I13: =I14+I15 -> 4611.3464 | J13: =J14+J15 -> 3822.0964 | ... L13: =L14+L15 -> 1962.4613
B14: 대형원전 | C14: =C29 -> 0 | D14: =D29 -> 250 | E14: =E29 -> 883.91045 | F14: =F29 -> 1970.0259 | G14: =G29 -> 2806.1413 | H14: =H29 -> 3258.3463 | I14: =I29 -> 3258.3464 | J14: =J29 -> 3258.3464 | ... L14: =L29 -> 1736.9613
B15: SMR | C15: =C60 -> 148.5 | D15: =D60 -> 297 | E15: =E60 -> 1003.75 | F15: =F60 -> 671 | G15: =G60 -> 1680.25 | H15: =H60 -> 860.75 | I15: =I60 -> 1353 | J15: =J60 -> 563.75 | ... L15: =L60 -> 225.5
B16: 매출원가 | C16: =C17+C19 -> 138.105 | D16: =D17+D19 -> 511.0225 | E16: =E17+E19 -> 1763.7004 | F16: =F17+F19 -> 2474.3768 | G16: =G17+G19 -> 4198.3008 | H16: =H17+H19 -> 3860.8993 | I16: =I17+I19 -> 4318.6918 | J16: =J17+J19 -> 3584.6893 | ... L16: =L17+L19 -> 1841.1559 | Q16: 원가율 추정논리
B17: 대형원전 | C17: =C14*C18 -> 0 | D17: =D14*D18 -> 234.8125 | E17: =E14*E18 -> 830.21289 | F17: =F14*F18 -> 1850.3468 | G17: =G14*G18 -> 2635.6683 | H17: =H14*H18 -> 3060.4018 | I17: =I14*I18 -> 3060.4018 | J17: =J14*J18 -> 3060.4018 | ... L17: =L14*L18 -> 1631.4409 | Q17: 기존 시공(C)만 담당하던 바라카 원전 사업의 GPM은 약 3.5%로 추정. 하지만 컨소시엄 단위의 수주로 EPC 전 영역에 참여하게 되며 GPM 상승할 것으로 추정, 업계 자료 바탕으로 향후 GPM 추정함.
B18: 원가율 | C18: =1-0.06075 -> 0.93925 | D18: =1-0.06075 -> 0.93925 | E18: =1-0.06075 -> 0.93925 | F18: =1-0.06075 -> 0.93925 | G18: =1-0.06075 -> 0.93925 | H18: =1-0.06075 -> 0.93925 | I18: =1-0.06075 -> 0.93925 | J18: =1-0.06075 -> 0.93925 | ... L18: =1-0.06075 -> 0.93925 | Q18: 업계 평균 E/P/C의 각 단계별 수주액 비중과 평균 GPM은 각각 15%/10%, 40%/7.5%, 45%/3.5%로 추정됨. 각 단계별 수주액 비중에 평균 GPM을 곱한 후 합하여 총 GPM을 추정하여, 6.075%를 적용함.
B19: SMR | C19: =C15*C20 -> 138.105 | D19: =D15*D20 -> 276.21 | E19: =E15*E20 -> 933.4875 | F19: =F15*F20 -> 624.03 | G19: =G15*G20 -> 1562.6325 | H19: =H15*H20 -> 800.4975 | I19: =I15*I20 -> 1258.29 | J19: =J15*J20 -> 524.2875 | ... L19: =L15*L20 -> 209.715 | Q19: SMR은 과거 시공 이력이 존재하지 않지만, 통상적으로 대형 원전에 비해 짧은 공기와 모듈화 설계 구조로 변동성이 작고 시공 단계에서의 리스크 관리가 용이함.
B20: 원가율 | C20: =93% -> 0.93 | D20: =93% -> 0.93 | E20: =93% -> 0.93 | F20: =93% -> 0.93 | G20: =93% -> 0.93 | H20: =93% -> 0.93 | I20: =93% -> 0.93 | J20: =93% -> 0.93 | ... L20: =93% -> 0.93 | Q20: 이를 반영하기 위해, 1.33배의 프리미엄을 적용하여 SMR의 GPM을 8%로 적용함.
B22: 대형 원전 수주 및 매출 추정
B25: 대형원전 수주 및 매출 추정 | Q25: 대형원전 전체 추정논리
B26: (단위: 십억 원) | C26: 2025E | D26: 2026E | E26: 2027E | F26: 2028E | G26: 2029E | H26: 2030E | I26: 2031E | J26: 2032E | K26: 2033E | L26: 2034E | Q26: 1. 건설회계 수익인식기준에 의해 공사 진행률에 따라 매출인식 및 수주잔고 소진을 추정하였으며, 이에 동사가 기 시공했던 UAE 바라카 원전사업의 연도별 진행률을 바탕으로 진행단계별 진행률(매출인식률) 추정함
B27: 신규수주 | C27: 0 | D27: =O36 -> 5000 | E27: =O43 -> 7678.209 | F27: =O50 -> 9044.1 | G27: 0 | H27: 0 | I27: 0 | J27: 0 | K27: 0 | L27: 0 | Q27: 2. 각 사업 별 수주잔고 인식시점은 '기본설계/인허가' 시작 시점으로 추정함 | X27: 1546
B28: 수주잔고 | C28: =C35+C42+C49 -> 0 | D28: =D35+D42+D49 -> 4750 | E28: =E35+E42+E49 -> 11544.299 | F28: =F35+F42+F49 -> 18618.373 | G28: =G35+G42+G49 -> 15812.231 | H28: =H35+H42+H49 -> 12553.885 | I28: =I35+I42+I49 -> 9295.5386 | J28: =J35+J42+J49 -> 6037.1923 | ... L28: =L35+L42+L49 -> 1641.8846 | Q28: 3. 유럽 프로젝트에 대한 수주액 추정을 위한 기준 환율은 1600원/￡로 Flat 추정함
B29: 매출 | C29: =C34+C41+C48 -> 0 | D29: =D34+D41+D48 -> 250 | E29: =E34+E41+E48 -> 883.91045 | F29: =F34+F41+F48 -> 1970.0259 | G29: =G34+G41+G48 -> 2806.1413 | H29: =H34+H41+H48 -> 3258.3463 | I29: =I34+I41+I48 -> 3258.3464 | J29: =J34+J41+J48 -> 3258.3464 | ... L29: =L34+L41+L48 -> 1736.9613 | Q29: 4. 총 사업비 중 EPC 수주액과 현대건설 지분율은 동사 IR 문의 결과 50~60%로, 보수적 추정을 위해 50% 가정하여 추정함
B31: 수주1. 불가리아 코즐로두이 대형원전 AP1000 × 2기 | N31: 내용 추정 | Q31: 불가리아 코즐로두이 대형원전 수주 내용 추정논리
B32: (단위: 십억 원) | C32: 2025E | D32: 2026E | E32: 2027E | F32: 2028E | G32: 2029E | H32: 2030E | I32: 2031E | J32: 2032E | K32: 2033E | L32: 2034E | N32: (단위: 십억 원) | Q32: 1. 총 사업비 : 동사가 기 발표한 금액인 10조원 적용함
B33: 진행률 | C33: 0 | D33: 0.05 | E33: 0.15 | F33: 0.3 | G33: 0.45 | H33: 0.6 | I33: 0.75 | J33: 0.9 | K33: 0.93 | L33: 0.96 | N33: 총 사업비 | O33: 10000 | Q33: 2. 사업 공사기간 : 동사 시공계획에 의해 2035년 완공 추정함
B34: 완성공사액 | C34: =O36*C33 -> 0 | D34: =(D33-C33)*$O36 -> 250 | E34: =(E33-D33)*$O36 -> 500 | F34: =(F33-E33)*$O36 -> 750 | G34: =(G33-F33)*$O36 -> 750 | H34: =(H33-G33)*$O36 -> 750 | I34: =(I33-H33)*$O36 -> 750 | J34: =(J33-I33)*$O36 -> 750 | K34: =(K33-J33)*$O36 -> 150 | L34: =(L33-K33)*$O36 -> 150 | N34: EPC 수주액 | O34: =O33*100% -> 10000 | Q34: 3. 사업 진행률 : 동사 발표에 의해 25년 내 기본설계 완료 후, 25년 말 EPC계약체결 및 착공할 것으로 추정함
B35: 계약잔액 | C35: 0 | D35: =$O36-SUM(C34:D34) -> 4750 | E35: =$O36-SUM(C34:E34) -> 4250 | F35: =$O36-SUM(C34:F34) -> 3500 | G35: =$O36-SUM(C34:G34) -> 2750 | H35: =$O36-SUM(C34:H34) -> 2000 | I35: =$O36-SUM(C34:I34) -> 1250 | J35: =$O36-SUM(C34:J34) -> 500 | K35: =$O36-SUM(C34:K34) -> 350 | L35: =$O36-SUM(C34:L34) -> 200 | N35: 추정 지분율 | O35: 0.5
B36: 진행단계 | C36: EWA | D36: 기본설계/인허가 | E36: EPC 계약체결 및 상세설계 | F36: 토목 기초 공사 | G36: 구조물 기계 설비 설치 | H36: 구조물 기계 설비 설치 | I36: 계통 연결 및 시운전 | J36: 상업 운전 개시 | K36: 상업 운전 개시 | L36: 상업 운전 개시 | N36: 추정 수주액 | O36: =O34*O35 -> 5000
B38: 수주2. 핀란드 포툼 대형원전 AP1000 × 1기 | N38: 내용 추정 | Q38: 필란드 포툼 대형원전 수주 내용 추정논리
B39: (단위: 십억 원) | C39: 2025E | D39: 2026E | E39: 2027E | F39: 2028E | G39: 2029E | H39: 2030E | I39: 2031E | J39: 2032E | K39: 2033E | L39: 2034E | N39: (단위: 십억 원) | Q39: 1. 총 사업비 : 추정한 발전용량 당 사업비와 발전규모를 고려하여 추정함
B40: 진행률 | C40: 0 | D40: 0 | E40: 0.05 | F40: 0.15 | G40: 0.3 | H40: 0.45 | I40: 0.6 | J40: 0.75 | K40: 0.9 | L40: 0.93 | N40: 총 사업비 | O40: =1.1*9.03*X27 -> 15356.418 | Q40: - 발전용량 1GW 당 사업비 : 과거 2005년 체결된 당국의 1.6GW규모 대형원전의 총 수주액 80억유로 발생함을 고려하고, 장기인플레이션율 3% 적용하여 추정함.
B41: 완성공사액 | C41: =O43*C40 -> 0 | D41: =(D40-C40)*$O43 -> 0 | E41: =(E40-D40)*$O43 -> 383.91045 | F41: =(F40-E40)*$O43 -> 767.8209 | G41: =(G40-F40)*$O43 -> 1151.7314 | H41: =(H40-G40)*$O43 -> 1151.7314 | I41: =(I40-H40)*$O43 -> 1151.7313 | J41: =(J40-I40)*$O43 -> 1151.7314 | K41: =(K40-J40)*$O43 -> 1151.7314 | L41: =(L40-K40)*$O43 -> 230.34627 | N41: EPC 수주액 | O41: =O40*100% -> 15356.418 | Q41: - 발전규모 : AP1000의 1기 당 통상 발전용량인 1.1GW 추정함
B42: 계약잔액 | C42: 0 | D42: 0 | E42: =$O43-SUM(C41:E41) -> 7294.2985 | F42: =$O43-SUM(C41:F41) -> 6526.4776 | G42: =$O43-SUM(C41:G41) -> 5374.7463 | H42: =$O43-SUM(C41:H41) -> 4223.0149 | I42: =$O43-SUM(C41:I41) -> 3071.2836 | J42: =$O43-SUM(C41:J41) -> 1919.5522 | K42: =$O43-SUM(C41:K41) -> 767.8209 | L42: =$O43-SUM(C41:L41) -> 537.47463 | N42: 추정 지분율 | O42: 0.5 | Q42: 2. 사업 진행률 : 동사 발표에 의해 25년 EWA 진행 중이며, 26년 기본설계/인허가, 27년 EPC 계약 체결 및 착공할 것으로 추정함.
B43: 진행단계 | C43: TFS | D43: EWA | E43: 기본설계/인허가 | F43: EPC 계약체결 및 상세설계 | G43: 토목 기초 공사 | H43: 토목 기초 공사 | I43: 토목 기초 공사 | J43: 구조물 기계 설비 설치 | K43: 계통 연결 및 시운전 | L43: 상업 운전 개시 | N43: 추정 수주액 | O43: =O41*O42 -> 7678.209
B45: 수주3. 슬로베니아 크르슈코 대형원전 AP1000 × 1기 | N45: 내용 추정 | Q45: 슬로베니아 크르슈코 대형원전 수주 내용 추정논리
B46: (단위: 십억 원) | C46: 2025E | D46: 2026E | E46: 2027E | F46: 2028E | G46: 2029E | H46: 2030E | I46: 2031E | J46: 2032E | K46: 2033E | L46: 2034E | N46: (단위: 십억 원) | Q46: 1. 총 사업비 : 슬로베니아 국영 원전기업 GEN energija이 분석한 원전 발전용량 1GW 당 사업비(93억유로)와 대형원전 1기 당 추정 발전규모(1.3GW)를 고려하여 추정함
B47: 진행률 | C47: 0 | D47: 0 | E47: 0 | F47: 0.05 | G47: 0.15 | H47: 0.3 | I47: 0.45 | J47: 0.6 | K47: 0.75 | L47: 0.9 | N47: 총 사업비 | O47: =1.3*9*X27 -> 18088.2 | Q47: 2. 사업 진행률 : 동사 발표에 의해 25년 3분기 내로 TFS 완료 후, 26년 EWA, 27년 기본설계/인허가가 시작될 것으로 추정함.
B48: 완성공사액 | C48: 0 | D48: =(D47-C47)*$O50 -> 0 | E48: =(E47-D47)*$O50 -> 0 | F48: =(F47-E47)*$O50 -> 452.205 | G48: =(G47-F47)*$O50 -> 904.41 | H48: =(H47-G47)*$O50 -> 1356.615 | I48: =(I47-H47)*$O50 -> 1356.615 | J48: =(J47-I47)*$O50 -> 1356.615 | K48: =(K47-J47)*$O50 -> 1356.615 | L48: =(L47-K47)*$O50 -> 1356.615 | N48: EPC 수주액 | O48: =O47*100% -> 18088.2
B49: 계약잔액 | C49: 0 | D49: 0 | E49: 0 | F49: =$O50-SUM(D48:F48) -> 8591.895 | G49: =$O50-SUM(D48:G48) -> 7687.485 | H49: =$O50-SUM(D48:H48) -> 6330.87 | I49: =$O50-SUM(D48:I48) -> 4974.255 | J49: =$O50-SUM(D48:J48) -> 3617.64 | K49: =$O50-SUM(D48:K48) -> 2261.025 | L49: =$O50-SUM(D48:L48) -> 904.41 | N49: 추정 지분율 | O49: 0.5
...

Sheet 토목 및 기타
B1: 토목 및 기타 매출
B5: 토목 및 기타 부문 신규수주
B6: (단위: 십억 원) | C6: 2020 | D6: 2021 | E6: 2022 | F6: 2023 | G6: 2024 | H6: 2025E | I6: 2026E | J6: 2027E | K6: 2028E | L6: 2029E | N6: 신규수주 : 두 사업부 모두 투자분석 과정에서 특이적 투자아이디어 발견할 수 없고 특별한 경향성 없어 3개년 이동평균 활용하여 보수적 추정
B7: 토목 | C7: 3930.32 | D7: 2104.8 | E7: 3849.422 | F7: 3427.864 | G7: 2962.016 | H7: =AVERAGE(E7:G7) -> 3413.1007 | I7: =AVERAGE(F7:H7) -> 3267.6602 | J7: =AVERAGE(G7:I7) -> 3214.259 | K7: =AVERAGE(H7:J7) -> 3298.34 | L7: =AVERAGE(I7:K7) -> 3260.0864
B8: 기타 | C8: 794.061 | D8: 1128.385 | E8: 1307.9721 | F8: 1280.6402 | G8: 1022.4438 | H8: =AVERAGE(E8:G8) -> 1203.6854 | I8: =AVERAGE(F8:H8) -> 1168.9231 | J8: =AVERAGE(G8:I8) -> 1131.6841 | K8: =AVERAGE(H8:J8) -> 1168.0975 | L8: =AVERAGE(I8:K8) -> 1156.2349
B10: 토목 및 기타 부문 수주잔고
B11: (단위: 십억 원) | C11: 2020 | D11: 2021 | E11: 2022 | F11: 2023 | G11: 2024 | H11: 2025E | I11: 2026E | J11: 2027E | K11: 2028E | L11: 2029E | N11: 수주잔고 = 전기 수주잔고 - 당기 매출액 + 당기 신규수주
B12: 토목 | C12: 7818.648 | D12: 8472.748 | E12: 12157.76 | F12: 13923.76 | G12: 10840 | H12: =G12+H7-H17 -> 11613.997 | I12: =H12+I7-I17 -> 12054.116 | J12: =I12+J7-J17 -> 12333.683 | K12: =J12+K7-K17 -> 12629.267 | L12: =K12+L7-L17 -> 12814.635
B13: 기타 | C13: 1951.3964 | D13: 2419.5164 | E13: 2497.968 | F13: 2593.418 | G13: 2407 | H13: =G13+H8-H18 -> 2227.3108 | I13: =H13+I8-I18 -> 2116.1322 | J13: =I13+J8-J18 -> 2031.6121 | K13: =J13+K8-K18 -> 2032.0817 | L13: =K13+L8-L18 -> 2020.4188
B15: 토목 및 기타 부문 매출액
B16: (단위: 십억 원) | C16: 2020 | D16: 2021 | E16: 2022 | F16: 2023 | G16: 2024 | H16: 2025E | I16: 2026E | J16: 2027E | K16: 2028E | L16: 2029E
B17: 토목 | C17: 2364.6 | D17: 2104.1 | E17: 2458 | F17: 2740 | G17: 2780.2 | H17: =G12*$C$26 -> 2639.1039 | I17: =H12*$C$26 -> 2827.541 | J17: =I12*$C$26 -> 2934.6923 | K17: =J12*$C$26 -> 3002.7555 | L17: =K12*$C$26 -> 3074.7184 | N17: 매출액 : 5년 평균 매출전환율 고려하여 전기 수주잔고에 적용하여 매출액 추정
B18: 기타 | C18: 1090.1 | D18: 1290.8 | E18: 1296.5 | F18: 1336.2 | G18: 1492.4 | H18: =G13*$C$34 -> 1383.3745 | I18: =H13*$C$34 -> 1280.1018 | J18: =I13*$C$34 -> 1216.2041 | K18: =J13*$C$34 -> 1167.6279 | L18: =K13*$C$34 -> 1167.8978
B21: 토목 매출전환율 추정
B22: (단위: 십억 원) | C22: 2020 | D22: 2021 | E22: 2022 | F22: 2023 | G22: 2024
B23: 수주잔고 | C23: 7818.648 | D23: 8472.748 | E23: 12157.76 | F23: 13923.76 | G23: 10840
B24: 매출액 | C24: 2364.6 | D24: 2104.1 | E24: 2458 | F24: 2740 | G24: 2780.2
B25: 매출전환율 | D25: =D24/C23 -> 0.26911302 | E25: =E24/D23 -> 0.29010659 | F25: =F24/E23 -> 0.22537046 | G25: =G24/F23 -> 0.19967308
B26: Avg 매출전환율 | C26: =GEOMEAN(D25:G25) -> 0.24345977
B27: *매출전환율(BBR) = 당기 매출액/전기 수주잔고
B29: 기타 매출전환율 추정
B30: (단위: 십억 원) | C30: 2020 | D30: 2021 | E30: 2022 | F30: 2023 | G30: 2024
B31: 수주잔고 | C31: 1951.3964 | D31: 2419.5164 | E31: 2497.968 | F31: 2593.418 | G31: 2407
B32: 매출액 | C32: 1090.1 | D32: 1290.8 | E32: 1296.5 | F32: 1336.2 | G32: 1492.4
B33: 매출전환율 | D33: =D32/C31 -> 0.66147503 | E33: =E32/D31 -> 0.53585088 | F33: =F32/E31 -> 0.53491478 | G33: =G32/F31 -> 0.57545679
B34: Avg 매출전환율 | C34: =GEOMEAN(D33:G33) -> 0.57472975
B35: *매출전환율(BBR) = 당기 매출액/전기 수주잔고

Sheet 영업비용추정
A1: ` | B1: 매출원가 및 판관비 추정 | I1: H
B5: 매출원가 추정
B8: 사업부별 매출원가 추정
B9: (단위: 십억 원) | C9: 2022 | D9: 2023 | E9: 2024 | F9: 2025E | G9: 2026E | H9: 2027E | I9: 2028E | J9: 2029E
B10: 매출원가 | C10: 19726.334 | D10: 27948.549 | E10: 32887.201 | F10: =F11+F13+F18+F20+F22 -> 29477.928 | G10: =G11+G13+G18+G20+G22 -> 29925.842 | H10: =H11+H13+H18+H20+H22 -> 30504.859 | I10: =I11+I13+I18+I20+I22 -> 31853.049 | J10: =J11+J13+J18+J20+J22 -> 34247.952 | T10: 사업부문별 원가율
B11: 건축주택 | C11: 11255.327 | D11: 18463.972 | E11: 21067.826 | F11: =F51*F12 -> 18659.519 | G11: =G51*G12 -> 19279.558 | H11: =H51*H12 -> 18859.796 | I11: =I51*I12 -> 19619.348 | J11: =J51*J12 -> 20504.053 | U11: 건축주택 | V11: 토목 | W11: 플랜트 | X11: 기타
B12: %of segment sales | C12: =C11/C51 -> 0.90034693 | D12: =D11/D51 -> 0.93726222 | E12: =E11/E51 -> 0.95766763 | F12: =E12*(1+RATE(3,0,-$E$12,$H$12)) -> 0.93632932 | G12: =F12*(1+RATE(3,0,-$E$12,$H$12)) -> 0.91546647 | H12: =1-U18 -> 0.89506846 | I12: =H12 -> 0.89506846 | J12: =H12 -> 0.89506846 | K12: [추정논리] 악성사업 준공으로 27년까지 정상원가율까지 단계적 감소 추정했으며, 정상 원가율은 보수적 추정 위해 17~24년 평균 원가율 적용함 | T12: 2024 | U12: 0.042335 | V12: 0.030575 | W12: -0.21835 | X12: 0.168216
B13: 플랜트 | C13: 5340.737 | D13: 6362.17 | E13: 8321.793 | F13: =F14+F16 -> 7639.2464 | G13: =G14+G16 -> 7393.3233 | H13: =H14+H16 -> 8349.056 | I13: =I14+I16 -> 8936.1734 | J13: =J14+J16 -> 10423.128 | T13: 2023 | U13: 0.062742966 | V13: 0.036636666 | W13: 0.031501247 | X13: 0.16220913
B14: 원전 플랜트 | F14: ='플랜트-원전'!C16 -> 138.105 | G14: ='플랜트-원전'!D16 -> 511.0225 | H14: ='플랜트-원전'!E16 -> 1763.7004 | I14: ='플랜트-원전'!F16 -> 2474.3768 | J14: ='플랜트-원전'!G16 -> 4198.3008 | T14: 2022 | U14: 0.099656744 | V14: 0.012889092 | W14: 0.014498346 | X14: 0.13492477
B15: %of segment sales | F15: =F14/F53 -> 0.93 | G15: =G14/G53 -> 0.93422761 | H15: =H14/H53 -> 0.9277409 | I15: =I14/I53 -> 0.92202264 | J15: =J14/J53 -> 0.92104154 | K15: [추정논리] '플랜트-원전' 시트 참조 | T15: 2021 | U15: 0.14215925 | V15: -0.02113102 | W15: 0.042824846 | X15: 0.14829137
B16: 비원전 플랜트 | F16: =F54 -> 7501.1414 | G16: =G54 -> 6882.3008 | H16: =H54 -> 6585.3556 | I16: =I54 -> 6461.7966 | J16: =J54 -> 6224.8272 | T16: 2020 | U16: 0.13581139 | V16: 0.0035274555 | W16: 0.0076793099 | X16: 0.14541066
B17: %of segment sales | C17: =C13/C52 -> 0.99143051 | D17: =D13/D52 -> 0.96849949 | E17: =E13/E52 -> 1.2183464 | F17: {=GEOMEAN(C17:D17+1,2-W15)-1} -> 0.972317 | G17: {=GEOMEAN(F17+1,C17:D17+1)-1} -> 0.97739027 | H17: {=GEOMEAN(F17:G17+1,D17+1)-1} -> 0.97273223 | I17: {=GEOMEAN(F17:H17+1)-1} -> 0.97414516 | J17: {=GEOMEAN(G17:I17+1)-1} -> 0.97475493 | K17: [이동평균] 최근 3년간 수익성 악화 환경 동일해, 일회적 요인 발생한 2024년 제외하여 3개년 이동평균 | T17: 2019 | U17: 0.15156016 | V17: 0.032649207 | W17: 0.052819407 | X17: 0.1049776
B18: 토목 | C18: 2383.631 | D18: 2639.577 | E18: 2695.173 | F18: =F55*F19 -> 2553.3363 | G18: =G55*G19 -> 2733.5371 | H18: =H55*H19 -> 2840.4607 | I18: =I55*I19 -> 2904.8114 | J18: =J55*J19 -> 2974.3047 | T18: 평균 | U18: {=GEOMEAN(U12:U17+1)-1} -> 0.10493154 | V18: {=GEOMEAN(V12:V17+1)-1} -> 0.015654002 | W18: {=GEOMEAN(W12:W17+1)-1} -> -0.016509496 | X18: {=GEOMEAN(X12:X17+1)-1} -> 0.14381789
B19: %of segment sales | C19: =C18/C55 -> 0.9697441 | D19: =D18/D55 -> 0.96334927 | E19: =E18/E55 -> 0.96941695 | F19: {=GEOMEAN(C19:E19+1)-1} -> 0.96750124 | G19: {=GEOMEAN(D19:F19+1)-1} -> 0.96675419 | H19: {=GEOMEAN(E19:G19+1)-1} -> 0.96789047 | I19: {=GEOMEAN(F19:H19+1)-1} -> 0.96738191 | J19: {=GEOMEAN(G19:I19+1)-1} -> 0.96734214 | K19: [이동평균] 특별한 경향성 없어 3년 이동평균
B20: 기타 | C20: 1130.976 | D20: 1119.519 | E20: 1241.457 | F20: =F21*F56 -> 1172.0702 | G20: =G21*G56 -> 1073.968 | H20: =H21*H56 -> 1020.8192 | I20: =I21*I56 -> 982.97223 | J20: =J21*J56 -> 981.10113
B21: %of segment sales | C21: =C20/C56 -> 0.87233012 | D21: =D20/D56 -> 0.8378379 | E21: =E20/E56 -> 0.83185272 | F21: {=GEOMEAN(C21:E21+1)-1} -> 0.84725447 | G21: {=GEOMEAN(D21:F21+1)-1} -> 0.83897078 | H21: {=GEOMEAN(E21:G21+1)-1} -> 0.83934856 | I21: {=GEOMEAN(F21:H21+1)-1} -> 0.84185398 | J21: {=GEOMEAN(G21:I21+1)-1} -> 0.84005733 | K21: [이동평균] 특별한 경향성 없어 3년 이동평균
B22: 내부거래 제거 | C22: -384.337 | D22: -636.689 | E22: -439.048 | F22: =(F11+F13+F18+F20)*E25 -> -546.2438 | G22: =(G11+G13+G18+G20)*$E$25 -> -554.54392 | H22: =(H11+H13+H18+H20)*$E$25 -> -565.27345 | I22: =(I11+I13+I18+I20)*$E$25 -> -590.25622 | J22: =(J11+J13+J18+J20)*$E$25 -> -634.63522
B24: 내부거래 제거 비중 | C24: =C22/(C11+C13+C18+C20) -> -0.019111098 | D24: =D22/(D11+D13+D18+D20) -> -0.02227335 | E24: =E22/(E11+E13+E18+E20) -> -0.01317424
D25: Geomean | E25: {=GEOMEAN(C24:E24+1)-1} -> -0.018193468
B27: 판매관리비 추정
B30: 판매관리비 추정 | R30: 상관계수 측정
B31: (단위: 백만 원) | C31: 2022 | D31: 2023 | E31: 2024 | F31: 2025E | G31: 2026E | H31: 2027E | I31: 2028E | J31: 2029E | R31: 판관비 세부항목
B32: 판매관리비 | C32: 937.846 | D32: 917.378 | E32: 1046.487 | F32: =(F33+F35+F37+F39+F41+F43) -> 1079.8136 | G32: =(G33+G35+G37+G39+G41+G43) -> 1070.4019 | H32: =(H33+H35+H37+H39+H41+H43) -> 1116.1486 | I32: =(I33+I35+I37+I39+I41+I43) -> 1153.7349 | J32: =(J33+J35+J37+J39+J41+J43) -> 1194.2343 | R32: 인건비 | S32: =CORREL($C$50:$E$50,C33:E33) -> 0.95534305
B33: 인건비 | C33: 538.377 | D33: 583.153 | E33: 633.54 | F33: =E33*1.0287 -> 651.7226 | G33: =F33*1.0287 -> 670.42704 | H33: =G33*1.0287 -> 689.66829 | I33: =H33*1.0287 -> 709.46177 | J33: =I33*1.0287 -> 729.82333 | K33: [CAGR] 고용노동부 300인 이상 건설업 임금 평균 상승률 2.87% 적용 | R33: 감가상각비 | S33: =CORREL(C35:E35,C50:E50) -> 0.81775601
B34: %of sales | C34: =C33/C$50 -> 0.02534839 | D34: =D33/$D$50 -> 0.019666963 | E34: =E33/$E$50 -> 0.019391925 | F34: =F33/F$50 -> 0.021006002 | G34: =G33/G$50 -> 0.020948432 | H34: =H33/H$50 -> 0.020847613 | I34: =I33/I50 -> 0.020537272 | J34: =J33/J50 -> 0.019645036 | R34: 연구개발비 | S34: =CORREL($C$50:$E$50,C37:E37) -> -0.78246256
B35: 감가상각비 | C35: 38.666 | D35: 42.762 | E35: 60.631 | F35: =E35*1.042 -> 63.177502 | G35: =F35*1.042 -> 65.830957 | H35: =G35*1.042 -> 68.595857 | I35: =H35*1.042 -> 71.476883 | J35: =I35*1.042 -> 74.478912 | K35: [추정논리] 유형자산 증가율 4.2% 반영하여 감가상각비 상승 가정('Expected BS'시트 참조) | R35: 지급수수료 | S35: =CORREL($C$50:$E$50,C39:E39) -> 0.39272761
B36: %of sales | C36: =C35/C$50 -> 0.0018205103 | D36: =D35/$D$50 -> 0.0014421579 | E36: =E35/$E$50 -> 0.0018558446 | F36: =AVERAGE(C36:E36) -> 0.0017061709 | G36: =F36 -> 0.0017061709 | H36: =G36 -> 0.0017061709 | I36: =H36 -> 0.0017061709 | J36: =I36 -> 0.0017061709 | R36: 대손상각비 | S36: =CORREL($C$50:$E$50,C41:E41) -> -0.57428852
B37: 연구개발비 | C37: 178.612 | D37: 138.787 | E37: 154.923 | F37: =F50*F38 -> 177.30991 | G37: =G50*G38 -> 160.8027 | H37: =H50*H38 -> 170.19253 | I37: =I50*I38 -> 182.61681 | J37: =J50*J38 -> 191.35202 | K37: [추정논리] 매출액 대비 연구개발비 평균 비중에 당기 추정매출액 적용하여 추정 | R37: 기타비용 | S37: =CORREL($C$43:$E$43,C50:E50) -> 0.99172541
B38: %of sales | C38: =C37/C$50 -> 0.0084095842 | D38: =D37/$D$50 -> 0.0046806222 | E38: =E37/$E$50 -> 0.0047420134 | F38: =GEOMEAN(C38:E38) -> 0.0057149657 | G38: =GEOMEAN(D38:F38) -> 0.0050245055 | H38: =GEOMEAN(E38:G38) -> 0.0051446588 | I38: =GEOMEAN(F38:H38) -> 0.0052863329 | J38: =GEOMEAN(G38:I38) -> 0.0051507223
B39: 지급수수료 | C39: 57.694 | D39: 50.619 | E39: 69.602 | F39: =$E$60*F49 -> 69.488549 | G39: =$E$60*G49 -> 57.353533 | H39: =$E$60*H49 -> 67.060694 | I39: =$E$60*I49 -> 71.93477 | J39: =$E$60*J49 -> 80.292156 | K39: [추정논리] 신규수주 시점에서 발생, 최근 3개년 평균 신규수주액 대비 지급수수료율 0.18% 적용하여 추정
B40: %of sales | C40: =C39/C$50 -> 0.0027164051 | D40: =D39/$D$50 -> 0.0017071369 | E40: =E39/$E$50 -> 0.0021304365 | F40: =F39/F$49 -> 0.0018386076 | G40: =G39/G$50 -> 0.0017920915 | H40: =H39/H$50 -> 0.0020271418 | I40: =I39/I$50 -> 0.0020823446 | J40: =J39/J$50 -> 0.0021612659
B41: 대손상각비 | C41: 22.687 | D41: -8.434 | E41: 11.97 | F41: =AVERAGE(C41:E41) -> 8.741 | G41: =AVERAGE(D41:F41) -> 4.0923333 | H41: =AVERAGE(E41:G41) -> 8.2677778 | I41: =AVERAGE(F41:H41) -> 7.0337037 | J41: =AVERAGE(G41:I41) -> 6.4646049 | K41: [이동평균] 완공 사업장으로부터 자금회수 지연, 미분양 물량에 대한 할인 매각 등으로 매출채권 미회수시 인식하는 항목으로, 합리적 추정할 수 없어 3개년 이동평균
B42: %of sales | C42: =C41/C$50 -> 0.0010681714 | D42: =D41/$D$50 -> -0.00028443851 | E42: =E41/$E$50 -> 0.00036638782 | F42: =F41/F$50 -> 0.00028173561 | G42: =G41/G$50 -> 0.00012787069 | H42: =H41/H$50 -> 0.00024992223 | I42: =I41/I50 -> 0.0002036094 | J42: =J41/J50 -> 0.00017401115
B43: 기타비용 | C43: =(C32-(C33+C35+C37+C39+C41)) -> 101.81 | D43: =(D32-(D33+D35+D37+D39+D41)) -> 110.491 | E43: =(E32-(E33+E35+E37+E39+E41)) -> 115.821 | F43: =AVERAGE(C43:E43) -> 109.374 | G43: =AVERAGE(D43:F43) -> 111.89533 | H43: =AVERAGE(E43:G43) -> 112.36344 | I43: =AVERAGE(F43:H43) -> 111.21093 | J43: =AVERAGE(G43:I43) -> 111.82323 | K43: [이동평균] 합리적 추정할 수 없어 3개년 이동평균
B44: %of sales | C44: =C43/C$50 -> 0.0047935176 | D44: =D43/$D$50 -> 0.0037263333 | E44: =E43/$E$50 -> 0.0035451465 | F44: =F43/F50 -> 0.0035252889 | G44: =G43/G50 -> 0.0034963264 | H44: =H43/H50 -> 0.0033965744 | I44: =I43/I50 -> 0.0032192982 | J44: =J43/J50 -> 0.0030100045
B47: 전체 매출
B48: (단위: 백만 원) | C48: 2022 | D48: 2023 | E48: 2024 | F48: 2025E | G48: 2026E | H48: 2027E | I48: 2028E | J48: 2029E
B49: 전체 신규수주(연간) | C49: 34376.181 | D49: 29651.4 | E49: 32670.3 | F49: 37794.116 | G49: 31194.005 | H49: 36473.631 | I49: 39124.591 | J49: 43670.089
